{"ts":"2026-08-24T20:48:26.872Z","event_type":"best_bid_ask","market_id":"3826919","outcome_index":1,"market_type":"set2","local_side":"away","local_uid":"2026-08-24_dalibor_svrcina_felipe_meligeni_alves","bid":0.48,"ask":0.57,"mid":0.525,"spread":0.09,"bid_size":null,"ask_size":null}
{"ts":"2026-08-24T20:48:26.873Z","event_type":"price_change","market_id":"3826919","outcome_index":1,"market_type":"set2","local_side":"away","local_uid":"2026-08-24_dalibor_svrcina_felipe_meligeni_alves","bid":0.48,"ask":0.57,"mid":0.525,"spread":0.09,"price":0.49,"size":0.0,"side":"BUY"}
{"ts":"2026-08-24T20:48:26.873Z","event_type":"price_change","market_id":"3826919","outcome_index":0,"market_type":"set2","local_side":"home","local_uid":"2026-08-24_dalibor_svrcina_felipe_meligeni_alves","bid":0.43,"ask":0.52,"mid":0.475,"spread":0.09,"price":0.51,"size":0.0,"side":"SELL"}
{"ts":"2026-08-24T20:48:27.040Z","event_type":"best_bid_ask","market_id":"3826919","outcome_index":0,"market_type":"set2","local_side":"home","local_uid":"2026-08-24_dalibor_svrcina_felipe_meligeni_alves","bid":0.43,"ask":0.51,"mid":0.47,"spread":0.08,"bid_size":null,"ask_size":null}
{"ts":"2026-08-24T20:48:27.041Z","event_type":"best_bid_ask","market_id":"3826919","outcome_index":1,"market_type":"set2","local_side":"away","local_uid":"2026-08-24_dalibor_svrcina_felipe_meligeni_alves","bid":0.49,"ask":0.57,"mid":0.53,"spread":0.08,"bid_size":null,"ask_size":null}
{"ts":"2026-08-24T20:48:27.041Z","event_type":"price_change","market_id":"3826919","outcome_index":1,"market_type":"set2","local_side":"away","local_uid":"2026-08-24_dalibor_svrcina_felipe_meligeni_alves","bid":0.49,"ask":0.57,"mid":0.53,"spread":0.08,"price":0.49,"size":24.6,"side":"BUY"}
{"ts":"2026-08-24T20:48:27.041Z","event_type":"price_change","market_id":"3826919","outcome_index":0,"market_type":"set2","local_side":"home","local_uid":"2026-08-24_dalibor_svrcina_felipe_meligeni_alves","bid":0.43,"ask":0.51,"mid":0.47,"spread":0.08,"price":0.51,"size":24.6,"side":"SELL"}
{"ts":"2026-08-24T20:48:27.073Z","event_type":"best_bid_ask","market_id":"3826919","outcome_index":0,"market_type":"set2","local_side":"home","local_uid":"2026-08-24_dalibor_svrcina_felipe_meligeni_alves","bid":0.43,"ask":0.52,"mid":0.475,"spread":0.09,"bid_size":null,"ask_size":null}
{"ts":"2026-08-24T20:48:27.073Z","event_type":"best_bid_ask","market_id":"3826919","outcome_index":1,"market_type":"set2","local_side":"away","local_uid":"2026-08-24_dalibor_svrcina_felipe_meligeni_alves","bid":0.48,"ask":0.57,"mid":0.525,"spread":0.09,"bid_size":null,"ask_size":null}
{"ts":"2026-08-24T20:48:27.074Z","event_type":"price_change","market_id":"3826919","outcome_index":1,"market_type":"set2","local_side":"away","local_uid":"2026-08-24_dalibor_svrcina_felipe_meligeni_alves","bid":0.48,"ask":0.57,"mid":0.525,"spread":0.09,"price":0.49,"size":0.0,"side":"BUY"}
{"ts":"2026-08-24T20:48:27.074Z","event_type":"price_change","market_id":"3826919","outcome_index":0,"market_type":"set2","local_side":"home","local_uid":"2026-08-24_dalibor_svrcina_felipe_meligeni_alves","bid":0.43,"ask":0.52,"mid":0.475,"spread":0.09,"price":0.51,"size":0.0,"side":"SELL"}
{"ts":"2026-08-24T20:48:27.143Z","event_type":"best_bid_ask","market_id":"3826654","outcome_index":0,"market_type":"set2","local_side":"home","local_uid":"2026-08-24_sebastian_gorzny_cruz_hewitt","bid":0.05,"ask":0.13,"mid":0.09,"spread":0.08,"bid_size":null,"ask_size":null}
{"ts":"2026-08-24T20:48:27.144Z","event_type":"best_bid_ask","market_id":"3826654","outcome_index":1,"market_type":"set2","local_side":"away","local_uid":"2026-08-24_sebastian_gorzny_cruz_hewitt","bid":0.87,"ask":0.95,"mid":0.91,"spread":0.08,"bid_size":null,"ask_size":null}
{"ts":"2026-08-24T20:48:27.144Z","event_type":"price_change","market_id":"3826654","outcome_index":0,"market_type":"set2","local_side":"home","local_uid":"2026-08-24_sebastian_gorzny_cruz_hewitt","bid":0.05,"ask":0.13,"mid":0.09,"spread":0.08,"price":0.06,"size":0.0,"side":"BUY"}
{"ts":"2026-08-24T20:48:27.144Z","event_type":"price_change","market_id":"3826654","outcome_index":1,"market_type":"set2","local_side":"away","local_uid":"2026-08-24_sebastian_gorzny_cruz_hewitt","bid":0.87,"ask":0.95,"mid":0.91,"spread":0.08,"price":0.94,"size":0.0,"side":"SELL"}
{"ts":"2026-08-24T20:48:27.169Z","event_type":"best_bid_ask","market_id":"3826654","outcome_index":0,"market_type":"set2","local_side":"home","local_uid":"2026-08-24_sebastian_gorzny_cruz_hewitt","bid":0.06,"ask":0.13,"mid":0.095,"spread":0.07,"bid_size":null,"ask_size":null}
{"ts":"2026-08-24T20:48:27.170Z","event_type":"best_bid_ask","market_id":"3826654","outcome_index":1,"market_type":"set2","local_side":"away","local_uid":"2026-08-24_sebastian_gorzny_cruz_hewitt","bid":0.87,"ask":0.94,"mid":0.905,"spread":0.07,"bid_size":null,"ask_size":null}
{"ts":"2026-08-24T20:48:27.170Z","event_type":"price_change","market_id":"3826654","outcome_index":0,"market_type":"set2","local_side":"home","local_uid":"2026-08-24_sebastian_gorzny_cruz_hewitt","bid":0.06,"ask":0.13,"mid":0.095,"spread":0.07,"price":0.06,"size":5.0,"side":"BUY"}
{"ts":"2026-08-24T20:48:27.170Z","event_type":"price_change","market_id":"3826654","outcome_index":1,"market_type":"set2","local_side":"away","local_uid":"2026-08-24_sebastian_gorzny_cruz_hewitt","bid":0.87,"ask":0.94,"mid":0.905,"spread":0.07,"price":0.94,"size":5.0,"side":"SELL"}
{"ts":"2026-08-24T20:48:27.175Z","event_type":"best_bid_ask","market_id":"3826654","outcome_index":0,"market_type":"set2","local_side":"home","local_uid":"2026-08-24_sebastian_gorzny_cruz_hewitt","bid":0.04,"ask":0.13,"mid":0.085,"spread":0.09,"bid_size":null,"ask_size":null}
{"ts":"2026-08-24T20:48:27.175Z","event_type":"best_bid_ask","market_id":"3826654","outcome_index":1,"market_type":"set2","local_side":"away","local_uid":"2026-08-24_sebastian_gorzny_cruz_hewitt","bid":0.87,"ask":0.96,"mid":0.915,"spread":0.09,"bid_size":null,"ask_size":null}
{"ts":"2026-08-24T20:48:27.176Z","event_type":"price_change","market_id":"3826654","outcome_index":0,"market_type":"set2","local_side":"home","local_uid":"2026-08-24_sebastian_gorzny_cruz_hewitt","bid":0.04,"ask":0.13,"mid":0.085,"spread":0.09,"price":0.06,"size":0.0,"side":"BUY"}
{"ts":"2026-08-24T20:48:27.176Z","event_type":"price_change","market_id":"3826654","outcome_index":1,"market_type":"set2","local_side":"away","local_uid":"2026-08-24_sebastian_gorzny_cruz_hewitt","bid":0.87,"ask":0.96,"mid":0.915,"spread":0.09,"price":0.94,"size":0.0,"side":"SELL"}
{"ts":"2026-08-24T20:48:27.199Z","event_type":"best_bid_ask","market_id":"3826919","outcome_index":0,"market_type":"set2","local_side":"home","local_uid":"2026-08-24_dalibor_svrcina_felipe_meligeni_alves","bid":0.43,"ask":0.51,"mid":0.47,"spread":0.08,"bid_size":null,"ask_size":null}
{"ts":"2026-08-24T20:48:27.200Z","event_type":"best_bid_ask","market_id":"3826919","outcome_index":1,"market_type":"set2","local_side":"away","local_uid":"2026-08-24_dalibor_svrcina_felipe_meligeni_alves","bid":0.49,"ask":0.57,"mid":0.53,"spread":0.08,"bid_size":null,"ask_size":null}
{"ts":"2026-08-24T20:48:27.205Z","event_type":"price_change","market_id":"3826919","outcome_index":1,"market_type":"set2","local_side":"away","local_uid":"2026-08-24_dalibor_svrcina_felipe_meligeni_alves","bid":0.49,"ask":0.57,"mid":0.53,"spread":0.08,"price":0.49,"size":24.6,"side":"BUY"}
{"ts":"2026-08-24T20:48:27.205Z","event_type":"price_change","market_id":"3826919","outcome_index":0,"market_type":"set2","local_side":"home","local_uid":"2026-08-24_dalibor_svrcina_felipe_meligeni_alves","bid":0.43,"ask":0.51,"mid":0.47,"spread":0.08,"price":0.51,"size":24.6,"side":"SELL"}
{"ts":"2026-08-24T20:48:27.219Z","event_type":"best_bid_ask","market_id":"3824994","outcome_index":0,"market_type":"set2","local_side":"home","local_uid":"2026-08-24_angela_fita_boluda_lin_zhu","bid":0.35,"ask":0.46,"mid":0.405,"spread":0.11,"bid_size":null,"ask_size":null}
{"ts":"2026-08-24T20:48:27.219Z","event_type":"best_bid_ask","market_id":"3824994","outcome_index":1,"market_type":"set2","local_side":"away","local_uid":"2026-08-24_angela_fita_boluda_lin_zhu","bid":0.54,"ask":0.65,"mid":0.595,"spread":0.11,"bid_size":null,"ask_size":null}
{"ts":"2026-08-24T20:48:27.219Z","event_type":"price_change","market_id":"3824994","outcome_index":1,"market_type":"set2","local_side":"away","local_uid":"2026-08-24_angela_fita_boluda_lin_zhu","bid":0.54,"ask":0.65,"mid":0.595,"spread":0.11,"price":0.54,"size":1095.0,"side":"BUY"}
{"ts":"2026-08-24T20:48:27.219Z","event_type":"price_change","market_id":"3824994","outcome_index":0,"market_type":"set2","local_side":"home","local_uid":"2026-08-24_angela_fita_boluda_lin_zhu","bid":0.35,"ask":0.46,"mid":0.405,"spread":0.11,"price":0.46,"size":1095.0,"side":"SELL"}
{"ts":"2026-08-24T20:48:27.230Z","event_type":"best_bid_ask","market_id":"3826919","outcome_index":0,"market_type":"set2","local_side":"home","local_uid":"2026-08-24_dalibor_svrcina_felipe_meligeni_alves","bid":0.43,"ask":0.52,"mid":0.475,"spread":0.09,"bid_size":null,"ask_size":null}
{"ts":"2026-08-24T20:48:27.231Z","event_type":"best_bid_ask","market_id":"3826919","outcome_index":1,"market_type":"set2","local_side":"away","local_uid":"2026-08-24_dalibor_svrcina_felipe_meligeni_alves","bid":0.48,"ask":0.57,"mid":0.525,"spread":0.09,"bid_size":null,"ask_size":null}
{"ts":"2026-08-24T20:48:27.231Z","event_type":"price_change","market_id":"3826919","outcome_index":1,"market_type":"set2","local_side":"away","local_uid":"2026-08-24_dalibor_svrcina_felipe_meligeni_alves","bid":0.48,"ask":0.57,"mid":0.525,"spread":0.09,"price":0.49,"size":0.0,"side":"BUY"}
{"ts":"2026-08-24T20:48:27.231Z","event_type":"price_change","market_id":"3826919","outcome_index":0,"market_type":"set2","local_side":"home","local_uid":"2026-08-24_dalibor_svrcina_felipe_meligeni_alves","bid":0.43,"ask":0.52,"mid":0.475,"spread":0.09,"price":0.51,"size":0.0,"side":"SELL"}
{"ts":"2026-08-24T20:48:27.248Z","event_type":"best_bid_ask","market_id":"3824994","outcome_index":0,"market_type":"set2","local_side":"home","local_uid":"2026-08-24_angela_fita_boluda_lin_zhu","bid":0.36,"ask":0.46,"mid":0.41,"spread":0.1,"bid_size":null,"ask_size":null}
{"ts":"2026-08-24T20:48:27.249Z","event_type":"best_bid_ask","market_id":"3824994","outcome_index":1,"market_type":"set2","local_side":"away","local_uid":"2026-08-24_angela_fita_boluda_lin_zhu","bid":0.54,"ask":0.64,"mid":0.59,"spread":0.1,"bid_size":null,"ask_size":null}
{"ts":"2026-08-24T20:48:27.249Z","event_type":"price_change","market_id":"3824994","outcome_index":0,"market_type":"set2","local_side":"home","local_uid":"2026-08-24_angela_fita_boluda_lin_zhu","bid":0.36,"ask":0.46,"mid":0.41,"spread":0.1,"price":0.36,"size":150.0,"side":"BUY"}
{"ts":"2026-08-24T20:48:27.249Z","event_type":"price_change","market_id":"3824994","outcome_index":1,"market_type":"set2","local_side":"away","local_uid":"2026-08-24_angela_fita_boluda_lin_zhu","bid":0.54,"ask":0.64,"mid":0.59,"spread":0.1,"price":0.64,"size":150.0,"side":"SELL"}
{"ts":"2026-08-24T20:48:27.345Z","event_type":"best_bid_ask","market_id":"3825038","outcome_index":0,"market_type":"set1","local_side":"home","local_uid":"2026-08-24_greet_minnen_jeline_vandromme","bid":0.001,"ask":0.07,"mid":0.0355,"spread":0.069,"bid_size":null,"ask_size":null}
{"ts":"2026-08-24T20:48:27.346Z","event_type":"best_bid_ask","market_id":"3825038","outcome_index":1,"market_type":"set1","local_side":"away","local_uid":"2026-08-24_greet_minnen_jeline_vandromme","bid":0.93,"ask":0.999,"mid":0.9645,"spread":0.069,"bid_size":null,"ask_size":null}
{"ts":"2026-08-24T20:48:27.346Z","event_type":"price_change","market_id":"3825038","outcome_index":1,"market_type":"set1","local_side":"away","local_uid":"2026-08-24_greet_minnen_jeline_vandromme","bid":0.93,"ask":0.999,"mid":0.9645,"spread":0.069,"price":0.93,"size":44.0,"side":"BUY"}
{"ts":"2026-08-24T20:48:27.346Z","event_type":"price_change","market_id":"3825038","outcome_index":0,"market_type":"set1","local_side":"home","local_uid":"2026-08-24_greet_minnen_jeline_vandromme","bid":0.001,"ask":0.07,"mid":0.0355,"spread":0.069,"price":0.07,"size":44.0,"side":"SELL"}
{"ts":"2026-08-24T20:48:27.347Z","event_type":"price_change","market_id":"3824875","outcome_index":0,"market_type":"set2","local_side":"home","local_uid":"2026-08-24_eva_vedder_bianca_andreescu","bid":0.21,"ask":0.25,"mid":0.23,"spread":0.04,"price":0.2,"size":26.4,"side":"BUY"}
{"ts":"2026-08-24T20:48:27.347Z","event_type":"price_change","market_id":"3824875","outcome_index":1,"market_type":"set2","local_side":"away","local_uid":"2026-08-24_eva_vedder_bianca_andreescu","bid":0.75,"ask":0.79,"mid":0.77,"spread":0.04,"price":0.8,"size":26.4,"side":"SELL"}
{"ts":"2026-08-24T20:48:27.396Z","event_type":"best_bid_ask","market_id":"3825038","outcome_index":0,"market_type":"set1","local_side":"home","local_uid":"2026-08-24_greet_minnen_jeline_vandromme","bid":0.001,"ask":0.054,"mid":0.0275,"spread":0.053,"bid_size":null,"ask_size":null}
{"ts":"2026-08-24T20:48:27.396Z","event_type":"best_bid_ask","market_id":"3825038","outcome_index":1,"market_type":"set1","local_side":"away","local_uid":"2026-08-24_greet_minnen_jeline_vandromme","bid":0.946,"ask":0.999,"mid":0.9725,"spread":0.053,"bid_size":null,"ask_size":null}
{"ts":"2026-08-24T20:48:27.397Z","event_type":"price_change","market_id":"3825038","outcome_index":1,"market_type":"set1","local_side":"away","local_uid":"2026-08-24_greet_minnen_jeline_vandromme","bid":0.946,"ask":0.999,"mid":0.9725,"spread":0.053,"price":0.946,"size":22.49,"side":"BUY"}
{"ts":"2026-08-24T20:48:27.397Z","event_type":"price_change","market_id":"3825038","outcome_index":0,"market_type":"set1","local_side":"home","local_uid":"2026-08-24_greet_minnen_jeline_vandromme","bid":0.001,"ask":0.054,"mid":0.0275,"spread":0.053,"price":0.054,"size":22.49,"side":"SELL"}
{"ts":"2026-08-24T20:48:27.441Z","event_type":"best_bid_ask","market_id":"3826919","outcome_index":0,"market_type":"set2","local_side":"home","local_uid":"2026-08-24_dalibor_svrcina_felipe_meligeni_alves","bid":0.43,"ask":0.51,"mid":0.47,"spread":0.08,"bid_size":null,"ask_size":null}
{"ts":"2026-08-24T20:48:27.441Z","event_type":"best_bid_ask","market_id":"3826919","outcome_index":1,"market_type":"set2","local_side":"away","local_uid":"2026-08-24_dalibor_svrcina_felipe_meligeni_alves","bid":0.49,"ask":0.57,"mid":0.53,"spread":0.08,"bid_size":null,"ask_size":null}
{"ts":"2026-08-24T20:48:27.442Z","event_type":"price_change","market_id":"3826919","outcome_index":1,"market_type":"set2","local_side":"away","local_uid":"2026-08-24_dalibor_svrcina_felipe_meligeni_alves","bid":0.49,"ask":0.57,"mid":0.53,"spread":0.08,"price":0.49,"size":24.6,"side":"BUY"}
{"ts":"2026-08-24T20:48:27.442Z","event_type":"price_change","market_id":"3826919","outcome_index":0,"market_type":"set2","local_side":"home","local_uid":"2026-08-24_dalibor_svrcina_felipe_meligeni_alves","bid":0.43,"ask":0.51,"mid":0.47,"spread":0.08,"price":0.51,"size":24.6,"side":"SELL"}
{"ts":"2026-08-24T20:48:27.467Z","event_type":"best_bid_ask","market_id":"3826919","outcome_index":0,"market_type":"set2","local_side":"home","local_uid":"2026-08-24_dalibor_svrcina_felipe_meligeni_alves","bid":0.43,"ask":0.52,"mid":0.475,"spread":0.09,"bid_size":null,"ask_size":null}
{"ts":"2026-08-24T20:48:27.467Z","event_type":"best_bid_ask","market_id":"3826919","outcome_index":1,"market_type":"set2","local_side":"away","local_uid":"2026-08-24_dalibor_svrcina_felipe_meligeni_alves","bid":0.48,"ask":0.57,"mid":0.525,"spread":0.09,"bid_size":null,"ask_size":null}
{"ts":"2026-08-24T20:48:27.467Z","event_type":"price_change","market_id":"3826919","outcome_index":1,"market_type":"set2","local_side":"away","local_uid":"2026-08-24_dalibor_svrcina_felipe_meligeni_alves","bid":0.48,"ask":0.57,"mid":0.525,"spread":0.09,"price":0.49,"size":0.0,"side":"BUY"}
{"ts":"2026-08-24T20:48:27.468Z","event_type":"price_change","market_id":"3826919","outcome_index":0,"market_type":"set2","local_side":"home","local_uid":"2026-08-24_dalibor_svrcina_felipe_meligeni_alves","bid":0.43,"ask":0.52,"mid":0.475,"spread":0.09,"price":0.51,"size":0.0,"side":"SELL"}
{"ts":"2026-08-24T20:48:27.500Z","event_type":"best_bid_ask","market_id":"3826919","outcome_index":0,"market_type":"set2","local_side":"home","local_uid":"2026-08-24_dalibor_svrcina_felipe_meligeni_alves","bid":0.43,"ask":0.51,"mid":0.47,"spread":0.08,"bid_size":null,"ask_size":null}
{"ts":"2026-08-24T20:48:27.501Z","event_type":"best_bid_ask","market_id":"3826919","outcome_index":1,"market_type":"set2","local_side":"away","local_uid":"2026-08-24_dalibor_svrcina_felipe_meligeni_alves","bid":0.49,"ask":0.57,"mid":0.53,"spread":0.08,"bid_size":null,"ask_size":null}
{"ts":"2026-08-24T20:48:27.501Z","event_type":"price_change","market_id":"3826919","outcome_index":1,"market_type":"set2","local_side":"away","local_uid":"2026-08-24_dalibor_svrcina_felipe_meligeni_alves","bid":0.49,"ask":0.57,"mid":0.53,"spread":0.08,"price":0.49,"size":24.6,"side":"BUY"}
{"ts":"2026-08-24T20:48:27.501Z","event_type":"price_change","market_id":"3826919","outcome_index":0,"market_type":"set2","local_side":"home","local_uid":"2026-08-24_dalibor_svrcina_felipe_meligeni_alves","bid":0.43,"ask":0.51,"mid":0.47,"spread":0.08,"price":0.51,"size":24.6,"side":"SELL"}
{"ts":"2026-08-24T20:48:27.520Z","event_type":"best_bid_ask","market_id":"3825038","outcome_index":0,"market_type":"set1","local_side":"home","local_uid":"2026-08-24_greet_minnen_jeline_vandromme","bid":0.001,"ask":0.09,"mid":0.0455,"spread":0.089,"bid_size":null,"ask_size":null}
{"ts":"2026-08-24T20:48:27.521Z","event_type":"best_bid_ask","market_id":"3825038","outcome_index":1,"market_type":"set1","local_side":"away","local_uid":"2026-08-24_greet_minnen_jeline_vandromme","bid":0.91,"ask":0.999,"mid":0.9545,"spread":0.089,"bid_size":null,"ask_size":null}
{"ts":"2026-08-24T20:48:27.521Z","event_type":"price_change","market_id":"3825038","outcome_index":1,"market_type":"set1","local_side":"away","local_uid":"2026-08-24_greet_minnen_jeline_vandromme","bid":0.91,"ask":0.999,"mid":0.9545,"spread":0.089,"price":0.946,"size":0.0,"side":"BUY"}
{"ts":"2026-08-24T20:48:27.521Z","event_type":"price_change","market_id":"3825038","outcome_index":0,"market_type":"set1","local_side":"home","local_uid":"2026-08-24_greet_minnen_jeline_vandromme","bid":0.001,"ask":0.09,"mid":0.0455,"spread":0.089,"price":0.054,"size":0.0,"side":"SELL"}
{"ts":"2026-08-24T20:48:27.537Z","event_type":"best_bid_ask","market_id":"3826919","outcome_index":0,"market_type":"set2","local_side":"home","local_uid":"2026-08-24_dalibor_svrcina_felipe_meligeni_alves","bid":0.43,"ask":0.52,"mid":0.475,"spread":0.09,"bid_size":null,"ask_size":null}
{"ts":"2026-08-24T20:48:27.538Z","event_type":"best_bid_ask","market_id":"3826919","outcome_index":1,"market_type":"set2","local_side":"away","local_uid":"2026-08-24_dalibor_svrcina_felipe_meligeni_alves","bid":0.48,"ask":0.57,"mid":0.525,"spread":0.09,"bid_size":null,"ask_size":null}
{"ts":"2026-08-24T20:48:27.538Z","event_type":"price_change","market_id":"3826919","outcome_index":1,"market_type":"set2","local_side":"away","local_uid":"2026-08-24_dalibor_svrcina_felipe_meligeni_alves","bid":0.48,"ask":0.57,"mid":0.525,"spread":0.09,"price":0.49,"size":0.0,"side":"BUY"}
{"ts":"2026-08-24T20:48:27.538Z","event_type":"price_change","market_id":"3826919","outcome_index":0,"market_type":"set2","local_side":"home","local_uid":"2026-08-24_dalibor_svrcina_felipe_meligeni_alves","bid":0.43,"ask":0.52,"mid":0.475,"spread":0.09,"price":0.51,"size":0.0,"side":"SELL"}
{"ts":"2026-08-24T20:48:27.538Z","event_type":"best_bid_ask","market_id":"3825038","outcome_index":0,"market_type":"set1","local_side":"home","local_uid":"2026-08-24_greet_minnen_jeline_vandromme","bid":0.001,"ask":0.075,"mid":0.038,"spread":0.074,"bid_size":null,"ask_size":null}
{"ts":"2026-08-24T20:48:27.539Z","event_type":"best_bid_ask","market_id":"3825038","outcome_index":1,"market_type":"set1","local_side":"away","local_uid":"2026-08-24_greet_minnen_jeline_vandromme","bid":0.925,"ask":0.999,"mid":0.962,"spread":0.074,"bid_size":null,"ask_size":null}
{"ts":"2026-08-24T20:48:27.539Z","event_type":"price_change","market_id":"3825038","outcome_index":1,"market_type":"set1","local_side":"away","local_uid":"2026-08-24_greet_minnen_jeline_vandromme","bid":0.925,"ask":0.999,"mid":0.962,"spread":0.074,"price":0.925,"size":42.07,"side":"BUY"}
{"ts":"2026-08-24T20:48:27.539Z","event_type":"price_change","market_id":"3825038","outcome_index":0,"market_type":"set1","local_side":"home","local_uid":"2026-08-24_greet_minnen_jeline_vandromme","bid":0.001,"ask":0.075,"mid":0.038,"spread":0.074,"price":0.075,"size":42.07,"side":"SELL"}
{"ts":"2026-08-24T20:48:27.558Z","event_type":"best_bid_ask","market_id":"3825038","outcome_index":0,"market_type":"set1","local_side":"home","local_uid":"2026-08-24_greet_minnen_jeline_vandromme","bid":0.001,"ask":0.065,"mid":0.033,"spread":0.064,"bid_size":null,"ask_size":null}
{"ts":"2026-08-24T20:48:27.559Z","event_type":"best_bid_ask","market_id":"3825038","outcome_index":1,"market_type":"set1","local_side":"away","local_uid":"2026-08-24_greet_minnen_jeline_vandromme","bid":0.935,"ask":0.999,"mid":0.967,"spread":0.064,"bid_size":null,"ask_size":null}
{"ts":"2026-08-24T20:48:27.559Z","event_type":"price_change","market_id":"3825038","outcome_index":1,"market_type":"set1","local_side":"away","local_uid":"2026-08-24_greet_minnen_jeline_vandromme","bid":0.935,"ask":0.999,"mid":0.967,"spread":0.064,"price":0.935,"size":24.6,"side":"BUY"}
{"ts":"2026-08-24T20:48:27.559Z","event_type":"price_change","market_id":"3825038","outcome_index":0,"market_type":"set1","local_side":"home","local_uid":"2026-08-24_greet_minnen_jeline_vandromme","bid":0.001,"ask":0.065,"mid":0.033,"spread":0.064,"price":0.065,"size":24.6,"side":"SELL"}
{"ts":"2026-08-24T20:48:27.632Z","event_type":"best_bid_ask","market_id":"3825038","outcome_index":0,"market_type":"set1","local_side":"home","local_uid":"2026-08-24_greet_minnen_jeline_vandromme","bid":0.001,"ask":0.075,"mid":0.038,"spread":0.074,"bid_size":null,"ask_size":null}
{"ts":"2026-08-24T20:48:27.633Z","event_type":"best_bid_ask","market_id":"3825038","outcome_index":1,"market_type":"set1","local_side":"away","local_uid":"2026-08-24_greet_minnen_jeline_vandromme","bid":0.925,"ask":0.999,"mid":0.962,"spread":0.074,"bid_size":null,"ask_size":null}
{"ts":"2026-08-24T20:48:27.633Z","event_type":"price_change","market_id":"3825038","outcome_index":1,"market_type":"set1","local_side":"away","local_uid":"2026-08-24_greet_minnen_jeline_vandromme","bid":0.925,"ask":0.999,"mid":0.962,"spread":0.074,"price":0.935,"size":0.0,"side":"BUY"}
{"ts":"2026-08-24T20:48:27.633Z","event_type":"price_change","market_id":"3825038","outcome_index":0,"market_type":"set1","local_side":"home","local_uid":"2026-08-24_greet_minnen_jeline_vandromme","bid":0.001,"ask":0.075,"mid":0.038,"spread":0.074,"price":0.065,"size":0.0,"side":"SELL"}
{"ts":"2026-08-24T20:48:27.635Z","event_type":"best_bid_ask","market_id":"3825604","outcome_index":0,"market_type":"match","local_side":"home","local_uid":"2026-08-24_dalibor_svrcina_felipe_meligeni_alves","bid":0.77,"ask":0.79,"mid":0.78,"spread":0.02,"bid_size":null,"ask_size":null}
{"ts":"2026-08-24T20:48:27.635Z","event_type":"best_bid_ask","market_id":"3825604","outcome_index":1,"market_type":"match","local_side":"away","local_uid":"2026-08-24_dalibor_svrcina_felipe_meligeni_alves","bid":0.21,"ask":0.23,"mid":0.22,"spread":0.02,"bid_size":null,"ask_size":null}
{"ts":"2026-08-24T20:48:27.635Z","event_type":"price_change","market_id":"3825604","outcome_index":0,"market_type":"match","local_side":"home","local_uid":"2026-08-24_dalibor_svrcina_felipe_meligeni_alves","bid":0.77,"ask":0.79,"mid":0.78,"spread":0.02,"price":0.78,"size":0.0,"side":"BUY"}
{"ts":"2026-08-24T20:48:27.635Z","event_type":"price_change","market_id":"3825604","outcome_index":1,"market_type":"match","local_side":"away","local_uid":"2026-08-24_dalibor_svrcina_felipe_meligeni_alves","bid":0.21,"ask":0.23,"mid":0.22,"spread":0.02,"price":0.22,"size":0.0,"side":"SELL"}
{"ts":"2026-08-24T20:48:27.650Z","event_type":"best_bid_ask","market_id":"3825038","outcome_index":0,"market_type":"set1","local_side":"home","local_uid":"2026-08-24_greet_minnen_jeline_vandromme","bid":0.001,"ask":0.07,"mid":0.0355,"spread":0.069,"bid_size":null,"ask_size":null}
{"ts":"2026-08-24T20:48:27.650Z","event_type":"best_bid_ask","market_id":"3825038","outcome_index":1,"market_type":"set1","local_side":"away","local_uid":"2026-08-24_greet_minnen_jeline_vandromme","bid":0.93,"ask":0.999,"mid":0.9645,"spread":0.069,"bid_size":null,"ask_size":null}
{"ts":"2026-08-24T20:48:27.650Z","event_type":"price_change","market_id":"3825038","outcome_index":1,"market_type":"set1","local_side":"away","local_uid":"2026-08-24_greet_minnen_jeline_vandromme","bid":0.93,"ask":0.999,"mid":0.9645,"spread":0.069,"price":0.93,"size":44.0,"side":"BUY"}
{"ts":"2026-08-24T20:48:27.651Z","event_type":"price_change","market_id":"3825038","outcome_index":0,"market_type":"set1","local_side":"home","local_uid":"2026-08-24_greet_minnen_jeline_vandromme","bid":0.001,"ask":0.07,"mid":0.0355,"spread":0.069,"price":0.07,"size":44.0,"side":"SELL"}
{"ts":"2026-08-24T20:48:27.675Z","event_type":"best_bid_ask","market_id":"3825038","outcome_index":0,"market_type":"set1","local_side":"home","local_uid":"2026-08-24_greet_minnen_jeline_vandromme","bid":0.001,"ask":0.08,"mid":0.0405,"spread":0.079,"bid_size":null,"ask_size":null}
{"ts":"2026-08-24T20:48:27.675Z","event_type":"best_bid_ask","market_id":"3825038","outcome_index":1,"market_type":"set1","local_side":"away","local_uid":"2026-08-24_greet_minnen_jeline_vandromme","bid":0.92,"ask":0.999,"mid":0.9595,"spread":0.079,"bid_size":null,"ask_size":null}
{"ts":"2026-08-24T20:48:27.676Z","event_type":"price_change","market_id":"3825038","outcome_index":1,"market_type":"set1","local_side":"away","local_uid":"2026-08-24_greet_minnen_jeline_vandromme","bid":0.92,"ask":0.999,"mid":0.9595,"spread":0.079,"price":0.93,"size":0.0,"side":"BUY"}
{"ts":"2026-08-24T20:48:27.676Z","event_type":"price_change","market_id":"3825038","outcome_index":0,"market_type":"set1","local_side":"home","local_uid":"2026-08-24_greet_minnen_jeline_vandromme","bid":0.001,"ask":0.08,"mid":0.0405,"spread":0.079,"price":0.07,"size":0.0,"side":"SELL"}
{"ts":"2026-08-24T20:48:27.679Z","event_type":"best_bid_ask","market_id":"3825038","outcome_index":0,"market_type":"set1","local_side":"home","local_uid":"2026-08-24_greet_minnen_jeline_vandromme","bid":0.001,"ask":0.09,"mid":0.0455,"spread":0.089,"bid_size":null,"ask_size":null}
{"ts":"2026-08-24T20:48:27.679Z","event_type":"best_bid_ask","market_id":"3825038","outcome_index":1,"market_type":"set1","local_side":"away","local_uid":"2026-08-24_greet_minnen_jeline_vandromme","bid":0.91,"ask":0.999,"mid":0.9545,"spread":0.089,"bid_size":null,"ask_size":null}
{"ts":"2026-08-24T20:48:27.680Z","event_type":"price_change","market_id":"3825038","outcome_index":1,"market_type":"set1","local_side":"away","local_uid":"2026-08-24_greet_minnen_jeline_vandromme","bid":0.91,"ask":0.999,"mid":0.9545,"spread":0.089,"price":0.92,"size":0.0,"side":"BUY"}
{"ts":"2026-08-24T20:48:27.680Z","event_type":"price_change","market_id":"3825038","outcome_index":0,"market_type":"set1","local_side":"home","local_uid":"2026-08-24_greet_minnen_jeline_vandromme","bid":0.001,"ask":0.09,"mid":0.0455,"spread":0.089,"price":0.08,"size":0.0,"side":"SELL"}
{"ts":"2026-08-24T20:48:27.680Z","event_type":"best_bid_ask","market_id":"3825038","outcome_index":0,"market_type":"set1","local_side":"home","local_uid":"2026-08-24_greet_minnen_jeline_vandromme","bid":0.001,"ask":0.054,"mid":0.0275,"spread":0.053,"bid_size":null,"ask_size":null}
{"ts":"2026-08-24T20:48:27.680Z","event_type":"best_bid_ask","market_id":"3825038","outcome_index":1,"market_type":"set1","local_side":"away","local_uid":"2026-08-24_greet_minnen_jeline_vandromme","bid":0.946,"ask":0.999,"mid":0.9725,"spread":0.053,"bid_size":null,"ask_size":null}
{"ts":"2026-08-24T20:48:27.681Z","event_type":"price_change","market_id":"3825038","outcome_index":1,"market_type":"set1","local_side":"away","local_uid":"2026-08-24_greet_minnen_jeline_vandromme","bid":0.946,"ask":0.999,"mid":0.9725,"spread":0.053,"price":0.946,"size":18.0,"side":"BUY"}
{"ts":"2026-08-24T20:48:27.681Z","event_type":"price_change","market_id":"3825038","outcome_index":0,"market_type":"set1","local_side":"home","local_uid":"2026-08-24_greet_minnen_jeline_vandromme","bid":0.001,"ask":0.054,"mid":0.0275,"spread":0.053,"price":0.054,"size":18.0,"side":"SELL"}
{"ts":"2026-08-24T20:48:27.696Z","event_type":"best_bid_ask","market_id":"3825604","outcome_index":0,"market_type":"match","local_side":"home","local_uid":"2026-08-24_dalibor_svrcina_felipe_meligeni_alves","bid":0.77,"ask":0.78,"mid":0.775,"spread":0.01,"bid_size":null,"ask_size":null}
{"ts":"2026-08-24T20:48:27.696Z","event_type":"best_bid_ask","market_id":"3825604","outcome_index":1,"market_type":"match","local_side":"away","local_uid":"2026-08-24_dalibor_svrcina_felipe_meligeni_alves","bid":0.22,"ask":0.23,"mid":0.225,"spread":0.01,"bid_size":null,"ask_size":null}
{"ts":"2026-08-24T20:48:27.696Z","event_type":"price_change","market_id":"3825604","outcome_index":1,"market_type":"match","local_side":"away","local_uid":"2026-08-24_dalibor_svrcina_felipe_meligeni_alves","bid":0.22,"ask":0.23,"mid":0.225,"spread":0.01,"price":0.22,"size":708.71,"side":"BUY"}
{"ts":"2026-08-24T20:48:27.697Z","event_type":"price_change","market_id":"3825604","outcome_index":0,"market_type":"match","local_side":"home","local_uid":"2026-08-24_dalibor_svrcina_felipe_meligeni_alves","bid":0.77,"ask":0.78,"mid":0.775,"spread":0.01,"price":0.78,"size":708.71,"side":"SELL"}
{"ts":"2026-08-24T20:48:27.719Z","event_type":"best_bid_ask","market_id":"3825038","outcome_index":0,"market_type":"set1","local_side":"home","local_uid":"2026-08-24_greet_minnen_jeline_vandromme","bid":0.001,"ask":0.09,"mid":0.0455,"spread":0.089,"bid_size":null,"ask_size":null}
{"ts":"2026-08-24T20:48:27.719Z","event_type":"best_bid_ask","market_id":"3825038","outcome_index":1,"market_type":"set1","local_side":"away","local_uid":"2026-08-24_greet_minnen_jeline_vandromme","bid":0.91,"ask":0.999,"mid":0.9545,"spread":0.089,"bid_size":null,"ask_size":null}
{"ts":"2026-08-24T20:48:27.720Z","event_type":"price_change","market_id":"3825038","outcome_index":1,"market_type":"set1","local_side":"away","local_uid":"2026-08-24_greet_minnen_jeline_vandromme","bid":0.91,"ask":0.999,"mid":0.9545,"spread":0.089,"price":0.946,"size":0.0,"side":"BUY"}
{"ts":"2026-08-24T20:48:27.720Z","event_type":"price_change","market_id":"3825038","outcome_index":0,"market_type":"set1","local_side":"home","local_uid":"2026-08-24_greet_minnen_jeline_vandromme","bid":0.001,"ask":0.09,"mid":0.0455,"spread":0.089,"price":0.054,"size":0.0,"side":"SELL"}
{"ts":"2026-08-24T20:48:27.730Z","event_type":"best_bid_ask","market_id":"3825038","outcome_index":0,"market_type":"set1","local_side":"home","local_uid":"2026-08-24_greet_minnen_jeline_vandromme","bid":0.001,"ask":0.1,"mid":0.0505,"spread":0.099,"bid_size":null,"ask_size":null}
{"ts":"2026-08-24T20:48:27.730Z","event_type":"best_bid_ask","market_id":"3825038","outcome_index":1,"market_type":"set1","local_side":"away","local_uid":"2026-08-24_greet_minnen_jeline_vandromme","bid":0.9,"ask":0.999,"mid":0.9495,"spread":0.099,"bid_size":null,"ask_size":null}
{"ts":"2026-08-24T20:48:27.731Z","event_type":"price_change","market_id":"3825038","outcome_index":1,"market_type":"set1","local_side":"away","local_uid":"2026-08-24_greet_minnen_jeline_vandromme","bid":0.9,"ask":0.999,"mid":0.9495,"spread":0.099,"price":0.91,"size":0.0,"side":"BUY"}
{"ts":"2026-08-24T20:48:27.731Z","event_type":"price_change","market_id":"3825038","outcome_index":0,"market_type":"set1","local_side":"home","local_uid":"2026-08-24_greet_minnen_jeline_vandromme","bid":0.001,"ask":0.1,"mid":0.0505,"spread":0.099,"price":0.09,"size":0.0,"side":"SELL"}
{"ts":"2026-08-24T20:48:27.763Z","event_type":"best_bid_ask","market_id":"3825038","outcome_index":0,"market_type":"set1","local_side":"home","local_uid":"2026-08-24_greet_minnen_jeline_vandromme","bid":0.001,"ask":0.086,"mid":0.0435,"spread":0.085,"bid_size":null,"ask_size":null}
{"ts":"2026-08-24T20:48:27.763Z","event_type":"best_bid_ask","market_id":"3825038","outcome_index":1,"market_type":"set1","local_side":"away","local_uid":"2026-08-24_greet_minnen_jeline_vandromme","bid":0.914,"ask":0.999,"mid":0.9565,"spread":0.085,"bid_size":null,"ask_size":null}
{"ts":"2026-08-24T20:48:27.763Z","event_type":"price_change","market_id":"3825038","outcome_index":1,"market_type":"set1","local_side":"away","local_uid":"2026-08-24_greet_minnen_jeline_vandromme","bid":0.914,"ask":0.999,"mid":0.9565,"spread":0.085,"price":0.914,"size":43.2,"side":"BUY"}
{"ts":"2026-08-24T20:48:27.764Z","event_type":"price_change","market_id":"3825038","outcome_index":0,"market_type":"set1","local_side":"home","local_uid":"2026-08-24_greet_minnen_jeline_vandromme","bid":0.001,"ask":0.086,"mid":0.0435,"spread":0.085,"price":0.086,"size":43.2,"side":"SELL"}
{"ts":"2026-08-24T20:48:27.801Z","event_type":"best_bid_ask","market_id":"3825038","outcome_index":0,"market_type":"set1","local_side":"home","local_uid":"2026-08-24_greet_minnen_jeline_vandromme","bid":0.001,"ask":0.1,"mid":0.0505,"spread":0.099,"bid_size":null,"ask_size":null}
{"ts":"2026-08-24T20:48:27.802Z","event_type":"best_bid_ask","market_id":"3825038","outcome_index":1,"market_type":"set1","local_side":"away","local_uid":"2026-08-24_greet_minnen_jeline_vandromme","bid":0.9,"ask":0.999,"mid":0.9495,"spread":0.099,"bid_size":null,"ask_size":null}
{"ts":"2026-08-24T20:48:27.802Z","event_type":"price_change","market_id":"3825038","outcome_index":1,"market_type":"set1","local_side":"away","local_uid":"2026-08-24_greet_minnen_jeline_vandromme","bid":0.9,"ask":0.999,"mid":0.9495,"spread":0.099,"price":0.914,"size":0.0,"side":"BUY"}
{"ts":"2026-08-24T20:48:27.802Z","event_type":"price_change","market_id":"3825038","outcome_index":0,"market_type":"set1","local_side":"home","local_uid":"2026-08-24_greet_minnen_jeline_vandromme","bid":0.001,"ask":0.1,"mid":0.0505,"spread":0.099,"price":0.086,"size":0.0,"side":"SELL"}
{"ts":"2026-08-24T20:48:27.922Z","event_type":"best_bid_ask","market_id":"3825038","outcome_index":0,"market_type":"set1","local_side":"home","local_uid":"2026-08-24_greet_minnen_jeline_vandromme","bid":0.001,"ask":0.09,"mid":0.0455,"spread":0.089,"bid_size":null,"ask_size":null}
{"ts":"2026-08-24T20:48:27.922Z","event_type":"best_bid_ask","market_id":"3825038","outcome_index":1,"market_type":"set1","local_side":"away","local_uid":"2026-08-24_greet_minnen_jeline_vandromme","bid":0.91,"ask":0.999,"mid":0.9545,"spread":0.089,"bid_size":null,"ask_size":null}
{"ts":"2026-08-24T20:48:27.922Z","event_type":"price_change","market_id":"3825038","outcome_index":1,"market_type":"set1","local_side":"away","local_uid":"2026-08-24_greet_minnen_jeline_vandromme","bid":0.91,"ask":0.999,"mid":0.9545,"spread":0.089,"price":0.91,"size":88.0,"side":"BUY"}
{"ts":"2026-08-24T20:48:27.922Z","event_type":"price_change","market_id":"3825038","outcome_index":0,"market_type":"set1","local_side":"home","local_uid":"2026-08-24_greet_minnen_jeline_vandromme","bid":0.001,"ask":0.09,"mid":0.0455,"spread":0.089,"price":0.09,"size":88.0,"side":"SELL"}
{"ts":"2026-08-24T20:48:27.956Z","event_type":"best_bid_ask","market_id":"3825038","outcome_index":0,"market_type":"set1","local_side":"home","local_uid":"2026-08-24_greet_minnen_jeline_vandromme","bid":0.001,"ask":0.1,"mid":0.0505,"spread":0.099,"bid_size":null,"ask_size":null}
{"ts":"2026-08-24T20:48:27.956Z","event_type":"best_bid_ask","market_id":"3825038","outcome_index":1,"market_type":"set1","local_side":"away","local_uid":"2026-08-24_greet_minnen_jeline_vandromme","bid":0.9,"ask":0.999,"mid":0.9495,"spread":0.099,"bid_size":null,"ask_size":null}
{"ts":"2026-08-24T20:48:27.956Z","event_type":"price_change","market_id":"3825038","outcome_index":1,"market_type":"set1","local_side":"away","local_uid":"2026-08-24_greet_minnen_jeline_vandromme","bid":0.9,"ask":0.999,"mid":0.9495,"spread":0.099,"price":0.91,"size":0.0,"side":"BUY"}
{"ts":"2026-08-24T20:48:27.956Z","event_type":"price_change","market_id":"3825038","outcome_index":0,"market_type":"set1","local_side":"home","local_uid":"2026-08-24_greet_minnen_jeline_vandromme","bid":0.001,"ask":0.1,"mid":0.0505,"spread":0.099,"price":0.09,"size":0.0,"side":"SELL"}
{"ts":"2026-08-24T20:48:27.959Z","event_type":"best_bid_ask","market_id":"3825038","outcome_index":0,"market_type":"set1","local_side":"home","local_uid":"2026-08-24_greet_minnen_jeline_vandromme","bid":0.001,"ask":0.08,"mid":0.0405,"spread":0.079,"bid_size":null,"ask_size":null}
{"ts":"2026-08-24T20:48:27.959Z","event_type":"best_bid_ask","market_id":"3825038","outcome_index":1,"market_type":"set1","local_side":"away","local_uid":"2026-08-24_greet_minnen_jeline_vandromme","bid":0.92,"ask":0.999,"mid":0.9595,"spread":0.079,"bid_size":null,"ask_size":null}
{"ts":"2026-08-24T20:48:27.960Z","event_type":"price_change","market_id":"3825038","outcome_index":1,"market_type":"set1","local_side":"away","local_uid":"2026-08-24_greet_minnen_jeline_vandromme","bid":0.92,"ask":0.999,"mid":0.9595,"spread":0.079,"price":0.92,"size":44.0,"side":"BUY"}
{"ts":"2026-08-24T20:48:27.960Z","event_type":"price_change","market_id":"3825038","outcome_index":0,"market_type":"set1","local_side":"home","local_uid":"2026-08-24_greet_minnen_jeline_vandromme","bid":0.001,"ask":0.08,"mid":0.0405,"spread":0.079,"price":0.08,"size":44.0,"side":"SELL"}
{"ts":"2026-08-24T20:48:27.981Z","event_type":"best_bid_ask","market_id":"3824761","outcome_index":0,"market_type":"set1","local_side":"home","local_uid":"2026-08-24_jazmin_ortenzi_himeno_sakatsume","bid":0.13,"ask":0.29,"mid":0.21,"spread":0.16,"bid_size":null,"ask_size":null}
{"ts":"2026-08-24T20:48:27.981Z","event_type":"best_bid_ask","market_id":"3824761","outcome_index":1,"market_type":"set1","local_side":"away","local_uid":"2026-08-24_jazmin_ortenzi_himeno_sakatsume","bid":0.71,"ask":0.87,"mid":0.79,"spread":0.16,"bid_size":null,"ask_size":null}
{"ts":"2026-08-24T20:48:27.983Z","event_type":"price_change","market_id":"3824761","outcome_index":0,"market_type":"set1","local_side":"home","local_uid":"2026-08-24_jazmin_ortenzi_himeno_sakatsume","bid":0.13,"ask":0.29,"mid":0.21,"spread":0.16,"price":0.14,"size":0.0,"side":"BUY"}
{"ts":"2026-08-24T20:48:27.983Z","event_type":"price_change","market_id":"3824761","outcome_index":1,"market_type":"set1","local_side":"away","local_uid":"2026-08-24_jazmin_ortenzi_himeno_sakatsume","bid":0.71,"ask":0.87,"mid":0.79,"spread":0.16,"price":0.86,"size":0.0,"side":"SELL"}
{"ts":"2026-08-24T20:48:27.999Z","event_type":"best_bid_ask","market_id":"3826919","outcome_index":0,"market_type":"set2","local_side":"home","local_uid":"2026-08-24_dalibor_svrcina_felipe_meligeni_alves","bid":0.43,"ask":0.51,"mid":0.47,"spread":0.08,"bid_size":null,"ask_size":null}
{"ts":"2026-08-24T20:48:27.999Z","event_type":"best_bid_ask","market_id":"3826919","outcome_index":1,"market_type":"set2","local_side":"away","local_uid":"2026-08-24_dalibor_svrcina_felipe_meligeni_alves","bid":0.49,"ask":0.57,"mid":0.53,"spread":0.08,"bid_size":null,"ask_size":null}
{"ts":"2026-08-24T20:48:28.001Z","event_type":"price_change","market_id":"3826919","outcome_index":1,"market_type":"set2","local_side":"away","local_uid":"2026-08-24_dalibor_svrcina_felipe_meligeni_alves","bid":0.49,"ask":0.57,"mid":0.53,"spread":0.08,"price":0.49,"size":24.6,"side":"BUY"}
{"ts":"2026-08-24T20:48:28.002Z","event_type":"price_change","market_id":"3826919","outcome_index":0,"market_type":"set2","local_side":"home","local_uid":"2026-08-24_dalibor_svrcina_felipe_meligeni_alves","bid":0.43,"ask":0.51,"mid":0.47,"spread":0.08,"price":0.51,"size":24.6,"side":"SELL"}
{"ts":"2026-08-24T20:48:28.034Z","event_type":"best_bid_ask","market_id":"3825038","outcome_index":0,"market_type":"set1","local_side":"home","local_uid":"2026-08-24_greet_minnen_jeline_vandromme","bid":0.001,"ask":0.05,"mid":0.0255,"spread":0.049,"bid_size":null,"ask_size":null}
{"ts":"2026-08-24T20:48:28.039Z","event_type":"best_bid_ask","market_id":"3825038","outcome_index":1,"market_type":"set1","local_side":"away","local_uid":"2026-08-24_greet_minnen_jeline_vandromme","bid":0.95,"ask":0.999,"mid":0.9745,"spread":0.049,"bid_size":null,"ask_size":null}
{"ts":"2026-08-24T20:48:28.040Z","event_type":"price_change","market_id":"3825038","outcome_index":1,"market_type":"set1","local_side":"away","local_uid":"2026-08-24_greet_minnen_jeline_vandromme","bid":0.95,"ask":0.999,"mid":0.9745,"spread":0.049,"price":0.95,"size":423.0,"side":"BUY"}
{"ts":"2026-08-24T20:48:28.040Z","event_type":"price_change","market_id":"3825038","outcome_index":0,"market_type":"set1","local_side":"home","local_uid":"2026-08-24_greet_minnen_jeline_vandromme","bid":0.001,"ask":0.05,"mid":0.0255,"spread":0.049,"price":0.05,"size":423.0,"side":"SELL"}
{"ts":"2026-08-24T20:48:28.041Z","event_type":"best_bid_ask","market_id":"3825038","outcome_index":0,"market_type":"set1","local_side":"home","local_uid":"2026-08-24_greet_minnen_jeline_vandromme","bid":0.001,"ask":0.04,"mid":0.0205,"spread":0.039,"bid_size":null,"ask_size":null}
{"ts":"2026-08-24T20:48:28.041Z","event_type":"best_bid_ask","market_id":"3825038","outcome_index":1,"market_type":"set1","local_side":"away","local_uid":"2026-08-24_greet_minnen_jeline_vandromme","bid":0.96,"ask":0.999,"mid":0.9795,"spread":0.039,"bid_size":null,"ask_size":null}
{"ts":"2026-08-24T20:48:28.041Z","event_type":"price_change","market_id":"3825038","outcome_index":1,"market_type":"set1","local_side":"away","local_uid":"2026-08-24_greet_minnen_jeline_vandromme","bid":0.96,"ask":0.999,"mid":0.9795,"spread":0.039,"price":0.96,"size":88.0,"side":"BUY"}
{"ts":"2026-08-24T20:48:28.042Z","event_type":"price_change","market_id":"3825038","outcome_index":0,"market_type":"set1","local_side":"home","local_uid":"2026-08-24_greet_minnen_jeline_vandromme","bid":0.001,"ask":0.04,"mid":0.0205,"spread":0.039,"price":0.04,"size":88.0,"side":"SELL"}
{"ts":"2026-08-24T20:48:28.058Z","event_type":"best_bid_ask","market_id":"3826919","outcome_index":0,"market_type":"set2","local_side":"home","local_uid":"2026-08-24_dalibor_svrcina_felipe_meligeni_alves","bid":0.43,"ask":0.52,"mid":0.475,"spread":0.09,"bid_size":null,"ask_size":null}
{"ts":"2026-08-24T20:48:28.058Z","event_type":"best_bid_ask","market_id":"3826919","outcome_index":1,"market_type":"set2","local_side":"away","local_uid":"2026-08-24_dalibor_svrcina_felipe_meligeni_alves","bid":0.48,"ask":0.57,"mid":0.525,"spread":0.09,"bid_size":null,"ask_size":null}
{"ts":"2026-08-24T20:48:28.058Z","event_type":"price_change","market_id":"3826919","outcome_index":1,"market_type":"set2","local_side":"away","local_uid":"2026-08-24_dalibor_svrcina_felipe_meligeni_alves","bid":0.48,"ask":0.57,"mid":0.525,"spread":0.09,"price":0.49,"size":0.0,"side":"BUY"}
{"ts":"2026-08-24T20:48:28.059Z","event_type":"price_change","market_id":"3826919","outcome_index":0,"market_type":"set2","local_side":"home","local_uid":"2026-08-24_dalibor_svrcina_felipe_meligeni_alves","bid":0.43,"ask":0.52,"mid":0.475,"spread":0.09,"price":0.51,"size":0.0,"side":"SELL"}
{"ts":"2026-08-24T20:48:28.083Z","event_type":"best_bid_ask","market_id":"3825040","outcome_index":0,"market_type":"set2","local_side":"home","local_uid":"2026-08-24_greet_minnen_jeline_vandromme","bid":0.27,"ask":0.39,"mid":0.33,"spread":0.12,"bid_size":null,"ask_size":null}
{"ts":"2026-08-24T20:48:28.083Z","event_type":"best_bid_ask","market_id":"3825040","outcome_index":1,"market_type":"set2","local_side":"away","local_uid":"2026-08-24_greet_minnen_jeline_vandromme","bid":0.61,"ask":0.73,"mid":0.67,"spread":0.12,"bid_size":null,"ask_size":null}
{"ts":"2026-08-24T20:48:28.084Z","event_type":"price_change","market_id":"3825040","outcome_index":1,"market_type":"set2","local_side":"away","local_uid":"2026-08-24_greet_minnen_jeline_vandromme","bid":0.61,"ask":0.73,"mid":0.67,"spread":0.12,"price":0.61,"size":150.0,"side":"BUY"}
{"ts":"2026-08-24T20:48:28.084Z","event_type":"price_change","market_id":"3825040","outcome_index":0,"market_type":"set2","local_side":"home","local_uid":"2026-08-24_greet_minnen_jeline_vandromme","bid":0.27,"ask":0.39,"mid":0.33,"spread":0.12,"price":0.39,"size":150.0,"side":"SELL"}
{"ts":"2026-08-24T20:48:28.217Z","event_type":"best_bid_ask","market_id":"3825040","outcome_index":0,"market_type":"set2","local_side":"home","local_uid":"2026-08-24_greet_minnen_jeline_vandromme","bid":0.28,"ask":0.39,"mid":0.335,"spread":0.11,"bid_size":null,"ask_size":null}
{"ts":"2026-08-24T20:48:28.218Z","event_type":"best_bid_ask","market_id":"3825040","outcome_index":1,"market_type":"set2","local_side":"away","local_uid":"2026-08-24_greet_minnen_jeline_vandromme","bid":0.61,"ask":0.72,"mid":0.665,"spread":0.11,"bid_size":null,"ask_size":null}
{"ts":"2026-08-24T20:48:28.218Z","event_type":"price_change","market_id":"3825040","outcome_index":0,"market_type":"set2","local_side":"home","local_uid":"2026-08-24_greet_minnen_jeline_vandromme","bid":0.28,"ask":0.39,"mid":0.335,"spread":0.11,"price":0.28,"size":150.0,"side":"BUY"}
{"ts":"2026-08-24T20:48:28.218Z","event_type":"price_change","market_id":"3825040","outcome_index":1,"market_type":"set2","local_side":"away","local_uid":"2026-08-24_greet_minnen_jeline_vandromme","bid":0.61,"ask":0.72,"mid":0.665,"spread":0.11,"price":0.72,"size":150.0,"side":"SELL"}
{"ts":"2026-08-24T20:48:28.283Z","event_type":"best_bid_ask","market_id":"3826919","outcome_index":0,"market_type":"set2","local_side":"home","local_uid":"2026-08-24_dalibor_svrcina_felipe_meligeni_alves","bid":0.43,"ask":0.51,"mid":0.47,"spread":0.08,"bid_size":null,"ask_size":null}
{"ts":"2026-08-24T20:48:28.283Z","event_type":"best_bid_ask","market_id":"3826919","outcome_index":1,"market_type":"set2","local_side":"away","local_uid":"2026-08-24_dalibor_svrcina_felipe_meligeni_alves","bid":0.49,"ask":0.57,"mid":0.53,"spread":0.08,"bid_size":null,"ask_size":null}
{"ts":"2026-08-24T20:48:28.284Z","event_type":"price_change","market_id":"3826919","outcome_index":1,"market_type":"set2","local_side":"away","local_uid":"2026-08-24_dalibor_svrcina_felipe_meligeni_alves","bid":0.49,"ask":0.57,"mid":0.53,"spread":0.08,"price":0.49,"size":24.6,"side":"BUY"}
{"ts":"2026-08-24T20:48:28.284Z","event_type":"price_change","market_id":"3826919","outcome_index":0,"market_type":"set2","local_side":"home","local_uid":"2026-08-24_dalibor_svrcina_felipe_meligeni_alves","bid":0.43,"ask":0.51,"mid":0.47,"spread":0.08,"price":0.51,"size":24.6,"side":"SELL"}
{"ts":"2026-08-24T20:48:28.314Z","event_type":"best_bid_ask","market_id":"3826919","outcome_index":0,"market_type":"set2","local_side":"home","local_uid":"2026-08-24_dalibor_svrcina_felipe_meligeni_alves","bid":0.43,"ask":0.52,"mid":0.475,"spread":0.09,"bid_size":null,"ask_size":null}
{"ts":"2026-08-24T20:48:28.314Z","event_type":"best_bid_ask","market_id":"3826919","outcome_index":1,"market_type":"set2","local_side":"away","local_uid":"2026-08-24_dalibor_svrcina_felipe_meligeni_alves","bid":0.48,"ask":0.57,"mid":0.525,"spread":0.09,"bid_size":null,"ask_size":null}
{"ts":"2026-08-24T20:48:28.321Z","event_type":"price_change","market_id":"3826919","outcome_index":1,"market_type":"set2","local_side":"away","local_uid":"2026-08-24_dalibor_svrcina_felipe_meligeni_alves","bid":0.48,"ask":0.57,"mid":0.525,"spread":0.09,"price":0.49,"size":0.0,"side":"BUY"}
{"ts":"2026-08-24T20:48:28.321Z","event_type":"price_change","market_id":"3826919","outcome_index":0,"market_type":"set2","local_side":"home","local_uid":"2026-08-24_dalibor_svrcina_felipe_meligeni_alves","bid":0.43,"ask":0.52,"mid":0.475,"spread":0.09,"price":0.51,"size":0.0,"side":"SELL"}
{"ts":"2026-08-24T20:48:28.349Z","event_type":"best_bid_ask","market_id":"3824875","outcome_index":0,"market_type":"set2","local_side":"home","local_uid":"2026-08-24_eva_vedder_bianca_andreescu","bid":0.22,"ask":0.25,"mid":0.235,"spread":0.03,"bid_size":null,"ask_size":null}
{"ts":"2026-08-24T20:48:28.350Z","event_type":"best_bid_ask","market_id":"3824875","outcome_index":1,"market_type":"set2","local_side":"away","local_uid":"2026-08-24_eva_vedder_bianca_andreescu","bid":0.75,"ask":0.78,"mid":0.765,"spread":0.03,"bid_size":null,"ask_size":null}
{"ts":"2026-08-24T20:48:28.350Z","event_type":"price_change","market_id":"3824875","outcome_index":1,"market_type":"set2","local_side":"away","local_uid":"2026-08-24_eva_vedder_bianca_andreescu","bid":0.75,"ask":0.78,"mid":0.765,"spread":0.03,"price":0.78,"size":50.0,"side":"SELL"}
{"ts":"2026-08-24T20:48:28.350Z","event_type":"price_change","market_id":"3824875","outcome_index":0,"market_type":"set2","local_side":"home","local_uid":"2026-08-24_eva_vedder_bianca_andreescu","bid":0.22,"ask":0.25,"mid":0.235,"spread":0.03,"price":0.22,"size":50.0,"side":"BUY"}
{"ts":"2026-08-24T20:48:28.416Z","event_type":"best_bid_ask","market_id":"3826654","outcome_index":0,"market_type":"set2","local_side":"home","local_uid":"2026-08-24_sebastian_gorzny_cruz_hewitt","bid":0.05,"ask":0.13,"mid":0.09,"spread":0.08,"bid_size":null,"ask_size":null}
{"ts":"2026-08-24T20:48:28.417Z","event_type":"best_bid_ask","market_id":"3826654","outcome_index":1,"market_type":"set2","local_side":"away","local_uid":"2026-08-24_sebastian_gorzny_cruz_hewitt","bid":0.87,"ask":0.95,"mid":0.91,"spread":0.08,"bid_size":null,"ask_size":null}
{"ts":"2026-08-24T20:48:28.417Z","event_type":"price_change","market_id":"3826654","outcome_index":0,"market_type":"set2","local_side":"home","local_uid":"2026-08-24_sebastian_gorzny_cruz_hewitt","bid":0.05,"ask":0.13,"mid":0.09,"spread":0.08,"price":0.05,"size":44.0,"side":"BUY"}
{"ts":"2026-08-24T20:48:28.417Z","event_type":"price_change","market_id":"3826654","outcome_index":1,"market_type":"set2","local_side":"away","local_uid":"2026-08-24_sebastian_gorzny_cruz_hewitt","bid":0.87,"ask":0.95,"mid":0.91,"spread":0.08,"price":0.95,"size":44.0,"side":"SELL"}
{"ts":"2026-08-24T20:48:28.476Z","event_type":"best_bid_ask","market_id":"3826654","outcome_index":0,"market_type":"set2","local_side":"home","local_uid":"2026-08-24_sebastian_gorzny_cruz_hewitt","bid":0.06,"ask":0.13,"mid":0.095,"spread":0.07,"bid_size":null,"ask_size":null}
{"ts":"2026-08-24T20:48:28.477Z","event_type":"best_bid_ask","market_id":"3826654","outcome_index":1,"market_type":"set2","local_side":"away","local_uid":"2026-08-24_sebastian_gorzny_cruz_hewitt","bid":0.87,"ask":0.94,"mid":0.905,"spread":0.07,"bid_size":null,"ask_size":null}
{"ts":"2026-08-24T20:48:28.477Z","event_type":"price_change","market_id":"3826654","outcome_index":0,"market_type":"set2","local_side":"home","local_uid":"2026-08-24_sebastian_gorzny_cruz_hewitt","bid":0.06,"ask":0.13,"mid":0.095,"spread":0.07,"price":0.06,"size":22.0,"side":"BUY"}
{"ts":"2026-08-24T20:48:28.477Z","event_type":"price_change","market_id":"3826654","outcome_index":1,"market_type":"set2","local_side":"away","local_uid":"2026-08-24_sebastian_gorzny_cruz_hewitt","bid":0.87,"ask":0.94,"mid":0.905,"spread":0.07,"price":0.94,"size":22.0,"side":"SELL"}
{"ts":"2026-08-24T20:48:28.500Z","event_type":"price_change","market_id":"3825606","outcome_index":0,"market_type":"match","local_side":"home","local_uid":"2026-08-24_keegan_smith_alexis_galarneau","bid":0.43,"ask":0.44,"mid":0.435,"spread":0.01,"price":0.27,"size":55.0,"side":"BUY"}
{"ts":"2026-08-24T20:48:28.500Z","event_type":"price_change","market_id":"3825606","outcome_index":1,"market_type":"match","local_side":"away","local_uid":"2026-08-24_keegan_smith_alexis_galarneau","bid":0.56,"ask":0.57,"mid":0.565,"spread":0.01,"price":0.73,"size":55.0,"side":"SELL"}
{"ts":"2026-08-24T20:48:28.647Z","event_type":"best_bid_ask","market_id":"3826919","outcome_index":0,"market_type":"set2","local_side":"home","local_uid":"2026-08-24_dalibor_svrcina_felipe_meligeni_alves","bid":0.43,"ask":0.51,"mid":0.47,"spread":0.08,"bid_size":null,"ask_size":null}
{"ts":"2026-08-24T20:48:28.648Z","event_type":"best_bid_ask","market_id":"3826919","outcome_index":1,"market_type":"set2","local_side":"away","local_uid":"2026-08-24_dalibor_svrcina_felipe_meligeni_alves","bid":0.49,"ask":0.57,"mid":0.53,"spread":0.08,"bid_size":null,"ask_size":null}
{"ts":"2026-08-24T20:48:28.648Z","event_type":"price_change","market_id":"3826919","outcome_index":1,"market_type":"set2","local_side":"away","local_uid":"2026-08-24_dalibor_svrcina_felipe_meligeni_alves","bid":0.49,"ask":0.57,"mid":0.53,"spread":0.08,"price":0.49,"size":24.6,"side":"BUY"}
{"ts":"2026-08-24T20:48:28.648Z","event_type":"price_change","market_id":"3826919","outcome_index":0,"market_type":"set2","local_side":"home","local_uid":"2026-08-24_dalibor_svrcina_felipe_meligeni_alves","bid":0.43,"ask":0.51,"mid":0.47,"spread":0.08,"price":0.51,"size":24.6,"side":"SELL"}
{"ts":"2026-08-24T20:48:28.685Z","event_type":"best_bid_ask","market_id":"3826919","outcome_index":0,"market_type":"set2","local_side":"home","local_uid":"2026-08-24_dalibor_svrcina_felipe_meligeni_alves","bid":0.43,"ask":0.52,"mid":0.475,"spread":0.09,"bid_size":null,"ask_size":null}
{"ts":"2026-08-24T20:48:28.685Z","event_type":"best_bid_ask","market_id":"3826919","outcome_index":1,"market_type":"set2","local_side":"away","local_uid":"2026-08-24_dalibor_svrcina_felipe_meligeni_alves","bid":0.48,"ask":0.57,"mid":0.525,"spread":0.09,"bid_size":null,"ask_size":null}
{"ts":"2026-08-24T20:48:28.686Z","event_type":"price_change","market_id":"3826919","outcome_index":1,"market_type":"set2","local_side":"away","local_uid":"2026-08-24_dalibor_svrcina_felipe_meligeni_alves","bid":0.48,"ask":0.57,"mid":0.525,"spread":0.09,"price":0.49,"size":0.0,"side":"BUY"}
{"ts":"2026-08-24T20:48:28.686Z","event_type":"price_change","market_id":"3826919","outcome_index":0,"market_type":"set2","local_side":"home","local_uid":"2026-08-24_dalibor_svrcina_felipe_meligeni_alves","bid":0.43,"ask":0.52,"mid":0.475,"spread":0.09,"price":0.51,"size":0.0,"side":"SELL"}
{"ts":"2026-08-24T20:48:28.717Z","event_type":"best_bid_ask","market_id":"3826919","outcome_index":0,"market_type":"set2","local_side":"home","local_uid":"2026-08-24_dalibor_svrcina_felipe_meligeni_alves","bid":0.43,"ask":0.51,"mid":0.47,"spread":0.08,"bid_size":null,"ask_size":null}
{"ts":"2026-08-24T20:48:28.718Z","event_type":"best_bid_ask","market_id":"3826919","outcome_index":1,"market_type":"set2","local_side":"away","local_uid":"2026-08-24_dalibor_svrcina_felipe_meligeni_alves","bid":0.49,"ask":0.57,"mid":0.53,"spread":0.08,"bid_size":null,"ask_size":null}
{"ts":"2026-08-24T20:48:28.718Z","event_type":"price_change","market_id":"3826919","outcome_index":1,"market_type":"set2","local_side":"away","local_uid":"2026-08-24_dalibor_svrcina_felipe_meligeni_alves","bid":0.49,"ask":0.57,"mid":0.53,"spread":0.08,"price":0.49,"size":24.6,"side":"BUY"}
{"ts":"2026-08-24T20:48:28.719Z","event_type":"price_change","market_id":"3826919","outcome_index":0,"market_type":"set2","local_side":"home","local_uid":"2026-08-24_dalibor_svrcina_felipe_meligeni_alves","bid":0.43,"ask":0.51,"mid":0.47,"spread":0.08,"price":0.51,"size":24.6,"side":"SELL"}
{"ts":"2026-08-24T20:48:28.754Z","event_type":"best_bid_ask","market_id":"3826919","outcome_index":0,"market_type":"set2","local_side":"home","local_uid":"2026-08-24_dalibor_svrcina_felipe_meligeni_alves","bid":0.43,"ask":0.52,"mid":0.475,"spread":0.09,"bid_size":null,"ask_size":null}
{"ts":"2026-08-24T20:48:28.754Z","event_type":"best_bid_ask","market_id":"3826919","outcome_index":1,"market_type":"set2","local_side":"away","local_uid":"2026-08-24_dalibor_svrcina_felipe_meligeni_alves","bid":0.48,"ask":0.57,"mid":0.525,"spread":0.09,"bid_size":null,"ask_size":null}
{"ts":"2026-08-24T20:48:28.755Z","event_type":"price_change","market_id":"3826919","outcome_index":1,"market_type":"set2","local_side":"away","local_uid":"2026-08-24_dalibor_svrcina_felipe_meligeni_alves","bid":0.48,"ask":0.57,"mid":0.525,"spread":0.09,"price":0.49,"size":0.0,"side":"BUY"}
{"ts":"2026-08-24T20:48:28.755Z","event_type":"price_change","market_id":"3826919","outcome_index":0,"market_type":"set2","local_side":"home","local_uid":"2026-08-24_dalibor_svrcina_felipe_meligeni_alves","bid":0.43,"ask":0.52,"mid":0.475,"spread":0.09,"price":0.51,"size":0.0,"side":"SELL"}
{"ts":"2026-08-24T20:48:28.870Z","event_type":"best_bid_ask","market_id":"3826919","outcome_index":0,"market_type":"set2","local_side":"home","local_uid":"2026-08-24_dalibor_svrcina_felipe_meligeni_alves","bid":0.43,"ask":0.51,"mid":0.47,"spread":0.08,"bid_size":null,"ask_size":null}
{"ts":"2026-08-24T20:48:28.870Z","event_type":"best_bid_ask","market_id":"3826919","outcome_index":1,"market_type":"set2","local_side":"away","local_uid":"2026-08-24_dalibor_svrcina_felipe_meligeni_alves","bid":0.49,"ask":0.57,"mid":0.53,"spread":0.08,"bid_size":null,"ask_size":null}
{"ts":"2026-08-24T20:48:28.871Z","event_type":"price_change","market_id":"3826919","outcome_index":1,"market_type":"set2","local_side":"away","local_uid":"2026-08-24_dalibor_svrcina_felipe_meligeni_alves","bid":0.49,"ask":0.57,"mid":0.53,"spread":0.08,"price":0.49,"size":24.6,"side":"BUY"}
{"ts":"2026-08-24T20:48:28.871Z","event_type":"price_change","market_id":"3826919","outcome_index":0,"market_type":"set2","local_side":"home","local_uid":"2026-08-24_dalibor_svrcina_felipe_meligeni_alves","bid":0.43,"ask":0.51,"mid":0.47,"spread":0.08,"price":0.51,"size":24.6,"side":"SELL"}
{"ts":"2026-08-24T20:48:28.884Z","event_type":"best_bid_ask","market_id":"3824875","outcome_index":0,"market_type":"set2","local_side":"home","local_uid":"2026-08-24_eva_vedder_bianca_andreescu","bid":0.19,"ask":0.25,"mid":0.22,"spread":0.06,"bid_size":null,"ask_size":null}
{"ts":"2026-08-24T20:48:28.884Z","event_type":"best_bid_ask","market_id":"3824875","outcome_index":1,"market_type":"set2","local_side":"away","local_uid":"2026-08-24_eva_vedder_bianca_andreescu","bid":0.75,"ask":0.81,"mid":0.78,"spread":0.06,"bid_size":null,"ask_size":null}
{"ts":"2026-08-24T20:48:28.884Z","event_type":"price_change","market_id":"3824875","outcome_index":1,"market_type":"set2","local_side":"away","local_uid":"2026-08-24_eva_vedder_bianca_andreescu","bid":0.75,"ask":0.81,"mid":0.78,"spread":0.06,"price":0.78,"size":0.0,"side":"SELL"}
{"ts":"2026-08-24T20:48:28.885Z","event_type":"price_change","market_id":"3824875","outcome_index":0,"market_type":"set2","local_side":"home","local_uid":"2026-08-24_eva_vedder_bianca_andreescu","bid":0.19,"ask":0.25,"mid":0.22,"spread":0.06,"price":0.22,"size":0.0,"side":"BUY"}
{"ts":"2026-08-24T20:48:28.902Z","event_type":"best_bid_ask","market_id":"3826919","outcome_index":0,"market_type":"set2","local_side":"home","local_uid":"2026-08-24_dalibor_svrcina_felipe_meligeni_alves","bid":0.43,"ask":0.52,"mid":0.475,"spread":0.09,"bid_size":null,"ask_size":null}
{"ts":"2026-08-24T20:48:28.902Z","event_type":"best_bid_ask","market_id":"3826919","outcome_index":1,"market_type":"set2","local_side":"away","local_uid":"2026-08-24_dalibor_svrcina_felipe_meligeni_alves","bid":0.48,"ask":0.57,"mid":0.525,"spread":0.09,"bid_size":null,"ask_size":null}
{"ts":"2026-08-24T20:48:28.902Z","event_type":"price_change","market_id":"3826919","outcome_index":1,"market_type":"set2","local_side":"away","local_uid":"2026-08-24_dalibor_svrcina_felipe_meligeni_alves","bid":0.48,"ask":0.57,"mid":0.525,"spread":0.09,"price":0.49,"size":0.0,"side":"BUY"}
{"ts":"2026-08-24T20:48:28.903Z","event_type":"price_change","market_id":"3826919","outcome_index":0,"market_type":"set2","local_side":"home","local_uid":"2026-08-24_dalibor_svrcina_felipe_meligeni_alves","bid":0.43,"ask":0.52,"mid":0.475,"spread":0.09,"price":0.51,"size":0.0,"side":"SELL"}
{"ts":"2026-08-24T20:48:28.905Z","event_type":"best_bid_ask","market_id":"3824875","outcome_index":0,"market_type":"set2","local_side":"home","local_uid":"2026-08-24_eva_vedder_bianca_andreescu","bid":0.2,"ask":0.25,"mid":0.225,"spread":0.05,"bid_size":null,"ask_size":null}
{"ts":"2026-08-24T20:48:28.906Z","event_type":"best_bid_ask","market_id":"3824875","outcome_index":1,"market_type":"set2","local_side":"away","local_uid":"2026-08-24_eva_vedder_bianca_andreescu","bid":0.75,"ask":0.8,"mid":0.775,"spread":0.05,"bid_size":null,"ask_size":null}
{"ts":"2026-08-24T20:48:28.906Z","event_type":"price_change","market_id":"3824875","outcome_index":0,"market_type":"set2","local_side":"home","local_uid":"2026-08-24_eva_vedder_bianca_andreescu","bid":0.2,"ask":0.25,"mid":0.225,"spread":0.05,"price":0.2,"size":26.4,"side":"BUY"}
{"ts":"2026-08-24T20:48:28.906Z","event_type":"price_change","market_id":"3824875","outcome_index":1,"market_type":"set2","local_side":"away","local_uid":"2026-08-24_eva_vedder_bianca_andreescu","bid":0.75,"ask":0.8,"mid":0.775,"spread":0.05,"price":0.8,"size":26.4,"side":"SELL"}
{"ts":"2026-08-24T20:48:28.947Z","event_type":"best_bid_ask","market_id":"3824875","outcome_index":0,"market_type":"set2","local_side":"home","local_uid":"2026-08-24_eva_vedder_bianca_andreescu","bid":0.21,"ask":0.25,"mid":0.23,"spread":0.04,"bid_size":null,"ask_size":null}
{"ts":"2026-08-24T20:48:28.949Z","event_type":"best_bid_ask","market_id":"3824875","outcome_index":1,"market_type":"set2","local_side":"away","local_uid":"2026-08-24_eva_vedder_bianca_andreescu","bid":0.75,"ask":0.79,"mid":0.77,"spread":0.04,"bid_size":null,"ask_size":null}
{"ts":"2026-08-24T20:48:28.950Z","event_type":"price_change","market_id":"3824875","outcome_index":0,"market_type":"set2","local_side":"home","local_uid":"2026-08-24_eva_vedder_bianca_andreescu","bid":0.21,"ask":0.25,"mid":0.23,"spread":0.04,"price":0.21,"size":26.4,"side":"BUY"}
{"ts":"2026-08-24T20:48:28.950Z","event_type":"price_change","market_id":"3824875","outcome_index":1,"market_type":"set2","local_side":"away","local_uid":"2026-08-24_eva_vedder_bianca_andreescu","bid":0.75,"ask":0.79,"mid":0.77,"spread":0.04,"price":0.79,"size":26.4,"side":"SELL"}
{"ts":"2026-08-24T20:48:28.950Z","event_type":"best_bid_ask","market_id":"3826919","outcome_index":0,"market_type":"set2","local_side":"home","local_uid":"2026-08-24_dalibor_svrcina_felipe_meligeni_alves","bid":0.43,"ask":0.51,"mid":0.47,"spread":0.08,"bid_size":null,"ask_size":null}
{"ts":"2026-08-24T20:48:28.950Z","event_type":"best_bid_ask","market_id":"3826919","outcome_index":1,"market_type":"set2","local_side":"away","local_uid":"2026-08-24_dalibor_svrcina_felipe_meligeni_alves","bid":0.49,"ask":0.57,"mid":0.53,"spread":0.08,"bid_size":null,"ask_size":null}
{"ts":"2026-08-24T20:48:28.951Z","event_type":"price_change","market_id":"3826919","outcome_index":1,"market_type":"set2","local_side":"away","local_uid":"2026-08-24_dalibor_svrcina_felipe_meligeni_alves","bid":0.49,"ask":0.57,"mid":0.53,"spread":0.08,"price":0.49,"size":24.6,"side":"BUY"}
{"ts":"2026-08-24T20:48:28.951Z","event_type":"price_change","market_id":"3826919","outcome_index":0,"market_type":"set2","local_side":"home","local_uid":"2026-08-24_dalibor_svrcina_felipe_meligeni_alves","bid":0.43,"ask":0.51,"mid":0.47,"spread":0.08,"price":0.51,"size":24.6,"side":"SELL"}
{"ts":"2026-08-24T20:48:28.984Z","event_type":"best_bid_ask","market_id":"3826919","outcome_index":0,"market_type":"set2","local_side":"home","local_uid":"2026-08-24_dalibor_svrcina_felipe_meligeni_alves","bid":0.43,"ask":0.52,"mid":0.475,"spread":0.09,"bid_size":null,"ask_size":null}
{"ts":"2026-08-24T20:48:28.988Z","event_type":"best_bid_ask","market_id":"3826919","outcome_index":1,"market_type":"set2","local_side":"away","local_uid":"2026-08-24_dalibor_svrcina_felipe_meligeni_alves","bid":0.48,"ask":0.57,"mid":0.525,"spread":0.09,"bid_size":null,"ask_size":null}
{"ts":"2026-08-24T20:48:28.988Z","event_type":"price_change","market_id":"3826919","outcome_index":1,"market_type":"set2","local_side":"away","local_uid":"2026-08-24_dalibor_svrcina_felipe_meligeni_alves","bid":0.48,"ask":0.57,"mid":0.525,"spread":0.09,"price":0.49,"size":0.0,"side":"BUY"}
{"ts":"2026-08-24T20:48:28.989Z","event_type":"price_change","market_id":"3826919","outcome_index":0,"market_type":"set2","local_side":"home","local_uid":"2026-08-24_dalibor_svrcina_felipe_meligeni_alves","bid":0.43,"ask":0.52,"mid":0.475,"spread":0.09,"price":0.51,"size":0.0,"side":"SELL"}
{"ts":"2026-08-24T20:48:29.168Z","event_type":"best_bid_ask","market_id":"3826919","outcome_index":0,"market_type":"set2","local_side":"home","local_uid":"2026-08-24_dalibor_svrcina_felipe_meligeni_alves","bid":0.43,"ask":0.51,"mid":0.47,"spread":0.08,"bid_size":null,"ask_size":null}
{"ts":"2026-08-24T20:48:29.168Z","event_type":"best_bid_ask","market_id":"3826919","outcome_index":1,"market_type":"set2","local_side":"away","local_uid":"2026-08-24_dalibor_svrcina_felipe_meligeni_alves","bid":0.49,"ask":0.57,"mid":0.53,"spread":0.08,"bid_size":null,"ask_size":null}
{"ts":"2026-08-24T20:48:29.168Z","event_type":"price_change","market_id":"3826919","outcome_index":1,"market_type":"set2","local_side":"away","local_uid":"2026-08-24_dalibor_svrcina_felipe_meligeni_alves","bid":0.49,"ask":0.57,"mid":0.53,"spread":0.08,"price":0.49,"size":24.6,"side":"BUY"}
{"ts":"2026-08-24T20:48:29.169Z","event_type":"price_change","market_id":"3826919","outcome_index":0,"market_type":"set2","local_side":"home","local_uid":"2026-08-24_dalibor_svrcina_felipe_meligeni_alves","bid":0.43,"ask":0.51,"mid":0.47,"spread":0.08,"price":0.51,"size":24.6,"side":"SELL"}
{"ts":"2026-08-24T20:48:29.203Z","event_type":"best_bid_ask","market_id":"3826919","outcome_index":0,"market_type":"set2","local_side":"home","local_uid":"2026-08-24_dalibor_svrcina_felipe_meligeni_alves","bid":0.43,"ask":0.52,"mid":0.475,"spread":0.09,"bid_size":null,"ask_size":null}
{"ts":"2026-08-24T20:48:29.203Z","event_type":"best_bid_ask","market_id":"3826919","outcome_index":1,"market_type":"set2","local_side":"away","local_uid":"2026-08-24_dalibor_svrcina_felipe_meligeni_alves","bid":0.48,"ask":0.57,"mid":0.525,"spread":0.09,"bid_size":null,"ask_size":null}
{"ts":"2026-08-24T20:48:29.204Z","event_type":"price_change","market_id":"3826919","outcome_index":1,"market_type":"set2","local_side":"away","local_uid":"2026-08-24_dalibor_svrcina_felipe_meligeni_alves","bid":0.48,"ask":0.57,"mid":0.525,"spread":0.09,"price":0.49,"size":0.0,"side":"BUY"}
{"ts":"2026-08-24T20:48:29.204Z","event_type":"price_change","market_id":"3826919","outcome_index":0,"market_type":"set2","local_side":"home","local_uid":"2026-08-24_dalibor_svrcina_felipe_meligeni_alves","bid":0.43,"ask":0.52,"mid":0.475,"spread":0.09,"price":0.51,"size":0.0,"side":"SELL"}
{"ts":"2026-08-24T20:48:29.221Z","event_type":"best_bid_ask","market_id":"3823665","outcome_index":0,"market_type":"match","local_side":"home","local_uid":"2026-08-24_jazmin_ortenzi_himeno_sakatsume","bid":0.15,"ask":0.16,"mid":0.155,"spread":0.01,"bid_size":null,"ask_size":null}
{"ts":"2026-08-24T20:48:29.221Z","event_type":"best_bid_ask","market_id":"3823665","outcome_index":1,"market_type":"match","local_side":"away","local_uid":"2026-08-24_jazmin_ortenzi_himeno_sakatsume","bid":0.84,"ask":0.85,"mid":0.845,"spread":0.01,"bid_size":null,"ask_size":null}
{"ts":"2026-08-24T20:48:29.222Z","event_type":"price_change","market_id":"3823665","outcome_index":1,"market_type":"match","local_side":"away","local_uid":"2026-08-24_jazmin_ortenzi_himeno_sakatsume","bid":0.84,"ask":0.85,"mid":0.845,"spread":0.01,"price":0.84,"size":5000.0,"side":"BUY"}
{"ts":"2026-08-24T20:48:29.222Z","event_type":"price_change","market_id":"3823665","outcome_index":0,"market_type":"match","local_side":"home","local_uid":"2026-08-24_jazmin_ortenzi_himeno_sakatsume","bid":0.15,"ask":0.16,"mid":0.155,"spread":0.01,"price":0.16,"size":5000.0,"side":"SELL"}
{"ts":"2026-08-24T20:48:29.251Z","event_type":"best_bid_ask","market_id":"3823665","outcome_index":0,"market_type":"match","local_side":"home","local_uid":"2026-08-24_jazmin_ortenzi_himeno_sakatsume","bid":0.15,"ask":0.17,"mid":0.16,"spread":0.02,"bid_size":null,"ask_size":null}
{"ts":"2026-08-24T20:48:29.252Z","event_type":"best_bid_ask","market_id":"3823665","outcome_index":1,"market_type":"match","local_side":"away","local_uid":"2026-08-24_jazmin_ortenzi_himeno_sakatsume","bid":0.83,"ask":0.85,"mid":0.84,"spread":0.02,"bid_size":null,"ask_size":null}
{"ts":"2026-08-24T20:48:29.252Z","event_type":"price_change","market_id":"3823665","outcome_index":1,"market_type":"match","local_side":"away","local_uid":"2026-08-24_jazmin_ortenzi_himeno_sakatsume","bid":0.83,"ask":0.85,"mid":0.84,"spread":0.02,"price":0.84,"size":0.0,"side":"BUY"}
{"ts":"2026-08-24T20:48:29.252Z","event_type":"price_change","market_id":"3823665","outcome_index":0,"market_type":"match","local_side":"home","local_uid":"2026-08-24_jazmin_ortenzi_himeno_sakatsume","bid":0.15,"ask":0.17,"mid":0.16,"spread":0.02,"price":0.16,"size":0.0,"side":"SELL"}
{"ts":"2026-08-24T20:48:29.348Z","event_type":"best_bid_ask","market_id":"3826733","outcome_index":0,"market_type":"set1","local_side":"home","local_uid":"2026-08-24_harry_wendelken_stefano_travaglia","bid":0.88,"ask":0.95,"mid":0.915,"spread":0.07,"bid_size":null,"ask_size":null}
{"ts":"2026-08-24T20:48:29.348Z","event_type":"best_bid_ask","market_id":"3826733","outcome_index":1,"market_type":"set1","local_side":"away","local_uid":"2026-08-24_harry_wendelken_stefano_travaglia","bid":0.05,"ask":0.12,"mid":0.085,"spread":0.07,"bid_size":null,"ask_size":null}
{"ts":"2026-08-24T20:48:29.348Z","event_type":"price_change","market_id":"3826733","outcome_index":0,"market_type":"set1","local_side":"home","local_uid":"2026-08-24_harry_wendelken_stefano_travaglia","bid":0.88,"ask":0.95,"mid":0.915,"spread":0.07,"price":0.88,"size":88.0,"side":"BUY"}
{"ts":"2026-08-24T20:48:29.349Z","event_type":"price_change","market_id":"3826733","outcome_index":1,"market_type":"set1","local_side":"away","local_uid":"2026-08-24_harry_wendelken_stefano_travaglia","bid":0.05,"ask":0.12,"mid":0.085,"spread":0.07,"price":0.12,"size":88.0,"side":"SELL"}
{"ts":"2026-08-24T20:48:29.366Z","event_type":"best_bid_ask","market_id":"3826738","outcome_index":0,"market_type":"set2","local_side":"home","local_uid":"2026-08-24_harry_wendelken_stefano_travaglia","bid":0.48,"ask":0.6,"mid":0.54,"spread":0.12,"bid_size":null,"ask_size":null}
{"ts":"2026-08-24T20:48:29.367Z","event_type":"best_bid_ask","market_id":"3826738","outcome_index":1,"market_type":"set2","local_side":"away","local_uid":"2026-08-24_harry_wendelken_stefano_travaglia","bid":0.4,"ask":0.52,"mid":0.46,"spread":0.12,"bid_size":null,"ask_size":null}
{"ts":"2026-08-24T20:48:29.367Z","event_type":"price_change","market_id":"3826738","outcome_index":0,"market_type":"set2","local_side":"home","local_uid":"2026-08-24_harry_wendelken_stefano_travaglia","bid":0.48,"ask":0.6,"mid":0.54,"spread":0.12,"price":0.49,"size":0.0,"side":"BUY"}
{"ts":"2026-08-24T20:48:29.367Z","event_type":"price_change","market_id":"3826738","outcome_index":1,"market_type":"set2","local_side":"away","local_uid":"2026-08-24_harry_wendelken_stefano_travaglia","bid":0.4,"ask":0.52,"mid":0.46,"spread":0.12,"price":0.51,"size":0.0,"side":"SELL"}
{"ts":"2026-08-24T20:48:29.368Z","event_type":"best_bid_ask","market_id":"3826738","outcome_index":0,"market_type":"set2","local_side":"home","local_uid":"2026-08-24_harry_wendelken_stefano_travaglia","bid":0.49,"ask":0.6,"mid":0.545,"spread":0.11,"bid_size":null,"ask_size":null}
{"ts":"2026-08-24T20:48:29.368Z","event_type":"best_bid_ask","market_id":"3826738","outcome_index":1,"market_type":"set2","local_side":"away","local_uid":"2026-08-24_harry_wendelken_stefano_travaglia","bid":0.4,"ask":0.51,"mid":0.455,"spread":0.11,"bid_size":null,"ask_size":null}
{"ts":"2026-08-24T20:48:29.369Z","event_type":"price_change","market_id":"3826738","outcome_index":0,"market_type":"set2","local_side":"home","local_uid":"2026-08-24_harry_wendelken_stefano_travaglia","bid":0.49,"ask":0.6,"mid":0.545,"spread":0.11,"price":0.49,"size":757.0,"side":"BUY"}
{"ts":"2026-08-24T20:48:29.369Z","event_type":"price_change","market_id":"3826738","outcome_index":1,"market_type":"set2","local_side":"away","local_uid":"2026-08-24_harry_wendelken_stefano_travaglia","bid":0.4,"ask":0.51,"mid":0.455,"spread":0.11,"price":0.51,"size":757.0,"side":"SELL"}
{"ts":"2026-08-24T20:48:29.405Z","event_type":"best_bid_ask","market_id":"3826733","outcome_index":0,"market_type":"set1","local_side":"home","local_uid":"2026-08-24_harry_wendelken_stefano_travaglia","bid":0.89,"ask":0.95,"mid":0.92,"spread":0.06,"bid_size":null,"ask_size":null}
{"ts":"2026-08-24T20:48:29.406Z","event_type":"best_bid_ask","market_id":"3826733","outcome_index":1,"market_type":"set1","local_side":"away","local_uid":"2026-08-24_harry_wendelken_stefano_travaglia","bid":0.05,"ask":0.11,"mid":0.08,"spread":0.06,"bid_size":null,"ask_size":null}
{"ts":"2026-08-24T20:48:29.406Z","event_type":"price_change","market_id":"3826733","outcome_index":0,"market_type":"set1","local_side":"home","local_uid":"2026-08-24_harry_wendelken_stefano_travaglia","bid":0.89,"ask":0.95,"mid":0.92,"spread":0.06,"price":0.89,"size":150.0,"side":"BUY"}
{"ts":"2026-08-24T20:48:29.406Z","event_type":"price_change","market_id":"3826733","outcome_index":1,"market_type":"set1","local_side":"away","local_uid":"2026-08-24_harry_wendelken_stefano_travaglia","bid":0.05,"ask":0.11,"mid":0.08,"spread":0.06,"price":0.11,"size":150.0,"side":"SELL"}
{"ts":"2026-08-24T20:48:29.439Z","event_type":"best_bid_ask","market_id":"3826919","outcome_index":0,"market_type":"set2","local_side":"home","local_uid":"2026-08-24_dalibor_svrcina_felipe_meligeni_alves","bid":0.43,"ask":0.51,"mid":0.47,"spread":0.08,"bid_size":null,"ask_size":null}
{"ts":"2026-08-24T20:48:29.439Z","event_type":"best_bid_ask","market_id":"3826919","outcome_index":1,"market_type":"set2","local_side":"away","local_uid":"2026-08-24_dalibor_svrcina_felipe_meligeni_alves","bid":0.49,"ask":0.57,"mid":0.53,"spread":0.08,"bid_size":null,"ask_size":null}
{"ts":"2026-08-24T20:48:29.439Z","event_type":"best_bid_ask","market_id":"3823665","outcome_index":0,"market_type":"match","local_side":"home","local_uid":"2026-08-24_jazmin_ortenzi_himeno_sakatsume","bid":0.15,"ask":0.16,"mid":0.155,"spread":0.01,"bid_size":null,"ask_size":null}
{"ts":"2026-08-24T20:48:29.440Z","event_type":"price_change","market_id":"3826919","outcome_index":1,"market_type":"set2","local_side":"away","local_uid":"2026-08-24_dalibor_svrcina_felipe_meligeni_alves","bid":0.49,"ask":0.57,"mid":0.53,"spread":0.08,"price":0.49,"size":24.6,"side":"BUY"}
{"ts":"2026-08-24T20:48:29.440Z","event_type":"price_change","market_id":"3826919","outcome_index":0,"market_type":"set2","local_side":"home","local_uid":"2026-08-24_dalibor_svrcina_felipe_meligeni_alves","bid":0.43,"ask":0.51,"mid":0.47,"spread":0.08,"price":0.51,"size":24.6,"side":"SELL"}
{"ts":"2026-08-24T20:48:29.440Z","event_type":"best_bid_ask","market_id":"3823665","outcome_index":1,"market_type":"match","local_side":"away","local_uid":"2026-08-24_jazmin_ortenzi_himeno_sakatsume","bid":0.84,"ask":0.85,"mid":0.845,"spread":0.01,"bid_size":null,"ask_size":null}
{"ts":"2026-08-24T20:48:29.441Z","event_type":"price_change","market_id":"3823665","outcome_index":1,"market_type":"match","local_side":"away","local_uid":"2026-08-24_jazmin_ortenzi_himeno_sakatsume","bid":0.84,"ask":0.85,"mid":0.845,"spread":0.01,"price":0.84,"size":105.0,"side":"BUY"}
{"ts":"2026-08-24T20:48:29.441Z","event_type":"price_change","market_id":"3823665","outcome_index":0,"market_type":"match","local_side":"home","local_uid":"2026-08-24_jazmin_ortenzi_himeno_sakatsume","bid":0.15,"ask":0.16,"mid":0.155,"spread":0.01,"price":0.16,"size":105.0,"side":"SELL"}
{"ts":"2026-08-24T20:48:29.446Z","event_type":"best_bid_ask","market_id":"3826654","outcome_index":0,"market_type":"set2","local_side":"home","local_uid":"2026-08-24_sebastian_gorzny_cruz_hewitt","bid":0.05,"ask":0.13,"mid":0.09,"spread":0.08,"bid_size":null,"ask_size":null}
{"ts":"2026-08-24T20:48:29.446Z","event_type":"best_bid_ask","market_id":"3826654","outcome_index":1,"market_type":"set2","local_side":"away","local_uid":"2026-08-24_sebastian_gorzny_cruz_hewitt","bid":0.87,"ask":0.95,"mid":0.91,"spread":0.08,"bid_size":null,"ask_size":null}
{"ts":"2026-08-24T20:48:29.446Z","event_type":"price_change","market_id":"3826654","outcome_index":0,"market_type":"set2","local_side":"home","local_uid":"2026-08-24_sebastian_gorzny_cruz_hewitt","bid":0.05,"ask":0.13,"mid":0.09,"spread":0.08,"price":0.06,"size":0.0,"side":"BUY"}
{"ts":"2026-08-24T20:48:29.446Z","event_type":"price_change","market_id":"3826654","outcome_index":1,"market_type":"set2","local_side":"away","local_uid":"2026-08-24_sebastian_gorzny_cruz_hewitt","bid":0.87,"ask":0.95,"mid":0.91,"spread":0.08,"price":0.94,"size":0.0,"side":"SELL"}
{"ts":"2026-08-24T20:48:29.448Z","event_type":"best_bid_ask","market_id":"3826654","outcome_index":0,"market_type":"set2","local_side":"home","local_uid":"2026-08-24_sebastian_gorzny_cruz_hewitt","bid":0.06,"ask":0.13,"mid":0.095,"spread":0.07,"bid_size":null,"ask_size":null}
{"ts":"2026-08-24T20:48:29.448Z","event_type":"best_bid_ask","market_id":"3826654","outcome_index":1,"market_type":"set2","local_side":"away","local_uid":"2026-08-24_sebastian_gorzny_cruz_hewitt","bid":0.87,"ask":0.94,"mid":0.905,"spread":0.07,"bid_size":null,"ask_size":null}
{"ts":"2026-08-24T20:48:29.449Z","event_type":"price_change","market_id":"3826654","outcome_index":0,"market_type":"set2","local_side":"home","local_uid":"2026-08-24_sebastian_gorzny_cruz_hewitt","bid":0.06,"ask":0.13,"mid":0.095,"spread":0.07,"price":0.06,"size":5.0,"side":"BUY"}
{"ts":"2026-08-24T20:48:29.449Z","event_type":"price_change","market_id":"3826654","outcome_index":1,"market_type":"set2","local_side":"away","local_uid":"2026-08-24_sebastian_gorzny_cruz_hewitt","bid":0.87,"ask":0.94,"mid":0.905,"spread":0.07,"price":0.94,"size":5.0,"side":"SELL"}
{"ts":"2026-08-24T20:48:29.477Z","event_type":"best_bid_ask","market_id":"3826654","outcome_index":0,"market_type":"set2","local_side":"home","local_uid":"2026-08-24_sebastian_gorzny_cruz_hewitt","bid":0.05,"ask":0.13,"mid":0.09,"spread":0.08,"bid_size":null,"ask_size":null}
{"ts":"2026-08-24T20:48:29.477Z","event_type":"best_bid_ask","market_id":"3826654","outcome_index":1,"market_type":"set2","local_side":"away","local_uid":"2026-08-24_sebastian_gorzny_cruz_hewitt","bid":0.87,"ask":0.95,"mid":0.91,"spread":0.08,"bid_size":null,"ask_size":null}
{"ts":"2026-08-24T20:48:29.477Z","event_type":"price_change","market_id":"3826654","outcome_index":0,"market_type":"set2","local_side":"home","local_uid":"2026-08-24_sebastian_gorzny_cruz_hewitt","bid":0.05,"ask":0.13,"mid":0.09,"spread":0.08,"price":0.06,"size":0.0,"side":"BUY"}
{"ts":"2026-08-24T20:48:29.478Z","event_type":"price_change","market_id":"3826654","outcome_index":1,"market_type":"set2","local_side":"away","local_uid":"2026-08-24_sebastian_gorzny_cruz_hewitt","bid":0.87,"ask":0.95,"mid":0.91,"spread":0.08,"price":0.94,"size":0.0,"side":"SELL"}
{"ts":"2026-08-24T20:48:29.483Z","event_type":"best_bid_ask","market_id":"3826919","outcome_index":0,"market_type":"set2","local_side":"home","local_uid":"2026-08-24_dalibor_svrcina_felipe_meligeni_alves","bid":0.43,"ask":0.52,"mid":0.475,"spread":0.09,"bid_size":null,"ask_size":null}
{"ts":"2026-08-24T20:48:29.484Z","event_type":"best_bid_ask","market_id":"3826919","outcome_index":1,"market_type":"set2","local_side":"away","local_uid":"2026-08-24_dalibor_svrcina_felipe_meligeni_alves","bid":0.48,"ask":0.57,"mid":0.525,"spread":0.09,"bid_size":null,"ask_size":null}
{"ts":"2026-08-24T20:48:29.484Z","event_type":"price_change","market_id":"3826919","outcome_index":1,"market_type":"set2","local_side":"away","local_uid":"2026-08-24_dalibor_svrcina_felipe_meligeni_alves","bid":0.48,"ask":0.57,"mid":0.525,"spread":0.09,"price":0.49,"size":0.0,"side":"BUY"}
{"ts":"2026-08-24T20:48:29.484Z","event_type":"price_change","market_id":"3826919","outcome_index":0,"market_type":"set2","local_side":"home","local_uid":"2026-08-24_dalibor_svrcina_felipe_meligeni_alves","bid":0.43,"ask":0.52,"mid":0.475,"spread":0.09,"price":0.51,"size":0.0,"side":"SELL"}
{"ts":"2026-08-24T20:48:29.488Z","event_type":"best_bid_ask","market_id":"3826733","outcome_index":0,"market_type":"set1","local_side":"home","local_uid":"2026-08-24_harry_wendelken_stefano_travaglia","bid":0.9,"ask":0.95,"mid":0.925,"spread":0.05,"bid_size":null,"ask_size":null}
{"ts":"2026-08-24T20:48:29.488Z","event_type":"best_bid_ask","market_id":"3826733","outcome_index":1,"market_type":"set1","local_side":"away","local_uid":"2026-08-24_harry_wendelken_stefano_travaglia","bid":0.05,"ask":0.1,"mid":0.075,"spread":0.05,"bid_size":null,"ask_size":null}
{"ts":"2026-08-24T20:48:29.488Z","event_type":"price_change","market_id":"3826733","outcome_index":0,"market_type":"set1","local_side":"home","local_uid":"2026-08-24_harry_wendelken_stefano_travaglia","bid":0.9,"ask":0.95,"mid":0.925,"spread":0.05,"price":0.9,"size":150.0,"side":"BUY"}
{"ts":"2026-08-24T20:48:29.489Z","event_type":"price_change","market_id":"3826733","outcome_index":1,"market_type":"set1","local_side":"away","local_uid":"2026-08-24_harry_wendelken_stefano_travaglia","bid":0.05,"ask":0.1,"mid":0.075,"spread":0.05,"price":0.1,"size":150.0,"side":"SELL"}
{"ts":"2026-08-24T20:48:29.502Z","event_type":"price_change","market_id":"3823621","outcome_index":0,"market_type":"match","local_side":"home","local_uid":"2026-08-24_carson_branstine_clervie_ngounoue","bid":0.41,"ask":0.42,"mid":0.415,"spread":0.01,"price":0.37,"size":2261.9,"side":"BUY"}
{"ts":"2026-08-24T20:48:29.503Z","event_type":"price_change","market_id":"3823621","outcome_index":1,"market_type":"match","local_side":"away","local_uid":"2026-08-24_carson_branstine_clervie_ngounoue","bid":0.58,"ask":0.59,"mid":0.585,"spread":0.01,"price":0.63,"size":2261.9,"side":"SELL"}
{"ts":"2026-08-24T20:48:29.510Z","event_type":"best_bid_ask","market_id":"3826733","outcome_index":0,"market_type":"set1","local_side":"home","local_uid":"2026-08-24_harry_wendelken_stefano_travaglia","bid":0.9,"ask":0.96,"mid":0.93,"spread":0.06,"bid_size":null,"ask_size":null}
{"ts":"2026-08-24T20:48:29.510Z","event_type":"best_bid_ask","market_id":"3826733","outcome_index":1,"market_type":"set1","local_side":"away","local_uid":"2026-08-24_harry_wendelken_stefano_travaglia","bid":0.04,"ask":0.1,"mid":0.07,"spread":0.06,"bid_size":null,"ask_size":null}
{"ts":"2026-08-24T20:48:29.510Z","event_type":"price_change","market_id":"3826733","outcome_index":1,"market_type":"set1","local_side":"away","local_uid":"2026-08-24_harry_wendelken_stefano_travaglia","bid":0.04,"ask":0.1,"mid":0.07,"spread":0.06,"price":0.05,"size":0.0,"side":"BUY"}
{"ts":"2026-08-24T20:48:29.510Z","event_type":"price_change","market_id":"3826733","outcome_index":0,"market_type":"set1","local_side":"home","local_uid":"2026-08-24_harry_wendelken_stefano_travaglia","bid":0.9,"ask":0.96,"mid":0.93,"spread":0.06,"price":0.95,"size":0.0,"side":"SELL"}
{"ts":"2026-08-24T20:48:29.536Z","event_type":"best_bid_ask","market_id":"3826738","outcome_index":0,"market_type":"set2","local_side":"home","local_uid":"2026-08-24_harry_wendelken_stefano_travaglia","bid":0.5,"ask":0.6,"mid":0.55,"spread":0.1,"bid_size":null,"ask_size":null}
{"ts":"2026-08-24T20:48:29.536Z","event_type":"best_bid_ask","market_id":"3826738","outcome_index":1,"market_type":"set2","local_side":"away","local_uid":"2026-08-24_harry_wendelken_stefano_travaglia","bid":0.4,"ask":0.5,"mid":0.45,"spread":0.1,"bid_size":null,"ask_size":null}
{"ts":"2026-08-24T20:48:29.537Z","event_type":"price_change","market_id":"3826738","outcome_index":0,"market_type":"set2","local_side":"home","local_uid":"2026-08-24_harry_wendelken_stefano_travaglia","bid":0.5,"ask":0.6,"mid":0.55,"spread":0.1,"price":0.5,"size":150.0,"side":"BUY"}
{"ts":"2026-08-24T20:48:29.537Z","event_type":"price_change","market_id":"3826738","outcome_index":1,"market_type":"set2","local_side":"away","local_uid":"2026-08-24_harry_wendelken_stefano_travaglia","bid":0.4,"ask":0.5,"mid":0.45,"spread":0.1,"price":0.5,"size":150.0,"side":"SELL"}
{"ts":"2026-08-24T20:48:29.548Z","event_type":"best_bid_ask","market_id":"3826733","outcome_index":0,"market_type":"set1","local_side":"home","local_uid":"2026-08-24_harry_wendelken_stefano_travaglia","bid":0.9,"ask":0.95,"mid":0.925,"spread":0.05,"bid_size":null,"ask_size":null}
{"ts":"2026-08-24T20:48:29.548Z","event_type":"best_bid_ask","market_id":"3826733","outcome_index":1,"market_type":"set1","local_side":"away","local_uid":"2026-08-24_harry_wendelken_stefano_travaglia","bid":0.05,"ask":0.1,"mid":0.075,"spread":0.05,"bid_size":null,"ask_size":null}
{"ts":"2026-08-24T20:48:29.549Z","event_type":"price_change","market_id":"3826733","outcome_index":1,"market_type":"set1","local_side":"away","local_uid":"2026-08-24_harry_wendelken_stefano_travaglia","bid":0.05,"ask":0.1,"mid":0.075,"spread":0.05,"price":0.05,"size":20.66,"side":"BUY"}
{"ts":"2026-08-24T20:48:29.549Z","event_type":"price_change","market_id":"3826733","outcome_index":0,"market_type":"set1","local_side":"home","local_uid":"2026-08-24_harry_wendelken_stefano_travaglia","bid":0.9,"ask":0.95,"mid":0.925,"spread":0.05,"price":0.95,"size":20.66,"side":"SELL"}
{"ts":"2026-08-24T20:48:29.571Z","event_type":"best_bid_ask","market_id":"3824761","outcome_index":0,"market_type":"set1","local_side":"home","local_uid":"2026-08-24_jazmin_ortenzi_himeno_sakatsume","bid":0.13,"ask":0.23,"mid":0.18,"spread":0.1,"bid_size":null,"ask_size":null}
{"ts":"2026-08-24T20:48:29.571Z","event_type":"best_bid_ask","market_id":"3824761","outcome_index":1,"market_type":"set1","local_side":"away","local_uid":"2026-08-24_jazmin_ortenzi_himeno_sakatsume","bid":0.77,"ask":0.87,"mid":0.82,"spread":0.1,"bid_size":null,"ask_size":null}
{"ts":"2026-08-24T20:48:29.572Z","event_type":"price_change","market_id":"3824761","outcome_index":1,"market_type":"set1","local_side":"away","local_uid":"2026-08-24_jazmin_ortenzi_himeno_sakatsume","bid":0.77,"ask":0.87,"mid":0.82,"spread":0.1,"price":0.77,"size":88.0,"side":"BUY"}
{"ts":"2026-08-24T20:48:29.572Z","event_type":"price_change","market_id":"3824761","outcome_index":0,"market_type":"set1","local_side":"home","local_uid":"2026-08-24_jazmin_ortenzi_himeno_sakatsume","bid":0.13,"ask":0.23,"mid":0.18,"spread":0.1,"price":0.23,"size":88.0,"side":"SELL"}
{"ts":"2026-08-24T20:48:29.611Z","event_type":"best_bid_ask","market_id":"3826919","outcome_index":0,"market_type":"set2","local_side":"home","local_uid":"2026-08-24_dalibor_svrcina_felipe_meligeni_alves","bid":0.43,"ask":0.51,"mid":0.47,"spread":0.08,"bid_size":null,"ask_size":null}
{"ts":"2026-08-24T20:48:29.611Z","event_type":"best_bid_ask","market_id":"3826919","outcome_index":1,"market_type":"set2","local_side":"away","local_uid":"2026-08-24_dalibor_svrcina_felipe_meligeni_alves","bid":0.49,"ask":0.57,"mid":0.53,"spread":0.08,"bid_size":null,"ask_size":null}
{"ts":"2026-08-24T20:48:29.611Z","event_type":"price_change","market_id":"3826919","outcome_index":1,"market_type":"set2","local_side":"away","local_uid":"2026-08-24_dalibor_svrcina_felipe_meligeni_alves","bid":0.49,"ask":0.57,"mid":0.53,"spread":0.08,"price":0.49,"size":24.6,"side":"BUY"}
{"ts":"2026-08-24T20:48:29.611Z","event_type":"price_change","market_id":"3826919","outcome_index":0,"market_type":"set2","local_side":"home","local_uid":"2026-08-24_dalibor_svrcina_felipe_meligeni_alves","bid":0.43,"ask":0.51,"mid":0.47,"spread":0.08,"price":0.51,"size":24.6,"side":"SELL"}
{"ts":"2026-08-24T20:48:29.625Z","event_type":"best_bid_ask","market_id":"3826738","outcome_index":0,"market_type":"set2","local_side":"home","local_uid":"2026-08-24_harry_wendelken_stefano_travaglia","bid":0.51,"ask":0.6,"mid":0.555,"spread":0.09,"bid_size":null,"ask_size":null}
{"ts":"2026-08-24T20:48:29.626Z","event_type":"best_bid_ask","market_id":"3826738","outcome_index":1,"market_type":"set2","local_side":"away","local_uid":"2026-08-24_harry_wendelken_stefano_travaglia","bid":0.4,"ask":0.49,"mid":0.445,"spread":0.09,"bid_size":null,"ask_size":null}
{"ts":"2026-08-24T20:48:29.626Z","event_type":"price_change","market_id":"3826738","outcome_index":0,"market_type":"set2","local_side":"home","local_uid":"2026-08-24_harry_wendelken_stefano_travaglia","bid":0.51,"ask":0.6,"mid":0.555,"spread":0.09,"price":0.51,"size":24.6,"side":"BUY"}
{"ts":"2026-08-24T20:48:29.626Z","event_type":"price_change","market_id":"3826738","outcome_index":1,"market_type":"set2","local_side":"away","local_uid":"2026-08-24_harry_wendelken_stefano_travaglia","bid":0.4,"ask":0.49,"mid":0.445,"spread":0.09,"price":0.49,"size":24.6,"side":"SELL"}
{"ts":"2026-08-24T20:48:29.630Z","event_type":"best_bid_ask","market_id":"3824761","outcome_index":0,"market_type":"set1","local_side":"home","local_uid":"2026-08-24_jazmin_ortenzi_himeno_sakatsume","bid":0.13,"ask":0.21,"mid":0.17,"spread":0.08,"bid_size":null,"ask_size":null}
{"ts":"2026-08-24T20:48:29.630Z","event_type":"best_bid_ask","market_id":"3824761","outcome_index":1,"market_type":"set1","local_side":"away","local_uid":"2026-08-24_jazmin_ortenzi_himeno_sakatsume","bid":0.79,"ask":0.87,"mid":0.83,"spread":0.08,"bid_size":null,"ask_size":null}
{"ts":"2026-08-24T20:48:29.632Z","event_type":"price_change","market_id":"3824761","outcome_index":1,"market_type":"set1","local_side":"away","local_uid":"2026-08-24_jazmin_ortenzi_himeno_sakatsume","bid":0.79,"ask":0.87,"mid":0.83,"spread":0.08,"price":0.79,"size":150.0,"side":"BUY"}
{"ts":"2026-08-24T20:48:29.633Z","event_type":"price_change","market_id":"3824761","outcome_index":0,"market_type":"set1","local_side":"home","local_uid":"2026-08-24_jazmin_ortenzi_himeno_sakatsume","bid":0.13,"ask":0.21,"mid":0.17,"spread":0.08,"price":0.21,"size":150.0,"side":"SELL"}
{"ts":"2026-08-24T20:48:29.636Z","event_type":"best_bid_ask","market_id":"3824760","outcome_index":0,"market_type":"set2","local_side":"home","local_uid":"2026-08-24_jazmin_ortenzi_himeno_sakatsume","bid":0.2,"ask":0.29,"mid":0.245,"spread":0.09,"bid_size":null,"ask_size":null}
{"ts":"2026-08-24T20:48:29.637Z","event_type":"best_bid_ask","market_id":"3824760","outcome_index":1,"market_type":"set2","local_side":"away","local_uid":"2026-08-24_jazmin_ortenzi_himeno_sakatsume","bid":0.71,"ask":0.8,"mid":0.755,"spread":0.09,"bid_size":null,"ask_size":null}
{"ts":"2026-08-24T20:48:29.638Z","event_type":"price_change","market_id":"3824760","outcome_index":1,"market_type":"set2","local_side":"away","local_uid":"2026-08-24_jazmin_ortenzi_himeno_sakatsume","bid":0.71,"ask":0.8,"mid":0.755,"spread":0.09,"price":0.71,"size":2377.0,"side":"BUY"}
{"ts":"2026-08-24T20:48:29.638Z","event_type":"price_change","market_id":"3824760","outcome_index":0,"market_type":"set2","local_side":"home","local_uid":"2026-08-24_jazmin_ortenzi_himeno_sakatsume","bid":0.2,"ask":0.29,"mid":0.245,"spread":0.09,"price":0.29,"size":2377.0,"side":"SELL"}
{"ts":"2026-08-24T20:48:29.639Z","event_type":"best_bid_ask","market_id":"3826919","outcome_index":0,"market_type":"set2","local_side":"home","local_uid":"2026-08-24_dalibor_svrcina_felipe_meligeni_alves","bid":0.43,"ask":0.52,"mid":0.475,"spread":0.09,"bid_size":null,"ask_size":null}
{"ts":"2026-08-24T20:48:29.639Z","event_type":"best_bid_ask","market_id":"3826919","outcome_index":1,"market_type":"set2","local_side":"away","local_uid":"2026-08-24_dalibor_svrcina_felipe_meligeni_alves","bid":0.48,"ask":0.57,"mid":0.525,"spread":0.09,"bid_size":null,"ask_size":null}
{"ts":"2026-08-24T20:48:29.640Z","event_type":"price_change","market_id":"3826919","outcome_index":1,"market_type":"set2","local_side":"away","local_uid":"2026-08-24_dalibor_svrcina_felipe_meligeni_alves","bid":0.48,"ask":0.57,"mid":0.525,"spread":0.09,"price":0.49,"size":0.0,"side":"BUY"}
{"ts":"2026-08-24T20:48:29.640Z","event_type":"price_change","market_id":"3826919","outcome_index":0,"market_type":"set2","local_side":"home","local_uid":"2026-08-24_dalibor_svrcina_felipe_meligeni_alves","bid":0.43,"ask":0.52,"mid":0.475,"spread":0.09,"price":0.51,"size":0.0,"side":"SELL"}
{"ts":"2026-08-24T20:48:29.681Z","event_type":"best_bid_ask","market_id":"3826919","outcome_index":0,"market_type":"set2","local_side":"home","local_uid":"2026-08-24_dalibor_svrcina_felipe_meligeni_alves","bid":0.43,"ask":0.51,"mid":0.47,"spread":0.08,"bid_size":null,"ask_size":null}
{"ts":"2026-08-24T20:48:29.681Z","event_type":"best_bid_ask","market_id":"3826919","outcome_index":1,"market_type":"set2","local_side":"away","local_uid":"2026-08-24_dalibor_svrcina_felipe_meligeni_alves","bid":0.49,"ask":0.57,"mid":0.53,"spread":0.08,"bid_size":null,"ask_size":null}
{"ts":"2026-08-24T20:48:29.682Z","event_type":"price_change","market_id":"3826919","outcome_index":1,"market_type":"set2","local_side":"away","local_uid":"2026-08-24_dalibor_svrcina_felipe_meligeni_alves","bid":0.49,"ask":0.57,"mid":0.53,"spread":0.08,"price":0.49,"size":24.6,"side":"BUY"}
{"ts":"2026-08-24T20:48:29.682Z","event_type":"price_change","market_id":"3826919","outcome_index":0,"market_type":"set2","local_side":"home","local_uid":"2026-08-24_dalibor_svrcina_felipe_meligeni_alves","bid":0.43,"ask":0.51,"mid":0.47,"spread":0.08,"price":0.51,"size":24.6,"side":"SELL"}
{"ts":"2026-08-24T20:48:29.717Z","event_type":"best_bid_ask","market_id":"3826654","outcome_index":0,"market_type":"set2","local_side":"home","local_uid":"2026-08-24_sebastian_gorzny_cruz_hewitt","bid":0.06,"ask":0.13,"mid":0.095,"spread":0.07,"bid_size":null,"ask_size":null}
{"ts":"2026-08-24T20:48:29.718Z","event_type":"best_bid_ask","market_id":"3826654","outcome_index":1,"market_type":"set2","local_side":"away","local_uid":"2026-08-24_sebastian_gorzny_cruz_hewitt","bid":0.87,"ask":0.94,"mid":0.905,"spread":0.07,"bid_size":null,"ask_size":null}
{"ts":"2026-08-24T20:48:29.718Z","event_type":"price_change","market_id":"3826654","outcome_index":0,"market_type":"set2","local_side":"home","local_uid":"2026-08-24_sebastian_gorzny_cruz_hewitt","bid":0.06,"ask":0.13,"mid":0.095,"spread":0.07,"price":0.06,"size":22.0,"side":"BUY"}
{"ts":"2026-08-24T20:48:29.718Z","event_type":"price_change","market_id":"3826654","outcome_index":1,"market_type":"set2","local_side":"away","local_uid":"2026-08-24_sebastian_gorzny_cruz_hewitt","bid":0.87,"ask":0.94,"mid":0.905,"spread":0.07,"price":0.94,"size":22.0,"side":"SELL"}
{"ts":"2026-08-24T20:48:29.726Z","event_type":"best_bid_ask","market_id":"3826919","outcome_index":0,"market_type":"set2","local_side":"home","local_uid":"2026-08-24_dalibor_svrcina_felipe_meligeni_alves","bid":0.43,"ask":0.52,"mid":0.475,"spread":0.09,"bid_size":null,"ask_size":null}
{"ts":"2026-08-24T20:48:29.727Z","event_type":"best_bid_ask","market_id":"3826919","outcome_index":1,"market_type":"set2","local_side":"away","local_uid":"2026-08-24_dalibor_svrcina_felipe_meligeni_alves","bid":0.48,"ask":0.57,"mid":0.525,"spread":0.09,"bid_size":null,"ask_size":null}
{"ts":"2026-08-24T20:48:29.727Z","event_type":"price_change","market_id":"3826919","outcome_index":1,"market_type":"set2","local_side":"away","local_uid":"2026-08-24_dalibor_svrcina_felipe_meligeni_alves","bid":0.48,"ask":0.57,"mid":0.525,"spread":0.09,"price":0.49,"size":0.0,"side":"BUY"}
{"ts":"2026-08-24T20:48:29.727Z","event_type":"price_change","market_id":"3826919","outcome_index":0,"market_type":"set2","local_side":"home","local_uid":"2026-08-24_dalibor_svrcina_felipe_meligeni_alves","bid":0.43,"ask":0.52,"mid":0.475,"spread":0.09,"price":0.51,"size":0.0,"side":"SELL"}
{"ts":"2026-08-24T20:48:29.862Z","event_type":"best_bid_ask","market_id":"3825038","outcome_index":0,"market_type":"set1","local_side":"home","local_uid":"2026-08-24_greet_minnen_jeline_vandromme","bid":0.001,"ask":0.022,"mid":0.0115,"spread":0.021,"bid_size":null,"ask_size":null}
{"ts":"2026-08-24T20:48:29.863Z","event_type":"best_bid_ask","market_id":"3825038","outcome_index":1,"market_type":"set1","local_side":"away","local_uid":"2026-08-24_greet_minnen_jeline_vandromme","bid":0.978,"ask":0.999,"mid":0.9885,"spread":0.021,"bid_size":null,"ask_size":null}
{"ts":"2026-08-24T20:48:29.863Z","event_type":"price_change","market_id":"3825038","outcome_index":1,"market_type":"set1","local_side":"away","local_uid":"2026-08-24_greet_minnen_jeline_vandromme","bid":0.978,"ask":0.999,"mid":0.9885,"spread":0.021,"price":0.978,"size":150.0,"side":"BUY"}
{"ts":"2026-08-24T20:48:29.863Z","event_type":"price_change","market_id":"3825038","outcome_index":0,"market_type":"set1","local_side":"home","local_uid":"2026-08-24_greet_minnen_jeline_vandromme","bid":0.001,"ask":0.022,"mid":0.0115,"spread":0.021,"price":0.022,"size":150.0,"side":"SELL"}
{"ts":"2026-08-24T20:48:29.896Z","event_type":"best_bid_ask","market_id":"3826919","outcome_index":0,"market_type":"set2","local_side":"home","local_uid":"2026-08-24_dalibor_svrcina_felipe_meligeni_alves","bid":0.43,"ask":0.51,"mid":0.47,"spread":0.08,"bid_size":null,"ask_size":null}
{"ts":"2026-08-24T20:48:29.896Z","event_type":"best_bid_ask","market_id":"3826919","outcome_index":1,"market_type":"set2","local_side":"away","local_uid":"2026-08-24_dalibor_svrcina_felipe_meligeni_alves","bid":0.49,"ask":0.57,"mid":0.53,"spread":0.08,"bid_size":null,"ask_size":null}
{"ts":"2026-08-24T20:48:29.896Z","event_type":"price_change","market_id":"3826919","outcome_index":1,"market_type":"set2","local_side":"away","local_uid":"2026-08-24_dalibor_svrcina_felipe_meligeni_alves","bid":0.49,"ask":0.57,"mid":0.53,"spread":0.08,"price":0.49,"size":24.6,"side":"BUY"}
{"ts":"2026-08-24T20:48:29.896Z","event_type":"price_change","market_id":"3826919","outcome_index":0,"market_type":"set2","local_side":"home","local_uid":"2026-08-24_dalibor_svrcina_felipe_meligeni_alves","bid":0.43,"ask":0.51,"mid":0.47,"spread":0.08,"price":0.51,"size":24.6,"side":"SELL"}
{"ts":"2026-08-24T20:48:29.943Z","event_type":"best_bid_ask","market_id":"3826919","outcome_index":0,"market_type":"set2","local_side":"home","local_uid":"2026-08-24_dalibor_svrcina_felipe_meligeni_alves","bid":0.43,"ask":0.52,"mid":0.475,"spread":0.09,"bid_size":null,"ask_size":null}
{"ts":"2026-08-24T20:48:29.944Z","event_type":"best_bid_ask","market_id":"3826919","outcome_index":1,"market_type":"set2","local_side":"away","local_uid":"2026-08-24_dalibor_svrcina_felipe_meligeni_alves","bid":0.48,"ask":0.57,"mid":0.525,"spread":0.09,"bid_size":null,"ask_size":null}
{"ts":"2026-08-24T20:48:29.944Z","event_type":"price_change","market_id":"3826919","outcome_index":1,"market_type":"set2","local_side":"away","local_uid":"2026-08-24_dalibor_svrcina_felipe_meligeni_alves","bid":0.48,"ask":0.57,"mid":0.525,"spread":0.09,"price":0.49,"size":0.0,"side":"BUY"}
{"ts":"2026-08-24T20:48:29.944Z","event_type":"price_change","market_id":"3826919","outcome_index":0,"market_type":"set2","local_side":"home","local_uid":"2026-08-24_dalibor_svrcina_felipe_meligeni_alves","bid":0.43,"ask":0.52,"mid":0.475,"spread":0.09,"price":0.51,"size":0.0,"side":"SELL"}
{"ts":"2026-08-24T20:48:29.981Z","event_type":"best_bid_ask","market_id":"3826919","outcome_index":0,"market_type":"set2","local_side":"home","local_uid":"2026-08-24_dalibor_svrcina_felipe_meligeni_alves","bid":0.43,"ask":0.51,"mid":0.47,"spread":0.08,"bid_size":null,"ask_size":null}
{"ts":"2026-08-24T20:48:29.981Z","event_type":"best_bid_ask","market_id":"3826919","outcome_index":1,"market_type":"set2","local_side":"away","local_uid":"2026-08-24_dalibor_svrcina_felipe_meligeni_alves","bid":0.49,"ask":0.57,"mid":0.53,"spread":0.08,"bid_size":null,"ask_size":null}
{"ts":"2026-08-24T20:48:29.982Z","event_type":"price_change","market_id":"3826919","outcome_index":1,"market_type":"set2","local_side":"away","local_uid":"2026-08-24_dalibor_svrcina_felipe_meligeni_alves","bid":0.49,"ask":0.57,"mid":0.53,"spread":0.08,"price":0.49,"size":24.6,"side":"BUY"}
{"ts":"2026-08-24T20:48:29.982Z","event_type":"price_change","market_id":"3826919","outcome_index":0,"market_type":"set2","local_side":"home","local_uid":"2026-08-24_dalibor_svrcina_felipe_meligeni_alves","bid":0.43,"ask":0.51,"mid":0.47,"spread":0.08,"price":0.51,"size":24.6,"side":"SELL"}
{"ts":"2026-08-24T20:48:30.016Z","event_type":"best_bid_ask","market_id":"3826919","outcome_index":0,"market_type":"set2","local_side":"home","local_uid":"2026-08-24_dalibor_svrcina_felipe_meligeni_alves","bid":0.43,"ask":0.52,"mid":0.475,"spread":0.09,"bid_size":null,"ask_size":null}
{"ts":"2026-08-24T20:48:30.016Z","event_type":"best_bid_ask","market_id":"3826919","outcome_index":1,"market_type":"set2","local_side":"away","local_uid":"2026-08-24_dalibor_svrcina_felipe_meligeni_alves","bid":0.48,"ask":0.57,"mid":0.525,"spread":0.09,"bid_size":null,"ask_size":null}
{"ts":"2026-08-24T20:48:30.016Z","event_type":"price_change","market_id":"3826919","outcome_index":1,"market_type":"set2","local_side":"away","local_uid":"2026-08-24_dalibor_svrcina_felipe_meligeni_alves","bid":0.48,"ask":0.57,"mid":0.525,"spread":0.09,"price":0.49,"size":0.0,"side":"BUY"}
{"ts":"2026-08-24T20:48:30.017Z","event_type":"price_change","market_id":"3826919","outcome_index":0,"market_type":"set2","local_side":"home","local_uid":"2026-08-24_dalibor_svrcina_felipe_meligeni_alves","bid":0.43,"ask":0.52,"mid":0.475,"spread":0.09,"price":0.51,"size":0.0,"side":"SELL"}
{"ts":"2026-08-24T20:48:30.075Z","event_type":"best_bid_ask","market_id":"3825631","outcome_index":0,"market_type":"match","local_side":"home","local_uid":"2026-08-24_harry_wendelken_stefano_travaglia","bid":0.64,"ask":0.66,"mid":0.65,"spread":0.02,"bid_size":null,"ask_size":null}
{"ts":"2026-08-24T20:48:30.075Z","event_type":"best_bid_ask","market_id":"3825631","outcome_index":1,"market_type":"match","local_side":"away","local_uid":"2026-08-24_harry_wendelken_stefano_travaglia","bid":0.34,"ask":0.36,"mid":0.35,"spread":0.02,"bid_size":null,"ask_size":null}
{"ts":"2026-08-24T20:48:30.076Z","event_type":"price_change","market_id":"3825631","outcome_index":1,"market_type":"match","local_side":"away","local_uid":"2026-08-24_harry_wendelken_stefano_travaglia","bid":0.34,"ask":0.36,"mid":0.35,"spread":0.02,"price":0.35,"size":0.0,"side":"BUY"}
{"ts":"2026-08-24T20:48:30.076Z","event_type":"price_change","market_id":"3825631","outcome_index":0,"market_type":"match","local_side":"home","local_uid":"2026-08-24_harry_wendelken_stefano_travaglia","bid":0.64,"ask":0.66,"mid":0.65,"spread":0.02,"price":0.65,"size":0.0,"side":"SELL"}
{"ts":"2026-08-24T20:48:30.077Z","event_type":"book","market_id":"3825631","outcome_index":0,"market_type":"match","local_side":"home","local_uid":"2026-08-24_harry_wendelken_stefano_travaglia","bid":0.64,"ask":0.66,"mid":0.65,"spread":0.02,"bid_size":63493.5,"ask_size":365.0}
{"ts":"2026-08-24T20:48:30.078Z","event_type":"book","market_id":"3825631","outcome_index":1,"market_type":"match","local_side":"away","local_uid":"2026-08-24_harry_wendelken_stefano_travaglia","bid":0.34,"ask":0.36,"mid":0.35,"spread":0.02,"bid_size":365.0,"ask_size":63493.5}
{"ts":"2026-08-24T20:48:30.153Z","event_type":"best_bid_ask","market_id":"3825631","outcome_index":0,"market_type":"match","local_side":"home","local_uid":"2026-08-24_harry_wendelken_stefano_travaglia","bid":0.65,"ask":0.66,"mid":0.655,"spread":0.01,"bid_size":null,"ask_size":null}
{"ts":"2026-08-24T20:48:30.153Z","event_type":"best_bid_ask","market_id":"3825631","outcome_index":1,"market_type":"match","local_side":"away","local_uid":"2026-08-24_harry_wendelken_stefano_travaglia","bid":0.34,"ask":0.35,"mid":0.345,"spread":0.01,"bid_size":null,"ask_size":null}
{"ts":"2026-08-24T20:48:30.153Z","event_type":"price_change","market_id":"3825631","outcome_index":0,"market_type":"match","local_side":"home","local_uid":"2026-08-24_harry_wendelken_stefano_travaglia","bid":0.65,"ask":0.66,"mid":0.655,"spread":0.01,"price":0.65,"size":60.0,"side":"BUY"}
{"ts":"2026-08-24T20:48:30.154Z","event_type":"price_change","market_id":"3825631","outcome_index":1,"market_type":"match","local_side":"away","local_uid":"2026-08-24_harry_wendelken_stefano_travaglia","bid":0.34,"ask":0.35,"mid":0.345,"spread":0.01,"price":0.35,"size":60.0,"side":"SELL"}
{"ts":"2026-08-24T20:48:30.156Z","event_type":"last_trade_price","market_id":"3825631","outcome_index":0,"market_type":"match","local_side":"home","local_uid":"2026-08-24_harry_wendelken_stefano_travaglia","last_trade":0.66,"trade_size":60.0,"trade_side":"BUY","trade_notional":39.6}
{"ts":"2026-08-24T20:48:30.166Z","event_type":"book","market_id":"3823665","outcome_index":0,"market_type":"match","local_side":"home","local_uid":"2026-08-24_jazmin_ortenzi_himeno_sakatsume","bid":0.15,"ask":0.16,"mid":0.155,"spread":0.01,"bid_size":100.0,"ask_size":17141.56}
{"ts":"2026-08-24T20:48:30.167Z","event_type":"book","market_id":"3823665","outcome_index":1,"market_type":"match","local_side":"away","local_uid":"2026-08-24_jazmin_ortenzi_himeno_sakatsume","bid":0.84,"ask":0.85,"mid":0.845,"spread":0.01,"bid_size":17141.56,"ask_size":100.0}
{"ts":"2026-08-24T20:48:30.175Z","event_type":"last_trade_price","market_id":"3825631","outcome_index":0,"market_type":"match","local_side":"home","local_uid":"2026-08-24_harry_wendelken_stefano_travaglia","last_trade":0.65,"trade_size":36.94,"trade_side":"BUY","trade_notional":24.011}
{"ts":"2026-08-24T20:48:30.192Z","event_type":"best_bid_ask","market_id":"3825070","outcome_index":0,"market_type":"set2","local_side":"home","local_uid":"2026-08-24_polina_kudermetova_linda_fruhvirtova","bid":0.52,"ask":0.61,"mid":0.565,"spread":0.09,"bid_size":null,"ask_size":null}
{"ts":"2026-08-24T20:48:30.194Z","event_type":"best_bid_ask","market_id":"3825070","outcome_index":1,"market_type":"set2","local_side":"away","local_uid":"2026-08-24_polina_kudermetova_linda_fruhvirtova","bid":0.39,"ask":0.48,"mid":0.435,"spread":0.09,"bid_size":null,"ask_size":null}
{"ts":"2026-08-24T20:48:30.194Z","event_type":"price_change","market_id":"3825070","outcome_index":0,"market_type":"set2","local_side":"home","local_uid":"2026-08-24_polina_kudermetova_linda_fruhvirtova","bid":0.52,"ask":0.61,"mid":0.565,"spread":0.09,"price":0.53,"size":0.0,"side":"BUY"}
{"ts":"2026-08-24T20:48:30.194Z","event_type":"price_change","market_id":"3825070","outcome_index":1,"market_type":"set2","local_side":"away","local_uid":"2026-08-24_polina_kudermetova_linda_fruhvirtova","bid":0.39,"ask":0.48,"mid":0.435,"spread":0.09,"price":0.47,"size":0.0,"side":"SELL"}
{"ts":"2026-08-24T20:48:30.203Z","event_type":"best_bid_ask","market_id":"3824761","outcome_index":0,"market_type":"set1","local_side":"home","local_uid":"2026-08-24_jazmin_ortenzi_himeno_sakatsume","bid":0.12,"ask":0.21,"mid":0.165,"spread":0.09,"bid_size":null,"ask_size":null}
{"ts":"2026-08-24T20:48:30.203Z","event_type":"best_bid_ask","market_id":"3824761","outcome_index":1,"market_type":"set1","local_side":"away","local_uid":"2026-08-24_jazmin_ortenzi_himeno_sakatsume","bid":0.79,"ask":0.88,"mid":0.835,"spread":0.09,"bid_size":null,"ask_size":null}
{"ts":"2026-08-24T20:48:30.203Z","event_type":"price_change","market_id":"3824761","outcome_index":0,"market_type":"set1","local_side":"home","local_uid":"2026-08-24_jazmin_ortenzi_himeno_sakatsume","bid":0.12,"ask":0.21,"mid":0.165,"spread":0.09,"price":0.13,"size":0.0,"side":"BUY"}
{"ts":"2026-08-24T20:48:30.204Z","event_type":"price_change","market_id":"3824761","outcome_index":1,"market_type":"set1","local_side":"away","local_uid":"2026-08-24_jazmin_ortenzi_himeno_sakatsume","bid":0.79,"ask":0.88,"mid":0.835,"spread":0.09,"price":0.87,"size":0.0,"side":"SELL"}
{"ts":"2026-08-24T20:48:30.214Z","event_type":"last_trade_price","market_id":"3825631","outcome_index":0,"market_type":"match","local_side":"home","local_uid":"2026-08-24_harry_wendelken_stefano_travaglia","last_trade":0.66,"trade_size":1.5151,"trade_side":"BUY","trade_notional":1.0}
{"ts":"2026-08-24T20:48:30.237Z","event_type":"best_bid_ask","market_id":"3824761","outcome_index":0,"market_type":"set1","local_side":"home","local_uid":"2026-08-24_jazmin_ortenzi_himeno_sakatsume","bid":0.12,"ask":0.2,"mid":0.16,"spread":0.08,"bid_size":null,"ask_size":null}
{"ts":"2026-08-24T20:48:30.238Z","event_type":"best_bid_ask","market_id":"3824761","outcome_index":1,"market_type":"set1","local_side":"away","local_uid":"2026-08-24_jazmin_ortenzi_himeno_sakatsume","bid":0.8,"ask":0.88,"mid":0.84,"spread":0.08,"bid_size":null,"ask_size":null}
{"ts":"2026-08-24T20:48:30.238Z","event_type":"price_change","market_id":"3824761","outcome_index":1,"market_type":"set1","local_side":"away","local_uid":"2026-08-24_jazmin_ortenzi_himeno_sakatsume","bid":0.8,"ask":0.88,"mid":0.84,"spread":0.08,"price":0.8,"size":250.0,"side":"BUY"}
{"ts":"2026-08-24T20:48:30.238Z","event_type":"price_change","market_id":"3824761","outcome_index":0,"market_type":"set1","local_side":"home","local_uid":"2026-08-24_jazmin_ortenzi_himeno_sakatsume","bid":0.12,"ask":0.2,"mid":0.16,"spread":0.08,"price":0.2,"size":250.0,"side":"SELL"}
{"ts":"2026-08-24T20:48:30.258Z","event_type":"best_bid_ask","market_id":"3824761","outcome_index":0,"market_type":"set1","local_side":"home","local_uid":"2026-08-24_jazmin_ortenzi_himeno_sakatsume","bid":0.13,"ask":0.2,"mid":0.165,"spread":0.07,"bid_size":null,"ask_size":null}
{"ts":"2026-08-24T20:48:30.258Z","event_type":"best_bid_ask","market_id":"3824761","outcome_index":1,"market_type":"set1","local_side":"away","local_uid":"2026-08-24_jazmin_ortenzi_himeno_sakatsume","bid":0.8,"ask":0.87,"mid":0.835,"spread":0.07,"bid_size":null,"ask_size":null}
{"ts":"2026-08-24T20:48:30.258Z","event_type":"price_change","market_id":"3824761","outcome_index":0,"market_type":"set1","local_side":"home","local_uid":"2026-08-24_jazmin_ortenzi_himeno_sakatsume","bid":0.13,"ask":0.2,"mid":0.165,"spread":0.07,"price":0.13,"size":250.0,"side":"BUY"}
{"ts":"2026-08-24T20:48:30.259Z","event_type":"price_change","market_id":"3824761","outcome_index":1,"market_type":"set1","local_side":"away","local_uid":"2026-08-24_jazmin_ortenzi_himeno_sakatsume","bid":0.8,"ask":0.87,"mid":0.835,"spread":0.07,"price":0.87,"size":250.0,"side":"SELL"}
{"ts":"2026-08-24T20:48:30.298Z","event_type":"last_trade_price","market_id":"3823665","outcome_index":1,"market_type":"match","local_side":"away","local_uid":"2026-08-24_jazmin_ortenzi_himeno_sakatsume","last_trade":0.85,"trade_size":1.1765,"trade_side":"BUY","trade_notional":1.0}
{"ts":"2026-08-24T20:48:30.301Z","event_type":"best_bid_ask","market_id":"3826919","outcome_index":0,"market_type":"set2","local_side":"home","local_uid":"2026-08-24_dalibor_svrcina_felipe_meligeni_alves","bid":0.43,"ask":0.51,"mid":0.47,"spread":0.08,"bid_size":null,"ask_size":null}
{"ts":"2026-08-24T20:48:30.301Z","event_type":"best_bid_ask","market_id":"3826919","outcome_index":1,"market_type":"set2","local_side":"away","local_uid":"2026-08-24_dalibor_svrcina_felipe_meligeni_alves","bid":0.49,"ask":0.57,"mid":0.53,"spread":0.08,"bid_size":null,"ask_size":null}
{"ts":"2026-08-24T20:48:30.302Z","event_type":"price_change","market_id":"3826919","outcome_index":1,"market_type":"set2","local_side":"away","local_uid":"2026-08-24_dalibor_svrcina_felipe_meligeni_alves","bid":0.49,"ask":0.57,"mid":0.53,"spread":0.08,"price":0.49,"size":24.6,"side":"BUY"}
{"ts":"2026-08-24T20:48:30.302Z","event_type":"price_change","market_id":"3826919","outcome_index":0,"market_type":"set2","local_side":"home","local_uid":"2026-08-24_dalibor_svrcina_felipe_meligeni_alves","bid":0.43,"ask":0.51,"mid":0.47,"spread":0.08,"price":0.51,"size":24.6,"side":"SELL"}
{"ts":"2026-08-24T20:48:30.327Z","event_type":"best_bid_ask","market_id":"3826919","outcome_index":0,"market_type":"set2","local_side":"home","local_uid":"2026-08-24_dalibor_svrcina_felipe_meligeni_alves","bid":0.43,"ask":0.52,"mid":0.475,"spread":0.09,"bid_size":null,"ask_size":null}
{"ts":"2026-08-24T20:48:30.327Z","event_type":"best_bid_ask","market_id":"3826919","outcome_index":1,"market_type":"set2","local_side":"away","local_uid":"2026-08-24_dalibor_svrcina_felipe_meligeni_alves","bid":0.48,"ask":0.57,"mid":0.525,"spread":0.09,"bid_size":null,"ask_size":null}
{"ts":"2026-08-24T20:48:30.327Z","event_type":"price_change","market_id":"3826919","outcome_index":1,"market_type":"set2","local_side":"away","local_uid":"2026-08-24_dalibor_svrcina_felipe_meligeni_alves","bid":0.48,"ask":0.57,"mid":0.525,"spread":0.09,"price":0.49,"size":0.0,"side":"BUY"}
{"ts":"2026-08-24T20:48:30.327Z","event_type":"price_change","market_id":"3826919","outcome_index":0,"market_type":"set2","local_side":"home","local_uid":"2026-08-24_dalibor_svrcina_felipe_meligeni_alves","bid":0.43,"ask":0.52,"mid":0.475,"spread":0.09,"price":0.51,"size":0.0,"side":"SELL"}
{"ts":"2026-08-24T20:48:30.403Z","event_type":"best_bid_ask","market_id":"3825631","outcome_index":0,"market_type":"match","local_side":"home","local_uid":"2026-08-24_harry_wendelken_stefano_travaglia","bid":0.65,"ask":0.67,"mid":0.66,"spread":0.02,"bid_size":null,"ask_size":null}
{"ts":"2026-08-24T20:48:30.403Z","event_type":"best_bid_ask","market_id":"3825631","outcome_index":1,"market_type":"match","local_side":"away","local_uid":"2026-08-24_harry_wendelken_stefano_travaglia","bid":0.33,"ask":0.35,"mid":0.34,"spread":0.02,"bid_size":null,"ask_size":null}
{"ts":"2026-08-24T20:48:30.404Z","event_type":"price_change","market_id":"3825631","outcome_index":1,"market_type":"match","local_side":"away","local_uid":"2026-08-24_harry_wendelken_stefano_travaglia","bid":0.33,"ask":0.35,"mid":0.34,"spread":0.02,"price":0.34,"size":0.0,"side":"BUY"}
{"ts":"2026-08-24T20:48:30.404Z","event_type":"price_change","market_id":"3825631","outcome_index":0,"market_type":"match","local_side":"home","local_uid":"2026-08-24_harry_wendelken_stefano_travaglia","bid":0.65,"ask":0.67,"mid":0.66,"spread":0.02,"price":0.66,"size":0.0,"side":"SELL"}
{"ts":"2026-08-24T20:48:30.408Z","event_type":"best_bid_ask","market_id":"3825631","outcome_index":0,"market_type":"match","local_side":"home","local_uid":"2026-08-24_harry_wendelken_stefano_travaglia","bid":0.66,"ask":0.67,"mid":0.665,"spread":0.01,"bid_size":null,"ask_size":null}
{"ts":"2026-08-24T20:48:30.408Z","event_type":"best_bid_ask","market_id":"3825631","outcome_index":1,"market_type":"match","local_side":"away","local_uid":"2026-08-24_harry_wendelken_stefano_travaglia","bid":0.33,"ask":0.34,"mid":0.335,"spread":0.01,"bid_size":null,"ask_size":null}
{"ts":"2026-08-24T20:48:30.409Z","event_type":"price_change","market_id":"3825631","outcome_index":0,"market_type":"match","local_side":"home","local_uid":"2026-08-24_harry_wendelken_stefano_travaglia","bid":0.66,"ask":0.67,"mid":0.665,"spread":0.01,"price":0.66,"size":10.0,"side":"BUY"}
{"ts":"2026-08-24T20:48:30.409Z","event_type":"price_change","market_id":"3825631","outcome_index":1,"market_type":"match","local_side":"away","local_uid":"2026-08-24_harry_wendelken_stefano_travaglia","bid":0.33,"ask":0.34,"mid":0.335,"spread":0.01,"price":0.34,"size":10.0,"side":"SELL"}
{"ts":"2026-08-24T20:48:30.506Z","event_type":"best_bid_ask","market_id":"3826733","outcome_index":0,"market_type":"set1","local_side":"home","local_uid":"2026-08-24_harry_wendelken_stefano_travaglia","bid":0.9,"ask":0.96,"mid":0.93,"spread":0.06,"bid_size":null,"ask_size":null}
{"ts":"2026-08-24T20:48:30.507Z","event_type":"best_bid_ask","market_id":"3826733","outcome_index":1,"market_type":"set1","local_side":"away","local_uid":"2026-08-24_harry_wendelken_stefano_travaglia","bid":0.04,"ask":0.1,"mid":0.07,"spread":0.06,"bid_size":null,"ask_size":null}
{"ts":"2026-08-24T20:48:30.507Z","event_type":"price_change","market_id":"3826733","outcome_index":1,"market_type":"set1","local_side":"away","local_uid":"2026-08-24_harry_wendelken_stefano_travaglia","bid":0.04,"ask":0.1,"mid":0.07,"spread":0.06,"price":0.05,"size":0.0,"side":"BUY"}
{"ts":"2026-08-24T20:48:30.507Z","event_type":"price_change","market_id":"3826733","outcome_index":0,"market_type":"set1","local_side":"home","local_uid":"2026-08-24_harry_wendelken_stefano_travaglia","bid":0.9,"ask":0.96,"mid":0.93,"spread":0.06,"price":0.95,"size":0.0,"side":"SELL"}
{"ts":"2026-08-24T20:48:30.534Z","event_type":"best_bid_ask","market_id":"3826733","outcome_index":0,"market_type":"set1","local_side":"home","local_uid":"2026-08-24_harry_wendelken_stefano_travaglia","bid":0.9,"ask":0.94,"mid":0.92,"spread":0.04,"bid_size":null,"ask_size":null}
{"ts":"2026-08-24T20:48:30.534Z","event_type":"best_bid_ask","market_id":"3826733","outcome_index":1,"market_type":"set1","local_side":"away","local_uid":"2026-08-24_harry_wendelken_stefano_travaglia","bid":0.06,"ask":0.1,"mid":0.08,"spread":0.04,"bid_size":null,"ask_size":null}
{"ts":"2026-08-24T20:48:30.534Z","event_type":"price_change","market_id":"3826733","outcome_index":1,"market_type":"set1","local_side":"away","local_uid":"2026-08-24_harry_wendelken_stefano_travaglia","bid":0.06,"ask":0.1,"mid":0.08,"spread":0.04,"price":0.06,"size":200.0,"side":"BUY"}
{"ts":"2026-08-24T20:48:30.534Z","event_type":"price_change","market_id":"3826733","outcome_index":0,"market_type":"set1","local_side":"home","local_uid":"2026-08-24_harry_wendelken_stefano_travaglia","bid":0.9,"ask":0.94,"mid":0.92,"spread":0.04,"price":0.94,"size":200.0,"side":"SELL"}
{"ts":"2026-08-24T20:48:30.557Z","event_type":"best_bid_ask","market_id":"3826919","outcome_index":0,"market_type":"set2","local_side":"home","local_uid":"2026-08-24_dalibor_svrcina_felipe_meligeni_alves","bid":0.43,"ask":0.51,"mid":0.47,"spread":0.08,"bid_size":null,"ask_size":null}
{"ts":"2026-08-24T20:48:30.558Z","event_type":"best_bid_ask","market_id":"3826919","outcome_index":1,"market_type":"set2","local_side":"away","local_uid":"2026-08-24_dalibor_svrcina_felipe_meligeni_alves","bid":0.49,"ask":0.57,"mid":0.53,"spread":0.08,"bid_size":null,"ask_size":null}
{"ts":"2026-08-24T20:48:30.558Z","event_type":"price_change","market_id":"3826919","outcome_index":1,"market_type":"set2","local_side":"away","local_uid":"2026-08-24_dalibor_svrcina_felipe_meligeni_alves","bid":0.49,"ask":0.57,"mid":0.53,"spread":0.08,"price":0.49,"size":24.6,"side":"BUY"}
{"ts":"2026-08-24T20:48:30.558Z","event_type":"price_change","market_id":"3826919","outcome_index":0,"market_type":"set2","local_side":"home","local_uid":"2026-08-24_dalibor_svrcina_felipe_meligeni_alves","bid":0.43,"ask":0.51,"mid":0.47,"spread":0.08,"price":0.51,"size":24.6,"side":"SELL"}
{"ts":"2026-08-24T20:48:30.634Z","event_type":"best_bid_ask","market_id":"3826919","outcome_index":0,"market_type":"set2","local_side":"home","local_uid":"2026-08-24_dalibor_svrcina_felipe_meligeni_alves","bid":0.43,"ask":0.52,"mid":0.475,"spread":0.09,"bid_size":null,"ask_size":null}
{"ts":"2026-08-24T20:48:30.638Z","event_type":"best_bid_ask","market_id":"3826919","outcome_index":1,"market_type":"set2","local_side":"away","local_uid":"2026-08-24_dalibor_svrcina_felipe_meligeni_alves","bid":0.48,"ask":0.57,"mid":0.525,"spread":0.09,"bid_size":null,"ask_size":null}
{"ts":"2026-08-24T20:48:30.638Z","event_type":"price_change","market_id":"3826919","outcome_index":1,"market_type":"set2","local_side":"away","local_uid":"2026-08-24_dalibor_svrcina_felipe_meligeni_alves","bid":0.48,"ask":0.57,"mid":0.525,"spread":0.09,"price":0.49,"size":0.0,"side":"BUY"}
{"ts":"2026-08-24T20:48:30.638Z","event_type":"price_change","market_id":"3826919","outcome_index":0,"market_type":"set2","local_side":"home","local_uid":"2026-08-24_dalibor_svrcina_felipe_meligeni_alves","bid":0.43,"ask":0.52,"mid":0.475,"spread":0.09,"price":0.51,"size":0.0,"side":"SELL"}
{"ts":"2026-08-24T20:48:30.654Z","event_type":"best_bid_ask","market_id":"3825077","outcome_index":0,"market_type":"set1","local_side":"home","local_uid":"2026-08-24_polina_kudermetova_linda_fruhvirtova","bid":0.45,"ask":0.51,"mid":0.48,"spread":0.06,"bid_size":null,"ask_size":null}
{"ts":"2026-08-24T20:48:30.655Z","event_type":"best_bid_ask","market_id":"3825077","outcome_index":1,"market_type":"set1","local_side":"away","local_uid":"2026-08-24_polina_kudermetova_linda_fruhvirtova","bid":0.49,"ask":0.55,"mid":0.52,"spread":0.06,"bid_size":null,"ask_size":null}
{"ts":"2026-08-24T20:48:30.655Z","event_type":"price_change","market_id":"3825077","outcome_index":1,"market_type":"set1","local_side":"away","local_uid":"2026-08-24_polina_kudermetova_linda_fruhvirtova","bid":0.49,"ask":0.55,"mid":0.52,"spread":0.06,"price":0.5,"size":0.0,"side":"BUY"}
{"ts":"2026-08-24T20:48:30.655Z","event_type":"price_change","market_id":"3825077","outcome_index":0,"market_type":"set1","local_side":"home","local_uid":"2026-08-24_polina_kudermetova_linda_fruhvirtova","bid":0.45,"ask":0.51,"mid":0.48,"spread":0.06,"price":0.5,"size":0.0,"side":"SELL"}
{"ts":"2026-08-24T20:48:30.732Z","event_type":"best_bid_ask","market_id":"3826654","outcome_index":0,"market_type":"set2","local_side":"home","local_uid":"2026-08-24_sebastian_gorzny_cruz_hewitt","bid":0.05,"ask":0.13,"mid":0.09,"spread":0.08,"bid_size":null,"ask_size":null}
{"ts":"2026-08-24T20:48:30.733Z","event_type":"best_bid_ask","market_id":"3826654","outcome_index":1,"market_type":"set2","local_side":"away","local_uid":"2026-08-24_sebastian_gorzny_cruz_hewitt","bid":0.87,"ask":0.95,"mid":0.91,"spread":0.08,"bid_size":null,"ask_size":null}
{"ts":"2026-08-24T20:48:30.733Z","event_type":"price_change","market_id":"3826654","outcome_index":0,"market_type":"set2","local_side":"home","local_uid":"2026-08-24_sebastian_gorzny_cruz_hewitt","bid":0.05,"ask":0.13,"mid":0.09,"spread":0.08,"price":0.06,"size":0.0,"side":"BUY"}
{"ts":"2026-08-24T20:48:30.733Z","event_type":"price_change","market_id":"3826654","outcome_index":1,"market_type":"set2","local_side":"away","local_uid":"2026-08-24_sebastian_gorzny_cruz_hewitt","bid":0.87,"ask":0.95,"mid":0.91,"spread":0.08,"price":0.94,"size":0.0,"side":"SELL"}
{"ts":"2026-08-24T20:48:30.788Z","event_type":"best_bid_ask","market_id":"3823627","outcome_index":0,"market_type":"match","local_side":"home","local_uid":"2026-08-24_claire_liu_heather_watson","bid":0.35,"ask":0.37,"mid":0.36,"spread":0.02,"bid_size":null,"ask_size":null}
{"ts":"2026-08-24T20:48:30.788Z","event_type":"best_bid_ask","market_id":"3823627","outcome_index":1,"market_type":"match","local_side":"away","local_uid":"2026-08-24_claire_liu_heather_watson","bid":0.63,"ask":0.65,"mid":0.64,"spread":0.02,"bid_size":null,"ask_size":null}
{"ts":"2026-08-24T20:48:30.790Z","event_type":"price_change","market_id":"3823627","outcome_index":0,"market_type":"match","local_side":"home","local_uid":"2026-08-24_claire_liu_heather_watson","bid":0.35,"ask":0.37,"mid":0.36,"spread":0.02,"price":0.36,"size":0.0,"side":"BUY"}
{"ts":"2026-08-24T20:48:30.790Z","event_type":"price_change","market_id":"3823627","outcome_index":1,"market_type":"match","local_side":"away","local_uid":"2026-08-24_claire_liu_heather_watson","bid":0.63,"ask":0.65,"mid":0.64,"spread":0.02,"price":0.64,"size":0.0,"side":"SELL"}
{"ts":"2026-08-24T20:48:30.827Z","event_type":"best_bid_ask","market_id":"3826919","outcome_index":0,"market_type":"set2","local_side":"home","local_uid":"2026-08-24_dalibor_svrcina_felipe_meligeni_alves","bid":0.43,"ask":0.51,"mid":0.47,"spread":0.08,"bid_size":null,"ask_size":null}
{"ts":"2026-08-24T20:48:30.827Z","event_type":"best_bid_ask","market_id":"3826919","outcome_index":1,"market_type":"set2","local_side":"away","local_uid":"2026-08-24_dalibor_svrcina_felipe_meligeni_alves","bid":0.49,"ask":0.57,"mid":0.53,"spread":0.08,"bid_size":null,"ask_size":null}
{"ts":"2026-08-24T20:48:30.828Z","event_type":"price_change","market_id":"3826919","outcome_index":1,"market_type":"set2","local_side":"away","local_uid":"2026-08-24_dalibor_svrcina_felipe_meligeni_alves","bid":0.49,"ask":0.57,"mid":0.53,"spread":0.08,"price":0.49,"size":24.6,"side":"BUY"}
{"ts":"2026-08-24T20:48:30.828Z","event_type":"price_change","market_id":"3826919","outcome_index":0,"market_type":"set2","local_side":"home","local_uid":"2026-08-24_dalibor_svrcina_felipe_meligeni_alves","bid":0.43,"ask":0.51,"mid":0.47,"spread":0.08,"price":0.51,"size":24.6,"side":"SELL"}
{"ts":"2026-08-24T20:48:30.858Z","event_type":"best_bid_ask","market_id":"3826919","outcome_index":0,"market_type":"set2","local_side":"home","local_uid":"2026-08-24_dalibor_svrcina_felipe_meligeni_alves","bid":0.43,"ask":0.52,"mid":0.475,"spread":0.09,"bid_size":null,"ask_size":null}
{"ts":"2026-08-24T20:48:30.858Z","event_type":"best_bid_ask","market_id":"3826919","outcome_index":1,"market_type":"set2","local_side":"away","local_uid":"2026-08-24_dalibor_svrcina_felipe_meligeni_alves","bid":0.48,"ask":0.57,"mid":0.525,"spread":0.09,"bid_size":null,"ask_size":null}
{"ts":"2026-08-24T20:48:30.859Z","event_type":"price_change","market_id":"3826919","outcome_index":1,"market_type":"set2","local_side":"away","local_uid":"2026-08-24_dalibor_svrcina_felipe_meligeni_alves","bid":0.48,"ask":0.57,"mid":0.525,"spread":0.09,"price":0.49,"size":0.0,"side":"BUY"}
{"ts":"2026-08-24T20:48:30.859Z","event_type":"price_change","market_id":"3826919","outcome_index":0,"market_type":"set2","local_side":"home","local_uid":"2026-08-24_dalibor_svrcina_felipe_meligeni_alves","bid":0.43,"ask":0.52,"mid":0.475,"spread":0.09,"price":0.51,"size":0.0,"side":"SELL"}
{"ts":"2026-08-24T20:48:31.055Z","event_type":"best_bid_ask","market_id":"3826919","outcome_index":0,"market_type":"set2","local_side":"home","local_uid":"2026-08-24_dalibor_svrcina_felipe_meligeni_alves","bid":0.43,"ask":0.51,"mid":0.47,"spread":0.08,"bid_size":null,"ask_size":null}
{"ts":"2026-08-24T20:48:31.056Z","event_type":"best_bid_ask","market_id":"3826919","outcome_index":1,"market_type":"set2","local_side":"away","local_uid":"2026-08-24_dalibor_svrcina_felipe_meligeni_alves","bid":0.49,"ask":0.57,"mid":0.53,"spread":0.08,"bid_size":null,"ask_size":null}
{"ts":"2026-08-24T20:48:31.056Z","event_type":"price_change","market_id":"3826919","outcome_index":1,"market_type":"set2","local_side":"away","local_uid":"2026-08-24_dalibor_svrcina_felipe_meligeni_alves","bid":0.49,"ask":0.57,"mid":0.53,"spread":0.08,"price":0.49,"size":24.6,"side":"BUY"}
{"ts":"2026-08-24T20:48:31.056Z","event_type":"price_change","market_id":"3826919","outcome_index":0,"market_type":"set2","local_side":"home","local_uid":"2026-08-24_dalibor_svrcina_felipe_meligeni_alves","bid":0.43,"ask":0.51,"mid":0.47,"spread":0.08,"price":0.51,"size":24.6,"side":"SELL"}
{"ts":"2026-08-24T20:48:31.058Z","event_type":"best_bid_ask","market_id":"3823619","outcome_index":0,"market_type":"match","local_side":"home","local_uid":"2026-08-24_polina_kudermetova_linda_fruhvirtova","bid":0.56,"ask":0.58,"mid":0.57,"spread":0.02,"bid_size":null,"ask_size":null}
{"ts":"2026-08-24T20:48:31.058Z","event_type":"best_bid_ask","market_id":"3823619","outcome_index":1,"market_type":"match","local_side":"away","local_uid":"2026-08-24_polina_kudermetova_linda_fruhvirtova","bid":0.42,"ask":0.44,"mid":0.43,"spread":0.02,"bid_size":null,"ask_size":null}
{"ts":"2026-08-24T20:48:31.058Z","event_type":"price_change","market_id":"3823619","outcome_index":0,"market_type":"match","local_side":"home","local_uid":"2026-08-24_polina_kudermetova_linda_fruhvirtova","bid":0.56,"ask":0.58,"mid":0.57,"spread":0.02,"price":0.57,"size":0.0,"side":"SELL"}
{"ts":"2026-08-24T20:48:31.058Z","event_type":"price_change","market_id":"3823619","outcome_index":1,"market_type":"match","local_side":"away","local_uid":"2026-08-24_polina_kudermetova_linda_fruhvirtova","bid":0.42,"ask":0.44,"mid":0.43,"spread":0.02,"price":0.43,"size":0.0,"side":"BUY"}
{"ts":"2026-08-24T20:48:31.105Z","event_type":"best_bid_ask","market_id":"3826919","outcome_index":0,"market_type":"set2","local_side":"home","local_uid":"2026-08-24_dalibor_svrcina_felipe_meligeni_alves","bid":0.43,"ask":0.52,"mid":0.475,"spread":0.09,"bid_size":null,"ask_size":null}
{"ts":"2026-08-24T20:48:31.105Z","event_type":"best_bid_ask","market_id":"3826919","outcome_index":1,"market_type":"set2","local_side":"away","local_uid":"2026-08-24_dalibor_svrcina_felipe_meligeni_alves","bid":0.48,"ask":0.57,"mid":0.525,"spread":0.09,"bid_size":null,"ask_size":null}
{"ts":"2026-08-24T20:48:31.106Z","event_type":"price_change","market_id":"3826919","outcome_index":1,"market_type":"set2","local_side":"away","local_uid":"2026-08-24_dalibor_svrcina_felipe_meligeni_alves","bid":0.48,"ask":0.57,"mid":0.525,"spread":0.09,"price":0.49,"size":0.0,"side":"BUY"}
{"ts":"2026-08-24T20:48:31.106Z","event_type":"price_change","market_id":"3826919","outcome_index":0,"market_type":"set2","local_side":"home","local_uid":"2026-08-24_dalibor_svrcina_felipe_meligeni_alves","bid":0.43,"ask":0.52,"mid":0.475,"spread":0.09,"price":0.51,"size":0.0,"side":"SELL"}
{"ts":"2026-08-24T20:48:31.106Z","event_type":"best_bid_ask","market_id":"3823665","outcome_index":0,"market_type":"match","local_side":"home","local_uid":"2026-08-24_jazmin_ortenzi_himeno_sakatsume","bid":0.14,"ask":0.16,"mid":0.15,"spread":0.02,"bid_size":null,"ask_size":null}
{"ts":"2026-08-24T20:48:31.107Z","event_type":"best_bid_ask","market_id":"3823665","outcome_index":1,"market_type":"match","local_side":"away","local_uid":"2026-08-24_jazmin_ortenzi_himeno_sakatsume","bid":0.84,"ask":0.86,"mid":0.85,"spread":0.02,"bid_size":null,"ask_size":null}
{"ts":"2026-08-24T20:48:31.107Z","event_type":"price_change","market_id":"3823665","outcome_index":0,"market_type":"match","local_side":"home","local_uid":"2026-08-24_jazmin_ortenzi_himeno_sakatsume","bid":0.14,"ask":0.16,"mid":0.15,"spread":0.02,"price":0.15,"size":0.0,"side":"BUY"}
{"ts":"2026-08-24T20:48:31.107Z","event_type":"price_change","market_id":"3823665","outcome_index":1,"market_type":"match","local_side":"away","local_uid":"2026-08-24_jazmin_ortenzi_himeno_sakatsume","bid":0.84,"ask":0.86,"mid":0.85,"spread":0.02,"price":0.85,"size":0.0,"side":"SELL"}
{"ts":"2026-08-24T20:48:31.108Z","event_type":"book","market_id":"3823665","outcome_index":0,"market_type":"match","local_side":"home","local_uid":"2026-08-24_jazmin_ortenzi_himeno_sakatsume","bid":0.14,"ask":0.16,"mid":0.15,"spread":0.02,"bid_size":699.0,"ask_size":22396.56}
{"ts":"2026-08-24T20:48:31.109Z","event_type":"book","market_id":"3823665","outcome_index":1,"market_type":"match","local_side":"away","local_uid":"2026-08-24_jazmin_ortenzi_himeno_sakatsume","bid":0.84,"ask":0.86,"mid":0.85,"spread":0.02,"bid_size":22396.56,"ask_size":699.0}
{"ts":"2026-08-24T20:48:31.109Z","event_type":"best_bid_ask","market_id":"3823665","outcome_index":0,"market_type":"match","local_side":"home","local_uid":"2026-08-24_jazmin_ortenzi_himeno_sakatsume","bid":0.13,"ask":0.14,"mid":0.135,"spread":0.01,"bid_size":null,"ask_size":null}
{"ts":"2026-08-24T20:48:31.109Z","event_type":"best_bid_ask","market_id":"3823665","outcome_index":1,"market_type":"match","local_side":"away","local_uid":"2026-08-24_jazmin_ortenzi_himeno_sakatsume","bid":0.86,"ask":0.87,"mid":0.865,"spread":0.01,"bid_size":null,"ask_size":null}
{"ts":"2026-08-24T20:48:31.110Z","event_type":"price_change","market_id":"3823665","outcome_index":1,"market_type":"match","local_side":"away","local_uid":"2026-08-24_jazmin_ortenzi_himeno_sakatsume","bid":0.86,"ask":0.87,"mid":0.865,"spread":0.01,"price":0.86,"size":1731.23,"side":"BUY"}
{"ts":"2026-08-24T20:48:31.110Z","event_type":"price_change","market_id":"3823665","outcome_index":0,"market_type":"match","local_side":"home","local_uid":"2026-08-24_jazmin_ortenzi_himeno_sakatsume","bid":0.13,"ask":0.14,"mid":0.135,"spread":0.01,"price":0.14,"size":1731.23,"side":"SELL"}
{"ts":"2026-08-24T20:48:31.111Z","event_type":"book","market_id":"3823665","outcome_index":0,"market_type":"match","local_side":"home","local_uid":"2026-08-24_jazmin_ortenzi_himeno_sakatsume","bid":0.13,"ask":0.14,"mid":0.135,"spread":0.01,"bid_size":20597.0,"ask_size":1731.23}
{"ts":"2026-08-24T20:48:31.111Z","event_type":"book","market_id":"3823665","outcome_index":1,"market_type":"match","local_side":"away","local_uid":"2026-08-24_jazmin_ortenzi_himeno_sakatsume","bid":0.86,"ask":0.87,"mid":0.865,"spread":0.01,"bid_size":1731.23,"ask_size":20597.0}
{"ts":"2026-08-24T20:48:31.132Z","event_type":"last_trade_price","market_id":"3823665","outcome_index":1,"market_type":"match","local_side":"away","local_uid":"2026-08-24_jazmin_ortenzi_himeno_sakatsume","last_trade":0.85,"trade_size":98.82,"trade_side":"BUY","trade_notional":83.997}
{"ts":"2026-08-24T20:48:31.141Z","event_type":"last_trade_price","market_id":"3823665","outcome_index":1,"market_type":"match","local_side":"away","local_uid":"2026-08-24_jazmin_ortenzi_himeno_sakatsume","last_trade":0.86,"trade_size":699.0,"trade_side":"BUY","trade_notional":601.14}
{"ts":"2026-08-24T20:48:31.329Z","event_type":"best_bid_ask","market_id":"3826738","outcome_index":0,"market_type":"set2","local_side":"home","local_uid":"2026-08-24_harry_wendelken_stefano_travaglia","bid":0.51,"ask":0.59,"mid":0.55,"spread":0.08,"bid_size":null,"ask_size":null}
{"ts":"2026-08-24T20:48:31.329Z","event_type":"best_bid_ask","market_id":"3826738","outcome_index":1,"market_type":"set2","local_side":"away","local_uid":"2026-08-24_harry_wendelken_stefano_travaglia","bid":0.41,"ask":0.49,"mid":0.45,"spread":0.08,"bid_size":null,"ask_size":null}
{"ts":"2026-08-24T20:48:31.329Z","event_type":"price_change","market_id":"3826738","outcome_index":1,"market_type":"set2","local_side":"away","local_uid":"2026-08-24_harry_wendelken_stefano_travaglia","bid":0.41,"ask":0.49,"mid":0.45,"spread":0.08,"price":0.41,"size":1095.0,"side":"BUY"}
{"ts":"2026-08-24T20:48:31.329Z","event_type":"price_change","market_id":"3826738","outcome_index":0,"market_type":"set2","local_side":"home","local_uid":"2026-08-24_harry_wendelken_stefano_travaglia","bid":0.51,"ask":0.59,"mid":0.55,"spread":0.08,"price":0.59,"size":1095.0,"side":"SELL"}
{"ts":"2026-08-24T20:48:31.343Z","event_type":"best_bid_ask","market_id":"3825077","outcome_index":0,"market_type":"set1","local_side":"home","local_uid":"2026-08-24_polina_kudermetova_linda_fruhvirtova","bid":0.45,"ask":0.53,"mid":0.49,"spread":0.08,"bid_size":null,"ask_size":null}
{"ts":"2026-08-24T20:48:31.344Z","event_type":"best_bid_ask","market_id":"3825077","outcome_index":1,"market_type":"set1","local_side":"away","local_uid":"2026-08-24_polina_kudermetova_linda_fruhvirtova","bid":0.47,"ask":0.55,"mid":0.51,"spread":0.08,"bid_size":null,"ask_size":null}
{"ts":"2026-08-24T20:48:31.344Z","event_type":"price_change","market_id":"3825077","outcome_index":0,"market_type":"set1","local_side":"home","local_uid":"2026-08-24_polina_kudermetova_linda_fruhvirtova","bid":0.45,"ask":0.53,"mid":0.49,"spread":0.08,"price":0.43,"size":0.0,"side":"BUY"}
{"ts":"2026-08-24T20:48:31.344Z","event_type":"price_change","market_id":"3825077","outcome_index":1,"market_type":"set1","local_side":"away","local_uid":"2026-08-24_polina_kudermetova_linda_fruhvirtova","bid":0.47,"ask":0.55,"mid":0.51,"spread":0.08,"price":0.57,"size":0.0,"side":"SELL"}
{"ts":"2026-08-24T20:48:31.349Z","event_type":"best_bid_ask","market_id":"3823619","outcome_index":0,"market_type":"match","local_side":"home","local_uid":"2026-08-24_polina_kudermetova_linda_fruhvirtova","bid":0.57,"ask":0.58,"mid":0.575,"spread":0.01,"bid_size":null,"ask_size":null}
{"ts":"2026-08-24T20:48:31.349Z","event_type":"best_bid_ask","market_id":"3823619","outcome_index":1,"market_type":"match","local_side":"away","local_uid":"2026-08-24_polina_kudermetova_linda_fruhvirtova","bid":0.42,"ask":0.43,"mid":0.425,"spread":0.01,"bid_size":null,"ask_size":null}
{"ts":"2026-08-24T20:48:31.349Z","event_type":"price_change","market_id":"3823619","outcome_index":0,"market_type":"match","local_side":"home","local_uid":"2026-08-24_polina_kudermetova_linda_fruhvirtova","bid":0.57,"ask":0.58,"mid":0.575,"spread":0.01,"price":0.57,"size":50.0,"side":"BUY"}
{"ts":"2026-08-24T20:48:31.349Z","event_type":"price_change","market_id":"3823619","outcome_index":1,"market_type":"match","local_side":"away","local_uid":"2026-08-24_polina_kudermetova_linda_fruhvirtova","bid":0.42,"ask":0.43,"mid":0.425,"spread":0.01,"price":0.43,"size":50.0,"side":"SELL"}
{"ts":"2026-08-24T20:48:31.359Z","event_type":"best_bid_ask","market_id":"3825077","outcome_index":0,"market_type":"set1","local_side":"home","local_uid":"2026-08-24_polina_kudermetova_linda_fruhvirtova","bid":0.45,"ask":0.54,"mid":0.495,"spread":0.09,"bid_size":null,"ask_size":null}
{"ts":"2026-08-24T20:48:31.359Z","event_type":"best_bid_ask","market_id":"3825077","outcome_index":1,"market_type":"set1","local_side":"away","local_uid":"2026-08-24_polina_kudermetova_linda_fruhvirtova","bid":0.46,"ask":0.55,"mid":0.505,"spread":0.09,"bid_size":null,"ask_size":null}
{"ts":"2026-08-24T20:48:31.359Z","event_type":"price_change","market_id":"3825077","outcome_index":1,"market_type":"set1","local_side":"away","local_uid":"2026-08-24_polina_kudermetova_linda_fruhvirtova","bid":0.46,"ask":0.55,"mid":0.505,"spread":0.09,"price":0.47,"size":0.0,"side":"BUY"}
{"ts":"2026-08-24T20:48:31.359Z","event_type":"price_change","market_id":"3825077","outcome_index":0,"market_type":"set1","local_side":"home","local_uid":"2026-08-24_polina_kudermetova_linda_fruhvirtova","bid":0.45,"ask":0.54,"mid":0.495,"spread":0.09,"price":0.53,"size":0.0,"side":"SELL"}
{"ts":"2026-08-24T20:48:31.370Z","event_type":"best_bid_ask","market_id":"3826919","outcome_index":0,"market_type":"set2","local_side":"home","local_uid":"2026-08-24_dalibor_svrcina_felipe_meligeni_alves","bid":0.43,"ask":0.51,"mid":0.47,"spread":0.08,"bid_size":null,"ask_size":null}
{"ts":"2026-08-24T20:48:31.371Z","event_type":"best_bid_ask","market_id":"3826919","outcome_index":1,"market_type":"set2","local_side":"away","local_uid":"2026-08-24_dalibor_svrcina_felipe_meligeni_alves","bid":0.49,"ask":0.57,"mid":0.53,"spread":0.08,"bid_size":null,"ask_size":null}
{"ts":"2026-08-24T20:48:31.371Z","event_type":"price_change","market_id":"3826919","outcome_index":1,"market_type":"set2","local_side":"away","local_uid":"2026-08-24_dalibor_svrcina_felipe_meligeni_alves","bid":0.49,"ask":0.57,"mid":0.53,"spread":0.08,"price":0.49,"size":24.6,"side":"BUY"}
{"ts":"2026-08-24T20:48:31.371Z","event_type":"price_change","market_id":"3826919","outcome_index":0,"market_type":"set2","local_side":"home","local_uid":"2026-08-24_dalibor_svrcina_felipe_meligeni_alves","bid":0.43,"ask":0.51,"mid":0.47,"spread":0.08,"price":0.51,"size":24.6,"side":"SELL"}
{"ts":"2026-08-24T20:48:31.390Z","event_type":"best_bid_ask","market_id":"3825077","outcome_index":0,"market_type":"set1","local_side":"home","local_uid":"2026-08-24_polina_kudermetova_linda_fruhvirtova","bid":0.45,"ask":0.55,"mid":0.5,"spread":0.1,"bid_size":null,"ask_size":null}
{"ts":"2026-08-24T20:48:31.390Z","event_type":"best_bid_ask","market_id":"3825077","outcome_index":1,"market_type":"set1","local_side":"away","local_uid":"2026-08-24_polina_kudermetova_linda_fruhvirtova","bid":0.45,"ask":0.55,"mid":0.5,"spread":0.1,"bid_size":null,"ask_size":null}
{"ts":"2026-08-24T20:48:31.390Z","event_type":"price_change","market_id":"3825077","outcome_index":1,"market_type":"set1","local_side":"away","local_uid":"2026-08-24_polina_kudermetova_linda_fruhvirtova","bid":0.45,"ask":0.55,"mid":0.5,"spread":0.1,"price":0.46,"size":0.0,"side":"BUY"}
{"ts":"2026-08-24T20:48:31.391Z","event_type":"price_change","market_id":"3825077","outcome_index":0,"market_type":"set1","local_side":"home","local_uid":"2026-08-24_polina_kudermetova_linda_fruhvirtova","bid":0.45,"ask":0.55,"mid":0.5,"spread":0.1,"price":0.54,"size":0.0,"side":"SELL"}
{"ts":"2026-08-24T20:48:31.395Z","event_type":"best_bid_ask","market_id":"3826919","outcome_index":0,"market_type":"set2","local_side":"home","local_uid":"2026-08-24_dalibor_svrcina_felipe_meligeni_alves","bid":0.43,"ask":0.52,"mid":0.475,"spread":0.09,"bid_size":null,"ask_size":null}
{"ts":"2026-08-24T20:48:31.395Z","event_type":"best_bid_ask","market_id":"3826919","outcome_index":1,"market_type":"set2","local_side":"away","local_uid":"2026-08-24_dalibor_svrcina_felipe_meligeni_alves","bid":0.48,"ask":0.57,"mid":0.525,"spread":0.09,"bid_size":null,"ask_size":null}
{"ts":"2026-08-24T20:48:31.395Z","event_type":"price_change","market_id":"3826919","outcome_index":1,"market_type":"set2","local_side":"away","local_uid":"2026-08-24_dalibor_svrcina_felipe_meligeni_alves","bid":0.48,"ask":0.57,"mid":0.525,"spread":0.09,"price":0.49,"size":0.0,"side":"BUY"}
{"ts":"2026-08-24T20:48:31.395Z","event_type":"price_change","market_id":"3826919","outcome_index":0,"market_type":"set2","local_side":"home","local_uid":"2026-08-24_dalibor_svrcina_felipe_meligeni_alves","bid":0.43,"ask":0.52,"mid":0.475,"spread":0.09,"price":0.51,"size":0.0,"side":"SELL"}
{"ts":"2026-08-24T20:48:31.461Z","event_type":"best_bid_ask","market_id":"3826919","outcome_index":0,"market_type":"set2","local_side":"home","local_uid":"2026-08-24_dalibor_svrcina_felipe_meligeni_alves","bid":0.43,"ask":0.51,"mid":0.47,"spread":0.08,"bid_size":null,"ask_size":null}
{"ts":"2026-08-24T20:48:31.461Z","event_type":"best_bid_ask","market_id":"3826919","outcome_index":1,"market_type":"set2","local_side":"away","local_uid":"2026-08-24_dalibor_svrcina_felipe_meligeni_alves","bid":0.49,"ask":0.57,"mid":0.53,"spread":0.08,"bid_size":null,"ask_size":null}
{"ts":"2026-08-24T20:48:31.461Z","event_type":"price_change","market_id":"3826919","outcome_index":1,"market_type":"set2","local_side":"away","local_uid":"2026-08-24_dalibor_svrcina_felipe_meligeni_alves","bid":0.49,"ask":0.57,"mid":0.53,"spread":0.08,"price":0.49,"size":24.6,"side":"BUY"}
{"ts":"2026-08-24T20:48:31.461Z","event_type":"price_change","market_id":"3826919","outcome_index":0,"market_type":"set2","local_side":"home","local_uid":"2026-08-24_dalibor_svrcina_felipe_meligeni_alves","bid":0.43,"ask":0.51,"mid":0.47,"spread":0.08,"price":0.51,"size":24.6,"side":"SELL"}
{"ts":"2026-08-24T20:48:31.480Z","event_type":"best_bid_ask","market_id":"3825077","outcome_index":0,"market_type":"set1","local_side":"home","local_uid":"2026-08-24_polina_kudermetova_linda_fruhvirtova","bid":0.45,"ask":0.53,"mid":0.49,"spread":0.08,"bid_size":null,"ask_size":null}
{"ts":"2026-08-24T20:48:31.481Z","event_type":"best_bid_ask","market_id":"3825077","outcome_index":1,"market_type":"set1","local_side":"away","local_uid":"2026-08-24_polina_kudermetova_linda_fruhvirtova","bid":0.47,"ask":0.55,"mid":0.51,"spread":0.08,"bid_size":null,"ask_size":null}
{"ts":"2026-08-24T20:48:31.481Z","event_type":"price_change","market_id":"3825077","outcome_index":1,"market_type":"set1","local_side":"away","local_uid":"2026-08-24_polina_kudermetova_linda_fruhvirtova","bid":0.47,"ask":0.55,"mid":0.51,"spread":0.08,"price":0.47,"size":15.0,"side":"BUY"}
{"ts":"2026-08-24T20:48:31.481Z","event_type":"price_change","market_id":"3825077","outcome_index":0,"market_type":"set1","local_side":"home","local_uid":"2026-08-24_polina_kudermetova_linda_fruhvirtova","bid":0.45,"ask":0.53,"mid":0.49,"spread":0.08,"price":0.53,"size":15.0,"side":"SELL"}
{"ts":"2026-08-24T20:48:31.506Z","event_type":"best_bid_ask","market_id":"3826919","outcome_index":0,"market_type":"set2","local_side":"home","local_uid":"2026-08-24_dalibor_svrcina_felipe_meligeni_alves","bid":0.43,"ask":0.52,"mid":0.475,"spread":0.09,"bid_size":null,"ask_size":null}
{"ts":"2026-08-24T20:48:31.506Z","event_type":"best_bid_ask","market_id":"3826919","outcome_index":1,"market_type":"set2","local_side":"away","local_uid":"2026-08-24_dalibor_svrcina_felipe_meligeni_alves","bid":0.48,"ask":0.57,"mid":0.525,"spread":0.09,"bid_size":null,"ask_size":null}
{"ts":"2026-08-24T20:48:31.506Z","event_type":"price_change","market_id":"3826919","outcome_index":1,"market_type":"set2","local_side":"away","local_uid":"2026-08-24_dalibor_svrcina_felipe_meligeni_alves","bid":0.48,"ask":0.57,"mid":0.525,"spread":0.09,"price":0.49,"size":0.0,"side":"BUY"}
{"ts":"2026-08-24T20:48:31.507Z","event_type":"price_change","market_id":"3826919","outcome_index":0,"market_type":"set2","local_side":"home","local_uid":"2026-08-24_dalibor_svrcina_felipe_meligeni_alves","bid":0.43,"ask":0.52,"mid":0.475,"spread":0.09,"price":0.51,"size":0.0,"side":"SELL"}
{"ts":"2026-08-24T20:48:31.530Z","event_type":"best_bid_ask","market_id":"3826919","outcome_index":0,"market_type":"set2","local_side":"home","local_uid":"2026-08-24_dalibor_svrcina_felipe_meligeni_alves","bid":0.43,"ask":0.51,"mid":0.47,"spread":0.08,"bid_size":null,"ask_size":null}
{"ts":"2026-08-24T20:48:31.531Z","event_type":"best_bid_ask","market_id":"3826919","outcome_index":1,"market_type":"set2","local_side":"away","local_uid":"2026-08-24_dalibor_svrcina_felipe_meligeni_alves","bid":0.49,"ask":0.57,"mid":0.53,"spread":0.08,"bid_size":null,"ask_size":null}
{"ts":"2026-08-24T20:48:31.531Z","event_type":"price_change","market_id":"3826919","outcome_index":1,"market_type":"set2","local_side":"away","local_uid":"2026-08-24_dalibor_svrcina_felipe_meligeni_alves","bid":0.49,"ask":0.57,"mid":0.53,"spread":0.08,"price":0.49,"size":24.6,"side":"BUY"}
{"ts":"2026-08-24T20:48:31.531Z","event_type":"price_change","market_id":"3826919","outcome_index":0,"market_type":"set2","local_side":"home","local_uid":"2026-08-24_dalibor_svrcina_felipe_meligeni_alves","bid":0.43,"ask":0.51,"mid":0.47,"spread":0.08,"price":0.51,"size":24.6,"side":"SELL"}
{"ts":"2026-08-24T20:48:31.568Z","event_type":"best_bid_ask","market_id":"3826919","outcome_index":0,"market_type":"set2","local_side":"home","local_uid":"2026-08-24_dalibor_svrcina_felipe_meligeni_alves","bid":0.43,"ask":0.52,"mid":0.475,"spread":0.09,"bid_size":null,"ask_size":null}
{"ts":"2026-08-24T20:48:31.568Z","event_type":"best_bid_ask","market_id":"3826919","outcome_index":1,"market_type":"set2","local_side":"away","local_uid":"2026-08-24_dalibor_svrcina_felipe_meligeni_alves","bid":0.48,"ask":0.57,"mid":0.525,"spread":0.09,"bid_size":null,"ask_size":null}
{"ts":"2026-08-24T20:48:31.569Z","event_type":"price_change","market_id":"3826919","outcome_index":1,"market_type":"set2","local_side":"away","local_uid":"2026-08-24_dalibor_svrcina_felipe_meligeni_alves","bid":0.48,"ask":0.57,"mid":0.525,"spread":0.09,"price":0.49,"size":0.0,"side":"BUY"}
{"ts":"2026-08-24T20:48:31.569Z","event_type":"price_change","market_id":"3826919","outcome_index":0,"market_type":"set2","local_side":"home","local_uid":"2026-08-24_dalibor_svrcina_felipe_meligeni_alves","bid":0.43,"ask":0.52,"mid":0.475,"spread":0.09,"price":0.51,"size":0.0,"side":"SELL"}
{"ts":"2026-08-24T20:48:31.721Z","event_type":"price_change","market_id":"3826905","outcome_index":1,"market_type":"set1","local_side":"away","local_uid":"2026-08-24_keegan_smith_alexis_galarneau","bid":0.45,"ask":0.57,"mid":0.51,"spread":0.12,"price":0.45,"size":250.0,"side":"BUY"}
{"ts":"2026-08-24T20:48:31.721Z","event_type":"price_change","market_id":"3826905","outcome_index":0,"market_type":"set1","local_side":"home","local_uid":"2026-08-24_keegan_smith_alexis_galarneau","bid":0.43,"ask":0.55,"mid":0.49,"spread":0.12,"price":0.55,"size":250.0,"side":"SELL"}
{"ts":"2026-08-24T20:48:31.751Z","event_type":"best_bid_ask","market_id":"3826919","outcome_index":0,"market_type":"set2","local_side":"home","local_uid":"2026-08-24_dalibor_svrcina_felipe_meligeni_alves","bid":0.43,"ask":0.51,"mid":0.47,"spread":0.08,"bid_size":null,"ask_size":null}
{"ts":"2026-08-24T20:48:31.751Z","event_type":"best_bid_ask","market_id":"3826919","outcome_index":1,"market_type":"set2","local_side":"away","local_uid":"2026-08-24_dalibor_svrcina_felipe_meligeni_alves","bid":0.49,"ask":0.57,"mid":0.53,"spread":0.08,"bid_size":null,"ask_size":null}
{"ts":"2026-08-24T20:48:31.752Z","event_type":"price_change","market_id":"3826919","outcome_index":1,"market_type":"set2","local_side":"away","local_uid":"2026-08-24_dalibor_svrcina_felipe_meligeni_alves","bid":0.49,"ask":0.57,"mid":0.53,"spread":0.08,"price":0.49,"size":24.6,"side":"BUY"}
{"ts":"2026-08-24T20:48:31.752Z","event_type":"price_change","market_id":"3826919","outcome_index":0,"market_type":"set2","local_side":"home","local_uid":"2026-08-24_dalibor_svrcina_felipe_meligeni_alves","bid":0.43,"ask":0.51,"mid":0.47,"spread":0.08,"price":0.51,"size":24.6,"side":"SELL"}
{"ts":"2026-08-24T20:48:31.796Z","event_type":"best_bid_ask","market_id":"3826919","outcome_index":0,"market_type":"set2","local_side":"home","local_uid":"2026-08-24_dalibor_svrcina_felipe_meligeni_alves","bid":0.43,"ask":0.52,"mid":0.475,"spread":0.09,"bid_size":null,"ask_size":null}
{"ts":"2026-08-24T20:48:31.797Z","event_type":"best_bid_ask","market_id":"3826919","outcome_index":1,"market_type":"set2","local_side":"away","local_uid":"2026-08-24_dalibor_svrcina_felipe_meligeni_alves","bid":0.48,"ask":0.57,"mid":0.525,"spread":0.09,"bid_size":null,"ask_size":null}
{"ts":"2026-08-24T20:48:31.797Z","event_type":"price_change","market_id":"3826919","outcome_index":1,"market_type":"set2","local_side":"away","local_uid":"2026-08-24_dalibor_svrcina_felipe_meligeni_alves","bid":0.48,"ask":0.57,"mid":0.525,"spread":0.09,"price":0.49,"size":0.0,"side":"BUY"}
{"ts":"2026-08-24T20:48:31.797Z","event_type":"price_change","market_id":"3826919","outcome_index":0,"market_type":"set2","local_side":"home","local_uid":"2026-08-24_dalibor_svrcina_felipe_meligeni_alves","bid":0.43,"ask":0.52,"mid":0.475,"spread":0.09,"price":0.51,"size":0.0,"side":"SELL"}
{"ts":"2026-08-24T20:48:31.882Z","event_type":"best_bid_ask","market_id":"3825608","outcome_index":0,"market_type":"match","local_side":"home","local_uid":"2026-08-24_raul_brancaccio_thiago_seyboth_wild","bid":0.22,"ask":0.25,"mid":0.235,"spread":0.03,"bid_size":null,"ask_size":null}
{"ts":"2026-08-24T20:48:31.883Z","event_type":"best_bid_ask","market_id":"3825608","outcome_index":1,"market_type":"match","local_side":"away","local_uid":"2026-08-24_raul_brancaccio_thiago_seyboth_wild","bid":0.75,"ask":0.78,"mid":0.765,"spread":0.03,"bid_size":null,"ask_size":null}
{"ts":"2026-08-24T20:48:31.883Z","event_type":"price_change","market_id":"3825608","outcome_index":0,"market_type":"match","local_side":"home","local_uid":"2026-08-24_raul_brancaccio_thiago_seyboth_wild","bid":0.22,"ask":0.25,"mid":0.235,"spread":0.03,"price":0.23,"size":0.0,"side":"BUY"}
{"ts":"2026-08-24T20:48:31.884Z","event_type":"price_change","market_id":"3825608","outcome_index":1,"market_type":"match","local_side":"away","local_uid":"2026-08-24_raul_brancaccio_thiago_seyboth_wild","bid":0.75,"ask":0.78,"mid":0.765,"spread":0.03,"price":0.77,"size":0.0,"side":"SELL"}
{"ts":"2026-08-24T20:48:31.887Z","event_type":"best_bid_ask","market_id":"3826919","outcome_index":0,"market_type":"set2","local_side":"home","local_uid":"2026-08-24_dalibor_svrcina_felipe_meligeni_alves","bid":0.43,"ask":0.51,"mid":0.47,"spread":0.08,"bid_size":null,"ask_size":null}
{"ts":"2026-08-24T20:48:31.887Z","event_type":"best_bid_ask","market_id":"3826919","outcome_index":1,"market_type":"set2","local_side":"away","local_uid":"2026-08-24_dalibor_svrcina_felipe_meligeni_alves","bid":0.49,"ask":0.57,"mid":0.53,"spread":0.08,"bid_size":null,"ask_size":null}
{"ts":"2026-08-24T20:48:31.888Z","event_type":"price_change","market_id":"3826919","outcome_index":1,"market_type":"set2","local_side":"away","local_uid":"2026-08-24_dalibor_svrcina_felipe_meligeni_alves","bid":0.49,"ask":0.57,"mid":0.53,"spread":0.08,"price":0.49,"size":24.6,"side":"BUY"}
{"ts":"2026-08-24T20:48:31.888Z","event_type":"price_change","market_id":"3826919","outcome_index":0,"market_type":"set2","local_side":"home","local_uid":"2026-08-24_dalibor_svrcina_felipe_meligeni_alves","bid":0.43,"ask":0.51,"mid":0.47,"spread":0.08,"price":0.51,"size":24.6,"side":"SELL"}
{"ts":"2026-08-24T20:48:31.905Z","event_type":"market_resolved","market_id":"0xc0661be16bd9952ea32bfc43650d3f7882f0b91ae09c03fbaf3955725eecba29"}
{"ts":"2026-08-24T20:48:31.923Z","event_type":"best_bid_ask","market_id":"3825608","outcome_index":0,"market_type":"match","local_side":"home","local_uid":"2026-08-24_raul_brancaccio_thiago_seyboth_wild","bid":0.22,"ask":0.23,"mid":0.225,"spread":0.01,"bid_size":null,"ask_size":null}
{"ts":"2026-08-24T20:48:31.923Z","event_type":"best_bid_ask","market_id":"3825608","outcome_index":1,"market_type":"match","local_side":"away","local_uid":"2026-08-24_raul_brancaccio_thiago_seyboth_wild","bid":0.77,"ask":0.78,"mid":0.775,"spread":0.01,"bid_size":null,"ask_size":null}
{"ts":"2026-08-24T20:48:31.924Z","event_type":"price_change","market_id":"3825608","outcome_index":1,"market_type":"match","local_side":"away","local_uid":"2026-08-24_raul_brancaccio_thiago_seyboth_wild","bid":0.77,"ask":0.78,"mid":0.775,"spread":0.01,"price":0.77,"size":30.0,"side":"BUY"}
{"ts":"2026-08-24T20:48:31.924Z","event_type":"price_change","market_id":"3825608","outcome_index":0,"market_type":"match","local_side":"home","local_uid":"2026-08-24_raul_brancaccio_thiago_seyboth_wild","bid":0.22,"ask":0.23,"mid":0.225,"spread":0.01,"price":0.23,"size":30.0,"side":"SELL"}
{"ts":"2026-08-24T20:48:31.928Z","event_type":"best_bid_ask","market_id":"3826919","outcome_index":0,"market_type":"set2","local_side":"home","local_uid":"2026-08-24_dalibor_svrcina_felipe_meligeni_alves","bid":0.43,"ask":0.52,"mid":0.475,"spread":0.09,"bid_size":null,"ask_size":null}
{"ts":"2026-08-24T20:48:31.928Z","event_type":"best_bid_ask","market_id":"3826919","outcome_index":1,"market_type":"set2","local_side":"away","local_uid":"2026-08-24_dalibor_svrcina_felipe_meligeni_alves","bid":0.48,"ask":0.57,"mid":0.525,"spread":0.09,"bid_size":null,"ask_size":null}
{"ts":"2026-08-24T20:48:31.928Z","event_type":"price_change","market_id":"3826919","outcome_index":1,"market_type":"set2","local_side":"away","local_uid":"2026-08-24_dalibor_svrcina_felipe_meligeni_alves","bid":0.48,"ask":0.57,"mid":0.525,"spread":0.09,"price":0.49,"size":0.0,"side":"BUY"}
{"ts":"2026-08-24T20:48:31.929Z","event_type":"price_change","market_id":"3826919","outcome_index":0,"market_type":"set2","local_side":"home","local_uid":"2026-08-24_dalibor_svrcina_felipe_meligeni_alves","bid":0.43,"ask":0.52,"mid":0.475,"spread":0.09,"price":0.51,"size":0.0,"side":"SELL"}
{"ts":"2026-08-24T20:48:31.971Z","event_type":"best_bid_ask","market_id":"3825608","outcome_index":0,"market_type":"match","local_side":"home","local_uid":"2026-08-24_raul_brancaccio_thiago_seyboth_wild","bid":0.22,"ask":0.25,"mid":0.235,"spread":0.03,"bid_size":null,"ask_size":null}
{"ts":"2026-08-24T20:48:31.971Z","event_type":"best_bid_ask","market_id":"3825608","outcome_index":1,"market_type":"match","local_side":"away","local_uid":"2026-08-24_raul_brancaccio_thiago_seyboth_wild","bid":0.75,"ask":0.78,"mid":0.765,"spread":0.03,"bid_size":null,"ask_size":null}
{"ts":"2026-08-24T20:48:31.976Z","event_type":"price_change","market_id":"3825608","outcome_index":1,"market_type":"match","local_side":"away","local_uid":"2026-08-24_raul_brancaccio_thiago_seyboth_wild","bid":0.75,"ask":0.78,"mid":0.765,"spread":0.03,"price":0.77,"size":0.0,"side":"BUY"}
{"ts":"2026-08-24T20:48:31.977Z","event_type":"price_change","market_id":"3825608","outcome_index":0,"market_type":"match","local_side":"home","local_uid":"2026-08-24_raul_brancaccio_thiago_seyboth_wild","bid":0.22,"ask":0.25,"mid":0.235,"spread":0.03,"price":0.23,"size":0.0,"side":"SELL"}
{"ts":"2026-08-24T20:48:31.982Z","event_type":"best_bid_ask","market_id":"3823619","outcome_index":0,"market_type":"match","local_side":"home","local_uid":"2026-08-24_polina_kudermetova_linda_fruhvirtova","bid":0.57,"ask":0.59,"mid":0.58,"spread":0.02,"bid_size":null,"ask_size":null}
{"ts":"2026-08-24T20:48:31.983Z","event_type":"best_bid_ask","market_id":"3823619","outcome_index":1,"market_type":"match","local_side":"away","local_uid":"2026-08-24_polina_kudermetova_linda_fruhvirtova","bid":0.41,"ask":0.43,"mid":0.42,"spread":0.02,"bid_size":null,"ask_size":null}
{"ts":"2026-08-24T20:48:31.987Z","event_type":"price_change","market_id":"3823619","outcome_index":0,"market_type":"match","local_side":"home","local_uid":"2026-08-24_polina_kudermetova_linda_fruhvirtova","bid":0.57,"ask":0.59,"mid":0.58,"spread":0.02,"price":0.46,"size":2053.03,"side":"BUY"}
{"ts":"2026-08-24T20:48:31.987Z","event_type":"price_change","market_id":"3823619","outcome_index":1,"market_type":"match","local_side":"away","local_uid":"2026-08-24_polina_kudermetova_linda_fruhvirtova","bid":0.41,"ask":0.43,"mid":0.42,"spread":0.02,"price":0.54,"size":2053.03,"side":"SELL"}
{"ts":"2026-08-24T20:48:31.992Z","event_type":"best_bid_ask","market_id":"3825608","outcome_index":0,"market_type":"match","local_side":"home","local_uid":"2026-08-24_raul_brancaccio_thiago_seyboth_wild","bid":0.22,"ask":0.24,"mid":0.23,"spread":0.02,"bid_size":null,"ask_size":null}
{"ts":"2026-08-24T20:48:31.992Z","event_type":"best_bid_ask","market_id":"3825608","outcome_index":1,"market_type":"match","local_side":"away","local_uid":"2026-08-24_raul_brancaccio_thiago_seyboth_wild","bid":0.76,"ask":0.78,"mid":0.77,"spread":0.02,"bid_size":null,"ask_size":null}
{"ts":"2026-08-24T20:48:31.993Z","event_type":"price_change","market_id":"3825608","outcome_index":1,"market_type":"match","local_side":"away","local_uid":"2026-08-24_raul_brancaccio_thiago_seyboth_wild","bid":0.76,"ask":0.78,"mid":0.77,"spread":0.02,"price":0.76,"size":255.0,"side":"BUY"}
{"ts":"2026-08-24T20:48:31.993Z","event_type":"price_change","market_id":"3825608","outcome_index":0,"market_type":"match","local_side":"home","local_uid":"2026-08-24_raul_brancaccio_thiago_seyboth_wild","bid":0.22,"ask":0.24,"mid":0.23,"spread":0.02,"price":0.24,"size":255.0,"side":"SELL"}
{"ts":"2026-08-24T20:48:31.994Z","event_type":"best_bid_ask","market_id":"3825608","outcome_index":0,"market_type":"match","local_side":"home","local_uid":"2026-08-24_raul_brancaccio_thiago_seyboth_wild","bid":0.22,"ask":0.23,"mid":0.225,"spread":0.01,"bid_size":null,"ask_size":null}
{"ts":"2026-08-24T20:48:31.994Z","event_type":"best_bid_ask","market_id":"3825608","outcome_index":1,"market_type":"match","local_side":"away","local_uid":"2026-08-24_raul_brancaccio_thiago_seyboth_wild","bid":0.77,"ask":0.78,"mid":0.775,"spread":0.01,"bid_size":null,"ask_size":null}
{"ts":"2026-08-24T20:48:31.995Z","event_type":"price_change","market_id":"3825608","outcome_index":1,"market_type":"match","local_side":"away","local_uid":"2026-08-24_raul_brancaccio_thiago_seyboth_wild","bid":0.77,"ask":0.78,"mid":0.775,"spread":0.01,"price":0.77,"size":255.0,"side":"BUY"}
{"ts":"2026-08-24T20:48:31.995Z","event_type":"price_change","market_id":"3825608","outcome_index":0,"market_type":"match","local_side":"home","local_uid":"2026-08-24_raul_brancaccio_thiago_seyboth_wild","bid":0.22,"ask":0.23,"mid":0.225,"spread":0.01,"price":0.23,"size":255.0,"side":"SELL"}
{"ts":"2026-08-24T20:48:32.029Z","event_type":"best_bid_ask","market_id":"3825608","outcome_index":0,"market_type":"match","local_side":"home","local_uid":"2026-08-24_raul_brancaccio_thiago_seyboth_wild","bid":0.22,"ask":0.25,"mid":0.235,"spread":0.03,"bid_size":null,"ask_size":null}
{"ts":"2026-08-24T20:48:32.030Z","event_type":"best_bid_ask","market_id":"3825608","outcome_index":1,"market_type":"match","local_side":"away","local_uid":"2026-08-24_raul_brancaccio_thiago_seyboth_wild","bid":0.75,"ask":0.78,"mid":0.765,"spread":0.03,"bid_size":null,"ask_size":null}
{"ts":"2026-08-24T20:48:32.030Z","event_type":"price_change","market_id":"3825608","outcome_index":1,"market_type":"match","local_side":"away","local_uid":"2026-08-24_raul_brancaccio_thiago_seyboth_wild","bid":0.75,"ask":0.78,"mid":0.765,"spread":0.03,"price":0.77,"size":0.0,"side":"BUY"}
{"ts":"2026-08-24T20:48:32.030Z","event_type":"price_change","market_id":"3825608","outcome_index":0,"market_type":"match","local_side":"home","local_uid":"2026-08-24_raul_brancaccio_thiago_seyboth_wild","bid":0.22,"ask":0.25,"mid":0.235,"spread":0.03,"price":0.23,"size":0.0,"side":"SELL"}
{"ts":"2026-08-24T20:48:32.099Z","event_type":"last_trade_price","market_id":"3823665","outcome_index":0,"market_type":"match","local_side":"home","local_uid":"2026-08-24_jazmin_ortenzi_himeno_sakatsume","last_trade":0.14,"trade_size":24.0,"trade_side":"BUY","trade_notional":3.36}
{"ts":"2026-08-24T20:48:32.123Z","event_type":"best_bid_ask","market_id":"3825608","outcome_index":0,"market_type":"match","local_side":"home","local_uid":"2026-08-24_raul_brancaccio_thiago_seyboth_wild","bid":0.22,"ask":0.24,"mid":0.23,"spread":0.02,"bid_size":null,"ask_size":null}
{"ts":"2026-08-24T20:48:32.124Z","event_type":"best_bid_ask","market_id":"3825608","outcome_index":1,"market_type":"match","local_side":"away","local_uid":"2026-08-24_raul_brancaccio_thiago_seyboth_wild","bid":0.76,"ask":0.78,"mid":0.77,"spread":0.02,"bid_size":null,"ask_size":null}
{"ts":"2026-08-24T20:48:32.124Z","event_type":"price_change","market_id":"3825608","outcome_index":1,"market_type":"match","local_side":"away","local_uid":"2026-08-24_raul_brancaccio_thiago_seyboth_wild","bid":0.76,"ask":0.78,"mid":0.77,"spread":0.02,"price":0.76,"size":213.0,"side":"BUY"}
{"ts":"2026-08-24T20:48:32.124Z","event_type":"price_change","market_id":"3825608","outcome_index":0,"market_type":"match","local_side":"home","local_uid":"2026-08-24_raul_brancaccio_thiago_seyboth_wild","bid":0.22,"ask":0.24,"mid":0.23,"spread":0.02,"price":0.24,"size":213.0,"side":"SELL"}
{"ts":"2026-08-24T20:48:32.208Z","event_type":"best_bid_ask","market_id":"3825608","outcome_index":0,"market_type":"match","local_side":"home","local_uid":"2026-08-24_raul_brancaccio_thiago_seyboth_wild","bid":0.21,"ask":0.24,"mid":0.225,"spread":0.03,"bid_size":null,"ask_size":null}
{"ts":"2026-08-24T20:48:32.208Z","event_type":"best_bid_ask","market_id":"3825608","outcome_index":1,"market_type":"match","local_side":"away","local_uid":"2026-08-24_raul_brancaccio_thiago_seyboth_wild","bid":0.76,"ask":0.79,"mid":0.775,"spread":0.03,"bid_size":null,"ask_size":null}
{"ts":"2026-08-24T20:48:32.209Z","event_type":"price_change","market_id":"3825608","outcome_index":0,"market_type":"match","local_side":"home","local_uid":"2026-08-24_raul_brancaccio_thiago_seyboth_wild","bid":0.21,"ask":0.24,"mid":0.225,"spread":0.03,"price":0.22,"size":0.0,"side":"BUY"}
{"ts":"2026-08-24T20:48:32.209Z","event_type":"price_change","market_id":"3825608","outcome_index":1,"market_type":"match","local_side":"away","local_uid":"2026-08-24_raul_brancaccio_thiago_seyboth_wild","bid":0.76,"ask":0.79,"mid":0.775,"spread":0.03,"price":0.78,"size":0.0,"side":"SELL"}
{"ts":"2026-08-24T20:48:32.212Z","event_type":"best_bid_ask","market_id":"3826919","outcome_index":0,"market_type":"set2","local_side":"home","local_uid":"2026-08-24_dalibor_svrcina_felipe_meligeni_alves","bid":0.43,"ask":0.51,"mid":0.47,"spread":0.08,"bid_size":null,"ask_size":null}
{"ts":"2026-08-24T20:48:32.213Z","event_type":"best_bid_ask","market_id":"3826919","outcome_index":1,"market_type":"set2","local_side":"away","local_uid":"2026-08-24_dalibor_svrcina_felipe_meligeni_alves","bid":0.49,"ask":0.57,"mid":0.53,"spread":0.08,"bid_size":null,"ask_size":null}
{"ts":"2026-08-24T20:48:32.213Z","event_type":"price_change","market_id":"3826919","outcome_index":1,"market_type":"set2","local_side":"away","local_uid":"2026-08-24_dalibor_svrcina_felipe_meligeni_alves","bid":0.49,"ask":0.57,"mid":0.53,"spread":0.08,"price":0.49,"size":24.6,"side":"BUY"}
{"ts":"2026-08-24T20:48:32.213Z","event_type":"price_change","market_id":"3826919","outcome_index":0,"market_type":"set2","local_side":"home","local_uid":"2026-08-24_dalibor_svrcina_felipe_meligeni_alves","bid":0.43,"ask":0.51,"mid":0.47,"spread":0.08,"price":0.51,"size":24.6,"side":"SELL"}
{"ts":"2026-08-24T20:48:32.215Z","event_type":"best_bid_ask","market_id":"3825608","outcome_index":0,"market_type":"match","local_side":"home","local_uid":"2026-08-24_raul_brancaccio_thiago_seyboth_wild","bid":0.22,"ask":0.24,"mid":0.23,"spread":0.02,"bid_size":null,"ask_size":null}
{"ts":"2026-08-24T20:48:32.215Z","event_type":"best_bid_ask","market_id":"3825608","outcome_index":1,"market_type":"match","local_side":"away","local_uid":"2026-08-24_raul_brancaccio_thiago_seyboth_wild","bid":0.76,"ask":0.78,"mid":0.77,"spread":0.02,"bid_size":null,"ask_size":null}
{"ts":"2026-08-24T20:48:32.215Z","event_type":"price_change","market_id":"3825608","outcome_index":0,"market_type":"match","local_side":"home","local_uid":"2026-08-24_raul_brancaccio_thiago_seyboth_wild","bid":0.22,"ask":0.24,"mid":0.23,"spread":0.02,"price":0.22,"size":425.0,"side":"BUY"}
{"ts":"2026-08-24T20:48:32.215Z","event_type":"price_change","market_id":"3825608","outcome_index":1,"market_type":"match","local_side":"away","local_uid":"2026-08-24_raul_brancaccio_thiago_seyboth_wild","bid":0.76,"ask":0.78,"mid":0.77,"spread":0.02,"price":0.78,"size":425.0,"side":"SELL"}
{"ts":"2026-08-24T20:48:32.249Z","event_type":"best_bid_ask","market_id":"3826919","outcome_index":0,"market_type":"set2","local_side":"home","local_uid":"2026-08-24_dalibor_svrcina_felipe_meligeni_alves","bid":0.43,"ask":0.52,"mid":0.475,"spread":0.09,"bid_size":null,"ask_size":null}
{"ts":"2026-08-24T20:48:32.250Z","event_type":"best_bid_ask","market_id":"3826919","outcome_index":1,"market_type":"set2","local_side":"away","local_uid":"2026-08-24_dalibor_svrcina_felipe_meligeni_alves","bid":0.48,"ask":0.57,"mid":0.525,"spread":0.09,"bid_size":null,"ask_size":null}
{"ts":"2026-08-24T20:48:32.251Z","event_type":"price_change","market_id":"3826919","outcome_index":1,"market_type":"set2","local_side":"away","local_uid":"2026-08-24_dalibor_svrcina_felipe_meligeni_alves","bid":0.48,"ask":0.57,"mid":0.525,"spread":0.09,"price":0.49,"size":0.0,"side":"BUY"}
{"ts":"2026-08-24T20:48:32.251Z","event_type":"price_change","market_id":"3826919","outcome_index":0,"market_type":"set2","local_side":"home","local_uid":"2026-08-24_dalibor_svrcina_felipe_meligeni_alves","bid":0.43,"ask":0.52,"mid":0.475,"spread":0.09,"price":0.51,"size":0.0,"side":"SELL"}
{"ts":"2026-08-24T20:48:32.255Z","event_type":"best_bid_ask","market_id":"3825608","outcome_index":0,"market_type":"match","local_side":"home","local_uid":"2026-08-24_raul_brancaccio_thiago_seyboth_wild","bid":0.22,"ask":0.23,"mid":0.225,"spread":0.01,"bid_size":null,"ask_size":null}
{"ts":"2026-08-24T20:48:32.255Z","event_type":"best_bid_ask","market_id":"3825608","outcome_index":1,"market_type":"match","local_side":"away","local_uid":"2026-08-24_raul_brancaccio_thiago_seyboth_wild","bid":0.77,"ask":0.78,"mid":0.775,"spread":0.01,"bid_size":null,"ask_size":null}
{"ts":"2026-08-24T20:48:32.256Z","event_type":"price_change","market_id":"3825608","outcome_index":1,"market_type":"match","local_side":"away","local_uid":"2026-08-24_raul_brancaccio_thiago_seyboth_wild","bid":0.77,"ask":0.78,"mid":0.775,"spread":0.01,"price":0.77,"size":14025.26,"side":"BUY"}
{"ts":"2026-08-24T20:48:32.256Z","event_type":"price_change","market_id":"3825608","outcome_index":0,"market_type":"match","local_side":"home","local_uid":"2026-08-24_raul_brancaccio_thiago_seyboth_wild","bid":0.22,"ask":0.23,"mid":0.225,"spread":0.01,"price":0.23,"size":14025.26,"side":"SELL"}
{"ts":"2026-08-24T20:48:32.290Z","event_type":"best_bid_ask","market_id":"3824760","outcome_index":0,"market_type":"set2","local_side":"home","local_uid":"2026-08-24_jazmin_ortenzi_himeno_sakatsume","bid":0.2,"ask":0.28,"mid":0.24,"spread":0.08,"bid_size":null,"ask_size":null}
{"ts":"2026-08-24T20:48:32.290Z","event_type":"best_bid_ask","market_id":"3824760","outcome_index":1,"market_type":"set2","local_side":"away","local_uid":"2026-08-24_jazmin_ortenzi_himeno_sakatsume","bid":0.72,"ask":0.8,"mid":0.76,"spread":0.08,"bid_size":null,"ask_size":null}
{"ts":"2026-08-24T20:48:32.290Z","event_type":"price_change","market_id":"3824760","outcome_index":1,"market_type":"set2","local_side":"away","local_uid":"2026-08-24_jazmin_ortenzi_himeno_sakatsume","bid":0.72,"ask":0.8,"mid":0.76,"spread":0.08,"price":0.72,"size":50.0,"side":"BUY"}
{"ts":"2026-08-24T20:48:32.291Z","event_type":"price_change","market_id":"3824760","outcome_index":0,"market_type":"set2","local_side":"home","local_uid":"2026-08-24_jazmin_ortenzi_himeno_sakatsume","bid":0.2,"ask":0.28,"mid":0.24,"spread":0.08,"price":0.28,"size":50.0,"side":"SELL"}
{"ts":"2026-08-24T20:48:32.336Z","event_type":"best_bid_ask","market_id":"3823619","outcome_index":0,"market_type":"match","local_side":"home","local_uid":"2026-08-24_polina_kudermetova_linda_fruhvirtova","bid":0.56,"ask":0.59,"mid":0.575,"spread":0.03,"bid_size":null,"ask_size":null}
{"ts":"2026-08-24T20:48:32.336Z","event_type":"best_bid_ask","market_id":"3823619","outcome_index":1,"market_type":"match","local_side":"away","local_uid":"2026-08-24_polina_kudermetova_linda_fruhvirtova","bid":0.41,"ask":0.44,"mid":0.425,"spread":0.03,"bid_size":null,"ask_size":null}
{"ts":"2026-08-24T20:48:32.337Z","event_type":"price_change","market_id":"3823619","outcome_index":0,"market_type":"match","local_side":"home","local_uid":"2026-08-24_polina_kudermetova_linda_fruhvirtova","bid":0.56,"ask":0.59,"mid":0.575,"spread":0.03,"price":0.57,"size":0.0,"side":"BUY"}
{"ts":"2026-08-24T20:48:32.337Z","event_type":"price_change","market_id":"3823619","outcome_index":1,"market_type":"match","local_side":"away","local_uid":"2026-08-24_polina_kudermetova_linda_fruhvirtova","bid":0.41,"ask":0.44,"mid":0.425,"spread":0.03,"price":0.43,"size":0.0,"side":"SELL"}
{"ts":"2026-08-24T20:48:32.387Z","event_type":"best_bid_ask","market_id":"3826919","outcome_index":0,"market_type":"set2","local_side":"home","local_uid":"2026-08-24_dalibor_svrcina_felipe_meligeni_alves","bid":0.43,"ask":0.51,"mid":0.47,"spread":0.08,"bid_size":null,"ask_size":null}
{"ts":"2026-08-24T20:48:32.388Z","event_type":"best_bid_ask","market_id":"3826919","outcome_index":1,"market_type":"set2","local_side":"away","local_uid":"2026-08-24_dalibor_svrcina_felipe_meligeni_alves","bid":0.49,"ask":0.57,"mid":0.53,"spread":0.08,"bid_size":null,"ask_size":null}
{"ts":"2026-08-24T20:48:32.392Z","event_type":"price_change","market_id":"3826919","outcome_index":1,"market_type":"set2","local_side":"away","local_uid":"2026-08-24_dalibor_svrcina_felipe_meligeni_alves","bid":0.49,"ask":0.57,"mid":0.53,"spread":0.08,"price":0.49,"size":24.6,"side":"BUY"}
{"ts":"2026-08-24T20:48:32.392Z","event_type":"price_change","market_id":"3826919","outcome_index":0,"market_type":"set2","local_side":"home","local_uid":"2026-08-24_dalibor_svrcina_felipe_meligeni_alves","bid":0.43,"ask":0.51,"mid":0.47,"spread":0.08,"price":0.51,"size":24.6,"side":"SELL"}
{"ts":"2026-08-24T20:48:32.422Z","event_type":"best_bid_ask","market_id":"3825077","outcome_index":0,"market_type":"set1","local_side":"home","local_uid":"2026-08-24_polina_kudermetova_linda_fruhvirtova","bid":0.45,"ask":0.55,"mid":0.5,"spread":0.1,"bid_size":null,"ask_size":null}
{"ts":"2026-08-24T20:48:32.423Z","event_type":"best_bid_ask","market_id":"3825077","outcome_index":1,"market_type":"set1","local_side":"away","local_uid":"2026-08-24_polina_kudermetova_linda_fruhvirtova","bid":0.45,"ask":0.55,"mid":0.5,"spread":0.1,"bid_size":null,"ask_size":null}
{"ts":"2026-08-24T20:48:32.423Z","event_type":"price_change","market_id":"3825077","outcome_index":1,"market_type":"set1","local_side":"away","local_uid":"2026-08-24_polina_kudermetova_linda_fruhvirtova","bid":0.45,"ask":0.55,"mid":0.5,"spread":0.1,"price":0.47,"size":0.0,"side":"BUY"}
{"ts":"2026-08-24T20:48:32.423Z","event_type":"price_change","market_id":"3825077","outcome_index":0,"market_type":"set1","local_side":"home","local_uid":"2026-08-24_polina_kudermetova_linda_fruhvirtova","bid":0.45,"ask":0.55,"mid":0.5,"spread":0.1,"price":0.53,"size":0.0,"side":"SELL"}
{"ts":"2026-08-24T20:48:32.425Z","event_type":"best_bid_ask","market_id":"3826919","outcome_index":0,"market_type":"set2","local_side":"home","local_uid":"2026-08-24_dalibor_svrcina_felipe_meligeni_alves","bid":0.43,"ask":0.52,"mid":0.475,"spread":0.09,"bid_size":null,"ask_size":null}
{"ts":"2026-08-24T20:48:32.425Z","event_type":"best_bid_ask","market_id":"3826919","outcome_index":1,"market_type":"set2","local_side":"away","local_uid":"2026-08-24_dalibor_svrcina_felipe_meligeni_alves","bid":0.48,"ask":0.57,"mid":0.525,"spread":0.09,"bid_size":null,"ask_size":null}
{"ts":"2026-08-24T20:48:32.425Z","event_type":"price_change","market_id":"3826919","outcome_index":1,"market_type":"set2","local_side":"away","local_uid":"2026-08-24_dalibor_svrcina_felipe_meligeni_alves","bid":0.48,"ask":0.57,"mid":0.525,"spread":0.09,"price":0.49,"size":0.0,"side":"BUY"}
{"ts":"2026-08-24T20:48:32.426Z","event_type":"price_change","market_id":"3826919","outcome_index":0,"market_type":"set2","local_side":"home","local_uid":"2026-08-24_dalibor_svrcina_felipe_meligeni_alves","bid":0.43,"ask":0.52,"mid":0.475,"spread":0.09,"price":0.51,"size":0.0,"side":"SELL"}
{"ts":"2026-08-24T20:48:32.464Z","event_type":"best_bid_ask","market_id":"3826919","outcome_index":0,"market_type":"set2","local_side":"home","local_uid":"2026-08-24_dalibor_svrcina_felipe_meligeni_alves","bid":0.43,"ask":0.51,"mid":0.47,"spread":0.08,"bid_size":null,"ask_size":null}
{"ts":"2026-08-24T20:48:32.465Z","event_type":"best_bid_ask","market_id":"3826919","outcome_index":1,"market_type":"set2","local_side":"away","local_uid":"2026-08-24_dalibor_svrcina_felipe_meligeni_alves","bid":0.49,"ask":0.57,"mid":0.53,"spread":0.08,"bid_size":null,"ask_size":null}
{"ts":"2026-08-24T20:48:32.465Z","event_type":"price_change","market_id":"3826919","outcome_index":1,"market_type":"set2","local_side":"away","local_uid":"2026-08-24_dalibor_svrcina_felipe_meligeni_alves","bid":0.49,"ask":0.57,"mid":0.53,"spread":0.08,"price":0.49,"size":24.6,"side":"BUY"}
{"ts":"2026-08-24T20:48:32.465Z","event_type":"price_change","market_id":"3826919","outcome_index":0,"market_type":"set2","local_side":"home","local_uid":"2026-08-24_dalibor_svrcina_felipe_meligeni_alves","bid":0.43,"ask":0.51,"mid":0.47,"spread":0.08,"price":0.51,"size":24.6,"side":"SELL"}
{"ts":"2026-08-24T20:48:32.471Z","event_type":"best_bid_ask","market_id":"3825608","outcome_index":0,"market_type":"match","local_side":"home","local_uid":"2026-08-24_raul_brancaccio_thiago_seyboth_wild","bid":0.21,"ask":0.23,"mid":0.22,"spread":0.02,"bid_size":null,"ask_size":null}
{"ts":"2026-08-24T20:48:32.471Z","event_type":"best_bid_ask","market_id":"3825608","outcome_index":1,"market_type":"match","local_side":"away","local_uid":"2026-08-24_raul_brancaccio_thiago_seyboth_wild","bid":0.77,"ask":0.79,"mid":0.78,"spread":0.02,"bid_size":null,"ask_size":null}
{"ts":"2026-08-24T20:48:32.472Z","event_type":"price_change","market_id":"3825608","outcome_index":0,"market_type":"match","local_side":"home","local_uid":"2026-08-24_raul_brancaccio_thiago_seyboth_wild","bid":0.21,"ask":0.23,"mid":0.22,"spread":0.02,"price":0.22,"size":0.0,"side":"BUY"}
{"ts":"2026-08-24T20:48:32.472Z","event_type":"price_change","market_id":"3825608","outcome_index":1,"market_type":"match","local_side":"away","local_uid":"2026-08-24_raul_brancaccio_thiago_seyboth_wild","bid":0.77,"ask":0.79,"mid":0.78,"spread":0.02,"price":0.78,"size":0.0,"side":"SELL"}
{"ts":"2026-08-24T20:48:32.482Z","event_type":"best_bid_ask","market_id":"3823619","outcome_index":0,"market_type":"match","local_side":"home","local_uid":"2026-08-24_polina_kudermetova_linda_fruhvirtova","bid":0.56,"ask":0.58,"mid":0.57,"spread":0.02,"bid_size":null,"ask_size":null}
{"ts":"2026-08-24T20:48:32.482Z","event_type":"best_bid_ask","market_id":"3823619","outcome_index":1,"market_type":"match","local_side":"away","local_uid":"2026-08-24_polina_kudermetova_linda_fruhvirtova","bid":0.42,"ask":0.44,"mid":0.43,"spread":0.02,"bid_size":null,"ask_size":null}
{"ts":"2026-08-24T20:48:32.483Z","event_type":"price_change","market_id":"3823619","outcome_index":1,"market_type":"match","local_side":"away","local_uid":"2026-08-24_polina_kudermetova_linda_fruhvirtova","bid":0.42,"ask":0.44,"mid":0.43,"spread":0.02,"price":0.42,"size":50.0,"side":"BUY"}
{"ts":"2026-08-24T20:48:32.483Z","event_type":"price_change","market_id":"3823619","outcome_index":0,"market_type":"match","local_side":"home","local_uid":"2026-08-24_polina_kudermetova_linda_fruhvirtova","bid":0.56,"ask":0.58,"mid":0.57,"spread":0.02,"price":0.58,"size":50.0,"side":"SELL"}
{"ts":"2026-08-24T20:48:32.514Z","event_type":"best_bid_ask","market_id":"3826919","outcome_index":0,"market_type":"set2","local_side":"home","local_uid":"2026-08-24_dalibor_svrcina_felipe_meligeni_alves","bid":0.43,"ask":0.52,"mid":0.475,"spread":0.09,"bid_size":null,"ask_size":null}
{"ts":"2026-08-24T20:48:32.514Z","event_type":"best_bid_ask","market_id":"3826919","outcome_index":1,"market_type":"set2","local_side":"away","local_uid":"2026-08-24_dalibor_svrcina_felipe_meligeni_alves","bid":0.48,"ask":0.57,"mid":0.525,"spread":0.09,"bid_size":null,"ask_size":null}
{"ts":"2026-08-24T20:48:32.514Z","event_type":"price_change","market_id":"3826919","outcome_index":1,"market_type":"set2","local_side":"away","local_uid":"2026-08-24_dalibor_svrcina_felipe_meligeni_alves","bid":0.48,"ask":0.57,"mid":0.525,"spread":0.09,"price":0.49,"size":0.0,"side":"BUY"}
{"ts":"2026-08-24T20:48:32.515Z","event_type":"price_change","market_id":"3826919","outcome_index":0,"market_type":"set2","local_side":"home","local_uid":"2026-08-24_dalibor_svrcina_felipe_meligeni_alves","bid":0.43,"ask":0.52,"mid":0.475,"spread":0.09,"price":0.51,"size":0.0,"side":"SELL"}
{"ts":"2026-08-24T20:48:32.552Z","event_type":"best_bid_ask","market_id":"3824796","outcome_index":0,"market_type":"set2","local_side":"home","local_uid":"2026-08-24_victoria_jimenez_kasintseva_francisca_jorge","bid":0.46,"ask":0.57,"mid":0.515,"spread":0.11,"bid_size":null,"ask_size":null}
{"ts":"2026-08-24T20:48:32.552Z","event_type":"best_bid_ask","market_id":"3824796","outcome_index":1,"market_type":"set2","local_side":"away","local_uid":"2026-08-24_victoria_jimenez_kasintseva_francisca_jorge","bid":0.43,"ask":0.54,"mid":0.485,"spread":0.11,"bid_size":null,"ask_size":null}
{"ts":"2026-08-24T20:48:32.552Z","event_type":"price_change","market_id":"3824796","outcome_index":0,"market_type":"set2","local_side":"home","local_uid":"2026-08-24_victoria_jimenez_kasintseva_francisca_jorge","bid":0.46,"ask":0.57,"mid":0.515,"spread":0.11,"price":0.47,"size":0.0,"side":"BUY"}
{"ts":"2026-08-24T20:48:32.553Z","event_type":"price_change","market_id":"3824796","outcome_index":1,"market_type":"set2","local_side":"away","local_uid":"2026-08-24_victoria_jimenez_kasintseva_francisca_jorge","bid":0.43,"ask":0.54,"mid":0.485,"spread":0.11,"price":0.53,"size":0.0,"side":"SELL"}
{"ts":"2026-08-24T20:48:32.561Z","event_type":"best_bid_ask","market_id":"3826905","outcome_index":0,"market_type":"set1","local_side":"home","local_uid":"2026-08-24_keegan_smith_alexis_galarneau","bid":0.0,"ask":1.0,"mid":0.5,"spread":1.0,"bid_size":null,"ask_size":null}
{"ts":"2026-08-24T20:48:32.563Z","event_type":"best_bid_ask","market_id":"3826905","outcome_index":1,"market_type":"set1","local_side":"away","local_uid":"2026-08-24_keegan_smith_alexis_galarneau","bid":0.0,"ask":1.0,"mid":0.5,"spread":1.0,"bid_size":null,"ask_size":null}
{"ts":"2026-08-24T20:48:32.564Z","event_type":"price_change","market_id":"3826905","outcome_index":1,"market_type":"set1","local_side":"away","local_uid":"2026-08-24_keegan_smith_alexis_galarneau","bid":0.0,"ask":1.0,"mid":0.5,"spread":1.0,"price":0.45,"size":0.0,"side":"BUY"}
{"ts":"2026-08-24T20:48:32.564Z","event_type":"price_change","market_id":"3826905","outcome_index":0,"market_type":"set1","local_side":"home","local_uid":"2026-08-24_keegan_smith_alexis_galarneau","bid":0.0,"ask":1.0,"mid":0.5,"spread":1.0,"price":0.55,"size":0.0,"side":"SELL"}
{"ts":"2026-08-24T20:48:32.566Z","event_type":"best_bid_ask","market_id":"3824796","outcome_index":0,"market_type":"set2","local_side":"home","local_uid":"2026-08-24_victoria_jimenez_kasintseva_francisca_jorge","bid":0.45,"ask":0.57,"mid":0.51,"spread":0.12,"bid_size":null,"ask_size":null}
{"ts":"2026-08-24T20:48:32.567Z","event_type":"best_bid_ask","market_id":"3824796","outcome_index":1,"market_type":"set2","local_side":"away","local_uid":"2026-08-24_victoria_jimenez_kasintseva_francisca_jorge","bid":0.43,"ask":0.55,"mid":0.49,"spread":0.12,"bid_size":null,"ask_size":null}
{"ts":"2026-08-24T20:48:32.567Z","event_type":"price_change","market_id":"3824796","outcome_index":0,"market_type":"set2","local_side":"home","local_uid":"2026-08-24_victoria_jimenez_kasintseva_francisca_jorge","bid":0.45,"ask":0.57,"mid":0.51,"spread":0.12,"price":0.46,"size":0.0,"side":"BUY"}
{"ts":"2026-08-24T20:48:32.567Z","event_type":"price_change","market_id":"3824796","outcome_index":1,"market_type":"set2","local_side":"away","local_uid":"2026-08-24_victoria_jimenez_kasintseva_francisca_jorge","bid":0.43,"ask":0.55,"mid":0.49,"spread":0.12,"price":0.54,"size":0.0,"side":"SELL"}
{"ts":"2026-08-24T20:48:32.567Z","event_type":"best_bid_ask","market_id":"3824796","outcome_index":0,"market_type":"set2","local_side":"home","local_uid":"2026-08-24_victoria_jimenez_kasintseva_francisca_jorge","bid":0.44,"ask":0.57,"mid":0.505,"spread":0.13,"bid_size":null,"ask_size":null}
{"ts":"2026-08-24T20:48:32.568Z","event_type":"best_bid_ask","market_id":"3824796","outcome_index":1,"market_type":"set2","local_side":"away","local_uid":"2026-08-24_victoria_jimenez_kasintseva_francisca_jorge","bid":0.43,"ask":0.56,"mid":0.495,"spread":0.13,"bid_size":null,"ask_size":null}
{"ts":"2026-08-24T20:48:32.568Z","event_type":"price_change","market_id":"3824796","outcome_index":0,"market_type":"set2","local_side":"home","local_uid":"2026-08-24_victoria_jimenez_kasintseva_francisca_jorge","bid":0.44,"ask":0.57,"mid":0.505,"spread":0.13,"price":0.45,"size":0.0,"side":"BUY"}
{"ts":"2026-08-24T20:48:32.568Z","event_type":"price_change","market_id":"3824796","outcome_index":1,"market_type":"set2","local_side":"away","local_uid":"2026-08-24_victoria_jimenez_kasintseva_francisca_jorge","bid":0.43,"ask":0.56,"mid":0.495,"spread":0.13,"price":0.55,"size":0.0,"side":"SELL"}
{"ts":"2026-08-24T20:48:32.570Z","event_type":"best_bid_ask","market_id":"3824796","outcome_index":0,"market_type":"set2","local_side":"home","local_uid":"2026-08-24_victoria_jimenez_kasintseva_francisca_jorge","bid":0.45,"ask":0.57,"mid":0.51,"spread":0.12,"bid_size":null,"ask_size":null}
{"ts":"2026-08-24T20:48:32.570Z","event_type":"best_bid_ask","market_id":"3824796","outcome_index":1,"market_type":"set2","local_side":"away","local_uid":"2026-08-24_victoria_jimenez_kasintseva_francisca_jorge","bid":0.43,"ask":0.55,"mid":0.49,"spread":0.12,"bid_size":null,"ask_size":null}
{"ts":"2026-08-24T20:48:32.571Z","event_type":"price_change","market_id":"3824796","outcome_index":0,"market_type":"set2","local_side":"home","local_uid":"2026-08-24_victoria_jimenez_kasintseva_francisca_jorge","bid":0.45,"ask":0.57,"mid":0.51,"spread":0.12,"price":0.45,"size":6.0,"side":"BUY"}
{"ts":"2026-08-24T20:48:32.571Z","event_type":"price_change","market_id":"3824796","outcome_index":1,"market_type":"set2","local_side":"away","local_uid":"2026-08-24_victoria_jimenez_kasintseva_francisca_jorge","bid":0.43,"ask":0.55,"mid":0.49,"spread":0.12,"price":0.55,"size":6.0,"side":"SELL"}
{"ts":"2026-08-24T20:48:32.578Z","event_type":"best_bid_ask","market_id":"3824796","outcome_index":0,"market_type":"set2","local_side":"home","local_uid":"2026-08-24_victoria_jimenez_kasintseva_francisca_jorge","bid":0.46,"ask":0.57,"mid":0.515,"spread":0.11,"bid_size":null,"ask_size":null}
{"ts":"2026-08-24T20:48:32.578Z","event_type":"best_bid_ask","market_id":"3824796","outcome_index":1,"market_type":"set2","local_side":"away","local_uid":"2026-08-24_victoria_jimenez_kasintseva_francisca_jorge","bid":0.43,"ask":0.54,"mid":0.485,"spread":0.11,"bid_size":null,"ask_size":null}
{"ts":"2026-08-24T20:48:32.578Z","event_type":"price_change","market_id":"3824796","outcome_index":0,"market_type":"set2","local_side":"home","local_uid":"2026-08-24_victoria_jimenez_kasintseva_francisca_jorge","bid":0.46,"ask":0.57,"mid":0.515,"spread":0.11,"price":0.46,"size":5.0,"side":"BUY"}
{"ts":"2026-08-24T20:48:32.579Z","event_type":"price_change","market_id":"3824796","outcome_index":1,"market_type":"set2","local_side":"away","local_uid":"2026-08-24_victoria_jimenez_kasintseva_francisca_jorge","bid":0.43,"ask":0.54,"mid":0.485,"spread":0.11,"price":0.54,"size":5.0,"side":"SELL"}
{"ts":"2026-08-24T20:48:32.594Z","event_type":"best_bid_ask","market_id":"3824761","outcome_index":0,"market_type":"set1","local_side":"home","local_uid":"2026-08-24_jazmin_ortenzi_himeno_sakatsume","bid":0.14,"ask":0.2,"mid":0.17,"spread":0.06,"bid_size":null,"ask_size":null}
{"ts":"2026-08-24T20:48:32.595Z","event_type":"best_bid_ask","market_id":"3824761","outcome_index":1,"market_type":"set1","local_side":"away","local_uid":"2026-08-24_jazmin_ortenzi_himeno_sakatsume","bid":0.8,"ask":0.86,"mid":0.83,"spread":0.06,"bid_size":null,"ask_size":null}
{"ts":"2026-08-24T20:48:32.595Z","event_type":"price_change","market_id":"3824761","outcome_index":0,"market_type":"set1","local_side":"home","local_uid":"2026-08-24_jazmin_ortenzi_himeno_sakatsume","bid":0.14,"ask":0.2,"mid":0.17,"spread":0.06,"price":0.14,"size":1281.0,"side":"BUY"}
{"ts":"2026-08-24T20:48:32.595Z","event_type":"price_change","market_id":"3824761","outcome_index":1,"market_type":"set1","local_side":"away","local_uid":"2026-08-24_jazmin_ortenzi_himeno_sakatsume","bid":0.8,"ask":0.86,"mid":0.83,"spread":0.06,"price":0.86,"size":1281.0,"side":"SELL"}
{"ts":"2026-08-24T20:48:32.601Z","event_type":"best_bid_ask","market_id":"3826905","outcome_index":0,"market_type":"set1","local_side":"home","local_uid":"2026-08-24_keegan_smith_alexis_galarneau","bid":0.41,"ask":1.0,"mid":0.705,"spread":0.59,"bid_size":null,"ask_size":null}
{"ts":"2026-08-24T20:48:32.601Z","event_type":"best_bid_ask","market_id":"3826905","outcome_index":1,"market_type":"set1","local_side":"away","local_uid":"2026-08-24_keegan_smith_alexis_galarneau","bid":0.0,"ask":0.59,"mid":0.295,"spread":0.59,"bid_size":null,"ask_size":null}
{"ts":"2026-08-24T20:48:32.604Z","event_type":"price_change","market_id":"3826905","outcome_index":0,"market_type":"set1","local_side":"home","local_uid":"2026-08-24_keegan_smith_alexis_galarneau","bid":0.41,"ask":1.0,"mid":0.705,"spread":0.59,"price":0.41,"size":250.0,"side":"BUY"}
{"ts":"2026-08-24T20:48:32.604Z","event_type":"price_change","market_id":"3826905","outcome_index":1,"market_type":"set1","local_side":"away","local_uid":"2026-08-24_keegan_smith_alexis_galarneau","bid":0.0,"ask":0.59,"mid":0.295,"spread":0.59,"price":0.59,"size":250.0,"side":"SELL"}
{"ts":"2026-08-24T20:48:32.618Z","event_type":"best_bid_ask","market_id":"3826905","outcome_index":0,"market_type":"set1","local_side":"home","local_uid":"2026-08-24_keegan_smith_alexis_galarneau","bid":0.41,"ask":0.58,"mid":0.495,"spread":0.17,"bid_size":null,"ask_size":null}
{"ts":"2026-08-24T20:48:32.618Z","event_type":"best_bid_ask","market_id":"3826905","outcome_index":1,"market_type":"set1","local_side":"away","local_uid":"2026-08-24_keegan_smith_alexis_galarneau","bid":0.42,"ask":0.59,"mid":0.505,"spread":0.17,"bid_size":null,"ask_size":null}
{"ts":"2026-08-24T20:48:32.619Z","event_type":"price_change","market_id":"3826905","outcome_index":1,"market_type":"set1","local_side":"away","local_uid":"2026-08-24_keegan_smith_alexis_galarneau","bid":0.42,"ask":0.59,"mid":0.505,"spread":0.17,"price":0.42,"size":250.0,"side":"BUY"}
{"ts":"2026-08-24T20:48:32.619Z","event_type":"price_change","market_id":"3826905","outcome_index":0,"market_type":"set1","local_side":"home","local_uid":"2026-08-24_keegan_smith_alexis_galarneau","bid":0.41,"ask":0.58,"mid":0.495,"spread":0.17,"price":0.58,"size":250.0,"side":"SELL"}
{"ts":"2026-08-24T20:48:32.623Z","event_type":"best_bid_ask","market_id":"3824796","outcome_index":0,"market_type":"set2","local_side":"home","local_uid":"2026-08-24_victoria_jimenez_kasintseva_francisca_jorge","bid":0.47,"ask":0.57,"mid":0.52,"spread":0.1,"bid_size":null,"ask_size":null}
{"ts":"2026-08-24T20:48:32.624Z","event_type":"best_bid_ask","market_id":"3824796","outcome_index":1,"market_type":"set2","local_side":"away","local_uid":"2026-08-24_victoria_jimenez_kasintseva_francisca_jorge","bid":0.43,"ask":0.53,"mid":0.48,"spread":0.1,"bid_size":null,"ask_size":null}
{"ts":"2026-08-24T20:48:32.624Z","event_type":"price_change","market_id":"3824796","outcome_index":0,"market_type":"set2","local_side":"home","local_uid":"2026-08-24_victoria_jimenez_kasintseva_francisca_jorge","bid":0.47,"ask":0.57,"mid":0.52,"spread":0.1,"price":0.47,"size":9.0,"side":"BUY"}
{"ts":"2026-08-24T20:48:32.624Z","event_type":"price_change","market_id":"3824796","outcome_index":1,"market_type":"set2","local_side":"away","local_uid":"2026-08-24_victoria_jimenez_kasintseva_francisca_jorge","bid":0.43,"ask":0.53,"mid":0.48,"spread":0.1,"price":0.53,"size":9.0,"side":"SELL"}
{"ts":"2026-08-24T20:48:32.663Z","event_type":"best_bid_ask","market_id":"3824796","outcome_index":0,"market_type":"set2","local_side":"home","local_uid":"2026-08-24_victoria_jimenez_kasintseva_francisca_jorge","bid":0.47,"ask":0.62,"mid":0.545,"spread":0.15,"bid_size":null,"ask_size":null}
{"ts":"2026-08-24T20:48:32.664Z","event_type":"best_bid_ask","market_id":"3824796","outcome_index":1,"market_type":"set2","local_side":"away","local_uid":"2026-08-24_victoria_jimenez_kasintseva_francisca_jorge","bid":0.38,"ask":0.53,"mid":0.455,"spread":0.15,"bid_size":null,"ask_size":null}
{"ts":"2026-08-24T20:48:32.664Z","event_type":"price_change","market_id":"3824796","outcome_index":1,"market_type":"set2","local_side":"away","local_uid":"2026-08-24_victoria_jimenez_kasintseva_francisca_jorge","bid":0.38,"ask":0.53,"mid":0.455,"spread":0.15,"price":0.43,"size":0.0,"side":"BUY"}
{"ts":"2026-08-24T20:48:32.664Z","event_type":"price_change","market_id":"3824796","outcome_index":0,"market_type":"set2","local_side":"home","local_uid":"2026-08-24_victoria_jimenez_kasintseva_francisca_jorge","bid":0.47,"ask":0.62,"mid":0.545,"spread":0.15,"price":0.57,"size":0.0,"side":"SELL"}
{"ts":"2026-08-24T20:48:32.667Z","event_type":"best_bid_ask","market_id":"3824796","outcome_index":0,"market_type":"set2","local_side":"home","local_uid":"2026-08-24_victoria_jimenez_kasintseva_francisca_jorge","bid":0.47,"ask":0.59,"mid":0.53,"spread":0.12,"bid_size":null,"ask_size":null}
{"ts":"2026-08-24T20:48:32.667Z","event_type":"best_bid_ask","market_id":"3824796","outcome_index":1,"market_type":"set2","local_side":"away","local_uid":"2026-08-24_victoria_jimenez_kasintseva_francisca_jorge","bid":0.41,"ask":0.53,"mid":0.47,"spread":0.12,"bid_size":null,"ask_size":null}
{"ts":"2026-08-24T20:48:32.667Z","event_type":"price_change","market_id":"3824796","outcome_index":1,"market_type":"set2","local_side":"away","local_uid":"2026-08-24_victoria_jimenez_kasintseva_francisca_jorge","bid":0.41,"ask":0.53,"mid":0.47,"spread":0.12,"price":0.41,"size":6.0,"side":"BUY"}
{"ts":"2026-08-24T20:48:32.668Z","event_type":"price_change","market_id":"3824796","outcome_index":0,"market_type":"set2","local_side":"home","local_uid":"2026-08-24_victoria_jimenez_kasintseva_francisca_jorge","bid":0.47,"ask":0.59,"mid":0.53,"spread":0.12,"price":0.59,"size":6.0,"side":"SELL"}
{"ts":"2026-08-24T20:48:32.668Z","event_type":"best_bid_ask","market_id":"3824796","outcome_index":0,"market_type":"set2","local_side":"home","local_uid":"2026-08-24_victoria_jimenez_kasintseva_francisca_jorge","bid":0.47,"ask":0.58,"mid":0.525,"spread":0.11,"bid_size":null,"ask_size":null}
{"ts":"2026-08-24T20:48:32.669Z","event_type":"best_bid_ask","market_id":"3824796","outcome_index":1,"market_type":"set2","local_side":"away","local_uid":"2026-08-24_victoria_jimenez_kasintseva_francisca_jorge","bid":0.42,"ask":0.53,"mid":0.475,"spread":0.11,"bid_size":null,"ask_size":null}
{"ts":"2026-08-24T20:48:32.669Z","event_type":"price_change","market_id":"3824796","outcome_index":1,"market_type":"set2","local_side":"away","local_uid":"2026-08-24_victoria_jimenez_kasintseva_francisca_jorge","bid":0.42,"ask":0.53,"mid":0.475,"spread":0.11,"price":0.42,"size":5.0,"side":"BUY"}
{"ts":"2026-08-24T20:48:32.669Z","event_type":"price_change","market_id":"3824796","outcome_index":0,"market_type":"set2","local_side":"home","local_uid":"2026-08-24_victoria_jimenez_kasintseva_francisca_jorge","bid":0.47,"ask":0.58,"mid":0.525,"spread":0.11,"price":0.58,"size":5.0,"side":"SELL"}
{"ts":"2026-08-24T20:48:32.670Z","event_type":"best_bid_ask","market_id":"3825641","outcome_index":0,"market_type":"match","local_side":"home","local_uid":"2026-08-24_sebastian_gorzny_cruz_hewitt","bid":0.62,"ask":0.64,"mid":0.63,"spread":0.02,"bid_size":null,"ask_size":null}
{"ts":"2026-08-24T20:48:32.670Z","event_type":"best_bid_ask","market_id":"3825641","outcome_index":1,"market_type":"match","local_side":"away","local_uid":"2026-08-24_sebastian_gorzny_cruz_hewitt","bid":0.36,"ask":0.38,"mid":0.37,"spread":0.02,"bid_size":null,"ask_size":null}
{"ts":"2026-08-24T20:48:32.670Z","event_type":"price_change","market_id":"3825641","outcome_index":0,"market_type":"match","local_side":"home","local_uid":"2026-08-24_sebastian_gorzny_cruz_hewitt","bid":0.62,"ask":0.64,"mid":0.63,"spread":0.02,"price":0.62,"size":100.0,"side":"BUY"}
{"ts":"2026-08-24T20:48:32.671Z","event_type":"price_change","market_id":"3825641","outcome_index":1,"market_type":"match","local_side":"away","local_uid":"2026-08-24_sebastian_gorzny_cruz_hewitt","bid":0.36,"ask":0.38,"mid":0.37,"spread":0.02,"price":0.38,"size":100.0,"side":"SELL"}
{"ts":"2026-08-24T20:48:32.727Z","event_type":"best_bid_ask","market_id":"3825608","outcome_index":0,"market_type":"match","local_side":"home","local_uid":"2026-08-24_raul_brancaccio_thiago_seyboth_wild","bid":0.21,"ask":0.22,"mid":0.215,"spread":0.01,"bid_size":null,"ask_size":null}
{"ts":"2026-08-24T20:48:32.729Z","event_type":"best_bid_ask","market_id":"3825608","outcome_index":1,"market_type":"match","local_side":"away","local_uid":"2026-08-24_raul_brancaccio_thiago_seyboth_wild","bid":0.78,"ask":0.79,"mid":0.785,"spread":0.01,"bid_size":null,"ask_size":null}
{"ts":"2026-08-24T20:48:32.730Z","event_type":"price_change","market_id":"3825608","outcome_index":0,"market_type":"match","local_side":"home","local_uid":"2026-08-24_raul_brancaccio_thiago_seyboth_wild","bid":0.21,"ask":0.22,"mid":0.215,"spread":0.01,"price":0.22,"size":2263.0,"side":"SELL"}
{"ts":"2026-08-24T20:48:32.730Z","event_type":"price_change","market_id":"3825608","outcome_index":1,"market_type":"match","local_side":"away","local_uid":"2026-08-24_raul_brancaccio_thiago_seyboth_wild","bid":0.78,"ask":0.79,"mid":0.785,"spread":0.01,"price":0.78,"size":2263.0,"side":"BUY"}
{"ts":"2026-08-24T20:48:32.743Z","event_type":"best_bid_ask","market_id":"3825641","outcome_index":0,"market_type":"match","local_side":"home","local_uid":"2026-08-24_sebastian_gorzny_cruz_hewitt","bid":0.63,"ask":0.64,"mid":0.635,"spread":0.01,"bid_size":null,"ask_size":null}
{"ts":"2026-08-24T20:48:32.743Z","event_type":"best_bid_ask","market_id":"3825641","outcome_index":1,"market_type":"match","local_side":"away","local_uid":"2026-08-24_sebastian_gorzny_cruz_hewitt","bid":0.36,"ask":0.37,"mid":0.365,"spread":0.01,"bid_size":null,"ask_size":null}
{"ts":"2026-08-24T20:48:32.744Z","event_type":"price_change","market_id":"3825641","outcome_index":0,"market_type":"match","local_side":"home","local_uid":"2026-08-24_sebastian_gorzny_cruz_hewitt","bid":0.63,"ask":0.64,"mid":0.635,"spread":0.01,"price":0.63,"size":105.0,"side":"BUY"}
{"ts":"2026-08-24T20:48:32.744Z","event_type":"price_change","market_id":"3825641","outcome_index":1,"market_type":"match","local_side":"away","local_uid":"2026-08-24_sebastian_gorzny_cruz_hewitt","bid":0.36,"ask":0.37,"mid":0.365,"spread":0.01,"price":0.37,"size":105.0,"side":"SELL"}
{"ts":"2026-08-24T20:48:32.758Z","event_type":"best_bid_ask","market_id":"3824761","outcome_index":0,"market_type":"set1","local_side":"home","local_uid":"2026-08-24_jazmin_ortenzi_himeno_sakatsume","bid":0.15,"ask":0.2,"mid":0.175,"spread":0.05,"bid_size":null,"ask_size":null}
{"ts":"2026-08-24T20:48:32.758Z","event_type":"best_bid_ask","market_id":"3824761","outcome_index":1,"market_type":"set1","local_side":"away","local_uid":"2026-08-24_jazmin_ortenzi_himeno_sakatsume","bid":0.8,"ask":0.85,"mid":0.825,"spread":0.05,"bid_size":null,"ask_size":null}
{"ts":"2026-08-24T20:48:32.759Z","event_type":"price_change","market_id":"3824761","outcome_index":0,"market_type":"set1","local_side":"home","local_uid":"2026-08-24_jazmin_ortenzi_himeno_sakatsume","bid":0.15,"ask":0.2,"mid":0.175,"spread":0.05,"price":0.15,"size":1753.15,"side":"BUY"}
{"ts":"2026-08-24T20:48:32.759Z","event_type":"price_change","market_id":"3824761","outcome_index":1,"market_type":"set1","local_side":"away","local_uid":"2026-08-24_jazmin_ortenzi_himeno_sakatsume","bid":0.8,"ask":0.85,"mid":0.825,"spread":0.05,"price":0.85,"size":1753.15,"side":"SELL"}
{"ts":"2026-08-24T20:48:32.770Z","event_type":"best_bid_ask","market_id":"3825641","outcome_index":0,"market_type":"match","local_side":"home","local_uid":"2026-08-24_sebastian_gorzny_cruz_hewitt","bid":0.63,"ask":0.65,"mid":0.64,"spread":0.02,"bid_size":null,"ask_size":null}
{"ts":"2026-08-24T20:48:32.770Z","event_type":"best_bid_ask","market_id":"3825641","outcome_index":1,"market_type":"match","local_side":"away","local_uid":"2026-08-24_sebastian_gorzny_cruz_hewitt","bid":0.35,"ask":0.37,"mid":0.36,"spread":0.02,"bid_size":null,"ask_size":null}
{"ts":"2026-08-24T20:48:32.770Z","event_type":"price_change","market_id":"3825641","outcome_index":1,"market_type":"match","local_side":"away","local_uid":"2026-08-24_sebastian_gorzny_cruz_hewitt","bid":0.35,"ask":0.37,"mid":0.36,"spread":0.02,"price":0.36,"size":0.0,"side":"BUY"}
{"ts":"2026-08-24T20:48:32.770Z","event_type":"price_change","market_id":"3825641","outcome_index":0,"market_type":"match","local_side":"home","local_uid":"2026-08-24_sebastian_gorzny_cruz_hewitt","bid":0.63,"ask":0.65,"mid":0.64,"spread":0.02,"price":0.64,"size":0.0,"side":"SELL"}
{"ts":"2026-08-24T20:48:32.826Z","event_type":"best_bid_ask","market_id":"3825641","outcome_index":0,"market_type":"match","local_side":"home","local_uid":"2026-08-24_sebastian_gorzny_cruz_hewitt","bid":0.64,"ask":0.65,"mid":0.645,"spread":0.01,"bid_size":null,"ask_size":null}
{"ts":"2026-08-24T20:48:32.827Z","event_type":"best_bid_ask","market_id":"3825641","outcome_index":1,"market_type":"match","local_side":"away","local_uid":"2026-08-24_sebastian_gorzny_cruz_hewitt","bid":0.35,"ask":0.36,"mid":0.355,"spread":0.01,"bid_size":null,"ask_size":null}
{"ts":"2026-08-24T20:48:32.827Z","event_type":"price_change","market_id":"3825641","outcome_index":0,"market_type":"match","local_side":"home","local_uid":"2026-08-24_sebastian_gorzny_cruz_hewitt","bid":0.64,"ask":0.65,"mid":0.645,"spread":0.01,"price":0.64,"size":50.0,"side":"BUY"}
{"ts":"2026-08-24T20:48:32.827Z","event_type":"price_change","market_id":"3825641","outcome_index":1,"market_type":"match","local_side":"away","local_uid":"2026-08-24_sebastian_gorzny_cruz_hewitt","bid":0.35,"ask":0.36,"mid":0.355,"spread":0.01,"price":0.36,"size":50.0,"side":"SELL"}
{"ts":"2026-08-24T20:48:32.832Z","event_type":"best_bid_ask","market_id":"3823619","outcome_index":0,"market_type":"match","local_side":"home","local_uid":"2026-08-24_polina_kudermetova_linda_fruhvirtova","bid":0.56,"ask":0.59,"mid":0.575,"spread":0.03,"bid_size":null,"ask_size":null}
