{"ts":"2026-08-23T17:53:56.691Z","event_type":"price_change","market_id":"3790415","outcome_index":1,"market_type":"set2","local_side":"away","local_uid":"2026-08-23_pierre_hugues_herbert_quinn_vandecasteele","bid":0.34,"ask":0.43,"mid":0.385,"spread":0.09,"price":0.43,"size":150.0,"side":"SELL"}
{"ts":"2026-08-23T17:53:56.816Z","event_type":"best_bid_ask","market_id":"3790415","outcome_index":0,"market_type":"set2","local_side":"home","local_uid":"2026-08-23_pierre_hugues_herbert_quinn_vandecasteele","bid":0.58,"ask":0.66,"mid":0.62,"spread":0.08,"bid_size":null,"ask_size":null}
{"ts":"2026-08-23T17:53:56.816Z","event_type":"best_bid_ask","market_id":"3790415","outcome_index":1,"market_type":"set2","local_side":"away","local_uid":"2026-08-23_pierre_hugues_herbert_quinn_vandecasteele","bid":0.34,"ask":0.42,"mid":0.38,"spread":0.08,"bid_size":null,"ask_size":null}
{"ts":"2026-08-23T17:53:56.816Z","event_type":"price_change","market_id":"3790415","outcome_index":0,"market_type":"set2","local_side":"home","local_uid":"2026-08-23_pierre_hugues_herbert_quinn_vandecasteele","bid":0.58,"ask":0.66,"mid":0.62,"spread":0.08,"price":0.58,"size":150.0,"side":"BUY"}
{"ts":"2026-08-23T17:53:56.816Z","event_type":"price_change","market_id":"3790415","outcome_index":1,"market_type":"set2","local_side":"away","local_uid":"2026-08-23_pierre_hugues_herbert_quinn_vandecasteele","bid":0.34,"ask":0.42,"mid":0.38,"spread":0.08,"price":0.42,"size":150.0,"side":"SELL"}
{"ts":"2026-08-23T17:53:57.060Z","event_type":"best_bid_ask","market_id":"3795960","outcome_index":0,"market_type":"match","local_side":"home","local_uid":"2026-08-23_enmanuel_munoz_thomas_fancutt","bid":0.001,"ask":0.008,"mid":0.0045,"spread":0.007,"bid_size":null,"ask_size":null}
{"ts":"2026-08-23T17:53:57.060Z","event_type":"best_bid_ask","market_id":"3795960","outcome_index":1,"market_type":"match","local_side":"away","local_uid":"2026-08-23_enmanuel_munoz_thomas_fancutt","bid":0.992,"ask":0.999,"mid":0.9955,"spread":0.007,"bid_size":null,"ask_size":null}
{"ts":"2026-08-23T17:53:57.061Z","event_type":"book","market_id":"3795960","outcome_index":0,"market_type":"match","local_side":"home","local_uid":"2026-08-23_enmanuel_munoz_thomas_fancutt","bid":0.001,"ask":0.008,"mid":0.0045,"spread":0.007,"bid_size":106.0,"ask_size":3956.0}
{"ts":"2026-08-23T17:53:57.061Z","event_type":"book","market_id":"3795960","outcome_index":1,"market_type":"match","local_side":"away","local_uid":"2026-08-23_enmanuel_munoz_thomas_fancutt","bid":0.992,"ask":0.999,"mid":0.9955,"spread":0.007,"bid_size":3956.0,"ask_size":106.0}
{"ts":"2026-08-23T17:53:57.063Z","event_type":"best_bid_ask","market_id":"3795960","outcome_index":0,"market_type":"match","local_side":"home","local_uid":"2026-08-23_enmanuel_munoz_thomas_fancutt","bid":0.0,"ask":0.001,"mid":0.0005,"spread":0.001,"bid_size":null,"ask_size":null}
{"ts":"2026-08-23T17:53:57.063Z","event_type":"best_bid_ask","market_id":"3795960","outcome_index":1,"market_type":"match","local_side":"away","local_uid":"2026-08-23_enmanuel_munoz_thomas_fancutt","bid":0.999,"ask":1.0,"mid":0.9995,"spread":0.001,"bid_size":null,"ask_size":null}
{"ts":"2026-08-23T17:53:57.063Z","event_type":"price_change","market_id":"3795960","outcome_index":1,"market_type":"match","local_side":"away","local_uid":"2026-08-23_enmanuel_munoz_thomas_fancutt","bid":0.999,"ask":1.0,"mid":0.9995,"spread":0.001,"price":0.999,"size":894.0,"side":"BUY"}
{"ts":"2026-08-23T17:53:57.063Z","event_type":"price_change","market_id":"3795960","outcome_index":0,"market_type":"match","local_side":"home","local_uid":"2026-08-23_enmanuel_munoz_thomas_fancutt","bid":0.0,"ask":0.001,"mid":0.0005,"spread":0.001,"price":0.001,"size":894.0,"side":"SELL"}
{"ts":"2026-08-23T17:53:57.092Z","event_type":"last_trade_price","market_id":"3795960","outcome_index":1,"market_type":"match","local_side":"away","local_uid":"2026-08-23_enmanuel_munoz_thomas_fancutt","last_trade":0.999,"trade_size":106.0,"trade_side":"BUY","trade_notional":105.894}
{"ts":"2026-08-23T17:53:57.117Z","event_type":"last_trade_price","market_id":"3795960","outcome_index":1,"market_type":"match","local_side":"away","local_uid":"2026-08-23_enmanuel_munoz_thomas_fancutt","last_trade":0.999,"trade_size":50.0,"trade_side":"BUY","trade_notional":49.95}
{"ts":"2026-08-23T17:53:58.022Z","event_type":"best_bid_ask","market_id":"3790415","outcome_index":0,"market_type":"set2","local_side":"home","local_uid":"2026-08-23_pierre_hugues_herbert_quinn_vandecasteele","bid":0.57,"ask":0.66,"mid":0.615,"spread":0.09,"bid_size":null,"ask_size":null}
{"ts":"2026-08-23T17:53:58.022Z","event_type":"best_bid_ask","market_id":"3790415","outcome_index":1,"market_type":"set2","local_side":"away","local_uid":"2026-08-23_pierre_hugues_herbert_quinn_vandecasteele","bid":0.34,"ask":0.43,"mid":0.385,"spread":0.09,"bid_size":null,"ask_size":null}
{"ts":"2026-08-23T17:53:58.022Z","event_type":"price_change","market_id":"3790415","outcome_index":0,"market_type":"set2","local_side":"home","local_uid":"2026-08-23_pierre_hugues_herbert_quinn_vandecasteele","bid":0.57,"ask":0.66,"mid":0.615,"spread":0.09,"price":0.58,"size":0.0,"side":"BUY"}
{"ts":"2026-08-23T17:53:58.022Z","event_type":"price_change","market_id":"3790415","outcome_index":1,"market_type":"set2","local_side":"away","local_uid":"2026-08-23_pierre_hugues_herbert_quinn_vandecasteele","bid":0.34,"ask":0.43,"mid":0.385,"spread":0.09,"price":0.42,"size":0.0,"side":"SELL"}
{"ts":"2026-08-23T17:53:58.236Z","event_type":"new_market","market_id":"0x44cbe389c465dd787e400e5bec687538a07f23b3287390ca9093ec7e3711052e"}
{"ts":"2026-08-23T17:53:58.534Z","event_type":"price_change","market_id":"3781395","outcome_index":1,"market_type":"set2","local_side":"away","local_uid":"2026-08-23_dino_prizmic_cruz_hewitt","bid":0.49,"ask":0.5,"mid":0.495,"spread":0.01,"price":0.5,"size":623.66,"side":"SELL"}
{"ts":"2026-08-23T17:53:58.534Z","event_type":"price_change","market_id":"3781395","outcome_index":0,"market_type":"set2","local_side":"home","local_uid":"2026-08-23_dino_prizmic_cruz_hewitt","bid":0.5,"ask":0.51,"mid":0.505,"spread":0.01,"price":0.5,"size":623.66,"side":"BUY"}
{"ts":"2026-08-23T17:53:58.585Z","event_type":"best_bid_ask","market_id":"3790415","outcome_index":0,"market_type":"set2","local_side":"home","local_uid":"2026-08-23_pierre_hugues_herbert_quinn_vandecasteele","bid":0.56,"ask":0.66,"mid":0.61,"spread":0.1,"bid_size":null,"ask_size":null}
{"ts":"2026-08-23T17:53:58.585Z","event_type":"best_bid_ask","market_id":"3790415","outcome_index":1,"market_type":"set2","local_side":"away","local_uid":"2026-08-23_pierre_hugues_herbert_quinn_vandecasteele","bid":0.34,"ask":0.44,"mid":0.39,"spread":0.1,"bid_size":null,"ask_size":null}
{"ts":"2026-08-23T17:53:58.586Z","event_type":"price_change","market_id":"3790415","outcome_index":0,"market_type":"set2","local_side":"home","local_uid":"2026-08-23_pierre_hugues_herbert_quinn_vandecasteele","bid":0.56,"ask":0.66,"mid":0.61,"spread":0.1,"price":0.57,"size":0.0,"side":"BUY"}
{"ts":"2026-08-23T17:53:58.586Z","event_type":"price_change","market_id":"3790415","outcome_index":1,"market_type":"set2","local_side":"away","local_uid":"2026-08-23_pierre_hugues_herbert_quinn_vandecasteele","bid":0.34,"ask":0.44,"mid":0.39,"spread":0.1,"price":0.43,"size":0.0,"side":"SELL"}
{"ts":"2026-08-23T17:53:58.700Z","event_type":"best_bid_ask","market_id":"3790415","outcome_index":0,"market_type":"set2","local_side":"home","local_uid":"2026-08-23_pierre_hugues_herbert_quinn_vandecasteele","bid":0.57,"ask":0.66,"mid":0.615,"spread":0.09,"bid_size":null,"ask_size":null}
{"ts":"2026-08-23T17:53:58.700Z","event_type":"best_bid_ask","market_id":"3790415","outcome_index":1,"market_type":"set2","local_side":"away","local_uid":"2026-08-23_pierre_hugues_herbert_quinn_vandecasteele","bid":0.34,"ask":0.43,"mid":0.385,"spread":0.09,"bid_size":null,"ask_size":null}
{"ts":"2026-08-23T17:53:58.700Z","event_type":"price_change","market_id":"3790415","outcome_index":0,"market_type":"set2","local_side":"home","local_uid":"2026-08-23_pierre_hugues_herbert_quinn_vandecasteele","bid":0.57,"ask":0.66,"mid":0.615,"spread":0.09,"price":0.57,"size":150.0,"side":"BUY"}
{"ts":"2026-08-23T17:53:58.701Z","event_type":"price_change","market_id":"3790415","outcome_index":1,"market_type":"set2","local_side":"away","local_uid":"2026-08-23_pierre_hugues_herbert_quinn_vandecasteele","bid":0.34,"ask":0.43,"mid":0.385,"spread":0.09,"price":0.43,"size":150.0,"side":"SELL"}
{"ts":"2026-08-23T17:53:58.816Z","event_type":"best_bid_ask","market_id":"3790415","outcome_index":0,"market_type":"set2","local_side":"home","local_uid":"2026-08-23_pierre_hugues_herbert_quinn_vandecasteele","bid":0.58,"ask":0.66,"mid":0.62,"spread":0.08,"bid_size":null,"ask_size":null}
{"ts":"2026-08-23T17:53:58.816Z","event_type":"best_bid_ask","market_id":"3790415","outcome_index":1,"market_type":"set2","local_side":"away","local_uid":"2026-08-23_pierre_hugues_herbert_quinn_vandecasteele","bid":0.34,"ask":0.42,"mid":0.38,"spread":0.08,"bid_size":null,"ask_size":null}
{"ts":"2026-08-23T17:53:58.816Z","event_type":"price_change","market_id":"3790415","outcome_index":0,"market_type":"set2","local_side":"home","local_uid":"2026-08-23_pierre_hugues_herbert_quinn_vandecasteele","bid":0.58,"ask":0.66,"mid":0.62,"spread":0.08,"price":0.58,"size":150.0,"side":"BUY"}
{"ts":"2026-08-23T17:53:58.816Z","event_type":"price_change","market_id":"3790415","outcome_index":1,"market_type":"set2","local_side":"away","local_uid":"2026-08-23_pierre_hugues_herbert_quinn_vandecasteele","bid":0.34,"ask":0.42,"mid":0.38,"spread":0.08,"price":0.42,"size":150.0,"side":"SELL"}
{"ts":"2026-08-23T17:53:59.321Z","event_type":"price_change","market_id":"3780826","outcome_index":1,"market_type":"match","local_side":"away","local_uid":"2026-08-23_giovanni_mpetshi_perricard_jenson_brooksby","bid":0.62,"ask":0.63,"mid":0.625,"spread":0.01,"price":0.61,"size":8644.15,"side":"BUY"}
{"ts":"2026-08-23T17:53:59.321Z","event_type":"price_change","market_id":"3780826","outcome_index":0,"market_type":"match","local_side":"home","local_uid":"2026-08-23_giovanni_mpetshi_perricard_jenson_brooksby","bid":0.37,"ask":0.38,"mid":0.375,"spread":0.01,"price":0.39,"size":8644.15,"side":"SELL"}
{"ts":"2026-08-23T17:53:59.514Z","event_type":"price_change","market_id":"3792969","outcome_index":0,"market_type":"match","local_side":"home","local_uid":"2026-08-23_maya_joint_yulia_putintseva","bid":0.44,"ask":0.45,"mid":0.445,"spread":0.01,"price":0.2,"size":0.0,"side":"BUY"}
{"ts":"2026-08-23T17:53:59.514Z","event_type":"price_change","market_id":"3792969","outcome_index":1,"market_type":"match","local_side":"away","local_uid":"2026-08-23_maya_joint_yulia_putintseva","bid":0.55,"ask":0.56,"mid":0.555,"spread":0.01,"price":0.8,"size":0.0,"side":"SELL"}
{"ts":"2026-08-23T17:54:00.146Z","event_type":"best_bid_ask","market_id":"3790415","outcome_index":0,"market_type":"set2","local_side":"home","local_uid":"2026-08-23_pierre_hugues_herbert_quinn_vandecasteele","bid":0.57,"ask":0.66,"mid":0.615,"spread":0.09,"bid_size":null,"ask_size":null}
{"ts":"2026-08-23T17:54:00.146Z","event_type":"best_bid_ask","market_id":"3790415","outcome_index":1,"market_type":"set2","local_side":"away","local_uid":"2026-08-23_pierre_hugues_herbert_quinn_vandecasteele","bid":0.34,"ask":0.43,"mid":0.385,"spread":0.09,"bid_size":null,"ask_size":null}
{"ts":"2026-08-23T17:54:00.147Z","event_type":"price_change","market_id":"3790415","outcome_index":0,"market_type":"set2","local_side":"home","local_uid":"2026-08-23_pierre_hugues_herbert_quinn_vandecasteele","bid":0.57,"ask":0.66,"mid":0.615,"spread":0.09,"price":0.58,"size":0.0,"side":"BUY"}
{"ts":"2026-08-23T17:54:00.147Z","event_type":"price_change","market_id":"3790415","outcome_index":1,"market_type":"set2","local_side":"away","local_uid":"2026-08-23_pierre_hugues_herbert_quinn_vandecasteele","bid":0.34,"ask":0.43,"mid":0.385,"spread":0.09,"price":0.42,"size":0.0,"side":"SELL"}
{"ts":"2026-08-23T17:54:00.157Z","event_type":"price_change","market_id":"3793654","outcome_index":1,"market_type":"set1","local_side":"away","local_uid":"2026-08-24_lilli_tagger_yuliia_starodubtseva","bid":0.38,"ask":0.41,"mid":0.395,"spread":0.03,"price":0.33,"size":803.62,"side":"BUY"}
{"ts":"2026-08-23T17:54:00.157Z","event_type":"price_change","market_id":"3793654","outcome_index":0,"market_type":"set1","local_side":"home","local_uid":"2026-08-24_lilli_tagger_yuliia_starodubtseva","bid":0.59,"ask":0.62,"mid":0.605,"spread":0.03,"price":0.67,"size":803.62,"side":"SELL"}
{"ts":"2026-08-23T17:54:00.165Z","event_type":"best_bid_ask","market_id":"3790415","outcome_index":0,"market_type":"set2","local_side":"home","local_uid":"2026-08-23_pierre_hugues_herbert_quinn_vandecasteele","bid":0.0,"ask":0.66,"mid":0.33,"spread":0.66,"bid_size":null,"ask_size":null}
{"ts":"2026-08-23T17:54:00.165Z","event_type":"best_bid_ask","market_id":"3790415","outcome_index":1,"market_type":"set2","local_side":"away","local_uid":"2026-08-23_pierre_hugues_herbert_quinn_vandecasteele","bid":0.34,"ask":1.0,"mid":0.67,"spread":0.66,"bid_size":null,"ask_size":null}
{"ts":"2026-08-23T17:54:00.165Z","event_type":"price_change","market_id":"3790415","outcome_index":0,"market_type":"set2","local_side":"home","local_uid":"2026-08-23_pierre_hugues_herbert_quinn_vandecasteele","bid":0.0,"ask":0.66,"mid":0.33,"spread":0.66,"price":0.57,"size":0.0,"side":"BUY"}
{"ts":"2026-08-23T17:54:00.165Z","event_type":"price_change","market_id":"3790415","outcome_index":1,"market_type":"set2","local_side":"away","local_uid":"2026-08-23_pierre_hugues_herbert_quinn_vandecasteele","bid":0.34,"ask":1.0,"mid":0.67,"spread":0.66,"price":0.43,"size":0.0,"side":"SELL"}
{"ts":"2026-08-23T17:54:00.184Z","event_type":"best_bid_ask","market_id":"3789997","outcome_index":0,"market_type":"match","local_side":"home","local_uid":"2026-08-23_oscar_weightman_alec_deckers","bid":0.06,"ask":0.07,"mid":0.065,"spread":0.01,"bid_size":null,"ask_size":null}
{"ts":"2026-08-23T17:54:00.185Z","event_type":"best_bid_ask","market_id":"3789997","outcome_index":1,"market_type":"match","local_side":"away","local_uid":"2026-08-23_oscar_weightman_alec_deckers","bid":0.93,"ask":0.94,"mid":0.935,"spread":0.01,"bid_size":null,"ask_size":null}
{"ts":"2026-08-23T17:54:00.185Z","event_type":"price_change","market_id":"3789997","outcome_index":1,"market_type":"match","local_side":"away","local_uid":"2026-08-23_oscar_weightman_alec_deckers","bid":0.93,"ask":0.94,"mid":0.935,"spread":0.01,"price":0.93,"size":43.0,"side":"BUY"}
{"ts":"2026-08-23T17:54:00.185Z","event_type":"price_change","market_id":"3789997","outcome_index":0,"market_type":"match","local_side":"home","local_uid":"2026-08-23_oscar_weightman_alec_deckers","bid":0.06,"ask":0.07,"mid":0.065,"spread":0.01,"price":0.07,"size":43.0,"side":"SELL"}
{"ts":"2026-08-23T17:54:00.248Z","event_type":"best_bid_ask","market_id":"3790415","outcome_index":0,"market_type":"set2","local_side":"home","local_uid":"2026-08-23_pierre_hugues_herbert_quinn_vandecasteele","bid":0.56,"ask":0.66,"mid":0.61,"spread":0.1,"bid_size":null,"ask_size":null}
{"ts":"2026-08-23T17:54:00.248Z","event_type":"best_bid_ask","market_id":"3790415","outcome_index":1,"market_type":"set2","local_side":"away","local_uid":"2026-08-23_pierre_hugues_herbert_quinn_vandecasteele","bid":0.34,"ask":0.44,"mid":0.39,"spread":0.1,"bid_size":null,"ask_size":null}
{"ts":"2026-08-23T17:54:00.249Z","event_type":"price_change","market_id":"3790415","outcome_index":0,"market_type":"set2","local_side":"home","local_uid":"2026-08-23_pierre_hugues_herbert_quinn_vandecasteele","bid":0.56,"ask":0.66,"mid":0.61,"spread":0.1,"price":0.56,"size":150.0,"side":"BUY"}
{"ts":"2026-08-23T17:54:00.249Z","event_type":"price_change","market_id":"3790415","outcome_index":1,"market_type":"set2","local_side":"away","local_uid":"2026-08-23_pierre_hugues_herbert_quinn_vandecasteele","bid":0.34,"ask":0.44,"mid":0.39,"spread":0.1,"price":0.44,"size":150.0,"side":"SELL"}
{"ts":"2026-08-23T17:54:00.293Z","event_type":"price_change","market_id":"3795956","outcome_index":0,"market_type":"match","local_side":"home","local_uid":"2026-08-23_evan_zhu_arthur_reymond","bid":0.5,"ask":0.51,"mid":0.505,"spread":0.01,"price":0.27,"size":0.0,"side":"BUY"}
{"ts":"2026-08-23T17:54:00.293Z","event_type":"price_change","market_id":"3795956","outcome_index":1,"market_type":"match","local_side":"away","local_uid":"2026-08-23_evan_zhu_arthur_reymond","bid":0.49,"ask":0.5,"mid":0.495,"spread":0.01,"price":0.73,"size":0.0,"side":"SELL"}
{"ts":"2026-08-23T17:54:00.300Z","event_type":"new_market","market_id":"0x8780164c7f61445ee449ecbeec2e39734dfd626e9f6d56cc30ac2996804d2e20"}
{"ts":"2026-08-23T17:54:00.335Z","event_type":"best_bid_ask","market_id":"3790415","outcome_index":0,"market_type":"set2","local_side":"home","local_uid":"2026-08-23_pierre_hugues_herbert_quinn_vandecasteele","bid":0.57,"ask":0.66,"mid":0.615,"spread":0.09,"bid_size":null,"ask_size":null}
{"ts":"2026-08-23T17:54:00.335Z","event_type":"best_bid_ask","market_id":"3790415","outcome_index":1,"market_type":"set2","local_side":"away","local_uid":"2026-08-23_pierre_hugues_herbert_quinn_vandecasteele","bid":0.34,"ask":0.43,"mid":0.385,"spread":0.09,"bid_size":null,"ask_size":null}
{"ts":"2026-08-23T17:54:00.335Z","event_type":"price_change","market_id":"3790415","outcome_index":0,"market_type":"set2","local_side":"home","local_uid":"2026-08-23_pierre_hugues_herbert_quinn_vandecasteele","bid":0.57,"ask":0.66,"mid":0.615,"spread":0.09,"price":0.57,"size":5.0,"side":"BUY"}
{"ts":"2026-08-23T17:54:00.335Z","event_type":"price_change","market_id":"3790415","outcome_index":1,"market_type":"set2","local_side":"away","local_uid":"2026-08-23_pierre_hugues_herbert_quinn_vandecasteele","bid":0.34,"ask":0.43,"mid":0.385,"spread":0.09,"price":0.43,"size":5.0,"side":"SELL"}
{"ts":"2026-08-23T17:54:00.598Z","event_type":"best_bid_ask","market_id":"3790415","outcome_index":0,"market_type":"set2","local_side":"home","local_uid":"2026-08-23_pierre_hugues_herbert_quinn_vandecasteele","bid":0.56,"ask":0.66,"mid":0.61,"spread":0.1,"bid_size":null,"ask_size":null}
{"ts":"2026-08-23T17:54:00.598Z","event_type":"best_bid_ask","market_id":"3790415","outcome_index":1,"market_type":"set2","local_side":"away","local_uid":"2026-08-23_pierre_hugues_herbert_quinn_vandecasteele","bid":0.34,"ask":0.44,"mid":0.39,"spread":0.1,"bid_size":null,"ask_size":null}
{"ts":"2026-08-23T17:54:00.598Z","event_type":"price_change","market_id":"3790415","outcome_index":0,"market_type":"set2","local_side":"home","local_uid":"2026-08-23_pierre_hugues_herbert_quinn_vandecasteele","bid":0.56,"ask":0.66,"mid":0.61,"spread":0.1,"price":0.57,"size":0.0,"side":"BUY"}
{"ts":"2026-08-23T17:54:00.598Z","event_type":"price_change","market_id":"3790415","outcome_index":1,"market_type":"set2","local_side":"away","local_uid":"2026-08-23_pierre_hugues_herbert_quinn_vandecasteele","bid":0.34,"ask":0.44,"mid":0.39,"spread":0.1,"price":0.43,"size":0.0,"side":"SELL"}
{"ts":"2026-08-23T17:54:00.809Z","event_type":"best_bid_ask","market_id":"3790415","outcome_index":0,"market_type":"set2","local_side":"home","local_uid":"2026-08-23_pierre_hugues_herbert_quinn_vandecasteele","bid":0.57,"ask":0.66,"mid":0.615,"spread":0.09,"bid_size":null,"ask_size":null}
{"ts":"2026-08-23T17:54:00.809Z","event_type":"best_bid_ask","market_id":"3790415","outcome_index":1,"market_type":"set2","local_side":"away","local_uid":"2026-08-23_pierre_hugues_herbert_quinn_vandecasteele","bid":0.34,"ask":0.43,"mid":0.385,"spread":0.09,"bid_size":null,"ask_size":null}
{"ts":"2026-08-23T17:54:00.809Z","event_type":"price_change","market_id":"3790415","outcome_index":0,"market_type":"set2","local_side":"home","local_uid":"2026-08-23_pierre_hugues_herbert_quinn_vandecasteele","bid":0.57,"ask":0.66,"mid":0.615,"spread":0.09,"price":0.57,"size":150.0,"side":"BUY"}
{"ts":"2026-08-23T17:54:00.809Z","event_type":"price_change","market_id":"3790415","outcome_index":1,"market_type":"set2","local_side":"away","local_uid":"2026-08-23_pierre_hugues_herbert_quinn_vandecasteele","bid":0.34,"ask":0.43,"mid":0.385,"spread":0.09,"price":0.43,"size":150.0,"side":"SELL"}
{"ts":"2026-08-23T17:54:01.005Z","event_type":"price_change","market_id":"3792973","outcome_index":0,"market_type":"match","local_side":"home","local_uid":"2026-08-23_anna_bondar_en_shuo_liang","bid":0.74,"ask":0.75,"mid":0.745,"spread":0.01,"price":0.52,"size":95.0,"side":"BUY"}
{"ts":"2026-08-23T17:54:01.005Z","event_type":"price_change","market_id":"3792973","outcome_index":1,"market_type":"match","local_side":"away","local_uid":"2026-08-23_anna_bondar_en_shuo_liang","bid":0.25,"ask":0.26,"mid":0.255,"spread":0.01,"price":0.48,"size":95.0,"side":"SELL"}
{"ts":"2026-08-23T17:54:01.006Z","event_type":"best_bid_ask","market_id":"3790415","outcome_index":0,"market_type":"set2","local_side":"home","local_uid":"2026-08-23_pierre_hugues_herbert_quinn_vandecasteele","bid":0.58,"ask":0.66,"mid":0.62,"spread":0.08,"bid_size":null,"ask_size":null}
{"ts":"2026-08-23T17:54:01.006Z","event_type":"best_bid_ask","market_id":"3790415","outcome_index":1,"market_type":"set2","local_side":"away","local_uid":"2026-08-23_pierre_hugues_herbert_quinn_vandecasteele","bid":0.34,"ask":0.42,"mid":0.38,"spread":0.08,"bid_size":null,"ask_size":null}
{"ts":"2026-08-23T17:54:01.006Z","event_type":"price_change","market_id":"3790415","outcome_index":0,"market_type":"set2","local_side":"home","local_uid":"2026-08-23_pierre_hugues_herbert_quinn_vandecasteele","bid":0.58,"ask":0.66,"mid":0.62,"spread":0.08,"price":0.58,"size":150.0,"side":"BUY"}
{"ts":"2026-08-23T17:54:01.006Z","event_type":"price_change","market_id":"3790415","outcome_index":1,"market_type":"set2","local_side":"away","local_uid":"2026-08-23_pierre_hugues_herbert_quinn_vandecasteele","bid":0.34,"ask":0.42,"mid":0.38,"spread":0.08,"price":0.42,"size":150.0,"side":"SELL"}
{"ts":"2026-08-23T17:54:02.240Z","event_type":"best_bid_ask","market_id":"3790415","outcome_index":0,"market_type":"set2","local_side":"home","local_uid":"2026-08-23_pierre_hugues_herbert_quinn_vandecasteele","bid":0.57,"ask":0.66,"mid":0.615,"spread":0.09,"bid_size":null,"ask_size":null}
{"ts":"2026-08-23T17:54:02.240Z","event_type":"best_bid_ask","market_id":"3790415","outcome_index":1,"market_type":"set2","local_side":"away","local_uid":"2026-08-23_pierre_hugues_herbert_quinn_vandecasteele","bid":0.34,"ask":0.43,"mid":0.385,"spread":0.09,"bid_size":null,"ask_size":null}
{"ts":"2026-08-23T17:54:02.240Z","event_type":"price_change","market_id":"3790415","outcome_index":0,"market_type":"set2","local_side":"home","local_uid":"2026-08-23_pierre_hugues_herbert_quinn_vandecasteele","bid":0.57,"ask":0.66,"mid":0.615,"spread":0.09,"price":0.58,"size":0.0,"side":"BUY"}
{"ts":"2026-08-23T17:54:02.240Z","event_type":"price_change","market_id":"3790415","outcome_index":1,"market_type":"set2","local_side":"away","local_uid":"2026-08-23_pierre_hugues_herbert_quinn_vandecasteele","bid":0.34,"ask":0.43,"mid":0.385,"spread":0.09,"price":0.42,"size":0.0,"side":"SELL"}
{"ts":"2026-08-23T17:54:02.583Z","event_type":"best_bid_ask","market_id":"3790415","outcome_index":0,"market_type":"set2","local_side":"home","local_uid":"2026-08-23_pierre_hugues_herbert_quinn_vandecasteele","bid":0.56,"ask":0.66,"mid":0.61,"spread":0.1,"bid_size":null,"ask_size":null}
{"ts":"2026-08-23T17:54:02.583Z","event_type":"best_bid_ask","market_id":"3790415","outcome_index":1,"market_type":"set2","local_side":"away","local_uid":"2026-08-23_pierre_hugues_herbert_quinn_vandecasteele","bid":0.34,"ask":0.44,"mid":0.39,"spread":0.1,"bid_size":null,"ask_size":null}
{"ts":"2026-08-23T17:54:02.584Z","event_type":"price_change","market_id":"3790415","outcome_index":0,"market_type":"set2","local_side":"home","local_uid":"2026-08-23_pierre_hugues_herbert_quinn_vandecasteele","bid":0.56,"ask":0.66,"mid":0.61,"spread":0.1,"price":0.57,"size":0.0,"side":"BUY"}
{"ts":"2026-08-23T17:54:02.584Z","event_type":"price_change","market_id":"3790415","outcome_index":1,"market_type":"set2","local_side":"away","local_uid":"2026-08-23_pierre_hugues_herbert_quinn_vandecasteele","bid":0.34,"ask":0.44,"mid":0.39,"spread":0.1,"price":0.43,"size":0.0,"side":"SELL"}
{"ts":"2026-08-23T17:54:03.122Z","event_type":"price_change","market_id":"3795974","outcome_index":0,"market_type":"match","local_side":"home","local_uid":"2026-08-23_juan_jose_bianchi_keshav_chopra","bid":0.15,"ask":0.19,"mid":0.17,"spread":0.04,"price":0.13,"size":1599.62,"side":"BUY"}
{"ts":"2026-08-23T17:54:03.122Z","event_type":"price_change","market_id":"3795974","outcome_index":1,"market_type":"match","local_side":"away","local_uid":"2026-08-23_juan_jose_bianchi_keshav_chopra","bid":0.81,"ask":0.85,"mid":0.83,"spread":0.04,"price":0.87,"size":1599.62,"side":"SELL"}
{"ts":"2026-08-23T17:54:03.200Z","event_type":"best_bid_ask","market_id":"3789927","outcome_index":0,"market_type":"match","local_side":"home","local_uid":"2026-08-23_hugo_grenier_mees_rottgering","bid":0.26,"ask":0.28,"mid":0.27,"spread":0.02,"bid_size":null,"ask_size":null}
{"ts":"2026-08-23T17:54:03.201Z","event_type":"best_bid_ask","market_id":"3789927","outcome_index":1,"market_type":"match","local_side":"away","local_uid":"2026-08-23_hugo_grenier_mees_rottgering","bid":0.72,"ask":0.74,"mid":0.73,"spread":0.02,"bid_size":null,"ask_size":null}
{"ts":"2026-08-23T17:54:03.201Z","event_type":"price_change","market_id":"3789927","outcome_index":1,"market_type":"match","local_side":"away","local_uid":"2026-08-23_hugo_grenier_mees_rottgering","bid":0.72,"ask":0.74,"mid":0.73,"spread":0.02,"price":0.73,"size":0.0,"side":"SELL"}
{"ts":"2026-08-23T17:54:03.201Z","event_type":"price_change","market_id":"3789927","outcome_index":0,"market_type":"match","local_side":"home","local_uid":"2026-08-23_hugo_grenier_mees_rottgering","bid":0.26,"ask":0.28,"mid":0.27,"spread":0.02,"price":0.27,"size":0.0,"side":"BUY"}
{"ts":"2026-08-23T17:54:03.287Z","event_type":"best_bid_ask","market_id":"3795958","outcome_index":0,"market_type":"match","local_side":"home","local_uid":"2026-08-23_bruno_kuzuhara_kody_pearson","bid":0.943,"ask":0.948,"mid":0.9455,"spread":0.005,"bid_size":null,"ask_size":null}
{"ts":"2026-08-23T17:54:03.287Z","event_type":"best_bid_ask","market_id":"3795958","outcome_index":1,"market_type":"match","local_side":"away","local_uid":"2026-08-23_bruno_kuzuhara_kody_pearson","bid":0.052,"ask":0.057,"mid":0.0545,"spread":0.005,"bid_size":null,"ask_size":null}
{"ts":"2026-08-23T17:54:03.287Z","event_type":"price_change","market_id":"3795958","outcome_index":1,"market_type":"match","local_side":"away","local_uid":"2026-08-23_bruno_kuzuhara_kody_pearson","bid":0.052,"ask":0.057,"mid":0.0545,"spread":0.005,"price":0.052,"size":307.69,"side":"BUY"}
{"ts":"2026-08-23T17:54:03.287Z","event_type":"price_change","market_id":"3795958","outcome_index":0,"market_type":"match","local_side":"home","local_uid":"2026-08-23_bruno_kuzuhara_kody_pearson","bid":0.943,"ask":0.948,"mid":0.9455,"spread":0.005,"price":0.948,"size":307.69,"side":"SELL"}
{"ts":"2026-08-23T17:54:03.331Z","event_type":"new_market","market_id":"0x639d4841a7e0abfdf72faec5cf024ec4d3eab401ef9fc627299e37891141c06c"}
{"ts":"2026-08-23T17:54:03.602Z","event_type":"best_bid_ask","market_id":"3790415","outcome_index":0,"market_type":"set2","local_side":"home","local_uid":"2026-08-23_pierre_hugues_herbert_quinn_vandecasteele","bid":0.0,"ask":0.66,"mid":0.33,"spread":0.66,"bid_size":null,"ask_size":null}
{"ts":"2026-08-23T17:54:03.602Z","event_type":"best_bid_ask","market_id":"3790415","outcome_index":1,"market_type":"set2","local_side":"away","local_uid":"2026-08-23_pierre_hugues_herbert_quinn_vandecasteele","bid":0.34,"ask":1.0,"mid":0.67,"spread":0.66,"bid_size":null,"ask_size":null}
{"ts":"2026-08-23T17:54:03.602Z","event_type":"price_change","market_id":"3790415","outcome_index":0,"market_type":"set2","local_side":"home","local_uid":"2026-08-23_pierre_hugues_herbert_quinn_vandecasteele","bid":0.0,"ask":0.66,"mid":0.33,"spread":0.66,"price":0.56,"size":0.0,"side":"BUY"}
{"ts":"2026-08-23T17:54:03.602Z","event_type":"price_change","market_id":"3790415","outcome_index":1,"market_type":"set2","local_side":"away","local_uid":"2026-08-23_pierre_hugues_herbert_quinn_vandecasteele","bid":0.34,"ask":1.0,"mid":0.67,"spread":0.66,"price":0.44,"size":0.0,"side":"SELL"}
{"ts":"2026-08-23T17:54:03.615Z","event_type":"best_bid_ask","market_id":"3790397","outcome_index":0,"market_type":"set2","local_side":"home","local_uid":"2026-08-23_hugo_grenier_mees_rottgering","bid":0.31,"ask":0.41,"mid":0.36,"spread":0.1,"bid_size":null,"ask_size":null}
{"ts":"2026-08-23T17:54:03.615Z","event_type":"best_bid_ask","market_id":"3790397","outcome_index":1,"market_type":"set2","local_side":"away","local_uid":"2026-08-23_hugo_grenier_mees_rottgering","bid":0.59,"ask":0.69,"mid":0.64,"spread":0.1,"bid_size":null,"ask_size":null}
{"ts":"2026-08-23T17:54:03.615Z","event_type":"price_change","market_id":"3790397","outcome_index":1,"market_type":"set2","local_side":"away","local_uid":"2026-08-23_hugo_grenier_mees_rottgering","bid":0.59,"ask":0.69,"mid":0.64,"spread":0.1,"price":0.61,"size":0.0,"side":"BUY"}
{"ts":"2026-08-23T17:54:03.615Z","event_type":"price_change","market_id":"3790397","outcome_index":0,"market_type":"set2","local_side":"home","local_uid":"2026-08-23_hugo_grenier_mees_rottgering","bid":0.31,"ask":0.41,"mid":0.36,"spread":0.1,"price":0.39,"size":0.0,"side":"SELL"}
{"ts":"2026-08-23T17:54:03.617Z","event_type":"best_bid_ask","market_id":"3790397","outcome_index":0,"market_type":"set2","local_side":"home","local_uid":"2026-08-23_hugo_grenier_mees_rottgering","bid":0.31,"ask":1.0,"mid":0.655,"spread":0.69,"bid_size":null,"ask_size":null}
{"ts":"2026-08-23T17:54:03.618Z","event_type":"best_bid_ask","market_id":"3790397","outcome_index":1,"market_type":"set2","local_side":"away","local_uid":"2026-08-23_hugo_grenier_mees_rottgering","bid":0.0,"ask":0.69,"mid":0.345,"spread":0.69,"bid_size":null,"ask_size":null}
{"ts":"2026-08-23T17:54:03.618Z","event_type":"price_change","market_id":"3790397","outcome_index":1,"market_type":"set2","local_side":"away","local_uid":"2026-08-23_hugo_grenier_mees_rottgering","bid":0.0,"ask":0.69,"mid":0.345,"spread":0.69,"price":0.59,"size":0.0,"side":"BUY"}
{"ts":"2026-08-23T17:54:03.618Z","event_type":"price_change","market_id":"3790397","outcome_index":0,"market_type":"set2","local_side":"home","local_uid":"2026-08-23_hugo_grenier_mees_rottgering","bid":0.31,"ask":1.0,"mid":0.655,"spread":0.69,"price":0.41,"size":0.0,"side":"SELL"}
{"ts":"2026-08-23T17:54:03.618Z","event_type":"best_bid_ask","market_id":"3790397","outcome_index":0,"market_type":"set2","local_side":"home","local_uid":"2026-08-23_hugo_grenier_mees_rottgering","bid":0.0,"ask":1.0,"mid":0.5,"spread":1.0,"bid_size":null,"ask_size":null}
{"ts":"2026-08-23T17:54:03.618Z","event_type":"best_bid_ask","market_id":"3790397","outcome_index":1,"market_type":"set2","local_side":"away","local_uid":"2026-08-23_hugo_grenier_mees_rottgering","bid":0.0,"ask":1.0,"mid":0.5,"spread":1.0,"bid_size":null,"ask_size":null}
{"ts":"2026-08-23T17:54:03.618Z","event_type":"price_change","market_id":"3790397","outcome_index":0,"market_type":"set2","local_side":"home","local_uid":"2026-08-23_hugo_grenier_mees_rottgering","bid":0.0,"ask":1.0,"mid":0.5,"spread":1.0,"price":0.31,"size":0.0,"side":"BUY"}
{"ts":"2026-08-23T17:54:03.618Z","event_type":"price_change","market_id":"3790397","outcome_index":1,"market_type":"set2","local_side":"away","local_uid":"2026-08-23_hugo_grenier_mees_rottgering","bid":0.0,"ask":1.0,"mid":0.5,"spread":1.0,"price":0.69,"size":0.0,"side":"SELL"}
{"ts":"2026-08-23T17:54:03.628Z","event_type":"best_bid_ask","market_id":"3790323","outcome_index":0,"market_type":"set2","local_side":"home","local_uid":"2026-08-23_felix_balshaw_sebastian_gorzny","bid":0.62,"ask":0.72,"mid":0.67,"spread":0.1,"bid_size":null,"ask_size":null}
{"ts":"2026-08-23T17:54:03.629Z","event_type":"best_bid_ask","market_id":"3790323","outcome_index":1,"market_type":"set2","local_side":"away","local_uid":"2026-08-23_felix_balshaw_sebastian_gorzny","bid":0.28,"ask":0.38,"mid":0.33,"spread":0.1,"bid_size":null,"ask_size":null}
{"ts":"2026-08-23T17:54:03.629Z","event_type":"price_change","market_id":"3790323","outcome_index":0,"market_type":"set2","local_side":"home","local_uid":"2026-08-23_felix_balshaw_sebastian_gorzny","bid":0.62,"ask":0.72,"mid":0.67,"spread":0.1,"price":0.63,"size":0.0,"side":"BUY"}
{"ts":"2026-08-23T17:54:03.629Z","event_type":"price_change","market_id":"3790323","outcome_index":1,"market_type":"set2","local_side":"away","local_uid":"2026-08-23_felix_balshaw_sebastian_gorzny","bid":0.28,"ask":0.38,"mid":0.33,"spread":0.1,"price":0.37,"size":0.0,"side":"SELL"}
{"ts":"2026-08-23T17:54:03.629Z","event_type":"best_bid_ask","market_id":"3790323","outcome_index":0,"market_type":"set2","local_side":"home","local_uid":"2026-08-23_felix_balshaw_sebastian_gorzny","bid":0.0,"ask":0.72,"mid":0.36,"spread":0.72,"bid_size":null,"ask_size":null}
{"ts":"2026-08-23T17:54:03.629Z","event_type":"best_bid_ask","market_id":"3790323","outcome_index":1,"market_type":"set2","local_side":"away","local_uid":"2026-08-23_felix_balshaw_sebastian_gorzny","bid":0.28,"ask":1.0,"mid":0.64,"spread":0.72,"bid_size":null,"ask_size":null}
{"ts":"2026-08-23T17:54:03.629Z","event_type":"price_change","market_id":"3790323","outcome_index":0,"market_type":"set2","local_side":"home","local_uid":"2026-08-23_felix_balshaw_sebastian_gorzny","bid":0.0,"ask":0.72,"mid":0.36,"spread":0.72,"price":0.62,"size":0.0,"side":"BUY"}
{"ts":"2026-08-23T17:54:03.629Z","event_type":"price_change","market_id":"3790323","outcome_index":1,"market_type":"set2","local_side":"away","local_uid":"2026-08-23_felix_balshaw_sebastian_gorzny","bid":0.28,"ask":1.0,"mid":0.64,"spread":0.72,"price":0.38,"size":0.0,"side":"SELL"}
{"ts":"2026-08-23T17:54:03.629Z","event_type":"best_bid_ask","market_id":"3790323","outcome_index":0,"market_type":"set2","local_side":"home","local_uid":"2026-08-23_felix_balshaw_sebastian_gorzny","bid":0.0,"ask":1.0,"mid":0.5,"spread":1.0,"bid_size":null,"ask_size":null}
{"ts":"2026-08-23T17:54:03.629Z","event_type":"best_bid_ask","market_id":"3790323","outcome_index":1,"market_type":"set2","local_side":"away","local_uid":"2026-08-23_felix_balshaw_sebastian_gorzny","bid":0.0,"ask":1.0,"mid":0.5,"spread":1.0,"bid_size":null,"ask_size":null}
{"ts":"2026-08-23T17:54:03.629Z","event_type":"price_change","market_id":"3790323","outcome_index":1,"market_type":"set2","local_side":"away","local_uid":"2026-08-23_felix_balshaw_sebastian_gorzny","bid":0.0,"ask":1.0,"mid":0.5,"spread":1.0,"price":0.28,"size":0.0,"side":"BUY"}
{"ts":"2026-08-23T17:54:03.630Z","event_type":"price_change","market_id":"3790323","outcome_index":0,"market_type":"set2","local_side":"home","local_uid":"2026-08-23_felix_balshaw_sebastian_gorzny","bid":0.0,"ask":1.0,"mid":0.5,"spread":1.0,"price":0.72,"size":0.0,"side":"SELL"}
{"ts":"2026-08-23T17:54:03.633Z","event_type":"best_bid_ask","market_id":"3789927","outcome_index":0,"market_type":"match","local_side":"home","local_uid":"2026-08-23_hugo_grenier_mees_rottgering","bid":0.27,"ask":0.28,"mid":0.275,"spread":0.01,"bid_size":null,"ask_size":null}
{"ts":"2026-08-23T17:54:03.634Z","event_type":"best_bid_ask","market_id":"3789927","outcome_index":1,"market_type":"match","local_side":"away","local_uid":"2026-08-23_hugo_grenier_mees_rottgering","bid":0.72,"ask":0.73,"mid":0.725,"spread":0.01,"bid_size":null,"ask_size":null}
{"ts":"2026-08-23T17:54:03.634Z","event_type":"price_change","market_id":"3789927","outcome_index":0,"market_type":"match","local_side":"home","local_uid":"2026-08-23_hugo_grenier_mees_rottgering","bid":0.27,"ask":0.28,"mid":0.275,"spread":0.01,"price":0.27,"size":449.05,"side":"BUY"}
{"ts":"2026-08-23T17:54:03.634Z","event_type":"price_change","market_id":"3789927","outcome_index":1,"market_type":"match","local_side":"away","local_uid":"2026-08-23_hugo_grenier_mees_rottgering","bid":0.72,"ask":0.73,"mid":0.725,"spread":0.01,"price":0.73,"size":449.05,"side":"SELL"}
{"ts":"2026-08-23T17:54:03.708Z","event_type":"best_bid_ask","market_id":"3790415","outcome_index":0,"market_type":"set2","local_side":"home","local_uid":"2026-08-23_pierre_hugues_herbert_quinn_vandecasteele","bid":0.56,"ask":0.66,"mid":0.61,"spread":0.1,"bid_size":null,"ask_size":null}
{"ts":"2026-08-23T17:54:03.708Z","event_type":"best_bid_ask","market_id":"3790415","outcome_index":1,"market_type":"set2","local_side":"away","local_uid":"2026-08-23_pierre_hugues_herbert_quinn_vandecasteele","bid":0.34,"ask":0.44,"mid":0.39,"spread":0.1,"bid_size":null,"ask_size":null}
{"ts":"2026-08-23T17:54:03.709Z","event_type":"price_change","market_id":"3790415","outcome_index":0,"market_type":"set2","local_side":"home","local_uid":"2026-08-23_pierre_hugues_herbert_quinn_vandecasteele","bid":0.56,"ask":0.66,"mid":0.61,"spread":0.1,"price":0.56,"size":88.0,"side":"BUY"}
{"ts":"2026-08-23T17:54:03.709Z","event_type":"price_change","market_id":"3790415","outcome_index":1,"market_type":"set2","local_side":"away","local_uid":"2026-08-23_pierre_hugues_herbert_quinn_vandecasteele","bid":0.34,"ask":0.44,"mid":0.39,"spread":0.1,"price":0.44,"size":88.0,"side":"SELL"}
{"ts":"2026-08-23T17:54:03.709Z","event_type":"best_bid_ask","market_id":"3790415","outcome_index":0,"market_type":"set2","local_side":"home","local_uid":"2026-08-23_pierre_hugues_herbert_quinn_vandecasteele","bid":0.57,"ask":0.66,"mid":0.615,"spread":0.09,"bid_size":null,"ask_size":null}
{"ts":"2026-08-23T17:54:03.709Z","event_type":"best_bid_ask","market_id":"3790415","outcome_index":1,"market_type":"set2","local_side":"away","local_uid":"2026-08-23_pierre_hugues_herbert_quinn_vandecasteele","bid":0.34,"ask":0.43,"mid":0.385,"spread":0.09,"bid_size":null,"ask_size":null}
{"ts":"2026-08-23T17:54:03.709Z","event_type":"price_change","market_id":"3790415","outcome_index":0,"market_type":"set2","local_side":"home","local_uid":"2026-08-23_pierre_hugues_herbert_quinn_vandecasteele","bid":0.57,"ask":0.66,"mid":0.615,"spread":0.09,"price":0.57,"size":150.0,"side":"BUY"}
{"ts":"2026-08-23T17:54:03.709Z","event_type":"price_change","market_id":"3790415","outcome_index":1,"market_type":"set2","local_side":"away","local_uid":"2026-08-23_pierre_hugues_herbert_quinn_vandecasteele","bid":0.34,"ask":0.43,"mid":0.385,"spread":0.09,"price":0.43,"size":150.0,"side":"SELL"}
{"ts":"2026-08-23T17:54:03.710Z","event_type":"best_bid_ask","market_id":"3790323","outcome_index":0,"market_type":"set2","local_side":"home","local_uid":"2026-08-23_felix_balshaw_sebastian_gorzny","bid":0.0,"ask":0.74,"mid":0.37,"spread":0.74,"bid_size":null,"ask_size":null}
{"ts":"2026-08-23T17:54:03.710Z","event_type":"best_bid_ask","market_id":"3790323","outcome_index":1,"market_type":"set2","local_side":"away","local_uid":"2026-08-23_felix_balshaw_sebastian_gorzny","bid":0.26,"ask":1.0,"mid":0.63,"spread":0.74,"bid_size":null,"ask_size":null}
{"ts":"2026-08-23T17:54:03.716Z","event_type":"price_change","market_id":"3790323","outcome_index":1,"market_type":"set2","local_side":"away","local_uid":"2026-08-23_felix_balshaw_sebastian_gorzny","bid":0.26,"ask":1.0,"mid":0.63,"spread":0.74,"price":0.26,"size":22.0,"side":"BUY"}
{"ts":"2026-08-23T17:54:03.716Z","event_type":"price_change","market_id":"3790323","outcome_index":0,"market_type":"set2","local_side":"home","local_uid":"2026-08-23_felix_balshaw_sebastian_gorzny","bid":0.0,"ask":0.74,"mid":0.37,"spread":0.74,"price":0.74,"size":22.0,"side":"SELL"}
{"ts":"2026-08-23T17:54:03.717Z","event_type":"best_bid_ask","market_id":"3790323","outcome_index":0,"market_type":"set2","local_side":"home","local_uid":"2026-08-23_felix_balshaw_sebastian_gorzny","bid":0.62,"ask":0.74,"mid":0.68,"spread":0.12,"bid_size":null,"ask_size":null}
{"ts":"2026-08-23T17:54:03.717Z","event_type":"best_bid_ask","market_id":"3790323","outcome_index":1,"market_type":"set2","local_side":"away","local_uid":"2026-08-23_felix_balshaw_sebastian_gorzny","bid":0.26,"ask":0.38,"mid":0.32,"spread":0.12,"bid_size":null,"ask_size":null}
{"ts":"2026-08-23T17:54:03.717Z","event_type":"best_bid_ask","market_id":"3790394","outcome_index":0,"market_type":"set1","local_side":"home","local_uid":"2026-08-23_hugo_grenier_mees_rottgering","bid":0.25,"ask":0.33,"mid":0.29,"spread":0.08,"bid_size":null,"ask_size":null}
{"ts":"2026-08-23T17:54:03.717Z","event_type":"best_bid_ask","market_id":"3790394","outcome_index":1,"market_type":"set1","local_side":"away","local_uid":"2026-08-23_hugo_grenier_mees_rottgering","bid":0.67,"ask":0.75,"mid":0.71,"spread":0.08,"bid_size":null,"ask_size":null}
{"ts":"2026-08-23T17:54:03.717Z","event_type":"price_change","market_id":"3790394","outcome_index":0,"market_type":"set1","local_side":"home","local_uid":"2026-08-23_hugo_grenier_mees_rottgering","bid":0.25,"ask":0.33,"mid":0.29,"spread":0.08,"price":0.26,"size":0.0,"side":"BUY"}
{"ts":"2026-08-23T17:54:03.717Z","event_type":"price_change","market_id":"3790394","outcome_index":1,"market_type":"set1","local_side":"away","local_uid":"2026-08-23_hugo_grenier_mees_rottgering","bid":0.67,"ask":0.75,"mid":0.71,"spread":0.08,"price":0.74,"size":0.0,"side":"SELL"}
{"ts":"2026-08-23T17:54:03.717Z","event_type":"price_change","market_id":"3790323","outcome_index":0,"market_type":"set2","local_side":"home","local_uid":"2026-08-23_felix_balshaw_sebastian_gorzny","bid":0.62,"ask":0.74,"mid":0.68,"spread":0.12,"price":0.62,"size":44.0,"side":"BUY"}
{"ts":"2026-08-23T17:54:03.717Z","event_type":"price_change","market_id":"3790323","outcome_index":1,"market_type":"set2","local_side":"away","local_uid":"2026-08-23_felix_balshaw_sebastian_gorzny","bid":0.26,"ask":0.38,"mid":0.32,"spread":0.12,"price":0.38,"size":44.0,"side":"SELL"}
{"ts":"2026-08-23T17:54:03.723Z","event_type":"best_bid_ask","market_id":"3790394","outcome_index":0,"market_type":"set1","local_side":"home","local_uid":"2026-08-23_hugo_grenier_mees_rottgering","bid":0.25,"ask":0.34,"mid":0.295,"spread":0.09,"bid_size":null,"ask_size":null}
{"ts":"2026-08-23T17:54:03.723Z","event_type":"best_bid_ask","market_id":"3790394","outcome_index":1,"market_type":"set1","local_side":"away","local_uid":"2026-08-23_hugo_grenier_mees_rottgering","bid":0.66,"ask":0.75,"mid":0.705,"spread":0.09,"bid_size":null,"ask_size":null}
{"ts":"2026-08-23T17:54:03.723Z","event_type":"price_change","market_id":"3790394","outcome_index":1,"market_type":"set1","local_side":"away","local_uid":"2026-08-23_hugo_grenier_mees_rottgering","bid":0.66,"ask":0.75,"mid":0.705,"spread":0.09,"price":0.67,"size":0.0,"side":"BUY"}
{"ts":"2026-08-23T17:54:03.723Z","event_type":"price_change","market_id":"3790394","outcome_index":0,"market_type":"set1","local_side":"home","local_uid":"2026-08-23_hugo_grenier_mees_rottgering","bid":0.25,"ask":0.34,"mid":0.295,"spread":0.09,"price":0.33,"size":0.0,"side":"SELL"}
{"ts":"2026-08-23T17:54:03.723Z","event_type":"best_bid_ask","market_id":"3790394","outcome_index":0,"market_type":"set1","local_side":"home","local_uid":"2026-08-23_hugo_grenier_mees_rottgering","bid":0.0,"ask":0.34,"mid":0.17,"spread":0.34,"bid_size":null,"ask_size":null}
{"ts":"2026-08-23T17:54:03.723Z","event_type":"best_bid_ask","market_id":"3790394","outcome_index":1,"market_type":"set1","local_side":"away","local_uid":"2026-08-23_hugo_grenier_mees_rottgering","bid":0.66,"ask":1.0,"mid":0.83,"spread":0.34,"bid_size":null,"ask_size":null}
{"ts":"2026-08-23T17:54:03.723Z","event_type":"price_change","market_id":"3790394","outcome_index":0,"market_type":"set1","local_side":"home","local_uid":"2026-08-23_hugo_grenier_mees_rottgering","bid":0.0,"ask":0.34,"mid":0.17,"spread":0.34,"price":0.25,"size":0.0,"side":"BUY"}
{"ts":"2026-08-23T17:54:03.723Z","event_type":"price_change","market_id":"3790394","outcome_index":1,"market_type":"set1","local_side":"away","local_uid":"2026-08-23_hugo_grenier_mees_rottgering","bid":0.66,"ask":1.0,"mid":0.83,"spread":0.34,"price":0.75,"size":0.0,"side":"SELL"}
{"ts":"2026-08-23T17:54:03.723Z","event_type":"best_bid_ask","market_id":"3790394","outcome_index":0,"market_type":"set1","local_side":"home","local_uid":"2026-08-23_hugo_grenier_mees_rottgering","bid":0.0,"ask":0.77,"mid":0.385,"spread":0.77,"bid_size":null,"ask_size":null}
{"ts":"2026-08-23T17:54:03.723Z","event_type":"best_bid_ask","market_id":"3790394","outcome_index":1,"market_type":"set1","local_side":"away","local_uid":"2026-08-23_hugo_grenier_mees_rottgering","bid":0.23,"ask":1.0,"mid":0.615,"spread":0.77,"bid_size":null,"ask_size":null}
{"ts":"2026-08-23T17:54:03.724Z","event_type":"price_change","market_id":"3790394","outcome_index":1,"market_type":"set1","local_side":"away","local_uid":"2026-08-23_hugo_grenier_mees_rottgering","bid":0.23,"ask":1.0,"mid":0.615,"spread":0.77,"price":0.66,"size":0.0,"side":"BUY"}
{"ts":"2026-08-23T17:54:03.724Z","event_type":"price_change","market_id":"3790394","outcome_index":0,"market_type":"set1","local_side":"home","local_uid":"2026-08-23_hugo_grenier_mees_rottgering","bid":0.0,"ask":0.77,"mid":0.385,"spread":0.77,"price":0.34,"size":0.0,"side":"SELL"}
{"ts":"2026-08-23T17:54:03.724Z","event_type":"best_bid_ask","market_id":"3790394","outcome_index":0,"market_type":"set1","local_side":"home","local_uid":"2026-08-23_hugo_grenier_mees_rottgering","bid":0.25,"ask":0.77,"mid":0.51,"spread":0.52,"bid_size":null,"ask_size":null}
{"ts":"2026-08-23T17:54:03.724Z","event_type":"best_bid_ask","market_id":"3790394","outcome_index":1,"market_type":"set1","local_side":"away","local_uid":"2026-08-23_hugo_grenier_mees_rottgering","bid":0.23,"ask":0.75,"mid":0.49,"spread":0.52,"bid_size":null,"ask_size":null}
{"ts":"2026-08-23T17:54:03.724Z","event_type":"price_change","market_id":"3790394","outcome_index":0,"market_type":"set1","local_side":"home","local_uid":"2026-08-23_hugo_grenier_mees_rottgering","bid":0.25,"ask":0.77,"mid":0.51,"spread":0.52,"price":0.25,"size":11.0,"side":"BUY"}
{"ts":"2026-08-23T17:54:03.724Z","event_type":"price_change","market_id":"3790394","outcome_index":1,"market_type":"set1","local_side":"away","local_uid":"2026-08-23_hugo_grenier_mees_rottgering","bid":0.23,"ask":0.75,"mid":0.49,"spread":0.52,"price":0.75,"size":11.0,"side":"SELL"}
{"ts":"2026-08-23T17:54:03.724Z","event_type":"best_bid_ask","market_id":"3790394","outcome_index":0,"market_type":"set1","local_side":"home","local_uid":"2026-08-23_hugo_grenier_mees_rottgering","bid":0.25,"ask":0.35,"mid":0.3,"spread":0.1,"bid_size":null,"ask_size":null}
{"ts":"2026-08-23T17:54:03.724Z","event_type":"best_bid_ask","market_id":"3790394","outcome_index":1,"market_type":"set1","local_side":"away","local_uid":"2026-08-23_hugo_grenier_mees_rottgering","bid":0.65,"ask":0.75,"mid":0.7,"spread":0.1,"bid_size":null,"ask_size":null}
{"ts":"2026-08-23T17:54:03.724Z","event_type":"price_change","market_id":"3790394","outcome_index":1,"market_type":"set1","local_side":"away","local_uid":"2026-08-23_hugo_grenier_mees_rottgering","bid":0.65,"ask":0.75,"mid":0.7,"spread":0.1,"price":0.65,"size":88.0,"side":"BUY"}
{"ts":"2026-08-23T17:54:03.724Z","event_type":"price_change","market_id":"3790394","outcome_index":0,"market_type":"set1","local_side":"home","local_uid":"2026-08-23_hugo_grenier_mees_rottgering","bid":0.25,"ask":0.35,"mid":0.3,"spread":0.1,"price":0.35,"size":88.0,"side":"SELL"}
{"ts":"2026-08-23T17:54:03.727Z","event_type":"best_bid_ask","market_id":"3790397","outcome_index":0,"market_type":"set2","local_side":"home","local_uid":"2026-08-23_hugo_grenier_mees_rottgering","bid":0.0,"ask":0.42,"mid":0.21,"spread":0.42,"bid_size":null,"ask_size":null}
{"ts":"2026-08-23T17:54:03.727Z","event_type":"best_bid_ask","market_id":"3790397","outcome_index":1,"market_type":"set2","local_side":"away","local_uid":"2026-08-23_hugo_grenier_mees_rottgering","bid":0.58,"ask":1.0,"mid":0.79,"spread":0.42,"bid_size":null,"ask_size":null}
{"ts":"2026-08-23T17:54:03.727Z","event_type":"price_change","market_id":"3790397","outcome_index":1,"market_type":"set2","local_side":"away","local_uid":"2026-08-23_hugo_grenier_mees_rottgering","bid":0.58,"ask":1.0,"mid":0.79,"spread":0.42,"price":0.58,"size":211.0,"side":"BUY"}
{"ts":"2026-08-23T17:54:03.727Z","event_type":"price_change","market_id":"3790397","outcome_index":0,"market_type":"set2","local_side":"home","local_uid":"2026-08-23_hugo_grenier_mees_rottgering","bid":0.0,"ask":0.42,"mid":0.21,"spread":0.42,"price":0.42,"size":211.0,"side":"SELL"}
{"ts":"2026-08-23T17:54:03.727Z","event_type":"best_bid_ask","market_id":"3790397","outcome_index":0,"market_type":"set2","local_side":"home","local_uid":"2026-08-23_hugo_grenier_mees_rottgering","bid":0.0,"ask":0.41,"mid":0.205,"spread":0.41,"bid_size":null,"ask_size":null}
{"ts":"2026-08-23T17:54:03.727Z","event_type":"best_bid_ask","market_id":"3790397","outcome_index":1,"market_type":"set2","local_side":"away","local_uid":"2026-08-23_hugo_grenier_mees_rottgering","bid":0.59,"ask":1.0,"mid":0.795,"spread":0.41,"bid_size":null,"ask_size":null}
{"ts":"2026-08-23T17:54:03.727Z","event_type":"price_change","market_id":"3790397","outcome_index":1,"market_type":"set2","local_side":"away","local_uid":"2026-08-23_hugo_grenier_mees_rottgering","bid":0.59,"ask":1.0,"mid":0.795,"spread":0.41,"price":0.59,"size":22.0,"side":"BUY"}
{"ts":"2026-08-23T17:54:03.727Z","event_type":"price_change","market_id":"3790397","outcome_index":0,"market_type":"set2","local_side":"home","local_uid":"2026-08-23_hugo_grenier_mees_rottgering","bid":0.0,"ask":0.41,"mid":0.205,"spread":0.41,"price":0.41,"size":22.0,"side":"SELL"}
{"ts":"2026-08-23T17:54:03.735Z","event_type":"best_bid_ask","market_id":"3790394","outcome_index":0,"market_type":"set1","local_side":"home","local_uid":"2026-08-23_hugo_grenier_mees_rottgering","bid":0.25,"ask":0.34,"mid":0.295,"spread":0.09,"bid_size":null,"ask_size":null}
{"ts":"2026-08-23T17:54:03.735Z","event_type":"best_bid_ask","market_id":"3790394","outcome_index":1,"market_type":"set1","local_side":"away","local_uid":"2026-08-23_hugo_grenier_mees_rottgering","bid":0.66,"ask":0.75,"mid":0.705,"spread":0.09,"bid_size":null,"ask_size":null}
{"ts":"2026-08-23T17:54:03.735Z","event_type":"best_bid_ask","market_id":"3790323","outcome_index":0,"market_type":"set2","local_side":"home","local_uid":"2026-08-23_felix_balshaw_sebastian_gorzny","bid":0.62,"ask":0.75,"mid":0.685,"spread":0.13,"bid_size":null,"ask_size":null}
{"ts":"2026-08-23T17:54:03.735Z","event_type":"best_bid_ask","market_id":"3790323","outcome_index":1,"market_type":"set2","local_side":"away","local_uid":"2026-08-23_felix_balshaw_sebastian_gorzny","bid":0.25,"ask":0.38,"mid":0.315,"spread":0.13,"bid_size":null,"ask_size":null}
{"ts":"2026-08-23T17:54:03.735Z","event_type":"price_change","market_id":"3790394","outcome_index":1,"market_type":"set1","local_side":"away","local_uid":"2026-08-23_hugo_grenier_mees_rottgering","bid":0.66,"ask":0.75,"mid":0.705,"spread":0.09,"price":0.66,"size":11.0,"side":"BUY"}
{"ts":"2026-08-23T17:54:03.735Z","event_type":"price_change","market_id":"3790394","outcome_index":0,"market_type":"set1","local_side":"home","local_uid":"2026-08-23_hugo_grenier_mees_rottgering","bid":0.25,"ask":0.34,"mid":0.295,"spread":0.09,"price":0.34,"size":11.0,"side":"SELL"}
{"ts":"2026-08-23T17:54:03.735Z","event_type":"price_change","market_id":"3790323","outcome_index":1,"market_type":"set2","local_side":"away","local_uid":"2026-08-23_felix_balshaw_sebastian_gorzny","bid":0.25,"ask":0.38,"mid":0.315,"spread":0.13,"price":0.26,"size":0.0,"side":"BUY"}
{"ts":"2026-08-23T17:54:03.735Z","event_type":"price_change","market_id":"3790323","outcome_index":0,"market_type":"set2","local_side":"home","local_uid":"2026-08-23_felix_balshaw_sebastian_gorzny","bid":0.62,"ask":0.75,"mid":0.685,"spread":0.13,"price":0.74,"size":0.0,"side":"SELL"}
{"ts":"2026-08-23T17:54:03.735Z","event_type":"best_bid_ask","market_id":"3790323","outcome_index":0,"market_type":"set2","local_side":"home","local_uid":"2026-08-23_felix_balshaw_sebastian_gorzny","bid":0.61,"ask":0.75,"mid":0.68,"spread":0.14,"bid_size":null,"ask_size":null}
{"ts":"2026-08-23T17:54:03.736Z","event_type":"best_bid_ask","market_id":"3790323","outcome_index":1,"market_type":"set2","local_side":"away","local_uid":"2026-08-23_felix_balshaw_sebastian_gorzny","bid":0.25,"ask":0.39,"mid":0.32,"spread":0.14,"bid_size":null,"ask_size":null}
{"ts":"2026-08-23T17:54:03.736Z","event_type":"price_change","market_id":"3790323","outcome_index":0,"market_type":"set2","local_side":"home","local_uid":"2026-08-23_felix_balshaw_sebastian_gorzny","bid":0.61,"ask":0.75,"mid":0.68,"spread":0.14,"price":0.62,"size":0.0,"side":"BUY"}
{"ts":"2026-08-23T17:54:03.736Z","event_type":"price_change","market_id":"3790323","outcome_index":1,"market_type":"set2","local_side":"away","local_uid":"2026-08-23_felix_balshaw_sebastian_gorzny","bid":0.25,"ask":0.39,"mid":0.32,"spread":0.14,"price":0.38,"size":0.0,"side":"SELL"}
{"ts":"2026-08-23T17:54:03.737Z","event_type":"best_bid_ask","market_id":"3790323","outcome_index":0,"market_type":"set2","local_side":"home","local_uid":"2026-08-23_felix_balshaw_sebastian_gorzny","bid":0.0,"ask":0.75,"mid":0.375,"spread":0.75,"bid_size":null,"ask_size":null}
{"ts":"2026-08-23T17:54:03.737Z","event_type":"best_bid_ask","market_id":"3790323","outcome_index":1,"market_type":"set2","local_side":"away","local_uid":"2026-08-23_felix_balshaw_sebastian_gorzny","bid":0.25,"ask":1.0,"mid":0.625,"spread":0.75,"bid_size":null,"ask_size":null}
{"ts":"2026-08-23T17:54:03.737Z","event_type":"price_change","market_id":"3790323","outcome_index":0,"market_type":"set2","local_side":"home","local_uid":"2026-08-23_felix_balshaw_sebastian_gorzny","bid":0.0,"ask":0.75,"mid":0.375,"spread":0.75,"price":0.61,"size":0.0,"side":"BUY"}
{"ts":"2026-08-23T17:54:03.737Z","event_type":"price_change","market_id":"3790323","outcome_index":1,"market_type":"set2","local_side":"away","local_uid":"2026-08-23_felix_balshaw_sebastian_gorzny","bid":0.25,"ask":1.0,"mid":0.625,"spread":0.75,"price":0.39,"size":0.0,"side":"SELL"}
{"ts":"2026-08-23T17:54:03.738Z","event_type":"best_bid_ask","market_id":"3790323","outcome_index":0,"market_type":"set2","local_side":"home","local_uid":"2026-08-23_felix_balshaw_sebastian_gorzny","bid":0.0,"ask":1.0,"mid":0.5,"spread":1.0,"bid_size":null,"ask_size":null}
{"ts":"2026-08-23T17:54:03.738Z","event_type":"best_bid_ask","market_id":"3790323","outcome_index":1,"market_type":"set2","local_side":"away","local_uid":"2026-08-23_felix_balshaw_sebastian_gorzny","bid":0.0,"ask":1.0,"mid":0.5,"spread":1.0,"bid_size":null,"ask_size":null}
{"ts":"2026-08-23T17:54:03.738Z","event_type":"price_change","market_id":"3790323","outcome_index":1,"market_type":"set2","local_side":"away","local_uid":"2026-08-23_felix_balshaw_sebastian_gorzny","bid":0.0,"ask":1.0,"mid":0.5,"spread":1.0,"price":0.25,"size":0.0,"side":"BUY"}
{"ts":"2026-08-23T17:54:03.739Z","event_type":"price_change","market_id":"3790323","outcome_index":0,"market_type":"set2","local_side":"home","local_uid":"2026-08-23_felix_balshaw_sebastian_gorzny","bid":0.0,"ask":1.0,"mid":0.5,"spread":1.0,"price":0.75,"size":0.0,"side":"SELL"}
{"ts":"2026-08-23T17:54:03.739Z","event_type":"best_bid_ask","market_id":"3790394","outcome_index":0,"market_type":"set1","local_side":"home","local_uid":"2026-08-23_hugo_grenier_mees_rottgering","bid":0.25,"ask":0.35,"mid":0.3,"spread":0.1,"bid_size":null,"ask_size":null}
{"ts":"2026-08-23T17:54:03.739Z","event_type":"best_bid_ask","market_id":"3790394","outcome_index":1,"market_type":"set1","local_side":"away","local_uid":"2026-08-23_hugo_grenier_mees_rottgering","bid":0.65,"ask":0.75,"mid":0.7,"spread":0.1,"bid_size":null,"ask_size":null}
{"ts":"2026-08-23T17:54:03.739Z","event_type":"price_change","market_id":"3790394","outcome_index":1,"market_type":"set1","local_side":"away","local_uid":"2026-08-23_hugo_grenier_mees_rottgering","bid":0.65,"ask":0.75,"mid":0.7,"spread":0.1,"price":0.66,"size":0.0,"side":"BUY"}
{"ts":"2026-08-23T17:54:03.739Z","event_type":"price_change","market_id":"3790394","outcome_index":0,"market_type":"set1","local_side":"home","local_uid":"2026-08-23_hugo_grenier_mees_rottgering","bid":0.25,"ask":0.35,"mid":0.3,"spread":0.1,"price":0.34,"size":0.0,"side":"SELL"}
{"ts":"2026-08-23T17:54:03.739Z","event_type":"best_bid_ask","market_id":"3790397","outcome_index":0,"market_type":"set2","local_side":"home","local_uid":"2026-08-23_hugo_grenier_mees_rottgering","bid":0.0,"ask":0.42,"mid":0.21,"spread":0.42,"bid_size":null,"ask_size":null}
{"ts":"2026-08-23T17:54:03.739Z","event_type":"best_bid_ask","market_id":"3790397","outcome_index":1,"market_type":"set2","local_side":"away","local_uid":"2026-08-23_hugo_grenier_mees_rottgering","bid":0.58,"ask":1.0,"mid":0.79,"spread":0.42,"bid_size":null,"ask_size":null}
{"ts":"2026-08-23T17:54:03.739Z","event_type":"price_change","market_id":"3790397","outcome_index":1,"market_type":"set2","local_side":"away","local_uid":"2026-08-23_hugo_grenier_mees_rottgering","bid":0.58,"ask":1.0,"mid":0.79,"spread":0.42,"price":0.59,"size":0.0,"side":"BUY"}
{"ts":"2026-08-23T17:54:03.739Z","event_type":"price_change","market_id":"3790397","outcome_index":0,"market_type":"set2","local_side":"home","local_uid":"2026-08-23_hugo_grenier_mees_rottgering","bid":0.0,"ask":0.42,"mid":0.21,"spread":0.42,"price":0.41,"size":0.0,"side":"SELL"}
{"ts":"2026-08-23T17:54:03.739Z","event_type":"best_bid_ask","market_id":"3790394","outcome_index":0,"market_type":"set1","local_side":"home","local_uid":"2026-08-23_hugo_grenier_mees_rottgering","bid":0.25,"ask":0.36,"mid":0.305,"spread":0.11,"bid_size":null,"ask_size":null}
{"ts":"2026-08-23T17:54:03.740Z","event_type":"best_bid_ask","market_id":"3790394","outcome_index":1,"market_type":"set1","local_side":"away","local_uid":"2026-08-23_hugo_grenier_mees_rottgering","bid":0.64,"ask":0.75,"mid":0.695,"spread":0.11,"bid_size":null,"ask_size":null}
{"ts":"2026-08-23T17:54:03.740Z","event_type":"price_change","market_id":"3790394","outcome_index":1,"market_type":"set1","local_side":"away","local_uid":"2026-08-23_hugo_grenier_mees_rottgering","bid":0.64,"ask":0.75,"mid":0.695,"spread":0.11,"price":0.65,"size":0.0,"side":"BUY"}
{"ts":"2026-08-23T17:54:03.740Z","event_type":"price_change","market_id":"3790394","outcome_index":0,"market_type":"set1","local_side":"home","local_uid":"2026-08-23_hugo_grenier_mees_rottgering","bid":0.25,"ask":0.36,"mid":0.305,"spread":0.11,"price":0.35,"size":0.0,"side":"SELL"}
{"ts":"2026-08-23T17:54:03.741Z","event_type":"best_bid_ask","market_id":"3790394","outcome_index":0,"market_type":"set1","local_side":"home","local_uid":"2026-08-23_hugo_grenier_mees_rottgering","bid":0.0,"ask":0.36,"mid":0.18,"spread":0.36,"bid_size":null,"ask_size":null}
{"ts":"2026-08-23T17:54:03.741Z","event_type":"best_bid_ask","market_id":"3790394","outcome_index":1,"market_type":"set1","local_side":"away","local_uid":"2026-08-23_hugo_grenier_mees_rottgering","bid":0.64,"ask":1.0,"mid":0.82,"spread":0.36,"bid_size":null,"ask_size":null}
{"ts":"2026-08-23T17:54:03.741Z","event_type":"price_change","market_id":"3790394","outcome_index":0,"market_type":"set1","local_side":"home","local_uid":"2026-08-23_hugo_grenier_mees_rottgering","bid":0.0,"ask":0.36,"mid":0.18,"spread":0.36,"price":0.25,"size":0.0,"side":"BUY"}
{"ts":"2026-08-23T17:54:03.741Z","event_type":"price_change","market_id":"3790394","outcome_index":1,"market_type":"set1","local_side":"away","local_uid":"2026-08-23_hugo_grenier_mees_rottgering","bid":0.64,"ask":1.0,"mid":0.82,"spread":0.36,"price":0.75,"size":0.0,"side":"SELL"}
{"ts":"2026-08-23T17:54:03.741Z","event_type":"best_bid_ask","market_id":"3790397","outcome_index":0,"market_type":"set2","local_side":"home","local_uid":"2026-08-23_hugo_grenier_mees_rottgering","bid":0.0,"ask":1.0,"mid":0.5,"spread":1.0,"bid_size":null,"ask_size":null}
{"ts":"2026-08-23T17:54:03.741Z","event_type":"best_bid_ask","market_id":"3790397","outcome_index":1,"market_type":"set2","local_side":"away","local_uid":"2026-08-23_hugo_grenier_mees_rottgering","bid":0.0,"ask":1.0,"mid":0.5,"spread":1.0,"bid_size":null,"ask_size":null}
{"ts":"2026-08-23T17:54:03.741Z","event_type":"price_change","market_id":"3790397","outcome_index":1,"market_type":"set2","local_side":"away","local_uid":"2026-08-23_hugo_grenier_mees_rottgering","bid":0.0,"ask":1.0,"mid":0.5,"spread":1.0,"price":0.58,"size":0.0,"side":"BUY"}
{"ts":"2026-08-23T17:54:03.741Z","event_type":"price_change","market_id":"3790397","outcome_index":0,"market_type":"set2","local_side":"home","local_uid":"2026-08-23_hugo_grenier_mees_rottgering","bid":0.0,"ask":1.0,"mid":0.5,"spread":1.0,"price":0.42,"size":0.0,"side":"SELL"}
{"ts":"2026-08-23T17:54:03.741Z","event_type":"best_bid_ask","market_id":"3790397","outcome_index":0,"market_type":"set2","local_side":"home","local_uid":"2026-08-23_hugo_grenier_mees_rottgering","bid":0.29,"ask":1.0,"mid":0.645,"spread":0.71,"bid_size":null,"ask_size":null}
{"ts":"2026-08-23T17:54:03.741Z","event_type":"best_bid_ask","market_id":"3790397","outcome_index":1,"market_type":"set2","local_side":"away","local_uid":"2026-08-23_hugo_grenier_mees_rottgering","bid":0.0,"ask":0.71,"mid":0.355,"spread":0.71,"bid_size":null,"ask_size":null}
{"ts":"2026-08-23T17:54:03.742Z","event_type":"price_change","market_id":"3790397","outcome_index":0,"market_type":"set2","local_side":"home","local_uid":"2026-08-23_hugo_grenier_mees_rottgering","bid":0.29,"ask":1.0,"mid":0.645,"spread":0.71,"price":0.29,"size":37.39,"side":"BUY"}
{"ts":"2026-08-23T17:54:03.742Z","event_type":"price_change","market_id":"3790397","outcome_index":1,"market_type":"set2","local_side":"away","local_uid":"2026-08-23_hugo_grenier_mees_rottgering","bid":0.0,"ask":0.71,"mid":0.355,"spread":0.71,"price":0.71,"size":37.39,"side":"SELL"}
{"ts":"2026-08-23T17:54:03.742Z","event_type":"best_bid_ask","market_id":"3790394","outcome_index":0,"market_type":"set1","local_side":"home","local_uid":"2026-08-23_hugo_grenier_mees_rottgering","bid":0.0,"ask":0.77,"mid":0.385,"spread":0.77,"bid_size":null,"ask_size":null}
{"ts":"2026-08-23T17:54:03.742Z","event_type":"best_bid_ask","market_id":"3790394","outcome_index":1,"market_type":"set1","local_side":"away","local_uid":"2026-08-23_hugo_grenier_mees_rottgering","bid":0.23,"ask":1.0,"mid":0.615,"spread":0.77,"bid_size":null,"ask_size":null}
{"ts":"2026-08-23T17:54:03.742Z","event_type":"price_change","market_id":"3790394","outcome_index":1,"market_type":"set1","local_side":"away","local_uid":"2026-08-23_hugo_grenier_mees_rottgering","bid":0.23,"ask":1.0,"mid":0.615,"spread":0.77,"price":0.64,"size":0.0,"side":"BUY"}
{"ts":"2026-08-23T17:54:03.742Z","event_type":"price_change","market_id":"3790394","outcome_index":0,"market_type":"set1","local_side":"home","local_uid":"2026-08-23_hugo_grenier_mees_rottgering","bid":0.0,"ask":0.77,"mid":0.385,"spread":0.77,"price":0.36,"size":0.0,"side":"SELL"}
{"ts":"2026-08-23T17:54:03.744Z","event_type":"best_bid_ask","market_id":"3790397","outcome_index":0,"market_type":"set2","local_side":"home","local_uid":"2026-08-23_hugo_grenier_mees_rottgering","bid":0.29,"ask":0.42,"mid":0.355,"spread":0.13,"bid_size":null,"ask_size":null}
{"ts":"2026-08-23T17:54:03.744Z","event_type":"best_bid_ask","market_id":"3790397","outcome_index":1,"market_type":"set2","local_side":"away","local_uid":"2026-08-23_hugo_grenier_mees_rottgering","bid":0.58,"ask":0.71,"mid":0.645,"spread":0.13,"bid_size":null,"ask_size":null}
{"ts":"2026-08-23T17:54:03.744Z","event_type":"price_change","market_id":"3790397","outcome_index":1,"market_type":"set2","local_side":"away","local_uid":"2026-08-23_hugo_grenier_mees_rottgering","bid":0.58,"ask":0.71,"mid":0.645,"spread":0.13,"price":0.58,"size":150.0,"side":"BUY"}
{"ts":"2026-08-23T17:54:03.744Z","event_type":"price_change","market_id":"3790397","outcome_index":0,"market_type":"set2","local_side":"home","local_uid":"2026-08-23_hugo_grenier_mees_rottgering","bid":0.29,"ask":0.42,"mid":0.355,"spread":0.13,"price":0.42,"size":150.0,"side":"SELL"}
{"ts":"2026-08-23T17:54:03.745Z","event_type":"best_bid_ask","market_id":"3790397","outcome_index":0,"market_type":"set2","local_side":"home","local_uid":"2026-08-23_hugo_grenier_mees_rottgering","bid":0.29,"ask":0.41,"mid":0.35,"spread":0.12,"bid_size":null,"ask_size":null}
{"ts":"2026-08-23T17:54:03.745Z","event_type":"best_bid_ask","market_id":"3790397","outcome_index":1,"market_type":"set2","local_side":"away","local_uid":"2026-08-23_hugo_grenier_mees_rottgering","bid":0.59,"ask":0.71,"mid":0.65,"spread":0.12,"bid_size":null,"ask_size":null}
{"ts":"2026-08-23T17:54:03.745Z","event_type":"price_change","market_id":"3790397","outcome_index":1,"market_type":"set2","local_side":"away","local_uid":"2026-08-23_hugo_grenier_mees_rottgering","bid":0.59,"ask":0.71,"mid":0.65,"spread":0.12,"price":0.59,"size":43.79,"side":"BUY"}
{"ts":"2026-08-23T17:54:03.745Z","event_type":"price_change","market_id":"3790397","outcome_index":0,"market_type":"set2","local_side":"home","local_uid":"2026-08-23_hugo_grenier_mees_rottgering","bid":0.29,"ask":0.41,"mid":0.35,"spread":0.12,"price":0.41,"size":43.79,"side":"SELL"}
{"ts":"2026-08-23T17:54:03.745Z","event_type":"best_bid_ask","market_id":"3790394","outcome_index":0,"market_type":"set1","local_side":"home","local_uid":"2026-08-23_hugo_grenier_mees_rottgering","bid":0.18,"ask":0.77,"mid":0.475,"spread":0.59,"bid_size":null,"ask_size":null}
{"ts":"2026-08-23T17:54:03.748Z","event_type":"best_bid_ask","market_id":"3790394","outcome_index":1,"market_type":"set1","local_side":"away","local_uid":"2026-08-23_hugo_grenier_mees_rottgering","bid":0.23,"ask":0.82,"mid":0.525,"spread":0.59,"bid_size":null,"ask_size":null}
{"ts":"2026-08-23T17:54:03.748Z","event_type":"price_change","market_id":"3790394","outcome_index":0,"market_type":"set1","local_side":"home","local_uid":"2026-08-23_hugo_grenier_mees_rottgering","bid":0.18,"ask":0.77,"mid":0.475,"spread":0.59,"price":0.18,"size":11.0,"side":"BUY"}
{"ts":"2026-08-23T17:54:03.748Z","event_type":"price_change","market_id":"3790394","outcome_index":1,"market_type":"set1","local_side":"away","local_uid":"2026-08-23_hugo_grenier_mees_rottgering","bid":0.23,"ask":0.82,"mid":0.525,"spread":0.59,"price":0.82,"size":11.0,"side":"SELL"}
{"ts":"2026-08-23T17:54:03.749Z","event_type":"best_bid_ask","market_id":"3790394","outcome_index":0,"market_type":"set1","local_side":"home","local_uid":"2026-08-23_hugo_grenier_mees_rottgering","bid":0.2,"ask":0.77,"mid":0.485,"spread":0.57,"bid_size":null,"ask_size":null}
{"ts":"2026-08-23T17:54:03.749Z","event_type":"best_bid_ask","market_id":"3790394","outcome_index":1,"market_type":"set1","local_side":"away","local_uid":"2026-08-23_hugo_grenier_mees_rottgering","bid":0.23,"ask":0.8,"mid":0.515,"spread":0.57,"bid_size":null,"ask_size":null}
{"ts":"2026-08-23T17:54:03.749Z","event_type":"price_change","market_id":"3790394","outcome_index":0,"market_type":"set1","local_side":"home","local_uid":"2026-08-23_hugo_grenier_mees_rottgering","bid":0.2,"ask":0.77,"mid":0.485,"spread":0.57,"price":0.2,"size":13.0,"side":"BUY"}
{"ts":"2026-08-23T17:54:03.749Z","event_type":"price_change","market_id":"3790394","outcome_index":1,"market_type":"set1","local_side":"away","local_uid":"2026-08-23_hugo_grenier_mees_rottgering","bid":0.23,"ask":0.8,"mid":0.515,"spread":0.57,"price":0.8,"size":13.0,"side":"SELL"}
{"ts":"2026-08-23T17:54:03.749Z","event_type":"best_bid_ask","market_id":"3790394","outcome_index":0,"market_type":"set1","local_side":"home","local_uid":"2026-08-23_hugo_grenier_mees_rottgering","bid":0.2,"ask":0.41,"mid":0.305,"spread":0.21,"bid_size":null,"ask_size":null}
{"ts":"2026-08-23T17:54:03.749Z","event_type":"best_bid_ask","market_id":"3790394","outcome_index":1,"market_type":"set1","local_side":"away","local_uid":"2026-08-23_hugo_grenier_mees_rottgering","bid":0.59,"ask":0.8,"mid":0.695,"spread":0.21,"bid_size":null,"ask_size":null}
{"ts":"2026-08-23T17:54:03.749Z","event_type":"price_change","market_id":"3790394","outcome_index":1,"market_type":"set1","local_side":"away","local_uid":"2026-08-23_hugo_grenier_mees_rottgering","bid":0.59,"ask":0.8,"mid":0.695,"spread":0.21,"price":0.59,"size":11.0,"side":"BUY"}
{"ts":"2026-08-23T17:54:03.749Z","event_type":"price_change","market_id":"3790394","outcome_index":0,"market_type":"set1","local_side":"home","local_uid":"2026-08-23_hugo_grenier_mees_rottgering","bid":0.2,"ask":0.41,"mid":0.305,"spread":0.21,"price":0.41,"size":11.0,"side":"SELL"}
{"ts":"2026-08-23T17:54:03.751Z","event_type":"best_bid_ask","market_id":"3790415","outcome_index":0,"market_type":"set2","local_side":"home","local_uid":"2026-08-23_pierre_hugues_herbert_quinn_vandecasteele","bid":0.58,"ask":0.66,"mid":0.62,"spread":0.08,"bid_size":null,"ask_size":null}
{"ts":"2026-08-23T17:54:03.751Z","event_type":"best_bid_ask","market_id":"3790415","outcome_index":1,"market_type":"set2","local_side":"away","local_uid":"2026-08-23_pierre_hugues_herbert_quinn_vandecasteele","bid":0.34,"ask":0.42,"mid":0.38,"spread":0.08,"bid_size":null,"ask_size":null}
{"ts":"2026-08-23T17:54:03.751Z","event_type":"price_change","market_id":"3790415","outcome_index":0,"market_type":"set2","local_side":"home","local_uid":"2026-08-23_pierre_hugues_herbert_quinn_vandecasteele","bid":0.58,"ask":0.66,"mid":0.62,"spread":0.08,"price":0.58,"size":150.0,"side":"BUY"}
{"ts":"2026-08-23T17:54:03.751Z","event_type":"price_change","market_id":"3790415","outcome_index":1,"market_type":"set2","local_side":"away","local_uid":"2026-08-23_pierre_hugues_herbert_quinn_vandecasteele","bid":0.34,"ask":0.42,"mid":0.38,"spread":0.08,"price":0.42,"size":150.0,"side":"SELL"}
{"ts":"2026-08-23T17:54:03.817Z","event_type":"best_bid_ask","market_id":"3790323","outcome_index":0,"market_type":"set2","local_side":"home","local_uid":"2026-08-23_felix_balshaw_sebastian_gorzny","bid":0.0,"ask":0.84,"mid":0.42,"spread":0.84,"bid_size":null,"ask_size":null}
{"ts":"2026-08-23T17:54:03.817Z","event_type":"best_bid_ask","market_id":"3790323","outcome_index":1,"market_type":"set2","local_side":"away","local_uid":"2026-08-23_felix_balshaw_sebastian_gorzny","bid":0.16,"ask":1.0,"mid":0.58,"spread":0.84,"bid_size":null,"ask_size":null}
{"ts":"2026-08-23T17:54:03.817Z","event_type":"price_change","market_id":"3790323","outcome_index":1,"market_type":"set2","local_side":"away","local_uid":"2026-08-23_felix_balshaw_sebastian_gorzny","bid":0.16,"ask":1.0,"mid":0.58,"spread":0.84,"price":0.16,"size":423.0,"side":"BUY"}
{"ts":"2026-08-23T17:54:03.817Z","event_type":"price_change","market_id":"3790323","outcome_index":0,"market_type":"set2","local_side":"home","local_uid":"2026-08-23_felix_balshaw_sebastian_gorzny","bid":0.0,"ask":0.84,"mid":0.42,"spread":0.84,"price":0.84,"size":423.0,"side":"SELL"}
{"ts":"2026-08-23T17:54:03.818Z","event_type":"best_bid_ask","market_id":"3790323","outcome_index":0,"market_type":"set2","local_side":"home","local_uid":"2026-08-23_felix_balshaw_sebastian_gorzny","bid":0.0,"ask":0.83,"mid":0.415,"spread":0.83,"bid_size":null,"ask_size":null}
{"ts":"2026-08-23T17:54:03.818Z","event_type":"best_bid_ask","market_id":"3790323","outcome_index":1,"market_type":"set2","local_side":"away","local_uid":"2026-08-23_felix_balshaw_sebastian_gorzny","bid":0.17,"ask":1.0,"mid":0.585,"spread":0.83,"bid_size":null,"ask_size":null}
{"ts":"2026-08-23T17:54:03.818Z","event_type":"price_change","market_id":"3790323","outcome_index":1,"market_type":"set2","local_side":"away","local_uid":"2026-08-23_felix_balshaw_sebastian_gorzny","bid":0.17,"ask":1.0,"mid":0.585,"spread":0.83,"price":0.17,"size":88.0,"side":"BUY"}
{"ts":"2026-08-23T17:54:03.818Z","event_type":"price_change","market_id":"3790323","outcome_index":0,"market_type":"set2","local_side":"home","local_uid":"2026-08-23_felix_balshaw_sebastian_gorzny","bid":0.0,"ask":0.83,"mid":0.415,"spread":0.83,"price":0.83,"size":88.0,"side":"SELL"}
{"ts":"2026-08-23T17:54:03.828Z","event_type":"best_bid_ask","market_id":"3790397","outcome_index":0,"market_type":"set2","local_side":"home","local_uid":"2026-08-23_hugo_grenier_mees_rottgering","bid":0.29,"ask":0.42,"mid":0.355,"spread":0.13,"bid_size":null,"ask_size":null}
{"ts":"2026-08-23T17:54:03.828Z","event_type":"best_bid_ask","market_id":"3790397","outcome_index":1,"market_type":"set2","local_side":"away","local_uid":"2026-08-23_hugo_grenier_mees_rottgering","bid":0.58,"ask":0.71,"mid":0.645,"spread":0.13,"bid_size":null,"ask_size":null}
{"ts":"2026-08-23T17:54:03.828Z","event_type":"price_change","market_id":"3790397","outcome_index":1,"market_type":"set2","local_side":"away","local_uid":"2026-08-23_hugo_grenier_mees_rottgering","bid":0.58,"ask":0.71,"mid":0.645,"spread":0.13,"price":0.59,"size":0.0,"side":"BUY"}
{"ts":"2026-08-23T17:54:03.828Z","event_type":"price_change","market_id":"3790397","outcome_index":0,"market_type":"set2","local_side":"home","local_uid":"2026-08-23_hugo_grenier_mees_rottgering","bid":0.29,"ask":0.42,"mid":0.355,"spread":0.13,"price":0.41,"size":0.0,"side":"SELL"}
{"ts":"2026-08-23T17:54:03.832Z","event_type":"best_bid_ask","market_id":"3789927","outcome_index":0,"market_type":"match","local_side":"home","local_uid":"2026-08-23_hugo_grenier_mees_rottgering","bid":0.26,"ask":0.28,"mid":0.27,"spread":0.02,"bid_size":null,"ask_size":null}
{"ts":"2026-08-23T17:54:03.832Z","event_type":"best_bid_ask","market_id":"3789927","outcome_index":1,"market_type":"match","local_side":"away","local_uid":"2026-08-23_hugo_grenier_mees_rottgering","bid":0.72,"ask":0.74,"mid":0.73,"spread":0.02,"bid_size":null,"ask_size":null}
{"ts":"2026-08-23T17:54:03.832Z","event_type":"price_change","market_id":"3789927","outcome_index":0,"market_type":"match","local_side":"home","local_uid":"2026-08-23_hugo_grenier_mees_rottgering","bid":0.26,"ask":0.28,"mid":0.27,"spread":0.02,"price":0.27,"size":0.0,"side":"BUY"}
{"ts":"2026-08-23T17:54:03.832Z","event_type":"price_change","market_id":"3789927","outcome_index":1,"market_type":"match","local_side":"away","local_uid":"2026-08-23_hugo_grenier_mees_rottgering","bid":0.72,"ask":0.74,"mid":0.73,"spread":0.02,"price":0.73,"size":0.0,"side":"SELL"}
{"ts":"2026-08-23T17:54:03.842Z","event_type":"best_bid_ask","market_id":"3790397","outcome_index":0,"market_type":"set2","local_side":"home","local_uid":"2026-08-23_hugo_grenier_mees_rottgering","bid":0.29,"ask":0.41,"mid":0.35,"spread":0.12,"bid_size":null,"ask_size":null}
{"ts":"2026-08-23T17:54:03.842Z","event_type":"best_bid_ask","market_id":"3790397","outcome_index":1,"market_type":"set2","local_side":"away","local_uid":"2026-08-23_hugo_grenier_mees_rottgering","bid":0.59,"ask":0.71,"mid":0.65,"spread":0.12,"bid_size":null,"ask_size":null}
{"ts":"2026-08-23T17:54:03.842Z","event_type":"price_change","market_id":"3790397","outcome_index":1,"market_type":"set2","local_side":"away","local_uid":"2026-08-23_hugo_grenier_mees_rottgering","bid":0.59,"ask":0.71,"mid":0.65,"spread":0.12,"price":0.59,"size":31.49,"side":"BUY"}
{"ts":"2026-08-23T17:54:03.842Z","event_type":"price_change","market_id":"3790397","outcome_index":0,"market_type":"set2","local_side":"home","local_uid":"2026-08-23_hugo_grenier_mees_rottgering","bid":0.29,"ask":0.41,"mid":0.35,"spread":0.12,"price":0.41,"size":31.49,"side":"SELL"}
{"ts":"2026-08-23T17:54:03.934Z","event_type":"best_bid_ask","market_id":"3790394","outcome_index":0,"market_type":"set1","local_side":"home","local_uid":"2026-08-23_hugo_grenier_mees_rottgering","bid":0.18,"ask":0.41,"mid":0.295,"spread":0.23,"bid_size":null,"ask_size":null}
{"ts":"2026-08-23T17:54:03.934Z","event_type":"best_bid_ask","market_id":"3790394","outcome_index":1,"market_type":"set1","local_side":"away","local_uid":"2026-08-23_hugo_grenier_mees_rottgering","bid":0.59,"ask":0.82,"mid":0.705,"spread":0.23,"bid_size":null,"ask_size":null}
{"ts":"2026-08-23T17:54:03.934Z","event_type":"price_change","market_id":"3790394","outcome_index":0,"market_type":"set1","local_side":"home","local_uid":"2026-08-23_hugo_grenier_mees_rottgering","bid":0.18,"ask":0.41,"mid":0.295,"spread":0.23,"price":0.2,"size":0.0,"side":"BUY"}
{"ts":"2026-08-23T17:54:03.934Z","event_type":"price_change","market_id":"3790394","outcome_index":1,"market_type":"set1","local_side":"away","local_uid":"2026-08-23_hugo_grenier_mees_rottgering","bid":0.59,"ask":0.82,"mid":0.705,"spread":0.23,"price":0.8,"size":0.0,"side":"SELL"}
{"ts":"2026-08-23T17:54:03.939Z","event_type":"best_bid_ask","market_id":"3789987","outcome_index":0,"market_type":"match","local_side":"home","local_uid":"2026-08-23_mika_petkovic_federico_iannaccone","bid":0.0,"ask":1.0,"mid":0.5,"spread":1.0,"bid_size":null,"ask_size":null}
{"ts":"2026-08-23T17:54:03.939Z","event_type":"best_bid_ask","market_id":"3789987","outcome_index":1,"market_type":"match","local_side":"away","local_uid":"2026-08-23_mika_petkovic_federico_iannaccone","bid":0.0,"ask":1.0,"mid":0.5,"spread":1.0,"bid_size":null,"ask_size":null}
{"ts":"2026-08-23T17:54:03.939Z","event_type":"price_change","market_id":"3789987","outcome_index":1,"market_type":"match","local_side":"away","local_uid":"2026-08-23_mika_petkovic_federico_iannaccone","bid":0.0,"ask":1.0,"mid":0.5,"spread":1.0,"price":0.999,"size":0.0,"side":"BUY"}
{"ts":"2026-08-23T17:54:03.939Z","event_type":"price_change","market_id":"3789987","outcome_index":0,"market_type":"match","local_side":"home","local_uid":"2026-08-23_mika_petkovic_federico_iannaccone","bid":0.0,"ask":1.0,"mid":0.5,"spread":1.0,"price":0.001,"size":0.0,"side":"SELL"}
{"ts":"2026-08-23T17:54:03.945Z","event_type":"market_resolved","market_id":"0x920bcb537c6a02586f519488289a10525f8937a766583da11c25ed0f2f48d136"}
{"ts":"2026-08-23T17:54:04.055Z","event_type":"best_bid_ask","market_id":"3789927","outcome_index":0,"market_type":"match","local_side":"home","local_uid":"2026-08-23_hugo_grenier_mees_rottgering","bid":0.26,"ask":0.29,"mid":0.275,"spread":0.03,"bid_size":null,"ask_size":null}
{"ts":"2026-08-23T17:54:04.055Z","event_type":"best_bid_ask","market_id":"3789927","outcome_index":1,"market_type":"match","local_side":"away","local_uid":"2026-08-23_hugo_grenier_mees_rottgering","bid":0.71,"ask":0.74,"mid":0.725,"spread":0.03,"bid_size":null,"ask_size":null}
{"ts":"2026-08-23T17:54:04.055Z","event_type":"price_change","market_id":"3789927","outcome_index":1,"market_type":"match","local_side":"away","local_uid":"2026-08-23_hugo_grenier_mees_rottgering","bid":0.71,"ask":0.74,"mid":0.725,"spread":0.03,"price":0.72,"size":0.0,"side":"BUY"}
{"ts":"2026-08-23T17:54:04.055Z","event_type":"price_change","market_id":"3789927","outcome_index":0,"market_type":"match","local_side":"home","local_uid":"2026-08-23_hugo_grenier_mees_rottgering","bid":0.26,"ask":0.29,"mid":0.275,"spread":0.03,"price":0.28,"size":0.0,"side":"SELL"}
{"ts":"2026-08-23T17:54:04.422Z","event_type":"price_change","market_id":"3780846","outcome_index":0,"market_type":"match","local_side":"home","local_uid":"2026-08-23_martin_landaluce_mattia_bellucci","bid":0.53,"ask":0.54,"mid":0.535,"spread":0.01,"price":0.36,"size":41.0,"side":"BUY"}
{"ts":"2026-08-23T17:54:04.422Z","event_type":"price_change","market_id":"3780846","outcome_index":1,"market_type":"match","local_side":"away","local_uid":"2026-08-23_martin_landaluce_mattia_bellucci","bid":0.46,"ask":0.47,"mid":0.465,"spread":0.01,"price":0.64,"size":41.0,"side":"SELL"}
{"ts":"2026-08-23T17:54:04.446Z","event_type":"best_bid_ask","market_id":"3790394","outcome_index":0,"market_type":"set1","local_side":"home","local_uid":"2026-08-23_hugo_grenier_mees_rottgering","bid":0.16,"ask":0.41,"mid":0.285,"spread":0.25,"bid_size":null,"ask_size":null}
{"ts":"2026-08-23T17:54:04.446Z","event_type":"best_bid_ask","market_id":"3790394","outcome_index":1,"market_type":"set1","local_side":"away","local_uid":"2026-08-23_hugo_grenier_mees_rottgering","bid":0.59,"ask":0.84,"mid":0.715,"spread":0.25,"bid_size":null,"ask_size":null}
{"ts":"2026-08-23T17:54:04.446Z","event_type":"price_change","market_id":"3790394","outcome_index":0,"market_type":"set1","local_side":"home","local_uid":"2026-08-23_hugo_grenier_mees_rottgering","bid":0.16,"ask":0.41,"mid":0.285,"spread":0.25,"price":0.18,"size":0.0,"side":"BUY"}
{"ts":"2026-08-23T17:54:04.446Z","event_type":"price_change","market_id":"3790394","outcome_index":1,"market_type":"set1","local_side":"away","local_uid":"2026-08-23_hugo_grenier_mees_rottgering","bid":0.59,"ask":0.84,"mid":0.715,"spread":0.25,"price":0.82,"size":0.0,"side":"SELL"}
{"ts":"2026-08-23T17:54:04.446Z","event_type":"best_bid_ask","market_id":"3790394","outcome_index":0,"market_type":"set1","local_side":"home","local_uid":"2026-08-23_hugo_grenier_mees_rottgering","bid":0.17,"ask":0.41,"mid":0.29,"spread":0.24,"bid_size":null,"ask_size":null}
{"ts":"2026-08-23T17:54:04.446Z","event_type":"best_bid_ask","market_id":"3790394","outcome_index":1,"market_type":"set1","local_side":"away","local_uid":"2026-08-23_hugo_grenier_mees_rottgering","bid":0.59,"ask":0.83,"mid":0.71,"spread":0.24,"bid_size":null,"ask_size":null}
{"ts":"2026-08-23T17:54:04.447Z","event_type":"price_change","market_id":"3790394","outcome_index":0,"market_type":"set1","local_side":"home","local_uid":"2026-08-23_hugo_grenier_mees_rottgering","bid":0.17,"ask":0.41,"mid":0.29,"spread":0.24,"price":0.17,"size":22.0,"side":"BUY"}
{"ts":"2026-08-23T17:54:04.447Z","event_type":"price_change","market_id":"3790394","outcome_index":1,"market_type":"set1","local_side":"away","local_uid":"2026-08-23_hugo_grenier_mees_rottgering","bid":0.59,"ask":0.83,"mid":0.71,"spread":0.24,"price":0.83,"size":22.0,"side":"SELL"}
{"ts":"2026-08-23T17:54:04.471Z","event_type":"best_bid_ask","market_id":"3790394","outcome_index":0,"market_type":"set1","local_side":"home","local_uid":"2026-08-23_hugo_grenier_mees_rottgering","bid":0.14,"ask":0.41,"mid":0.275,"spread":0.27,"bid_size":null,"ask_size":null}
{"ts":"2026-08-23T17:54:04.472Z","event_type":"best_bid_ask","market_id":"3790394","outcome_index":1,"market_type":"set1","local_side":"away","local_uid":"2026-08-23_hugo_grenier_mees_rottgering","bid":0.59,"ask":0.86,"mid":0.725,"spread":0.27,"bid_size":null,"ask_size":null}
{"ts":"2026-08-23T17:54:04.472Z","event_type":"price_change","market_id":"3790394","outcome_index":0,"market_type":"set1","local_side":"home","local_uid":"2026-08-23_hugo_grenier_mees_rottgering","bid":0.14,"ask":0.41,"mid":0.275,"spread":0.27,"price":0.17,"size":0.0,"side":"BUY"}
{"ts":"2026-08-23T17:54:04.472Z","event_type":"price_change","market_id":"3790394","outcome_index":1,"market_type":"set1","local_side":"away","local_uid":"2026-08-23_hugo_grenier_mees_rottgering","bid":0.59,"ask":0.86,"mid":0.725,"spread":0.27,"price":0.83,"size":0.0,"side":"SELL"}
{"ts":"2026-08-23T17:54:04.570Z","event_type":"best_bid_ask","market_id":"3789929","outcome_index":0,"market_type":"match","local_side":"home","local_uid":"2026-08-23_felix_balshaw_sebastian_gorzny","bid":0.38,"ask":0.4,"mid":0.39,"spread":0.02,"bid_size":null,"ask_size":null}
{"ts":"2026-08-23T17:54:04.570Z","event_type":"best_bid_ask","market_id":"3789929","outcome_index":1,"market_type":"match","local_side":"away","local_uid":"2026-08-23_felix_balshaw_sebastian_gorzny","bid":0.6,"ask":0.62,"mid":0.61,"spread":0.02,"bid_size":null,"ask_size":null}
{"ts":"2026-08-23T17:54:04.570Z","event_type":"price_change","market_id":"3789929","outcome_index":0,"market_type":"match","local_side":"home","local_uid":"2026-08-23_felix_balshaw_sebastian_gorzny","bid":0.38,"ask":0.4,"mid":0.39,"spread":0.02,"price":0.38,"size":69.8,"side":"BUY"}
{"ts":"2026-08-23T17:54:04.571Z","event_type":"price_change","market_id":"3789929","outcome_index":1,"market_type":"match","local_side":"away","local_uid":"2026-08-23_felix_balshaw_sebastian_gorzny","bid":0.6,"ask":0.62,"mid":0.61,"spread":0.02,"price":0.62,"size":69.8,"side":"SELL"}
{"ts":"2026-08-23T17:54:04.633Z","event_type":"best_bid_ask","market_id":"3789929","outcome_index":0,"market_type":"match","local_side":"home","local_uid":"2026-08-23_felix_balshaw_sebastian_gorzny","bid":0.38,"ask":0.41,"mid":0.395,"spread":0.03,"bid_size":null,"ask_size":null}
{"ts":"2026-08-23T17:54:04.633Z","event_type":"best_bid_ask","market_id":"3789929","outcome_index":1,"market_type":"match","local_side":"away","local_uid":"2026-08-23_felix_balshaw_sebastian_gorzny","bid":0.59,"ask":0.62,"mid":0.605,"spread":0.03,"bid_size":null,"ask_size":null}
{"ts":"2026-08-23T17:54:04.633Z","event_type":"price_change","market_id":"3789929","outcome_index":1,"market_type":"match","local_side":"away","local_uid":"2026-08-23_felix_balshaw_sebastian_gorzny","bid":0.59,"ask":0.62,"mid":0.605,"spread":0.03,"price":0.6,"size":0.0,"side":"BUY"}
{"ts":"2026-08-23T17:54:04.633Z","event_type":"price_change","market_id":"3789929","outcome_index":0,"market_type":"match","local_side":"home","local_uid":"2026-08-23_felix_balshaw_sebastian_gorzny","bid":0.38,"ask":0.41,"mid":0.395,"spread":0.03,"price":0.4,"size":0.0,"side":"SELL"}
{"ts":"2026-08-23T17:54:04.668Z","event_type":"best_bid_ask","market_id":"3790397","outcome_index":0,"market_type":"set2","local_side":"home","local_uid":"2026-08-23_hugo_grenier_mees_rottgering","bid":0.29,"ask":0.42,"mid":0.355,"spread":0.13,"bid_size":null,"ask_size":null}
{"ts":"2026-08-23T17:54:04.669Z","event_type":"best_bid_ask","market_id":"3790397","outcome_index":1,"market_type":"set2","local_side":"away","local_uid":"2026-08-23_hugo_grenier_mees_rottgering","bid":0.58,"ask":0.71,"mid":0.645,"spread":0.13,"bid_size":null,"ask_size":null}
{"ts":"2026-08-23T17:54:04.669Z","event_type":"price_change","market_id":"3790397","outcome_index":1,"market_type":"set2","local_side":"away","local_uid":"2026-08-23_hugo_grenier_mees_rottgering","bid":0.58,"ask":0.71,"mid":0.645,"spread":0.13,"price":0.59,"size":0.0,"side":"BUY"}
{"ts":"2026-08-23T17:54:04.669Z","event_type":"price_change","market_id":"3790397","outcome_index":0,"market_type":"set2","local_side":"home","local_uid":"2026-08-23_hugo_grenier_mees_rottgering","bid":0.29,"ask":0.42,"mid":0.355,"spread":0.13,"price":0.41,"size":0.0,"side":"SELL"}
{"ts":"2026-08-23T17:54:04.690Z","event_type":"best_bid_ask","market_id":"3790415","outcome_index":0,"market_type":"set2","local_side":"home","local_uid":"2026-08-23_pierre_hugues_herbert_quinn_vandecasteele","bid":0.57,"ask":0.66,"mid":0.615,"spread":0.09,"bid_size":null,"ask_size":null}
{"ts":"2026-08-23T17:54:04.690Z","event_type":"best_bid_ask","market_id":"3790415","outcome_index":1,"market_type":"set2","local_side":"away","local_uid":"2026-08-23_pierre_hugues_herbert_quinn_vandecasteele","bid":0.34,"ask":0.43,"mid":0.385,"spread":0.09,"bid_size":null,"ask_size":null}
{"ts":"2026-08-23T17:54:04.690Z","event_type":"price_change","market_id":"3790415","outcome_index":0,"market_type":"set2","local_side":"home","local_uid":"2026-08-23_pierre_hugues_herbert_quinn_vandecasteele","bid":0.57,"ask":0.66,"mid":0.615,"spread":0.09,"price":0.58,"size":0.0,"side":"BUY"}
{"ts":"2026-08-23T17:54:04.690Z","event_type":"price_change","market_id":"3790415","outcome_index":1,"market_type":"set2","local_side":"away","local_uid":"2026-08-23_pierre_hugues_herbert_quinn_vandecasteele","bid":0.34,"ask":0.43,"mid":0.385,"spread":0.09,"price":0.42,"size":0.0,"side":"SELL"}
{"ts":"2026-08-23T17:54:04.704Z","event_type":"best_bid_ask","market_id":"3790415","outcome_index":0,"market_type":"set2","local_side":"home","local_uid":"2026-08-23_pierre_hugues_herbert_quinn_vandecasteele","bid":0.55,"ask":0.66,"mid":0.605,"spread":0.11,"bid_size":null,"ask_size":null}
{"ts":"2026-08-23T17:54:04.704Z","event_type":"best_bid_ask","market_id":"3790415","outcome_index":1,"market_type":"set2","local_side":"away","local_uid":"2026-08-23_pierre_hugues_herbert_quinn_vandecasteele","bid":0.34,"ask":0.45,"mid":0.395,"spread":0.11,"bid_size":null,"ask_size":null}
{"ts":"2026-08-23T17:54:04.704Z","event_type":"price_change","market_id":"3790415","outcome_index":0,"market_type":"set2","local_side":"home","local_uid":"2026-08-23_pierre_hugues_herbert_quinn_vandecasteele","bid":0.55,"ask":0.66,"mid":0.605,"spread":0.11,"price":0.57,"size":0.0,"side":"BUY"}
{"ts":"2026-08-23T17:54:04.704Z","event_type":"price_change","market_id":"3790415","outcome_index":1,"market_type":"set2","local_side":"away","local_uid":"2026-08-23_pierre_hugues_herbert_quinn_vandecasteele","bid":0.34,"ask":0.45,"mid":0.395,"spread":0.11,"price":0.43,"size":0.0,"side":"SELL"}
{"ts":"2026-08-23T17:54:04.708Z","event_type":"best_bid_ask","market_id":"3790397","outcome_index":0,"market_type":"set2","local_side":"home","local_uid":"2026-08-23_hugo_grenier_mees_rottgering","bid":0.29,"ask":0.41,"mid":0.35,"spread":0.12,"bid_size":null,"ask_size":null}
{"ts":"2026-08-23T17:54:04.708Z","event_type":"best_bid_ask","market_id":"3790397","outcome_index":1,"market_type":"set2","local_side":"away","local_uid":"2026-08-23_hugo_grenier_mees_rottgering","bid":0.59,"ask":0.71,"mid":0.65,"spread":0.12,"bid_size":null,"ask_size":null}
{"ts":"2026-08-23T17:54:04.708Z","event_type":"price_change","market_id":"3790397","outcome_index":1,"market_type":"set2","local_side":"away","local_uid":"2026-08-23_hugo_grenier_mees_rottgering","bid":0.59,"ask":0.71,"mid":0.65,"spread":0.12,"price":0.59,"size":129.88,"side":"BUY"}
{"ts":"2026-08-23T17:54:04.708Z","event_type":"price_change","market_id":"3790397","outcome_index":0,"market_type":"set2","local_side":"home","local_uid":"2026-08-23_hugo_grenier_mees_rottgering","bid":0.29,"ask":0.41,"mid":0.35,"spread":0.12,"price":0.41,"size":129.88,"side":"SELL"}
{"ts":"2026-08-23T17:54:04.730Z","event_type":"best_bid_ask","market_id":"3790415","outcome_index":0,"market_type":"set2","local_side":"home","local_uid":"2026-08-23_pierre_hugues_herbert_quinn_vandecasteele","bid":0.56,"ask":0.66,"mid":0.61,"spread":0.1,"bid_size":null,"ask_size":null}
{"ts":"2026-08-23T17:54:04.730Z","event_type":"best_bid_ask","market_id":"3790415","outcome_index":1,"market_type":"set2","local_side":"away","local_uid":"2026-08-23_pierre_hugues_herbert_quinn_vandecasteele","bid":0.34,"ask":0.44,"mid":0.39,"spread":0.1,"bid_size":null,"ask_size":null}
{"ts":"2026-08-23T17:54:04.730Z","event_type":"price_change","market_id":"3790415","outcome_index":0,"market_type":"set2","local_side":"home","local_uid":"2026-08-23_pierre_hugues_herbert_quinn_vandecasteele","bid":0.56,"ask":0.66,"mid":0.61,"spread":0.1,"price":0.56,"size":150.0,"side":"BUY"}
{"ts":"2026-08-23T17:54:04.731Z","event_type":"price_change","market_id":"3790415","outcome_index":1,"market_type":"set2","local_side":"away","local_uid":"2026-08-23_pierre_hugues_herbert_quinn_vandecasteele","bid":0.34,"ask":0.44,"mid":0.39,"spread":0.1,"price":0.44,"size":150.0,"side":"SELL"}
{"ts":"2026-08-23T17:54:04.764Z","event_type":"best_bid_ask","market_id":"3790394","outcome_index":0,"market_type":"set1","local_side":"home","local_uid":"2026-08-23_hugo_grenier_mees_rottgering","bid":0.15,"ask":0.41,"mid":0.28,"spread":0.26,"bid_size":null,"ask_size":null}
{"ts":"2026-08-23T17:54:04.764Z","event_type":"best_bid_ask","market_id":"3790394","outcome_index":1,"market_type":"set1","local_side":"away","local_uid":"2026-08-23_hugo_grenier_mees_rottgering","bid":0.59,"ask":0.85,"mid":0.72,"spread":0.26,"bid_size":null,"ask_size":null}
{"ts":"2026-08-23T17:54:04.764Z","event_type":"price_change","market_id":"3790394","outcome_index":0,"market_type":"set1","local_side":"home","local_uid":"2026-08-23_hugo_grenier_mees_rottgering","bid":0.15,"ask":0.41,"mid":0.28,"spread":0.26,"price":0.15,"size":22.0,"side":"BUY"}
{"ts":"2026-08-23T17:54:04.764Z","event_type":"price_change","market_id":"3790394","outcome_index":1,"market_type":"set1","local_side":"away","local_uid":"2026-08-23_hugo_grenier_mees_rottgering","bid":0.59,"ask":0.85,"mid":0.72,"spread":0.26,"price":0.85,"size":22.0,"side":"SELL"}
{"ts":"2026-08-23T17:54:05.174Z","event_type":"best_bid_ask","market_id":"3790397","outcome_index":0,"market_type":"set2","local_side":"home","local_uid":"2026-08-23_hugo_grenier_mees_rottgering","bid":0.29,"ask":0.42,"mid":0.355,"spread":0.13,"bid_size":null,"ask_size":null}
{"ts":"2026-08-23T17:54:05.174Z","event_type":"best_bid_ask","market_id":"3790397","outcome_index":1,"market_type":"set2","local_side":"away","local_uid":"2026-08-23_hugo_grenier_mees_rottgering","bid":0.58,"ask":0.71,"mid":0.645,"spread":0.13,"bid_size":null,"ask_size":null}
{"ts":"2026-08-23T17:54:05.175Z","event_type":"price_change","market_id":"3790397","outcome_index":1,"market_type":"set2","local_side":"away","local_uid":"2026-08-23_hugo_grenier_mees_rottgering","bid":0.58,"ask":0.71,"mid":0.645,"spread":0.13,"price":0.59,"size":0.0,"side":"BUY"}
{"ts":"2026-08-23T17:54:05.175Z","event_type":"price_change","market_id":"3790397","outcome_index":0,"market_type":"set2","local_side":"home","local_uid":"2026-08-23_hugo_grenier_mees_rottgering","bid":0.29,"ask":0.42,"mid":0.355,"spread":0.13,"price":0.41,"size":0.0,"side":"SELL"}
{"ts":"2026-08-23T17:54:05.222Z","event_type":"best_bid_ask","market_id":"3790397","outcome_index":0,"market_type":"set2","local_side":"home","local_uid":"2026-08-23_hugo_grenier_mees_rottgering","bid":0.29,"ask":0.41,"mid":0.35,"spread":0.12,"bid_size":null,"ask_size":null}
{"ts":"2026-08-23T17:54:05.222Z","event_type":"best_bid_ask","market_id":"3790397","outcome_index":1,"market_type":"set2","local_side":"away","local_uid":"2026-08-23_hugo_grenier_mees_rottgering","bid":0.59,"ask":0.71,"mid":0.65,"spread":0.12,"bid_size":null,"ask_size":null}
{"ts":"2026-08-23T17:54:05.222Z","event_type":"price_change","market_id":"3790397","outcome_index":1,"market_type":"set2","local_side":"away","local_uid":"2026-08-23_hugo_grenier_mees_rottgering","bid":0.59,"ask":0.71,"mid":0.65,"spread":0.12,"price":0.59,"size":99.21,"side":"BUY"}
{"ts":"2026-08-23T17:54:05.223Z","event_type":"price_change","market_id":"3790397","outcome_index":0,"market_type":"set2","local_side":"home","local_uid":"2026-08-23_hugo_grenier_mees_rottgering","bid":0.29,"ask":0.41,"mid":0.35,"spread":0.12,"price":0.41,"size":99.21,"side":"SELL"}
{"ts":"2026-08-23T17:54:05.399Z","event_type":"best_bid_ask","market_id":"3789929","outcome_index":0,"market_type":"match","local_side":"home","local_uid":"2026-08-23_felix_balshaw_sebastian_gorzny","bid":0.38,"ask":0.42,"mid":0.4,"spread":0.04,"bid_size":null,"ask_size":null}
{"ts":"2026-08-23T17:54:05.399Z","event_type":"best_bid_ask","market_id":"3789929","outcome_index":1,"market_type":"match","local_side":"away","local_uid":"2026-08-23_felix_balshaw_sebastian_gorzny","bid":0.58,"ask":0.62,"mid":0.6,"spread":0.04,"bid_size":null,"ask_size":null}
{"ts":"2026-08-23T17:54:05.399Z","event_type":"price_change","market_id":"3789929","outcome_index":1,"market_type":"match","local_side":"away","local_uid":"2026-08-23_felix_balshaw_sebastian_gorzny","bid":0.58,"ask":0.62,"mid":0.6,"spread":0.04,"price":0.58,"size":67.0,"side":"BUY"}
{"ts":"2026-08-23T17:54:05.399Z","event_type":"price_change","market_id":"3789929","outcome_index":0,"market_type":"match","local_side":"home","local_uid":"2026-08-23_felix_balshaw_sebastian_gorzny","bid":0.38,"ask":0.42,"mid":0.4,"spread":0.04,"price":0.42,"size":67.0,"side":"SELL"}
{"ts":"2026-08-23T17:54:05.743Z","event_type":"price_change","market_id":"3780820","outcome_index":1,"market_type":"match","local_side":"away","local_uid":"2026-08-23_sho_shimabukuro_miomir_kecmanovic","bid":0.68,"ask":0.69,"mid":0.685,"spread":0.01,"price":0.39,"size":27.98,"side":"BUY"}
{"ts":"2026-08-23T17:54:05.743Z","event_type":"price_change","market_id":"3780820","outcome_index":0,"market_type":"match","local_side":"home","local_uid":"2026-08-23_sho_shimabukuro_miomir_kecmanovic","bid":0.31,"ask":0.32,"mid":0.315,"spread":0.01,"price":0.61,"size":27.98,"side":"SELL"}
{"ts":"2026-08-23T17:54:05.753Z","event_type":"best_bid_ask","market_id":"3790323","outcome_index":0,"market_type":"set2","local_side":"home","local_uid":"2026-08-23_felix_balshaw_sebastian_gorzny","bid":0.57,"ask":0.83,"mid":0.7,"spread":0.26,"bid_size":null,"ask_size":null}
{"ts":"2026-08-23T17:54:05.753Z","event_type":"best_bid_ask","market_id":"3790323","outcome_index":1,"market_type":"set2","local_side":"away","local_uid":"2026-08-23_felix_balshaw_sebastian_gorzny","bid":0.17,"ask":0.43,"mid":0.3,"spread":0.26,"bid_size":null,"ask_size":null}
{"ts":"2026-08-23T17:54:05.753Z","event_type":"price_change","market_id":"3790323","outcome_index":0,"market_type":"set2","local_side":"home","local_uid":"2026-08-23_felix_balshaw_sebastian_gorzny","bid":0.57,"ask":0.83,"mid":0.7,"spread":0.26,"price":0.57,"size":150.0,"side":"BUY"}
{"ts":"2026-08-23T17:54:05.753Z","event_type":"price_change","market_id":"3790323","outcome_index":1,"market_type":"set2","local_side":"away","local_uid":"2026-08-23_felix_balshaw_sebastian_gorzny","bid":0.17,"ask":0.43,"mid":0.3,"spread":0.26,"price":0.43,"size":150.0,"side":"SELL"}
{"ts":"2026-08-23T17:54:05.757Z","event_type":"best_bid_ask","market_id":"3790323","outcome_index":0,"market_type":"set2","local_side":"home","local_uid":"2026-08-23_felix_balshaw_sebastian_gorzny","bid":0.58,"ask":0.83,"mid":0.705,"spread":0.25,"bid_size":null,"ask_size":null}
{"ts":"2026-08-23T17:54:05.757Z","event_type":"best_bid_ask","market_id":"3790323","outcome_index":1,"market_type":"set2","local_side":"away","local_uid":"2026-08-23_felix_balshaw_sebastian_gorzny","bid":0.17,"ask":0.42,"mid":0.295,"spread":0.25,"bid_size":null,"ask_size":null}
{"ts":"2026-08-23T17:54:05.757Z","event_type":"price_change","market_id":"3790323","outcome_index":0,"market_type":"set2","local_side":"home","local_uid":"2026-08-23_felix_balshaw_sebastian_gorzny","bid":0.58,"ask":0.83,"mid":0.705,"spread":0.25,"price":0.58,"size":131.86,"side":"BUY"}
{"ts":"2026-08-23T17:54:05.757Z","event_type":"price_change","market_id":"3790323","outcome_index":1,"market_type":"set2","local_side":"away","local_uid":"2026-08-23_felix_balshaw_sebastian_gorzny","bid":0.17,"ask":0.42,"mid":0.295,"spread":0.25,"price":0.42,"size":131.86,"side":"SELL"}
{"ts":"2026-08-23T17:54:05.779Z","event_type":"best_bid_ask","market_id":"3790415","outcome_index":0,"market_type":"set2","local_side":"home","local_uid":"2026-08-23_pierre_hugues_herbert_quinn_vandecasteele","bid":0.57,"ask":0.66,"mid":0.615,"spread":0.09,"bid_size":null,"ask_size":null}
{"ts":"2026-08-23T17:54:05.779Z","event_type":"best_bid_ask","market_id":"3790415","outcome_index":1,"market_type":"set2","local_side":"away","local_uid":"2026-08-23_pierre_hugues_herbert_quinn_vandecasteele","bid":0.34,"ask":0.43,"mid":0.385,"spread":0.09,"bid_size":null,"ask_size":null}
{"ts":"2026-08-23T17:54:05.779Z","event_type":"price_change","market_id":"3790415","outcome_index":0,"market_type":"set2","local_side":"home","local_uid":"2026-08-23_pierre_hugues_herbert_quinn_vandecasteele","bid":0.57,"ask":0.66,"mid":0.615,"spread":0.09,"price":0.57,"size":150.0,"side":"BUY"}
{"ts":"2026-08-23T17:54:05.779Z","event_type":"price_change","market_id":"3790415","outcome_index":1,"market_type":"set2","local_side":"away","local_uid":"2026-08-23_pierre_hugues_herbert_quinn_vandecasteele","bid":0.34,"ask":0.43,"mid":0.385,"spread":0.09,"price":0.43,"size":150.0,"side":"SELL"}
{"ts":"2026-08-23T17:54:05.918Z","event_type":"best_bid_ask","market_id":"3790415","outcome_index":0,"market_type":"set2","local_side":"home","local_uid":"2026-08-23_pierre_hugues_herbert_quinn_vandecasteele","bid":0.58,"ask":0.66,"mid":0.62,"spread":0.08,"bid_size":null,"ask_size":null}
{"ts":"2026-08-23T17:54:05.918Z","event_type":"best_bid_ask","market_id":"3790415","outcome_index":1,"market_type":"set2","local_side":"away","local_uid":"2026-08-23_pierre_hugues_herbert_quinn_vandecasteele","bid":0.34,"ask":0.42,"mid":0.38,"spread":0.08,"bid_size":null,"ask_size":null}
{"ts":"2026-08-23T17:54:05.918Z","event_type":"price_change","market_id":"3790415","outcome_index":0,"market_type":"set2","local_side":"home","local_uid":"2026-08-23_pierre_hugues_herbert_quinn_vandecasteele","bid":0.58,"ask":0.66,"mid":0.62,"spread":0.08,"price":0.58,"size":150.0,"side":"BUY"}
{"ts":"2026-08-23T17:54:05.918Z","event_type":"price_change","market_id":"3790415","outcome_index":1,"market_type":"set2","local_side":"away","local_uid":"2026-08-23_pierre_hugues_herbert_quinn_vandecasteele","bid":0.34,"ask":0.42,"mid":0.38,"spread":0.08,"price":0.42,"size":150.0,"side":"SELL"}
{"ts":"2026-08-23T17:54:05.919Z","event_type":"best_bid_ask","market_id":"3790323","outcome_index":0,"market_type":"set2","local_side":"home","local_uid":"2026-08-23_felix_balshaw_sebastian_gorzny","bid":0.58,"ask":0.82,"mid":0.7,"spread":0.24,"bid_size":null,"ask_size":null}
{"ts":"2026-08-23T17:54:05.919Z","event_type":"best_bid_ask","market_id":"3790323","outcome_index":1,"market_type":"set2","local_side":"away","local_uid":"2026-08-23_felix_balshaw_sebastian_gorzny","bid":0.18,"ask":0.42,"mid":0.3,"spread":0.24,"bid_size":null,"ask_size":null}
{"ts":"2026-08-23T17:54:05.919Z","event_type":"price_change","market_id":"3790323","outcome_index":1,"market_type":"set2","local_side":"away","local_uid":"2026-08-23_felix_balshaw_sebastian_gorzny","bid":0.18,"ask":0.42,"mid":0.3,"spread":0.24,"price":0.18,"size":150.0,"side":"BUY"}
{"ts":"2026-08-23T17:54:05.919Z","event_type":"price_change","market_id":"3790323","outcome_index":0,"market_type":"set2","local_side":"home","local_uid":"2026-08-23_felix_balshaw_sebastian_gorzny","bid":0.58,"ask":0.82,"mid":0.7,"spread":0.24,"price":0.82,"size":150.0,"side":"SELL"}
{"ts":"2026-08-23T17:54:05.920Z","event_type":"best_bid_ask","market_id":"3790323","outcome_index":0,"market_type":"set2","local_side":"home","local_uid":"2026-08-23_felix_balshaw_sebastian_gorzny","bid":0.58,"ask":0.8,"mid":0.69,"spread":0.22,"bid_size":null,"ask_size":null}
{"ts":"2026-08-23T17:54:05.920Z","event_type":"best_bid_ask","market_id":"3790323","outcome_index":1,"market_type":"set2","local_side":"away","local_uid":"2026-08-23_felix_balshaw_sebastian_gorzny","bid":0.2,"ask":0.42,"mid":0.31,"spread":0.22,"bid_size":null,"ask_size":null}
{"ts":"2026-08-23T17:54:05.920Z","event_type":"price_change","market_id":"3790323","outcome_index":1,"market_type":"set2","local_side":"away","local_uid":"2026-08-23_felix_balshaw_sebastian_gorzny","bid":0.2,"ask":0.42,"mid":0.31,"spread":0.22,"price":0.2,"size":74.78,"side":"BUY"}
{"ts":"2026-08-23T17:54:05.920Z","event_type":"price_change","market_id":"3790323","outcome_index":0,"market_type":"set2","local_side":"home","local_uid":"2026-08-23_felix_balshaw_sebastian_gorzny","bid":0.58,"ask":0.8,"mid":0.69,"spread":0.22,"price":0.8,"size":74.78,"side":"SELL"}
{"ts":"2026-08-23T17:54:06.087Z","event_type":"price_change","market_id":"3780832","outcome_index":1,"market_type":"match","local_side":"away","local_uid":"2026-08-23_francisco_comesana_yibing_wu","bid":0.61,"ask":0.62,"mid":0.615,"spread":0.01,"price":0.41,"size":0.0,"side":"BUY"}
{"ts":"2026-08-23T17:54:06.087Z","event_type":"price_change","market_id":"3780832","outcome_index":0,"market_type":"match","local_side":"home","local_uid":"2026-08-23_francisco_comesana_yibing_wu","bid":0.38,"ask":0.39,"mid":0.385,"spread":0.01,"price":0.59,"size":0.0,"side":"SELL"}
{"ts":"2026-08-23T17:54:06.420Z","event_type":"best_bid_ask","market_id":"3789997","outcome_index":0,"market_type":"match","local_side":"home","local_uid":"2026-08-23_oscar_weightman_alec_deckers","bid":0.05,"ask":0.07,"mid":0.06,"spread":0.02,"bid_size":null,"ask_size":null}
{"ts":"2026-08-23T17:54:06.420Z","event_type":"best_bid_ask","market_id":"3789997","outcome_index":1,"market_type":"match","local_side":"away","local_uid":"2026-08-23_oscar_weightman_alec_deckers","bid":0.93,"ask":0.95,"mid":0.94,"spread":0.02,"bid_size":null,"ask_size":null}
{"ts":"2026-08-23T17:54:06.420Z","event_type":"price_change","market_id":"3789997","outcome_index":0,"market_type":"match","local_side":"home","local_uid":"2026-08-23_oscar_weightman_alec_deckers","bid":0.05,"ask":0.07,"mid":0.06,"spread":0.02,"price":0.06,"size":0.0,"side":"BUY"}
{"ts":"2026-08-23T17:54:06.420Z","event_type":"price_change","market_id":"3789997","outcome_index":1,"market_type":"match","local_side":"away","local_uid":"2026-08-23_oscar_weightman_alec_deckers","bid":0.93,"ask":0.95,"mid":0.94,"spread":0.02,"price":0.94,"size":0.0,"side":"SELL"}
{"ts":"2026-08-23T17:54:06.620Z","event_type":"best_bid_ask","market_id":"3790334","outcome_index":0,"market_type":"set2","local_side":"home","local_uid":"2026-08-23_abdullah_shelbayh_dhakshineswar_suresh","bid":0.48,"ask":0.52,"mid":0.5,"spread":0.04,"bid_size":null,"ask_size":null}
{"ts":"2026-08-23T17:54:06.620Z","event_type":"best_bid_ask","market_id":"3790334","outcome_index":1,"market_type":"set2","local_side":"away","local_uid":"2026-08-23_abdullah_shelbayh_dhakshineswar_suresh","bid":0.48,"ask":0.52,"mid":0.5,"spread":0.04,"bid_size":null,"ask_size":null}
{"ts":"2026-08-23T17:54:06.620Z","event_type":"price_change","market_id":"3790334","outcome_index":1,"market_type":"set2","local_side":"away","local_uid":"2026-08-23_abdullah_shelbayh_dhakshineswar_suresh","bid":0.48,"ask":0.52,"mid":0.5,"spread":0.04,"price":0.49,"size":0.0,"side":"BUY"}
{"ts":"2026-08-23T17:54:06.620Z","event_type":"price_change","market_id":"3790334","outcome_index":0,"market_type":"set2","local_side":"home","local_uid":"2026-08-23_abdullah_shelbayh_dhakshineswar_suresh","bid":0.48,"ask":0.52,"mid":0.5,"spread":0.04,"price":0.51,"size":0.0,"side":"SELL"}
{"ts":"2026-08-23T17:54:06.646Z","event_type":"best_bid_ask","market_id":"3790334","outcome_index":0,"market_type":"set2","local_side":"home","local_uid":"2026-08-23_abdullah_shelbayh_dhakshineswar_suresh","bid":0.48,"ask":0.51,"mid":0.495,"spread":0.03,"bid_size":null,"ask_size":null}
{"ts":"2026-08-23T17:54:06.646Z","event_type":"best_bid_ask","market_id":"3790334","outcome_index":1,"market_type":"set2","local_side":"away","local_uid":"2026-08-23_abdullah_shelbayh_dhakshineswar_suresh","bid":0.49,"ask":0.52,"mid":0.505,"spread":0.03,"bid_size":null,"ask_size":null}
{"ts":"2026-08-23T17:54:06.646Z","event_type":"price_change","market_id":"3790334","outcome_index":1,"market_type":"set2","local_side":"away","local_uid":"2026-08-23_abdullah_shelbayh_dhakshineswar_suresh","bid":0.49,"ask":0.52,"mid":0.505,"spread":0.03,"price":0.49,"size":86.59,"side":"BUY"}
{"ts":"2026-08-23T17:54:06.646Z","event_type":"price_change","market_id":"3790334","outcome_index":0,"market_type":"set2","local_side":"home","local_uid":"2026-08-23_abdullah_shelbayh_dhakshineswar_suresh","bid":0.48,"ask":0.51,"mid":0.495,"spread":0.03,"price":0.51,"size":86.59,"side":"SELL"}
{"ts":"2026-08-23T17:54:06.720Z","event_type":"best_bid_ask","market_id":"3790334","outcome_index":0,"market_type":"set2","local_side":"home","local_uid":"2026-08-23_abdullah_shelbayh_dhakshineswar_suresh","bid":0.48,"ask":0.52,"mid":0.5,"spread":0.04,"bid_size":null,"ask_size":null}
{"ts":"2026-08-23T17:54:06.720Z","event_type":"best_bid_ask","market_id":"3790334","outcome_index":1,"market_type":"set2","local_side":"away","local_uid":"2026-08-23_abdullah_shelbayh_dhakshineswar_suresh","bid":0.48,"ask":0.52,"mid":0.5,"spread":0.04,"bid_size":null,"ask_size":null}
{"ts":"2026-08-23T17:54:06.720Z","event_type":"price_change","market_id":"3790334","outcome_index":1,"market_type":"set2","local_side":"away","local_uid":"2026-08-23_abdullah_shelbayh_dhakshineswar_suresh","bid":0.48,"ask":0.52,"mid":0.5,"spread":0.04,"price":0.49,"size":0.0,"side":"BUY"}
{"ts":"2026-08-23T17:54:06.720Z","event_type":"price_change","market_id":"3790334","outcome_index":0,"market_type":"set2","local_side":"home","local_uid":"2026-08-23_abdullah_shelbayh_dhakshineswar_suresh","bid":0.48,"ask":0.52,"mid":0.5,"spread":0.04,"price":0.51,"size":0.0,"side":"SELL"}
{"ts":"2026-08-23T17:54:06.770Z","event_type":"best_bid_ask","market_id":"3790334","outcome_index":0,"market_type":"set2","local_side":"home","local_uid":"2026-08-23_abdullah_shelbayh_dhakshineswar_suresh","bid":0.48,"ask":0.51,"mid":0.495,"spread":0.03,"bid_size":null,"ask_size":null}
{"ts":"2026-08-23T17:54:06.770Z","event_type":"best_bid_ask","market_id":"3790334","outcome_index":1,"market_type":"set2","local_side":"away","local_uid":"2026-08-23_abdullah_shelbayh_dhakshineswar_suresh","bid":0.49,"ask":0.52,"mid":0.505,"spread":0.03,"bid_size":null,"ask_size":null}
{"ts":"2026-08-23T17:54:06.770Z","event_type":"price_change","market_id":"3790334","outcome_index":1,"market_type":"set2","local_side":"away","local_uid":"2026-08-23_abdullah_shelbayh_dhakshineswar_suresh","bid":0.49,"ask":0.52,"mid":0.505,"spread":0.03,"price":0.49,"size":76.98,"side":"BUY"}
{"ts":"2026-08-23T17:54:06.770Z","event_type":"price_change","market_id":"3790334","outcome_index":0,"market_type":"set2","local_side":"home","local_uid":"2026-08-23_abdullah_shelbayh_dhakshineswar_suresh","bid":0.48,"ask":0.51,"mid":0.495,"spread":0.03,"price":0.51,"size":76.98,"side":"SELL"}
{"ts":"2026-08-23T17:54:06.853Z","event_type":"best_bid_ask","market_id":"3789929","outcome_index":0,"market_type":"match","local_side":"home","local_uid":"2026-08-23_felix_balshaw_sebastian_gorzny","bid":0.39,"ask":0.42,"mid":0.405,"spread":0.03,"bid_size":null,"ask_size":null}
{"ts":"2026-08-23T17:54:06.853Z","event_type":"best_bid_ask","market_id":"3789929","outcome_index":1,"market_type":"match","local_side":"away","local_uid":"2026-08-23_felix_balshaw_sebastian_gorzny","bid":0.58,"ask":0.61,"mid":0.595,"spread":0.03,"bid_size":null,"ask_size":null}
{"ts":"2026-08-23T17:54:06.853Z","event_type":"price_change","market_id":"3789929","outcome_index":0,"market_type":"match","local_side":"home","local_uid":"2026-08-23_felix_balshaw_sebastian_gorzny","bid":0.39,"ask":0.42,"mid":0.405,"spread":0.03,"price":0.39,"size":100.0,"side":"BUY"}
{"ts":"2026-08-23T17:54:06.853Z","event_type":"price_change","market_id":"3789929","outcome_index":1,"market_type":"match","local_side":"away","local_uid":"2026-08-23_felix_balshaw_sebastian_gorzny","bid":0.58,"ask":0.61,"mid":0.595,"spread":0.03,"price":0.61,"size":100.0,"side":"SELL"}
{"ts":"2026-08-23T17:54:06.874Z","event_type":"best_bid_ask","market_id":"3790334","outcome_index":0,"market_type":"set2","local_side":"home","local_uid":"2026-08-23_abdullah_shelbayh_dhakshineswar_suresh","bid":0.48,"ask":0.54,"mid":0.51,"spread":0.06,"bid_size":null,"ask_size":null}
{"ts":"2026-08-23T17:54:06.875Z","event_type":"best_bid_ask","market_id":"3790334","outcome_index":1,"market_type":"set2","local_side":"away","local_uid":"2026-08-23_abdullah_shelbayh_dhakshineswar_suresh","bid":0.46,"ask":0.52,"mid":0.49,"spread":0.06,"bid_size":null,"ask_size":null}
{"ts":"2026-08-23T17:54:06.875Z","event_type":"price_change","market_id":"3790334","outcome_index":1,"market_type":"set2","local_side":"away","local_uid":"2026-08-23_abdullah_shelbayh_dhakshineswar_suresh","bid":0.46,"ask":0.52,"mid":0.49,"spread":0.06,"price":0.49,"size":0.0,"side":"BUY"}
{"ts":"2026-08-23T17:54:06.875Z","event_type":"price_change","market_id":"3790334","outcome_index":0,"market_type":"set2","local_side":"home","local_uid":"2026-08-23_abdullah_shelbayh_dhakshineswar_suresh","bid":0.48,"ask":0.54,"mid":0.51,"spread":0.06,"price":0.51,"size":0.0,"side":"SELL"}
{"ts":"2026-08-23T17:54:06.884Z","event_type":"best_bid_ask","market_id":"3790394","outcome_index":0,"market_type":"set1","local_side":"home","local_uid":"2026-08-23_hugo_grenier_mees_rottgering","bid":0.16,"ask":0.41,"mid":0.285,"spread":0.25,"bid_size":null,"ask_size":null}
{"ts":"2026-08-23T17:54:06.884Z","event_type":"best_bid_ask","market_id":"3790394","outcome_index":1,"market_type":"set1","local_side":"away","local_uid":"2026-08-23_hugo_grenier_mees_rottgering","bid":0.59,"ask":0.84,"mid":0.715,"spread":0.25,"bid_size":null,"ask_size":null}
{"ts":"2026-08-23T17:54:06.884Z","event_type":"price_change","market_id":"3790394","outcome_index":0,"market_type":"set1","local_side":"home","local_uid":"2026-08-23_hugo_grenier_mees_rottgering","bid":0.16,"ask":0.41,"mid":0.285,"spread":0.25,"price":0.16,"size":28.04,"side":"BUY"}
{"ts":"2026-08-23T17:54:06.884Z","event_type":"price_change","market_id":"3790394","outcome_index":1,"market_type":"set1","local_side":"away","local_uid":"2026-08-23_hugo_grenier_mees_rottgering","bid":0.59,"ask":0.84,"mid":0.715,"spread":0.25,"price":0.84,"size":28.04,"side":"SELL"}
{"ts":"2026-08-23T17:54:07.013Z","event_type":"best_bid_ask","market_id":"3790334","outcome_index":0,"market_type":"set2","local_side":"home","local_uid":"2026-08-23_abdullah_shelbayh_dhakshineswar_suresh","bid":0.48,"ask":0.53,"mid":0.505,"spread":0.05,"bid_size":null,"ask_size":null}
{"ts":"2026-08-23T17:54:07.013Z","event_type":"best_bid_ask","market_id":"3790334","outcome_index":1,"market_type":"set2","local_side":"away","local_uid":"2026-08-23_abdullah_shelbayh_dhakshineswar_suresh","bid":0.47,"ask":0.52,"mid":0.495,"spread":0.05,"bid_size":null,"ask_size":null}
{"ts":"2026-08-23T17:54:07.013Z","event_type":"price_change","market_id":"3790334","outcome_index":1,"market_type":"set2","local_side":"away","local_uid":"2026-08-23_abdullah_shelbayh_dhakshineswar_suresh","bid":0.47,"ask":0.52,"mid":0.495,"spread":0.05,"price":0.47,"size":150.0,"side":"BUY"}
{"ts":"2026-08-23T17:54:07.013Z","event_type":"price_change","market_id":"3790334","outcome_index":0,"market_type":"set2","local_side":"home","local_uid":"2026-08-23_abdullah_shelbayh_dhakshineswar_suresh","bid":0.48,"ask":0.53,"mid":0.505,"spread":0.05,"price":0.53,"size":150.0,"side":"SELL"}
{"ts":"2026-08-23T17:54:07.034Z","event_type":"best_bid_ask","market_id":"3790415","outcome_index":0,"market_type":"set2","local_side":"home","local_uid":"2026-08-23_pierre_hugues_herbert_quinn_vandecasteele","bid":0.57,"ask":0.66,"mid":0.615,"spread":0.09,"bid_size":null,"ask_size":null}
{"ts":"2026-08-23T17:54:07.034Z","event_type":"best_bid_ask","market_id":"3790415","outcome_index":1,"market_type":"set2","local_side":"away","local_uid":"2026-08-23_pierre_hugues_herbert_quinn_vandecasteele","bid":0.34,"ask":0.43,"mid":0.385,"spread":0.09,"bid_size":null,"ask_size":null}
{"ts":"2026-08-23T17:54:07.035Z","event_type":"price_change","market_id":"3790415","outcome_index":0,"market_type":"set2","local_side":"home","local_uid":"2026-08-23_pierre_hugues_herbert_quinn_vandecasteele","bid":0.57,"ask":0.66,"mid":0.615,"spread":0.09,"price":0.58,"size":0.0,"side":"BUY"}
{"ts":"2026-08-23T17:54:07.035Z","event_type":"price_change","market_id":"3790415","outcome_index":1,"market_type":"set2","local_side":"away","local_uid":"2026-08-23_pierre_hugues_herbert_quinn_vandecasteele","bid":0.34,"ask":0.43,"mid":0.385,"spread":0.09,"price":0.42,"size":0.0,"side":"SELL"}
{"ts":"2026-08-23T17:54:07.048Z","event_type":"best_bid_ask","market_id":"3790415","outcome_index":0,"market_type":"set2","local_side":"home","local_uid":"2026-08-23_pierre_hugues_herbert_quinn_vandecasteele","bid":0.55,"ask":0.66,"mid":0.605,"spread":0.11,"bid_size":null,"ask_size":null}
{"ts":"2026-08-23T17:54:07.048Z","event_type":"best_bid_ask","market_id":"3790415","outcome_index":1,"market_type":"set2","local_side":"away","local_uid":"2026-08-23_pierre_hugues_herbert_quinn_vandecasteele","bid":0.34,"ask":0.45,"mid":0.395,"spread":0.11,"bid_size":null,"ask_size":null}
{"ts":"2026-08-23T17:54:07.048Z","event_type":"price_change","market_id":"3790415","outcome_index":0,"market_type":"set2","local_side":"home","local_uid":"2026-08-23_pierre_hugues_herbert_quinn_vandecasteele","bid":0.55,"ask":0.66,"mid":0.605,"spread":0.11,"price":0.57,"size":0.0,"side":"BUY"}
{"ts":"2026-08-23T17:54:07.049Z","event_type":"price_change","market_id":"3790415","outcome_index":1,"market_type":"set2","local_side":"away","local_uid":"2026-08-23_pierre_hugues_herbert_quinn_vandecasteele","bid":0.34,"ask":0.45,"mid":0.395,"spread":0.11,"price":0.43,"size":0.0,"side":"SELL"}
{"ts":"2026-08-23T17:54:07.074Z","event_type":"best_bid_ask","market_id":"3790415","outcome_index":0,"market_type":"set2","local_side":"home","local_uid":"2026-08-23_pierre_hugues_herbert_quinn_vandecasteele","bid":0.56,"ask":0.66,"mid":0.61,"spread":0.1,"bid_size":null,"ask_size":null}
{"ts":"2026-08-23T17:54:07.074Z","event_type":"best_bid_ask","market_id":"3790415","outcome_index":1,"market_type":"set2","local_side":"away","local_uid":"2026-08-23_pierre_hugues_herbert_quinn_vandecasteele","bid":0.34,"ask":0.44,"mid":0.39,"spread":0.1,"bid_size":null,"ask_size":null}
{"ts":"2026-08-23T17:54:07.074Z","event_type":"price_change","market_id":"3790415","outcome_index":0,"market_type":"set2","local_side":"home","local_uid":"2026-08-23_pierre_hugues_herbert_quinn_vandecasteele","bid":0.56,"ask":0.66,"mid":0.61,"spread":0.1,"price":0.56,"size":150.0,"side":"BUY"}
{"ts":"2026-08-23T17:54:07.074Z","event_type":"price_change","market_id":"3790415","outcome_index":1,"market_type":"set2","local_side":"away","local_uid":"2026-08-23_pierre_hugues_herbert_quinn_vandecasteele","bid":0.34,"ask":0.44,"mid":0.39,"spread":0.1,"price":0.44,"size":150.0,"side":"SELL"}
{"ts":"2026-08-23T17:54:07.651Z","event_type":"price_change","market_id":"3789271","outcome_index":0,"market_type":"match","local_side":"home","local_uid":"2026-08-23_panna_udvardy_darja_vidmanova","bid":0.33,"ask":0.34,"mid":0.335,"spread":0.01,"price":0.17,"size":28.0,"side":"BUY"}
{"ts":"2026-08-23T17:54:07.652Z","event_type":"price_change","market_id":"3789271","outcome_index":1,"market_type":"match","local_side":"away","local_uid":"2026-08-23_panna_udvardy_darja_vidmanova","bid":0.66,"ask":0.67,"mid":0.665,"spread":0.01,"price":0.83,"size":28.0,"side":"SELL"}
{"ts":"2026-08-23T17:54:07.800Z","event_type":"best_bid_ask","market_id":"3790415","outcome_index":0,"market_type":"set2","local_side":"home","local_uid":"2026-08-23_pierre_hugues_herbert_quinn_vandecasteele","bid":0.57,"ask":0.66,"mid":0.615,"spread":0.09,"bid_size":null,"ask_size":null}
{"ts":"2026-08-23T17:54:07.800Z","event_type":"best_bid_ask","market_id":"3790415","outcome_index":1,"market_type":"set2","local_side":"away","local_uid":"2026-08-23_pierre_hugues_herbert_quinn_vandecasteele","bid":0.34,"ask":0.43,"mid":0.385,"spread":0.09,"bid_size":null,"ask_size":null}
{"ts":"2026-08-23T17:54:07.800Z","event_type":"price_change","market_id":"3790415","outcome_index":0,"market_type":"set2","local_side":"home","local_uid":"2026-08-23_pierre_hugues_herbert_quinn_vandecasteele","bid":0.57,"ask":0.66,"mid":0.615,"spread":0.09,"price":0.57,"size":150.0,"side":"BUY"}
{"ts":"2026-08-23T17:54:07.801Z","event_type":"price_change","market_id":"3790415","outcome_index":1,"market_type":"set2","local_side":"away","local_uid":"2026-08-23_pierre_hugues_herbert_quinn_vandecasteele","bid":0.34,"ask":0.43,"mid":0.385,"spread":0.09,"price":0.43,"size":150.0,"side":"SELL"}
{"ts":"2026-08-23T17:54:07.880Z","event_type":"best_bid_ask","market_id":"3790415","outcome_index":0,"market_type":"set2","local_side":"home","local_uid":"2026-08-23_pierre_hugues_herbert_quinn_vandecasteele","bid":0.58,"ask":0.66,"mid":0.62,"spread":0.08,"bid_size":null,"ask_size":null}
{"ts":"2026-08-23T17:54:07.880Z","event_type":"best_bid_ask","market_id":"3790415","outcome_index":1,"market_type":"set2","local_side":"away","local_uid":"2026-08-23_pierre_hugues_herbert_quinn_vandecasteele","bid":0.34,"ask":0.42,"mid":0.38,"spread":0.08,"bid_size":null,"ask_size":null}
{"ts":"2026-08-23T17:54:07.880Z","event_type":"price_change","market_id":"3790415","outcome_index":0,"market_type":"set2","local_side":"home","local_uid":"2026-08-23_pierre_hugues_herbert_quinn_vandecasteele","bid":0.58,"ask":0.66,"mid":0.62,"spread":0.08,"price":0.58,"size":31.98,"side":"BUY"}
{"ts":"2026-08-23T17:54:07.880Z","event_type":"price_change","market_id":"3790415","outcome_index":1,"market_type":"set2","local_side":"away","local_uid":"2026-08-23_pierre_hugues_herbert_quinn_vandecasteele","bid":0.34,"ask":0.42,"mid":0.38,"spread":0.08,"price":0.42,"size":31.98,"side":"SELL"}
{"ts":"2026-08-23T17:54:07.904Z","event_type":"best_bid_ask","market_id":"3790394","outcome_index":0,"market_type":"set1","local_side":"home","local_uid":"2026-08-23_hugo_grenier_mees_rottgering","bid":0.19,"ask":0.41,"mid":0.3,"spread":0.22,"bid_size":null,"ask_size":null}
{"ts":"2026-08-23T17:54:07.904Z","event_type":"best_bid_ask","market_id":"3790394","outcome_index":1,"market_type":"set1","local_side":"away","local_uid":"2026-08-23_hugo_grenier_mees_rottgering","bid":0.59,"ask":0.81,"mid":0.7,"spread":0.22,"bid_size":null,"ask_size":null}
{"ts":"2026-08-23T17:54:07.904Z","event_type":"price_change","market_id":"3790394","outcome_index":0,"market_type":"set1","local_side":"home","local_uid":"2026-08-23_hugo_grenier_mees_rottgering","bid":0.19,"ask":0.41,"mid":0.3,"spread":0.22,"price":0.19,"size":423.0,"side":"BUY"}
{"ts":"2026-08-23T17:54:07.904Z","event_type":"price_change","market_id":"3790394","outcome_index":1,"market_type":"set1","local_side":"away","local_uid":"2026-08-23_hugo_grenier_mees_rottgering","bid":0.59,"ask":0.81,"mid":0.7,"spread":0.22,"price":0.81,"size":423.0,"side":"SELL"}
{"ts":"2026-08-23T17:54:07.904Z","event_type":"best_bid_ask","market_id":"3790394","outcome_index":0,"market_type":"set1","local_side":"home","local_uid":"2026-08-23_hugo_grenier_mees_rottgering","bid":0.19,"ask":0.36,"mid":0.275,"spread":0.17,"bid_size":null,"ask_size":null}
{"ts":"2026-08-23T17:54:07.904Z","event_type":"best_bid_ask","market_id":"3790394","outcome_index":1,"market_type":"set1","local_side":"away","local_uid":"2026-08-23_hugo_grenier_mees_rottgering","bid":0.64,"ask":0.81,"mid":0.725,"spread":0.17,"bid_size":null,"ask_size":null}
{"ts":"2026-08-23T17:54:07.905Z","event_type":"price_change","market_id":"3790394","outcome_index":1,"market_type":"set1","local_side":"away","local_uid":"2026-08-23_hugo_grenier_mees_rottgering","bid":0.64,"ask":0.81,"mid":0.725,"spread":0.17,"price":0.64,"size":423.0,"side":"BUY"}
{"ts":"2026-08-23T17:54:07.905Z","event_type":"price_change","market_id":"3790394","outcome_index":0,"market_type":"set1","local_side":"home","local_uid":"2026-08-23_hugo_grenier_mees_rottgering","bid":0.19,"ask":0.36,"mid":0.275,"spread":0.17,"price":0.36,"size":423.0,"side":"SELL"}
{"ts":"2026-08-23T17:54:07.905Z","event_type":"best_bid_ask","market_id":"3790394","outcome_index":0,"market_type":"set1","local_side":"home","local_uid":"2026-08-23_hugo_grenier_mees_rottgering","bid":0.19,"ask":0.35,"mid":0.27,"spread":0.16,"bid_size":null,"ask_size":null}
{"ts":"2026-08-23T17:54:07.906Z","event_type":"best_bid_ask","market_id":"3790394","outcome_index":1,"market_type":"set1","local_side":"away","local_uid":"2026-08-23_hugo_grenier_mees_rottgering","bid":0.65,"ask":0.81,"mid":0.73,"spread":0.16,"bid_size":null,"ask_size":null}
{"ts":"2026-08-23T17:54:07.906Z","event_type":"price_change","market_id":"3790394","outcome_index":1,"market_type":"set1","local_side":"away","local_uid":"2026-08-23_hugo_grenier_mees_rottgering","bid":0.65,"ask":0.81,"mid":0.73,"spread":0.16,"price":0.65,"size":88.0,"side":"BUY"}
{"ts":"2026-08-23T17:54:07.906Z","event_type":"price_change","market_id":"3790394","outcome_index":0,"market_type":"set1","local_side":"home","local_uid":"2026-08-23_hugo_grenier_mees_rottgering","bid":0.19,"ask":0.35,"mid":0.27,"spread":0.16,"price":0.35,"size":88.0,"side":"SELL"}
{"ts":"2026-08-23T17:54:07.906Z","event_type":"best_bid_ask","market_id":"3790394","outcome_index":0,"market_type":"set1","local_side":"home","local_uid":"2026-08-23_hugo_grenier_mees_rottgering","bid":0.19,"ask":0.34,"mid":0.265,"spread":0.15,"bid_size":null,"ask_size":null}
{"ts":"2026-08-23T17:54:07.906Z","event_type":"best_bid_ask","market_id":"3790394","outcome_index":1,"market_type":"set1","local_side":"away","local_uid":"2026-08-23_hugo_grenier_mees_rottgering","bid":0.66,"ask":0.81,"mid":0.735,"spread":0.15,"bid_size":null,"ask_size":null}
{"ts":"2026-08-23T17:54:07.906Z","event_type":"price_change","market_id":"3790394","outcome_index":1,"market_type":"set1","local_side":"away","local_uid":"2026-08-23_hugo_grenier_mees_rottgering","bid":0.66,"ask":0.81,"mid":0.735,"spread":0.15,"price":0.66,"size":423.0,"side":"BUY"}
{"ts":"2026-08-23T17:54:07.906Z","event_type":"price_change","market_id":"3790394","outcome_index":0,"market_type":"set1","local_side":"home","local_uid":"2026-08-23_hugo_grenier_mees_rottgering","bid":0.19,"ask":0.34,"mid":0.265,"spread":0.15,"price":0.34,"size":423.0,"side":"SELL"}
{"ts":"2026-08-23T17:54:07.907Z","event_type":"best_bid_ask","market_id":"3790394","outcome_index":0,"market_type":"set1","local_side":"home","local_uid":"2026-08-23_hugo_grenier_mees_rottgering","bid":0.19,"ask":0.33,"mid":0.26,"spread":0.14,"bid_size":null,"ask_size":null}
{"ts":"2026-08-23T17:54:07.907Z","event_type":"best_bid_ask","market_id":"3790394","outcome_index":1,"market_type":"set1","local_side":"away","local_uid":"2026-08-23_hugo_grenier_mees_rottgering","bid":0.67,"ask":0.81,"mid":0.74,"spread":0.14,"bid_size":null,"ask_size":null}
{"ts":"2026-08-23T17:54:07.908Z","event_type":"price_change","market_id":"3790394","outcome_index":1,"market_type":"set1","local_side":"away","local_uid":"2026-08-23_hugo_grenier_mees_rottgering","bid":0.67,"ask":0.81,"mid":0.74,"spread":0.14,"price":0.67,"size":88.0,"side":"BUY"}
{"ts":"2026-08-23T17:54:07.908Z","event_type":"price_change","market_id":"3790394","outcome_index":0,"market_type":"set1","local_side":"home","local_uid":"2026-08-23_hugo_grenier_mees_rottgering","bid":0.19,"ask":0.33,"mid":0.26,"spread":0.14,"price":0.33,"size":88.0,"side":"SELL"}
{"ts":"2026-08-23T17:54:07.909Z","event_type":"best_bid_ask","market_id":"3790394","outcome_index":0,"market_type":"set1","local_side":"home","local_uid":"2026-08-23_hugo_grenier_mees_rottgering","bid":0.2,"ask":0.33,"mid":0.265,"spread":0.13,"bid_size":null,"ask_size":null}
{"ts":"2026-08-23T17:54:07.909Z","event_type":"best_bid_ask","market_id":"3790394","outcome_index":1,"market_type":"set1","local_side":"away","local_uid":"2026-08-23_hugo_grenier_mees_rottgering","bid":0.67,"ask":0.8,"mid":0.735,"spread":0.13,"bid_size":null,"ask_size":null}
{"ts":"2026-08-23T17:54:07.909Z","event_type":"price_change","market_id":"3790394","outcome_index":0,"market_type":"set1","local_side":"home","local_uid":"2026-08-23_hugo_grenier_mees_rottgering","bid":0.2,"ask":0.33,"mid":0.265,"spread":0.13,"price":0.2,"size":88.0,"side":"BUY"}
{"ts":"2026-08-23T17:54:07.909Z","event_type":"price_change","market_id":"3790394","outcome_index":1,"market_type":"set1","local_side":"away","local_uid":"2026-08-23_hugo_grenier_mees_rottgering","bid":0.67,"ask":0.8,"mid":0.735,"spread":0.13,"price":0.8,"size":88.0,"side":"SELL"}
{"ts":"2026-08-23T17:54:07.923Z","event_type":"best_bid_ask","market_id":"3790397","outcome_index":0,"market_type":"set2","local_side":"home","local_uid":"2026-08-23_hugo_grenier_mees_rottgering","bid":0.0,"ask":0.41,"mid":0.205,"spread":0.41,"bid_size":null,"ask_size":null}
{"ts":"2026-08-23T17:54:07.923Z","event_type":"best_bid_ask","market_id":"3790397","outcome_index":1,"market_type":"set2","local_side":"away","local_uid":"2026-08-23_hugo_grenier_mees_rottgering","bid":0.59,"ask":1.0,"mid":0.795,"spread":0.41,"bid_size":null,"ask_size":null}
{"ts":"2026-08-23T17:54:07.923Z","event_type":"price_change","market_id":"3790397","outcome_index":0,"market_type":"set2","local_side":"home","local_uid":"2026-08-23_hugo_grenier_mees_rottgering","bid":0.0,"ask":0.41,"mid":0.205,"spread":0.41,"price":0.28,"size":0.0,"side":"BUY"}
{"ts":"2026-08-23T17:54:07.923Z","event_type":"price_change","market_id":"3790397","outcome_index":1,"market_type":"set2","local_side":"away","local_uid":"2026-08-23_hugo_grenier_mees_rottgering","bid":0.59,"ask":1.0,"mid":0.795,"spread":0.41,"price":0.72,"size":0.0,"side":"SELL"}
{"ts":"2026-08-23T17:54:07.950Z","event_type":"best_bid_ask","market_id":"3790397","outcome_index":0,"market_type":"set2","local_side":"home","local_uid":"2026-08-23_hugo_grenier_mees_rottgering","bid":0.0,"ask":0.42,"mid":0.21,"spread":0.42,"bid_size":null,"ask_size":null}
{"ts":"2026-08-23T17:54:07.950Z","event_type":"best_bid_ask","market_id":"3790397","outcome_index":1,"market_type":"set2","local_side":"away","local_uid":"2026-08-23_hugo_grenier_mees_rottgering","bid":0.58,"ask":1.0,"mid":0.79,"spread":0.42,"bid_size":null,"ask_size":null}
{"ts":"2026-08-23T17:54:07.950Z","event_type":"price_change","market_id":"3790397","outcome_index":1,"market_type":"set2","local_side":"away","local_uid":"2026-08-23_hugo_grenier_mees_rottgering","bid":0.58,"ask":1.0,"mid":0.79,"spread":0.42,"price":0.59,"size":0.0,"side":"BUY"}
{"ts":"2026-08-23T17:54:07.950Z","event_type":"price_change","market_id":"3790397","outcome_index":0,"market_type":"set2","local_side":"home","local_uid":"2026-08-23_hugo_grenier_mees_rottgering","bid":0.0,"ask":0.42,"mid":0.21,"spread":0.42,"price":0.41,"size":0.0,"side":"SELL"}
{"ts":"2026-08-23T17:54:07.963Z","event_type":"best_bid_ask","market_id":"3790397","outcome_index":0,"market_type":"set2","local_side":"home","local_uid":"2026-08-23_hugo_grenier_mees_rottgering","bid":0.29,"ask":0.42,"mid":0.355,"spread":0.13,"bid_size":null,"ask_size":null}
{"ts":"2026-08-23T17:54:07.963Z","event_type":"best_bid_ask","market_id":"3790397","outcome_index":1,"market_type":"set2","local_side":"away","local_uid":"2026-08-23_hugo_grenier_mees_rottgering","bid":0.58,"ask":0.71,"mid":0.645,"spread":0.13,"bid_size":null,"ask_size":null}
{"ts":"2026-08-23T17:54:07.963Z","event_type":"price_change","market_id":"3790397","outcome_index":0,"market_type":"set2","local_side":"home","local_uid":"2026-08-23_hugo_grenier_mees_rottgering","bid":0.29,"ask":0.42,"mid":0.355,"spread":0.13,"price":0.29,"size":150.0,"side":"BUY"}
{"ts":"2026-08-23T17:54:07.963Z","event_type":"price_change","market_id":"3790397","outcome_index":1,"market_type":"set2","local_side":"away","local_uid":"2026-08-23_hugo_grenier_mees_rottgering","bid":0.58,"ask":0.71,"mid":0.645,"spread":0.13,"price":0.71,"size":150.0,"side":"SELL"}
{"ts":"2026-08-23T17:54:07.964Z","event_type":"best_bid_ask","market_id":"3790397","outcome_index":0,"market_type":"set2","local_side":"home","local_uid":"2026-08-23_hugo_grenier_mees_rottgering","bid":0.29,"ask":0.41,"mid":0.35,"spread":0.12,"bid_size":null,"ask_size":null}
{"ts":"2026-08-23T17:54:07.964Z","event_type":"best_bid_ask","market_id":"3790397","outcome_index":1,"market_type":"set2","local_side":"away","local_uid":"2026-08-23_hugo_grenier_mees_rottgering","bid":0.59,"ask":0.71,"mid":0.65,"spread":0.12,"bid_size":null,"ask_size":null}
{"ts":"2026-08-23T17:54:07.964Z","event_type":"price_change","market_id":"3790397","outcome_index":1,"market_type":"set2","local_side":"away","local_uid":"2026-08-23_hugo_grenier_mees_rottgering","bid":0.59,"ask":0.71,"mid":0.65,"spread":0.12,"price":0.59,"size":150.0,"side":"BUY"}
{"ts":"2026-08-23T17:54:07.964Z","event_type":"price_change","market_id":"3790397","outcome_index":0,"market_type":"set2","local_side":"home","local_uid":"2026-08-23_hugo_grenier_mees_rottgering","bid":0.29,"ask":0.41,"mid":0.35,"spread":0.12,"price":0.41,"size":150.0,"side":"SELL"}
{"ts":"2026-08-23T17:54:07.965Z","event_type":"best_bid_ask","market_id":"3790394","outcome_index":0,"market_type":"set1","local_side":"home","local_uid":"2026-08-23_hugo_grenier_mees_rottgering","bid":0.21,"ask":0.33,"mid":0.27,"spread":0.12,"bid_size":null,"ask_size":null}
{"ts":"2026-08-23T17:54:07.966Z","event_type":"best_bid_ask","market_id":"3790394","outcome_index":1,"market_type":"set1","local_side":"away","local_uid":"2026-08-23_hugo_grenier_mees_rottgering","bid":0.67,"ask":0.79,"mid":0.73,"spread":0.12,"bid_size":null,"ask_size":null}
{"ts":"2026-08-23T17:54:07.966Z","event_type":"price_change","market_id":"3790394","outcome_index":0,"market_type":"set1","local_side":"home","local_uid":"2026-08-23_hugo_grenier_mees_rottgering","bid":0.21,"ask":0.33,"mid":0.27,"spread":0.12,"price":0.21,"size":150.0,"side":"BUY"}
{"ts":"2026-08-23T17:54:07.966Z","event_type":"price_change","market_id":"3790394","outcome_index":1,"market_type":"set1","local_side":"away","local_uid":"2026-08-23_hugo_grenier_mees_rottgering","bid":0.67,"ask":0.79,"mid":0.73,"spread":0.12,"price":0.79,"size":150.0,"side":"SELL"}
{"ts":"2026-08-23T17:54:07.968Z","event_type":"best_bid_ask","market_id":"3790394","outcome_index":0,"market_type":"set1","local_side":"home","local_uid":"2026-08-23_hugo_grenier_mees_rottgering","bid":0.21,"ask":0.32,"mid":0.265,"spread":0.11,"bid_size":null,"ask_size":null}
{"ts":"2026-08-23T17:54:07.968Z","event_type":"best_bid_ask","market_id":"3790394","outcome_index":1,"market_type":"set1","local_side":"away","local_uid":"2026-08-23_hugo_grenier_mees_rottgering","bid":0.68,"ask":0.79,"mid":0.735,"spread":0.11,"bid_size":null,"ask_size":null}
{"ts":"2026-08-23T17:54:07.968Z","event_type":"price_change","market_id":"3790394","outcome_index":1,"market_type":"set1","local_side":"away","local_uid":"2026-08-23_hugo_grenier_mees_rottgering","bid":0.68,"ask":0.79,"mid":0.735,"spread":0.11,"price":0.68,"size":150.0,"side":"BUY"}
{"ts":"2026-08-23T17:54:07.968Z","event_type":"price_change","market_id":"3790394","outcome_index":0,"market_type":"set1","local_side":"home","local_uid":"2026-08-23_hugo_grenier_mees_rottgering","bid":0.21,"ask":0.32,"mid":0.265,"spread":0.11,"price":0.32,"size":150.0,"side":"SELL"}
{"ts":"2026-08-23T17:54:07.980Z","event_type":"best_bid_ask","market_id":"3789927","outcome_index":0,"market_type":"match","local_side":"home","local_uid":"2026-08-23_hugo_grenier_mees_rottgering","bid":0.26,"ask":0.28,"mid":0.27,"spread":0.02,"bid_size":null,"ask_size":null}
{"ts":"2026-08-23T17:54:07.980Z","event_type":"best_bid_ask","market_id":"3789927","outcome_index":1,"market_type":"match","local_side":"away","local_uid":"2026-08-23_hugo_grenier_mees_rottgering","bid":0.72,"ask":0.74,"mid":0.73,"spread":0.02,"bid_size":null,"ask_size":null}
{"ts":"2026-08-23T17:54:07.980Z","event_type":"price_change","market_id":"3789927","outcome_index":1,"market_type":"match","local_side":"away","local_uid":"2026-08-23_hugo_grenier_mees_rottgering","bid":0.72,"ask":0.74,"mid":0.73,"spread":0.02,"price":0.72,"size":29.0,"side":"BUY"}
{"ts":"2026-08-23T17:54:07.980Z","event_type":"price_change","market_id":"3789927","outcome_index":0,"market_type":"match","local_side":"home","local_uid":"2026-08-23_hugo_grenier_mees_rottgering","bid":0.26,"ask":0.28,"mid":0.27,"spread":0.02,"price":0.28,"size":29.0,"side":"SELL"}
{"ts":"2026-08-23T17:54:07.991Z","event_type":"best_bid_ask","market_id":"3790397","outcome_index":0,"market_type":"set2","local_side":"home","local_uid":"2026-08-23_hugo_grenier_mees_rottgering","bid":0.29,"ask":0.4,"mid":0.345,"spread":0.11,"bid_size":null,"ask_size":null}
{"ts":"2026-08-23T17:54:07.991Z","event_type":"best_bid_ask","market_id":"3790397","outcome_index":1,"market_type":"set2","local_side":"away","local_uid":"2026-08-23_hugo_grenier_mees_rottgering","bid":0.6,"ask":0.71,"mid":0.655,"spread":0.11,"bid_size":null,"ask_size":null}
{"ts":"2026-08-23T17:54:07.991Z","event_type":"price_change","market_id":"3790397","outcome_index":1,"market_type":"set2","local_side":"away","local_uid":"2026-08-23_hugo_grenier_mees_rottgering","bid":0.6,"ask":0.71,"mid":0.655,"spread":0.11,"price":0.6,"size":98.89,"side":"BUY"}
{"ts":"2026-08-23T17:54:07.991Z","event_type":"price_change","market_id":"3790397","outcome_index":0,"market_type":"set2","local_side":"home","local_uid":"2026-08-23_hugo_grenier_mees_rottgering","bid":0.29,"ask":0.4,"mid":0.345,"spread":0.11,"price":0.4,"size":98.89,"side":"SELL"}
{"ts":"2026-08-23T17:54:08.163Z","event_type":"best_bid_ask","market_id":"3789927","outcome_index":0,"market_type":"match","local_side":"home","local_uid":"2026-08-23_hugo_grenier_mees_rottgering","bid":0.26,"ask":0.27,"mid":0.265,"spread":0.01,"bid_size":null,"ask_size":null}
{"ts":"2026-08-23T17:54:08.163Z","event_type":"best_bid_ask","market_id":"3789927","outcome_index":1,"market_type":"match","local_side":"away","local_uid":"2026-08-23_hugo_grenier_mees_rottgering","bid":0.73,"ask":0.74,"mid":0.735,"spread":0.01,"bid_size":null,"ask_size":null}
{"ts":"2026-08-23T17:54:08.164Z","event_type":"price_change","market_id":"3789927","outcome_index":1,"market_type":"match","local_side":"away","local_uid":"2026-08-23_hugo_grenier_mees_rottgering","bid":0.73,"ask":0.74,"mid":0.735,"spread":0.01,"price":0.73,"size":31.0,"side":"BUY"}
{"ts":"2026-08-23T17:54:08.164Z","event_type":"price_change","market_id":"3789927","outcome_index":0,"market_type":"match","local_side":"home","local_uid":"2026-08-23_hugo_grenier_mees_rottgering","bid":0.26,"ask":0.27,"mid":0.265,"spread":0.01,"price":0.27,"size":31.0,"side":"SELL"}
{"ts":"2026-08-23T17:54:08.286Z","event_type":"best_bid_ask","market_id":"3790415","outcome_index":0,"market_type":"set2","local_side":"home","local_uid":"2026-08-23_pierre_hugues_herbert_quinn_vandecasteele","bid":0.57,"ask":0.66,"mid":0.615,"spread":0.09,"bid_size":null,"ask_size":null}
{"ts":"2026-08-23T17:54:08.287Z","event_type":"best_bid_ask","market_id":"3790415","outcome_index":1,"market_type":"set2","local_side":"away","local_uid":"2026-08-23_pierre_hugues_herbert_quinn_vandecasteele","bid":0.34,"ask":0.43,"mid":0.385,"spread":0.09,"bid_size":null,"ask_size":null}
{"ts":"2026-08-23T17:54:08.287Z","event_type":"price_change","market_id":"3790415","outcome_index":0,"market_type":"set2","local_side":"home","local_uid":"2026-08-23_pierre_hugues_herbert_quinn_vandecasteele","bid":0.57,"ask":0.66,"mid":0.615,"spread":0.09,"price":0.58,"size":0.0,"side":"BUY"}
{"ts":"2026-08-23T17:54:08.287Z","event_type":"price_change","market_id":"3790415","outcome_index":1,"market_type":"set2","local_side":"away","local_uid":"2026-08-23_pierre_hugues_herbert_quinn_vandecasteele","bid":0.34,"ask":0.43,"mid":0.385,"spread":0.09,"price":0.42,"size":0.0,"side":"SELL"}
{"ts":"2026-08-23T17:54:08.323Z","event_type":"best_bid_ask","market_id":"3790394","outcome_index":0,"market_type":"set1","local_side":"home","local_uid":"2026-08-23_hugo_grenier_mees_rottgering","bid":0.22,"ask":0.32,"mid":0.27,"spread":0.1,"bid_size":null,"ask_size":null}
{"ts":"2026-08-23T17:54:08.323Z","event_type":"best_bid_ask","market_id":"3790394","outcome_index":1,"market_type":"set1","local_side":"away","local_uid":"2026-08-23_hugo_grenier_mees_rottgering","bid":0.68,"ask":0.78,"mid":0.73,"spread":0.1,"bid_size":null,"ask_size":null}
{"ts":"2026-08-23T17:54:08.323Z","event_type":"price_change","market_id":"3790394","outcome_index":0,"market_type":"set1","local_side":"home","local_uid":"2026-08-23_hugo_grenier_mees_rottgering","bid":0.22,"ask":0.32,"mid":0.27,"spread":0.1,"price":0.22,"size":33.95,"side":"BUY"}
{"ts":"2026-08-23T17:54:08.323Z","event_type":"price_change","market_id":"3790394","outcome_index":1,"market_type":"set1","local_side":"away","local_uid":"2026-08-23_hugo_grenier_mees_rottgering","bid":0.68,"ask":0.78,"mid":0.73,"spread":0.1,"price":0.78,"size":33.95,"side":"SELL"}
{"ts":"2026-08-23T17:54:08.324Z","event_type":"best_bid_ask","market_id":"3790415","outcome_index":0,"market_type":"set2","local_side":"home","local_uid":"2026-08-23_pierre_hugues_herbert_quinn_vandecasteele","bid":0.58,"ask":0.66,"mid":0.62,"spread":0.08,"bid_size":null,"ask_size":null}
{"ts":"2026-08-23T17:54:08.324Z","event_type":"best_bid_ask","market_id":"3790415","outcome_index":1,"market_type":"set2","local_side":"away","local_uid":"2026-08-23_pierre_hugues_herbert_quinn_vandecasteele","bid":0.34,"ask":0.42,"mid":0.38,"spread":0.08,"bid_size":null,"ask_size":null}
{"ts":"2026-08-23T17:54:08.324Z","event_type":"price_change","market_id":"3790415","outcome_index":0,"market_type":"set2","local_side":"home","local_uid":"2026-08-23_pierre_hugues_herbert_quinn_vandecasteele","bid":0.58,"ask":0.66,"mid":0.62,"spread":0.08,"price":0.58,"size":150.0,"side":"BUY"}
{"ts":"2026-08-23T17:54:08.324Z","event_type":"price_change","market_id":"3790415","outcome_index":1,"market_type":"set2","local_side":"away","local_uid":"2026-08-23_pierre_hugues_herbert_quinn_vandecasteele","bid":0.34,"ask":0.42,"mid":0.38,"spread":0.08,"price":0.42,"size":150.0,"side":"SELL"}
{"ts":"2026-08-23T17:54:08.635Z","event_type":"best_bid_ask","market_id":"3790394","outcome_index":0,"market_type":"set1","local_side":"home","local_uid":"2026-08-23_hugo_grenier_mees_rottgering","bid":0.24,"ask":0.32,"mid":0.28,"spread":0.08,"bid_size":null,"ask_size":null}
{"ts":"2026-08-23T17:54:08.635Z","event_type":"best_bid_ask","market_id":"3790394","outcome_index":1,"market_type":"set1","local_side":"away","local_uid":"2026-08-23_hugo_grenier_mees_rottgering","bid":0.68,"ask":0.76,"mid":0.72,"spread":0.08,"bid_size":null,"ask_size":null}
{"ts":"2026-08-23T17:54:08.635Z","event_type":"price_change","market_id":"3790394","outcome_index":0,"market_type":"set1","local_side":"home","local_uid":"2026-08-23_hugo_grenier_mees_rottgering","bid":0.24,"ask":0.32,"mid":0.28,"spread":0.08,"price":0.24,"size":201.79,"side":"BUY"}
{"ts":"2026-08-23T17:54:08.635Z","event_type":"price_change","market_id":"3790394","outcome_index":1,"market_type":"set1","local_side":"away","local_uid":"2026-08-23_hugo_grenier_mees_rottgering","bid":0.68,"ask":0.76,"mid":0.72,"spread":0.08,"price":0.76,"size":201.79,"side":"SELL"}
{"ts":"2026-08-23T17:54:09.035Z","event_type":"best_bid_ask","market_id":"3790334","outcome_index":0,"market_type":"set2","local_side":"home","local_uid":"2026-08-23_abdullah_shelbayh_dhakshineswar_suresh","bid":0.48,"ask":0.52,"mid":0.5,"spread":0.04,"bid_size":null,"ask_size":null}
{"ts":"2026-08-23T17:54:09.036Z","event_type":"best_bid_ask","market_id":"3790334","outcome_index":1,"market_type":"set2","local_side":"away","local_uid":"2026-08-23_abdullah_shelbayh_dhakshineswar_suresh","bid":0.48,"ask":0.52,"mid":0.5,"spread":0.04,"bid_size":null,"ask_size":null}
{"ts":"2026-08-23T17:54:09.036Z","event_type":"price_change","market_id":"3790334","outcome_index":1,"market_type":"set2","local_side":"away","local_uid":"2026-08-23_abdullah_shelbayh_dhakshineswar_suresh","bid":0.48,"ask":0.52,"mid":0.5,"spread":0.04,"price":0.48,"size":66.0,"side":"BUY"}
{"ts":"2026-08-23T17:54:09.036Z","event_type":"price_change","market_id":"3790334","outcome_index":0,"market_type":"set2","local_side":"home","local_uid":"2026-08-23_abdullah_shelbayh_dhakshineswar_suresh","bid":0.48,"ask":0.52,"mid":0.5,"spread":0.04,"price":0.52,"size":66.0,"side":"SELL"}
{"ts":"2026-08-23T17:54:09.076Z","event_type":"best_bid_ask","market_id":"3790334","outcome_index":0,"market_type":"set2","local_side":"home","local_uid":"2026-08-23_abdullah_shelbayh_dhakshineswar_suresh","bid":0.48,"ask":0.53,"mid":0.505,"spread":0.05,"bid_size":null,"ask_size":null}
{"ts":"2026-08-23T17:54:09.077Z","event_type":"best_bid_ask","market_id":"3790334","outcome_index":1,"market_type":"set2","local_side":"away","local_uid":"2026-08-23_abdullah_shelbayh_dhakshineswar_suresh","bid":0.47,"ask":0.52,"mid":0.495,"spread":0.05,"bid_size":null,"ask_size":null}
{"ts":"2026-08-23T17:54:09.077Z","event_type":"price_change","market_id":"3790334","outcome_index":1,"market_type":"set2","local_side":"away","local_uid":"2026-08-23_abdullah_shelbayh_dhakshineswar_suresh","bid":0.47,"ask":0.52,"mid":0.495,"spread":0.05,"price":0.48,"size":0.0,"side":"BUY"}
{"ts":"2026-08-23T17:54:09.077Z","event_type":"price_change","market_id":"3790334","outcome_index":0,"market_type":"set2","local_side":"home","local_uid":"2026-08-23_abdullah_shelbayh_dhakshineswar_suresh","bid":0.48,"ask":0.53,"mid":0.505,"spread":0.05,"price":0.52,"size":0.0,"side":"SELL"}
{"ts":"2026-08-23T17:54:09.121Z","event_type":"best_bid_ask","market_id":"3790334","outcome_index":0,"market_type":"set2","local_side":"home","local_uid":"2026-08-23_abdullah_shelbayh_dhakshineswar_suresh","bid":0.48,"ask":0.54,"mid":0.51,"spread":0.06,"bid_size":null,"ask_size":null}
{"ts":"2026-08-23T17:54:09.121Z","event_type":"best_bid_ask","market_id":"3790334","outcome_index":1,"market_type":"set2","local_side":"away","local_uid":"2026-08-23_abdullah_shelbayh_dhakshineswar_suresh","bid":0.46,"ask":0.52,"mid":0.49,"spread":0.06,"bid_size":null,"ask_size":null}
{"ts":"2026-08-23T17:54:09.121Z","event_type":"price_change","market_id":"3790334","outcome_index":1,"market_type":"set2","local_side":"away","local_uid":"2026-08-23_abdullah_shelbayh_dhakshineswar_suresh","bid":0.46,"ask":0.52,"mid":0.49,"spread":0.06,"price":0.47,"size":0.0,"side":"BUY"}
{"ts":"2026-08-23T17:54:09.121Z","event_type":"price_change","market_id":"3790334","outcome_index":0,"market_type":"set2","local_side":"home","local_uid":"2026-08-23_abdullah_shelbayh_dhakshineswar_suresh","bid":0.48,"ask":0.54,"mid":0.51,"spread":0.06,"price":0.53,"size":0.0,"side":"SELL"}
{"ts":"2026-08-23T17:54:09.121Z","event_type":"best_bid_ask","market_id":"3790334","outcome_index":0,"market_type":"set2","local_side":"home","local_uid":"2026-08-23_abdullah_shelbayh_dhakshineswar_suresh","bid":0.48,"ask":0.55,"mid":0.515,"spread":0.07,"bid_size":null,"ask_size":null}
{"ts":"2026-08-23T17:54:09.121Z","event_type":"best_bid_ask","market_id":"3790334","outcome_index":1,"market_type":"set2","local_side":"away","local_uid":"2026-08-23_abdullah_shelbayh_dhakshineswar_suresh","bid":0.45,"ask":0.52,"mid":0.485,"spread":0.07,"bid_size":null,"ask_size":null}
{"ts":"2026-08-23T17:54:09.122Z","event_type":"price_change","market_id":"3790334","outcome_index":1,"market_type":"set2","local_side":"away","local_uid":"2026-08-23_abdullah_shelbayh_dhakshineswar_suresh","bid":0.45,"ask":0.52,"mid":0.485,"spread":0.07,"price":0.46,"size":0.0,"side":"BUY"}
{"ts":"2026-08-23T17:54:09.122Z","event_type":"price_change","market_id":"3790334","outcome_index":0,"market_type":"set2","local_side":"home","local_uid":"2026-08-23_abdullah_shelbayh_dhakshineswar_suresh","bid":0.48,"ask":0.55,"mid":0.515,"spread":0.07,"price":0.54,"size":0.0,"side":"SELL"}
{"ts":"2026-08-23T17:54:09.122Z","event_type":"best_bid_ask","market_id":"3790334","outcome_index":0,"market_type":"set2","local_side":"home","local_uid":"2026-08-23_abdullah_shelbayh_dhakshineswar_suresh","bid":0.48,"ask":0.52,"mid":0.5,"spread":0.04,"bid_size":null,"ask_size":null}
{"ts":"2026-08-23T17:54:09.122Z","event_type":"best_bid_ask","market_id":"3790334","outcome_index":1,"market_type":"set2","local_side":"away","local_uid":"2026-08-23_abdullah_shelbayh_dhakshineswar_suresh","bid":0.48,"ask":0.52,"mid":0.5,"spread":0.04,"bid_size":null,"ask_size":null}
{"ts":"2026-08-23T17:54:09.122Z","event_type":"price_change","market_id":"3790334","outcome_index":1,"market_type":"set2","local_side":"away","local_uid":"2026-08-23_abdullah_shelbayh_dhakshineswar_suresh","bid":0.48,"ask":0.52,"mid":0.5,"spread":0.04,"price":0.48,"size":18.0,"side":"BUY"}
{"ts":"2026-08-23T17:54:09.122Z","event_type":"price_change","market_id":"3790334","outcome_index":0,"market_type":"set2","local_side":"home","local_uid":"2026-08-23_abdullah_shelbayh_dhakshineswar_suresh","bid":0.48,"ask":0.52,"mid":0.5,"spread":0.04,"price":0.52,"size":18.0,"side":"SELL"}
{"ts":"2026-08-23T17:54:09.195Z","event_type":"best_bid_ask","market_id":"3790415","outcome_index":0,"market_type":"set2","local_side":"home","local_uid":"2026-08-23_pierre_hugues_herbert_quinn_vandecasteele","bid":0.57,"ask":0.66,"mid":0.615,"spread":0.09,"bid_size":null,"ask_size":null}
{"ts":"2026-08-23T17:54:09.196Z","event_type":"best_bid_ask","market_id":"3790415","outcome_index":1,"market_type":"set2","local_side":"away","local_uid":"2026-08-23_pierre_hugues_herbert_quinn_vandecasteele","bid":0.34,"ask":0.43,"mid":0.385,"spread":0.09,"bid_size":null,"ask_size":null}
{"ts":"2026-08-23T17:54:09.196Z","event_type":"price_change","market_id":"3790415","outcome_index":0,"market_type":"set2","local_side":"home","local_uid":"2026-08-23_pierre_hugues_herbert_quinn_vandecasteele","bid":0.57,"ask":0.66,"mid":0.615,"spread":0.09,"price":0.58,"size":0.0,"side":"BUY"}
{"ts":"2026-08-23T17:54:09.196Z","event_type":"price_change","market_id":"3790415","outcome_index":1,"market_type":"set2","local_side":"away","local_uid":"2026-08-23_pierre_hugues_herbert_quinn_vandecasteele","bid":0.34,"ask":0.43,"mid":0.385,"spread":0.09,"price":0.42,"size":0.0,"side":"SELL"}
{"ts":"2026-08-23T17:54:09.201Z","event_type":"best_bid_ask","market_id":"3790334","outcome_index":0,"market_type":"set2","local_side":"home","local_uid":"2026-08-23_abdullah_shelbayh_dhakshineswar_suresh","bid":0.48,"ask":0.55,"mid":0.515,"spread":0.07,"bid_size":null,"ask_size":null}
{"ts":"2026-08-23T17:54:09.201Z","event_type":"best_bid_ask","market_id":"3790334","outcome_index":1,"market_type":"set2","local_side":"away","local_uid":"2026-08-23_abdullah_shelbayh_dhakshineswar_suresh","bid":0.45,"ask":0.52,"mid":0.485,"spread":0.07,"bid_size":null,"ask_size":null}
{"ts":"2026-08-23T17:54:09.201Z","event_type":"price_change","market_id":"3790334","outcome_index":1,"market_type":"set2","local_side":"away","local_uid":"2026-08-23_abdullah_shelbayh_dhakshineswar_suresh","bid":0.45,"ask":0.52,"mid":0.485,"spread":0.07,"price":0.48,"size":0.0,"side":"BUY"}
{"ts":"2026-08-23T17:54:09.201Z","event_type":"price_change","market_id":"3790334","outcome_index":0,"market_type":"set2","local_side":"home","local_uid":"2026-08-23_abdullah_shelbayh_dhakshineswar_suresh","bid":0.48,"ask":0.55,"mid":0.515,"spread":0.07,"price":0.52,"size":0.0,"side":"SELL"}
{"ts":"2026-08-23T17:54:09.201Z","event_type":"best_bid_ask","market_id":"3790415","outcome_index":0,"market_type":"set2","local_side":"home","local_uid":"2026-08-23_pierre_hugues_herbert_quinn_vandecasteele","bid":0.55,"ask":0.66,"mid":0.605,"spread":0.11,"bid_size":null,"ask_size":null}
{"ts":"2026-08-23T17:54:09.201Z","event_type":"best_bid_ask","market_id":"3790415","outcome_index":1,"market_type":"set2","local_side":"away","local_uid":"2026-08-23_pierre_hugues_herbert_quinn_vandecasteele","bid":0.34,"ask":0.45,"mid":0.395,"spread":0.11,"bid_size":null,"ask_size":null}
{"ts":"2026-08-23T17:54:09.201Z","event_type":"price_change","market_id":"3790415","outcome_index":0,"market_type":"set2","local_side":"home","local_uid":"2026-08-23_pierre_hugues_herbert_quinn_vandecasteele","bid":0.55,"ask":0.66,"mid":0.605,"spread":0.11,"price":0.57,"size":0.0,"side":"BUY"}
{"ts":"2026-08-23T17:54:09.202Z","event_type":"price_change","market_id":"3790415","outcome_index":1,"market_type":"set2","local_side":"away","local_uid":"2026-08-23_pierre_hugues_herbert_quinn_vandecasteele","bid":0.34,"ask":0.45,"mid":0.395,"spread":0.11,"price":0.43,"size":0.0,"side":"SELL"}
{"ts":"2026-08-23T17:54:09.207Z","event_type":"best_bid_ask","market_id":"3790334","outcome_index":0,"market_type":"set2","local_side":"home","local_uid":"2026-08-23_abdullah_shelbayh_dhakshineswar_suresh","bid":0.48,"ask":0.54,"mid":0.51,"spread":0.06,"bid_size":null,"ask_size":null}
{"ts":"2026-08-23T17:54:09.207Z","event_type":"best_bid_ask","market_id":"3790334","outcome_index":1,"market_type":"set2","local_side":"away","local_uid":"2026-08-23_abdullah_shelbayh_dhakshineswar_suresh","bid":0.46,"ask":0.52,"mid":0.49,"spread":0.06,"bid_size":null,"ask_size":null}
{"ts":"2026-08-23T17:54:09.207Z","event_type":"price_change","market_id":"3790334","outcome_index":1,"market_type":"set2","local_side":"away","local_uid":"2026-08-23_abdullah_shelbayh_dhakshineswar_suresh","bid":0.46,"ask":0.52,"mid":0.49,"spread":0.06,"price":0.46,"size":150.0,"side":"BUY"}
{"ts":"2026-08-23T17:54:09.207Z","event_type":"price_change","market_id":"3790334","outcome_index":0,"market_type":"set2","local_side":"home","local_uid":"2026-08-23_abdullah_shelbayh_dhakshineswar_suresh","bid":0.48,"ask":0.54,"mid":0.51,"spread":0.06,"price":0.54,"size":150.0,"side":"SELL"}
{"ts":"2026-08-23T17:54:09.234Z","event_type":"best_bid_ask","market_id":"3790415","outcome_index":0,"market_type":"set2","local_side":"home","local_uid":"2026-08-23_pierre_hugues_herbert_quinn_vandecasteele","bid":0.56,"ask":0.66,"mid":0.61,"spread":0.1,"bid_size":null,"ask_size":null}
{"ts":"2026-08-23T17:54:09.234Z","event_type":"best_bid_ask","market_id":"3790415","outcome_index":1,"market_type":"set2","local_side":"away","local_uid":"2026-08-23_pierre_hugues_herbert_quinn_vandecasteele","bid":0.34,"ask":0.44,"mid":0.39,"spread":0.1,"bid_size":null,"ask_size":null}
{"ts":"2026-08-23T17:54:09.234Z","event_type":"price_change","market_id":"3790415","outcome_index":0,"market_type":"set2","local_side":"home","local_uid":"2026-08-23_pierre_hugues_herbert_quinn_vandecasteele","bid":0.56,"ask":0.66,"mid":0.61,"spread":0.1,"price":0.56,"size":150.0,"side":"BUY"}
{"ts":"2026-08-23T17:54:09.234Z","event_type":"price_change","market_id":"3790415","outcome_index":1,"market_type":"set2","local_side":"away","local_uid":"2026-08-23_pierre_hugues_herbert_quinn_vandecasteele","bid":0.34,"ask":0.44,"mid":0.39,"spread":0.1,"price":0.44,"size":150.0,"side":"SELL"}
{"ts":"2026-08-23T17:54:09.241Z","event_type":"best_bid_ask","market_id":"3790334","outcome_index":0,"market_type":"set2","local_side":"home","local_uid":"2026-08-23_abdullah_shelbayh_dhakshineswar_suresh","bid":0.48,"ask":0.53,"mid":0.505,"spread":0.05,"bid_size":null,"ask_size":null}
{"ts":"2026-08-23T17:54:09.241Z","event_type":"best_bid_ask","market_id":"3790334","outcome_index":1,"market_type":"set2","local_side":"away","local_uid":"2026-08-23_abdullah_shelbayh_dhakshineswar_suresh","bid":0.47,"ask":0.52,"mid":0.495,"spread":0.05,"bid_size":null,"ask_size":null}
{"ts":"2026-08-23T17:54:09.241Z","event_type":"price_change","market_id":"3790334","outcome_index":1,"market_type":"set2","local_side":"away","local_uid":"2026-08-23_abdullah_shelbayh_dhakshineswar_suresh","bid":0.47,"ask":0.52,"mid":0.495,"spread":0.05,"price":0.47,"size":60.91,"side":"BUY"}
{"ts":"2026-08-23T17:54:09.241Z","event_type":"price_change","market_id":"3790334","outcome_index":0,"market_type":"set2","local_side":"home","local_uid":"2026-08-23_abdullah_shelbayh_dhakshineswar_suresh","bid":0.48,"ask":0.53,"mid":0.505,"spread":0.05,"price":0.53,"size":60.91,"side":"SELL"}
{"ts":"2026-08-23T17:54:09.288Z","event_type":"best_bid_ask","market_id":"3790334","outcome_index":0,"market_type":"set2","local_side":"home","local_uid":"2026-08-23_abdullah_shelbayh_dhakshineswar_suresh","bid":0.48,"ask":0.54,"mid":0.51,"spread":0.06,"bid_size":null,"ask_size":null}
{"ts":"2026-08-23T17:54:09.289Z","event_type":"best_bid_ask","market_id":"3790334","outcome_index":1,"market_type":"set2","local_side":"away","local_uid":"2026-08-23_abdullah_shelbayh_dhakshineswar_suresh","bid":0.46,"ask":0.52,"mid":0.49,"spread":0.06,"bid_size":null,"ask_size":null}
{"ts":"2026-08-23T17:54:09.289Z","event_type":"price_change","market_id":"3790334","outcome_index":1,"market_type":"set2","local_side":"away","local_uid":"2026-08-23_abdullah_shelbayh_dhakshineswar_suresh","bid":0.46,"ask":0.52,"mid":0.49,"spread":0.06,"price":0.47,"size":0.0,"side":"BUY"}
{"ts":"2026-08-23T17:54:09.289Z","event_type":"price_change","market_id":"3790334","outcome_index":0,"market_type":"set2","local_side":"home","local_uid":"2026-08-23_abdullah_shelbayh_dhakshineswar_suresh","bid":0.48,"ask":0.54,"mid":0.51,"spread":0.06,"price":0.53,"size":0.0,"side":"SELL"}
{"ts":"2026-08-23T17:54:09.333Z","event_type":"best_bid_ask","market_id":"3790334","outcome_index":0,"market_type":"set2","local_side":"home","local_uid":"2026-08-23_abdullah_shelbayh_dhakshineswar_suresh","bid":0.48,"ask":0.51,"mid":0.495,"spread":0.03,"bid_size":null,"ask_size":null}
{"ts":"2026-08-23T17:54:09.333Z","event_type":"best_bid_ask","market_id":"3790334","outcome_index":1,"market_type":"set2","local_side":"away","local_uid":"2026-08-23_abdullah_shelbayh_dhakshineswar_suresh","bid":0.49,"ask":0.52,"mid":0.505,"spread":0.03,"bid_size":null,"ask_size":null}
{"ts":"2026-08-23T17:54:09.333Z","event_type":"price_change","market_id":"3790334","outcome_index":1,"market_type":"set2","local_side":"away","local_uid":"2026-08-23_abdullah_shelbayh_dhakshineswar_suresh","bid":0.49,"ask":0.52,"mid":0.505,"spread":0.03,"price":0.49,"size":80.64,"side":"BUY"}
{"ts":"2026-08-23T17:54:09.333Z","event_type":"price_change","market_id":"3790334","outcome_index":0,"market_type":"set2","local_side":"home","local_uid":"2026-08-23_abdullah_shelbayh_dhakshineswar_suresh","bid":0.48,"ask":0.51,"mid":0.495,"spread":0.03,"price":0.51,"size":80.64,"side":"SELL"}
{"ts":"2026-08-23T17:54:09.385Z","event_type":"best_bid_ask","market_id":"3790334","outcome_index":0,"market_type":"set2","local_side":"home","local_uid":"2026-08-23_abdullah_shelbayh_dhakshineswar_suresh","bid":0.48,"ask":0.54,"mid":0.51,"spread":0.06,"bid_size":null,"ask_size":null}
{"ts":"2026-08-23T17:54:09.385Z","event_type":"best_bid_ask","market_id":"3790334","outcome_index":1,"market_type":"set2","local_side":"away","local_uid":"2026-08-23_abdullah_shelbayh_dhakshineswar_suresh","bid":0.46,"ask":0.52,"mid":0.49,"spread":0.06,"bid_size":null,"ask_size":null}
{"ts":"2026-08-23T17:54:09.385Z","event_type":"price_change","market_id":"3790334","outcome_index":1,"market_type":"set2","local_side":"away","local_uid":"2026-08-23_abdullah_shelbayh_dhakshineswar_suresh","bid":0.46,"ask":0.52,"mid":0.49,"spread":0.06,"price":0.49,"size":0.0,"side":"BUY"}
{"ts":"2026-08-23T17:54:09.385Z","event_type":"price_change","market_id":"3790334","outcome_index":0,"market_type":"set2","local_side":"home","local_uid":"2026-08-23_abdullah_shelbayh_dhakshineswar_suresh","bid":0.48,"ask":0.54,"mid":0.51,"spread":0.06,"price":0.51,"size":0.0,"side":"SELL"}
{"ts":"2026-08-23T17:54:09.429Z","event_type":"best_bid_ask","market_id":"3790334","outcome_index":0,"market_type":"set2","local_side":"home","local_uid":"2026-08-23_abdullah_shelbayh_dhakshineswar_suresh","bid":0.48,"ask":0.52,"mid":0.5,"spread":0.04,"bid_size":null,"ask_size":null}
{"ts":"2026-08-23T17:54:09.429Z","event_type":"best_bid_ask","market_id":"3790334","outcome_index":1,"market_type":"set2","local_side":"away","local_uid":"2026-08-23_abdullah_shelbayh_dhakshineswar_suresh","bid":0.48,"ask":0.52,"mid":0.5,"spread":0.04,"bid_size":null,"ask_size":null}
{"ts":"2026-08-23T17:54:09.429Z","event_type":"price_change","market_id":"3790334","outcome_index":1,"market_type":"set2","local_side":"away","local_uid":"2026-08-23_abdullah_shelbayh_dhakshineswar_suresh","bid":0.48,"ask":0.52,"mid":0.5,"spread":0.04,"price":0.48,"size":144.36,"side":"BUY"}
{"ts":"2026-08-23T17:54:09.430Z","event_type":"price_change","market_id":"3790334","outcome_index":0,"market_type":"set2","local_side":"home","local_uid":"2026-08-23_abdullah_shelbayh_dhakshineswar_suresh","bid":0.48,"ask":0.52,"mid":0.5,"spread":0.04,"price":0.52,"size":144.36,"side":"SELL"}
{"ts":"2026-08-23T17:54:09.482Z","event_type":"best_bid_ask","market_id":"3790334","outcome_index":0,"market_type":"set2","local_side":"home","local_uid":"2026-08-23_abdullah_shelbayh_dhakshineswar_suresh","bid":0.48,"ask":0.54,"mid":0.51,"spread":0.06,"bid_size":null,"ask_size":null}
{"ts":"2026-08-23T17:54:09.482Z","event_type":"best_bid_ask","market_id":"3790334","outcome_index":1,"market_type":"set2","local_side":"away","local_uid":"2026-08-23_abdullah_shelbayh_dhakshineswar_suresh","bid":0.46,"ask":0.52,"mid":0.49,"spread":0.06,"bid_size":null,"ask_size":null}
{"ts":"2026-08-23T17:54:09.482Z","event_type":"price_change","market_id":"3790334","outcome_index":1,"market_type":"set2","local_side":"away","local_uid":"2026-08-23_abdullah_shelbayh_dhakshineswar_suresh","bid":0.46,"ask":0.52,"mid":0.49,"spread":0.06,"price":0.48,"size":0.0,"side":"BUY"}
{"ts":"2026-08-23T17:54:09.483Z","event_type":"price_change","market_id":"3790334","outcome_index":0,"market_type":"set2","local_side":"home","local_uid":"2026-08-23_abdullah_shelbayh_dhakshineswar_suresh","bid":0.48,"ask":0.54,"mid":0.51,"spread":0.06,"price":0.52,"size":0.0,"side":"SELL"}
{"ts":"2026-08-23T17:54:09.530Z","event_type":"best_bid_ask","market_id":"3790334","outcome_index":0,"market_type":"set2","local_side":"home","local_uid":"2026-08-23_abdullah_shelbayh_dhakshineswar_suresh","bid":0.48,"ask":0.53,"mid":0.505,"spread":0.05,"bid_size":null,"ask_size":null}
{"ts":"2026-08-23T17:54:09.530Z","event_type":"best_bid_ask","market_id":"3790334","outcome_index":1,"market_type":"set2","local_side":"away","local_uid":"2026-08-23_abdullah_shelbayh_dhakshineswar_suresh","bid":0.47,"ask":0.52,"mid":0.495,"spread":0.05,"bid_size":null,"ask_size":null}
{"ts":"2026-08-23T17:54:09.530Z","event_type":"price_change","market_id":"3790334","outcome_index":1,"market_type":"set2","local_side":"away","local_uid":"2026-08-23_abdullah_shelbayh_dhakshineswar_suresh","bid":0.47,"ask":0.52,"mid":0.495,"spread":0.05,"price":0.47,"size":150.0,"side":"BUY"}
{"ts":"2026-08-23T17:54:09.530Z","event_type":"price_change","market_id":"3790334","outcome_index":0,"market_type":"set2","local_side":"home","local_uid":"2026-08-23_abdullah_shelbayh_dhakshineswar_suresh","bid":0.48,"ask":0.53,"mid":0.505,"spread":0.05,"price":0.53,"size":150.0,"side":"SELL"}
{"ts":"2026-08-23T17:54:09.789Z","event_type":"best_bid_ask","market_id":"3790415","outcome_index":0,"market_type":"set2","local_side":"home","local_uid":"2026-08-23_pierre_hugues_herbert_quinn_vandecasteele","bid":0.57,"ask":0.66,"mid":0.615,"spread":0.09,"bid_size":null,"ask_size":null}
{"ts":"2026-08-23T17:54:09.789Z","event_type":"best_bid_ask","market_id":"3790415","outcome_index":1,"market_type":"set2","local_side":"away","local_uid":"2026-08-23_pierre_hugues_herbert_quinn_vandecasteele","bid":0.34,"ask":0.43,"mid":0.385,"spread":0.09,"bid_size":null,"ask_size":null}
{"ts":"2026-08-23T17:54:09.790Z","event_type":"price_change","market_id":"3790415","outcome_index":0,"market_type":"set2","local_side":"home","local_uid":"2026-08-23_pierre_hugues_herbert_quinn_vandecasteele","bid":0.57,"ask":0.66,"mid":0.615,"spread":0.09,"price":0.57,"size":150.0,"side":"BUY"}
{"ts":"2026-08-23T17:54:09.790Z","event_type":"price_change","market_id":"3790415","outcome_index":1,"market_type":"set2","local_side":"away","local_uid":"2026-08-23_pierre_hugues_herbert_quinn_vandecasteele","bid":0.34,"ask":0.43,"mid":0.385,"spread":0.09,"price":0.43,"size":150.0,"side":"SELL"}
{"ts":"2026-08-23T17:54:09.879Z","event_type":"best_bid_ask","market_id":"3790415","outcome_index":0,"market_type":"set2","local_side":"home","local_uid":"2026-08-23_pierre_hugues_herbert_quinn_vandecasteele","bid":0.58,"ask":0.66,"mid":0.62,"spread":0.08,"bid_size":null,"ask_size":null}
{"ts":"2026-08-23T17:54:09.879Z","event_type":"best_bid_ask","market_id":"3790415","outcome_index":1,"market_type":"set2","local_side":"away","local_uid":"2026-08-23_pierre_hugues_herbert_quinn_vandecasteele","bid":0.34,"ask":0.42,"mid":0.38,"spread":0.08,"bid_size":null,"ask_size":null}
{"ts":"2026-08-23T17:54:09.880Z","event_type":"price_change","market_id":"3790415","outcome_index":0,"market_type":"set2","local_side":"home","local_uid":"2026-08-23_pierre_hugues_herbert_quinn_vandecasteele","bid":0.58,"ask":0.66,"mid":0.62,"spread":0.08,"price":0.58,"size":31.98,"side":"BUY"}
{"ts":"2026-08-23T17:54:09.880Z","event_type":"price_change","market_id":"3790415","outcome_index":1,"market_type":"set2","local_side":"away","local_uid":"2026-08-23_pierre_hugues_herbert_quinn_vandecasteele","bid":0.34,"ask":0.42,"mid":0.38,"spread":0.08,"price":0.42,"size":31.98,"side":"SELL"}
{"ts":"2026-08-23T17:54:10.065Z","event_type":"best_bid_ask","market_id":"3790415","outcome_index":0,"market_type":"set2","local_side":"home","local_uid":"2026-08-23_pierre_hugues_herbert_quinn_vandecasteele","bid":0.57,"ask":0.66,"mid":0.615,"spread":0.09,"bid_size":null,"ask_size":null}
{"ts":"2026-08-23T17:54:10.065Z","event_type":"best_bid_ask","market_id":"3790415","outcome_index":1,"market_type":"set2","local_side":"away","local_uid":"2026-08-23_pierre_hugues_herbert_quinn_vandecasteele","bid":0.34,"ask":0.43,"mid":0.385,"spread":0.09,"bid_size":null,"ask_size":null}
{"ts":"2026-08-23T17:54:10.065Z","event_type":"price_change","market_id":"3790415","outcome_index":0,"market_type":"set2","local_side":"home","local_uid":"2026-08-23_pierre_hugues_herbert_quinn_vandecasteele","bid":0.57,"ask":0.66,"mid":0.615,"spread":0.09,"price":0.58,"size":0.0,"side":"BUY"}
{"ts":"2026-08-23T17:54:10.065Z","event_type":"price_change","market_id":"3790415","outcome_index":1,"market_type":"set2","local_side":"away","local_uid":"2026-08-23_pierre_hugues_herbert_quinn_vandecasteele","bid":0.34,"ask":0.43,"mid":0.385,"spread":0.09,"price":0.42,"size":0.0,"side":"SELL"}
{"ts":"2026-08-23T17:54:10.103Z","event_type":"best_bid_ask","market_id":"3790415","outcome_index":0,"market_type":"set2","local_side":"home","local_uid":"2026-08-23_pierre_hugues_herbert_quinn_vandecasteele","bid":0.58,"ask":0.66,"mid":0.62,"spread":0.08,"bid_size":null,"ask_size":null}
{"ts":"2026-08-23T17:54:10.103Z","event_type":"best_bid_ask","market_id":"3790415","outcome_index":1,"market_type":"set2","local_side":"away","local_uid":"2026-08-23_pierre_hugues_herbert_quinn_vandecasteele","bid":0.34,"ask":0.42,"mid":0.38,"spread":0.08,"bid_size":null,"ask_size":null}
{"ts":"2026-08-23T17:54:10.103Z","event_type":"price_change","market_id":"3790415","outcome_index":0,"market_type":"set2","local_side":"home","local_uid":"2026-08-23_pierre_hugues_herbert_quinn_vandecasteele","bid":0.58,"ask":0.66,"mid":0.62,"spread":0.08,"price":0.58,"size":150.0,"side":"BUY"}
{"ts":"2026-08-23T17:54:10.103Z","event_type":"price_change","market_id":"3790415","outcome_index":1,"market_type":"set2","local_side":"away","local_uid":"2026-08-23_pierre_hugues_herbert_quinn_vandecasteele","bid":0.34,"ask":0.42,"mid":0.38,"spread":0.08,"price":0.42,"size":150.0,"side":"SELL"}
{"ts":"2026-08-23T17:54:10.532Z","event_type":"best_bid_ask","market_id":"3790334","outcome_index":0,"market_type":"set2","local_side":"home","local_uid":"2026-08-23_abdullah_shelbayh_dhakshineswar_suresh","bid":0.48,"ask":0.52,"mid":0.5,"spread":0.04,"bid_size":null,"ask_size":null}
{"ts":"2026-08-23T17:54:10.533Z","event_type":"best_bid_ask","market_id":"3790334","outcome_index":1,"market_type":"set2","local_side":"away","local_uid":"2026-08-23_abdullah_shelbayh_dhakshineswar_suresh","bid":0.48,"ask":0.52,"mid":0.5,"spread":0.04,"bid_size":null,"ask_size":null}
{"ts":"2026-08-23T17:54:10.533Z","event_type":"price_change","market_id":"3790334","outcome_index":1,"market_type":"set2","local_side":"away","local_uid":"2026-08-23_abdullah_shelbayh_dhakshineswar_suresh","bid":0.48,"ask":0.52,"mid":0.5,"spread":0.04,"price":0.48,"size":44.0,"side":"BUY"}
{"ts":"2026-08-23T17:54:10.533Z","event_type":"price_change","market_id":"3790334","outcome_index":0,"market_type":"set2","local_side":"home","local_uid":"2026-08-23_abdullah_shelbayh_dhakshineswar_suresh","bid":0.48,"ask":0.52,"mid":0.5,"spread":0.04,"price":0.52,"size":44.0,"side":"SELL"}
{"ts":"2026-08-23T17:54:10.537Z","event_type":"best_bid_ask","market_id":"3795946","outcome_index":0,"market_type":"match","local_side":"home","local_uid":"2026-08-23_arthur_fils_frances_tiafoe","bid":0.66,"ask":0.67,"mid":0.665,"spread":0.01,"bid_size":null,"ask_size":null}
{"ts":"2026-08-23T17:54:10.537Z","event_type":"best_bid_ask","market_id":"3795946","outcome_index":1,"market_type":"match","local_side":"away","local_uid":"2026-08-23_arthur_fils_frances_tiafoe","bid":0.33,"ask":0.34,"mid":0.335,"spread":0.01,"bid_size":null,"ask_size":null}
{"ts":"2026-08-23T17:54:10.537Z","event_type":"book","market_id":"3795946","outcome_index":0,"market_type":"match","local_side":"home","local_uid":"2026-08-23_arthur_fils_frances_tiafoe","bid":0.66,"ask":0.67,"mid":0.665,"spread":0.01,"bid_size":36177.33,"ask_size":65437.82}
{"ts":"2026-08-23T17:54:10.538Z","event_type":"book","market_id":"3795946","outcome_index":1,"market_type":"match","local_side":"away","local_uid":"2026-08-23_arthur_fils_frances_tiafoe","bid":0.33,"ask":0.34,"mid":0.335,"spread":0.01,"bid_size":65437.82,"ask_size":36177.33}
{"ts":"2026-08-23T17:54:10.557Z","event_type":"best_bid_ask","market_id":"3790334","outcome_index":0,"market_type":"set2","local_side":"home","local_uid":"2026-08-23_abdullah_shelbayh_dhakshineswar_suresh","bid":0.48,"ask":0.53,"mid":0.505,"spread":0.05,"bid_size":null,"ask_size":null}
{"ts":"2026-08-23T17:54:10.557Z","event_type":"best_bid_ask","market_id":"3790334","outcome_index":1,"market_type":"set2","local_side":"away","local_uid":"2026-08-23_abdullah_shelbayh_dhakshineswar_suresh","bid":0.47,"ask":0.52,"mid":0.495,"spread":0.05,"bid_size":null,"ask_size":null}
{"ts":"2026-08-23T17:54:10.557Z","event_type":"price_change","market_id":"3790334","outcome_index":1,"market_type":"set2","local_side":"away","local_uid":"2026-08-23_abdullah_shelbayh_dhakshineswar_suresh","bid":0.47,"ask":0.52,"mid":0.495,"spread":0.05,"price":0.48,"size":0.0,"side":"BUY"}
{"ts":"2026-08-23T17:54:10.557Z","event_type":"price_change","market_id":"3790334","outcome_index":0,"market_type":"set2","local_side":"home","local_uid":"2026-08-23_abdullah_shelbayh_dhakshineswar_suresh","bid":0.48,"ask":0.53,"mid":0.505,"spread":0.05,"price":0.52,"size":0.0,"side":"SELL"}
{"ts":"2026-08-23T17:54:10.583Z","event_type":"best_bid_ask","market_id":"3790334","outcome_index":0,"market_type":"set2","local_side":"home","local_uid":"2026-08-23_abdullah_shelbayh_dhakshineswar_suresh","bid":0.48,"ask":0.54,"mid":0.51,"spread":0.06,"bid_size":null,"ask_size":null}
{"ts":"2026-08-23T17:54:10.583Z","event_type":"best_bid_ask","market_id":"3790334","outcome_index":1,"market_type":"set2","local_side":"away","local_uid":"2026-08-23_abdullah_shelbayh_dhakshineswar_suresh","bid":0.46,"ask":0.52,"mid":0.49,"spread":0.06,"bid_size":null,"ask_size":null}
{"ts":"2026-08-23T17:54:10.583Z","event_type":"price_change","market_id":"3790334","outcome_index":1,"market_type":"set2","local_side":"away","local_uid":"2026-08-23_abdullah_shelbayh_dhakshineswar_suresh","bid":0.46,"ask":0.52,"mid":0.49,"spread":0.06,"price":0.47,"size":0.0,"side":"BUY"}
{"ts":"2026-08-23T17:54:10.583Z","event_type":"price_change","market_id":"3790334","outcome_index":0,"market_type":"set2","local_side":"home","local_uid":"2026-08-23_abdullah_shelbayh_dhakshineswar_suresh","bid":0.48,"ask":0.54,"mid":0.51,"spread":0.06,"price":0.53,"size":0.0,"side":"SELL"}
{"ts":"2026-08-23T17:54:10.593Z","event_type":"best_bid_ask","market_id":"3790334","outcome_index":0,"market_type":"set2","local_side":"home","local_uid":"2026-08-23_abdullah_shelbayh_dhakshineswar_suresh","bid":0.48,"ask":0.55,"mid":0.515,"spread":0.07,"bid_size":null,"ask_size":null}
{"ts":"2026-08-23T17:54:10.593Z","event_type":"best_bid_ask","market_id":"3790334","outcome_index":1,"market_type":"set2","local_side":"away","local_uid":"2026-08-23_abdullah_shelbayh_dhakshineswar_suresh","bid":0.45,"ask":0.52,"mid":0.485,"spread":0.07,"bid_size":null,"ask_size":null}
{"ts":"2026-08-23T17:54:10.593Z","event_type":"price_change","market_id":"3790334","outcome_index":1,"market_type":"set2","local_side":"away","local_uid":"2026-08-23_abdullah_shelbayh_dhakshineswar_suresh","bid":0.45,"ask":0.52,"mid":0.485,"spread":0.07,"price":0.46,"size":0.0,"side":"BUY"}
{"ts":"2026-08-23T17:54:10.593Z","event_type":"price_change","market_id":"3790334","outcome_index":0,"market_type":"set2","local_side":"home","local_uid":"2026-08-23_abdullah_shelbayh_dhakshineswar_suresh","bid":0.48,"ask":0.55,"mid":0.515,"spread":0.07,"price":0.54,"size":0.0,"side":"SELL"}
{"ts":"2026-08-23T17:54:10.594Z","event_type":"best_bid_ask","market_id":"3790334","outcome_index":0,"market_type":"set2","local_side":"home","local_uid":"2026-08-23_abdullah_shelbayh_dhakshineswar_suresh","bid":0.48,"ask":0.51,"mid":0.495,"spread":0.03,"bid_size":null,"ask_size":null}
{"ts":"2026-08-23T17:54:10.594Z","event_type":"best_bid_ask","market_id":"3790334","outcome_index":1,"market_type":"set2","local_side":"away","local_uid":"2026-08-23_abdullah_shelbayh_dhakshineswar_suresh","bid":0.49,"ask":0.52,"mid":0.505,"spread":0.03,"bid_size":null,"ask_size":null}
{"ts":"2026-08-23T17:54:10.594Z","event_type":"price_change","market_id":"3790334","outcome_index":1,"market_type":"set2","local_side":"away","local_uid":"2026-08-23_abdullah_shelbayh_dhakshineswar_suresh","bid":0.49,"ask":0.52,"mid":0.505,"spread":0.03,"price":0.49,"size":86.59,"side":"BUY"}
{"ts":"2026-08-23T17:54:10.594Z","event_type":"price_change","market_id":"3790334","outcome_index":0,"market_type":"set2","local_side":"home","local_uid":"2026-08-23_abdullah_shelbayh_dhakshineswar_suresh","bid":0.48,"ask":0.51,"mid":0.495,"spread":0.03,"price":0.51,"size":86.59,"side":"SELL"}
{"ts":"2026-08-23T17:54:10.629Z","event_type":"last_trade_price","market_id":"3795946","outcome_index":0,"market_type":"match","local_side":"home","local_uid":"2026-08-23_arthur_fils_frances_tiafoe","last_trade":0.67,"trade_size":11.6866,"trade_side":"BUY","trade_notional":7.83}
{"ts":"2026-08-23T17:54:10.632Z","event_type":"best_bid_ask","market_id":"3790334","outcome_index":0,"market_type":"set2","local_side":"home","local_uid":"2026-08-23_abdullah_shelbayh_dhakshineswar_suresh","bid":0.48,"ask":0.55,"mid":0.515,"spread":0.07,"bid_size":null,"ask_size":null}
{"ts":"2026-08-23T17:54:10.633Z","event_type":"best_bid_ask","market_id":"3790334","outcome_index":1,"market_type":"set2","local_side":"away","local_uid":"2026-08-23_abdullah_shelbayh_dhakshineswar_suresh","bid":0.45,"ask":0.52,"mid":0.485,"spread":0.07,"bid_size":null,"ask_size":null}
{"ts":"2026-08-23T17:54:10.633Z","event_type":"price_change","market_id":"3790334","outcome_index":1,"market_type":"set2","local_side":"away","local_uid":"2026-08-23_abdullah_shelbayh_dhakshineswar_suresh","bid":0.45,"ask":0.52,"mid":0.485,"spread":0.07,"price":0.49,"size":0.0,"side":"BUY"}
{"ts":"2026-08-23T17:54:10.633Z","event_type":"price_change","market_id":"3790334","outcome_index":0,"market_type":"set2","local_side":"home","local_uid":"2026-08-23_abdullah_shelbayh_dhakshineswar_suresh","bid":0.48,"ask":0.55,"mid":0.515,"spread":0.07,"price":0.51,"size":0.0,"side":"SELL"}
{"ts":"2026-08-23T17:54:10.639Z","event_type":"best_bid_ask","market_id":"3790334","outcome_index":0,"market_type":"set2","local_side":"home","local_uid":"2026-08-23_abdullah_shelbayh_dhakshineswar_suresh","bid":0.48,"ask":0.54,"mid":0.51,"spread":0.06,"bid_size":null,"ask_size":null}
{"ts":"2026-08-23T17:54:10.639Z","event_type":"best_bid_ask","market_id":"3790334","outcome_index":1,"market_type":"set2","local_side":"away","local_uid":"2026-08-23_abdullah_shelbayh_dhakshineswar_suresh","bid":0.46,"ask":0.52,"mid":0.49,"spread":0.06,"bid_size":null,"ask_size":null}
{"ts":"2026-08-23T17:54:10.639Z","event_type":"price_change","market_id":"3790334","outcome_index":1,"market_type":"set2","local_side":"away","local_uid":"2026-08-23_abdullah_shelbayh_dhakshineswar_suresh","bid":0.46,"ask":0.52,"mid":0.49,"spread":0.06,"price":0.46,"size":150.0,"side":"BUY"}
{"ts":"2026-08-23T17:54:10.639Z","event_type":"price_change","market_id":"3790334","outcome_index":0,"market_type":"set2","local_side":"home","local_uid":"2026-08-23_abdullah_shelbayh_dhakshineswar_suresh","bid":0.48,"ask":0.54,"mid":0.51,"spread":0.06,"price":0.54,"size":150.0,"side":"SELL"}
{"ts":"2026-08-23T17:54:10.680Z","event_type":"best_bid_ask","market_id":"3790334","outcome_index":0,"market_type":"set2","local_side":"home","local_uid":"2026-08-23_abdullah_shelbayh_dhakshineswar_suresh","bid":0.48,"ask":0.51,"mid":0.495,"spread":0.03,"bid_size":null,"ask_size":null}
{"ts":"2026-08-23T17:54:10.680Z","event_type":"best_bid_ask","market_id":"3790334","outcome_index":1,"market_type":"set2","local_side":"away","local_uid":"2026-08-23_abdullah_shelbayh_dhakshineswar_suresh","bid":0.49,"ask":0.52,"mid":0.505,"spread":0.03,"bid_size":null,"ask_size":null}
{"ts":"2026-08-23T17:54:10.680Z","event_type":"price_change","market_id":"3790334","outcome_index":1,"market_type":"set2","local_side":"away","local_uid":"2026-08-23_abdullah_shelbayh_dhakshineswar_suresh","bid":0.49,"ask":0.52,"mid":0.505,"spread":0.03,"price":0.49,"size":86.59,"side":"BUY"}
{"ts":"2026-08-23T17:54:10.680Z","event_type":"price_change","market_id":"3790334","outcome_index":0,"market_type":"set2","local_side":"home","local_uid":"2026-08-23_abdullah_shelbayh_dhakshineswar_suresh","bid":0.48,"ask":0.51,"mid":0.495,"spread":0.03,"price":0.51,"size":86.59,"side":"SELL"}
{"ts":"2026-08-23T17:54:10.723Z","event_type":"best_bid_ask","market_id":"3790334","outcome_index":0,"market_type":"set2","local_side":"home","local_uid":"2026-08-23_abdullah_shelbayh_dhakshineswar_suresh","bid":0.48,"ask":0.54,"mid":0.51,"spread":0.06,"bid_size":null,"ask_size":null}
{"ts":"2026-08-23T17:54:10.723Z","event_type":"best_bid_ask","market_id":"3790334","outcome_index":1,"market_type":"set2","local_side":"away","local_uid":"2026-08-23_abdullah_shelbayh_dhakshineswar_suresh","bid":0.46,"ask":0.52,"mid":0.49,"spread":0.06,"bid_size":null,"ask_size":null}
{"ts":"2026-08-23T17:54:10.723Z","event_type":"price_change","market_id":"3790334","outcome_index":1,"market_type":"set2","local_side":"away","local_uid":"2026-08-23_abdullah_shelbayh_dhakshineswar_suresh","bid":0.46,"ask":0.52,"mid":0.49,"spread":0.06,"price":0.49,"size":0.0,"side":"BUY"}
{"ts":"2026-08-23T17:54:10.724Z","event_type":"price_change","market_id":"3790334","outcome_index":0,"market_type":"set2","local_side":"home","local_uid":"2026-08-23_abdullah_shelbayh_dhakshineswar_suresh","bid":0.48,"ask":0.54,"mid":0.51,"spread":0.06,"price":0.51,"size":0.0,"side":"SELL"}
{"ts":"2026-08-23T17:54:10.855Z","event_type":"best_bid_ask","market_id":"3790334","outcome_index":0,"market_type":"set2","local_side":"home","local_uid":"2026-08-23_abdullah_shelbayh_dhakshineswar_suresh","bid":0.48,"ask":0.53,"mid":0.505,"spread":0.05,"bid_size":null,"ask_size":null}
{"ts":"2026-08-23T17:54:10.855Z","event_type":"best_bid_ask","market_id":"3790334","outcome_index":1,"market_type":"set2","local_side":"away","local_uid":"2026-08-23_abdullah_shelbayh_dhakshineswar_suresh","bid":0.47,"ask":0.52,"mid":0.495,"spread":0.05,"bid_size":null,"ask_size":null}
{"ts":"2026-08-23T17:54:10.855Z","event_type":"price_change","market_id":"3790334","outcome_index":1,"market_type":"set2","local_side":"away","local_uid":"2026-08-23_abdullah_shelbayh_dhakshineswar_suresh","bid":0.47,"ask":0.52,"mid":0.495,"spread":0.05,"price":0.47,"size":150.0,"side":"BUY"}
{"ts":"2026-08-23T17:54:10.855Z","event_type":"price_change","market_id":"3790334","outcome_index":0,"market_type":"set2","local_side":"home","local_uid":"2026-08-23_abdullah_shelbayh_dhakshineswar_suresh","bid":0.48,"ask":0.53,"mid":0.505,"spread":0.05,"price":0.53,"size":150.0,"side":"SELL"}
{"ts":"2026-08-23T17:54:11.264Z","event_type":"best_bid_ask","market_id":"3790415","outcome_index":0,"market_type":"set2","local_side":"home","local_uid":"2026-08-23_pierre_hugues_herbert_quinn_vandecasteele","bid":0.57,"ask":0.66,"mid":0.615,"spread":0.09,"bid_size":null,"ask_size":null}
{"ts":"2026-08-23T17:54:11.264Z","event_type":"best_bid_ask","market_id":"3790415","outcome_index":1,"market_type":"set2","local_side":"away","local_uid":"2026-08-23_pierre_hugues_herbert_quinn_vandecasteele","bid":0.34,"ask":0.43,"mid":0.385,"spread":0.09,"bid_size":null,"ask_size":null}
{"ts":"2026-08-23T17:54:11.264Z","event_type":"price_change","market_id":"3790415","outcome_index":0,"market_type":"set2","local_side":"home","local_uid":"2026-08-23_pierre_hugues_herbert_quinn_vandecasteele","bid":0.57,"ask":0.66,"mid":0.615,"spread":0.09,"price":0.58,"size":0.0,"side":"BUY"}
{"ts":"2026-08-23T17:54:11.264Z","event_type":"price_change","market_id":"3790415","outcome_index":1,"market_type":"set2","local_side":"away","local_uid":"2026-08-23_pierre_hugues_herbert_quinn_vandecasteele","bid":0.34,"ask":0.43,"mid":0.385,"spread":0.09,"price":0.42,"size":0.0,"side":"SELL"}
{"ts":"2026-08-23T17:54:11.270Z","event_type":"best_bid_ask","market_id":"3790415","outcome_index":0,"market_type":"set2","local_side":"home","local_uid":"2026-08-23_pierre_hugues_herbert_quinn_vandecasteele","bid":0.55,"ask":0.66,"mid":0.605,"spread":0.11,"bid_size":null,"ask_size":null}
{"ts":"2026-08-23T17:54:11.270Z","event_type":"best_bid_ask","market_id":"3790415","outcome_index":1,"market_type":"set2","local_side":"away","local_uid":"2026-08-23_pierre_hugues_herbert_quinn_vandecasteele","bid":0.34,"ask":0.45,"mid":0.395,"spread":0.11,"bid_size":null,"ask_size":null}
{"ts":"2026-08-23T17:54:11.270Z","event_type":"price_change","market_id":"3790415","outcome_index":0,"market_type":"set2","local_side":"home","local_uid":"2026-08-23_pierre_hugues_herbert_quinn_vandecasteele","bid":0.55,"ask":0.66,"mid":0.605,"spread":0.11,"price":0.57,"size":0.0,"side":"BUY"}
{"ts":"2026-08-23T17:54:11.270Z","event_type":"price_change","market_id":"3790415","outcome_index":1,"market_type":"set2","local_side":"away","local_uid":"2026-08-23_pierre_hugues_herbert_quinn_vandecasteele","bid":0.34,"ask":0.45,"mid":0.395,"spread":0.11,"price":0.43,"size":0.0,"side":"SELL"}
{"ts":"2026-08-23T17:54:11.286Z","event_type":"best_bid_ask","market_id":"3790394","outcome_index":0,"market_type":"set1","local_side":"home","local_uid":"2026-08-23_hugo_grenier_mees_rottgering","bid":0.21,"ask":0.32,"mid":0.265,"spread":0.11,"bid_size":null,"ask_size":null}
{"ts":"2026-08-23T17:54:11.287Z","event_type":"best_bid_ask","market_id":"3790394","outcome_index":1,"market_type":"set1","local_side":"away","local_uid":"2026-08-23_hugo_grenier_mees_rottgering","bid":0.68,"ask":0.79,"mid":0.735,"spread":0.11,"bid_size":null,"ask_size":null}
{"ts":"2026-08-23T17:54:11.287Z","event_type":"price_change","market_id":"3790394","outcome_index":0,"market_type":"set1","local_side":"home","local_uid":"2026-08-23_hugo_grenier_mees_rottgering","bid":0.21,"ask":0.32,"mid":0.265,"spread":0.11,"price":0.24,"size":0.0,"side":"BUY"}
{"ts":"2026-08-23T17:54:11.287Z","event_type":"price_change","market_id":"3790394","outcome_index":1,"market_type":"set1","local_side":"away","local_uid":"2026-08-23_hugo_grenier_mees_rottgering","bid":0.68,"ask":0.79,"mid":0.735,"spread":0.11,"price":0.76,"size":0.0,"side":"SELL"}
{"ts":"2026-08-23T17:54:11.304Z","event_type":"best_bid_ask","market_id":"3790415","outcome_index":0,"market_type":"set2","local_side":"home","local_uid":"2026-08-23_pierre_hugues_herbert_quinn_vandecasteele","bid":0.56,"ask":0.66,"mid":0.61,"spread":0.1,"bid_size":null,"ask_size":null}
{"ts":"2026-08-23T17:54:11.304Z","event_type":"best_bid_ask","market_id":"3790415","outcome_index":1,"market_type":"set2","local_side":"away","local_uid":"2026-08-23_pierre_hugues_herbert_quinn_vandecasteele","bid":0.34,"ask":0.44,"mid":0.39,"spread":0.1,"bid_size":null,"ask_size":null}
{"ts":"2026-08-23T17:54:11.304Z","event_type":"price_change","market_id":"3790415","outcome_index":0,"market_type":"set2","local_side":"home","local_uid":"2026-08-23_pierre_hugues_herbert_quinn_vandecasteele","bid":0.56,"ask":0.66,"mid":0.61,"spread":0.1,"price":0.56,"size":150.0,"side":"BUY"}
{"ts":"2026-08-23T17:54:11.304Z","event_type":"price_change","market_id":"3790415","outcome_index":1,"market_type":"set2","local_side":"away","local_uid":"2026-08-23_pierre_hugues_herbert_quinn_vandecasteele","bid":0.34,"ask":0.44,"mid":0.39,"spread":0.1,"price":0.44,"size":150.0,"side":"SELL"}
{"ts":"2026-08-23T17:54:11.820Z","event_type":"best_bid_ask","market_id":"3790334","outcome_index":0,"market_type":"set2","local_side":"home","local_uid":"2026-08-23_abdullah_shelbayh_dhakshineswar_suresh","bid":0.48,"ask":0.54,"mid":0.51,"spread":0.06,"bid_size":null,"ask_size":null}
{"ts":"2026-08-23T17:54:11.820Z","event_type":"best_bid_ask","market_id":"3790334","outcome_index":1,"market_type":"set2","local_side":"away","local_uid":"2026-08-23_abdullah_shelbayh_dhakshineswar_suresh","bid":0.46,"ask":0.52,"mid":0.49,"spread":0.06,"bid_size":null,"ask_size":null}
{"ts":"2026-08-23T17:54:11.820Z","event_type":"price_change","market_id":"3790334","outcome_index":1,"market_type":"set2","local_side":"away","local_uid":"2026-08-23_abdullah_shelbayh_dhakshineswar_suresh","bid":0.46,"ask":0.52,"mid":0.49,"spread":0.06,"price":0.47,"size":0.0,"side":"BUY"}
{"ts":"2026-08-23T17:54:11.820Z","event_type":"price_change","market_id":"3790334","outcome_index":0,"market_type":"set2","local_side":"home","local_uid":"2026-08-23_abdullah_shelbayh_dhakshineswar_suresh","bid":0.48,"ask":0.54,"mid":0.51,"spread":0.06,"price":0.53,"size":0.0,"side":"SELL"}
{"ts":"2026-08-23T17:54:11.869Z","event_type":"best_bid_ask","market_id":"3790334","outcome_index":0,"market_type":"set2","local_side":"home","local_uid":"2026-08-23_abdullah_shelbayh_dhakshineswar_suresh","bid":0.48,"ask":0.51,"mid":0.495,"spread":0.03,"bid_size":null,"ask_size":null}
{"ts":"2026-08-23T17:54:11.869Z","event_type":"best_bid_ask","market_id":"3790334","outcome_index":1,"market_type":"set2","local_side":"away","local_uid":"2026-08-23_abdullah_shelbayh_dhakshineswar_suresh","bid":0.49,"ask":0.52,"mid":0.505,"spread":0.03,"bid_size":null,"ask_size":null}
{"ts":"2026-08-23T17:54:11.869Z","event_type":"price_change","market_id":"3790334","outcome_index":1,"market_type":"set2","local_side":"away","local_uid":"2026-08-23_abdullah_shelbayh_dhakshineswar_suresh","bid":0.49,"ask":0.52,"mid":0.505,"spread":0.03,"price":0.49,"size":130.24,"side":"BUY"}
{"ts":"2026-08-23T17:54:11.869Z","event_type":"price_change","market_id":"3790334","outcome_index":0,"market_type":"set2","local_side":"home","local_uid":"2026-08-23_abdullah_shelbayh_dhakshineswar_suresh","bid":0.48,"ask":0.51,"mid":0.495,"spread":0.03,"price":0.51,"size":130.24,"side":"SELL"}
{"ts":"2026-08-23T17:54:11.913Z","event_type":"best_bid_ask","market_id":"3790334","outcome_index":0,"market_type":"set2","local_side":"home","local_uid":"2026-08-23_abdullah_shelbayh_dhakshineswar_suresh","bid":0.48,"ask":0.52,"mid":0.5,"spread":0.04,"bid_size":null,"ask_size":null}
{"ts":"2026-08-23T17:54:11.913Z","event_type":"best_bid_ask","market_id":"3790334","outcome_index":1,"market_type":"set2","local_side":"away","local_uid":"2026-08-23_abdullah_shelbayh_dhakshineswar_suresh","bid":0.48,"ask":0.52,"mid":0.5,"spread":0.04,"bid_size":null,"ask_size":null}
{"ts":"2026-08-23T17:54:11.913Z","event_type":"price_change","market_id":"3790334","outcome_index":1,"market_type":"set2","local_side":"away","local_uid":"2026-08-23_abdullah_shelbayh_dhakshineswar_suresh","bid":0.48,"ask":0.52,"mid":0.5,"spread":0.04,"price":0.49,"size":0.0,"side":"BUY"}
{"ts":"2026-08-23T17:54:11.913Z","event_type":"price_change","market_id":"3790334","outcome_index":0,"market_type":"set2","local_side":"home","local_uid":"2026-08-23_abdullah_shelbayh_dhakshineswar_suresh","bid":0.48,"ask":0.52,"mid":0.5,"spread":0.04,"price":0.51,"size":0.0,"side":"SELL"}
{"ts":"2026-08-23T17:54:11.945Z","event_type":"best_bid_ask","market_id":"3790334","outcome_index":0,"market_type":"set2","local_side":"home","local_uid":"2026-08-23_abdullah_shelbayh_dhakshineswar_suresh","bid":0.48,"ask":0.55,"mid":0.515,"spread":0.07,"bid_size":null,"ask_size":null}
{"ts":"2026-08-23T17:54:11.945Z","event_type":"best_bid_ask","market_id":"3790334","outcome_index":1,"market_type":"set2","local_side":"away","local_uid":"2026-08-23_abdullah_shelbayh_dhakshineswar_suresh","bid":0.45,"ask":0.52,"mid":0.485,"spread":0.07,"bid_size":null,"ask_size":null}
{"ts":"2026-08-23T17:54:11.945Z","event_type":"price_change","market_id":"3790334","outcome_index":1,"market_type":"set2","local_side":"away","local_uid":"2026-08-23_abdullah_shelbayh_dhakshineswar_suresh","bid":0.45,"ask":0.52,"mid":0.485,"spread":0.07,"price":0.48,"size":0.0,"side":"BUY"}
{"ts":"2026-08-23T17:54:11.945Z","event_type":"price_change","market_id":"3790334","outcome_index":0,"market_type":"set2","local_side":"home","local_uid":"2026-08-23_abdullah_shelbayh_dhakshineswar_suresh","bid":0.48,"ask":0.55,"mid":0.515,"spread":0.07,"price":0.52,"size":0.0,"side":"SELL"}
{"ts":"2026-08-23T17:54:11.958Z","event_type":"best_bid_ask","market_id":"3790334","outcome_index":0,"market_type":"set2","local_side":"home","local_uid":"2026-08-23_abdullah_shelbayh_dhakshineswar_suresh","bid":0.48,"ask":0.52,"mid":0.5,"spread":0.04,"bid_size":null,"ask_size":null}
{"ts":"2026-08-23T17:54:11.958Z","event_type":"best_bid_ask","market_id":"3790334","outcome_index":1,"market_type":"set2","local_side":"away","local_uid":"2026-08-23_abdullah_shelbayh_dhakshineswar_suresh","bid":0.48,"ask":0.52,"mid":0.5,"spread":0.04,"bid_size":null,"ask_size":null}
{"ts":"2026-08-23T17:54:11.959Z","event_type":"price_change","market_id":"3790334","outcome_index":1,"market_type":"set2","local_side":"away","local_uid":"2026-08-23_abdullah_shelbayh_dhakshineswar_suresh","bid":0.48,"ask":0.52,"mid":0.5,"spread":0.04,"price":0.48,"size":150.0,"side":"BUY"}
{"ts":"2026-08-23T17:54:11.959Z","event_type":"price_change","market_id":"3790334","outcome_index":0,"market_type":"set2","local_side":"home","local_uid":"2026-08-23_abdullah_shelbayh_dhakshineswar_suresh","bid":0.48,"ask":0.52,"mid":0.5,"spread":0.04,"price":0.52,"size":150.0,"side":"SELL"}
{"ts":"2026-08-23T17:54:11.998Z","event_type":"best_bid_ask","market_id":"3790334","outcome_index":0,"market_type":"set2","local_side":"home","local_uid":"2026-08-23_abdullah_shelbayh_dhakshineswar_suresh","bid":0.48,"ask":0.54,"mid":0.51,"spread":0.06,"bid_size":null,"ask_size":null}
{"ts":"2026-08-23T17:54:11.998Z","event_type":"best_bid_ask","market_id":"3790334","outcome_index":1,"market_type":"set2","local_side":"away","local_uid":"2026-08-23_abdullah_shelbayh_dhakshineswar_suresh","bid":0.46,"ask":0.52,"mid":0.49,"spread":0.06,"bid_size":null,"ask_size":null}
{"ts":"2026-08-23T17:54:11.998Z","event_type":"price_change","market_id":"3790334","outcome_index":1,"market_type":"set2","local_side":"away","local_uid":"2026-08-23_abdullah_shelbayh_dhakshineswar_suresh","bid":0.46,"ask":0.52,"mid":0.49,"spread":0.06,"price":0.48,"size":0.0,"side":"BUY"}
{"ts":"2026-08-23T17:54:11.998Z","event_type":"price_change","market_id":"3790334","outcome_index":0,"market_type":"set2","local_side":"home","local_uid":"2026-08-23_abdullah_shelbayh_dhakshineswar_suresh","bid":0.48,"ask":0.54,"mid":0.51,"spread":0.06,"price":0.52,"size":0.0,"side":"SELL"}
{"ts":"2026-08-23T17:54:12.041Z","event_type":"best_bid_ask","market_id":"3790334","outcome_index":0,"market_type":"set2","local_side":"home","local_uid":"2026-08-23_abdullah_shelbayh_dhakshineswar_suresh","bid":0.48,"ask":0.52,"mid":0.5,"spread":0.04,"bid_size":null,"ask_size":null}
{"ts":"2026-08-23T17:54:12.041Z","event_type":"best_bid_ask","market_id":"3790334","outcome_index":1,"market_type":"set2","local_side":"away","local_uid":"2026-08-23_abdullah_shelbayh_dhakshineswar_suresh","bid":0.48,"ask":0.52,"mid":0.5,"spread":0.04,"bid_size":null,"ask_size":null}
{"ts":"2026-08-23T17:54:12.041Z","event_type":"price_change","market_id":"3790334","outcome_index":1,"market_type":"set2","local_side":"away","local_uid":"2026-08-23_abdullah_shelbayh_dhakshineswar_suresh","bid":0.48,"ask":0.52,"mid":0.5,"spread":0.04,"price":0.48,"size":72.36,"side":"BUY"}
{"ts":"2026-08-23T17:54:12.041Z","event_type":"price_change","market_id":"3790334","outcome_index":0,"market_type":"set2","local_side":"home","local_uid":"2026-08-23_abdullah_shelbayh_dhakshineswar_suresh","bid":0.48,"ask":0.52,"mid":0.5,"spread":0.04,"price":0.52,"size":72.36,"side":"SELL"}
{"ts":"2026-08-23T17:54:12.062Z","event_type":"book","market_id":"3789997","outcome_index":0,"market_type":"match","local_side":"home","local_uid":"2026-08-23_oscar_weightman_alec_deckers","bid":0.05,"ask":0.07,"mid":0.06,"spread":0.02,"bid_size":1154.66,"ask_size":800.0}
{"ts":"2026-08-23T17:54:12.063Z","event_type":"book","market_id":"3789997","outcome_index":1,"market_type":"match","local_side":"away","local_uid":"2026-08-23_oscar_weightman_alec_deckers","bid":0.93,"ask":0.95,"mid":0.94,"spread":0.02,"bid_size":800.0,"ask_size":1154.66}
{"ts":"2026-08-23T17:54:12.063Z","event_type":"book","market_id":"3789927","outcome_index":0,"market_type":"match","local_side":"home","local_uid":"2026-08-23_hugo_grenier_mees_rottgering","bid":0.26,"ask":0.27,"mid":0.265,"spread":0.01,"bid_size":29.0,"ask_size":2181.23}
{"ts":"2026-08-23T17:54:12.064Z","event_type":"book","market_id":"3789927","outcome_index":1,"market_type":"match","local_side":"away","local_uid":"2026-08-23_hugo_grenier_mees_rottgering","bid":0.73,"ask":0.74,"mid":0.735,"spread":0.01,"bid_size":2181.23,"ask_size":29.0}
{"ts":"2026-08-23T17:54:12.080Z","event_type":"best_bid_ask","market_id":"3790334","outcome_index":0,"market_type":"set2","local_side":"home","local_uid":"2026-08-23_abdullah_shelbayh_dhakshineswar_suresh","bid":0.48,"ask":0.53,"mid":0.505,"spread":0.05,"bid_size":null,"ask_size":null}
{"ts":"2026-08-23T17:54:12.080Z","event_type":"best_bid_ask","market_id":"3790334","outcome_index":1,"market_type":"set2","local_side":"away","local_uid":"2026-08-23_abdullah_shelbayh_dhakshineswar_suresh","bid":0.47,"ask":0.52,"mid":0.495,"spread":0.05,"bid_size":null,"ask_size":null}
{"ts":"2026-08-23T17:54:12.080Z","event_type":"price_change","market_id":"3790334","outcome_index":1,"market_type":"set2","local_side":"away","local_uid":"2026-08-23_abdullah_shelbayh_dhakshineswar_suresh","bid":0.47,"ask":0.52,"mid":0.495,"spread":0.05,"price":0.48,"size":0.0,"side":"BUY"}
{"ts":"2026-08-23T17:54:12.080Z","event_type":"price_change","market_id":"3790334","outcome_index":0,"market_type":"set2","local_side":"home","local_uid":"2026-08-23_abdullah_shelbayh_dhakshineswar_suresh","bid":0.48,"ask":0.53,"mid":0.505,"spread":0.05,"price":0.52,"size":0.0,"side":"SELL"}
{"ts":"2026-08-23T17:54:12.085Z","event_type":"best_bid_ask","market_id":"3790334","outcome_index":0,"market_type":"set2","local_side":"home","local_uid":"2026-08-23_abdullah_shelbayh_dhakshineswar_suresh","bid":0.48,"ask":0.54,"mid":0.51,"spread":0.06,"bid_size":null,"ask_size":null}
{"ts":"2026-08-23T17:54:12.085Z","event_type":"best_bid_ask","market_id":"3790334","outcome_index":1,"market_type":"set2","local_side":"away","local_uid":"2026-08-23_abdullah_shelbayh_dhakshineswar_suresh","bid":0.46,"ask":0.52,"mid":0.49,"spread":0.06,"bid_size":null,"ask_size":null}
{"ts":"2026-08-23T17:54:12.085Z","event_type":"price_change","market_id":"3790334","outcome_index":1,"market_type":"set2","local_side":"away","local_uid":"2026-08-23_abdullah_shelbayh_dhakshineswar_suresh","bid":0.46,"ask":0.52,"mid":0.49,"spread":0.06,"price":0.47,"size":0.0,"side":"BUY"}
{"ts":"2026-08-23T17:54:12.085Z","event_type":"price_change","market_id":"3790334","outcome_index":0,"market_type":"set2","local_side":"home","local_uid":"2026-08-23_abdullah_shelbayh_dhakshineswar_suresh","bid":0.48,"ask":0.54,"mid":0.51,"spread":0.06,"price":0.53,"size":0.0,"side":"SELL"}
{"ts":"2026-08-23T17:54:12.086Z","event_type":"best_bid_ask","market_id":"3790334","outcome_index":0,"market_type":"set2","local_side":"home","local_uid":"2026-08-23_abdullah_shelbayh_dhakshineswar_suresh","bid":0.48,"ask":0.53,"mid":0.505,"spread":0.05,"bid_size":null,"ask_size":null}
{"ts":"2026-08-23T17:54:12.086Z","event_type":"best_bid_ask","market_id":"3790334","outcome_index":1,"market_type":"set2","local_side":"away","local_uid":"2026-08-23_abdullah_shelbayh_dhakshineswar_suresh","bid":0.47,"ask":0.52,"mid":0.495,"spread":0.05,"bid_size":null,"ask_size":null}
{"ts":"2026-08-23T17:54:12.086Z","event_type":"price_change","market_id":"3790334","outcome_index":1,"market_type":"set2","local_side":"away","local_uid":"2026-08-23_abdullah_shelbayh_dhakshineswar_suresh","bid":0.47,"ask":0.52,"mid":0.495,"spread":0.05,"price":0.47,"size":26.0,"side":"BUY"}
{"ts":"2026-08-23T17:54:12.086Z","event_type":"price_change","market_id":"3790334","outcome_index":0,"market_type":"set2","local_side":"home","local_uid":"2026-08-23_abdullah_shelbayh_dhakshineswar_suresh","bid":0.48,"ask":0.53,"mid":0.505,"spread":0.05,"price":0.53,"size":26.0,"side":"SELL"}
{"ts":"2026-08-23T17:54:12.086Z","event_type":"best_bid_ask","market_id":"3790334","outcome_index":0,"market_type":"set2","local_side":"home","local_uid":"2026-08-23_abdullah_shelbayh_dhakshineswar_suresh","bid":0.48,"ask":0.52,"mid":0.5,"spread":0.04,"bid_size":null,"ask_size":null}
{"ts":"2026-08-23T17:54:12.086Z","event_type":"best_bid_ask","market_id":"3790334","outcome_index":1,"market_type":"set2","local_side":"away","local_uid":"2026-08-23_abdullah_shelbayh_dhakshineswar_suresh","bid":0.48,"ask":0.52,"mid":0.5,"spread":0.04,"bid_size":null,"ask_size":null}
{"ts":"2026-08-23T17:54:12.086Z","event_type":"price_change","market_id":"3790334","outcome_index":1,"market_type":"set2","local_side":"away","local_uid":"2026-08-23_abdullah_shelbayh_dhakshineswar_suresh","bid":0.48,"ask":0.52,"mid":0.5,"spread":0.04,"price":0.48,"size":44.0,"side":"BUY"}
{"ts":"2026-08-23T17:54:12.086Z","event_type":"price_change","market_id":"3790334","outcome_index":0,"market_type":"set2","local_side":"home","local_uid":"2026-08-23_abdullah_shelbayh_dhakshineswar_suresh","bid":0.48,"ask":0.52,"mid":0.5,"spread":0.04,"price":0.52,"size":44.0,"side":"SELL"}
{"ts":"2026-08-23T17:54:12.110Z","event_type":"best_bid_ask","market_id":"3790334","outcome_index":0,"market_type":"set2","local_side":"home","local_uid":"2026-08-23_abdullah_shelbayh_dhakshineswar_suresh","bid":0.48,"ask":0.54,"mid":0.51,"spread":0.06,"bid_size":null,"ask_size":null}
{"ts":"2026-08-23T17:54:12.110Z","event_type":"best_bid_ask","market_id":"3790334","outcome_index":1,"market_type":"set2","local_side":"away","local_uid":"2026-08-23_abdullah_shelbayh_dhakshineswar_suresh","bid":0.46,"ask":0.52,"mid":0.49,"spread":0.06,"bid_size":null,"ask_size":null}
{"ts":"2026-08-23T17:54:12.110Z","event_type":"price_change","market_id":"3790334","outcome_index":1,"market_type":"set2","local_side":"away","local_uid":"2026-08-23_abdullah_shelbayh_dhakshineswar_suresh","bid":0.46,"ask":0.52,"mid":0.49,"spread":0.06,"price":0.48,"size":0.0,"side":"BUY"}
{"ts":"2026-08-23T17:54:12.110Z","event_type":"price_change","market_id":"3790334","outcome_index":0,"market_type":"set2","local_side":"home","local_uid":"2026-08-23_abdullah_shelbayh_dhakshineswar_suresh","bid":0.48,"ask":0.54,"mid":0.51,"spread":0.06,"price":0.52,"size":0.0,"side":"SELL"}
{"ts":"2026-08-23T17:54:12.125Z","event_type":"best_bid_ask","market_id":"3790334","outcome_index":0,"market_type":"set2","local_side":"home","local_uid":"2026-08-23_abdullah_shelbayh_dhakshineswar_suresh","bid":0.48,"ask":0.53,"mid":0.505,"spread":0.05,"bid_size":null,"ask_size":null}
{"ts":"2026-08-23T17:54:12.125Z","event_type":"best_bid_ask","market_id":"3790334","outcome_index":1,"market_type":"set2","local_side":"away","local_uid":"2026-08-23_abdullah_shelbayh_dhakshineswar_suresh","bid":0.47,"ask":0.52,"mid":0.495,"spread":0.05,"bid_size":null,"ask_size":null}
{"ts":"2026-08-23T17:54:12.126Z","event_type":"price_change","market_id":"3790334","outcome_index":1,"market_type":"set2","local_side":"away","local_uid":"2026-08-23_abdullah_shelbayh_dhakshineswar_suresh","bid":0.47,"ask":0.52,"mid":0.495,"spread":0.05,"price":0.47,"size":150.0,"side":"BUY"}
{"ts":"2026-08-23T17:54:12.126Z","event_type":"price_change","market_id":"3790334","outcome_index":0,"market_type":"set2","local_side":"home","local_uid":"2026-08-23_abdullah_shelbayh_dhakshineswar_suresh","bid":0.48,"ask":0.53,"mid":0.505,"spread":0.05,"price":0.53,"size":150.0,"side":"SELL"}
{"ts":"2026-08-23T17:54:12.138Z","event_type":"last_trade_price","market_id":"3789927","outcome_index":0,"market_type":"match","local_side":"home","local_uid":"2026-08-23_hugo_grenier_mees_rottgering","last_trade":0.27,"trade_size":1851.8519,"trade_side":"BUY","trade_notional":500.0}
