{"ts":"2026-08-23T17:52:16.311Z","event_type":"price_change","market_id":"3795958","outcome_index":1,"market_type":"match","local_side":"away","local_uid":"2026-08-23_bruno_kuzuhara_kody_pearson","bid":0.03,"ask":0.042,"mid":0.036,"spread":0.012,"price":0.043,"size":2622.35,"side":"SELL"}
{"ts":"2026-08-23T17:52:16.360Z","event_type":"best_bid_ask","market_id":"3795958","outcome_index":0,"market_type":"match","local_side":"home","local_uid":"2026-08-23_bruno_kuzuhara_kody_pearson","bid":0.958,"ask":0.974,"mid":0.966,"spread":0.016,"bid_size":null,"ask_size":null}
{"ts":"2026-08-23T17:52:16.360Z","event_type":"best_bid_ask","market_id":"3795958","outcome_index":1,"market_type":"match","local_side":"away","local_uid":"2026-08-23_bruno_kuzuhara_kody_pearson","bid":0.026,"ask":0.042,"mid":0.034,"spread":0.016,"bid_size":null,"ask_size":null}
{"ts":"2026-08-23T17:52:16.360Z","event_type":"price_change","market_id":"3795958","outcome_index":1,"market_type":"match","local_side":"away","local_uid":"2026-08-23_bruno_kuzuhara_kody_pearson","bid":0.026,"ask":0.042,"mid":0.034,"spread":0.016,"price":0.03,"size":0.0,"side":"BUY"}
{"ts":"2026-08-23T17:52:16.361Z","event_type":"price_change","market_id":"3795958","outcome_index":0,"market_type":"match","local_side":"home","local_uid":"2026-08-23_bruno_kuzuhara_kody_pearson","bid":0.958,"ask":0.974,"mid":0.966,"spread":0.016,"price":0.97,"size":0.0,"side":"SELL"}
{"ts":"2026-08-23T17:52:16.394Z","event_type":"best_bid_ask","market_id":"3790394","outcome_index":0,"market_type":"set1","local_side":"home","local_uid":"2026-08-23_hugo_grenier_mees_rottgering","bid":0.26,"ask":0.34,"mid":0.3,"spread":0.08,"bid_size":null,"ask_size":null}
{"ts":"2026-08-23T17:52:16.394Z","event_type":"best_bid_ask","market_id":"3790394","outcome_index":1,"market_type":"set1","local_side":"away","local_uid":"2026-08-23_hugo_grenier_mees_rottgering","bid":0.66,"ask":0.74,"mid":0.7,"spread":0.08,"bid_size":null,"ask_size":null}
{"ts":"2026-08-23T17:52:16.394Z","event_type":"price_change","market_id":"3790394","outcome_index":0,"market_type":"set1","local_side":"home","local_uid":"2026-08-23_hugo_grenier_mees_rottgering","bid":0.26,"ask":0.34,"mid":0.3,"spread":0.08,"price":0.27,"size":0.0,"side":"BUY"}
{"ts":"2026-08-23T17:52:16.394Z","event_type":"price_change","market_id":"3790394","outcome_index":1,"market_type":"set1","local_side":"away","local_uid":"2026-08-23_hugo_grenier_mees_rottgering","bid":0.66,"ask":0.74,"mid":0.7,"spread":0.08,"price":0.73,"size":0.0,"side":"SELL"}
{"ts":"2026-08-23T17:52:16.491Z","event_type":"best_bid_ask","market_id":"3790334","outcome_index":0,"market_type":"set2","local_side":"home","local_uid":"2026-08-23_abdullah_shelbayh_dhakshineswar_suresh","bid":0.49,"ask":0.54,"mid":0.515,"spread":0.05,"bid_size":null,"ask_size":null}
{"ts":"2026-08-23T17:52:16.491Z","event_type":"best_bid_ask","market_id":"3790334","outcome_index":1,"market_type":"set2","local_side":"away","local_uid":"2026-08-23_abdullah_shelbayh_dhakshineswar_suresh","bid":0.46,"ask":0.51,"mid":0.485,"spread":0.05,"bid_size":null,"ask_size":null}
{"ts":"2026-08-23T17:52:16.491Z","event_type":"price_change","market_id":"3790334","outcome_index":1,"market_type":"set2","local_side":"away","local_uid":"2026-08-23_abdullah_shelbayh_dhakshineswar_suresh","bid":0.46,"ask":0.51,"mid":0.485,"spread":0.05,"price":0.46,"size":150.0,"side":"BUY"}
{"ts":"2026-08-23T17:52:16.491Z","event_type":"price_change","market_id":"3790334","outcome_index":0,"market_type":"set2","local_side":"home","local_uid":"2026-08-23_abdullah_shelbayh_dhakshineswar_suresh","bid":0.49,"ask":0.54,"mid":0.515,"spread":0.05,"price":0.54,"size":150.0,"side":"SELL"}
{"ts":"2026-08-23T17:52:16.545Z","event_type":"best_bid_ask","market_id":"3795958","outcome_index":0,"market_type":"match","local_side":"home","local_uid":"2026-08-23_bruno_kuzuhara_kody_pearson","bid":0.96,"ask":0.978,"mid":0.969,"spread":0.018,"bid_size":null,"ask_size":null}
{"ts":"2026-08-23T17:52:16.545Z","event_type":"best_bid_ask","market_id":"3795958","outcome_index":1,"market_type":"match","local_side":"away","local_uid":"2026-08-23_bruno_kuzuhara_kody_pearson","bid":0.022,"ask":0.04,"mid":0.031,"spread":0.018,"bid_size":null,"ask_size":null}
{"ts":"2026-08-23T17:52:16.545Z","event_type":"price_change","market_id":"3795958","outcome_index":1,"market_type":"match","local_side":"away","local_uid":"2026-08-23_bruno_kuzuhara_kody_pearson","bid":0.022,"ask":0.04,"mid":0.031,"spread":0.018,"price":0.026,"size":0.0,"side":"BUY"}
{"ts":"2026-08-23T17:52:16.546Z","event_type":"price_change","market_id":"3795958","outcome_index":0,"market_type":"match","local_side":"home","local_uid":"2026-08-23_bruno_kuzuhara_kody_pearson","bid":0.96,"ask":0.978,"mid":0.969,"spread":0.018,"price":0.974,"size":0.0,"side":"SELL"}
{"ts":"2026-08-23T17:52:16.702Z","event_type":"best_bid_ask","market_id":"3790415","outcome_index":0,"market_type":"set2","local_side":"home","local_uid":"2026-08-23_pierre_hugues_herbert_quinn_vandecasteele","bid":0.64,"ask":0.74,"mid":0.69,"spread":0.1,"bid_size":null,"ask_size":null}
{"ts":"2026-08-23T17:52:16.702Z","event_type":"best_bid_ask","market_id":"3790415","outcome_index":1,"market_type":"set2","local_side":"away","local_uid":"2026-08-23_pierre_hugues_herbert_quinn_vandecasteele","bid":0.26,"ask":0.36,"mid":0.31,"spread":0.1,"bid_size":null,"ask_size":null}
{"ts":"2026-08-23T17:52:16.702Z","event_type":"price_change","market_id":"3790415","outcome_index":1,"market_type":"set2","local_side":"away","local_uid":"2026-08-23_pierre_hugues_herbert_quinn_vandecasteele","bid":0.26,"ask":0.36,"mid":0.31,"spread":0.1,"price":0.27,"size":0.0,"side":"BUY"}
{"ts":"2026-08-23T17:52:16.702Z","event_type":"price_change","market_id":"3790415","outcome_index":0,"market_type":"set2","local_side":"home","local_uid":"2026-08-23_pierre_hugues_herbert_quinn_vandecasteele","bid":0.64,"ask":0.74,"mid":0.69,"spread":0.1,"price":0.73,"size":0.0,"side":"SELL"}
{"ts":"2026-08-23T17:52:16.741Z","event_type":"best_bid_ask","market_id":"3790415","outcome_index":0,"market_type":"set2","local_side":"home","local_uid":"2026-08-23_pierre_hugues_herbert_quinn_vandecasteele","bid":0.64,"ask":0.72,"mid":0.68,"spread":0.08,"bid_size":null,"ask_size":null}
{"ts":"2026-08-23T17:52:16.742Z","event_type":"best_bid_ask","market_id":"3790415","outcome_index":1,"market_type":"set2","local_side":"away","local_uid":"2026-08-23_pierre_hugues_herbert_quinn_vandecasteele","bid":0.28,"ask":0.36,"mid":0.32,"spread":0.08,"bid_size":null,"ask_size":null}
{"ts":"2026-08-23T17:52:16.742Z","event_type":"price_change","market_id":"3790415","outcome_index":1,"market_type":"set2","local_side":"away","local_uid":"2026-08-23_pierre_hugues_herbert_quinn_vandecasteele","bid":0.28,"ask":0.36,"mid":0.32,"spread":0.08,"price":0.28,"size":150.0,"side":"BUY"}
{"ts":"2026-08-23T17:52:16.742Z","event_type":"price_change","market_id":"3790415","outcome_index":0,"market_type":"set2","local_side":"home","local_uid":"2026-08-23_pierre_hugues_herbert_quinn_vandecasteele","bid":0.64,"ask":0.72,"mid":0.68,"spread":0.08,"price":0.72,"size":150.0,"side":"SELL"}
{"ts":"2026-08-23T17:52:16.892Z","event_type":"best_bid_ask","market_id":"3790415","outcome_index":0,"market_type":"set2","local_side":"home","local_uid":"2026-08-23_pierre_hugues_herbert_quinn_vandecasteele","bid":0.64,"ask":0.73,"mid":0.685,"spread":0.09,"bid_size":null,"ask_size":null}
{"ts":"2026-08-23T17:52:16.892Z","event_type":"best_bid_ask","market_id":"3790415","outcome_index":1,"market_type":"set2","local_side":"away","local_uid":"2026-08-23_pierre_hugues_herbert_quinn_vandecasteele","bid":0.27,"ask":0.36,"mid":0.315,"spread":0.09,"bid_size":null,"ask_size":null}
{"ts":"2026-08-23T17:52:16.892Z","event_type":"price_change","market_id":"3790415","outcome_index":1,"market_type":"set2","local_side":"away","local_uid":"2026-08-23_pierre_hugues_herbert_quinn_vandecasteele","bid":0.27,"ask":0.36,"mid":0.315,"spread":0.09,"price":0.28,"size":0.0,"side":"BUY"}
{"ts":"2026-08-23T17:52:16.892Z","event_type":"price_change","market_id":"3790415","outcome_index":0,"market_type":"set2","local_side":"home","local_uid":"2026-08-23_pierre_hugues_herbert_quinn_vandecasteele","bid":0.64,"ask":0.73,"mid":0.685,"spread":0.09,"price":0.72,"size":0.0,"side":"SELL"}
{"ts":"2026-08-23T17:52:16.931Z","event_type":"best_bid_ask","market_id":"3790415","outcome_index":0,"market_type":"set2","local_side":"home","local_uid":"2026-08-23_pierre_hugues_herbert_quinn_vandecasteele","bid":0.64,"ask":0.71,"mid":0.675,"spread":0.07,"bid_size":null,"ask_size":null}
{"ts":"2026-08-23T17:52:16.931Z","event_type":"best_bid_ask","market_id":"3790415","outcome_index":1,"market_type":"set2","local_side":"away","local_uid":"2026-08-23_pierre_hugues_herbert_quinn_vandecasteele","bid":0.29,"ask":0.36,"mid":0.325,"spread":0.07,"bid_size":null,"ask_size":null}
{"ts":"2026-08-23T17:52:16.931Z","event_type":"price_change","market_id":"3790415","outcome_index":1,"market_type":"set2","local_side":"away","local_uid":"2026-08-23_pierre_hugues_herbert_quinn_vandecasteele","bid":0.29,"ask":0.36,"mid":0.325,"spread":0.07,"price":0.29,"size":150.0,"side":"BUY"}
{"ts":"2026-08-23T17:52:16.931Z","event_type":"price_change","market_id":"3790415","outcome_index":0,"market_type":"set2","local_side":"home","local_uid":"2026-08-23_pierre_hugues_herbert_quinn_vandecasteele","bid":0.64,"ask":0.71,"mid":0.675,"spread":0.07,"price":0.71,"size":150.0,"side":"SELL"}
{"ts":"2026-08-23T17:52:17.107Z","event_type":"best_bid_ask","market_id":"3790334","outcome_index":0,"market_type":"set2","local_side":"home","local_uid":"2026-08-23_abdullah_shelbayh_dhakshineswar_suresh","bid":0.49,"ask":0.55,"mid":0.52,"spread":0.06,"bid_size":null,"ask_size":null}
{"ts":"2026-08-23T17:52:17.107Z","event_type":"best_bid_ask","market_id":"3790334","outcome_index":1,"market_type":"set2","local_side":"away","local_uid":"2026-08-23_abdullah_shelbayh_dhakshineswar_suresh","bid":0.45,"ask":0.51,"mid":0.48,"spread":0.06,"bid_size":null,"ask_size":null}
{"ts":"2026-08-23T17:52:17.108Z","event_type":"price_change","market_id":"3790334","outcome_index":1,"market_type":"set2","local_side":"away","local_uid":"2026-08-23_abdullah_shelbayh_dhakshineswar_suresh","bid":0.45,"ask":0.51,"mid":0.48,"spread":0.06,"price":0.46,"size":0.0,"side":"BUY"}
{"ts":"2026-08-23T17:52:17.108Z","event_type":"price_change","market_id":"3790334","outcome_index":0,"market_type":"set2","local_side":"home","local_uid":"2026-08-23_abdullah_shelbayh_dhakshineswar_suresh","bid":0.49,"ask":0.55,"mid":0.52,"spread":0.06,"price":0.54,"size":0.0,"side":"SELL"}
{"ts":"2026-08-23T17:52:17.130Z","event_type":"best_bid_ask","market_id":"3790334","outcome_index":0,"market_type":"set2","local_side":"home","local_uid":"2026-08-23_abdullah_shelbayh_dhakshineswar_suresh","bid":0.49,"ask":0.56,"mid":0.525,"spread":0.07,"bid_size":null,"ask_size":null}
{"ts":"2026-08-23T17:52:17.130Z","event_type":"best_bid_ask","market_id":"3790334","outcome_index":1,"market_type":"set2","local_side":"away","local_uid":"2026-08-23_abdullah_shelbayh_dhakshineswar_suresh","bid":0.44,"ask":0.51,"mid":0.475,"spread":0.07,"bid_size":null,"ask_size":null}
{"ts":"2026-08-23T17:52:17.130Z","event_type":"price_change","market_id":"3790334","outcome_index":1,"market_type":"set2","local_side":"away","local_uid":"2026-08-23_abdullah_shelbayh_dhakshineswar_suresh","bid":0.44,"ask":0.51,"mid":0.475,"spread":0.07,"price":0.45,"size":0.0,"side":"BUY"}
{"ts":"2026-08-23T17:52:17.130Z","event_type":"price_change","market_id":"3790334","outcome_index":0,"market_type":"set2","local_side":"home","local_uid":"2026-08-23_abdullah_shelbayh_dhakshineswar_suresh","bid":0.49,"ask":0.56,"mid":0.525,"spread":0.07,"price":0.55,"size":0.0,"side":"SELL"}
{"ts":"2026-08-23T17:52:17.153Z","event_type":"best_bid_ask","market_id":"3790323","outcome_index":0,"market_type":"set2","local_side":"home","local_uid":"2026-08-23_felix_balshaw_sebastian_gorzny","bid":0.5,"ask":0.57,"mid":0.535,"spread":0.07,"bid_size":null,"ask_size":null}
{"ts":"2026-08-23T17:52:17.153Z","event_type":"best_bid_ask","market_id":"3790323","outcome_index":1,"market_type":"set2","local_side":"away","local_uid":"2026-08-23_felix_balshaw_sebastian_gorzny","bid":0.43,"ask":0.5,"mid":0.465,"spread":0.07,"bid_size":null,"ask_size":null}
{"ts":"2026-08-23T17:52:17.153Z","event_type":"price_change","market_id":"3790323","outcome_index":0,"market_type":"set2","local_side":"home","local_uid":"2026-08-23_felix_balshaw_sebastian_gorzny","bid":0.5,"ask":0.57,"mid":0.535,"spread":0.07,"price":0.5,"size":150.0,"side":"BUY"}
{"ts":"2026-08-23T17:52:17.153Z","event_type":"price_change","market_id":"3790323","outcome_index":1,"market_type":"set2","local_side":"away","local_uid":"2026-08-23_felix_balshaw_sebastian_gorzny","bid":0.43,"ask":0.5,"mid":0.465,"spread":0.07,"price":0.5,"size":150.0,"side":"SELL"}
{"ts":"2026-08-23T17:52:17.168Z","event_type":"best_bid_ask","market_id":"3790334","outcome_index":0,"market_type":"set2","local_side":"home","local_uid":"2026-08-23_abdullah_shelbayh_dhakshineswar_suresh","bid":0.49,"ask":0.55,"mid":0.52,"spread":0.06,"bid_size":null,"ask_size":null}
{"ts":"2026-08-23T17:52:17.169Z","event_type":"best_bid_ask","market_id":"3790334","outcome_index":1,"market_type":"set2","local_side":"away","local_uid":"2026-08-23_abdullah_shelbayh_dhakshineswar_suresh","bid":0.45,"ask":0.51,"mid":0.48,"spread":0.06,"bid_size":null,"ask_size":null}
{"ts":"2026-08-23T17:52:17.169Z","event_type":"price_change","market_id":"3790334","outcome_index":1,"market_type":"set2","local_side":"away","local_uid":"2026-08-23_abdullah_shelbayh_dhakshineswar_suresh","bid":0.45,"ask":0.51,"mid":0.48,"spread":0.06,"price":0.45,"size":21.0,"side":"BUY"}
{"ts":"2026-08-23T17:52:17.169Z","event_type":"price_change","market_id":"3790334","outcome_index":0,"market_type":"set2","local_side":"home","local_uid":"2026-08-23_abdullah_shelbayh_dhakshineswar_suresh","bid":0.49,"ask":0.55,"mid":0.52,"spread":0.06,"price":0.55,"size":21.0,"side":"SELL"}
{"ts":"2026-08-23T17:52:17.210Z","event_type":"best_bid_ask","market_id":"3790334","outcome_index":0,"market_type":"set2","local_side":"home","local_uid":"2026-08-23_abdullah_shelbayh_dhakshineswar_suresh","bid":0.49,"ask":0.58,"mid":0.535,"spread":0.09,"bid_size":null,"ask_size":null}
{"ts":"2026-08-23T17:52:17.210Z","event_type":"best_bid_ask","market_id":"3790334","outcome_index":1,"market_type":"set2","local_side":"away","local_uid":"2026-08-23_abdullah_shelbayh_dhakshineswar_suresh","bid":0.42,"ask":0.51,"mid":0.465,"spread":0.09,"bid_size":null,"ask_size":null}
{"ts":"2026-08-23T17:52:17.210Z","event_type":"price_change","market_id":"3790334","outcome_index":1,"market_type":"set2","local_side":"away","local_uid":"2026-08-23_abdullah_shelbayh_dhakshineswar_suresh","bid":0.42,"ask":0.51,"mid":0.465,"spread":0.09,"price":0.45,"size":0.0,"side":"BUY"}
{"ts":"2026-08-23T17:52:17.210Z","event_type":"price_change","market_id":"3790334","outcome_index":0,"market_type":"set2","local_side":"home","local_uid":"2026-08-23_abdullah_shelbayh_dhakshineswar_suresh","bid":0.49,"ask":0.58,"mid":0.535,"spread":0.09,"price":0.55,"size":0.0,"side":"SELL"}
{"ts":"2026-08-23T17:52:17.215Z","event_type":"best_bid_ask","market_id":"3790334","outcome_index":0,"market_type":"set2","local_side":"home","local_uid":"2026-08-23_abdullah_shelbayh_dhakshineswar_suresh","bid":0.49,"ask":0.57,"mid":0.53,"spread":0.08,"bid_size":null,"ask_size":null}
{"ts":"2026-08-23T17:52:17.215Z","event_type":"best_bid_ask","market_id":"3790334","outcome_index":1,"market_type":"set2","local_side":"away","local_uid":"2026-08-23_abdullah_shelbayh_dhakshineswar_suresh","bid":0.43,"ask":0.51,"mid":0.47,"spread":0.08,"bid_size":null,"ask_size":null}
{"ts":"2026-08-23T17:52:17.215Z","event_type":"price_change","market_id":"3790334","outcome_index":1,"market_type":"set2","local_side":"away","local_uid":"2026-08-23_abdullah_shelbayh_dhakshineswar_suresh","bid":0.43,"ask":0.51,"mid":0.47,"spread":0.08,"price":0.43,"size":150.0,"side":"BUY"}
{"ts":"2026-08-23T17:52:17.215Z","event_type":"price_change","market_id":"3790334","outcome_index":0,"market_type":"set2","local_side":"home","local_uid":"2026-08-23_abdullah_shelbayh_dhakshineswar_suresh","bid":0.49,"ask":0.57,"mid":0.53,"spread":0.08,"price":0.57,"size":150.0,"side":"SELL"}
{"ts":"2026-08-23T17:52:17.373Z","event_type":"best_bid_ask","market_id":"3790334","outcome_index":0,"market_type":"set2","local_side":"home","local_uid":"2026-08-23_abdullah_shelbayh_dhakshineswar_suresh","bid":0.49,"ask":0.56,"mid":0.525,"spread":0.07,"bid_size":null,"ask_size":null}
{"ts":"2026-08-23T17:52:17.373Z","event_type":"best_bid_ask","market_id":"3790334","outcome_index":1,"market_type":"set2","local_side":"away","local_uid":"2026-08-23_abdullah_shelbayh_dhakshineswar_suresh","bid":0.44,"ask":0.51,"mid":0.475,"spread":0.07,"bid_size":null,"ask_size":null}
{"ts":"2026-08-23T17:52:17.373Z","event_type":"price_change","market_id":"3790334","outcome_index":1,"market_type":"set2","local_side":"away","local_uid":"2026-08-23_abdullah_shelbayh_dhakshineswar_suresh","bid":0.44,"ask":0.51,"mid":0.475,"spread":0.07,"price":0.44,"size":150.0,"side":"BUY"}
{"ts":"2026-08-23T17:52:17.373Z","event_type":"price_change","market_id":"3790334","outcome_index":0,"market_type":"set2","local_side":"home","local_uid":"2026-08-23_abdullah_shelbayh_dhakshineswar_suresh","bid":0.49,"ask":0.56,"mid":0.525,"spread":0.07,"price":0.56,"size":150.0,"side":"SELL"}
{"ts":"2026-08-23T17:52:19.163Z","event_type":"best_bid_ask","market_id":"3789927","outcome_index":0,"market_type":"match","local_side":"home","local_uid":"2026-08-23_hugo_grenier_mees_rottgering","bid":0.27,"ask":0.29,"mid":0.28,"spread":0.02,"bid_size":null,"ask_size":null}
{"ts":"2026-08-23T17:52:19.164Z","event_type":"best_bid_ask","market_id":"3789927","outcome_index":1,"market_type":"match","local_side":"away","local_uid":"2026-08-23_hugo_grenier_mees_rottgering","bid":0.71,"ask":0.73,"mid":0.72,"spread":0.02,"bid_size":null,"ask_size":null}
{"ts":"2026-08-23T17:52:19.164Z","event_type":"price_change","market_id":"3789927","outcome_index":0,"market_type":"match","local_side":"home","local_uid":"2026-08-23_hugo_grenier_mees_rottgering","bid":0.27,"ask":0.29,"mid":0.28,"spread":0.02,"price":0.28,"size":0.0,"side":"BUY"}
{"ts":"2026-08-23T17:52:19.164Z","event_type":"price_change","market_id":"3789927","outcome_index":1,"market_type":"match","local_side":"away","local_uid":"2026-08-23_hugo_grenier_mees_rottgering","bid":0.71,"ask":0.73,"mid":0.72,"spread":0.02,"price":0.72,"size":0.0,"side":"SELL"}
{"ts":"2026-08-23T17:52:19.239Z","event_type":"best_bid_ask","market_id":"3790394","outcome_index":0,"market_type":"set1","local_side":"home","local_uid":"2026-08-23_hugo_grenier_mees_rottgering","bid":0.26,"ask":0.35,"mid":0.305,"spread":0.09,"bid_size":null,"ask_size":null}
{"ts":"2026-08-23T17:52:19.239Z","event_type":"best_bid_ask","market_id":"3790394","outcome_index":1,"market_type":"set1","local_side":"away","local_uid":"2026-08-23_hugo_grenier_mees_rottgering","bid":0.65,"ask":0.74,"mid":0.695,"spread":0.09,"bid_size":null,"ask_size":null}
{"ts":"2026-08-23T17:52:19.239Z","event_type":"price_change","market_id":"3790394","outcome_index":1,"market_type":"set1","local_side":"away","local_uid":"2026-08-23_hugo_grenier_mees_rottgering","bid":0.65,"ask":0.74,"mid":0.695,"spread":0.09,"price":0.66,"size":0.0,"side":"BUY"}
{"ts":"2026-08-23T17:52:19.239Z","event_type":"price_change","market_id":"3790394","outcome_index":0,"market_type":"set1","local_side":"home","local_uid":"2026-08-23_hugo_grenier_mees_rottgering","bid":0.26,"ask":0.35,"mid":0.305,"spread":0.09,"price":0.34,"size":0.0,"side":"SELL"}
{"ts":"2026-08-23T17:52:19.251Z","event_type":"best_bid_ask","market_id":"3790397","outcome_index":0,"market_type":"set2","local_side":"home","local_uid":"2026-08-23_hugo_grenier_mees_rottgering","bid":0.15,"ask":0.41,"mid":0.28,"spread":0.26,"bid_size":null,"ask_size":null}
{"ts":"2026-08-23T17:52:19.251Z","event_type":"best_bid_ask","market_id":"3790397","outcome_index":1,"market_type":"set2","local_side":"away","local_uid":"2026-08-23_hugo_grenier_mees_rottgering","bid":0.59,"ask":0.85,"mid":0.72,"spread":0.26,"bid_size":null,"ask_size":null}
{"ts":"2026-08-23T17:52:19.251Z","event_type":"price_change","market_id":"3790397","outcome_index":0,"market_type":"set2","local_side":"home","local_uid":"2026-08-23_hugo_grenier_mees_rottgering","bid":0.15,"ask":0.41,"mid":0.28,"spread":0.26,"price":0.3,"size":0.0,"side":"BUY"}
{"ts":"2026-08-23T17:52:19.251Z","event_type":"price_change","market_id":"3790397","outcome_index":1,"market_type":"set2","local_side":"away","local_uid":"2026-08-23_hugo_grenier_mees_rottgering","bid":0.59,"ask":0.85,"mid":0.72,"spread":0.26,"price":0.7,"size":0.0,"side":"SELL"}
{"ts":"2026-08-23T17:52:19.257Z","event_type":"best_bid_ask","market_id":"3790397","outcome_index":0,"market_type":"set2","local_side":"home","local_uid":"2026-08-23_hugo_grenier_mees_rottgering","bid":0.0,"ask":0.41,"mid":0.205,"spread":0.41,"bid_size":null,"ask_size":null}
{"ts":"2026-08-23T17:52:19.257Z","event_type":"best_bid_ask","market_id":"3790397","outcome_index":1,"market_type":"set2","local_side":"away","local_uid":"2026-08-23_hugo_grenier_mees_rottgering","bid":0.59,"ask":1.0,"mid":0.795,"spread":0.41,"bid_size":null,"ask_size":null}
{"ts":"2026-08-23T17:52:19.257Z","event_type":"price_change","market_id":"3790397","outcome_index":0,"market_type":"set2","local_side":"home","local_uid":"2026-08-23_hugo_grenier_mees_rottgering","bid":0.0,"ask":0.41,"mid":0.205,"spread":0.41,"price":0.15,"size":0.0,"side":"BUY"}
{"ts":"2026-08-23T17:52:19.257Z","event_type":"price_change","market_id":"3790397","outcome_index":1,"market_type":"set2","local_side":"away","local_uid":"2026-08-23_hugo_grenier_mees_rottgering","bid":0.59,"ask":1.0,"mid":0.795,"spread":0.41,"price":0.85,"size":0.0,"side":"SELL"}
{"ts":"2026-08-23T17:52:19.263Z","event_type":"best_bid_ask","market_id":"3790394","outcome_index":0,"market_type":"set1","local_side":"home","local_uid":"2026-08-23_hugo_grenier_mees_rottgering","bid":0.25,"ask":0.37,"mid":0.31,"spread":0.12,"bid_size":null,"ask_size":null}
{"ts":"2026-08-23T17:52:19.263Z","event_type":"best_bid_ask","market_id":"3790394","outcome_index":1,"market_type":"set1","local_side":"away","local_uid":"2026-08-23_hugo_grenier_mees_rottgering","bid":0.63,"ask":0.75,"mid":0.69,"spread":0.12,"bid_size":null,"ask_size":null}
{"ts":"2026-08-23T17:52:19.263Z","event_type":"price_change","market_id":"3790394","outcome_index":1,"market_type":"set1","local_side":"away","local_uid":"2026-08-23_hugo_grenier_mees_rottgering","bid":0.63,"ask":0.75,"mid":0.69,"spread":0.12,"price":0.65,"size":0.0,"side":"BUY"}
{"ts":"2026-08-23T17:52:19.263Z","event_type":"price_change","market_id":"3790394","outcome_index":0,"market_type":"set1","local_side":"home","local_uid":"2026-08-23_hugo_grenier_mees_rottgering","bid":0.25,"ask":0.37,"mid":0.31,"spread":0.12,"price":0.35,"size":0.0,"side":"SELL"}
{"ts":"2026-08-23T17:52:19.264Z","event_type":"best_bid_ask","market_id":"3790397","outcome_index":0,"market_type":"set2","local_side":"home","local_uid":"2026-08-23_hugo_grenier_mees_rottgering","bid":0.28,"ask":0.41,"mid":0.345,"spread":0.13,"bid_size":null,"ask_size":null}
{"ts":"2026-08-23T17:52:19.264Z","event_type":"best_bid_ask","market_id":"3790397","outcome_index":1,"market_type":"set2","local_side":"away","local_uid":"2026-08-23_hugo_grenier_mees_rottgering","bid":0.59,"ask":0.72,"mid":0.655,"spread":0.13,"bid_size":null,"ask_size":null}
{"ts":"2026-08-23T17:52:19.264Z","event_type":"price_change","market_id":"3790397","outcome_index":0,"market_type":"set2","local_side":"home","local_uid":"2026-08-23_hugo_grenier_mees_rottgering","bid":0.28,"ask":0.41,"mid":0.345,"spread":0.13,"price":0.28,"size":88.0,"side":"BUY"}
{"ts":"2026-08-23T17:52:19.264Z","event_type":"price_change","market_id":"3790397","outcome_index":1,"market_type":"set2","local_side":"away","local_uid":"2026-08-23_hugo_grenier_mees_rottgering","bid":0.59,"ask":0.72,"mid":0.655,"spread":0.13,"price":0.72,"size":88.0,"side":"SELL"}
{"ts":"2026-08-23T17:52:19.271Z","event_type":"best_bid_ask","market_id":"3790394","outcome_index":0,"market_type":"set1","local_side":"home","local_uid":"2026-08-23_hugo_grenier_mees_rottgering","bid":0.25,"ask":0.44,"mid":0.345,"spread":0.19,"bid_size":null,"ask_size":null}
{"ts":"2026-08-23T17:52:19.271Z","event_type":"best_bid_ask","market_id":"3790394","outcome_index":1,"market_type":"set1","local_side":"away","local_uid":"2026-08-23_hugo_grenier_mees_rottgering","bid":0.56,"ask":0.75,"mid":0.655,"spread":0.19,"bid_size":null,"ask_size":null}
{"ts":"2026-08-23T17:52:19.271Z","event_type":"price_change","market_id":"3790394","outcome_index":1,"market_type":"set1","local_side":"away","local_uid":"2026-08-23_hugo_grenier_mees_rottgering","bid":0.56,"ask":0.75,"mid":0.655,"spread":0.19,"price":0.63,"size":0.0,"side":"BUY"}
{"ts":"2026-08-23T17:52:19.271Z","event_type":"price_change","market_id":"3790394","outcome_index":0,"market_type":"set1","local_side":"home","local_uid":"2026-08-23_hugo_grenier_mees_rottgering","bid":0.25,"ask":0.44,"mid":0.345,"spread":0.19,"price":0.37,"size":0.0,"side":"SELL"}
{"ts":"2026-08-23T17:52:19.290Z","event_type":"best_bid_ask","market_id":"3790397","outcome_index":0,"market_type":"set2","local_side":"home","local_uid":"2026-08-23_hugo_grenier_mees_rottgering","bid":0.28,"ask":0.44,"mid":0.36,"spread":0.16,"bid_size":null,"ask_size":null}
{"ts":"2026-08-23T17:52:19.290Z","event_type":"best_bid_ask","market_id":"3790397","outcome_index":1,"market_type":"set2","local_side":"away","local_uid":"2026-08-23_hugo_grenier_mees_rottgering","bid":0.56,"ask":0.72,"mid":0.64,"spread":0.16,"bid_size":null,"ask_size":null}
{"ts":"2026-08-23T17:52:19.290Z","event_type":"price_change","market_id":"3790397","outcome_index":1,"market_type":"set2","local_side":"away","local_uid":"2026-08-23_hugo_grenier_mees_rottgering","bid":0.56,"ask":0.72,"mid":0.64,"spread":0.16,"price":0.59,"size":0.0,"side":"BUY"}
{"ts":"2026-08-23T17:52:19.290Z","event_type":"price_change","market_id":"3790397","outcome_index":0,"market_type":"set2","local_side":"home","local_uid":"2026-08-23_hugo_grenier_mees_rottgering","bid":0.28,"ask":0.44,"mid":0.36,"spread":0.16,"price":0.41,"size":0.0,"side":"SELL"}
{"ts":"2026-08-23T17:52:19.296Z","event_type":"best_bid_ask","market_id":"3790397","outcome_index":0,"market_type":"set2","local_side":"home","local_uid":"2026-08-23_hugo_grenier_mees_rottgering","bid":0.28,"ask":0.41,"mid":0.345,"spread":0.13,"bid_size":null,"ask_size":null}
{"ts":"2026-08-23T17:52:19.296Z","event_type":"best_bid_ask","market_id":"3790397","outcome_index":1,"market_type":"set2","local_side":"away","local_uid":"2026-08-23_hugo_grenier_mees_rottgering","bid":0.59,"ask":0.72,"mid":0.655,"spread":0.13,"bid_size":null,"ask_size":null}
{"ts":"2026-08-23T17:52:19.296Z","event_type":"price_change","market_id":"3790397","outcome_index":1,"market_type":"set2","local_side":"away","local_uid":"2026-08-23_hugo_grenier_mees_rottgering","bid":0.59,"ask":0.72,"mid":0.655,"spread":0.13,"price":0.59,"size":26.64,"side":"BUY"}
{"ts":"2026-08-23T17:52:19.296Z","event_type":"price_change","market_id":"3790397","outcome_index":0,"market_type":"set2","local_side":"home","local_uid":"2026-08-23_hugo_grenier_mees_rottgering","bid":0.28,"ask":0.41,"mid":0.345,"spread":0.13,"price":0.41,"size":26.64,"side":"SELL"}
{"ts":"2026-08-23T17:52:19.296Z","event_type":"best_bid_ask","market_id":"3790397","outcome_index":0,"market_type":"set2","local_side":"home","local_uid":"2026-08-23_hugo_grenier_mees_rottgering","bid":0.31,"ask":0.41,"mid":0.36,"spread":0.1,"bid_size":null,"ask_size":null}
{"ts":"2026-08-23T17:52:19.296Z","event_type":"best_bid_ask","market_id":"3790397","outcome_index":1,"market_type":"set2","local_side":"away","local_uid":"2026-08-23_hugo_grenier_mees_rottgering","bid":0.59,"ask":0.69,"mid":0.64,"spread":0.1,"bid_size":null,"ask_size":null}
{"ts":"2026-08-23T17:52:19.296Z","event_type":"price_change","market_id":"3790397","outcome_index":0,"market_type":"set2","local_side":"home","local_uid":"2026-08-23_hugo_grenier_mees_rottgering","bid":0.31,"ask":0.41,"mid":0.36,"spread":0.1,"price":0.31,"size":25.56,"side":"BUY"}
{"ts":"2026-08-23T17:52:19.296Z","event_type":"price_change","market_id":"3790397","outcome_index":1,"market_type":"set2","local_side":"away","local_uid":"2026-08-23_hugo_grenier_mees_rottgering","bid":0.59,"ask":0.69,"mid":0.64,"spread":0.1,"price":0.69,"size":25.56,"side":"SELL"}
{"ts":"2026-08-23T17:52:19.299Z","event_type":"best_bid_ask","market_id":"3790394","outcome_index":0,"market_type":"set1","local_side":"home","local_uid":"2026-08-23_hugo_grenier_mees_rottgering","bid":0.26,"ask":0.44,"mid":0.35,"spread":0.18,"bid_size":null,"ask_size":null}
{"ts":"2026-08-23T17:52:19.307Z","event_type":"best_bid_ask","market_id":"3790394","outcome_index":1,"market_type":"set1","local_side":"away","local_uid":"2026-08-23_hugo_grenier_mees_rottgering","bid":0.56,"ask":0.74,"mid":0.65,"spread":0.18,"bid_size":null,"ask_size":null}
{"ts":"2026-08-23T17:52:19.308Z","event_type":"price_change","market_id":"3790394","outcome_index":0,"market_type":"set1","local_side":"home","local_uid":"2026-08-23_hugo_grenier_mees_rottgering","bid":0.26,"ask":0.44,"mid":0.35,"spread":0.18,"price":0.26,"size":15.22,"side":"BUY"}
{"ts":"2026-08-23T17:52:19.308Z","event_type":"price_change","market_id":"3790394","outcome_index":1,"market_type":"set1","local_side":"away","local_uid":"2026-08-23_hugo_grenier_mees_rottgering","bid":0.56,"ask":0.74,"mid":0.65,"spread":0.18,"price":0.74,"size":15.22,"side":"SELL"}
{"ts":"2026-08-23T17:52:19.331Z","event_type":"best_bid_ask","market_id":"3790394","outcome_index":0,"market_type":"set1","local_side":"home","local_uid":"2026-08-23_hugo_grenier_mees_rottgering","bid":0.26,"ask":0.46,"mid":0.36,"spread":0.2,"bid_size":null,"ask_size":null}
{"ts":"2026-08-23T17:52:19.331Z","event_type":"best_bid_ask","market_id":"3790394","outcome_index":1,"market_type":"set1","local_side":"away","local_uid":"2026-08-23_hugo_grenier_mees_rottgering","bid":0.54,"ask":0.74,"mid":0.64,"spread":0.2,"bid_size":null,"ask_size":null}
{"ts":"2026-08-23T17:52:19.331Z","event_type":"price_change","market_id":"3790394","outcome_index":1,"market_type":"set1","local_side":"away","local_uid":"2026-08-23_hugo_grenier_mees_rottgering","bid":0.54,"ask":0.74,"mid":0.64,"spread":0.2,"price":0.56,"size":0.0,"side":"BUY"}
{"ts":"2026-08-23T17:52:19.331Z","event_type":"price_change","market_id":"3790394","outcome_index":0,"market_type":"set1","local_side":"home","local_uid":"2026-08-23_hugo_grenier_mees_rottgering","bid":0.26,"ask":0.46,"mid":0.36,"spread":0.2,"price":0.44,"size":0.0,"side":"SELL"}
{"ts":"2026-08-23T17:52:19.438Z","event_type":"best_bid_ask","market_id":"3790394","outcome_index":0,"market_type":"set1","local_side":"home","local_uid":"2026-08-23_hugo_grenier_mees_rottgering","bid":0.25,"ask":0.46,"mid":0.355,"spread":0.21,"bid_size":null,"ask_size":null}
{"ts":"2026-08-23T17:52:19.438Z","event_type":"best_bid_ask","market_id":"3790394","outcome_index":1,"market_type":"set1","local_side":"away","local_uid":"2026-08-23_hugo_grenier_mees_rottgering","bid":0.54,"ask":0.75,"mid":0.645,"spread":0.21,"bid_size":null,"ask_size":null}
{"ts":"2026-08-23T17:52:19.438Z","event_type":"price_change","market_id":"3790394","outcome_index":0,"market_type":"set1","local_side":"home","local_uid":"2026-08-23_hugo_grenier_mees_rottgering","bid":0.25,"ask":0.46,"mid":0.355,"spread":0.21,"price":0.26,"size":0.0,"side":"BUY"}
{"ts":"2026-08-23T17:52:19.438Z","event_type":"price_change","market_id":"3790394","outcome_index":1,"market_type":"set1","local_side":"away","local_uid":"2026-08-23_hugo_grenier_mees_rottgering","bid":0.54,"ask":0.75,"mid":0.645,"spread":0.21,"price":0.74,"size":0.0,"side":"SELL"}
{"ts":"2026-08-23T17:52:19.467Z","event_type":"best_bid_ask","market_id":"3790394","outcome_index":0,"market_type":"set1","local_side":"home","local_uid":"2026-08-23_hugo_grenier_mees_rottgering","bid":0.2,"ask":0.46,"mid":0.33,"spread":0.26,"bid_size":null,"ask_size":null}
{"ts":"2026-08-23T17:52:19.467Z","event_type":"best_bid_ask","market_id":"3790394","outcome_index":1,"market_type":"set1","local_side":"away","local_uid":"2026-08-23_hugo_grenier_mees_rottgering","bid":0.54,"ask":0.8,"mid":0.67,"spread":0.26,"bid_size":null,"ask_size":null}
{"ts":"2026-08-23T17:52:19.467Z","event_type":"price_change","market_id":"3790394","outcome_index":0,"market_type":"set1","local_side":"home","local_uid":"2026-08-23_hugo_grenier_mees_rottgering","bid":0.2,"ask":0.46,"mid":0.33,"spread":0.26,"price":0.25,"size":0.0,"side":"BUY"}
{"ts":"2026-08-23T17:52:19.467Z","event_type":"price_change","market_id":"3790394","outcome_index":1,"market_type":"set1","local_side":"away","local_uid":"2026-08-23_hugo_grenier_mees_rottgering","bid":0.54,"ask":0.8,"mid":0.67,"spread":0.26,"price":0.75,"size":0.0,"side":"SELL"}
{"ts":"2026-08-23T17:52:19.471Z","event_type":"best_bid_ask","market_id":"3790394","outcome_index":0,"market_type":"set1","local_side":"home","local_uid":"2026-08-23_hugo_grenier_mees_rottgering","bid":0.2,"ask":1.0,"mid":0.6,"spread":0.8,"bid_size":null,"ask_size":null}
{"ts":"2026-08-23T17:52:19.471Z","event_type":"best_bid_ask","market_id":"3790394","outcome_index":1,"market_type":"set1","local_side":"away","local_uid":"2026-08-23_hugo_grenier_mees_rottgering","bid":0.0,"ask":0.8,"mid":0.4,"spread":0.8,"bid_size":null,"ask_size":null}
{"ts":"2026-08-23T17:52:19.471Z","event_type":"price_change","market_id":"3790394","outcome_index":1,"market_type":"set1","local_side":"away","local_uid":"2026-08-23_hugo_grenier_mees_rottgering","bid":0.0,"ask":0.8,"mid":0.4,"spread":0.8,"price":0.54,"size":0.0,"side":"BUY"}
{"ts":"2026-08-23T17:52:19.471Z","event_type":"price_change","market_id":"3790394","outcome_index":0,"market_type":"set1","local_side":"home","local_uid":"2026-08-23_hugo_grenier_mees_rottgering","bid":0.2,"ask":1.0,"mid":0.6,"spread":0.8,"price":0.46,"size":0.0,"side":"SELL"}
{"ts":"2026-08-23T17:52:19.543Z","event_type":"best_bid_ask","market_id":"3790394","outcome_index":0,"market_type":"set1","local_side":"home","local_uid":"2026-08-23_hugo_grenier_mees_rottgering","bid":0.2,"ask":0.42,"mid":0.31,"spread":0.22,"bid_size":null,"ask_size":null}
{"ts":"2026-08-23T17:52:19.543Z","event_type":"best_bid_ask","market_id":"3790394","outcome_index":1,"market_type":"set1","local_side":"away","local_uid":"2026-08-23_hugo_grenier_mees_rottgering","bid":0.58,"ask":0.8,"mid":0.69,"spread":0.22,"bid_size":null,"ask_size":null}
{"ts":"2026-08-23T17:52:19.543Z","event_type":"price_change","market_id":"3790394","outcome_index":1,"market_type":"set1","local_side":"away","local_uid":"2026-08-23_hugo_grenier_mees_rottgering","bid":0.58,"ask":0.8,"mid":0.69,"spread":0.22,"price":0.58,"size":11.0,"side":"BUY"}
{"ts":"2026-08-23T17:52:19.543Z","event_type":"price_change","market_id":"3790394","outcome_index":0,"market_type":"set1","local_side":"home","local_uid":"2026-08-23_hugo_grenier_mees_rottgering","bid":0.2,"ask":0.42,"mid":0.31,"spread":0.22,"price":0.42,"size":11.0,"side":"SELL"}
{"ts":"2026-08-23T17:52:19.544Z","event_type":"best_bid_ask","market_id":"3790394","outcome_index":0,"market_type":"set1","local_side":"home","local_uid":"2026-08-23_hugo_grenier_mees_rottgering","bid":0.0,"ask":0.42,"mid":0.21,"spread":0.42,"bid_size":null,"ask_size":null}
{"ts":"2026-08-23T17:52:19.544Z","event_type":"best_bid_ask","market_id":"3790394","outcome_index":1,"market_type":"set1","local_side":"away","local_uid":"2026-08-23_hugo_grenier_mees_rottgering","bid":0.58,"ask":1.0,"mid":0.79,"spread":0.42,"bid_size":null,"ask_size":null}
{"ts":"2026-08-23T17:52:19.544Z","event_type":"price_change","market_id":"3790394","outcome_index":0,"market_type":"set1","local_side":"home","local_uid":"2026-08-23_hugo_grenier_mees_rottgering","bid":0.0,"ask":0.42,"mid":0.21,"spread":0.42,"price":0.2,"size":0.0,"side":"BUY"}
{"ts":"2026-08-23T17:52:19.544Z","event_type":"price_change","market_id":"3790394","outcome_index":1,"market_type":"set1","local_side":"away","local_uid":"2026-08-23_hugo_grenier_mees_rottgering","bid":0.58,"ask":1.0,"mid":0.79,"spread":0.42,"price":0.8,"size":0.0,"side":"SELL"}
{"ts":"2026-08-23T17:52:19.752Z","event_type":"best_bid_ask","market_id":"3790394","outcome_index":0,"market_type":"set1","local_side":"home","local_uid":"2026-08-23_hugo_grenier_mees_rottgering","bid":0.16,"ask":0.42,"mid":0.29,"spread":0.26,"bid_size":null,"ask_size":null}
{"ts":"2026-08-23T17:52:19.752Z","event_type":"best_bid_ask","market_id":"3790394","outcome_index":1,"market_type":"set1","local_side":"away","local_uid":"2026-08-23_hugo_grenier_mees_rottgering","bid":0.58,"ask":0.84,"mid":0.71,"spread":0.26,"bid_size":null,"ask_size":null}
{"ts":"2026-08-23T17:52:19.752Z","event_type":"price_change","market_id":"3790394","outcome_index":0,"market_type":"set1","local_side":"home","local_uid":"2026-08-23_hugo_grenier_mees_rottgering","bid":0.16,"ask":0.42,"mid":0.29,"spread":0.26,"price":0.16,"size":26.0,"side":"BUY"}
{"ts":"2026-08-23T17:52:19.753Z","event_type":"price_change","market_id":"3790394","outcome_index":1,"market_type":"set1","local_side":"away","local_uid":"2026-08-23_hugo_grenier_mees_rottgering","bid":0.58,"ask":0.84,"mid":0.71,"spread":0.26,"price":0.84,"size":26.0,"side":"SELL"}
{"ts":"2026-08-23T17:52:19.755Z","event_type":"best_bid_ask","market_id":"3790394","outcome_index":0,"market_type":"set1","local_side":"home","local_uid":"2026-08-23_hugo_grenier_mees_rottgering","bid":0.17,"ask":0.42,"mid":0.295,"spread":0.25,"bid_size":null,"ask_size":null}
{"ts":"2026-08-23T17:52:19.755Z","event_type":"best_bid_ask","market_id":"3790394","outcome_index":1,"market_type":"set1","local_side":"away","local_uid":"2026-08-23_hugo_grenier_mees_rottgering","bid":0.58,"ask":0.83,"mid":0.705,"spread":0.25,"bid_size":null,"ask_size":null}
{"ts":"2026-08-23T17:52:19.755Z","event_type":"price_change","market_id":"3790394","outcome_index":0,"market_type":"set1","local_side":"home","local_uid":"2026-08-23_hugo_grenier_mees_rottgering","bid":0.17,"ask":0.42,"mid":0.295,"spread":0.25,"price":0.17,"size":44.0,"side":"BUY"}
{"ts":"2026-08-23T17:52:19.755Z","event_type":"price_change","market_id":"3790394","outcome_index":1,"market_type":"set1","local_side":"away","local_uid":"2026-08-23_hugo_grenier_mees_rottgering","bid":0.58,"ask":0.83,"mid":0.705,"spread":0.25,"price":0.83,"size":44.0,"side":"SELL"}
{"ts":"2026-08-23T17:52:20.193Z","event_type":"best_bid_ask","market_id":"3789927","outcome_index":0,"market_type":"match","local_side":"home","local_uid":"2026-08-23_hugo_grenier_mees_rottgering","bid":0.27,"ask":0.3,"mid":0.285,"spread":0.03,"bid_size":null,"ask_size":null}
{"ts":"2026-08-23T17:52:20.193Z","event_type":"best_bid_ask","market_id":"3789927","outcome_index":1,"market_type":"match","local_side":"away","local_uid":"2026-08-23_hugo_grenier_mees_rottgering","bid":0.7,"ask":0.73,"mid":0.715,"spread":0.03,"bid_size":null,"ask_size":null}
{"ts":"2026-08-23T17:52:20.194Z","event_type":"price_change","market_id":"3789927","outcome_index":1,"market_type":"match","local_side":"away","local_uid":"2026-08-23_hugo_grenier_mees_rottgering","bid":0.7,"ask":0.73,"mid":0.715,"spread":0.03,"price":0.71,"size":0.0,"side":"BUY"}
{"ts":"2026-08-23T17:52:20.194Z","event_type":"price_change","market_id":"3789927","outcome_index":0,"market_type":"match","local_side":"home","local_uid":"2026-08-23_hugo_grenier_mees_rottgering","bid":0.27,"ask":0.3,"mid":0.285,"spread":0.03,"price":0.29,"size":0.0,"side":"SELL"}
{"ts":"2026-08-23T17:52:21.118Z","event_type":"price_change","market_id":"3789931","outcome_index":1,"market_type":"match","local_side":"away","local_uid":"2026-08-23_stefanos_sakellaridis_luca_van_assche","bid":0.94,"ask":0.95,"mid":0.945,"spread":0.01,"price":0.87,"size":940.0,"side":"BUY"}
{"ts":"2026-08-23T17:52:21.118Z","event_type":"price_change","market_id":"3789931","outcome_index":0,"market_type":"match","local_side":"home","local_uid":"2026-08-23_stefanos_sakellaridis_luca_van_assche","bid":0.05,"ask":0.06,"mid":0.055,"spread":0.01,"price":0.13,"size":940.0,"side":"SELL"}
{"ts":"2026-08-23T17:52:21.913Z","event_type":"best_bid_ask","market_id":"3790394","outcome_index":0,"market_type":"set1","local_side":"home","local_uid":"2026-08-23_hugo_grenier_mees_rottgering","bid":0.17,"ask":0.41,"mid":0.29,"spread":0.24,"bid_size":null,"ask_size":null}
{"ts":"2026-08-23T17:52:21.913Z","event_type":"best_bid_ask","market_id":"3790394","outcome_index":1,"market_type":"set1","local_side":"away","local_uid":"2026-08-23_hugo_grenier_mees_rottgering","bid":0.59,"ask":0.83,"mid":0.71,"spread":0.24,"bid_size":null,"ask_size":null}
{"ts":"2026-08-23T17:52:21.913Z","event_type":"price_change","market_id":"3790394","outcome_index":1,"market_type":"set1","local_side":"away","local_uid":"2026-08-23_hugo_grenier_mees_rottgering","bid":0.59,"ask":0.83,"mid":0.71,"spread":0.24,"price":0.59,"size":43.79,"side":"BUY"}
{"ts":"2026-08-23T17:52:21.913Z","event_type":"price_change","market_id":"3790394","outcome_index":0,"market_type":"set1","local_side":"home","local_uid":"2026-08-23_hugo_grenier_mees_rottgering","bid":0.17,"ask":0.41,"mid":0.29,"spread":0.24,"price":0.41,"size":43.79,"side":"SELL"}
{"ts":"2026-08-23T17:52:21.917Z","event_type":"price_change","market_id":"3780844","outcome_index":1,"market_type":"match","local_side":"away","local_uid":"2026-08-23_pablo_carreno_busta_adolfo_daniel_vallejo","bid":0.43,"ask":0.44,"mid":0.435,"spread":0.01,"price":0.26,"size":0.0,"side":"BUY"}
{"ts":"2026-08-23T17:52:21.917Z","event_type":"price_change","market_id":"3780844","outcome_index":0,"market_type":"match","local_side":"home","local_uid":"2026-08-23_pablo_carreno_busta_adolfo_daniel_vallejo","bid":0.56,"ask":0.57,"mid":0.565,"spread":0.01,"price":0.74,"size":0.0,"side":"SELL"}
{"ts":"2026-08-23T17:52:21.980Z","event_type":"best_bid_ask","market_id":"3790394","outcome_index":0,"market_type":"set1","local_side":"home","local_uid":"2026-08-23_hugo_grenier_mees_rottgering","bid":0.2,"ask":0.41,"mid":0.305,"spread":0.21,"bid_size":null,"ask_size":null}
{"ts":"2026-08-23T17:52:21.980Z","event_type":"best_bid_ask","market_id":"3790394","outcome_index":1,"market_type":"set1","local_side":"away","local_uid":"2026-08-23_hugo_grenier_mees_rottgering","bid":0.59,"ask":0.8,"mid":0.695,"spread":0.21,"bid_size":null,"ask_size":null}
{"ts":"2026-08-23T17:52:21.980Z","event_type":"price_change","market_id":"3790394","outcome_index":0,"market_type":"set1","local_side":"home","local_uid":"2026-08-23_hugo_grenier_mees_rottgering","bid":0.2,"ask":0.41,"mid":0.305,"spread":0.21,"price":0.2,"size":74.56,"side":"BUY"}
{"ts":"2026-08-23T17:52:21.980Z","event_type":"price_change","market_id":"3790394","outcome_index":1,"market_type":"set1","local_side":"away","local_uid":"2026-08-23_hugo_grenier_mees_rottgering","bid":0.59,"ask":0.8,"mid":0.695,"spread":0.21,"price":0.8,"size":74.56,"side":"SELL"}
{"ts":"2026-08-23T17:52:22.319Z","event_type":"new_market","market_id":"0x6b5c3efb1b5bd5bfe6a6080017fc4987839cadac5362cbbb9b6ee1bff4b29254"}
{"ts":"2026-08-23T17:52:22.319Z","event_type":"new_market","market_id":"0xb845f05bb13397119ed6f343f0526b6b2a4cd7e78ac7607514dce167503c9c6f"}
{"ts":"2026-08-23T17:52:22.326Z","event_type":"new_market","market_id":"0x4e241e9220714fd23063536edb6134ad477e4592269e7f38a6f29cd60f3ec23e"}
{"ts":"2026-08-23T17:52:22.335Z","event_type":"new_market","market_id":"0x8f9fe0ffcc5581557490ca080145caf0b5f07c940f60d8c608624ef95364b0e1"}
{"ts":"2026-08-23T17:52:22.336Z","event_type":"new_market","market_id":"0x3e903e8a1fdd59e03fc86f7934808312a465c3ee197c8042b6366ad87954db14"}
{"ts":"2026-08-23T17:52:22.336Z","event_type":"new_market","market_id":"0xd34e2d4ea4c28e7ecabe2548b8bad615dc6f40dbf39bb320373037fe23531c79"}
{"ts":"2026-08-23T17:52:22.441Z","event_type":"new_market","market_id":"0xceb37cb2f559198a450e26584f19cc899cff4a9b03853a14a827bfacecb4121f"}
{"ts":"2026-08-23T17:52:22.567Z","event_type":"new_market","market_id":"0x8d1a2f01660ac803404e55b780e46a7ae1c862eb0284b98e91b15d4b63fa6df7"}
{"ts":"2026-08-23T17:52:22.568Z","event_type":"new_market","market_id":"0x54104cc7014b5b33b27ea307d7bf80b3da51b2cfa733761926bd31553660ec40"}
{"ts":"2026-08-23T17:52:23.252Z","event_type":"price_change","market_id":"3793888","outcome_index":0,"market_type":"set1","local_side":"home","local_uid":"2026-08-23_anna_bondar_en_shuo_liang","bid":0.69,"ask":0.72,"mid":0.705,"spread":0.03,"price":0.65,"size":181.0,"side":"BUY"}
{"ts":"2026-08-23T17:52:23.252Z","event_type":"price_change","market_id":"3793888","outcome_index":1,"market_type":"set1","local_side":"away","local_uid":"2026-08-23_anna_bondar_en_shuo_liang","bid":0.28,"ask":0.31,"mid":0.295,"spread":0.03,"price":0.35,"size":181.0,"side":"SELL"}
{"ts":"2026-08-23T17:52:23.590Z","event_type":"best_bid_ask","market_id":"3789997","outcome_index":0,"market_type":"match","local_side":"home","local_uid":"2026-08-23_oscar_weightman_alec_deckers","bid":0.09,"ask":0.1,"mid":0.095,"spread":0.01,"bid_size":null,"ask_size":null}
{"ts":"2026-08-23T17:52:23.591Z","event_type":"best_bid_ask","market_id":"3789997","outcome_index":1,"market_type":"match","local_side":"away","local_uid":"2026-08-23_oscar_weightman_alec_deckers","bid":0.9,"ask":0.91,"mid":0.905,"spread":0.01,"bid_size":null,"ask_size":null}
{"ts":"2026-08-23T17:52:23.591Z","event_type":"price_change","market_id":"3789997","outcome_index":1,"market_type":"match","local_side":"away","local_uid":"2026-08-23_oscar_weightman_alec_deckers","bid":0.9,"ask":0.91,"mid":0.905,"spread":0.01,"price":0.91,"size":27.47,"side":"SELL"}
{"ts":"2026-08-23T17:52:23.591Z","event_type":"price_change","market_id":"3789997","outcome_index":0,"market_type":"match","local_side":"home","local_uid":"2026-08-23_oscar_weightman_alec_deckers","bid":0.09,"ask":0.1,"mid":0.095,"spread":0.01,"price":0.09,"size":27.47,"side":"BUY"}
{"ts":"2026-08-23T17:52:23.706Z","event_type":"best_bid_ask","market_id":"3790394","outcome_index":0,"market_type":"set1","local_side":"home","local_uid":"2026-08-23_hugo_grenier_mees_rottgering","bid":0.2,"ask":0.35,"mid":0.275,"spread":0.15,"bid_size":null,"ask_size":null}
{"ts":"2026-08-23T17:52:23.706Z","event_type":"best_bid_ask","market_id":"3790394","outcome_index":1,"market_type":"set1","local_side":"away","local_uid":"2026-08-23_hugo_grenier_mees_rottgering","bid":0.65,"ask":0.8,"mid":0.725,"spread":0.15,"bid_size":null,"ask_size":null}
{"ts":"2026-08-23T17:52:23.706Z","event_type":"price_change","market_id":"3790394","outcome_index":1,"market_type":"set1","local_side":"away","local_uid":"2026-08-23_hugo_grenier_mees_rottgering","bid":0.65,"ask":0.8,"mid":0.725,"spread":0.15,"price":0.65,"size":423.0,"side":"BUY"}
{"ts":"2026-08-23T17:52:23.706Z","event_type":"price_change","market_id":"3790394","outcome_index":0,"market_type":"set1","local_side":"home","local_uid":"2026-08-23_hugo_grenier_mees_rottgering","bid":0.2,"ask":0.35,"mid":0.275,"spread":0.15,"price":0.35,"size":423.0,"side":"SELL"}
{"ts":"2026-08-23T17:52:23.716Z","event_type":"best_bid_ask","market_id":"3790394","outcome_index":0,"market_type":"set1","local_side":"home","local_uid":"2026-08-23_hugo_grenier_mees_rottgering","bid":0.2,"ask":0.34,"mid":0.27,"spread":0.14,"bid_size":null,"ask_size":null}
{"ts":"2026-08-23T17:52:23.716Z","event_type":"best_bid_ask","market_id":"3790394","outcome_index":1,"market_type":"set1","local_side":"away","local_uid":"2026-08-23_hugo_grenier_mees_rottgering","bid":0.66,"ask":0.8,"mid":0.73,"spread":0.14,"bid_size":null,"ask_size":null}
{"ts":"2026-08-23T17:52:23.716Z","event_type":"price_change","market_id":"3790394","outcome_index":1,"market_type":"set1","local_side":"away","local_uid":"2026-08-23_hugo_grenier_mees_rottgering","bid":0.66,"ask":0.8,"mid":0.73,"spread":0.14,"price":0.66,"size":88.0,"side":"BUY"}
{"ts":"2026-08-23T17:52:23.716Z","event_type":"price_change","market_id":"3790394","outcome_index":0,"market_type":"set1","local_side":"home","local_uid":"2026-08-23_hugo_grenier_mees_rottgering","bid":0.2,"ask":0.34,"mid":0.27,"spread":0.14,"price":0.34,"size":88.0,"side":"SELL"}
{"ts":"2026-08-23T17:52:23.729Z","event_type":"best_bid_ask","market_id":"3790397","outcome_index":0,"market_type":"set2","local_side":"home","local_uid":"2026-08-23_hugo_grenier_mees_rottgering","bid":0.31,"ask":0.42,"mid":0.365,"spread":0.11,"bid_size":null,"ask_size":null}
{"ts":"2026-08-23T17:52:23.730Z","event_type":"best_bid_ask","market_id":"3790397","outcome_index":1,"market_type":"set2","local_side":"away","local_uid":"2026-08-23_hugo_grenier_mees_rottgering","bid":0.58,"ask":0.69,"mid":0.635,"spread":0.11,"bid_size":null,"ask_size":null}
{"ts":"2026-08-23T17:52:23.730Z","event_type":"price_change","market_id":"3790397","outcome_index":1,"market_type":"set2","local_side":"away","local_uid":"2026-08-23_hugo_grenier_mees_rottgering","bid":0.58,"ask":0.69,"mid":0.635,"spread":0.11,"price":0.57,"size":423.0,"side":"BUY"}
{"ts":"2026-08-23T17:52:23.730Z","event_type":"price_change","market_id":"3790397","outcome_index":0,"market_type":"set2","local_side":"home","local_uid":"2026-08-23_hugo_grenier_mees_rottgering","bid":0.31,"ask":0.42,"mid":0.365,"spread":0.11,"price":0.43,"size":423.0,"side":"SELL"}
{"ts":"2026-08-23T17:52:23.755Z","event_type":"best_bid_ask","market_id":"3790394","outcome_index":0,"market_type":"set1","local_side":"home","local_uid":"2026-08-23_hugo_grenier_mees_rottgering","bid":0.2,"ask":0.33,"mid":0.265,"spread":0.13,"bid_size":null,"ask_size":null}
{"ts":"2026-08-23T17:52:23.756Z","event_type":"best_bid_ask","market_id":"3790394","outcome_index":1,"market_type":"set1","local_side":"away","local_uid":"2026-08-23_hugo_grenier_mees_rottgering","bid":0.67,"ask":0.8,"mid":0.735,"spread":0.13,"bid_size":null,"ask_size":null}
{"ts":"2026-08-23T17:52:23.756Z","event_type":"price_change","market_id":"3790394","outcome_index":1,"market_type":"set1","local_side":"away","local_uid":"2026-08-23_hugo_grenier_mees_rottgering","bid":0.67,"ask":0.8,"mid":0.735,"spread":0.13,"price":0.67,"size":150.0,"side":"BUY"}
{"ts":"2026-08-23T17:52:23.756Z","event_type":"price_change","market_id":"3790394","outcome_index":0,"market_type":"set1","local_side":"home","local_uid":"2026-08-23_hugo_grenier_mees_rottgering","bid":0.2,"ask":0.33,"mid":0.265,"spread":0.13,"price":0.33,"size":150.0,"side":"SELL"}
{"ts":"2026-08-23T17:52:23.760Z","event_type":"best_bid_ask","market_id":"3790394","outcome_index":0,"market_type":"set1","local_side":"home","local_uid":"2026-08-23_hugo_grenier_mees_rottgering","bid":0.21,"ask":0.33,"mid":0.27,"spread":0.12,"bid_size":null,"ask_size":null}
{"ts":"2026-08-23T17:52:23.760Z","event_type":"best_bid_ask","market_id":"3790394","outcome_index":1,"market_type":"set1","local_side":"away","local_uid":"2026-08-23_hugo_grenier_mees_rottgering","bid":0.67,"ask":0.79,"mid":0.73,"spread":0.12,"bid_size":null,"ask_size":null}
{"ts":"2026-08-23T17:52:23.765Z","event_type":"price_change","market_id":"3790394","outcome_index":0,"market_type":"set1","local_side":"home","local_uid":"2026-08-23_hugo_grenier_mees_rottgering","bid":0.21,"ask":0.33,"mid":0.27,"spread":0.12,"price":0.21,"size":150.0,"side":"BUY"}
{"ts":"2026-08-23T17:52:23.765Z","event_type":"price_change","market_id":"3790394","outcome_index":1,"market_type":"set1","local_side":"away","local_uid":"2026-08-23_hugo_grenier_mees_rottgering","bid":0.67,"ask":0.79,"mid":0.73,"spread":0.12,"price":0.79,"size":150.0,"side":"SELL"}
{"ts":"2026-08-23T17:52:23.788Z","event_type":"best_bid_ask","market_id":"3790397","outcome_index":0,"market_type":"set2","local_side":"home","local_uid":"2026-08-23_hugo_grenier_mees_rottgering","bid":0.31,"ask":0.41,"mid":0.36,"spread":0.1,"bid_size":null,"ask_size":null}
{"ts":"2026-08-23T17:52:23.805Z","event_type":"best_bid_ask","market_id":"3790397","outcome_index":1,"market_type":"set2","local_side":"away","local_uid":"2026-08-23_hugo_grenier_mees_rottgering","bid":0.59,"ask":0.69,"mid":0.64,"spread":0.1,"bid_size":null,"ask_size":null}
{"ts":"2026-08-23T17:52:23.805Z","event_type":"price_change","market_id":"3790397","outcome_index":1,"market_type":"set2","local_side":"away","local_uid":"2026-08-23_hugo_grenier_mees_rottgering","bid":0.59,"ask":0.69,"mid":0.64,"spread":0.1,"price":0.59,"size":150.0,"side":"BUY"}
{"ts":"2026-08-23T17:52:23.805Z","event_type":"price_change","market_id":"3790397","outcome_index":0,"market_type":"set2","local_side":"home","local_uid":"2026-08-23_hugo_grenier_mees_rottgering","bid":0.31,"ask":0.41,"mid":0.36,"spread":0.1,"price":0.41,"size":150.0,"side":"SELL"}
{"ts":"2026-08-23T17:52:23.834Z","event_type":"best_bid_ask","market_id":"3789927","outcome_index":0,"market_type":"match","local_side":"home","local_uid":"2026-08-23_hugo_grenier_mees_rottgering","bid":0.27,"ask":0.29,"mid":0.28,"spread":0.02,"bid_size":null,"ask_size":null}
{"ts":"2026-08-23T17:52:23.834Z","event_type":"best_bid_ask","market_id":"3789927","outcome_index":1,"market_type":"match","local_side":"away","local_uid":"2026-08-23_hugo_grenier_mees_rottgering","bid":0.71,"ask":0.73,"mid":0.72,"spread":0.02,"bid_size":null,"ask_size":null}
{"ts":"2026-08-23T17:52:23.834Z","event_type":"price_change","market_id":"3789927","outcome_index":1,"market_type":"match","local_side":"away","local_uid":"2026-08-23_hugo_grenier_mees_rottgering","bid":0.71,"ask":0.73,"mid":0.72,"spread":0.02,"price":0.71,"size":28.0,"side":"BUY"}
{"ts":"2026-08-23T17:52:23.834Z","event_type":"price_change","market_id":"3789927","outcome_index":0,"market_type":"match","local_side":"home","local_uid":"2026-08-23_hugo_grenier_mees_rottgering","bid":0.27,"ask":0.29,"mid":0.28,"spread":0.02,"price":0.29,"size":28.0,"side":"SELL"}
{"ts":"2026-08-23T17:52:23.904Z","event_type":"best_bid_ask","market_id":"3790394","outcome_index":0,"market_type":"set1","local_side":"home","local_uid":"2026-08-23_hugo_grenier_mees_rottgering","bid":0.22,"ask":0.33,"mid":0.275,"spread":0.11,"bid_size":null,"ask_size":null}
{"ts":"2026-08-23T17:52:23.904Z","event_type":"best_bid_ask","market_id":"3790394","outcome_index":1,"market_type":"set1","local_side":"away","local_uid":"2026-08-23_hugo_grenier_mees_rottgering","bid":0.67,"ask":0.78,"mid":0.725,"spread":0.11,"bid_size":null,"ask_size":null}
{"ts":"2026-08-23T17:52:23.904Z","event_type":"price_change","market_id":"3790394","outcome_index":0,"market_type":"set1","local_side":"home","local_uid":"2026-08-23_hugo_grenier_mees_rottgering","bid":0.22,"ask":0.33,"mid":0.275,"spread":0.11,"price":0.22,"size":95.45,"side":"BUY"}
{"ts":"2026-08-23T17:52:23.904Z","event_type":"price_change","market_id":"3790394","outcome_index":1,"market_type":"set1","local_side":"away","local_uid":"2026-08-23_hugo_grenier_mees_rottgering","bid":0.67,"ask":0.78,"mid":0.725,"spread":0.11,"price":0.78,"size":95.45,"side":"SELL"}
{"ts":"2026-08-23T17:52:23.973Z","event_type":"new_market","market_id":"0x13b55f6d7fff071d8f797d869cc18af77e8a06b598d5866f4c7ffc6866802e9c"}
{"ts":"2026-08-23T17:52:23.998Z","event_type":"new_market","market_id":"0x8538561320d195b5a9ab46724e8bcc4ad902def00a544c084e91eb1572af21b8"}
{"ts":"2026-08-23T17:52:23.998Z","event_type":"new_market","market_id":"0x38b90965343e5bc8ded938eebeef706919cad709ecb41d3b77102047323a4b91"}
{"ts":"2026-08-23T17:52:23.999Z","event_type":"new_market","market_id":"0x63d584b2e79a10c1e5bba0a9868b7d21a9f30d69d22848db9de06396c0c27a89"}
{"ts":"2026-08-23T17:52:23.999Z","event_type":"new_market","market_id":"0xb02a737ee2b23995026353d4de13c3e69e677232a7d19215deb408d452c74406"}
{"ts":"2026-08-23T17:52:24.078Z","event_type":"best_bid_ask","market_id":"3790394","outcome_index":0,"market_type":"set1","local_side":"home","local_uid":"2026-08-23_hugo_grenier_mees_rottgering","bid":0.22,"ask":0.32,"mid":0.27,"spread":0.1,"bid_size":null,"ask_size":null}
{"ts":"2026-08-23T17:52:24.078Z","event_type":"best_bid_ask","market_id":"3790394","outcome_index":1,"market_type":"set1","local_side":"away","local_uid":"2026-08-23_hugo_grenier_mees_rottgering","bid":0.68,"ask":0.78,"mid":0.73,"spread":0.1,"bid_size":null,"ask_size":null}
{"ts":"2026-08-23T17:52:24.079Z","event_type":"price_change","market_id":"3790394","outcome_index":1,"market_type":"set1","local_side":"away","local_uid":"2026-08-23_hugo_grenier_mees_rottgering","bid":0.68,"ask":0.78,"mid":0.73,"spread":0.1,"price":0.68,"size":38.38,"side":"BUY"}
{"ts":"2026-08-23T17:52:24.079Z","event_type":"price_change","market_id":"3790394","outcome_index":0,"market_type":"set1","local_side":"home","local_uid":"2026-08-23_hugo_grenier_mees_rottgering","bid":0.22,"ask":0.32,"mid":0.27,"spread":0.1,"price":0.32,"size":38.38,"side":"SELL"}
{"ts":"2026-08-23T17:52:24.246Z","event_type":"new_market","market_id":"0x0aa433e24c04eb055b030409f2eee960e250538268872888e343cf1a86f1c212"}
{"ts":"2026-08-23T17:52:24.261Z","event_type":"new_market","market_id":"0xfab14db2b02a25f135740616aa709a3ebade22a4adb8fe23711419b72e6e993f"}
{"ts":"2026-08-23T17:52:24.380Z","event_type":"new_market","market_id":"0x74586dda6ec02b2a54655cf2c77d0343c5ac00bba5277ecff0ef5224c940c4ef"}
{"ts":"2026-08-23T17:52:24.380Z","event_type":"new_market","market_id":"0xc25f0fb8342fad9a5ddb15618d343bf6cf1e257ac690be968a0410e805e65791"}
{"ts":"2026-08-23T17:52:24.392Z","event_type":"new_market","market_id":"0x6c38c1d17ac64be9bd5d5b310242577883cddd40e2ec05a5fdf9ee42bd6a5374"}
{"ts":"2026-08-23T17:52:24.427Z","event_type":"best_bid_ask","market_id":"3790394","outcome_index":0,"market_type":"set1","local_side":"home","local_uid":"2026-08-23_hugo_grenier_mees_rottgering","bid":0.22,"ask":0.33,"mid":0.275,"spread":0.11,"bid_size":null,"ask_size":null}
{"ts":"2026-08-23T17:52:24.428Z","event_type":"best_bid_ask","market_id":"3790394","outcome_index":1,"market_type":"set1","local_side":"away","local_uid":"2026-08-23_hugo_grenier_mees_rottgering","bid":0.67,"ask":0.78,"mid":0.725,"spread":0.11,"bid_size":null,"ask_size":null}
{"ts":"2026-08-23T17:52:24.428Z","event_type":"price_change","market_id":"3790394","outcome_index":1,"market_type":"set1","local_side":"away","local_uid":"2026-08-23_hugo_grenier_mees_rottgering","bid":0.67,"ask":0.78,"mid":0.725,"spread":0.11,"price":0.68,"size":0.0,"side":"BUY"}
{"ts":"2026-08-23T17:52:24.428Z","event_type":"price_change","market_id":"3790394","outcome_index":0,"market_type":"set1","local_side":"home","local_uid":"2026-08-23_hugo_grenier_mees_rottgering","bid":0.22,"ask":0.33,"mid":0.275,"spread":0.11,"price":0.32,"size":0.0,"side":"SELL"}
{"ts":"2026-08-23T17:52:24.439Z","event_type":"best_bid_ask","market_id":"3790394","outcome_index":0,"market_type":"set1","local_side":"home","local_uid":"2026-08-23_hugo_grenier_mees_rottgering","bid":0.25,"ask":0.33,"mid":0.29,"spread":0.08,"bid_size":null,"ask_size":null}
{"ts":"2026-08-23T17:52:24.439Z","event_type":"best_bid_ask","market_id":"3790394","outcome_index":1,"market_type":"set1","local_side":"away","local_uid":"2026-08-23_hugo_grenier_mees_rottgering","bid":0.67,"ask":0.75,"mid":0.71,"spread":0.08,"bid_size":null,"ask_size":null}
{"ts":"2026-08-23T17:52:24.439Z","event_type":"price_change","market_id":"3790394","outcome_index":0,"market_type":"set1","local_side":"home","local_uid":"2026-08-23_hugo_grenier_mees_rottgering","bid":0.25,"ask":0.33,"mid":0.29,"spread":0.08,"price":0.25,"size":201.79,"side":"BUY"}
{"ts":"2026-08-23T17:52:24.439Z","event_type":"price_change","market_id":"3790394","outcome_index":1,"market_type":"set1","local_side":"away","local_uid":"2026-08-23_hugo_grenier_mees_rottgering","bid":0.67,"ask":0.75,"mid":0.71,"spread":0.08,"price":0.75,"size":201.79,"side":"SELL"}
{"ts":"2026-08-23T17:52:24.766Z","event_type":"best_bid_ask","market_id":"3789927","outcome_index":0,"market_type":"match","local_side":"home","local_uid":"2026-08-23_hugo_grenier_mees_rottgering","bid":0.27,"ask":0.28,"mid":0.275,"spread":0.01,"bid_size":null,"ask_size":null}
{"ts":"2026-08-23T17:52:24.766Z","event_type":"best_bid_ask","market_id":"3789927","outcome_index":1,"market_type":"match","local_side":"away","local_uid":"2026-08-23_hugo_grenier_mees_rottgering","bid":0.72,"ask":0.73,"mid":0.725,"spread":0.01,"bid_size":null,"ask_size":null}
{"ts":"2026-08-23T17:52:24.766Z","event_type":"price_change","market_id":"3789927","outcome_index":1,"market_type":"match","local_side":"away","local_uid":"2026-08-23_hugo_grenier_mees_rottgering","bid":0.72,"ask":0.73,"mid":0.725,"spread":0.01,"price":0.72,"size":3529.17,"side":"BUY"}
{"ts":"2026-08-23T17:52:24.766Z","event_type":"price_change","market_id":"3789927","outcome_index":0,"market_type":"match","local_side":"home","local_uid":"2026-08-23_hugo_grenier_mees_rottgering","bid":0.27,"ask":0.28,"mid":0.275,"spread":0.01,"price":0.28,"size":3529.17,"side":"SELL"}
{"ts":"2026-08-23T17:52:25.232Z","event_type":"new_market","market_id":"0x29aa6cef51958fc6d84915d0996d2e01c639cbc98aed4c3cb692e2cf01038665"}
{"ts":"2026-08-23T17:52:25.363Z","event_type":"new_market","market_id":"0xe82dda28fb3cdf8da1907af723d5d7ba463f400c1aadaa0abd92ec33dd9a44e2"}
{"ts":"2026-08-23T17:52:25.713Z","event_type":"price_change","market_id":"3792973","outcome_index":0,"market_type":"match","local_side":"home","local_uid":"2026-08-23_anna_bondar_en_shuo_liang","bid":0.74,"ask":0.75,"mid":0.745,"spread":0.01,"price":0.51,"size":31.0,"side":"BUY"}
{"ts":"2026-08-23T17:52:25.713Z","event_type":"price_change","market_id":"3792973","outcome_index":1,"market_type":"match","local_side":"away","local_uid":"2026-08-23_anna_bondar_en_shuo_liang","bid":0.25,"ask":0.26,"mid":0.255,"spread":0.01,"price":0.49,"size":31.0,"side":"SELL"}
{"ts":"2026-08-23T17:52:25.899Z","event_type":"best_bid_ask","market_id":"3790323","outcome_index":0,"market_type":"set2","local_side":"home","local_uid":"2026-08-23_felix_balshaw_sebastian_gorzny","bid":0.51,"ask":0.57,"mid":0.54,"spread":0.06,"bid_size":null,"ask_size":null}
{"ts":"2026-08-23T17:52:25.899Z","event_type":"best_bid_ask","market_id":"3790323","outcome_index":1,"market_type":"set2","local_side":"away","local_uid":"2026-08-23_felix_balshaw_sebastian_gorzny","bid":0.43,"ask":0.49,"mid":0.46,"spread":0.06,"bid_size":null,"ask_size":null}
{"ts":"2026-08-23T17:52:25.899Z","event_type":"price_change","market_id":"3790323","outcome_index":0,"market_type":"set2","local_side":"home","local_uid":"2026-08-23_felix_balshaw_sebastian_gorzny","bid":0.51,"ask":0.57,"mid":0.54,"spread":0.06,"price":0.51,"size":150.0,"side":"BUY"}
{"ts":"2026-08-23T17:52:25.900Z","event_type":"price_change","market_id":"3790323","outcome_index":1,"market_type":"set2","local_side":"away","local_uid":"2026-08-23_felix_balshaw_sebastian_gorzny","bid":0.43,"ask":0.49,"mid":0.46,"spread":0.06,"price":0.49,"size":150.0,"side":"SELL"}
{"ts":"2026-08-23T17:52:26.009Z","event_type":"best_bid_ask","market_id":"3790323","outcome_index":0,"market_type":"set2","local_side":"home","local_uid":"2026-08-23_felix_balshaw_sebastian_gorzny","bid":0.5,"ask":0.57,"mid":0.535,"spread":0.07,"bid_size":null,"ask_size":null}
{"ts":"2026-08-23T17:52:26.009Z","event_type":"best_bid_ask","market_id":"3790323","outcome_index":1,"market_type":"set2","local_side":"away","local_uid":"2026-08-23_felix_balshaw_sebastian_gorzny","bid":0.43,"ask":0.5,"mid":0.465,"spread":0.07,"bid_size":null,"ask_size":null}
{"ts":"2026-08-23T17:52:26.009Z","event_type":"price_change","market_id":"3790323","outcome_index":0,"market_type":"set2","local_side":"home","local_uid":"2026-08-23_felix_balshaw_sebastian_gorzny","bid":0.5,"ask":0.57,"mid":0.535,"spread":0.07,"price":0.51,"size":0.0,"side":"BUY"}
{"ts":"2026-08-23T17:52:26.009Z","event_type":"price_change","market_id":"3790323","outcome_index":1,"market_type":"set2","local_side":"away","local_uid":"2026-08-23_felix_balshaw_sebastian_gorzny","bid":0.43,"ask":0.5,"mid":0.465,"spread":0.07,"price":0.49,"size":0.0,"side":"SELL"}
{"ts":"2026-08-23T17:52:26.230Z","event_type":"price_change","market_id":"3789987","outcome_index":1,"market_type":"match","local_side":"away","local_uid":"2026-08-23_mika_petkovic_federico_iannaccone","bid":0.999,"ask":1.0,"mid":0.9995,"spread":0.001,"price":0.999,"size":73322.82,"side":"BUY"}
{"ts":"2026-08-23T17:52:26.231Z","event_type":"price_change","market_id":"3789987","outcome_index":0,"market_type":"match","local_side":"home","local_uid":"2026-08-23_mika_petkovic_federico_iannaccone","bid":0.0,"ask":0.001,"mid":0.0005,"spread":0.001,"price":0.001,"size":73322.82,"side":"SELL"}
{"ts":"2026-08-23T17:52:26.348Z","event_type":"new_market","market_id":"0x68a0215d89c1078b38acd424aab534f85968ce2089513d5ef4b3f855bba785d2"}
{"ts":"2026-08-23T17:52:26.349Z","event_type":"new_market","market_id":"0xe05f69fefaf502ee9edc43312c5666ae3fc253783aefe530434517b7ddd29aa9"}
{"ts":"2026-08-23T17:52:26.379Z","event_type":"new_market","market_id":"0x591479ab50bfbdb2410a1487c3c29ac4ed85e685a760b8903dc14af40249c7ae"}
{"ts":"2026-08-23T17:52:26.379Z","event_type":"new_market","market_id":"0xef248a607900c496ca423c39ab2ee9bc5e21f540201879e29aef15f71c1c527a"}
{"ts":"2026-08-23T17:52:26.419Z","event_type":"new_market","market_id":"0x46035fcbd78bad15fd419c526d8dbd1e5b3db4b1858b650c844fb9521f73868b"}
{"ts":"2026-08-23T17:52:26.420Z","event_type":"new_market","market_id":"0xc1bee5c4ab489097a96ca53622de18a034582923f1cd1f16ea2bdca46eff32db"}
{"ts":"2026-08-23T17:52:26.526Z","event_type":"new_market","market_id":"0x0d086763027a2305373f31a43851843d84d6464cad641668b81db8dcbd21782c"}
{"ts":"2026-08-23T17:52:26.528Z","event_type":"new_market","market_id":"0xf183c757bd3a4f4322d546e17e8b42e153031fccb767d0dcbe41056746ea2eb4"}
{"ts":"2026-08-23T17:52:26.532Z","event_type":"new_market","market_id":"0x479d5617869b8655545e74e4c509edab26e16513a46551b7b25559767b45e4e3"}
{"ts":"2026-08-23T17:52:26.553Z","event_type":"new_market","market_id":"0x88e481bd294637cbacd5c2c87c7f9e175c67a9ed50b25f53e8dff56bb9f3c334"}
{"ts":"2026-08-23T17:52:26.769Z","event_type":"best_bid_ask","market_id":"3790415","outcome_index":0,"market_type":"set2","local_side":"home","local_uid":"2026-08-23_pierre_hugues_herbert_quinn_vandecasteele","bid":0.64,"ask":0.72,"mid":0.68,"spread":0.08,"bid_size":null,"ask_size":null}
{"ts":"2026-08-23T17:52:26.769Z","event_type":"best_bid_ask","market_id":"3790415","outcome_index":1,"market_type":"set2","local_side":"away","local_uid":"2026-08-23_pierre_hugues_herbert_quinn_vandecasteele","bid":0.28,"ask":0.36,"mid":0.32,"spread":0.08,"bid_size":null,"ask_size":null}
{"ts":"2026-08-23T17:52:26.769Z","event_type":"price_change","market_id":"3790415","outcome_index":1,"market_type":"set2","local_side":"away","local_uid":"2026-08-23_pierre_hugues_herbert_quinn_vandecasteele","bid":0.28,"ask":0.36,"mid":0.32,"spread":0.08,"price":0.29,"size":0.0,"side":"BUY"}
{"ts":"2026-08-23T17:52:26.770Z","event_type":"price_change","market_id":"3790415","outcome_index":0,"market_type":"set2","local_side":"home","local_uid":"2026-08-23_pierre_hugues_herbert_quinn_vandecasteele","bid":0.64,"ask":0.72,"mid":0.68,"spread":0.08,"price":0.71,"size":0.0,"side":"SELL"}
{"ts":"2026-08-23T17:52:26.770Z","event_type":"best_bid_ask","market_id":"3790415","outcome_index":0,"market_type":"set2","local_side":"home","local_uid":"2026-08-23_pierre_hugues_herbert_quinn_vandecasteele","bid":0.63,"ask":0.72,"mid":0.675,"spread":0.09,"bid_size":null,"ask_size":null}
{"ts":"2026-08-23T17:52:26.770Z","event_type":"best_bid_ask","market_id":"3790415","outcome_index":1,"market_type":"set2","local_side":"away","local_uid":"2026-08-23_pierre_hugues_herbert_quinn_vandecasteele","bid":0.28,"ask":0.37,"mid":0.325,"spread":0.09,"bid_size":null,"ask_size":null}
{"ts":"2026-08-23T17:52:26.770Z","event_type":"price_change","market_id":"3790415","outcome_index":0,"market_type":"set2","local_side":"home","local_uid":"2026-08-23_pierre_hugues_herbert_quinn_vandecasteele","bid":0.63,"ask":0.72,"mid":0.675,"spread":0.09,"price":0.64,"size":0.0,"side":"BUY"}
{"ts":"2026-08-23T17:52:26.770Z","event_type":"price_change","market_id":"3790415","outcome_index":1,"market_type":"set2","local_side":"away","local_uid":"2026-08-23_pierre_hugues_herbert_quinn_vandecasteele","bid":0.28,"ask":0.37,"mid":0.325,"spread":0.09,"price":0.36,"size":0.0,"side":"SELL"}
{"ts":"2026-08-23T17:52:26.780Z","event_type":"best_bid_ask","market_id":"3790415","outcome_index":0,"market_type":"set2","local_side":"home","local_uid":"2026-08-23_pierre_hugues_herbert_quinn_vandecasteele","bid":0.63,"ask":0.73,"mid":0.68,"spread":0.1,"bid_size":null,"ask_size":null}
{"ts":"2026-08-23T17:52:26.780Z","event_type":"best_bid_ask","market_id":"3790415","outcome_index":1,"market_type":"set2","local_side":"away","local_uid":"2026-08-23_pierre_hugues_herbert_quinn_vandecasteele","bid":0.27,"ask":0.37,"mid":0.32,"spread":0.1,"bid_size":null,"ask_size":null}
{"ts":"2026-08-23T17:52:26.780Z","event_type":"price_change","market_id":"3790415","outcome_index":1,"market_type":"set2","local_side":"away","local_uid":"2026-08-23_pierre_hugues_herbert_quinn_vandecasteele","bid":0.27,"ask":0.37,"mid":0.32,"spread":0.1,"price":0.28,"size":0.0,"side":"BUY"}
{"ts":"2026-08-23T17:52:26.780Z","event_type":"price_change","market_id":"3790415","outcome_index":0,"market_type":"set2","local_side":"home","local_uid":"2026-08-23_pierre_hugues_herbert_quinn_vandecasteele","bid":0.63,"ask":0.73,"mid":0.68,"spread":0.1,"price":0.72,"size":0.0,"side":"SELL"}
{"ts":"2026-08-23T17:52:26.787Z","event_type":"best_bid_ask","market_id":"3790415","outcome_index":0,"market_type":"set2","local_side":"home","local_uid":"2026-08-23_pierre_hugues_herbert_quinn_vandecasteele","bid":0.2,"ask":0.73,"mid":0.465,"spread":0.53,"bid_size":null,"ask_size":null}
{"ts":"2026-08-23T17:52:26.787Z","event_type":"best_bid_ask","market_id":"3790415","outcome_index":1,"market_type":"set2","local_side":"away","local_uid":"2026-08-23_pierre_hugues_herbert_quinn_vandecasteele","bid":0.27,"ask":0.8,"mid":0.535,"spread":0.53,"bid_size":null,"ask_size":null}
{"ts":"2026-08-23T17:52:26.787Z","event_type":"price_change","market_id":"3790415","outcome_index":0,"market_type":"set2","local_side":"home","local_uid":"2026-08-23_pierre_hugues_herbert_quinn_vandecasteele","bid":0.2,"ask":0.73,"mid":0.465,"spread":0.53,"price":0.63,"size":0.0,"side":"BUY"}
{"ts":"2026-08-23T17:52:26.787Z","event_type":"price_change","market_id":"3790415","outcome_index":1,"market_type":"set2","local_side":"away","local_uid":"2026-08-23_pierre_hugues_herbert_quinn_vandecasteele","bid":0.27,"ask":0.8,"mid":0.535,"spread":0.53,"price":0.37,"size":0.0,"side":"SELL"}
{"ts":"2026-08-23T17:52:26.848Z","event_type":"best_bid_ask","market_id":"3790415","outcome_index":0,"market_type":"set2","local_side":"home","local_uid":"2026-08-23_pierre_hugues_herbert_quinn_vandecasteele","bid":0.2,"ask":0.72,"mid":0.46,"spread":0.52,"bid_size":null,"ask_size":null}
{"ts":"2026-08-23T17:52:26.848Z","event_type":"best_bid_ask","market_id":"3790415","outcome_index":1,"market_type":"set2","local_side":"away","local_uid":"2026-08-23_pierre_hugues_herbert_quinn_vandecasteele","bid":0.28,"ask":0.8,"mid":0.54,"spread":0.52,"bid_size":null,"ask_size":null}
{"ts":"2026-08-23T17:52:26.848Z","event_type":"price_change","market_id":"3790415","outcome_index":1,"market_type":"set2","local_side":"away","local_uid":"2026-08-23_pierre_hugues_herbert_quinn_vandecasteele","bid":0.28,"ask":0.8,"mid":0.54,"spread":0.52,"price":0.28,"size":30.48,"side":"BUY"}
{"ts":"2026-08-23T17:52:26.848Z","event_type":"price_change","market_id":"3790415","outcome_index":0,"market_type":"set2","local_side":"home","local_uid":"2026-08-23_pierre_hugues_herbert_quinn_vandecasteele","bid":0.2,"ask":0.72,"mid":0.46,"spread":0.52,"price":0.72,"size":30.48,"side":"SELL"}
{"ts":"2026-08-23T17:52:26.848Z","event_type":"best_bid_ask","market_id":"3790415","outcome_index":0,"market_type":"set2","local_side":"home","local_uid":"2026-08-23_pierre_hugues_herbert_quinn_vandecasteele","bid":0.59,"ask":0.72,"mid":0.655,"spread":0.13,"bid_size":null,"ask_size":null}
{"ts":"2026-08-23T17:52:26.848Z","event_type":"best_bid_ask","market_id":"3790415","outcome_index":1,"market_type":"set2","local_side":"away","local_uid":"2026-08-23_pierre_hugues_herbert_quinn_vandecasteele","bid":0.28,"ask":0.41,"mid":0.345,"spread":0.13,"bid_size":null,"ask_size":null}
{"ts":"2026-08-23T17:52:26.855Z","event_type":"price_change","market_id":"3790415","outcome_index":0,"market_type":"set2","local_side":"home","local_uid":"2026-08-23_pierre_hugues_herbert_quinn_vandecasteele","bid":0.59,"ask":0.72,"mid":0.655,"spread":0.13,"price":0.59,"size":423.0,"side":"BUY"}
{"ts":"2026-08-23T17:52:26.855Z","event_type":"price_change","market_id":"3790415","outcome_index":1,"market_type":"set2","local_side":"away","local_uid":"2026-08-23_pierre_hugues_herbert_quinn_vandecasteele","bid":0.28,"ask":0.41,"mid":0.345,"spread":0.13,"price":0.41,"size":423.0,"side":"SELL"}
{"ts":"2026-08-23T17:52:26.855Z","event_type":"best_bid_ask","market_id":"3790415","outcome_index":0,"market_type":"set2","local_side":"home","local_uid":"2026-08-23_pierre_hugues_herbert_quinn_vandecasteele","bid":0.6,"ask":0.72,"mid":0.66,"spread":0.12,"bid_size":null,"ask_size":null}
{"ts":"2026-08-23T17:52:26.855Z","event_type":"best_bid_ask","market_id":"3790415","outcome_index":1,"market_type":"set2","local_side":"away","local_uid":"2026-08-23_pierre_hugues_herbert_quinn_vandecasteele","bid":0.28,"ask":0.4,"mid":0.34,"spread":0.12,"bid_size":null,"ask_size":null}
{"ts":"2026-08-23T17:52:26.856Z","event_type":"price_change","market_id":"3790415","outcome_index":0,"market_type":"set2","local_side":"home","local_uid":"2026-08-23_pierre_hugues_herbert_quinn_vandecasteele","bid":0.6,"ask":0.72,"mid":0.66,"spread":0.12,"price":0.6,"size":88.0,"side":"BUY"}
{"ts":"2026-08-23T17:52:26.856Z","event_type":"price_change","market_id":"3790415","outcome_index":1,"market_type":"set2","local_side":"away","local_uid":"2026-08-23_pierre_hugues_herbert_quinn_vandecasteele","bid":0.28,"ask":0.4,"mid":0.34,"spread":0.12,"price":0.4,"size":88.0,"side":"SELL"}
{"ts":"2026-08-23T17:52:26.873Z","event_type":"best_bid_ask","market_id":"3790415","outcome_index":0,"market_type":"set2","local_side":"home","local_uid":"2026-08-23_pierre_hugues_herbert_quinn_vandecasteele","bid":0.6,"ask":0.74,"mid":0.67,"spread":0.14,"bid_size":null,"ask_size":null}
{"ts":"2026-08-23T17:52:26.873Z","event_type":"best_bid_ask","market_id":"3790415","outcome_index":1,"market_type":"set2","local_side":"away","local_uid":"2026-08-23_pierre_hugues_herbert_quinn_vandecasteele","bid":0.26,"ask":0.4,"mid":0.33,"spread":0.14,"bid_size":null,"ask_size":null}
{"ts":"2026-08-23T17:52:26.874Z","event_type":"price_change","market_id":"3790415","outcome_index":1,"market_type":"set2","local_side":"away","local_uid":"2026-08-23_pierre_hugues_herbert_quinn_vandecasteele","bid":0.26,"ask":0.4,"mid":0.33,"spread":0.14,"price":0.28,"size":0.0,"side":"BUY"}
{"ts":"2026-08-23T17:52:26.874Z","event_type":"price_change","market_id":"3790415","outcome_index":0,"market_type":"set2","local_side":"home","local_uid":"2026-08-23_pierre_hugues_herbert_quinn_vandecasteele","bid":0.6,"ask":0.74,"mid":0.67,"spread":0.14,"price":0.72,"size":0.0,"side":"SELL"}
{"ts":"2026-08-23T17:52:26.893Z","event_type":"best_bid_ask","market_id":"3790415","outcome_index":0,"market_type":"set2","local_side":"home","local_uid":"2026-08-23_pierre_hugues_herbert_quinn_vandecasteele","bid":0.6,"ask":0.76,"mid":0.68,"spread":0.16,"bid_size":null,"ask_size":null}
{"ts":"2026-08-23T17:52:26.893Z","event_type":"best_bid_ask","market_id":"3790415","outcome_index":1,"market_type":"set2","local_side":"away","local_uid":"2026-08-23_pierre_hugues_herbert_quinn_vandecasteele","bid":0.24,"ask":0.4,"mid":0.32,"spread":0.16,"bid_size":null,"ask_size":null}
{"ts":"2026-08-23T17:52:26.893Z","event_type":"price_change","market_id":"3790415","outcome_index":1,"market_type":"set2","local_side":"away","local_uid":"2026-08-23_pierre_hugues_herbert_quinn_vandecasteele","bid":0.24,"ask":0.4,"mid":0.32,"spread":0.16,"price":0.26,"size":0.0,"side":"BUY"}
{"ts":"2026-08-23T17:52:26.893Z","event_type":"price_change","market_id":"3790415","outcome_index":0,"market_type":"set2","local_side":"home","local_uid":"2026-08-23_pierre_hugues_herbert_quinn_vandecasteele","bid":0.6,"ask":0.76,"mid":0.68,"spread":0.16,"price":0.74,"size":0.0,"side":"SELL"}
{"ts":"2026-08-23T17:52:26.894Z","event_type":"best_bid_ask","market_id":"3790415","outcome_index":0,"market_type":"set2","local_side":"home","local_uid":"2026-08-23_pierre_hugues_herbert_quinn_vandecasteele","bid":0.57,"ask":0.76,"mid":0.665,"spread":0.19,"bid_size":null,"ask_size":null}
{"ts":"2026-08-23T17:52:26.894Z","event_type":"best_bid_ask","market_id":"3790415","outcome_index":1,"market_type":"set2","local_side":"away","local_uid":"2026-08-23_pierre_hugues_herbert_quinn_vandecasteele","bid":0.24,"ask":0.43,"mid":0.335,"spread":0.19,"bid_size":null,"ask_size":null}
{"ts":"2026-08-23T17:52:26.936Z","event_type":"price_change","market_id":"3790415","outcome_index":0,"market_type":"set2","local_side":"home","local_uid":"2026-08-23_pierre_hugues_herbert_quinn_vandecasteele","bid":0.57,"ask":0.76,"mid":0.665,"spread":0.19,"price":0.6,"size":0.0,"side":"BUY"}
{"ts":"2026-08-23T17:52:26.936Z","event_type":"price_change","market_id":"3790415","outcome_index":1,"market_type":"set2","local_side":"away","local_uid":"2026-08-23_pierre_hugues_herbert_quinn_vandecasteele","bid":0.24,"ask":0.43,"mid":0.335,"spread":0.19,"price":0.4,"size":0.0,"side":"SELL"}
{"ts":"2026-08-23T17:52:26.936Z","event_type":"best_bid_ask","market_id":"3790415","outcome_index":0,"market_type":"set2","local_side":"home","local_uid":"2026-08-23_pierre_hugues_herbert_quinn_vandecasteele","bid":0.58,"ask":0.76,"mid":0.67,"spread":0.18,"bid_size":null,"ask_size":null}
{"ts":"2026-08-23T17:52:26.936Z","event_type":"best_bid_ask","market_id":"3790415","outcome_index":1,"market_type":"set2","local_side":"away","local_uid":"2026-08-23_pierre_hugues_herbert_quinn_vandecasteele","bid":0.24,"ask":0.42,"mid":0.33,"spread":0.18,"bid_size":null,"ask_size":null}
{"ts":"2026-08-23T17:52:26.936Z","event_type":"price_change","market_id":"3790415","outcome_index":0,"market_type":"set2","local_side":"home","local_uid":"2026-08-23_pierre_hugues_herbert_quinn_vandecasteele","bid":0.58,"ask":0.76,"mid":0.67,"spread":0.18,"price":0.58,"size":88.0,"side":"BUY"}
{"ts":"2026-08-23T17:52:26.936Z","event_type":"price_change","market_id":"3790415","outcome_index":1,"market_type":"set2","local_side":"away","local_uid":"2026-08-23_pierre_hugues_herbert_quinn_vandecasteele","bid":0.24,"ask":0.42,"mid":0.33,"spread":0.18,"price":0.42,"size":88.0,"side":"SELL"}
{"ts":"2026-08-23T17:52:26.955Z","event_type":"best_bid_ask","market_id":"3790415","outcome_index":0,"market_type":"set2","local_side":"home","local_uid":"2026-08-23_pierre_hugues_herbert_quinn_vandecasteele","bid":0.58,"ask":1.0,"mid":0.79,"spread":0.42,"bid_size":null,"ask_size":null}
{"ts":"2026-08-23T17:52:26.955Z","event_type":"best_bid_ask","market_id":"3790415","outcome_index":1,"market_type":"set2","local_side":"away","local_uid":"2026-08-23_pierre_hugues_herbert_quinn_vandecasteele","bid":0.0,"ask":0.42,"mid":0.21,"spread":0.42,"bid_size":null,"ask_size":null}
{"ts":"2026-08-23T17:52:26.955Z","event_type":"price_change","market_id":"3790415","outcome_index":1,"market_type":"set2","local_side":"away","local_uid":"2026-08-23_pierre_hugues_herbert_quinn_vandecasteele","bid":0.0,"ask":0.42,"mid":0.21,"spread":0.42,"price":0.24,"size":0.0,"side":"BUY"}
{"ts":"2026-08-23T17:52:26.955Z","event_type":"price_change","market_id":"3790415","outcome_index":0,"market_type":"set2","local_side":"home","local_uid":"2026-08-23_pierre_hugues_herbert_quinn_vandecasteele","bid":0.58,"ask":1.0,"mid":0.79,"spread":0.42,"price":0.76,"size":0.0,"side":"SELL"}
{"ts":"2026-08-23T17:52:26.955Z","event_type":"best_bid_ask","market_id":"3790415","outcome_index":0,"market_type":"set2","local_side":"home","local_uid":"2026-08-23_pierre_hugues_herbert_quinn_vandecasteele","bid":0.58,"ask":0.76,"mid":0.67,"spread":0.18,"bid_size":null,"ask_size":null}
{"ts":"2026-08-23T17:52:26.955Z","event_type":"best_bid_ask","market_id":"3790415","outcome_index":1,"market_type":"set2","local_side":"away","local_uid":"2026-08-23_pierre_hugues_herbert_quinn_vandecasteele","bid":0.24,"ask":0.42,"mid":0.33,"spread":0.18,"bid_size":null,"ask_size":null}
{"ts":"2026-08-23T17:52:26.958Z","event_type":"price_change","market_id":"3790415","outcome_index":1,"market_type":"set2","local_side":"away","local_uid":"2026-08-23_pierre_hugues_herbert_quinn_vandecasteele","bid":0.24,"ask":0.42,"mid":0.33,"spread":0.18,"price":0.24,"size":150.0,"side":"BUY"}
{"ts":"2026-08-23T17:52:26.958Z","event_type":"price_change","market_id":"3790415","outcome_index":0,"market_type":"set2","local_side":"home","local_uid":"2026-08-23_pierre_hugues_herbert_quinn_vandecasteele","bid":0.58,"ask":0.76,"mid":0.67,"spread":0.18,"price":0.76,"size":150.0,"side":"SELL"}
{"ts":"2026-08-23T17:52:27.044Z","event_type":"best_bid_ask","market_id":"3790394","outcome_index":0,"market_type":"set1","local_side":"home","local_uid":"2026-08-23_hugo_grenier_mees_rottgering","bid":0.22,"ask":0.33,"mid":0.275,"spread":0.11,"bid_size":null,"ask_size":null}
{"ts":"2026-08-23T17:52:27.045Z","event_type":"best_bid_ask","market_id":"3790394","outcome_index":1,"market_type":"set1","local_side":"away","local_uid":"2026-08-23_hugo_grenier_mees_rottgering","bid":0.67,"ask":0.78,"mid":0.725,"spread":0.11,"bid_size":null,"ask_size":null}
{"ts":"2026-08-23T17:52:27.045Z","event_type":"price_change","market_id":"3790394","outcome_index":0,"market_type":"set1","local_side":"home","local_uid":"2026-08-23_hugo_grenier_mees_rottgering","bid":0.22,"ask":0.33,"mid":0.275,"spread":0.11,"price":0.25,"size":0.0,"side":"BUY"}
{"ts":"2026-08-23T17:52:27.045Z","event_type":"price_change","market_id":"3790394","outcome_index":1,"market_type":"set1","local_side":"away","local_uid":"2026-08-23_hugo_grenier_mees_rottgering","bid":0.67,"ask":0.78,"mid":0.725,"spread":0.11,"price":0.75,"size":0.0,"side":"SELL"}
{"ts":"2026-08-23T17:52:27.062Z","event_type":"best_bid_ask","market_id":"3790323","outcome_index":0,"market_type":"set2","local_side":"home","local_uid":"2026-08-23_felix_balshaw_sebastian_gorzny","bid":0.49,"ask":0.57,"mid":0.53,"spread":0.08,"bid_size":null,"ask_size":null}
{"ts":"2026-08-23T17:52:27.062Z","event_type":"best_bid_ask","market_id":"3790323","outcome_index":1,"market_type":"set2","local_side":"away","local_uid":"2026-08-23_felix_balshaw_sebastian_gorzny","bid":0.43,"ask":0.51,"mid":0.47,"spread":0.08,"bid_size":null,"ask_size":null}
{"ts":"2026-08-23T17:52:27.067Z","event_type":"price_change","market_id":"3790323","outcome_index":0,"market_type":"set2","local_side":"home","local_uid":"2026-08-23_felix_balshaw_sebastian_gorzny","bid":0.49,"ask":0.57,"mid":0.53,"spread":0.08,"price":0.5,"size":0.0,"side":"BUY"}
{"ts":"2026-08-23T17:52:27.068Z","event_type":"price_change","market_id":"3790323","outcome_index":1,"market_type":"set2","local_side":"away","local_uid":"2026-08-23_felix_balshaw_sebastian_gorzny","bid":0.43,"ask":0.51,"mid":0.47,"spread":0.08,"price":0.5,"size":0.0,"side":"SELL"}
{"ts":"2026-08-23T17:52:27.254Z","event_type":"price_change","market_id":"3795968","outcome_index":1,"market_type":"match","local_side":"away","local_uid":"2026-08-23_mario_gonzalez_fernandez_richard_mallory","bid":0.49,"ask":0.5,"mid":0.495,"spread":0.01,"price":0.26,"size":46.0,"side":"BUY"}
{"ts":"2026-08-23T17:52:27.254Z","event_type":"price_change","market_id":"3795968","outcome_index":0,"market_type":"match","local_side":"home","local_uid":"2026-08-23_mario_gonzalez_fernandez_richard_mallory","bid":0.5,"ask":0.51,"mid":0.505,"spread":0.01,"price":0.74,"size":46.0,"side":"SELL"}
{"ts":"2026-08-23T17:52:27.724Z","event_type":"best_bid_ask","market_id":"3790394","outcome_index":0,"market_type":"set1","local_side":"home","local_uid":"2026-08-23_hugo_grenier_mees_rottgering","bid":0.23,"ask":0.33,"mid":0.28,"spread":0.1,"bid_size":null,"ask_size":null}
{"ts":"2026-08-23T17:52:27.724Z","event_type":"best_bid_ask","market_id":"3790394","outcome_index":1,"market_type":"set1","local_side":"away","local_uid":"2026-08-23_hugo_grenier_mees_rottgering","bid":0.67,"ask":0.77,"mid":0.72,"spread":0.1,"bid_size":null,"ask_size":null}
{"ts":"2026-08-23T17:52:27.725Z","event_type":"price_change","market_id":"3790394","outcome_index":0,"market_type":"set1","local_side":"home","local_uid":"2026-08-23_hugo_grenier_mees_rottgering","bid":0.23,"ask":0.33,"mid":0.28,"spread":0.1,"price":0.23,"size":84.37,"side":"BUY"}
{"ts":"2026-08-23T17:52:27.725Z","event_type":"price_change","market_id":"3790394","outcome_index":1,"market_type":"set1","local_side":"away","local_uid":"2026-08-23_hugo_grenier_mees_rottgering","bid":0.67,"ask":0.77,"mid":0.72,"spread":0.1,"price":0.77,"size":84.37,"side":"SELL"}
{"ts":"2026-08-23T17:52:27.940Z","event_type":"best_bid_ask","market_id":"3790323","outcome_index":0,"market_type":"set2","local_side":"home","local_uid":"2026-08-23_felix_balshaw_sebastian_gorzny","bid":0.48,"ask":0.57,"mid":0.525,"spread":0.09,"bid_size":null,"ask_size":null}
{"ts":"2026-08-23T17:52:27.940Z","event_type":"best_bid_ask","market_id":"3790323","outcome_index":1,"market_type":"set2","local_side":"away","local_uid":"2026-08-23_felix_balshaw_sebastian_gorzny","bid":0.43,"ask":0.52,"mid":0.475,"spread":0.09,"bid_size":null,"ask_size":null}
{"ts":"2026-08-23T17:52:27.940Z","event_type":"price_change","market_id":"3790323","outcome_index":0,"market_type":"set2","local_side":"home","local_uid":"2026-08-23_felix_balshaw_sebastian_gorzny","bid":0.48,"ask":0.57,"mid":0.525,"spread":0.09,"price":0.49,"size":0.0,"side":"BUY"}
{"ts":"2026-08-23T17:52:27.941Z","event_type":"price_change","market_id":"3790323","outcome_index":1,"market_type":"set2","local_side":"away","local_uid":"2026-08-23_felix_balshaw_sebastian_gorzny","bid":0.43,"ask":0.52,"mid":0.475,"spread":0.09,"price":0.51,"size":0.0,"side":"SELL"}
{"ts":"2026-08-23T17:52:27.942Z","event_type":"best_bid_ask","market_id":"3790323","outcome_index":0,"market_type":"set2","local_side":"home","local_uid":"2026-08-23_felix_balshaw_sebastian_gorzny","bid":0.5,"ask":0.57,"mid":0.535,"spread":0.07,"bid_size":null,"ask_size":null}
{"ts":"2026-08-23T17:52:27.947Z","event_type":"best_bid_ask","market_id":"3790323","outcome_index":1,"market_type":"set2","local_side":"away","local_uid":"2026-08-23_felix_balshaw_sebastian_gorzny","bid":0.43,"ask":0.5,"mid":0.465,"spread":0.07,"bid_size":null,"ask_size":null}
{"ts":"2026-08-23T17:52:27.947Z","event_type":"price_change","market_id":"3790323","outcome_index":0,"market_type":"set2","local_side":"home","local_uid":"2026-08-23_felix_balshaw_sebastian_gorzny","bid":0.5,"ask":0.57,"mid":0.535,"spread":0.07,"price":0.5,"size":150.0,"side":"BUY"}
{"ts":"2026-08-23T17:52:27.947Z","event_type":"price_change","market_id":"3790323","outcome_index":1,"market_type":"set2","local_side":"away","local_uid":"2026-08-23_felix_balshaw_sebastian_gorzny","bid":0.43,"ask":0.5,"mid":0.465,"spread":0.07,"price":0.5,"size":150.0,"side":"SELL"}
{"ts":"2026-08-23T17:52:28.041Z","event_type":"best_bid_ask","market_id":"3790394","outcome_index":0,"market_type":"set1","local_side":"home","local_uid":"2026-08-23_hugo_grenier_mees_rottgering","bid":0.22,"ask":0.33,"mid":0.275,"spread":0.11,"bid_size":null,"ask_size":null}
{"ts":"2026-08-23T17:52:28.041Z","event_type":"best_bid_ask","market_id":"3790394","outcome_index":1,"market_type":"set1","local_side":"away","local_uid":"2026-08-23_hugo_grenier_mees_rottgering","bid":0.67,"ask":0.78,"mid":0.725,"spread":0.11,"bid_size":null,"ask_size":null}
{"ts":"2026-08-23T17:52:28.042Z","event_type":"price_change","market_id":"3790394","outcome_index":0,"market_type":"set1","local_side":"home","local_uid":"2026-08-23_hugo_grenier_mees_rottgering","bid":0.22,"ask":0.33,"mid":0.275,"spread":0.11,"price":0.23,"size":0.0,"side":"BUY"}
{"ts":"2026-08-23T17:52:28.042Z","event_type":"price_change","market_id":"3790394","outcome_index":1,"market_type":"set1","local_side":"away","local_uid":"2026-08-23_hugo_grenier_mees_rottgering","bid":0.67,"ask":0.78,"mid":0.725,"spread":0.11,"price":0.77,"size":0.0,"side":"SELL"}
{"ts":"2026-08-23T17:52:28.069Z","event_type":"best_bid_ask","market_id":"3790394","outcome_index":0,"market_type":"set1","local_side":"home","local_uid":"2026-08-23_hugo_grenier_mees_rottgering","bid":0.23,"ask":0.33,"mid":0.28,"spread":0.1,"bid_size":null,"ask_size":null}
{"ts":"2026-08-23T17:52:28.069Z","event_type":"best_bid_ask","market_id":"3790394","outcome_index":1,"market_type":"set1","local_side":"away","local_uid":"2026-08-23_hugo_grenier_mees_rottgering","bid":0.67,"ask":0.77,"mid":0.72,"spread":0.1,"bid_size":null,"ask_size":null}
{"ts":"2026-08-23T17:52:28.072Z","event_type":"price_change","market_id":"3790394","outcome_index":0,"market_type":"set1","local_side":"home","local_uid":"2026-08-23_hugo_grenier_mees_rottgering","bid":0.23,"ask":0.33,"mid":0.28,"spread":0.1,"price":0.23,"size":58.49,"side":"BUY"}
{"ts":"2026-08-23T17:52:28.072Z","event_type":"price_change","market_id":"3790394","outcome_index":1,"market_type":"set1","local_side":"away","local_uid":"2026-08-23_hugo_grenier_mees_rottgering","bid":0.67,"ask":0.77,"mid":0.72,"spread":0.1,"price":0.77,"size":58.49,"side":"SELL"}
{"ts":"2026-08-23T17:52:28.173Z","event_type":"best_bid_ask","market_id":"3790394","outcome_index":0,"market_type":"set1","local_side":"home","local_uid":"2026-08-23_hugo_grenier_mees_rottgering","bid":0.22,"ask":0.33,"mid":0.275,"spread":0.11,"bid_size":null,"ask_size":null}
{"ts":"2026-08-23T17:52:28.173Z","event_type":"best_bid_ask","market_id":"3790394","outcome_index":1,"market_type":"set1","local_side":"away","local_uid":"2026-08-23_hugo_grenier_mees_rottgering","bid":0.67,"ask":0.78,"mid":0.725,"spread":0.11,"bid_size":null,"ask_size":null}
{"ts":"2026-08-23T17:52:28.173Z","event_type":"price_change","market_id":"3790394","outcome_index":0,"market_type":"set1","local_side":"home","local_uid":"2026-08-23_hugo_grenier_mees_rottgering","bid":0.22,"ask":0.33,"mid":0.275,"spread":0.11,"price":0.23,"size":0.0,"side":"BUY"}
{"ts":"2026-08-23T17:52:28.173Z","event_type":"price_change","market_id":"3790394","outcome_index":1,"market_type":"set1","local_side":"away","local_uid":"2026-08-23_hugo_grenier_mees_rottgering","bid":0.67,"ask":0.78,"mid":0.725,"spread":0.11,"price":0.77,"size":0.0,"side":"SELL"}
{"ts":"2026-08-23T17:52:28.417Z","event_type":"new_market","market_id":"0xb82ff58e61b1e405a159e6d9ca275dbd2e9b1445ceba9c0352893fa6e3c8fb0e"}
{"ts":"2026-08-23T17:52:28.434Z","event_type":"new_market","market_id":"0x33c3e94d48a9d0775a05169c7710544664255c62db5434f29120516cfdfa9bc0"}
{"ts":"2026-08-23T17:52:28.782Z","event_type":"price_change","market_id":"3795964","outcome_index":1,"market_type":"match","local_side":"away","local_uid":"2026-08-23_nicholas_gore_dan_martin","bid":0.991,"ask":0.997,"mid":0.994,"spread":0.006,"price":0.73,"size":0.0,"side":"BUY"}
{"ts":"2026-08-23T17:52:28.782Z","event_type":"price_change","market_id":"3795964","outcome_index":0,"market_type":"match","local_side":"home","local_uid":"2026-08-23_nicholas_gore_dan_martin","bid":0.003,"ask":0.009,"mid":0.006,"spread":0.006,"price":0.27,"size":0.0,"side":"SELL"}
{"ts":"2026-08-23T17:52:28.882Z","event_type":"best_bid_ask","market_id":"3790415","outcome_index":0,"market_type":"set2","local_side":"home","local_uid":"2026-08-23_pierre_hugues_herbert_quinn_vandecasteele","bid":0.6,"ask":0.76,"mid":0.68,"spread":0.16,"bid_size":null,"ask_size":null}
{"ts":"2026-08-23T17:52:28.882Z","event_type":"best_bid_ask","market_id":"3790415","outcome_index":1,"market_type":"set2","local_side":"away","local_uid":"2026-08-23_pierre_hugues_herbert_quinn_vandecasteele","bid":0.24,"ask":0.4,"mid":0.32,"spread":0.16,"bid_size":null,"ask_size":null}
{"ts":"2026-08-23T17:52:28.882Z","event_type":"price_change","market_id":"3790415","outcome_index":0,"market_type":"set2","local_side":"home","local_uid":"2026-08-23_pierre_hugues_herbert_quinn_vandecasteele","bid":0.6,"ask":0.76,"mid":0.68,"spread":0.16,"price":0.6,"size":98.89,"side":"BUY"}
{"ts":"2026-08-23T17:52:28.882Z","event_type":"price_change","market_id":"3790415","outcome_index":1,"market_type":"set2","local_side":"away","local_uid":"2026-08-23_pierre_hugues_herbert_quinn_vandecasteele","bid":0.24,"ask":0.4,"mid":0.32,"spread":0.16,"price":0.4,"size":98.89,"side":"SELL"}
{"ts":"2026-08-23T17:52:29.445Z","event_type":"best_bid_ask","market_id":"3790394","outcome_index":0,"market_type":"set1","local_side":"home","local_uid":"2026-08-23_hugo_grenier_mees_rottgering","bid":0.21,"ask":0.33,"mid":0.27,"spread":0.12,"bid_size":null,"ask_size":null}
{"ts":"2026-08-23T17:52:29.446Z","event_type":"best_bid_ask","market_id":"3790394","outcome_index":1,"market_type":"set1","local_side":"away","local_uid":"2026-08-23_hugo_grenier_mees_rottgering","bid":0.67,"ask":0.79,"mid":0.73,"spread":0.12,"bid_size":null,"ask_size":null}
{"ts":"2026-08-23T17:52:29.446Z","event_type":"price_change","market_id":"3790394","outcome_index":0,"market_type":"set1","local_side":"home","local_uid":"2026-08-23_hugo_grenier_mees_rottgering","bid":0.21,"ask":0.33,"mid":0.27,"spread":0.12,"price":0.22,"size":0.0,"side":"BUY"}
{"ts":"2026-08-23T17:52:29.446Z","event_type":"price_change","market_id":"3790394","outcome_index":1,"market_type":"set1","local_side":"away","local_uid":"2026-08-23_hugo_grenier_mees_rottgering","bid":0.67,"ask":0.79,"mid":0.73,"spread":0.12,"price":0.78,"size":0.0,"side":"SELL"}
{"ts":"2026-08-23T17:52:29.516Z","event_type":"best_bid_ask","market_id":"3790397","outcome_index":0,"market_type":"set2","local_side":"home","local_uid":"2026-08-23_hugo_grenier_mees_rottgering","bid":0.3,"ask":0.41,"mid":0.355,"spread":0.11,"bid_size":null,"ask_size":null}
{"ts":"2026-08-23T17:52:29.517Z","event_type":"best_bid_ask","market_id":"3790397","outcome_index":1,"market_type":"set2","local_side":"away","local_uid":"2026-08-23_hugo_grenier_mees_rottgering","bid":0.59,"ask":0.7,"mid":0.645,"spread":0.11,"bid_size":null,"ask_size":null}
{"ts":"2026-08-23T17:52:29.517Z","event_type":"price_change","market_id":"3790397","outcome_index":0,"market_type":"set2","local_side":"home","local_uid":"2026-08-23_hugo_grenier_mees_rottgering","bid":0.3,"ask":0.41,"mid":0.355,"spread":0.11,"price":0.31,"size":0.0,"side":"BUY"}
{"ts":"2026-08-23T17:52:29.517Z","event_type":"price_change","market_id":"3790397","outcome_index":1,"market_type":"set2","local_side":"away","local_uid":"2026-08-23_hugo_grenier_mees_rottgering","bid":0.59,"ask":0.7,"mid":0.645,"spread":0.11,"price":0.69,"size":0.0,"side":"SELL"}
{"ts":"2026-08-23T17:52:29.519Z","event_type":"best_bid_ask","market_id":"3790397","outcome_index":0,"market_type":"set2","local_side":"home","local_uid":"2026-08-23_hugo_grenier_mees_rottgering","bid":0.27,"ask":0.41,"mid":0.34,"spread":0.14,"bid_size":null,"ask_size":null}
{"ts":"2026-08-23T17:52:29.520Z","event_type":"best_bid_ask","market_id":"3790397","outcome_index":1,"market_type":"set2","local_side":"away","local_uid":"2026-08-23_hugo_grenier_mees_rottgering","bid":0.59,"ask":0.73,"mid":0.66,"spread":0.14,"bid_size":null,"ask_size":null}
{"ts":"2026-08-23T17:52:29.520Z","event_type":"price_change","market_id":"3790397","outcome_index":0,"market_type":"set2","local_side":"home","local_uid":"2026-08-23_hugo_grenier_mees_rottgering","bid":0.27,"ask":0.41,"mid":0.34,"spread":0.14,"price":0.3,"size":0.0,"side":"BUY"}
{"ts":"2026-08-23T17:52:29.520Z","event_type":"price_change","market_id":"3790397","outcome_index":1,"market_type":"set2","local_side":"away","local_uid":"2026-08-23_hugo_grenier_mees_rottgering","bid":0.59,"ask":0.73,"mid":0.66,"spread":0.14,"price":0.7,"size":0.0,"side":"SELL"}
{"ts":"2026-08-23T17:52:29.552Z","event_type":"best_bid_ask","market_id":"3790394","outcome_index":0,"market_type":"set1","local_side":"home","local_uid":"2026-08-23_hugo_grenier_mees_rottgering","bid":0.21,"ask":0.35,"mid":0.28,"spread":0.14,"bid_size":null,"ask_size":null}
{"ts":"2026-08-23T17:52:29.552Z","event_type":"best_bid_ask","market_id":"3790394","outcome_index":1,"market_type":"set1","local_side":"away","local_uid":"2026-08-23_hugo_grenier_mees_rottgering","bid":0.65,"ask":0.79,"mid":0.72,"spread":0.14,"bid_size":null,"ask_size":null}
{"ts":"2026-08-23T17:52:29.552Z","event_type":"price_change","market_id":"3790394","outcome_index":1,"market_type":"set1","local_side":"away","local_uid":"2026-08-23_hugo_grenier_mees_rottgering","bid":0.65,"ask":0.79,"mid":0.72,"spread":0.14,"price":0.67,"size":0.0,"side":"BUY"}
{"ts":"2026-08-23T17:52:29.552Z","event_type":"price_change","market_id":"3790394","outcome_index":0,"market_type":"set1","local_side":"home","local_uid":"2026-08-23_hugo_grenier_mees_rottgering","bid":0.21,"ask":0.35,"mid":0.28,"spread":0.14,"price":0.33,"size":0.0,"side":"SELL"}
{"ts":"2026-08-23T17:52:29.585Z","event_type":"best_bid_ask","market_id":"3790397","outcome_index":0,"market_type":"set2","local_side":"home","local_uid":"2026-08-23_hugo_grenier_mees_rottgering","bid":0.27,"ask":0.44,"mid":0.355,"spread":0.17,"bid_size":null,"ask_size":null}
{"ts":"2026-08-23T17:52:29.586Z","event_type":"best_bid_ask","market_id":"3790397","outcome_index":1,"market_type":"set2","local_side":"away","local_uid":"2026-08-23_hugo_grenier_mees_rottgering","bid":0.56,"ask":0.73,"mid":0.645,"spread":0.17,"bid_size":null,"ask_size":null}
{"ts":"2026-08-23T17:52:29.586Z","event_type":"price_change","market_id":"3790397","outcome_index":1,"market_type":"set2","local_side":"away","local_uid":"2026-08-23_hugo_grenier_mees_rottgering","bid":0.56,"ask":0.73,"mid":0.645,"spread":0.17,"price":0.59,"size":0.0,"side":"BUY"}
{"ts":"2026-08-23T17:52:29.586Z","event_type":"price_change","market_id":"3790397","outcome_index":0,"market_type":"set2","local_side":"home","local_uid":"2026-08-23_hugo_grenier_mees_rottgering","bid":0.27,"ask":0.44,"mid":0.355,"spread":0.17,"price":0.41,"size":0.0,"side":"SELL"}
{"ts":"2026-08-23T17:52:29.609Z","event_type":"best_bid_ask","market_id":"3789927","outcome_index":0,"market_type":"match","local_side":"home","local_uid":"2026-08-23_hugo_grenier_mees_rottgering","bid":0.27,"ask":0.29,"mid":0.28,"spread":0.02,"bid_size":null,"ask_size":null}
{"ts":"2026-08-23T17:52:29.609Z","event_type":"best_bid_ask","market_id":"3789927","outcome_index":1,"market_type":"match","local_side":"away","local_uid":"2026-08-23_hugo_grenier_mees_rottgering","bid":0.71,"ask":0.73,"mid":0.72,"spread":0.02,"bid_size":null,"ask_size":null}
{"ts":"2026-08-23T17:52:29.609Z","event_type":"price_change","market_id":"3789927","outcome_index":1,"market_type":"match","local_side":"away","local_uid":"2026-08-23_hugo_grenier_mees_rottgering","bid":0.71,"ask":0.73,"mid":0.72,"spread":0.02,"price":0.76,"size":686.3,"side":"SELL"}
{"ts":"2026-08-23T17:52:29.609Z","event_type":"price_change","market_id":"3789927","outcome_index":0,"market_type":"match","local_side":"home","local_uid":"2026-08-23_hugo_grenier_mees_rottgering","bid":0.27,"ask":0.29,"mid":0.28,"spread":0.02,"price":0.24,"size":686.3,"side":"BUY"}
{"ts":"2026-08-23T17:52:29.625Z","event_type":"best_bid_ask","market_id":"3790394","outcome_index":0,"market_type":"set1","local_side":"home","local_uid":"2026-08-23_hugo_grenier_mees_rottgering","bid":0.22,"ask":0.35,"mid":0.285,"spread":0.13,"bid_size":null,"ask_size":null}
{"ts":"2026-08-23T17:52:29.625Z","event_type":"best_bid_ask","market_id":"3790394","outcome_index":1,"market_type":"set1","local_side":"away","local_uid":"2026-08-23_hugo_grenier_mees_rottgering","bid":0.65,"ask":0.78,"mid":0.715,"spread":0.13,"bid_size":null,"ask_size":null}
{"ts":"2026-08-23T17:52:29.626Z","event_type":"price_change","market_id":"3790394","outcome_index":0,"market_type":"set1","local_side":"home","local_uid":"2026-08-23_hugo_grenier_mees_rottgering","bid":0.22,"ask":0.35,"mid":0.285,"spread":0.13,"price":0.22,"size":18.82,"side":"BUY"}
{"ts":"2026-08-23T17:52:29.626Z","event_type":"price_change","market_id":"3790394","outcome_index":1,"market_type":"set1","local_side":"away","local_uid":"2026-08-23_hugo_grenier_mees_rottgering","bid":0.65,"ask":0.78,"mid":0.715,"spread":0.13,"price":0.78,"size":18.82,"side":"SELL"}
{"ts":"2026-08-23T17:52:29.653Z","event_type":"best_bid_ask","market_id":"3790394","outcome_index":0,"market_type":"set1","local_side":"home","local_uid":"2026-08-23_hugo_grenier_mees_rottgering","bid":0.22,"ask":0.39,"mid":0.305,"spread":0.17,"bid_size":null,"ask_size":null}
{"ts":"2026-08-23T17:52:29.653Z","event_type":"best_bid_ask","market_id":"3790394","outcome_index":1,"market_type":"set1","local_side":"away","local_uid":"2026-08-23_hugo_grenier_mees_rottgering","bid":0.61,"ask":0.78,"mid":0.695,"spread":0.17,"bid_size":null,"ask_size":null}
{"ts":"2026-08-23T17:52:29.653Z","event_type":"price_change","market_id":"3790394","outcome_index":1,"market_type":"set1","local_side":"away","local_uid":"2026-08-23_hugo_grenier_mees_rottgering","bid":0.61,"ask":0.78,"mid":0.695,"spread":0.17,"price":0.65,"size":0.0,"side":"BUY"}
{"ts":"2026-08-23T17:52:29.653Z","event_type":"price_change","market_id":"3790394","outcome_index":0,"market_type":"set1","local_side":"home","local_uid":"2026-08-23_hugo_grenier_mees_rottgering","bid":0.22,"ask":0.39,"mid":0.305,"spread":0.17,"price":0.35,"size":0.0,"side":"SELL"}
{"ts":"2026-08-23T17:52:29.653Z","event_type":"best_bid_ask","market_id":"3790397","outcome_index":0,"market_type":"set2","local_side":"home","local_uid":"2026-08-23_hugo_grenier_mees_rottgering","bid":0.28,"ask":0.44,"mid":0.36,"spread":0.16,"bid_size":null,"ask_size":null}
{"ts":"2026-08-23T17:52:29.654Z","event_type":"best_bid_ask","market_id":"3790397","outcome_index":1,"market_type":"set2","local_side":"away","local_uid":"2026-08-23_hugo_grenier_mees_rottgering","bid":0.56,"ask":0.72,"mid":0.64,"spread":0.16,"bid_size":null,"ask_size":null}
{"ts":"2026-08-23T17:52:29.657Z","event_type":"price_change","market_id":"3790397","outcome_index":0,"market_type":"set2","local_side":"home","local_uid":"2026-08-23_hugo_grenier_mees_rottgering","bid":0.28,"ask":0.44,"mid":0.36,"spread":0.16,"price":0.28,"size":150.0,"side":"BUY"}
{"ts":"2026-08-23T17:52:29.657Z","event_type":"price_change","market_id":"3790397","outcome_index":1,"market_type":"set2","local_side":"away","local_uid":"2026-08-23_hugo_grenier_mees_rottgering","bid":0.56,"ask":0.72,"mid":0.64,"spread":0.16,"price":0.72,"size":150.0,"side":"SELL"}
{"ts":"2026-08-23T17:52:29.657Z","event_type":"best_bid_ask","market_id":"3790397","outcome_index":0,"market_type":"set2","local_side":"home","local_uid":"2026-08-23_hugo_grenier_mees_rottgering","bid":0.31,"ask":0.44,"mid":0.375,"spread":0.13,"bid_size":null,"ask_size":null}
{"ts":"2026-08-23T17:52:29.657Z","event_type":"best_bid_ask","market_id":"3790397","outcome_index":1,"market_type":"set2","local_side":"away","local_uid":"2026-08-23_hugo_grenier_mees_rottgering","bid":0.56,"ask":0.69,"mid":0.625,"spread":0.13,"bid_size":null,"ask_size":null}
{"ts":"2026-08-23T17:52:29.657Z","event_type":"price_change","market_id":"3790397","outcome_index":0,"market_type":"set2","local_side":"home","local_uid":"2026-08-23_hugo_grenier_mees_rottgering","bid":0.31,"ask":0.44,"mid":0.375,"spread":0.13,"price":0.31,"size":11.71,"side":"BUY"}
{"ts":"2026-08-23T17:52:29.658Z","event_type":"price_change","market_id":"3790397","outcome_index":1,"market_type":"set2","local_side":"away","local_uid":"2026-08-23_hugo_grenier_mees_rottgering","bid":0.56,"ask":0.69,"mid":0.625,"spread":0.13,"price":0.69,"size":11.71,"side":"SELL"}
{"ts":"2026-08-23T17:52:29.658Z","event_type":"best_bid_ask","market_id":"3790397","outcome_index":0,"market_type":"set2","local_side":"home","local_uid":"2026-08-23_hugo_grenier_mees_rottgering","bid":0.31,"ask":0.43,"mid":0.37,"spread":0.12,"bid_size":null,"ask_size":null}
{"ts":"2026-08-23T17:52:29.658Z","event_type":"best_bid_ask","market_id":"3790397","outcome_index":1,"market_type":"set2","local_side":"away","local_uid":"2026-08-23_hugo_grenier_mees_rottgering","bid":0.57,"ask":0.69,"mid":0.63,"spread":0.12,"bid_size":null,"ask_size":null}
{"ts":"2026-08-23T17:52:29.658Z","event_type":"price_change","market_id":"3790397","outcome_index":1,"market_type":"set2","local_side":"away","local_uid":"2026-08-23_hugo_grenier_mees_rottgering","bid":0.57,"ask":0.69,"mid":0.63,"spread":0.12,"price":0.57,"size":150.0,"side":"BUY"}
{"ts":"2026-08-23T17:52:29.658Z","event_type":"price_change","market_id":"3790397","outcome_index":0,"market_type":"set2","local_side":"home","local_uid":"2026-08-23_hugo_grenier_mees_rottgering","bid":0.31,"ask":0.43,"mid":0.37,"spread":0.12,"price":0.43,"size":150.0,"side":"SELL"}
{"ts":"2026-08-23T17:52:29.658Z","event_type":"best_bid_ask","market_id":"3790397","outcome_index":0,"market_type":"set2","local_side":"home","local_uid":"2026-08-23_hugo_grenier_mees_rottgering","bid":0.31,"ask":0.41,"mid":0.36,"spread":0.1,"bid_size":null,"ask_size":null}
{"ts":"2026-08-23T17:52:29.659Z","event_type":"best_bid_ask","market_id":"3790397","outcome_index":1,"market_type":"set2","local_side":"away","local_uid":"2026-08-23_hugo_grenier_mees_rottgering","bid":0.59,"ask":0.69,"mid":0.64,"spread":0.1,"bid_size":null,"ask_size":null}
{"ts":"2026-08-23T17:52:29.680Z","event_type":"price_change","market_id":"3790397","outcome_index":1,"market_type":"set2","local_side":"away","local_uid":"2026-08-23_hugo_grenier_mees_rottgering","bid":0.59,"ask":0.69,"mid":0.64,"spread":0.1,"price":0.59,"size":23.04,"side":"BUY"}
{"ts":"2026-08-23T17:52:29.680Z","event_type":"price_change","market_id":"3790397","outcome_index":0,"market_type":"set2","local_side":"home","local_uid":"2026-08-23_hugo_grenier_mees_rottgering","bid":0.31,"ask":0.41,"mid":0.36,"spread":0.1,"price":0.41,"size":23.04,"side":"SELL"}
{"ts":"2026-08-23T17:52:29.691Z","event_type":"best_bid_ask","market_id":"3789927","outcome_index":0,"market_type":"match","local_side":"home","local_uid":"2026-08-23_hugo_grenier_mees_rottgering","bid":0.27,"ask":0.28,"mid":0.275,"spread":0.01,"bid_size":null,"ask_size":null}
{"ts":"2026-08-23T17:52:29.691Z","event_type":"best_bid_ask","market_id":"3789927","outcome_index":1,"market_type":"match","local_side":"away","local_uid":"2026-08-23_hugo_grenier_mees_rottgering","bid":0.72,"ask":0.73,"mid":0.725,"spread":0.01,"bid_size":null,"ask_size":null}
{"ts":"2026-08-23T17:52:29.691Z","event_type":"price_change","market_id":"3789927","outcome_index":1,"market_type":"match","local_side":"away","local_uid":"2026-08-23_hugo_grenier_mees_rottgering","bid":0.72,"ask":0.73,"mid":0.725,"spread":0.01,"price":0.72,"size":195.0,"side":"BUY"}
{"ts":"2026-08-23T17:52:29.691Z","event_type":"price_change","market_id":"3789927","outcome_index":0,"market_type":"match","local_side":"home","local_uid":"2026-08-23_hugo_grenier_mees_rottgering","bid":0.27,"ask":0.28,"mid":0.275,"spread":0.01,"price":0.28,"size":195.0,"side":"SELL"}
{"ts":"2026-08-23T17:52:29.763Z","event_type":"best_bid_ask","market_id":"3790394","outcome_index":0,"market_type":"set1","local_side":"home","local_uid":"2026-08-23_hugo_grenier_mees_rottgering","bid":0.22,"ask":0.4,"mid":0.31,"spread":0.18,"bid_size":null,"ask_size":null}
{"ts":"2026-08-23T17:52:29.763Z","event_type":"best_bid_ask","market_id":"3790394","outcome_index":1,"market_type":"set1","local_side":"away","local_uid":"2026-08-23_hugo_grenier_mees_rottgering","bid":0.6,"ask":0.78,"mid":0.69,"spread":0.18,"bid_size":null,"ask_size":null}
{"ts":"2026-08-23T17:52:29.764Z","event_type":"price_change","market_id":"3790394","outcome_index":1,"market_type":"set1","local_side":"away","local_uid":"2026-08-23_hugo_grenier_mees_rottgering","bid":0.6,"ask":0.78,"mid":0.69,"spread":0.18,"price":0.61,"size":0.0,"side":"BUY"}
{"ts":"2026-08-23T17:52:29.764Z","event_type":"price_change","market_id":"3790394","outcome_index":0,"market_type":"set1","local_side":"home","local_uid":"2026-08-23_hugo_grenier_mees_rottgering","bid":0.22,"ask":0.4,"mid":0.31,"spread":0.18,"price":0.39,"size":0.0,"side":"SELL"}
{"ts":"2026-08-23T17:52:29.865Z","event_type":"best_bid_ask","market_id":"3789927","outcome_index":0,"market_type":"match","local_side":"home","local_uid":"2026-08-23_hugo_grenier_mees_rottgering","bid":0.27,"ask":0.29,"mid":0.28,"spread":0.02,"bid_size":null,"ask_size":null}
{"ts":"2026-08-23T17:52:29.865Z","event_type":"best_bid_ask","market_id":"3789927","outcome_index":1,"market_type":"match","local_side":"away","local_uid":"2026-08-23_hugo_grenier_mees_rottgering","bid":0.71,"ask":0.73,"mid":0.72,"spread":0.02,"bid_size":null,"ask_size":null}
{"ts":"2026-08-23T17:52:29.866Z","event_type":"price_change","market_id":"3789927","outcome_index":1,"market_type":"match","local_side":"away","local_uid":"2026-08-23_hugo_grenier_mees_rottgering","bid":0.71,"ask":0.73,"mid":0.72,"spread":0.02,"price":0.72,"size":0.0,"side":"BUY"}
{"ts":"2026-08-23T17:52:29.866Z","event_type":"price_change","market_id":"3789927","outcome_index":0,"market_type":"match","local_side":"home","local_uid":"2026-08-23_hugo_grenier_mees_rottgering","bid":0.27,"ask":0.29,"mid":0.28,"spread":0.02,"price":0.28,"size":0.0,"side":"SELL"}
{"ts":"2026-08-23T17:52:29.866Z","event_type":"best_bid_ask","market_id":"3789927","outcome_index":0,"market_type":"match","local_side":"home","local_uid":"2026-08-23_hugo_grenier_mees_rottgering","bid":0.27,"ask":0.3,"mid":0.285,"spread":0.03,"bid_size":null,"ask_size":null}
{"ts":"2026-08-23T17:52:29.866Z","event_type":"best_bid_ask","market_id":"3789927","outcome_index":1,"market_type":"match","local_side":"away","local_uid":"2026-08-23_hugo_grenier_mees_rottgering","bid":0.7,"ask":0.73,"mid":0.715,"spread":0.03,"bid_size":null,"ask_size":null}
{"ts":"2026-08-23T17:52:29.866Z","event_type":"price_change","market_id":"3789927","outcome_index":1,"market_type":"match","local_side":"away","local_uid":"2026-08-23_hugo_grenier_mees_rottgering","bid":0.7,"ask":0.73,"mid":0.715,"spread":0.03,"price":0.71,"size":0.0,"side":"BUY"}
{"ts":"2026-08-23T17:52:29.866Z","event_type":"price_change","market_id":"3789927","outcome_index":0,"market_type":"match","local_side":"home","local_uid":"2026-08-23_hugo_grenier_mees_rottgering","bid":0.27,"ask":0.3,"mid":0.285,"spread":0.03,"price":0.29,"size":0.0,"side":"SELL"}
{"ts":"2026-08-23T17:52:29.976Z","event_type":"price_change","market_id":"3795974","outcome_index":0,"market_type":"match","local_side":"home","local_uid":"2026-08-23_juan_jose_bianchi_keshav_chopra","bid":0.15,"ask":0.19,"mid":0.17,"spread":0.04,"price":0.12,"size":2512.0,"side":"BUY"}
{"ts":"2026-08-23T17:52:29.976Z","event_type":"price_change","market_id":"3795974","outcome_index":1,"market_type":"match","local_side":"away","local_uid":"2026-08-23_juan_jose_bianchi_keshav_chopra","bid":0.81,"ask":0.85,"mid":0.83,"spread":0.04,"price":0.88,"size":2512.0,"side":"SELL"}
{"ts":"2026-08-23T17:52:30.252Z","event_type":"new_market","market_id":"0xc27fcccd56ad161ad42d1a20d9e38f1247b185dda7ad4d06b2fa1559a07e73e4"}
{"ts":"2026-08-23T17:52:30.252Z","event_type":"new_market","market_id":"0xcb868d6420000cde31f3606d2b6d9b143c6cab53066e2298ddc259c182423019"}
{"ts":"2026-08-23T17:52:30.253Z","event_type":"new_market","market_id":"0xb1d03e86d9e04383e8404aeade09df4219d47118dc6f3a02e3e19c0c7845e897"}
{"ts":"2026-08-23T17:52:30.253Z","event_type":"new_market","market_id":"0x85be753a54b2a05abfb3d541c6f3f532ce5da74d717a7cd3a582fa5545ab05d7"}
{"ts":"2026-08-23T17:52:30.429Z","event_type":"new_market","market_id":"0x55fb0ec0e6abc3a9f7717c878cf1607c1b11a664c1abba1abd5379009f539816"}
{"ts":"2026-08-23T17:52:30.437Z","event_type":"new_market","market_id":"0x021cdf911ce689ecf0bd02b1840c8a70349ba16127d42f0d08e7143d36c4c322"}
{"ts":"2026-08-23T17:52:30.771Z","event_type":"price_change","market_id":"3780820","outcome_index":1,"market_type":"match","local_side":"away","local_uid":"2026-08-23_sho_shimabukuro_miomir_kecmanovic","bid":0.68,"ask":0.69,"mid":0.685,"spread":0.01,"price":0.37,"size":0.0,"side":"BUY"}
{"ts":"2026-08-23T17:52:30.771Z","event_type":"price_change","market_id":"3780820","outcome_index":0,"market_type":"match","local_side":"home","local_uid":"2026-08-23_sho_shimabukuro_miomir_kecmanovic","bid":0.31,"ask":0.32,"mid":0.315,"spread":0.01,"price":0.63,"size":0.0,"side":"SELL"}
{"ts":"2026-08-23T17:52:32.236Z","event_type":"new_market","market_id":"0x1c6f38dd6260a58ad005a06075980cfa2219898e79f97428dc0db23fff50349a"}
{"ts":"2026-08-23T17:52:32.237Z","event_type":"new_market","market_id":"0xecbe064559e7123212f0bf77b4c72b637fcadb0c53361ce41d2d49bb8657b864"}
{"ts":"2026-08-23T17:52:32.237Z","event_type":"new_market","market_id":"0x4c1b52a94b23e1a17fee5d3521c6f6f737d4fd580e8cfc0856ff83b3f8455713"}
{"ts":"2026-08-23T17:52:32.238Z","event_type":"new_market","market_id":"0x56693b4c76c0c04ce77f993751e3988c945f9b72c9987951bb3c75d6e612d73e"}
{"ts":"2026-08-23T17:52:32.238Z","event_type":"new_market","market_id":"0x921a274c0ef4624982fb34e1c806aea371be3cabf8ebc33204d3cd9466d9b1ab"}
{"ts":"2026-08-23T17:52:32.566Z","event_type":"best_bid_ask","market_id":"3790419","outcome_index":0,"market_type":"set1","local_side":"home","local_uid":"2026-08-23_pierre_hugues_herbert_quinn_vandecasteele","bid":0.999,"ask":1.0,"mid":0.9995,"spread":0.001,"bid_size":null,"ask_size":null}
{"ts":"2026-08-23T17:52:32.567Z","event_type":"best_bid_ask","market_id":"3790419","outcome_index":1,"market_type":"set1","local_side":"away","local_uid":"2026-08-23_pierre_hugues_herbert_quinn_vandecasteele","bid":0.0,"ask":0.001,"mid":0.0005,"spread":0.001,"bid_size":null,"ask_size":null}
{"ts":"2026-08-23T17:52:32.567Z","event_type":"price_change","market_id":"3790419","outcome_index":0,"market_type":"set1","local_side":"home","local_uid":"2026-08-23_pierre_hugues_herbert_quinn_vandecasteele","bid":0.999,"ask":1.0,"mid":0.9995,"spread":0.001,"price":0.999,"size":2725.73,"side":"BUY"}
{"ts":"2026-08-23T17:52:32.567Z","event_type":"price_change","market_id":"3790419","outcome_index":1,"market_type":"set1","local_side":"away","local_uid":"2026-08-23_pierre_hugues_herbert_quinn_vandecasteele","bid":0.0,"ask":0.001,"mid":0.0005,"spread":0.001,"price":0.001,"size":2725.73,"side":"SELL"}
{"ts":"2026-08-23T17:52:32.567Z","event_type":"book","market_id":"3790419","outcome_index":0,"market_type":"set1","local_side":"home","local_uid":"2026-08-23_pierre_hugues_herbert_quinn_vandecasteele","bid":0.999,"ask":null,"mid":null,"spread":null,"bid_size":2725.73,"ask_size":null}
{"ts":"2026-08-23T17:52:32.567Z","event_type":"book","market_id":"3790419","outcome_index":1,"market_type":"set1","local_side":"away","local_uid":"2026-08-23_pierre_hugues_herbert_quinn_vandecasteele","bid":null,"ask":0.001,"mid":null,"spread":null,"bid_size":null,"ask_size":2725.73}
{"ts":"2026-08-23T17:52:32.770Z","event_type":"last_trade_price","market_id":"3790419","outcome_index":0,"market_type":"set1","local_side":"home","local_uid":"2026-08-23_pierre_hugues_herbert_quinn_vandecasteele","last_trade":0.999,"trade_size":14.51,"trade_side":"SELL","trade_notional":14.4955}
{"ts":"2026-08-23T17:52:32.983Z","event_type":"price_change","market_id":"3780826","outcome_index":1,"market_type":"match","local_side":"away","local_uid":"2026-08-23_giovanni_mpetshi_perricard_jenson_brooksby","bid":0.62,"ask":0.63,"mid":0.625,"spread":0.01,"price":0.43,"size":36.0,"side":"BUY"}
{"ts":"2026-08-23T17:52:32.983Z","event_type":"price_change","market_id":"3780826","outcome_index":0,"market_type":"match","local_side":"home","local_uid":"2026-08-23_giovanni_mpetshi_perricard_jenson_brooksby","bid":0.37,"ask":0.38,"mid":0.375,"spread":0.01,"price":0.57,"size":36.0,"side":"SELL"}
{"ts":"2026-08-23T17:52:33.195Z","event_type":"best_bid_ask","market_id":"3789927","outcome_index":0,"market_type":"match","local_side":"home","local_uid":"2026-08-23_hugo_grenier_mees_rottgering","bid":0.24,"ask":0.25,"mid":0.245,"spread":0.01,"bid_size":null,"ask_size":null}
{"ts":"2026-08-23T17:52:33.195Z","event_type":"best_bid_ask","market_id":"3789927","outcome_index":1,"market_type":"match","local_side":"away","local_uid":"2026-08-23_hugo_grenier_mees_rottgering","bid":0.75,"ask":0.76,"mid":0.755,"spread":0.01,"bid_size":null,"ask_size":null}
{"ts":"2026-08-23T17:52:33.196Z","event_type":"price_change","market_id":"3789927","outcome_index":1,"market_type":"match","local_side":"away","local_uid":"2026-08-23_hugo_grenier_mees_rottgering","bid":0.75,"ask":0.76,"mid":0.755,"spread":0.01,"price":0.75,"size":5913.0,"side":"BUY"}
{"ts":"2026-08-23T17:52:33.196Z","event_type":"price_change","market_id":"3789927","outcome_index":0,"market_type":"match","local_side":"home","local_uid":"2026-08-23_hugo_grenier_mees_rottgering","bid":0.24,"ask":0.25,"mid":0.245,"spread":0.01,"price":0.25,"size":5913.0,"side":"SELL"}
{"ts":"2026-08-23T17:52:33.199Z","event_type":"book","market_id":"3789927","outcome_index":0,"market_type":"match","local_side":"home","local_uid":"2026-08-23_hugo_grenier_mees_rottgering","bid":0.24,"ask":0.25,"mid":0.245,"spread":0.01,"bid_size":770.3,"ask_size":5913.0}
{"ts":"2026-08-23T17:52:33.202Z","event_type":"book","market_id":"3789927","outcome_index":1,"market_type":"match","local_side":"away","local_uid":"2026-08-23_hugo_grenier_mees_rottgering","bid":0.75,"ask":0.76,"mid":0.755,"spread":0.01,"bid_size":5913.0,"ask_size":770.3}
{"ts":"2026-08-23T17:52:33.305Z","event_type":"best_bid_ask","market_id":"3789927","outcome_index":0,"market_type":"match","local_side":"home","local_uid":"2026-08-23_hugo_grenier_mees_rottgering","bid":0.24,"ask":0.26,"mid":0.25,"spread":0.02,"bid_size":null,"ask_size":null}
{"ts":"2026-08-23T17:52:33.305Z","event_type":"best_bid_ask","market_id":"3789927","outcome_index":1,"market_type":"match","local_side":"away","local_uid":"2026-08-23_hugo_grenier_mees_rottgering","bid":0.74,"ask":0.76,"mid":0.75,"spread":0.02,"bid_size":null,"ask_size":null}
{"ts":"2026-08-23T17:52:33.306Z","event_type":"price_change","market_id":"3789927","outcome_index":1,"market_type":"match","local_side":"away","local_uid":"2026-08-23_hugo_grenier_mees_rottgering","bid":0.74,"ask":0.76,"mid":0.75,"spread":0.02,"price":0.75,"size":0.0,"side":"BUY"}
{"ts":"2026-08-23T17:52:33.306Z","event_type":"price_change","market_id":"3789927","outcome_index":0,"market_type":"match","local_side":"home","local_uid":"2026-08-23_hugo_grenier_mees_rottgering","bid":0.24,"ask":0.26,"mid":0.25,"spread":0.02,"price":0.25,"size":0.0,"side":"SELL"}
{"ts":"2026-08-23T17:52:33.308Z","event_type":"best_bid_ask","market_id":"3789927","outcome_index":0,"market_type":"match","local_side":"home","local_uid":"2026-08-23_hugo_grenier_mees_rottgering","bid":0.24,"ask":0.3,"mid":0.27,"spread":0.06,"bid_size":null,"ask_size":null}
{"ts":"2026-08-23T17:52:33.308Z","event_type":"best_bid_ask","market_id":"3789927","outcome_index":1,"market_type":"match","local_side":"away","local_uid":"2026-08-23_hugo_grenier_mees_rottgering","bid":0.7,"ask":0.76,"mid":0.73,"spread":0.06,"bid_size":null,"ask_size":null}
{"ts":"2026-08-23T17:52:33.308Z","event_type":"price_change","market_id":"3789927","outcome_index":1,"market_type":"match","local_side":"away","local_uid":"2026-08-23_hugo_grenier_mees_rottgering","bid":0.7,"ask":0.76,"mid":0.73,"spread":0.06,"price":0.74,"size":0.0,"side":"BUY"}
{"ts":"2026-08-23T17:52:33.308Z","event_type":"price_change","market_id":"3789927","outcome_index":0,"market_type":"match","local_side":"home","local_uid":"2026-08-23_hugo_grenier_mees_rottgering","bid":0.24,"ask":0.3,"mid":0.27,"spread":0.06,"price":0.26,"size":0.0,"side":"SELL"}
{"ts":"2026-08-23T17:52:33.356Z","event_type":"best_bid_ask","market_id":"3789927","outcome_index":0,"market_type":"match","local_side":"home","local_uid":"2026-08-23_hugo_grenier_mees_rottgering","bid":0.24,"ask":0.29,"mid":0.265,"spread":0.05,"bid_size":null,"ask_size":null}
{"ts":"2026-08-23T17:52:33.357Z","event_type":"best_bid_ask","market_id":"3789927","outcome_index":1,"market_type":"match","local_side":"away","local_uid":"2026-08-23_hugo_grenier_mees_rottgering","bid":0.71,"ask":0.76,"mid":0.735,"spread":0.05,"bid_size":null,"ask_size":null}
{"ts":"2026-08-23T17:52:33.357Z","event_type":"price_change","market_id":"3789927","outcome_index":1,"market_type":"match","local_side":"away","local_uid":"2026-08-23_hugo_grenier_mees_rottgering","bid":0.71,"ask":0.76,"mid":0.735,"spread":0.05,"price":0.71,"size":34.0,"side":"BUY"}
{"ts":"2026-08-23T17:52:33.357Z","event_type":"price_change","market_id":"3789927","outcome_index":0,"market_type":"match","local_side":"home","local_uid":"2026-08-23_hugo_grenier_mees_rottgering","bid":0.24,"ask":0.29,"mid":0.265,"spread":0.05,"price":0.29,"size":34.0,"side":"SELL"}
{"ts":"2026-08-23T17:52:33.462Z","event_type":"best_bid_ask","market_id":"3789927","outcome_index":0,"market_type":"match","local_side":"home","local_uid":"2026-08-23_hugo_grenier_mees_rottgering","bid":0.24,"ask":0.3,"mid":0.27,"spread":0.06,"bid_size":null,"ask_size":null}
{"ts":"2026-08-23T17:52:33.463Z","event_type":"best_bid_ask","market_id":"3789927","outcome_index":1,"market_type":"match","local_side":"away","local_uid":"2026-08-23_hugo_grenier_mees_rottgering","bid":0.7,"ask":0.76,"mid":0.73,"spread":0.06,"bid_size":null,"ask_size":null}
{"ts":"2026-08-23T17:52:33.463Z","event_type":"price_change","market_id":"3789927","outcome_index":0,"market_type":"match","local_side":"home","local_uid":"2026-08-23_hugo_grenier_mees_rottgering","bid":0.24,"ask":0.3,"mid":0.27,"spread":0.06,"price":0.2,"size":1077.8,"side":"BUY"}
{"ts":"2026-08-23T17:52:33.463Z","event_type":"price_change","market_id":"3789927","outcome_index":1,"market_type":"match","local_side":"away","local_uid":"2026-08-23_hugo_grenier_mees_rottgering","bid":0.7,"ask":0.76,"mid":0.73,"spread":0.06,"price":0.8,"size":1077.8,"side":"SELL"}
{"ts":"2026-08-23T17:52:33.463Z","event_type":"best_bid_ask","market_id":"3789927","outcome_index":0,"market_type":"match","local_side":"home","local_uid":"2026-08-23_hugo_grenier_mees_rottgering","bid":0.24,"ask":0.29,"mid":0.265,"spread":0.05,"bid_size":null,"ask_size":null}
{"ts":"2026-08-23T17:52:33.463Z","event_type":"best_bid_ask","market_id":"3789927","outcome_index":1,"market_type":"match","local_side":"away","local_uid":"2026-08-23_hugo_grenier_mees_rottgering","bid":0.71,"ask":0.76,"mid":0.735,"spread":0.05,"bid_size":null,"ask_size":null}
{"ts":"2026-08-23T17:52:33.463Z","event_type":"price_change","market_id":"3789927","outcome_index":1,"market_type":"match","local_side":"away","local_uid":"2026-08-23_hugo_grenier_mees_rottgering","bid":0.71,"ask":0.76,"mid":0.735,"spread":0.05,"price":0.71,"size":60.1,"side":"BUY"}
{"ts":"2026-08-23T17:52:33.463Z","event_type":"price_change","market_id":"3789927","outcome_index":0,"market_type":"match","local_side":"home","local_uid":"2026-08-23_hugo_grenier_mees_rottgering","bid":0.24,"ask":0.29,"mid":0.265,"spread":0.05,"price":0.29,"size":60.1,"side":"SELL"}
{"ts":"2026-08-23T17:52:33.568Z","event_type":"best_bid_ask","market_id":"3789927","outcome_index":0,"market_type":"match","local_side":"home","local_uid":"2026-08-23_hugo_grenier_mees_rottgering","bid":0.24,"ask":0.28,"mid":0.26,"spread":0.04,"bid_size":null,"ask_size":null}
{"ts":"2026-08-23T17:52:33.568Z","event_type":"best_bid_ask","market_id":"3789927","outcome_index":1,"market_type":"match","local_side":"away","local_uid":"2026-08-23_hugo_grenier_mees_rottgering","bid":0.72,"ask":0.76,"mid":0.74,"spread":0.04,"bid_size":null,"ask_size":null}
{"ts":"2026-08-23T17:52:33.568Z","event_type":"price_change","market_id":"3789927","outcome_index":1,"market_type":"match","local_side":"away","local_uid":"2026-08-23_hugo_grenier_mees_rottgering","bid":0.72,"ask":0.76,"mid":0.74,"spread":0.04,"price":0.72,"size":100.0,"side":"BUY"}
{"ts":"2026-08-23T17:52:33.568Z","event_type":"price_change","market_id":"3789927","outcome_index":0,"market_type":"match","local_side":"home","local_uid":"2026-08-23_hugo_grenier_mees_rottgering","bid":0.24,"ask":0.28,"mid":0.26,"spread":0.04,"price":0.28,"size":100.0,"side":"SELL"}
{"ts":"2026-08-23T17:52:33.733Z","event_type":"best_bid_ask","market_id":"3789927","outcome_index":0,"market_type":"match","local_side":"home","local_uid":"2026-08-23_hugo_grenier_mees_rottgering","bid":0.24,"ask":0.25,"mid":0.245,"spread":0.01,"bid_size":null,"ask_size":null}
{"ts":"2026-08-23T17:52:33.736Z","event_type":"best_bid_ask","market_id":"3789927","outcome_index":1,"market_type":"match","local_side":"away","local_uid":"2026-08-23_hugo_grenier_mees_rottgering","bid":0.75,"ask":0.76,"mid":0.755,"spread":0.01,"bid_size":null,"ask_size":null}
{"ts":"2026-08-23T17:52:33.737Z","event_type":"price_change","market_id":"3789927","outcome_index":1,"market_type":"match","local_side":"away","local_uid":"2026-08-23_hugo_grenier_mees_rottgering","bid":0.75,"ask":0.76,"mid":0.755,"spread":0.01,"price":0.75,"size":11687.72,"side":"BUY"}
{"ts":"2026-08-23T17:52:33.737Z","event_type":"price_change","market_id":"3789927","outcome_index":0,"market_type":"match","local_side":"home","local_uid":"2026-08-23_hugo_grenier_mees_rottgering","bid":0.24,"ask":0.25,"mid":0.245,"spread":0.01,"price":0.25,"size":11687.72,"side":"SELL"}
{"ts":"2026-08-23T17:52:33.783Z","event_type":"last_trade_price","market_id":"3789927","outcome_index":1,"market_type":"match","local_side":"away","local_uid":"2026-08-23_hugo_grenier_mees_rottgering","last_trade":0.74,"trade_size":87.0,"trade_side":"BUY","trade_notional":64.38}
{"ts":"2026-08-23T17:52:34.586Z","event_type":"best_bid_ask","market_id":"3789927","outcome_index":0,"market_type":"match","local_side":"home","local_uid":"2026-08-23_hugo_grenier_mees_rottgering","bid":0.23,"ask":0.25,"mid":0.24,"spread":0.02,"bid_size":null,"ask_size":null}
{"ts":"2026-08-23T17:52:34.586Z","event_type":"best_bid_ask","market_id":"3789927","outcome_index":1,"market_type":"match","local_side":"away","local_uid":"2026-08-23_hugo_grenier_mees_rottgering","bid":0.75,"ask":0.77,"mid":0.76,"spread":0.02,"bid_size":null,"ask_size":null}
{"ts":"2026-08-23T17:52:34.586Z","event_type":"price_change","market_id":"3789927","outcome_index":0,"market_type":"match","local_side":"home","local_uid":"2026-08-23_hugo_grenier_mees_rottgering","bid":0.23,"ask":0.25,"mid":0.24,"spread":0.02,"price":0.24,"size":0.0,"side":"BUY"}
{"ts":"2026-08-23T17:52:34.586Z","event_type":"price_change","market_id":"3789927","outcome_index":1,"market_type":"match","local_side":"away","local_uid":"2026-08-23_hugo_grenier_mees_rottgering","bid":0.75,"ask":0.77,"mid":0.76,"spread":0.02,"price":0.76,"size":0.0,"side":"SELL"}
{"ts":"2026-08-23T17:52:34.793Z","event_type":"best_bid_ask","market_id":"3790397","outcome_index":0,"market_type":"set2","local_side":"home","local_uid":"2026-08-23_hugo_grenier_mees_rottgering","bid":0.31,"ask":0.42,"mid":0.365,"spread":0.11,"bid_size":null,"ask_size":null}
{"ts":"2026-08-23T17:52:34.793Z","event_type":"best_bid_ask","market_id":"3790397","outcome_index":1,"market_type":"set2","local_side":"away","local_uid":"2026-08-23_hugo_grenier_mees_rottgering","bid":0.58,"ask":0.69,"mid":0.635,"spread":0.11,"bid_size":null,"ask_size":null}
{"ts":"2026-08-23T17:52:34.793Z","event_type":"price_change","market_id":"3790397","outcome_index":1,"market_type":"set2","local_side":"away","local_uid":"2026-08-23_hugo_grenier_mees_rottgering","bid":0.58,"ask":0.69,"mid":0.635,"spread":0.11,"price":0.59,"size":0.0,"side":"BUY"}
{"ts":"2026-08-23T17:52:34.793Z","event_type":"price_change","market_id":"3790397","outcome_index":0,"market_type":"set2","local_side":"home","local_uid":"2026-08-23_hugo_grenier_mees_rottgering","bid":0.31,"ask":0.42,"mid":0.365,"spread":0.11,"price":0.41,"size":0.0,"side":"SELL"}
{"ts":"2026-08-23T17:52:34.797Z","event_type":"best_bid_ask","market_id":"3790394","outcome_index":0,"market_type":"set1","local_side":"home","local_uid":"2026-08-23_hugo_grenier_mees_rottgering","bid":0.22,"ask":0.27,"mid":0.245,"spread":0.05,"bid_size":null,"ask_size":null}
{"ts":"2026-08-23T17:52:34.797Z","event_type":"best_bid_ask","market_id":"3790394","outcome_index":1,"market_type":"set1","local_side":"away","local_uid":"2026-08-23_hugo_grenier_mees_rottgering","bid":0.73,"ask":0.78,"mid":0.755,"spread":0.05,"bid_size":null,"ask_size":null}
{"ts":"2026-08-23T17:52:34.797Z","event_type":"price_change","market_id":"3790394","outcome_index":1,"market_type":"set1","local_side":"away","local_uid":"2026-08-23_hugo_grenier_mees_rottgering","bid":0.73,"ask":0.78,"mid":0.755,"spread":0.05,"price":0.73,"size":88.0,"side":"BUY"}
{"ts":"2026-08-23T17:52:34.797Z","event_type":"price_change","market_id":"3790394","outcome_index":0,"market_type":"set1","local_side":"home","local_uid":"2026-08-23_hugo_grenier_mees_rottgering","bid":0.22,"ask":0.27,"mid":0.245,"spread":0.05,"price":0.27,"size":88.0,"side":"SELL"}
{"ts":"2026-08-23T17:52:34.797Z","event_type":"best_bid_ask","market_id":"3790394","outcome_index":0,"market_type":"set1","local_side":"home","local_uid":"2026-08-23_hugo_grenier_mees_rottgering","bid":0.21,"ask":0.27,"mid":0.24,"spread":0.06,"bid_size":null,"ask_size":null}
{"ts":"2026-08-23T17:52:34.797Z","event_type":"best_bid_ask","market_id":"3790394","outcome_index":1,"market_type":"set1","local_side":"away","local_uid":"2026-08-23_hugo_grenier_mees_rottgering","bid":0.73,"ask":0.79,"mid":0.76,"spread":0.06,"bid_size":null,"ask_size":null}
{"ts":"2026-08-23T17:52:34.798Z","event_type":"price_change","market_id":"3790394","outcome_index":1,"market_type":"set1","local_side":"away","local_uid":"2026-08-23_hugo_grenier_mees_rottgering","bid":0.73,"ask":0.79,"mid":0.76,"spread":0.06,"price":0.6,"size":0.0,"side":"BUY"}
{"ts":"2026-08-23T17:52:34.798Z","event_type":"price_change","market_id":"3790394","outcome_index":0,"market_type":"set1","local_side":"home","local_uid":"2026-08-23_hugo_grenier_mees_rottgering","bid":0.21,"ask":0.27,"mid":0.24,"spread":0.06,"price":0.4,"size":0.0,"side":"SELL"}
{"ts":"2026-08-23T17:52:34.799Z","event_type":"best_bid_ask","market_id":"3790394","outcome_index":0,"market_type":"set1","local_side":"home","local_uid":"2026-08-23_hugo_grenier_mees_rottgering","bid":0.19,"ask":0.27,"mid":0.23,"spread":0.08,"bid_size":null,"ask_size":null}
{"ts":"2026-08-23T17:52:34.799Z","event_type":"best_bid_ask","market_id":"3790394","outcome_index":1,"market_type":"set1","local_side":"away","local_uid":"2026-08-23_hugo_grenier_mees_rottgering","bid":0.73,"ask":0.81,"mid":0.77,"spread":0.08,"bid_size":null,"ask_size":null}
{"ts":"2026-08-23T17:52:34.800Z","event_type":"price_change","market_id":"3790394","outcome_index":0,"market_type":"set1","local_side":"home","local_uid":"2026-08-23_hugo_grenier_mees_rottgering","bid":0.19,"ask":0.27,"mid":0.23,"spread":0.08,"price":0.21,"size":0.0,"side":"BUY"}
{"ts":"2026-08-23T17:52:34.800Z","event_type":"price_change","market_id":"3790394","outcome_index":1,"market_type":"set1","local_side":"away","local_uid":"2026-08-23_hugo_grenier_mees_rottgering","bid":0.73,"ask":0.81,"mid":0.77,"spread":0.08,"price":0.79,"size":0.0,"side":"SELL"}
{"ts":"2026-08-23T17:52:34.902Z","event_type":"best_bid_ask","market_id":"3790394","outcome_index":0,"market_type":"set1","local_side":"home","local_uid":"2026-08-23_hugo_grenier_mees_rottgering","bid":0.0,"ask":0.27,"mid":0.135,"spread":0.27,"bid_size":null,"ask_size":null}
{"ts":"2026-08-23T17:52:34.902Z","event_type":"best_bid_ask","market_id":"3790394","outcome_index":1,"market_type":"set1","local_side":"away","local_uid":"2026-08-23_hugo_grenier_mees_rottgering","bid":0.73,"ask":1.0,"mid":0.865,"spread":0.27,"bid_size":null,"ask_size":null}
{"ts":"2026-08-23T17:52:34.902Z","event_type":"price_change","market_id":"3790394","outcome_index":0,"market_type":"set1","local_side":"home","local_uid":"2026-08-23_hugo_grenier_mees_rottgering","bid":0.0,"ask":0.27,"mid":0.135,"spread":0.27,"price":0.19,"size":0.0,"side":"BUY"}
{"ts":"2026-08-23T17:52:34.902Z","event_type":"price_change","market_id":"3790394","outcome_index":1,"market_type":"set1","local_side":"away","local_uid":"2026-08-23_hugo_grenier_mees_rottgering","bid":0.73,"ask":1.0,"mid":0.865,"spread":0.27,"price":0.81,"size":0.0,"side":"SELL"}
{"ts":"2026-08-23T17:52:34.903Z","event_type":"best_bid_ask","market_id":"3790394","outcome_index":0,"market_type":"set1","local_side":"home","local_uid":"2026-08-23_hugo_grenier_mees_rottgering","bid":0.16,"ask":0.27,"mid":0.215,"spread":0.11,"bid_size":null,"ask_size":null}
{"ts":"2026-08-23T17:52:34.903Z","event_type":"best_bid_ask","market_id":"3790394","outcome_index":1,"market_type":"set1","local_side":"away","local_uid":"2026-08-23_hugo_grenier_mees_rottgering","bid":0.73,"ask":0.84,"mid":0.785,"spread":0.11,"bid_size":null,"ask_size":null}
{"ts":"2026-08-23T17:52:34.903Z","event_type":"price_change","market_id":"3790394","outcome_index":0,"market_type":"set1","local_side":"home","local_uid":"2026-08-23_hugo_grenier_mees_rottgering","bid":0.16,"ask":0.27,"mid":0.215,"spread":0.11,"price":0.16,"size":39.0,"side":"BUY"}
{"ts":"2026-08-23T17:52:34.903Z","event_type":"price_change","market_id":"3790394","outcome_index":1,"market_type":"set1","local_side":"away","local_uid":"2026-08-23_hugo_grenier_mees_rottgering","bid":0.73,"ask":0.84,"mid":0.785,"spread":0.11,"price":0.84,"size":39.0,"side":"SELL"}
{"ts":"2026-08-23T17:52:34.905Z","event_type":"best_bid_ask","market_id":"3790397","outcome_index":0,"market_type":"set2","local_side":"home","local_uid":"2026-08-23_hugo_grenier_mees_rottgering","bid":0.27,"ask":0.42,"mid":0.345,"spread":0.15,"bid_size":null,"ask_size":null}
{"ts":"2026-08-23T17:52:34.906Z","event_type":"best_bid_ask","market_id":"3790397","outcome_index":1,"market_type":"set2","local_side":"away","local_uid":"2026-08-23_hugo_grenier_mees_rottgering","bid":0.58,"ask":0.73,"mid":0.655,"spread":0.15,"bid_size":null,"ask_size":null}
{"ts":"2026-08-23T17:52:34.906Z","event_type":"price_change","market_id":"3790397","outcome_index":0,"market_type":"set2","local_side":"home","local_uid":"2026-08-23_hugo_grenier_mees_rottgering","bid":0.27,"ask":0.42,"mid":0.345,"spread":0.15,"price":0.31,"size":0.0,"side":"BUY"}
{"ts":"2026-08-23T17:52:34.906Z","event_type":"price_change","market_id":"3790397","outcome_index":1,"market_type":"set2","local_side":"away","local_uid":"2026-08-23_hugo_grenier_mees_rottgering","bid":0.58,"ask":0.73,"mid":0.655,"spread":0.15,"price":0.69,"size":0.0,"side":"SELL"}
{"ts":"2026-08-23T17:52:35.009Z","event_type":"best_bid_ask","market_id":"3790397","outcome_index":0,"market_type":"set2","local_side":"home","local_uid":"2026-08-23_hugo_grenier_mees_rottgering","bid":0.27,"ask":0.39,"mid":0.33,"spread":0.12,"bid_size":null,"ask_size":null}
{"ts":"2026-08-23T17:52:35.009Z","event_type":"best_bid_ask","market_id":"3790397","outcome_index":1,"market_type":"set2","local_side":"away","local_uid":"2026-08-23_hugo_grenier_mees_rottgering","bid":0.61,"ask":0.73,"mid":0.67,"spread":0.12,"bid_size":null,"ask_size":null}
{"ts":"2026-08-23T17:52:35.009Z","event_type":"price_change","market_id":"3790397","outcome_index":1,"market_type":"set2","local_side":"away","local_uid":"2026-08-23_hugo_grenier_mees_rottgering","bid":0.61,"ask":0.73,"mid":0.67,"spread":0.12,"price":0.61,"size":34.44,"side":"BUY"}
{"ts":"2026-08-23T17:52:35.009Z","event_type":"price_change","market_id":"3790397","outcome_index":0,"market_type":"set2","local_side":"home","local_uid":"2026-08-23_hugo_grenier_mees_rottgering","bid":0.27,"ask":0.39,"mid":0.33,"spread":0.12,"price":0.39,"size":34.44,"side":"SELL"}
{"ts":"2026-08-23T17:52:35.540Z","event_type":"best_bid_ask","market_id":"3790397","outcome_index":0,"market_type":"set2","local_side":"home","local_uid":"2026-08-23_hugo_grenier_mees_rottgering","bid":0.28,"ask":0.39,"mid":0.335,"spread":0.11,"bid_size":null,"ask_size":null}
{"ts":"2026-08-23T17:52:35.540Z","event_type":"best_bid_ask","market_id":"3790397","outcome_index":1,"market_type":"set2","local_side":"away","local_uid":"2026-08-23_hugo_grenier_mees_rottgering","bid":0.61,"ask":0.72,"mid":0.665,"spread":0.11,"bid_size":null,"ask_size":null}
{"ts":"2026-08-23T17:52:35.540Z","event_type":"price_change","market_id":"3790397","outcome_index":0,"market_type":"set2","local_side":"home","local_uid":"2026-08-23_hugo_grenier_mees_rottgering","bid":0.28,"ask":0.39,"mid":0.335,"spread":0.11,"price":0.28,"size":150.0,"side":"BUY"}
{"ts":"2026-08-23T17:52:35.540Z","event_type":"price_change","market_id":"3790397","outcome_index":1,"market_type":"set2","local_side":"away","local_uid":"2026-08-23_hugo_grenier_mees_rottgering","bid":0.61,"ask":0.72,"mid":0.665,"spread":0.11,"price":0.72,"size":150.0,"side":"SELL"}
{"ts":"2026-08-23T17:52:35.648Z","event_type":"price_change","market_id":"3795946","outcome_index":0,"market_type":"match","local_side":"home","local_uid":"2026-08-23_arthur_fils_frances_tiafoe","bid":0.66,"ask":0.67,"mid":0.665,"spread":0.01,"price":0.64,"size":32048.71,"side":"BUY"}
{"ts":"2026-08-23T17:52:35.649Z","event_type":"price_change","market_id":"3795946","outcome_index":1,"market_type":"match","local_side":"away","local_uid":"2026-08-23_arthur_fils_frances_tiafoe","bid":0.33,"ask":0.34,"mid":0.335,"spread":0.01,"price":0.36,"size":32048.71,"side":"SELL"}
{"ts":"2026-08-23T17:52:36.234Z","event_type":"new_market","market_id":"0xb24a5e49dd5f1d5c0b7d026857a12b82e436ae42355b0ec8b47f0e1f4f033a36"}
{"ts":"2026-08-23T17:52:36.235Z","event_type":"new_market","market_id":"0x6266b8fdc9850ed9847bea2d2516c6046ea84a1a6ced399bb57f4e8962dd36fd"}
{"ts":"2026-08-23T17:52:36.235Z","event_type":"new_market","market_id":"0xa22c92c690280726026f21ce3623f0e889c3ac0640fe10b899af08da73a184e3"}
{"ts":"2026-08-23T17:52:36.236Z","event_type":"new_market","market_id":"0x4a2d7d57d54376d4eb8475166b659802100071728d3696f1a8ef81039dd6f65a"}
{"ts":"2026-08-23T17:52:36.286Z","event_type":"new_market","market_id":"0x184babbfc7dd704f32605ebe7bcee55cb76b22a9b51a53f816bf25e3e58a4b47"}
{"ts":"2026-08-23T17:52:36.293Z","event_type":"new_market","market_id":"0xf78de790acde9da362f79b475e11cbe22bcb88b6f48bab9356691e9aba4a1cd6"}
{"ts":"2026-08-23T17:52:36.293Z","event_type":"new_market","market_id":"0xcdd262201e0d990dd2c41c84baf9eb1f21e0accee310880e380775527ed83671"}
{"ts":"2026-08-23T17:52:36.342Z","event_type":"new_market","market_id":"0x051cee547017f379a5671a8c5deb351132db53d71a627519c9cfb01896c10828"}
{"ts":"2026-08-23T17:52:36.343Z","event_type":"new_market","market_id":"0xd81f083208697fa89e45805cc3a37a97f7a08536eeeb3594d026a43627d19134"}
{"ts":"2026-08-23T17:52:36.395Z","event_type":"new_market","market_id":"0x2e154e26633bdc477a6b9d5c72b663331801225dd0e9d89b3dbf1c555e460310"}
{"ts":"2026-08-23T17:52:36.446Z","event_type":"best_bid_ask","market_id":"3790394","outcome_index":0,"market_type":"set1","local_side":"home","local_uid":"2026-08-23_hugo_grenier_mees_rottgering","bid":0.19,"ask":0.27,"mid":0.23,"spread":0.08,"bid_size":null,"ask_size":null}
{"ts":"2026-08-23T17:52:36.446Z","event_type":"best_bid_ask","market_id":"3790394","outcome_index":1,"market_type":"set1","local_side":"away","local_uid":"2026-08-23_hugo_grenier_mees_rottgering","bid":0.73,"ask":0.81,"mid":0.77,"spread":0.08,"bid_size":null,"ask_size":null}
{"ts":"2026-08-23T17:52:36.446Z","event_type":"price_change","market_id":"3790394","outcome_index":0,"market_type":"set1","local_side":"home","local_uid":"2026-08-23_hugo_grenier_mees_rottgering","bid":0.19,"ask":0.27,"mid":0.23,"spread":0.08,"price":0.19,"size":201.79,"side":"BUY"}
{"ts":"2026-08-23T17:52:36.446Z","event_type":"price_change","market_id":"3790394","outcome_index":1,"market_type":"set1","local_side":"away","local_uid":"2026-08-23_hugo_grenier_mees_rottgering","bid":0.73,"ask":0.81,"mid":0.77,"spread":0.08,"price":0.81,"size":201.79,"side":"SELL"}
{"ts":"2026-08-23T17:52:36.498Z","event_type":"best_bid_ask","market_id":"3789927","outcome_index":0,"market_type":"match","local_side":"home","local_uid":"2026-08-23_hugo_grenier_mees_rottgering","bid":0.23,"ask":0.24,"mid":0.235,"spread":0.01,"bid_size":null,"ask_size":null}
{"ts":"2026-08-23T17:52:36.498Z","event_type":"best_bid_ask","market_id":"3789927","outcome_index":1,"market_type":"match","local_side":"away","local_uid":"2026-08-23_hugo_grenier_mees_rottgering","bid":0.76,"ask":0.77,"mid":0.765,"spread":0.01,"bid_size":null,"ask_size":null}
{"ts":"2026-08-23T17:52:36.499Z","event_type":"price_change","market_id":"3789927","outcome_index":1,"market_type":"match","local_side":"away","local_uid":"2026-08-23_hugo_grenier_mees_rottgering","bid":0.76,"ask":0.77,"mid":0.765,"spread":0.01,"price":0.76,"size":3430.26,"side":"BUY"}
{"ts":"2026-08-23T17:52:36.499Z","event_type":"price_change","market_id":"3789927","outcome_index":0,"market_type":"match","local_side":"home","local_uid":"2026-08-23_hugo_grenier_mees_rottgering","bid":0.23,"ask":0.24,"mid":0.235,"spread":0.01,"price":0.24,"size":3430.26,"side":"SELL"}
{"ts":"2026-08-23T17:52:37.244Z","event_type":"best_bid_ask","market_id":"3789931","outcome_index":0,"market_type":"match","local_side":"home","local_uid":"2026-08-23_stefanos_sakellaridis_luca_van_assche","bid":0.06,"ask":0.07,"mid":0.065,"spread":0.01,"bid_size":null,"ask_size":null}
{"ts":"2026-08-23T17:52:37.244Z","event_type":"best_bid_ask","market_id":"3789931","outcome_index":1,"market_type":"match","local_side":"away","local_uid":"2026-08-23_stefanos_sakellaridis_luca_van_assche","bid":0.93,"ask":0.94,"mid":0.935,"spread":0.01,"bid_size":null,"ask_size":null}
{"ts":"2026-08-23T17:52:37.244Z","event_type":"price_change","market_id":"3789931","outcome_index":0,"market_type":"match","local_side":"home","local_uid":"2026-08-23_stefanos_sakellaridis_luca_van_assche","bid":0.06,"ask":0.07,"mid":0.065,"spread":0.01,"price":0.06,"size":5036.67,"side":"BUY"}
{"ts":"2026-08-23T17:52:37.244Z","event_type":"price_change","market_id":"3789931","outcome_index":1,"market_type":"match","local_side":"away","local_uid":"2026-08-23_stefanos_sakellaridis_luca_van_assche","bid":0.93,"ask":0.94,"mid":0.935,"spread":0.01,"price":0.94,"size":5036.67,"side":"SELL"}
{"ts":"2026-08-23T17:52:37.245Z","event_type":"book","market_id":"3789931","outcome_index":0,"market_type":"match","local_side":"home","local_uid":"2026-08-23_stefanos_sakellaridis_luca_van_assche","bid":0.06,"ask":0.07,"mid":0.065,"spread":0.01,"bid_size":5036.67,"ask_size":24665.17}
{"ts":"2026-08-23T17:52:37.250Z","event_type":"book","market_id":"3789931","outcome_index":1,"market_type":"match","local_side":"away","local_uid":"2026-08-23_stefanos_sakellaridis_luca_van_assche","bid":0.93,"ask":0.94,"mid":0.935,"spread":0.01,"bid_size":24665.17,"ask_size":5036.67}
{"ts":"2026-08-23T17:52:37.456Z","event_type":"last_trade_price","market_id":"3789931","outcome_index":0,"market_type":"match","local_side":"home","local_uid":"2026-08-23_stefanos_sakellaridis_luca_van_assche","last_trade":0.06,"trade_size":1530.0,"trade_side":"BUY","trade_notional":91.8}
{"ts":"2026-08-23T17:52:37.459Z","event_type":"price_change","market_id":"3793663","outcome_index":0,"market_type":"set1","local_side":"home","local_uid":"2026-08-24_antonia_ruzic_nikola_bartunkova","bid":0.34,"ask":0.37,"mid":0.355,"spread":0.03,"price":0.3,"size":205.0,"side":"BUY"}
{"ts":"2026-08-23T17:52:37.459Z","event_type":"price_change","market_id":"3793663","outcome_index":1,"market_type":"set1","local_side":"away","local_uid":"2026-08-24_antonia_ruzic_nikola_bartunkova","bid":0.63,"ask":0.66,"mid":0.645,"spread":0.03,"price":0.7,"size":205.0,"side":"SELL"}
{"ts":"2026-08-23T17:52:37.460Z","event_type":"best_bid_ask","market_id":"3790397","outcome_index":0,"market_type":"set2","local_side":"home","local_uid":"2026-08-23_hugo_grenier_mees_rottgering","bid":0.28,"ask":0.4,"mid":0.34,"spread":0.12,"bid_size":null,"ask_size":null}
{"ts":"2026-08-23T17:52:37.460Z","event_type":"best_bid_ask","market_id":"3790397","outcome_index":1,"market_type":"set2","local_side":"away","local_uid":"2026-08-23_hugo_grenier_mees_rottgering","bid":0.6,"ask":0.72,"mid":0.66,"spread":0.12,"bid_size":null,"ask_size":null}
{"ts":"2026-08-23T17:52:37.460Z","event_type":"price_change","market_id":"3790397","outcome_index":1,"market_type":"set2","local_side":"away","local_uid":"2026-08-23_hugo_grenier_mees_rottgering","bid":0.6,"ask":0.72,"mid":0.66,"spread":0.12,"price":0.61,"size":0.0,"side":"BUY"}
{"ts":"2026-08-23T17:52:37.460Z","event_type":"price_change","market_id":"3790397","outcome_index":0,"market_type":"set2","local_side":"home","local_uid":"2026-08-23_hugo_grenier_mees_rottgering","bid":0.28,"ask":0.4,"mid":0.34,"spread":0.12,"price":0.39,"size":0.0,"side":"SELL"}
{"ts":"2026-08-23T17:52:37.461Z","event_type":"best_bid_ask","market_id":"3790397","outcome_index":0,"market_type":"set2","local_side":"home","local_uid":"2026-08-23_hugo_grenier_mees_rottgering","bid":0.27,"ask":0.4,"mid":0.335,"spread":0.13,"bid_size":null,"ask_size":null}
{"ts":"2026-08-23T17:52:37.461Z","event_type":"best_bid_ask","market_id":"3790397","outcome_index":1,"market_type":"set2","local_side":"away","local_uid":"2026-08-23_hugo_grenier_mees_rottgering","bid":0.6,"ask":0.73,"mid":0.665,"spread":0.13,"bid_size":null,"ask_size":null}
{"ts":"2026-08-23T17:52:37.461Z","event_type":"price_change","market_id":"3790397","outcome_index":0,"market_type":"set2","local_side":"home","local_uid":"2026-08-23_hugo_grenier_mees_rottgering","bid":0.27,"ask":0.4,"mid":0.335,"spread":0.13,"price":0.28,"size":0.0,"side":"BUY"}
{"ts":"2026-08-23T17:52:37.461Z","event_type":"price_change","market_id":"3790397","outcome_index":1,"market_type":"set2","local_side":"away","local_uid":"2026-08-23_hugo_grenier_mees_rottgering","bid":0.6,"ask":0.73,"mid":0.665,"spread":0.13,"price":0.72,"size":0.0,"side":"SELL"}
{"ts":"2026-08-23T17:52:37.464Z","event_type":"new_market","market_id":"0xf37b9c59bf701ecbb28dd5edb3a536e2dd25540e0bf1b0dc83a8883180a28f9f"}
{"ts":"2026-08-23T17:52:37.511Z","event_type":"new_market","market_id":"0xc8e12af4b6022fad466335d42e21a8ac6f0a28d83c2c124cb09947cf117c7bf7"}
{"ts":"2026-08-23T17:52:37.511Z","event_type":"best_bid_ask","market_id":"3790397","outcome_index":0,"market_type":"set2","local_side":"home","local_uid":"2026-08-23_hugo_grenier_mees_rottgering","bid":0.27,"ask":0.39,"mid":0.33,"spread":0.12,"bid_size":null,"ask_size":null}
{"ts":"2026-08-23T17:52:37.511Z","event_type":"best_bid_ask","market_id":"3790397","outcome_index":1,"market_type":"set2","local_side":"away","local_uid":"2026-08-23_hugo_grenier_mees_rottgering","bid":0.61,"ask":0.73,"mid":0.67,"spread":0.12,"bid_size":null,"ask_size":null}
{"ts":"2026-08-23T17:52:37.511Z","event_type":"price_change","market_id":"3790397","outcome_index":1,"market_type":"set2","local_side":"away","local_uid":"2026-08-23_hugo_grenier_mees_rottgering","bid":0.61,"ask":0.73,"mid":0.67,"spread":0.12,"price":0.61,"size":150.0,"side":"BUY"}
{"ts":"2026-08-23T17:52:37.511Z","event_type":"price_change","market_id":"3790397","outcome_index":0,"market_type":"set2","local_side":"home","local_uid":"2026-08-23_hugo_grenier_mees_rottgering","bid":0.27,"ask":0.39,"mid":0.33,"spread":0.12,"price":0.39,"size":150.0,"side":"SELL"}
{"ts":"2026-08-23T17:52:37.511Z","event_type":"best_bid_ask","market_id":"3790397","outcome_index":0,"market_type":"set2","local_side":"home","local_uid":"2026-08-23_hugo_grenier_mees_rottgering","bid":0.32,"ask":0.39,"mid":0.355,"spread":0.07,"bid_size":null,"ask_size":null}
{"ts":"2026-08-23T17:52:37.512Z","event_type":"best_bid_ask","market_id":"3790397","outcome_index":1,"market_type":"set2","local_side":"away","local_uid":"2026-08-23_hugo_grenier_mees_rottgering","bid":0.61,"ask":0.68,"mid":0.645,"spread":0.07,"bid_size":null,"ask_size":null}
{"ts":"2026-08-23T17:52:37.512Z","event_type":"price_change","market_id":"3790397","outcome_index":0,"market_type":"set2","local_side":"home","local_uid":"2026-08-23_hugo_grenier_mees_rottgering","bid":0.32,"ask":0.39,"mid":0.355,"spread":0.07,"price":0.32,"size":150.0,"side":"BUY"}
{"ts":"2026-08-23T17:52:37.512Z","event_type":"price_change","market_id":"3790397","outcome_index":1,"market_type":"set2","local_side":"away","local_uid":"2026-08-23_hugo_grenier_mees_rottgering","bid":0.61,"ask":0.68,"mid":0.645,"spread":0.07,"price":0.68,"size":150.0,"side":"SELL"}
{"ts":"2026-08-23T17:52:37.616Z","event_type":"best_bid_ask","market_id":"3790394","outcome_index":0,"market_type":"set1","local_side":"home","local_uid":"2026-08-23_hugo_grenier_mees_rottgering","bid":0.19,"ask":0.26,"mid":0.225,"spread":0.07,"bid_size":null,"ask_size":null}
{"ts":"2026-08-23T17:52:37.617Z","event_type":"best_bid_ask","market_id":"3790394","outcome_index":1,"market_type":"set1","local_side":"away","local_uid":"2026-08-23_hugo_grenier_mees_rottgering","bid":0.74,"ask":0.81,"mid":0.775,"spread":0.07,"bid_size":null,"ask_size":null}
{"ts":"2026-08-23T17:52:37.617Z","event_type":"price_change","market_id":"3790394","outcome_index":1,"market_type":"set1","local_side":"away","local_uid":"2026-08-23_hugo_grenier_mees_rottgering","bid":0.74,"ask":0.81,"mid":0.775,"spread":0.07,"price":0.74,"size":1168.76,"side":"BUY"}
{"ts":"2026-08-23T17:52:37.617Z","event_type":"price_change","market_id":"3790394","outcome_index":0,"market_type":"set1","local_side":"home","local_uid":"2026-08-23_hugo_grenier_mees_rottgering","bid":0.19,"ask":0.26,"mid":0.225,"spread":0.07,"price":0.26,"size":1168.76,"side":"SELL"}
{"ts":"2026-08-23T17:52:37.617Z","event_type":"price_change","market_id":"3781392","outcome_index":1,"market_type":"set1","local_side":"away","local_uid":"2026-08-23_dino_prizmic_cruz_hewitt","bid":0.49,"ask":0.5,"mid":0.495,"spread":0.01,"price":0.49,"size":85161.03,"side":"BUY"}
{"ts":"2026-08-23T17:52:37.617Z","event_type":"price_change","market_id":"3781392","outcome_index":0,"market_type":"set1","local_side":"home","local_uid":"2026-08-23_dino_prizmic_cruz_hewitt","bid":0.5,"ask":0.51,"mid":0.505,"spread":0.01,"price":0.51,"size":85161.03,"side":"SELL"}
{"ts":"2026-08-23T17:52:37.617Z","event_type":"price_change","market_id":"3781395","outcome_index":1,"market_type":"set2","local_side":"away","local_uid":"2026-08-23_dino_prizmic_cruz_hewitt","bid":0.49,"ask":0.5,"mid":0.495,"spread":0.01,"price":0.49,"size":65298.49,"side":"BUY"}
{"ts":"2026-08-23T17:52:37.617Z","event_type":"price_change","market_id":"3781395","outcome_index":0,"market_type":"set2","local_side":"home","local_uid":"2026-08-23_dino_prizmic_cruz_hewitt","bid":0.5,"ask":0.51,"mid":0.505,"spread":0.01,"price":0.51,"size":65298.49,"side":"SELL"}
{"ts":"2026-08-23T17:52:37.618Z","event_type":"price_change","market_id":"3780824","outcome_index":1,"market_type":"match","local_side":"away","local_uid":"2026-08-23_dino_prizmic_cruz_hewitt","bid":0.49,"ask":0.5,"mid":0.495,"spread":0.01,"price":0.49,"size":286059.99,"side":"BUY"}
{"ts":"2026-08-23T17:52:37.618Z","event_type":"price_change","market_id":"3780824","outcome_index":0,"market_type":"match","local_side":"home","local_uid":"2026-08-23_dino_prizmic_cruz_hewitt","bid":0.5,"ask":0.51,"mid":0.505,"spread":0.01,"price":0.51,"size":286059.99,"side":"SELL"}
{"ts":"2026-08-23T17:52:37.618Z","event_type":"price_change","market_id":"3795956","outcome_index":0,"market_type":"match","local_side":"home","local_uid":"2026-08-23_evan_zhu_arthur_reymond","bid":0.5,"ask":0.51,"mid":0.505,"spread":0.01,"price":0.49,"size":46337.6,"side":"BUY"}
{"ts":"2026-08-23T17:52:37.618Z","event_type":"price_change","market_id":"3795956","outcome_index":1,"market_type":"match","local_side":"away","local_uid":"2026-08-23_evan_zhu_arthur_reymond","bid":0.49,"ask":0.5,"mid":0.495,"spread":0.01,"price":0.51,"size":46337.6,"side":"SELL"}
{"ts":"2026-08-23T17:52:37.723Z","event_type":"best_bid_ask","market_id":"3790397","outcome_index":0,"market_type":"set2","local_side":"home","local_uid":"2026-08-23_hugo_grenier_mees_rottgering","bid":0.29,"ask":0.39,"mid":0.34,"spread":0.1,"bid_size":null,"ask_size":null}
{"ts":"2026-08-23T17:52:37.723Z","event_type":"best_bid_ask","market_id":"3790397","outcome_index":1,"market_type":"set2","local_side":"away","local_uid":"2026-08-23_hugo_grenier_mees_rottgering","bid":0.61,"ask":0.71,"mid":0.66,"spread":0.1,"bid_size":null,"ask_size":null}
{"ts":"2026-08-23T17:52:37.724Z","event_type":"price_change","market_id":"3790397","outcome_index":0,"market_type":"set2","local_side":"home","local_uid":"2026-08-23_hugo_grenier_mees_rottgering","bid":0.29,"ask":0.39,"mid":0.34,"spread":0.1,"price":0.32,"size":0.0,"side":"BUY"}
{"ts":"2026-08-23T17:52:37.724Z","event_type":"price_change","market_id":"3790397","outcome_index":1,"market_type":"set2","local_side":"away","local_uid":"2026-08-23_hugo_grenier_mees_rottgering","bid":0.61,"ask":0.71,"mid":0.66,"spread":0.1,"price":0.68,"size":0.0,"side":"SELL"}
{"ts":"2026-08-23T17:52:37.724Z","event_type":"best_bid_ask","market_id":"3790397","outcome_index":0,"market_type":"set2","local_side":"home","local_uid":"2026-08-23_hugo_grenier_mees_rottgering","bid":0.27,"ask":0.39,"mid":0.33,"spread":0.12,"bid_size":null,"ask_size":null}
{"ts":"2026-08-23T17:52:37.776Z","event_type":"best_bid_ask","market_id":"3790397","outcome_index":1,"market_type":"set2","local_side":"away","local_uid":"2026-08-23_hugo_grenier_mees_rottgering","bid":0.61,"ask":0.73,"mid":0.67,"spread":0.12,"bid_size":null,"ask_size":null}
{"ts":"2026-08-23T17:52:37.776Z","event_type":"price_change","market_id":"3790397","outcome_index":0,"market_type":"set2","local_side":"home","local_uid":"2026-08-23_hugo_grenier_mees_rottgering","bid":0.27,"ask":0.39,"mid":0.33,"spread":0.12,"price":0.29,"size":0.0,"side":"BUY"}
{"ts":"2026-08-23T17:52:37.776Z","event_type":"price_change","market_id":"3790397","outcome_index":1,"market_type":"set2","local_side":"away","local_uid":"2026-08-23_hugo_grenier_mees_rottgering","bid":0.61,"ask":0.73,"mid":0.67,"spread":0.12,"price":0.71,"size":0.0,"side":"SELL"}
{"ts":"2026-08-23T17:52:37.783Z","event_type":"best_bid_ask","market_id":"3790397","outcome_index":0,"market_type":"set2","local_side":"home","local_uid":"2026-08-23_hugo_grenier_mees_rottgering","bid":0.26,"ask":0.39,"mid":0.325,"spread":0.13,"bid_size":null,"ask_size":null}
{"ts":"2026-08-23T17:52:37.783Z","event_type":"best_bid_ask","market_id":"3790397","outcome_index":1,"market_type":"set2","local_side":"away","local_uid":"2026-08-23_hugo_grenier_mees_rottgering","bid":0.61,"ask":0.74,"mid":0.675,"spread":0.13,"bid_size":null,"ask_size":null}
{"ts":"2026-08-23T17:52:37.783Z","event_type":"price_change","market_id":"3790397","outcome_index":0,"market_type":"set2","local_side":"home","local_uid":"2026-08-23_hugo_grenier_mees_rottgering","bid":0.26,"ask":0.39,"mid":0.325,"spread":0.13,"price":0.27,"size":0.0,"side":"BUY"}
{"ts":"2026-08-23T17:52:37.783Z","event_type":"price_change","market_id":"3790397","outcome_index":1,"market_type":"set2","local_side":"away","local_uid":"2026-08-23_hugo_grenier_mees_rottgering","bid":0.61,"ask":0.74,"mid":0.675,"spread":0.13,"price":0.73,"size":0.0,"side":"SELL"}
{"ts":"2026-08-23T17:52:37.783Z","event_type":"best_bid_ask","market_id":"3790397","outcome_index":0,"market_type":"set2","local_side":"home","local_uid":"2026-08-23_hugo_grenier_mees_rottgering","bid":0.28,"ask":0.39,"mid":0.335,"spread":0.11,"bid_size":null,"ask_size":null}
{"ts":"2026-08-23T17:52:37.824Z","event_type":"best_bid_ask","market_id":"3790397","outcome_index":1,"market_type":"set2","local_side":"away","local_uid":"2026-08-23_hugo_grenier_mees_rottgering","bid":0.61,"ask":0.72,"mid":0.665,"spread":0.11,"bid_size":null,"ask_size":null}
{"ts":"2026-08-23T17:52:37.824Z","event_type":"price_change","market_id":"3790397","outcome_index":0,"market_type":"set2","local_side":"home","local_uid":"2026-08-23_hugo_grenier_mees_rottgering","bid":0.28,"ask":0.39,"mid":0.335,"spread":0.11,"price":0.28,"size":150.0,"side":"BUY"}
{"ts":"2026-08-23T17:52:37.824Z","event_type":"price_change","market_id":"3790397","outcome_index":1,"market_type":"set2","local_side":"away","local_uid":"2026-08-23_hugo_grenier_mees_rottgering","bid":0.61,"ask":0.72,"mid":0.665,"spread":0.11,"price":0.72,"size":150.0,"side":"SELL"}
{"ts":"2026-08-23T17:52:37.832Z","event_type":"best_bid_ask","market_id":"3790394","outcome_index":0,"market_type":"set1","local_side":"home","local_uid":"2026-08-23_hugo_grenier_mees_rottgering","bid":0.19,"ask":0.25,"mid":0.22,"spread":0.06,"bid_size":null,"ask_size":null}
{"ts":"2026-08-23T17:52:37.832Z","event_type":"best_bid_ask","market_id":"3790394","outcome_index":1,"market_type":"set1","local_side":"away","local_uid":"2026-08-23_hugo_grenier_mees_rottgering","bid":0.75,"ask":0.81,"mid":0.78,"spread":0.06,"bid_size":null,"ask_size":null}
{"ts":"2026-08-23T17:52:37.833Z","event_type":"price_change","market_id":"3790394","outcome_index":1,"market_type":"set1","local_side":"away","local_uid":"2026-08-23_hugo_grenier_mees_rottgering","bid":0.75,"ask":0.81,"mid":0.78,"spread":0.06,"price":0.75,"size":150.0,"side":"BUY"}
{"ts":"2026-08-23T17:52:37.833Z","event_type":"price_change","market_id":"3790394","outcome_index":0,"market_type":"set1","local_side":"home","local_uid":"2026-08-23_hugo_grenier_mees_rottgering","bid":0.19,"ask":0.25,"mid":0.22,"spread":0.06,"price":0.25,"size":150.0,"side":"SELL"}
{"ts":"2026-08-23T17:52:38.308Z","event_type":"best_bid_ask","market_id":"3790415","outcome_index":0,"market_type":"set2","local_side":"home","local_uid":"2026-08-23_pierre_hugues_herbert_quinn_vandecasteele","bid":0.62,"ask":0.76,"mid":0.69,"spread":0.14,"bid_size":null,"ask_size":null}
{"ts":"2026-08-23T17:52:38.308Z","event_type":"best_bid_ask","market_id":"3790415","outcome_index":1,"market_type":"set2","local_side":"away","local_uid":"2026-08-23_pierre_hugues_herbert_quinn_vandecasteele","bid":0.24,"ask":0.38,"mid":0.31,"spread":0.14,"bid_size":null,"ask_size":null}
{"ts":"2026-08-23T17:52:38.309Z","event_type":"price_change","market_id":"3790415","outcome_index":0,"market_type":"set2","local_side":"home","local_uid":"2026-08-23_pierre_hugues_herbert_quinn_vandecasteele","bid":0.62,"ask":0.76,"mid":0.69,"spread":0.14,"price":0.62,"size":423.0,"side":"BUY"}
{"ts":"2026-08-23T17:52:38.309Z","event_type":"price_change","market_id":"3790415","outcome_index":1,"market_type":"set2","local_side":"away","local_uid":"2026-08-23_pierre_hugues_herbert_quinn_vandecasteele","bid":0.24,"ask":0.38,"mid":0.31,"spread":0.14,"price":0.38,"size":423.0,"side":"SELL"}
{"ts":"2026-08-23T17:52:38.309Z","event_type":"best_bid_ask","market_id":"3790415","outcome_index":0,"market_type":"set2","local_side":"home","local_uid":"2026-08-23_pierre_hugues_herbert_quinn_vandecasteele","bid":0.63,"ask":0.76,"mid":0.695,"spread":0.13,"bid_size":null,"ask_size":null}
{"ts":"2026-08-23T17:52:38.309Z","event_type":"best_bid_ask","market_id":"3790415","outcome_index":1,"market_type":"set2","local_side":"away","local_uid":"2026-08-23_pierre_hugues_herbert_quinn_vandecasteele","bid":0.24,"ask":0.37,"mid":0.305,"spread":0.13,"bid_size":null,"ask_size":null}
{"ts":"2026-08-23T17:52:38.309Z","event_type":"price_change","market_id":"3790415","outcome_index":0,"market_type":"set2","local_side":"home","local_uid":"2026-08-23_pierre_hugues_herbert_quinn_vandecasteele","bid":0.63,"ask":0.76,"mid":0.695,"spread":0.13,"price":0.63,"size":88.0,"side":"BUY"}
{"ts":"2026-08-23T17:52:38.309Z","event_type":"price_change","market_id":"3790415","outcome_index":1,"market_type":"set2","local_side":"away","local_uid":"2026-08-23_pierre_hugues_herbert_quinn_vandecasteele","bid":0.24,"ask":0.37,"mid":0.305,"spread":0.13,"price":0.37,"size":88.0,"side":"SELL"}
{"ts":"2026-08-23T17:52:38.364Z","event_type":"best_bid_ask","market_id":"3790415","outcome_index":0,"market_type":"set2","local_side":"home","local_uid":"2026-08-23_pierre_hugues_herbert_quinn_vandecasteele","bid":0.63,"ask":0.78,"mid":0.705,"spread":0.15,"bid_size":null,"ask_size":null}
{"ts":"2026-08-23T17:52:38.365Z","event_type":"best_bid_ask","market_id":"3790415","outcome_index":1,"market_type":"set2","local_side":"away","local_uid":"2026-08-23_pierre_hugues_herbert_quinn_vandecasteele","bid":0.22,"ask":0.37,"mid":0.295,"spread":0.15,"bid_size":null,"ask_size":null}
{"ts":"2026-08-23T17:52:38.365Z","event_type":"price_change","market_id":"3790415","outcome_index":1,"market_type":"set2","local_side":"away","local_uid":"2026-08-23_pierre_hugues_herbert_quinn_vandecasteele","bid":0.22,"ask":0.37,"mid":0.295,"spread":0.15,"price":0.24,"size":0.0,"side":"BUY"}
{"ts":"2026-08-23T17:52:38.365Z","event_type":"price_change","market_id":"3790415","outcome_index":0,"market_type":"set2","local_side":"home","local_uid":"2026-08-23_pierre_hugues_herbert_quinn_vandecasteele","bid":0.63,"ask":0.78,"mid":0.705,"spread":0.15,"price":0.76,"size":0.0,"side":"SELL"}
{"ts":"2026-08-23T17:52:38.470Z","event_type":"best_bid_ask","market_id":"3790415","outcome_index":0,"market_type":"set2","local_side":"home","local_uid":"2026-08-23_pierre_hugues_herbert_quinn_vandecasteele","bid":0.63,"ask":0.77,"mid":0.7,"spread":0.14,"bid_size":null,"ask_size":null}
{"ts":"2026-08-23T17:52:38.470Z","event_type":"best_bid_ask","market_id":"3790415","outcome_index":1,"market_type":"set2","local_side":"away","local_uid":"2026-08-23_pierre_hugues_herbert_quinn_vandecasteele","bid":0.23,"ask":0.37,"mid":0.3,"spread":0.14,"bid_size":null,"ask_size":null}
{"ts":"2026-08-23T17:52:38.470Z","event_type":"price_change","market_id":"3790415","outcome_index":1,"market_type":"set2","local_side":"away","local_uid":"2026-08-23_pierre_hugues_herbert_quinn_vandecasteele","bid":0.23,"ask":0.37,"mid":0.3,"spread":0.14,"price":0.23,"size":150.0,"side":"BUY"}
{"ts":"2026-08-23T17:52:38.470Z","event_type":"price_change","market_id":"3790415","outcome_index":0,"market_type":"set2","local_side":"home","local_uid":"2026-08-23_pierre_hugues_herbert_quinn_vandecasteele","bid":0.63,"ask":0.77,"mid":0.7,"spread":0.14,"price":0.77,"size":150.0,"side":"SELL"}
{"ts":"2026-08-23T17:52:38.579Z","event_type":"best_bid_ask","market_id":"3790415","outcome_index":0,"market_type":"set2","local_side":"home","local_uid":"2026-08-23_pierre_hugues_herbert_quinn_vandecasteele","bid":0.64,"ask":0.77,"mid":0.705,"spread":0.13,"bid_size":null,"ask_size":null}
{"ts":"2026-08-23T17:52:38.579Z","event_type":"best_bid_ask","market_id":"3790415","outcome_index":1,"market_type":"set2","local_side":"away","local_uid":"2026-08-23_pierre_hugues_herbert_quinn_vandecasteele","bid":0.23,"ask":0.36,"mid":0.295,"spread":0.13,"bid_size":null,"ask_size":null}
{"ts":"2026-08-23T17:52:38.579Z","event_type":"price_change","market_id":"3790415","outcome_index":0,"market_type":"set2","local_side":"home","local_uid":"2026-08-23_pierre_hugues_herbert_quinn_vandecasteele","bid":0.64,"ask":0.77,"mid":0.705,"spread":0.13,"price":0.64,"size":150.0,"side":"BUY"}
{"ts":"2026-08-23T17:52:38.579Z","event_type":"price_change","market_id":"3790415","outcome_index":1,"market_type":"set2","local_side":"away","local_uid":"2026-08-23_pierre_hugues_herbert_quinn_vandecasteele","bid":0.23,"ask":0.36,"mid":0.295,"spread":0.13,"price":0.36,"size":150.0,"side":"SELL"}
{"ts":"2026-08-23T17:52:38.579Z","event_type":"best_bid_ask","market_id":"3790415","outcome_index":0,"market_type":"set2","local_side":"home","local_uid":"2026-08-23_pierre_hugues_herbert_quinn_vandecasteele","bid":0.65,"ask":0.77,"mid":0.71,"spread":0.12,"bid_size":null,"ask_size":null}
{"ts":"2026-08-23T17:52:38.580Z","event_type":"best_bid_ask","market_id":"3790415","outcome_index":1,"market_type":"set2","local_side":"away","local_uid":"2026-08-23_pierre_hugues_herbert_quinn_vandecasteele","bid":0.23,"ask":0.35,"mid":0.29,"spread":0.12,"bid_size":null,"ask_size":null}
{"ts":"2026-08-23T17:52:38.580Z","event_type":"price_change","market_id":"3790415","outcome_index":0,"market_type":"set2","local_side":"home","local_uid":"2026-08-23_pierre_hugues_herbert_quinn_vandecasteele","bid":0.65,"ask":0.77,"mid":0.71,"spread":0.12,"price":0.65,"size":150.0,"side":"BUY"}
{"ts":"2026-08-23T17:52:38.580Z","event_type":"price_change","market_id":"3790415","outcome_index":1,"market_type":"set2","local_side":"away","local_uid":"2026-08-23_pierre_hugues_herbert_quinn_vandecasteele","bid":0.23,"ask":0.35,"mid":0.29,"spread":0.12,"price":0.35,"size":150.0,"side":"SELL"}
{"ts":"2026-08-23T17:52:38.580Z","event_type":"best_bid_ask","market_id":"3790415","outcome_index":0,"market_type":"set2","local_side":"home","local_uid":"2026-08-23_pierre_hugues_herbert_quinn_vandecasteele","bid":0.65,"ask":0.76,"mid":0.705,"spread":0.11,"bid_size":null,"ask_size":null}
{"ts":"2026-08-23T17:52:38.581Z","event_type":"best_bid_ask","market_id":"3790415","outcome_index":1,"market_type":"set2","local_side":"away","local_uid":"2026-08-23_pierre_hugues_herbert_quinn_vandecasteele","bid":0.24,"ask":0.35,"mid":0.295,"spread":0.11,"bid_size":null,"ask_size":null}
{"ts":"2026-08-23T17:52:38.581Z","event_type":"price_change","market_id":"3790415","outcome_index":1,"market_type":"set2","local_side":"away","local_uid":"2026-08-23_pierre_hugues_herbert_quinn_vandecasteele","bid":0.24,"ask":0.35,"mid":0.295,"spread":0.11,"price":0.24,"size":31.25,"side":"BUY"}
{"ts":"2026-08-23T17:52:38.581Z","event_type":"price_change","market_id":"3790415","outcome_index":0,"market_type":"set2","local_side":"home","local_uid":"2026-08-23_pierre_hugues_herbert_quinn_vandecasteele","bid":0.65,"ask":0.76,"mid":0.705,"spread":0.11,"price":0.76,"size":31.25,"side":"SELL"}
{"ts":"2026-08-23T17:52:39.002Z","event_type":"new_market","market_id":"0x0109a52d371c7942fa693241828f2a76a37fe703f41a9c31dc942f9eb3c5b2dd"}
{"ts":"2026-08-23T17:52:39.062Z","event_type":"new_market","market_id":"0xfe9727deb4f15937bdc39a6152b241dca32e79d38c7f579cb8f7e2fb81fc3f82"}
{"ts":"2026-08-23T17:52:39.063Z","event_type":"new_market","market_id":"0x564cf92d44c3f8f4e9c5ea4949a6ad79bc65aec584875c191e527c71b1ced131"}
{"ts":"2026-08-23T17:52:39.106Z","event_type":"new_market","market_id":"0xdee53746251c28ec62e835d24f52a520777ae11729a3d0105ded195ea9e245bf"}
{"ts":"2026-08-23T17:52:39.275Z","event_type":"last_trade_price","market_id":"3789931","outcome_index":0,"market_type":"match","local_side":"home","local_uid":"2026-08-23_stefanos_sakellaridis_luca_van_assche","last_trade":0.07,"trade_size":15.3,"trade_side":"BUY","trade_notional":1.071}
{"ts":"2026-08-23T17:52:39.382Z","event_type":"new_market","market_id":"0x37a2f5cf0a4d7631e811675e35fe87f71aa96a2f9e28cfe2ea1fbb8fe5e533dd"}
{"ts":"2026-08-23T17:52:39.382Z","event_type":"new_market","market_id":"0x7bd09943d9da08a734fe50ea5c80d53c4fc48db2639d7d99f8aa916456e46521"}
{"ts":"2026-08-23T17:52:39.431Z","event_type":"new_market","market_id":"0x1f6d7e5bcc5483b4ad5e9cbe743c47d7e73fc38a1a91f237e643b95a86872229"}
{"ts":"2026-08-23T17:52:39.432Z","event_type":"new_market","market_id":"0x52529470663f370738968d133125059f91852cbb7d8062ab2a491237c7d764a7"}
{"ts":"2026-08-23T17:52:39.432Z","event_type":"new_market","market_id":"0xd8187305f2cb2e0504655f620532631f49869885c1630ac05d9c07293e6106fd"}
{"ts":"2026-08-23T17:52:39.488Z","event_type":"new_market","market_id":"0xd5edd20a1732970cac02774fed843ec092c9f4e4fc9b8048944dc9f508f06eaf"}
{"ts":"2026-08-23T17:52:39.746Z","event_type":"best_bid_ask","market_id":"3790394","outcome_index":0,"market_type":"set1","local_side":"home","local_uid":"2026-08-23_hugo_grenier_mees_rottgering","bid":0.16,"ask":0.25,"mid":0.205,"spread":0.09,"bid_size":null,"ask_size":null}
{"ts":"2026-08-23T17:52:39.746Z","event_type":"best_bid_ask","market_id":"3790394","outcome_index":1,"market_type":"set1","local_side":"away","local_uid":"2026-08-23_hugo_grenier_mees_rottgering","bid":0.75,"ask":0.84,"mid":0.795,"spread":0.09,"bid_size":null,"ask_size":null}
{"ts":"2026-08-23T17:52:39.749Z","event_type":"price_change","market_id":"3790394","outcome_index":0,"market_type":"set1","local_side":"home","local_uid":"2026-08-23_hugo_grenier_mees_rottgering","bid":0.16,"ask":0.25,"mid":0.205,"spread":0.09,"price":0.19,"size":0.0,"side":"BUY"}
{"ts":"2026-08-23T17:52:39.749Z","event_type":"price_change","market_id":"3790394","outcome_index":1,"market_type":"set1","local_side":"away","local_uid":"2026-08-23_hugo_grenier_mees_rottgering","bid":0.75,"ask":0.84,"mid":0.795,"spread":0.09,"price":0.81,"size":0.0,"side":"SELL"}
{"ts":"2026-08-23T17:52:39.750Z","event_type":"best_bid_ask","market_id":"3790415","outcome_index":0,"market_type":"set2","local_side":"home","local_uid":"2026-08-23_pierre_hugues_herbert_quinn_vandecasteele","bid":0.65,"ask":0.77,"mid":0.71,"spread":0.12,"bid_size":null,"ask_size":null}
{"ts":"2026-08-23T17:52:39.750Z","event_type":"best_bid_ask","market_id":"3790415","outcome_index":1,"market_type":"set2","local_side":"away","local_uid":"2026-08-23_pierre_hugues_herbert_quinn_vandecasteele","bid":0.23,"ask":0.35,"mid":0.29,"spread":0.12,"bid_size":null,"ask_size":null}
{"ts":"2026-08-23T17:52:39.750Z","event_type":"price_change","market_id":"3790415","outcome_index":1,"market_type":"set2","local_side":"away","local_uid":"2026-08-23_pierre_hugues_herbert_quinn_vandecasteele","bid":0.23,"ask":0.35,"mid":0.29,"spread":0.12,"price":0.24,"size":0.0,"side":"BUY"}
{"ts":"2026-08-23T17:52:39.750Z","event_type":"price_change","market_id":"3790415","outcome_index":0,"market_type":"set2","local_side":"home","local_uid":"2026-08-23_pierre_hugues_herbert_quinn_vandecasteele","bid":0.65,"ask":0.77,"mid":0.71,"spread":0.12,"price":0.76,"size":0.0,"side":"SELL"}
{"ts":"2026-08-23T17:52:39.807Z","event_type":"best_bid_ask","market_id":"3790415","outcome_index":0,"market_type":"set2","local_side":"home","local_uid":"2026-08-23_pierre_hugues_herbert_quinn_vandecasteele","bid":0.65,"ask":0.76,"mid":0.705,"spread":0.11,"bid_size":null,"ask_size":null}
{"ts":"2026-08-23T17:52:39.807Z","event_type":"best_bid_ask","market_id":"3790415","outcome_index":1,"market_type":"set2","local_side":"away","local_uid":"2026-08-23_pierre_hugues_herbert_quinn_vandecasteele","bid":0.24,"ask":0.35,"mid":0.295,"spread":0.11,"bid_size":null,"ask_size":null}
{"ts":"2026-08-23T17:52:39.807Z","event_type":"price_change","market_id":"3790415","outcome_index":1,"market_type":"set2","local_side":"away","local_uid":"2026-08-23_pierre_hugues_herbert_quinn_vandecasteele","bid":0.24,"ask":0.35,"mid":0.295,"spread":0.11,"price":0.24,"size":115.25,"side":"BUY"}
{"ts":"2026-08-23T17:52:39.807Z","event_type":"price_change","market_id":"3790415","outcome_index":0,"market_type":"set2","local_side":"home","local_uid":"2026-08-23_pierre_hugues_herbert_quinn_vandecasteele","bid":0.65,"ask":0.76,"mid":0.705,"spread":0.11,"price":0.76,"size":115.25,"side":"SELL"}
{"ts":"2026-08-23T17:52:39.915Z","event_type":"book","market_id":"3789927","outcome_index":0,"market_type":"match","local_side":"home","local_uid":"2026-08-23_hugo_grenier_mees_rottgering","bid":0.23,"ask":0.24,"mid":0.235,"spread":0.01,"bid_size":810.0,"ask_size":16205.76}
{"ts":"2026-08-23T17:52:39.915Z","event_type":"book","market_id":"3789927","outcome_index":1,"market_type":"match","local_side":"away","local_uid":"2026-08-23_hugo_grenier_mees_rottgering","bid":0.76,"ask":0.77,"mid":0.765,"spread":0.01,"bid_size":16205.76,"ask_size":810.0}
{"ts":"2026-08-23T17:52:39.915Z","event_type":"price_change","market_id":"3792971","outcome_index":0,"market_type":"match","local_side":"home","local_uid":"2026-08-23_maria_timofeeva_kamilla_rakhimova","bid":0.39,"ask":0.4,"mid":0.395,"spread":0.01,"price":0.38,"size":20033.02,"side":"BUY"}
{"ts":"2026-08-23T17:52:39.915Z","event_type":"price_change","market_id":"3792971","outcome_index":1,"market_type":"match","local_side":"away","local_uid":"2026-08-23_maria_timofeeva_kamilla_rakhimova","bid":0.6,"ask":0.61,"mid":0.605,"spread":0.01,"price":0.62,"size":20033.02,"side":"SELL"}
{"ts":"2026-08-23T17:52:39.962Z","event_type":"last_trade_price","market_id":"3789929","outcome_index":0,"market_type":"match","local_side":"home","local_uid":"2026-08-23_felix_balshaw_sebastian_gorzny","last_trade":0.32,"trade_size":5.0,"trade_side":"BUY","trade_notional":1.6}
{"ts":"2026-08-23T17:52:39.963Z","event_type":"last_trade_price","market_id":"3789927","outcome_index":1,"market_type":"match","local_side":"away","local_uid":"2026-08-23_hugo_grenier_mees_rottgering","last_trade":0.77,"trade_size":2.5195,"trade_side":"BUY","trade_notional":1.94}
{"ts":"2026-08-23T17:52:40.167Z","event_type":"best_bid_ask","market_id":"3790415","outcome_index":0,"market_type":"set2","local_side":"home","local_uid":"2026-08-23_pierre_hugues_herbert_quinn_vandecasteele","bid":0.65,"ask":0.77,"mid":0.71,"spread":0.12,"bid_size":null,"ask_size":null}
{"ts":"2026-08-23T17:52:40.169Z","event_type":"best_bid_ask","market_id":"3790415","outcome_index":1,"market_type":"set2","local_side":"away","local_uid":"2026-08-23_pierre_hugues_herbert_quinn_vandecasteele","bid":0.23,"ask":0.35,"mid":0.29,"spread":0.12,"bid_size":null,"ask_size":null}
{"ts":"2026-08-23T17:52:40.169Z","event_type":"price_change","market_id":"3790415","outcome_index":1,"market_type":"set2","local_side":"away","local_uid":"2026-08-23_pierre_hugues_herbert_quinn_vandecasteele","bid":0.23,"ask":0.35,"mid":0.29,"spread":0.12,"price":0.24,"size":0.0,"side":"BUY"}
{"ts":"2026-08-23T17:52:40.169Z","event_type":"price_change","market_id":"3790415","outcome_index":0,"market_type":"set2","local_side":"home","local_uid":"2026-08-23_pierre_hugues_herbert_quinn_vandecasteele","bid":0.65,"ask":0.77,"mid":0.71,"spread":0.12,"price":0.76,"size":0.0,"side":"SELL"}
{"ts":"2026-08-23T17:52:40.233Z","event_type":"best_bid_ask","market_id":"3790415","outcome_index":0,"market_type":"set2","local_side":"home","local_uid":"2026-08-23_pierre_hugues_herbert_quinn_vandecasteele","bid":0.65,"ask":0.76,"mid":0.705,"spread":0.11,"bid_size":null,"ask_size":null}
{"ts":"2026-08-23T17:52:40.234Z","event_type":"best_bid_ask","market_id":"3790415","outcome_index":1,"market_type":"set2","local_side":"away","local_uid":"2026-08-23_pierre_hugues_herbert_quinn_vandecasteele","bid":0.24,"ask":0.35,"mid":0.295,"spread":0.11,"bid_size":null,"ask_size":null}
{"ts":"2026-08-23T17:52:40.234Z","event_type":"price_change","market_id":"3790415","outcome_index":1,"market_type":"set2","local_side":"away","local_uid":"2026-08-23_pierre_hugues_herbert_quinn_vandecasteele","bid":0.24,"ask":0.35,"mid":0.295,"spread":0.11,"price":0.24,"size":65.37,"side":"BUY"}
{"ts":"2026-08-23T17:52:40.234Z","event_type":"price_change","market_id":"3790415","outcome_index":0,"market_type":"set2","local_side":"home","local_uid":"2026-08-23_pierre_hugues_herbert_quinn_vandecasteele","bid":0.65,"ask":0.76,"mid":0.705,"spread":0.11,"price":0.76,"size":65.37,"side":"SELL"}
{"ts":"2026-08-23T17:52:40.281Z","event_type":"new_market","market_id":"0x81f6cbe32fdebb3b8056d6388557a32361508377560056522f9aaf823468b995"}
{"ts":"2026-08-23T17:52:40.873Z","event_type":"new_market","market_id":"0x5482406e28bba707ee34b7615040e0ecd8204586a540e0f6fd372cbb86e26a37"}
{"ts":"2026-08-23T17:52:40.874Z","event_type":"new_market","market_id":"0x0f8cc733384ad320d44c239b7d5f11aabe14ba80ae469adc9c253801247eb5d8"}
{"ts":"2026-08-23T17:52:40.874Z","event_type":"best_bid_ask","market_id":"3790415","outcome_index":0,"market_type":"set2","local_side":"home","local_uid":"2026-08-23_pierre_hugues_herbert_quinn_vandecasteele","bid":0.65,"ask":0.77,"mid":0.71,"spread":0.12,"bid_size":null,"ask_size":null}
{"ts":"2026-08-23T17:52:40.875Z","event_type":"best_bid_ask","market_id":"3790415","outcome_index":1,"market_type":"set2","local_side":"away","local_uid":"2026-08-23_pierre_hugues_herbert_quinn_vandecasteele","bid":0.23,"ask":0.35,"mid":0.29,"spread":0.12,"bid_size":null,"ask_size":null}
{"ts":"2026-08-23T17:52:40.916Z","event_type":"price_change","market_id":"3790415","outcome_index":1,"market_type":"set2","local_side":"away","local_uid":"2026-08-23_pierre_hugues_herbert_quinn_vandecasteele","bid":0.23,"ask":0.35,"mid":0.29,"spread":0.12,"price":0.24,"size":0.0,"side":"BUY"}
{"ts":"2026-08-23T17:52:40.917Z","event_type":"price_change","market_id":"3790415","outcome_index":0,"market_type":"set2","local_side":"home","local_uid":"2026-08-23_pierre_hugues_herbert_quinn_vandecasteele","bid":0.65,"ask":0.77,"mid":0.71,"spread":0.12,"price":0.76,"size":0.0,"side":"SELL"}
{"ts":"2026-08-23T17:52:40.917Z","event_type":"best_bid_ask","market_id":"3790415","outcome_index":0,"market_type":"set2","local_side":"home","local_uid":"2026-08-23_pierre_hugues_herbert_quinn_vandecasteele","bid":0.66,"ask":0.77,"mid":0.715,"spread":0.11,"bid_size":null,"ask_size":null}
{"ts":"2026-08-23T17:52:40.917Z","event_type":"best_bid_ask","market_id":"3790415","outcome_index":1,"market_type":"set2","local_side":"away","local_uid":"2026-08-23_pierre_hugues_herbert_quinn_vandecasteele","bid":0.23,"ask":0.34,"mid":0.285,"spread":0.11,"bid_size":null,"ask_size":null}
{"ts":"2026-08-23T17:52:40.917Z","event_type":"price_change","market_id":"3790415","outcome_index":0,"market_type":"set2","local_side":"home","local_uid":"2026-08-23_pierre_hugues_herbert_quinn_vandecasteele","bid":0.66,"ask":0.77,"mid":0.715,"spread":0.11,"price":0.66,"size":150.0,"side":"BUY"}
{"ts":"2026-08-23T17:52:40.917Z","event_type":"price_change","market_id":"3790415","outcome_index":1,"market_type":"set2","local_side":"away","local_uid":"2026-08-23_pierre_hugues_herbert_quinn_vandecasteele","bid":0.23,"ask":0.34,"mid":0.285,"spread":0.11,"price":0.34,"size":150.0,"side":"SELL"}
{"ts":"2026-08-23T17:52:40.918Z","event_type":"best_bid_ask","market_id":"3795958","outcome_index":0,"market_type":"match","local_side":"home","local_uid":"2026-08-23_bruno_kuzuhara_kody_pearson","bid":0.961,"ask":0.967,"mid":0.964,"spread":0.006,"bid_size":null,"ask_size":null}
{"ts":"2026-08-23T17:52:40.918Z","event_type":"best_bid_ask","market_id":"3795958","outcome_index":1,"market_type":"match","local_side":"away","local_uid":"2026-08-23_bruno_kuzuhara_kody_pearson","bid":0.033,"ask":0.039,"mid":0.036,"spread":0.006,"bid_size":null,"ask_size":null}
{"ts":"2026-08-23T17:52:40.918Z","event_type":"best_bid_ask","market_id":"3790415","outcome_index":0,"market_type":"set2","local_side":"home","local_uid":"2026-08-23_pierre_hugues_herbert_quinn_vandecasteele","bid":0.66,"ask":0.76,"mid":0.71,"spread":0.1,"bid_size":null,"ask_size":null}
{"ts":"2026-08-23T17:52:40.918Z","event_type":"best_bid_ask","market_id":"3790415","outcome_index":1,"market_type":"set2","local_side":"away","local_uid":"2026-08-23_pierre_hugues_herbert_quinn_vandecasteele","bid":0.24,"ask":0.34,"mid":0.29,"spread":0.1,"bid_size":null,"ask_size":null}
{"ts":"2026-08-23T17:52:40.979Z","event_type":"price_change","market_id":"3795958","outcome_index":1,"market_type":"match","local_side":"away","local_uid":"2026-08-23_bruno_kuzuhara_kody_pearson","bid":0.033,"ask":0.039,"mid":0.036,"spread":0.006,"price":0.033,"size":303.03,"side":"BUY"}
{"ts":"2026-08-23T17:52:40.979Z","event_type":"price_change","market_id":"3795958","outcome_index":0,"market_type":"match","local_side":"home","local_uid":"2026-08-23_bruno_kuzuhara_kody_pearson","bid":0.961,"ask":0.967,"mid":0.964,"spread":0.006,"price":0.967,"size":303.03,"side":"SELL"}
{"ts":"2026-08-23T17:52:40.980Z","event_type":"price_change","market_id":"3790415","outcome_index":1,"market_type":"set2","local_side":"away","local_uid":"2026-08-23_pierre_hugues_herbert_quinn_vandecasteele","bid":0.24,"ask":0.34,"mid":0.29,"spread":0.1,"price":0.24,"size":150.0,"side":"BUY"}
{"ts":"2026-08-23T17:52:40.980Z","event_type":"price_change","market_id":"3790415","outcome_index":0,"market_type":"set2","local_side":"home","local_uid":"2026-08-23_pierre_hugues_herbert_quinn_vandecasteele","bid":0.66,"ask":0.76,"mid":0.71,"spread":0.1,"price":0.76,"size":150.0,"side":"SELL"}
{"ts":"2026-08-23T17:52:41.087Z","event_type":"new_market","market_id":"0x1e1f1c517ef763bcf536c65eaa4860ca3fe69202625ad2e7f7200572f9b944cf"}
{"ts":"2026-08-23T17:52:41.087Z","event_type":"new_market","market_id":"0xaf6ed8628d377aba1aea80eb6bcb288b14f7ed2c56e9cb49da48d8b0e0e63045"}
{"ts":"2026-08-23T17:52:41.130Z","event_type":"new_market","market_id":"0xb70bb9c88453a9915ea7889f4b3b480e531e26572416a4374f1d66d1eee25afc"}
{"ts":"2026-08-23T17:52:41.131Z","event_type":"new_market","market_id":"0xec37002cf32631ddb8504045fb99acaf28caf8a28a11193dfd5686a6e0ac9f05"}
{"ts":"2026-08-23T17:52:41.131Z","event_type":"new_market","market_id":"0xb9885023a748ef14a246d29f326322f60584caf64cba41b22d5c53917fbb490b"}
{"ts":"2026-08-23T17:52:41.196Z","event_type":"new_market","market_id":"0x4de07250e609c8a74a88c5d514e5bb13ffd880cbedaf2713eb4ab137ba7e1ef9"}
{"ts":"2026-08-23T17:52:41.196Z","event_type":"new_market","market_id":"0x7293149b054fe39a3511d0e642c0f6b4d3ea2a24bed04f3efa38d602cce1a19c"}
{"ts":"2026-08-23T17:52:41.196Z","event_type":"new_market","market_id":"0xfd3066957ac8ee7223599f7a43e6cbd3b4c4af52de0a815fcb79fdc67b653fe5"}
{"ts":"2026-08-23T17:52:41.344Z","event_type":"best_bid_ask","market_id":"3790394","outcome_index":0,"market_type":"set1","local_side":"home","local_uid":"2026-08-23_hugo_grenier_mees_rottgering","bid":0.18,"ask":0.25,"mid":0.215,"spread":0.07,"bid_size":null,"ask_size":null}
{"ts":"2026-08-23T17:52:41.344Z","event_type":"best_bid_ask","market_id":"3790394","outcome_index":1,"market_type":"set1","local_side":"away","local_uid":"2026-08-23_hugo_grenier_mees_rottgering","bid":0.75,"ask":0.82,"mid":0.785,"spread":0.07,"bid_size":null,"ask_size":null}
{"ts":"2026-08-23T17:52:41.344Z","event_type":"price_change","market_id":"3790394","outcome_index":0,"market_type":"set1","local_side":"home","local_uid":"2026-08-23_hugo_grenier_mees_rottgering","bid":0.18,"ask":0.25,"mid":0.215,"spread":0.07,"price":0.18,"size":150.0,"side":"BUY"}
{"ts":"2026-08-23T17:52:41.344Z","event_type":"price_change","market_id":"3790394","outcome_index":1,"market_type":"set1","local_side":"away","local_uid":"2026-08-23_hugo_grenier_mees_rottgering","bid":0.75,"ask":0.82,"mid":0.785,"spread":0.07,"price":0.82,"size":150.0,"side":"SELL"}
{"ts":"2026-08-23T17:52:41.406Z","event_type":"price_change","market_id":"3789999","outcome_index":1,"market_type":"match","local_side":"away","local_uid":"2026-08-23_tiago_cacao_fabrizio_andaloro","bid":0.999,"ask":1.0,"mid":0.9995,"spread":0.001,"price":0.013,"size":44000.0,"side":"BUY"}
{"ts":"2026-08-23T17:52:41.406Z","event_type":"price_change","market_id":"3789999","outcome_index":0,"market_type":"match","local_side":"home","local_uid":"2026-08-23_tiago_cacao_fabrizio_andaloro","bid":0.0,"ask":0.001,"mid":0.0005,"spread":0.001,"price":0.987,"size":44000.0,"side":"SELL"}
{"ts":"2026-08-23T17:52:41.830Z","event_type":"last_trade_price","market_id":"3789927","outcome_index":1,"market_type":"match","local_side":"away","local_uid":"2026-08-23_hugo_grenier_mees_rottgering","last_trade":0.77,"trade_size":10.76,"trade_side":"BUY","trade_notional":8.2852}
{"ts":"2026-08-23T17:52:42.041Z","event_type":"new_market","market_id":"0x9aaf1b0a02be26a623389461662817b67746a8269db2a251d0af81c0710783ae"}
{"ts":"2026-08-23T17:52:42.042Z","event_type":"new_market","market_id":"0x1f87b83f8994599c1f3e70e058e47c5861f503f0828350994a49a29c24b1e808"}
{"ts":"2026-08-23T17:52:42.406Z","event_type":"price_change","market_id":"3795950","outcome_index":1,"market_type":"match","local_side":"away","local_uid":"2026-08-24_sebastian_baez_hubert_hurkacz","bid":0.68,"ask":0.69,"mid":0.685,"spread":0.01,"price":0.5,"size":1259.52,"side":"BUY"}
{"ts":"2026-08-23T17:52:42.406Z","event_type":"price_change","market_id":"3795950","outcome_index":0,"market_type":"match","local_side":"home","local_uid":"2026-08-24_sebastian_baez_hubert_hurkacz","bid":0.31,"ask":0.32,"mid":0.315,"spread":0.01,"price":0.5,"size":1259.52,"side":"SELL"}
{"ts":"2026-08-23T17:52:42.512Z","event_type":"new_market","market_id":"0x803576d3699bbff1959a27d3b33af09fe5d26936de3ab4650e8167f9f5d2f650"}
{"ts":"2026-08-23T17:52:42.513Z","event_type":"new_market","market_id":"0x0f1dc7dd635feb25b0660d0f9d5a77c66db71cb6290c7f1794fc823128b59061"}
{"ts":"2026-08-23T17:52:42.513Z","event_type":"new_market","market_id":"0x85f02a83f3b0b72a595e2d3f33bb71d1e40efdc370e6c74a6f6645d8a66cfa20"}
{"ts":"2026-08-23T17:52:42.513Z","event_type":"new_market","market_id":"0xb57255b8e5a2db13cc826dacdb8e8ea3bea82b9ef5897187d72203948869b8d6"}
{"ts":"2026-08-23T17:52:42.514Z","event_type":"new_market","market_id":"0xf39167f9a331dddefd1a28fb4ea5f7626668afe1e9937bffd7ce7e447707af5f"}
{"ts":"2026-08-23T17:52:42.682Z","event_type":"new_market","market_id":"0x67b5931f1e9f68b37bf86152f109eedf1bdd1df7651a46b8a16b1f960515dca3"}
{"ts":"2026-08-23T17:52:42.682Z","event_type":"new_market","market_id":"0xf3038efbb6fd196643d38e7834492ebf11909d52906e33db690203ed7dc71663"}
{"ts":"2026-08-23T17:52:42.682Z","event_type":"new_market","market_id":"0x831b6cedece70ecc32f8d449d453f0729be78f743c0da6b66a609c0eef09894a"}
{"ts":"2026-08-23T17:52:42.683Z","event_type":"new_market","market_id":"0x28f2ec99f829435d2031c39d64af40b0128764c7e047a2557a83ad01f9b27a90"}
{"ts":"2026-08-23T17:52:42.683Z","event_type":"price_change","market_id":"3802004","outcome_index":0,"market_type":"match","local_side":"home","local_uid":"2026-08-24_luis_guto_miguel_tyler_zink","bid":0.37,"ask":0.38,"mid":0.375,"spread":0.01,"price":0.3,"size":0.0,"side":"BUY"}
{"ts":"2026-08-23T17:52:42.683Z","event_type":"price_change","market_id":"3802004","outcome_index":1,"market_type":"match","local_side":"away","local_uid":"2026-08-24_luis_guto_miguel_tyler_zink","bid":0.62,"ask":0.63,"mid":0.625,"spread":0.01,"price":0.7,"size":0.0,"side":"SELL"}
{"ts":"2026-08-23T17:52:42.685Z","event_type":"new_market","market_id":"0x09a2bdc9bfc0a56156122bfdffa92e0b73b8ae9b04ee0b9bbfae6f21ed072a81"}
{"ts":"2026-08-23T17:52:42.938Z","event_type":"price_change","market_id":"3789929","outcome_index":0,"market_type":"match","local_side":"home","local_uid":"2026-08-23_felix_balshaw_sebastian_gorzny","bid":0.31,"ask":0.32,"mid":0.315,"spread":0.01,"price":0.08,"size":46.0,"side":"BUY"}
{"ts":"2026-08-23T17:52:42.938Z","event_type":"price_change","market_id":"3789929","outcome_index":1,"market_type":"match","local_side":"away","local_uid":"2026-08-23_felix_balshaw_sebastian_gorzny","bid":0.68,"ask":0.69,"mid":0.685,"spread":0.01,"price":0.92,"size":46.0,"side":"SELL"}
{"ts":"2026-08-23T17:52:42.999Z","event_type":"new_market","market_id":"0xcf49a97225dc16cc59f82f7a30b820ba80f9c20067b4a7e8098663df23d44af1"}
{"ts":"2026-08-23T17:52:43.257Z","event_type":"price_change","market_id":"3790338","outcome_index":0,"market_type":"set1","local_side":"home","local_uid":"2026-08-23_abdullah_shelbayh_dhakshineswar_suresh","bid":0.999,"ask":1.0,"mid":0.9995,"spread":0.001,"price":0.978,"size":150.0,"side":"BUY"}
{"ts":"2026-08-23T17:52:43.258Z","event_type":"price_change","market_id":"3790338","outcome_index":1,"market_type":"set1","local_side":"away","local_uid":"2026-08-23_abdullah_shelbayh_dhakshineswar_suresh","bid":0.0,"ask":0.001,"mid":0.0005,"spread":0.001,"price":0.022,"size":150.0,"side":"SELL"}
{"ts":"2026-08-23T17:52:43.258Z","event_type":"best_bid_ask","market_id":"3790334","outcome_index":0,"market_type":"set2","local_side":"home","local_uid":"2026-08-23_abdullah_shelbayh_dhakshineswar_suresh","bid":0.48,"ask":0.56,"mid":0.52,"spread":0.08,"bid_size":null,"ask_size":null}
{"ts":"2026-08-23T17:52:43.258Z","event_type":"best_bid_ask","market_id":"3790334","outcome_index":1,"market_type":"set2","local_side":"away","local_uid":"2026-08-23_abdullah_shelbayh_dhakshineswar_suresh","bid":0.44,"ask":0.52,"mid":0.48,"spread":0.08,"bid_size":null,"ask_size":null}
{"ts":"2026-08-23T17:52:43.258Z","event_type":"price_change","market_id":"3790334","outcome_index":0,"market_type":"set2","local_side":"home","local_uid":"2026-08-23_abdullah_shelbayh_dhakshineswar_suresh","bid":0.48,"ask":0.56,"mid":0.52,"spread":0.08,"price":0.49,"size":0.0,"side":"BUY"}
{"ts":"2026-08-23T17:52:43.258Z","event_type":"price_change","market_id":"3790334","outcome_index":1,"market_type":"set2","local_side":"away","local_uid":"2026-08-23_abdullah_shelbayh_dhakshineswar_suresh","bid":0.44,"ask":0.52,"mid":0.48,"spread":0.08,"price":0.51,"size":0.0,"side":"SELL"}
{"ts":"2026-08-23T17:52:43.320Z","event_type":"best_bid_ask","market_id":"3789997","outcome_index":0,"market_type":"match","local_side":"home","local_uid":"2026-08-23_oscar_weightman_alec_deckers","bid":0.09,"ask":0.11,"mid":0.1,"spread":0.02,"bid_size":null,"ask_size":null}
{"ts":"2026-08-23T17:52:43.320Z","event_type":"best_bid_ask","market_id":"3789997","outcome_index":1,"market_type":"match","local_side":"away","local_uid":"2026-08-23_oscar_weightman_alec_deckers","bid":0.89,"ask":0.91,"mid":0.9,"spread":0.02,"bid_size":null,"ask_size":null}
{"ts":"2026-08-23T17:52:43.320Z","event_type":"price_change","market_id":"3789997","outcome_index":1,"market_type":"match","local_side":"away","local_uid":"2026-08-23_oscar_weightman_alec_deckers","bid":0.89,"ask":0.91,"mid":0.9,"spread":0.02,"price":0.9,"size":0.0,"side":"BUY"}
{"ts":"2026-08-23T17:52:43.320Z","event_type":"price_change","market_id":"3789997","outcome_index":0,"market_type":"match","local_side":"home","local_uid":"2026-08-23_oscar_weightman_alec_deckers","bid":0.09,"ask":0.11,"mid":0.1,"spread":0.02,"price":0.1,"size":0.0,"side":"SELL"}
{"ts":"2026-08-23T17:52:43.425Z","event_type":"best_bid_ask","market_id":"3790415","outcome_index":0,"market_type":"set2","local_side":"home","local_uid":"2026-08-23_pierre_hugues_herbert_quinn_vandecasteele","bid":0.66,"ask":0.75,"mid":0.705,"spread":0.09,"bid_size":null,"ask_size":null}
{"ts":"2026-08-23T17:52:43.425Z","event_type":"best_bid_ask","market_id":"3790415","outcome_index":1,"market_type":"set2","local_side":"away","local_uid":"2026-08-23_pierre_hugues_herbert_quinn_vandecasteele","bid":0.25,"ask":0.34,"mid":0.295,"spread":0.09,"bid_size":null,"ask_size":null}
{"ts":"2026-08-23T17:52:43.425Z","event_type":"price_change","market_id":"3790415","outcome_index":1,"market_type":"set2","local_side":"away","local_uid":"2026-08-23_pierre_hugues_herbert_quinn_vandecasteele","bid":0.25,"ask":0.34,"mid":0.295,"spread":0.09,"price":0.25,"size":150.0,"side":"BUY"}
{"ts":"2026-08-23T17:52:43.425Z","event_type":"price_change","market_id":"3790415","outcome_index":0,"market_type":"set2","local_side":"home","local_uid":"2026-08-23_pierre_hugues_herbert_quinn_vandecasteele","bid":0.66,"ask":0.75,"mid":0.705,"spread":0.09,"price":0.75,"size":150.0,"side":"SELL"}
{"ts":"2026-08-23T17:52:43.532Z","event_type":"best_bid_ask","market_id":"3790415","outcome_index":0,"market_type":"set2","local_side":"home","local_uid":"2026-08-23_pierre_hugues_herbert_quinn_vandecasteele","bid":0.66,"ask":0.74,"mid":0.7,"spread":0.08,"bid_size":null,"ask_size":null}
{"ts":"2026-08-23T17:52:43.532Z","event_type":"best_bid_ask","market_id":"3790415","outcome_index":1,"market_type":"set2","local_side":"away","local_uid":"2026-08-23_pierre_hugues_herbert_quinn_vandecasteele","bid":0.26,"ask":0.34,"mid":0.3,"spread":0.08,"bid_size":null,"ask_size":null}
{"ts":"2026-08-23T17:52:43.532Z","event_type":"price_change","market_id":"3790415","outcome_index":1,"market_type":"set2","local_side":"away","local_uid":"2026-08-23_pierre_hugues_herbert_quinn_vandecasteele","bid":0.26,"ask":0.34,"mid":0.3,"spread":0.08,"price":0.26,"size":150.0,"side":"BUY"}
{"ts":"2026-08-23T17:52:43.532Z","event_type":"price_change","market_id":"3790415","outcome_index":0,"market_type":"set2","local_side":"home","local_uid":"2026-08-23_pierre_hugues_herbert_quinn_vandecasteele","bid":0.66,"ask":0.74,"mid":0.7,"spread":0.08,"price":0.74,"size":150.0,"side":"SELL"}
{"ts":"2026-08-23T17:52:43.575Z","event_type":"best_bid_ask","market_id":"3790334","outcome_index":0,"market_type":"set2","local_side":"home","local_uid":"2026-08-23_abdullah_shelbayh_dhakshineswar_suresh","bid":0.48,"ask":0.57,"mid":0.525,"spread":0.09,"bid_size":null,"ask_size":null}
{"ts":"2026-08-23T17:52:43.576Z","event_type":"best_bid_ask","market_id":"3790334","outcome_index":1,"market_type":"set2","local_side":"away","local_uid":"2026-08-23_abdullah_shelbayh_dhakshineswar_suresh","bid":0.43,"ask":0.52,"mid":0.475,"spread":0.09,"bid_size":null,"ask_size":null}
{"ts":"2026-08-23T17:52:43.576Z","event_type":"price_change","market_id":"3790334","outcome_index":1,"market_type":"set2","local_side":"away","local_uid":"2026-08-23_abdullah_shelbayh_dhakshineswar_suresh","bid":0.43,"ask":0.52,"mid":0.475,"spread":0.09,"price":0.44,"size":0.0,"side":"BUY"}
{"ts":"2026-08-23T17:52:43.576Z","event_type":"price_change","market_id":"3790334","outcome_index":0,"market_type":"set2","local_side":"home","local_uid":"2026-08-23_abdullah_shelbayh_dhakshineswar_suresh","bid":0.48,"ask":0.57,"mid":0.525,"spread":0.09,"price":0.56,"size":0.0,"side":"SELL"}
{"ts":"2026-08-23T17:52:43.637Z","event_type":"best_bid_ask","market_id":"3790334","outcome_index":0,"market_type":"set2","local_side":"home","local_uid":"2026-08-23_abdullah_shelbayh_dhakshineswar_suresh","bid":0.48,"ask":0.58,"mid":0.53,"spread":0.1,"bid_size":null,"ask_size":null}
{"ts":"2026-08-23T17:52:43.637Z","event_type":"best_bid_ask","market_id":"3790334","outcome_index":1,"market_type":"set2","local_side":"away","local_uid":"2026-08-23_abdullah_shelbayh_dhakshineswar_suresh","bid":0.42,"ask":0.52,"mid":0.47,"spread":0.1,"bid_size":null,"ask_size":null}
{"ts":"2026-08-23T17:52:43.637Z","event_type":"price_change","market_id":"3790334","outcome_index":1,"market_type":"set2","local_side":"away","local_uid":"2026-08-23_abdullah_shelbayh_dhakshineswar_suresh","bid":0.42,"ask":0.52,"mid":0.47,"spread":0.1,"price":0.43,"size":0.0,"side":"BUY"}
{"ts":"2026-08-23T17:52:43.637Z","event_type":"price_change","market_id":"3790334","outcome_index":0,"market_type":"set2","local_side":"home","local_uid":"2026-08-23_abdullah_shelbayh_dhakshineswar_suresh","bid":0.48,"ask":0.58,"mid":0.53,"spread":0.1,"price":0.57,"size":0.0,"side":"SELL"}
{"ts":"2026-08-23T17:52:43.639Z","event_type":"best_bid_ask","market_id":"3790334","outcome_index":0,"market_type":"set2","local_side":"home","local_uid":"2026-08-23_abdullah_shelbayh_dhakshineswar_suresh","bid":0.48,"ask":0.61,"mid":0.545,"spread":0.13,"bid_size":null,"ask_size":null}
{"ts":"2026-08-23T17:52:43.639Z","event_type":"best_bid_ask","market_id":"3790334","outcome_index":1,"market_type":"set2","local_side":"away","local_uid":"2026-08-23_abdullah_shelbayh_dhakshineswar_suresh","bid":0.39,"ask":0.52,"mid":0.455,"spread":0.13,"bid_size":null,"ask_size":null}
{"ts":"2026-08-23T17:52:43.639Z","event_type":"price_change","market_id":"3790334","outcome_index":1,"market_type":"set2","local_side":"away","local_uid":"2026-08-23_abdullah_shelbayh_dhakshineswar_suresh","bid":0.39,"ask":0.52,"mid":0.455,"spread":0.13,"price":0.42,"size":0.0,"side":"BUY"}
{"ts":"2026-08-23T17:52:43.639Z","event_type":"price_change","market_id":"3790334","outcome_index":0,"market_type":"set2","local_side":"home","local_uid":"2026-08-23_abdullah_shelbayh_dhakshineswar_suresh","bid":0.48,"ask":0.61,"mid":0.545,"spread":0.13,"price":0.58,"size":0.0,"side":"SELL"}
{"ts":"2026-08-23T17:52:43.678Z","event_type":"best_bid_ask","market_id":"3790334","outcome_index":0,"market_type":"set2","local_side":"home","local_uid":"2026-08-23_abdullah_shelbayh_dhakshineswar_suresh","bid":0.48,"ask":1.0,"mid":0.74,"spread":0.52,"bid_size":null,"ask_size":null}
{"ts":"2026-08-23T17:52:43.678Z","event_type":"best_bid_ask","market_id":"3790334","outcome_index":1,"market_type":"set2","local_side":"away","local_uid":"2026-08-23_abdullah_shelbayh_dhakshineswar_suresh","bid":0.0,"ask":0.52,"mid":0.26,"spread":0.52,"bid_size":null,"ask_size":null}
{"ts":"2026-08-23T17:52:43.681Z","event_type":"price_change","market_id":"3790334","outcome_index":1,"market_type":"set2","local_side":"away","local_uid":"2026-08-23_abdullah_shelbayh_dhakshineswar_suresh","bid":0.0,"ask":0.52,"mid":0.26,"spread":0.52,"price":0.39,"size":0.0,"side":"BUY"}
{"ts":"2026-08-23T17:52:43.681Z","event_type":"price_change","market_id":"3790334","outcome_index":0,"market_type":"set2","local_side":"home","local_uid":"2026-08-23_abdullah_shelbayh_dhakshineswar_suresh","bid":0.48,"ask":1.0,"mid":0.74,"spread":0.52,"price":0.61,"size":0.0,"side":"SELL"}
{"ts":"2026-08-23T17:52:43.681Z","event_type":"best_bid_ask","market_id":"3790334","outcome_index":0,"market_type":"set2","local_side":"home","local_uid":"2026-08-23_abdullah_shelbayh_dhakshineswar_suresh","bid":0.48,"ask":0.61,"mid":0.545,"spread":0.13,"bid_size":null,"ask_size":null}
{"ts":"2026-08-23T17:52:43.681Z","event_type":"best_bid_ask","market_id":"3790334","outcome_index":1,"market_type":"set2","local_side":"away","local_uid":"2026-08-23_abdullah_shelbayh_dhakshineswar_suresh","bid":0.39,"ask":0.52,"mid":0.455,"spread":0.13,"bid_size":null,"ask_size":null}
{"ts":"2026-08-23T17:52:43.681Z","event_type":"price_change","market_id":"3790334","outcome_index":1,"market_type":"set2","local_side":"away","local_uid":"2026-08-23_abdullah_shelbayh_dhakshineswar_suresh","bid":0.39,"ask":0.52,"mid":0.455,"spread":0.13,"price":0.39,"size":26.0,"side":"BUY"}
{"ts":"2026-08-23T17:52:43.681Z","event_type":"price_change","market_id":"3790334","outcome_index":0,"market_type":"set2","local_side":"home","local_uid":"2026-08-23_abdullah_shelbayh_dhakshineswar_suresh","bid":0.48,"ask":0.61,"mid":0.545,"spread":0.13,"price":0.61,"size":26.0,"side":"SELL"}
{"ts":"2026-08-23T17:52:43.681Z","event_type":"best_bid_ask","market_id":"3790334","outcome_index":0,"market_type":"set2","local_side":"home","local_uid":"2026-08-23_abdullah_shelbayh_dhakshineswar_suresh","bid":0.48,"ask":0.6,"mid":0.54,"spread":0.12,"bid_size":null,"ask_size":null}
{"ts":"2026-08-23T17:52:43.681Z","event_type":"best_bid_ask","market_id":"3790334","outcome_index":1,"market_type":"set2","local_side":"away","local_uid":"2026-08-23_abdullah_shelbayh_dhakshineswar_suresh","bid":0.4,"ask":0.52,"mid":0.46,"spread":0.12,"bid_size":null,"ask_size":null}
{"ts":"2026-08-23T17:52:43.682Z","event_type":"price_change","market_id":"3790334","outcome_index":1,"market_type":"set2","local_side":"away","local_uid":"2026-08-23_abdullah_shelbayh_dhakshineswar_suresh","bid":0.4,"ask":0.52,"mid":0.46,"spread":0.12,"price":0.4,"size":44.0,"side":"BUY"}
{"ts":"2026-08-23T17:52:43.682Z","event_type":"price_change","market_id":"3790334","outcome_index":0,"market_type":"set2","local_side":"home","local_uid":"2026-08-23_abdullah_shelbayh_dhakshineswar_suresh","bid":0.48,"ask":0.6,"mid":0.54,"spread":0.12,"price":0.6,"size":44.0,"side":"SELL"}
{"ts":"2026-08-23T17:52:43.682Z","event_type":"best_bid_ask","market_id":"3790334","outcome_index":0,"market_type":"set2","local_side":"home","local_uid":"2026-08-23_abdullah_shelbayh_dhakshineswar_suresh","bid":0.48,"ask":1.0,"mid":0.74,"spread":0.52,"bid_size":null,"ask_size":null}
{"ts":"2026-08-23T17:52:43.682Z","event_type":"best_bid_ask","market_id":"3790334","outcome_index":1,"market_type":"set2","local_side":"away","local_uid":"2026-08-23_abdullah_shelbayh_dhakshineswar_suresh","bid":0.0,"ask":0.52,"mid":0.26,"spread":0.52,"bid_size":null,"ask_size":null}
{"ts":"2026-08-23T17:52:43.682Z","event_type":"price_change","market_id":"3790334","outcome_index":1,"market_type":"set2","local_side":"away","local_uid":"2026-08-23_abdullah_shelbayh_dhakshineswar_suresh","bid":0.0,"ask":0.52,"mid":0.26,"spread":0.52,"price":0.4,"size":0.0,"side":"BUY"}
