{"ts":"2026-08-24T20:48:00.860Z","event_type":"best_bid_ask","market_id":"3826654","outcome_index":0,"market_type":"set2","local_side":"home","local_uid":"2026-08-24_sebastian_gorzny_cruz_hewitt","bid":0.07,"ask":0.26,"mid":0.165,"spread":0.19,"bid_size":null,"ask_size":null}
{"ts":"2026-08-24T20:48:00.860Z","event_type":"best_bid_ask","market_id":"3826654","outcome_index":1,"market_type":"set2","local_side":"away","local_uid":"2026-08-24_sebastian_gorzny_cruz_hewitt","bid":0.74,"ask":0.93,"mid":0.835,"spread":0.19,"bid_size":null,"ask_size":null}
{"ts":"2026-08-24T20:48:00.861Z","event_type":"price_change","market_id":"3826654","outcome_index":0,"market_type":"set2","local_side":"home","local_uid":"2026-08-24_sebastian_gorzny_cruz_hewitt","bid":0.07,"ask":0.26,"mid":0.165,"spread":0.19,"price":0.07,"size":211.0,"side":"BUY"}
{"ts":"2026-08-24T20:48:00.861Z","event_type":"price_change","market_id":"3826654","outcome_index":1,"market_type":"set2","local_side":"away","local_uid":"2026-08-24_sebastian_gorzny_cruz_hewitt","bid":0.74,"ask":0.93,"mid":0.835,"spread":0.19,"price":0.93,"size":211.0,"side":"SELL"}
{"ts":"2026-08-24T20:48:00.861Z","event_type":"best_bid_ask","market_id":"3826654","outcome_index":0,"market_type":"set2","local_side":"home","local_uid":"2026-08-24_sebastian_gorzny_cruz_hewitt","bid":0.08,"ask":0.26,"mid":0.17,"spread":0.18,"bid_size":null,"ask_size":null}
{"ts":"2026-08-24T20:48:00.861Z","event_type":"best_bid_ask","market_id":"3826654","outcome_index":1,"market_type":"set2","local_side":"away","local_uid":"2026-08-24_sebastian_gorzny_cruz_hewitt","bid":0.74,"ask":0.92,"mid":0.83,"spread":0.18,"bid_size":null,"ask_size":null}
{"ts":"2026-08-24T20:48:00.864Z","event_type":"price_change","market_id":"3826654","outcome_index":0,"market_type":"set2","local_side":"home","local_uid":"2026-08-24_sebastian_gorzny_cruz_hewitt","bid":0.08,"ask":0.26,"mid":0.17,"spread":0.18,"price":0.08,"size":88.0,"side":"BUY"}
{"ts":"2026-08-24T20:48:00.864Z","event_type":"price_change","market_id":"3826654","outcome_index":1,"market_type":"set2","local_side":"away","local_uid":"2026-08-24_sebastian_gorzny_cruz_hewitt","bid":0.74,"ask":0.92,"mid":0.83,"spread":0.18,"price":0.92,"size":88.0,"side":"SELL"}
{"ts":"2026-08-24T20:48:00.894Z","event_type":"best_bid_ask","market_id":"3826654","outcome_index":0,"market_type":"set2","local_side":"home","local_uid":"2026-08-24_sebastian_gorzny_cruz_hewitt","bid":0.1,"ask":0.26,"mid":0.18,"spread":0.16,"bid_size":null,"ask_size":null}
{"ts":"2026-08-24T20:48:00.894Z","event_type":"best_bid_ask","market_id":"3826654","outcome_index":1,"market_type":"set2","local_side":"away","local_uid":"2026-08-24_sebastian_gorzny_cruz_hewitt","bid":0.74,"ask":0.9,"mid":0.82,"spread":0.16,"bid_size":null,"ask_size":null}
{"ts":"2026-08-24T20:48:00.895Z","event_type":"price_change","market_id":"3826654","outcome_index":0,"market_type":"set2","local_side":"home","local_uid":"2026-08-24_sebastian_gorzny_cruz_hewitt","bid":0.1,"ask":0.26,"mid":0.18,"spread":0.16,"price":0.1,"size":44.0,"side":"BUY"}
{"ts":"2026-08-24T20:48:00.895Z","event_type":"price_change","market_id":"3826654","outcome_index":1,"market_type":"set2","local_side":"away","local_uid":"2026-08-24_sebastian_gorzny_cruz_hewitt","bid":0.74,"ask":0.9,"mid":0.82,"spread":0.16,"price":0.9,"size":44.0,"side":"SELL"}
{"ts":"2026-08-24T20:48:00.911Z","event_type":"best_bid_ask","market_id":"3825070","outcome_index":0,"market_type":"set2","local_side":"home","local_uid":"2026-08-24_polina_kudermetova_linda_fruhvirtova","bid":0.52,"ask":0.63,"mid":0.575,"spread":0.11,"bid_size":null,"ask_size":null}
{"ts":"2026-08-24T20:48:00.912Z","event_type":"best_bid_ask","market_id":"3825070","outcome_index":1,"market_type":"set2","local_side":"away","local_uid":"2026-08-24_polina_kudermetova_linda_fruhvirtova","bid":0.37,"ask":0.48,"mid":0.425,"spread":0.11,"bid_size":null,"ask_size":null}
{"ts":"2026-08-24T20:48:00.912Z","event_type":"price_change","market_id":"3825070","outcome_index":1,"market_type":"set2","local_side":"away","local_uid":"2026-08-24_polina_kudermetova_linda_fruhvirtova","bid":0.37,"ask":0.48,"mid":0.425,"spread":0.11,"price":0.38,"size":0.0,"side":"BUY"}
{"ts":"2026-08-24T20:48:00.912Z","event_type":"price_change","market_id":"3825070","outcome_index":0,"market_type":"set2","local_side":"home","local_uid":"2026-08-24_polina_kudermetova_linda_fruhvirtova","bid":0.52,"ask":0.63,"mid":0.575,"spread":0.11,"price":0.62,"size":0.0,"side":"SELL"}
{"ts":"2026-08-24T20:48:01.013Z","event_type":"best_bid_ask","market_id":"3826654","outcome_index":0,"market_type":"set2","local_side":"home","local_uid":"2026-08-24_sebastian_gorzny_cruz_hewitt","bid":0.1,"ask":0.27,"mid":0.185,"spread":0.17,"bid_size":null,"ask_size":null}
{"ts":"2026-08-24T20:48:01.013Z","event_type":"best_bid_ask","market_id":"3826654","outcome_index":1,"market_type":"set2","local_side":"away","local_uid":"2026-08-24_sebastian_gorzny_cruz_hewitt","bid":0.73,"ask":0.9,"mid":0.815,"spread":0.17,"bid_size":null,"ask_size":null}
{"ts":"2026-08-24T20:48:01.013Z","event_type":"price_change","market_id":"3826654","outcome_index":1,"market_type":"set2","local_side":"away","local_uid":"2026-08-24_sebastian_gorzny_cruz_hewitt","bid":0.73,"ask":0.9,"mid":0.815,"spread":0.17,"price":0.74,"size":0.0,"side":"BUY"}
{"ts":"2026-08-24T20:48:01.014Z","event_type":"price_change","market_id":"3826654","outcome_index":0,"market_type":"set2","local_side":"home","local_uid":"2026-08-24_sebastian_gorzny_cruz_hewitt","bid":0.1,"ask":0.27,"mid":0.185,"spread":0.17,"price":0.26,"size":0.0,"side":"SELL"}
{"ts":"2026-08-24T20:48:01.014Z","event_type":"best_bid_ask","market_id":"3826654","outcome_index":0,"market_type":"set2","local_side":"home","local_uid":"2026-08-24_sebastian_gorzny_cruz_hewitt","bid":0.08,"ask":0.27,"mid":0.175,"spread":0.19,"bid_size":null,"ask_size":null}
{"ts":"2026-08-24T20:48:01.014Z","event_type":"best_bid_ask","market_id":"3826654","outcome_index":1,"market_type":"set2","local_side":"away","local_uid":"2026-08-24_sebastian_gorzny_cruz_hewitt","bid":0.73,"ask":0.92,"mid":0.825,"spread":0.19,"bid_size":null,"ask_size":null}
{"ts":"2026-08-24T20:48:01.016Z","event_type":"price_change","market_id":"3826654","outcome_index":0,"market_type":"set2","local_side":"home","local_uid":"2026-08-24_sebastian_gorzny_cruz_hewitt","bid":0.08,"ask":0.27,"mid":0.175,"spread":0.19,"price":0.1,"size":0.0,"side":"BUY"}
{"ts":"2026-08-24T20:48:01.016Z","event_type":"price_change","market_id":"3826654","outcome_index":1,"market_type":"set2","local_side":"away","local_uid":"2026-08-24_sebastian_gorzny_cruz_hewitt","bid":0.73,"ask":0.92,"mid":0.825,"spread":0.19,"price":0.9,"size":0.0,"side":"SELL"}
{"ts":"2026-08-24T20:48:01.017Z","event_type":"best_bid_ask","market_id":"3826654","outcome_index":0,"market_type":"set2","local_side":"home","local_uid":"2026-08-24_sebastian_gorzny_cruz_hewitt","bid":0.06,"ask":0.27,"mid":0.165,"spread":0.21,"bid_size":null,"ask_size":null}
{"ts":"2026-08-24T20:48:01.017Z","event_type":"best_bid_ask","market_id":"3826654","outcome_index":1,"market_type":"set2","local_side":"away","local_uid":"2026-08-24_sebastian_gorzny_cruz_hewitt","bid":0.73,"ask":0.94,"mid":0.835,"spread":0.21,"bid_size":null,"ask_size":null}
{"ts":"2026-08-24T20:48:01.018Z","event_type":"price_change","market_id":"3826654","outcome_index":0,"market_type":"set2","local_side":"home","local_uid":"2026-08-24_sebastian_gorzny_cruz_hewitt","bid":0.06,"ask":0.27,"mid":0.165,"spread":0.21,"price":0.08,"size":0.0,"side":"BUY"}
{"ts":"2026-08-24T20:48:01.018Z","event_type":"price_change","market_id":"3826654","outcome_index":1,"market_type":"set2","local_side":"away","local_uid":"2026-08-24_sebastian_gorzny_cruz_hewitt","bid":0.73,"ask":0.94,"mid":0.835,"spread":0.21,"price":0.92,"size":0.0,"side":"SELL"}
{"ts":"2026-08-24T20:48:01.018Z","event_type":"best_bid_ask","market_id":"3826654","outcome_index":0,"market_type":"set2","local_side":"home","local_uid":"2026-08-24_sebastian_gorzny_cruz_hewitt","bid":0.07,"ask":0.27,"mid":0.17,"spread":0.2,"bid_size":null,"ask_size":null}
{"ts":"2026-08-24T20:48:01.018Z","event_type":"best_bid_ask","market_id":"3826654","outcome_index":1,"market_type":"set2","local_side":"away","local_uid":"2026-08-24_sebastian_gorzny_cruz_hewitt","bid":0.73,"ask":0.93,"mid":0.83,"spread":0.2,"bid_size":null,"ask_size":null}
{"ts":"2026-08-24T20:48:01.019Z","event_type":"price_change","market_id":"3826654","outcome_index":0,"market_type":"set2","local_side":"home","local_uid":"2026-08-24_sebastian_gorzny_cruz_hewitt","bid":0.07,"ask":0.27,"mid":0.17,"spread":0.2,"price":0.07,"size":88.0,"side":"BUY"}
{"ts":"2026-08-24T20:48:01.019Z","event_type":"price_change","market_id":"3826654","outcome_index":1,"market_type":"set2","local_side":"away","local_uid":"2026-08-24_sebastian_gorzny_cruz_hewitt","bid":0.73,"ask":0.93,"mid":0.83,"spread":0.2,"price":0.93,"size":88.0,"side":"SELL"}
{"ts":"2026-08-24T20:48:01.080Z","event_type":"best_bid_ask","market_id":"3825070","outcome_index":0,"market_type":"set2","local_side":"home","local_uid":"2026-08-24_polina_kudermetova_linda_fruhvirtova","bid":0.52,"ask":0.62,"mid":0.57,"spread":0.1,"bid_size":null,"ask_size":null}
{"ts":"2026-08-24T20:48:01.080Z","event_type":"best_bid_ask","market_id":"3825070","outcome_index":1,"market_type":"set2","local_side":"away","local_uid":"2026-08-24_polina_kudermetova_linda_fruhvirtova","bid":0.38,"ask":0.48,"mid":0.43,"spread":0.1,"bid_size":null,"ask_size":null}
{"ts":"2026-08-24T20:48:01.081Z","event_type":"price_change","market_id":"3825070","outcome_index":1,"market_type":"set2","local_side":"away","local_uid":"2026-08-24_polina_kudermetova_linda_fruhvirtova","bid":0.38,"ask":0.48,"mid":0.43,"spread":0.1,"price":0.38,"size":6.58,"side":"BUY"}
{"ts":"2026-08-24T20:48:01.081Z","event_type":"price_change","market_id":"3825070","outcome_index":0,"market_type":"set2","local_side":"home","local_uid":"2026-08-24_polina_kudermetova_linda_fruhvirtova","bid":0.52,"ask":0.62,"mid":0.57,"spread":0.1,"price":0.62,"size":6.58,"side":"SELL"}
{"ts":"2026-08-24T20:48:01.139Z","event_type":"best_bid_ask","market_id":"3825077","outcome_index":0,"market_type":"set1","local_side":"home","local_uid":"2026-08-24_polina_kudermetova_linda_fruhvirtova","bid":0.45,"ask":0.56,"mid":0.505,"spread":0.11,"bid_size":null,"ask_size":null}
{"ts":"2026-08-24T20:48:01.139Z","event_type":"best_bid_ask","market_id":"3825077","outcome_index":1,"market_type":"set1","local_side":"away","local_uid":"2026-08-24_polina_kudermetova_linda_fruhvirtova","bid":0.44,"ask":0.55,"mid":0.495,"spread":0.11,"bid_size":null,"ask_size":null}
{"ts":"2026-08-24T20:48:01.139Z","event_type":"price_change","market_id":"3825077","outcome_index":1,"market_type":"set1","local_side":"away","local_uid":"2026-08-24_polina_kudermetova_linda_fruhvirtova","bid":0.44,"ask":0.55,"mid":0.495,"spread":0.11,"price":0.49,"size":0.0,"side":"BUY"}
{"ts":"2026-08-24T20:48:01.139Z","event_type":"price_change","market_id":"3825077","outcome_index":0,"market_type":"set1","local_side":"home","local_uid":"2026-08-24_polina_kudermetova_linda_fruhvirtova","bid":0.45,"ask":0.56,"mid":0.505,"spread":0.11,"price":0.51,"size":0.0,"side":"SELL"}
{"ts":"2026-08-24T20:48:01.183Z","event_type":"best_bid_ask","market_id":"3823619","outcome_index":0,"market_type":"match","local_side":"home","local_uid":"2026-08-24_polina_kudermetova_linda_fruhvirtova","bid":0.55,"ask":0.58,"mid":0.565,"spread":0.03,"bid_size":null,"ask_size":null}
{"ts":"2026-08-24T20:48:01.183Z","event_type":"best_bid_ask","market_id":"3823619","outcome_index":1,"market_type":"match","local_side":"away","local_uid":"2026-08-24_polina_kudermetova_linda_fruhvirtova","bid":0.42,"ask":0.45,"mid":0.435,"spread":0.03,"bid_size":null,"ask_size":null}
{"ts":"2026-08-24T20:48:01.184Z","event_type":"price_change","market_id":"3823619","outcome_index":1,"market_type":"match","local_side":"away","local_uid":"2026-08-24_polina_kudermetova_linda_fruhvirtova","bid":0.42,"ask":0.45,"mid":0.435,"spread":0.03,"price":0.43,"size":0.0,"side":"BUY"}
{"ts":"2026-08-24T20:48:01.184Z","event_type":"price_change","market_id":"3823619","outcome_index":0,"market_type":"match","local_side":"home","local_uid":"2026-08-24_polina_kudermetova_linda_fruhvirtova","bid":0.55,"ask":0.58,"mid":0.565,"spread":0.03,"price":0.57,"size":0.0,"side":"SELL"}
{"ts":"2026-08-24T20:48:01.240Z","event_type":"best_bid_ask","market_id":"3825070","outcome_index":0,"market_type":"set2","local_side":"home","local_uid":"2026-08-24_polina_kudermetova_linda_fruhvirtova","bid":0.52,"ask":0.63,"mid":0.575,"spread":0.11,"bid_size":null,"ask_size":null}
{"ts":"2026-08-24T20:48:01.240Z","event_type":"best_bid_ask","market_id":"3825070","outcome_index":1,"market_type":"set2","local_side":"away","local_uid":"2026-08-24_polina_kudermetova_linda_fruhvirtova","bid":0.37,"ask":0.48,"mid":0.425,"spread":0.11,"bid_size":null,"ask_size":null}
{"ts":"2026-08-24T20:48:01.240Z","event_type":"price_change","market_id":"3825070","outcome_index":1,"market_type":"set2","local_side":"away","local_uid":"2026-08-24_polina_kudermetova_linda_fruhvirtova","bid":0.37,"ask":0.48,"mid":0.425,"spread":0.11,"price":0.38,"size":0.0,"side":"BUY"}
{"ts":"2026-08-24T20:48:01.240Z","event_type":"price_change","market_id":"3825070","outcome_index":0,"market_type":"set2","local_side":"home","local_uid":"2026-08-24_polina_kudermetova_linda_fruhvirtova","bid":0.52,"ask":0.63,"mid":0.575,"spread":0.11,"price":0.62,"size":0.0,"side":"SELL"}
{"ts":"2026-08-24T20:48:01.542Z","event_type":"best_bid_ask","market_id":"3825070","outcome_index":0,"market_type":"set2","local_side":"home","local_uid":"2026-08-24_polina_kudermetova_linda_fruhvirtova","bid":0.52,"ask":0.62,"mid":0.57,"spread":0.1,"bid_size":null,"ask_size":null}
{"ts":"2026-08-24T20:48:01.542Z","event_type":"best_bid_ask","market_id":"3825070","outcome_index":1,"market_type":"set2","local_side":"away","local_uid":"2026-08-24_polina_kudermetova_linda_fruhvirtova","bid":0.38,"ask":0.48,"mid":0.43,"spread":0.1,"bid_size":null,"ask_size":null}
{"ts":"2026-08-24T20:48:01.543Z","event_type":"price_change","market_id":"3825070","outcome_index":1,"market_type":"set2","local_side":"away","local_uid":"2026-08-24_polina_kudermetova_linda_fruhvirtova","bid":0.38,"ask":0.48,"mid":0.43,"spread":0.1,"price":0.38,"size":6.58,"side":"BUY"}
{"ts":"2026-08-24T20:48:01.543Z","event_type":"price_change","market_id":"3825070","outcome_index":0,"market_type":"set2","local_side":"home","local_uid":"2026-08-24_polina_kudermetova_linda_fruhvirtova","bid":0.52,"ask":0.62,"mid":0.57,"spread":0.1,"price":0.62,"size":6.58,"side":"SELL"}
{"ts":"2026-08-24T20:48:01.561Z","event_type":"best_bid_ask","market_id":"3826654","outcome_index":0,"market_type":"set2","local_side":"home","local_uid":"2026-08-24_sebastian_gorzny_cruz_hewitt","bid":0.07,"ask":0.28,"mid":0.175,"spread":0.21,"bid_size":null,"ask_size":null}
{"ts":"2026-08-24T20:48:01.562Z","event_type":"best_bid_ask","market_id":"3826654","outcome_index":1,"market_type":"set2","local_side":"away","local_uid":"2026-08-24_sebastian_gorzny_cruz_hewitt","bid":0.72,"ask":0.93,"mid":0.825,"spread":0.21,"bid_size":null,"ask_size":null}
{"ts":"2026-08-24T20:48:01.562Z","event_type":"price_change","market_id":"3826654","outcome_index":1,"market_type":"set2","local_side":"away","local_uid":"2026-08-24_sebastian_gorzny_cruz_hewitt","bid":0.72,"ask":0.93,"mid":0.825,"spread":0.21,"price":0.73,"size":0.0,"side":"BUY"}
{"ts":"2026-08-24T20:48:01.562Z","event_type":"price_change","market_id":"3826654","outcome_index":0,"market_type":"set2","local_side":"home","local_uid":"2026-08-24_sebastian_gorzny_cruz_hewitt","bid":0.07,"ask":0.28,"mid":0.175,"spread":0.21,"price":0.27,"size":0.0,"side":"SELL"}
{"ts":"2026-08-24T20:48:01.565Z","event_type":"best_bid_ask","market_id":"3826654","outcome_index":0,"market_type":"set2","local_side":"home","local_uid":"2026-08-24_sebastian_gorzny_cruz_hewitt","bid":0.07,"ask":0.3,"mid":0.185,"spread":0.23,"bid_size":null,"ask_size":null}
{"ts":"2026-08-24T20:48:01.565Z","event_type":"best_bid_ask","market_id":"3826654","outcome_index":1,"market_type":"set2","local_side":"away","local_uid":"2026-08-24_sebastian_gorzny_cruz_hewitt","bid":0.7,"ask":0.93,"mid":0.815,"spread":0.23,"bid_size":null,"ask_size":null}
{"ts":"2026-08-24T20:48:01.565Z","event_type":"price_change","market_id":"3826654","outcome_index":1,"market_type":"set2","local_side":"away","local_uid":"2026-08-24_sebastian_gorzny_cruz_hewitt","bid":0.7,"ask":0.93,"mid":0.815,"spread":0.23,"price":0.72,"size":0.0,"side":"BUY"}
{"ts":"2026-08-24T20:48:01.565Z","event_type":"price_change","market_id":"3826654","outcome_index":0,"market_type":"set2","local_side":"home","local_uid":"2026-08-24_sebastian_gorzny_cruz_hewitt","bid":0.07,"ask":0.3,"mid":0.185,"spread":0.23,"price":0.28,"size":0.0,"side":"SELL"}
{"ts":"2026-08-24T20:48:01.571Z","event_type":"best_bid_ask","market_id":"3826654","outcome_index":0,"market_type":"set2","local_side":"home","local_uid":"2026-08-24_sebastian_gorzny_cruz_hewitt","bid":0.07,"ask":0.31,"mid":0.19,"spread":0.24,"bid_size":null,"ask_size":null}
{"ts":"2026-08-24T20:48:01.571Z","event_type":"best_bid_ask","market_id":"3826654","outcome_index":1,"market_type":"set2","local_side":"away","local_uid":"2026-08-24_sebastian_gorzny_cruz_hewitt","bid":0.69,"ask":0.93,"mid":0.81,"spread":0.24,"bid_size":null,"ask_size":null}
{"ts":"2026-08-24T20:48:01.571Z","event_type":"price_change","market_id":"3826654","outcome_index":1,"market_type":"set2","local_side":"away","local_uid":"2026-08-24_sebastian_gorzny_cruz_hewitt","bid":0.69,"ask":0.93,"mid":0.81,"spread":0.24,"price":0.7,"size":0.0,"side":"BUY"}
{"ts":"2026-08-24T20:48:01.571Z","event_type":"price_change","market_id":"3826654","outcome_index":0,"market_type":"set2","local_side":"home","local_uid":"2026-08-24_sebastian_gorzny_cruz_hewitt","bid":0.07,"ask":0.31,"mid":0.19,"spread":0.24,"price":0.3,"size":0.0,"side":"SELL"}
{"ts":"2026-08-24T20:48:01.572Z","event_type":"best_bid_ask","market_id":"3826654","outcome_index":0,"market_type":"set2","local_side":"home","local_uid":"2026-08-24_sebastian_gorzny_cruz_hewitt","bid":0.07,"ask":0.32,"mid":0.195,"spread":0.25,"bid_size":null,"ask_size":null}
{"ts":"2026-08-24T20:48:01.573Z","event_type":"best_bid_ask","market_id":"3826654","outcome_index":1,"market_type":"set2","local_side":"away","local_uid":"2026-08-24_sebastian_gorzny_cruz_hewitt","bid":0.68,"ask":0.93,"mid":0.805,"spread":0.25,"bid_size":null,"ask_size":null}
{"ts":"2026-08-24T20:48:01.573Z","event_type":"price_change","market_id":"3826654","outcome_index":1,"market_type":"set2","local_side":"away","local_uid":"2026-08-24_sebastian_gorzny_cruz_hewitt","bid":0.68,"ask":0.93,"mid":0.805,"spread":0.25,"price":0.69,"size":0.0,"side":"BUY"}
{"ts":"2026-08-24T20:48:01.573Z","event_type":"price_change","market_id":"3826654","outcome_index":0,"market_type":"set2","local_side":"home","local_uid":"2026-08-24_sebastian_gorzny_cruz_hewitt","bid":0.07,"ask":0.32,"mid":0.195,"spread":0.25,"price":0.31,"size":0.0,"side":"SELL"}
{"ts":"2026-08-24T20:48:01.804Z","event_type":"price_change","market_id":"3802002","outcome_index":0,"market_type":"match","local_side":"home","local_uid":"2026-08-24_alvaro_guillen_meza_andrew_fenty","bid":0.39,"ask":0.4,"mid":0.395,"spread":0.01,"price":0.33,"size":413.0,"side":"BUY"}
{"ts":"2026-08-24T20:48:01.804Z","event_type":"price_change","market_id":"3802002","outcome_index":1,"market_type":"match","local_side":"away","local_uid":"2026-08-24_alvaro_guillen_meza_andrew_fenty","bid":0.6,"ask":0.61,"mid":0.605,"spread":0.01,"price":0.67,"size":413.0,"side":"SELL"}
{"ts":"2026-08-24T20:48:02.243Z","event_type":"best_bid_ask","market_id":"3824994","outcome_index":0,"market_type":"set2","local_side":"home","local_uid":"2026-08-24_angela_fita_boluda_lin_zhu","bid":0.31,"ask":0.43,"mid":0.37,"spread":0.12,"bid_size":null,"ask_size":null}
{"ts":"2026-08-24T20:48:02.243Z","event_type":"best_bid_ask","market_id":"3824994","outcome_index":1,"market_type":"set2","local_side":"away","local_uid":"2026-08-24_angela_fita_boluda_lin_zhu","bid":0.57,"ask":0.69,"mid":0.63,"spread":0.12,"bid_size":null,"ask_size":null}
{"ts":"2026-08-24T20:48:02.244Z","event_type":"price_change","market_id":"3824994","outcome_index":0,"market_type":"set2","local_side":"home","local_uid":"2026-08-24_angela_fita_boluda_lin_zhu","bid":0.31,"ask":0.43,"mid":0.37,"spread":0.12,"price":0.32,"size":0.0,"side":"BUY"}
{"ts":"2026-08-24T20:48:02.244Z","event_type":"price_change","market_id":"3824994","outcome_index":1,"market_type":"set2","local_side":"away","local_uid":"2026-08-24_angela_fita_boluda_lin_zhu","bid":0.57,"ask":0.69,"mid":0.63,"spread":0.12,"price":0.68,"size":0.0,"side":"SELL"}
{"ts":"2026-08-24T20:48:02.244Z","event_type":"best_bid_ask","market_id":"3824994","outcome_index":0,"market_type":"set2","local_side":"home","local_uid":"2026-08-24_angela_fita_boluda_lin_zhu","bid":0.32,"ask":0.43,"mid":0.375,"spread":0.11,"bid_size":null,"ask_size":null}
{"ts":"2026-08-24T20:48:02.244Z","event_type":"best_bid_ask","market_id":"3824994","outcome_index":1,"market_type":"set2","local_side":"away","local_uid":"2026-08-24_angela_fita_boluda_lin_zhu","bid":0.57,"ask":0.68,"mid":0.625,"spread":0.11,"bid_size":null,"ask_size":null}
{"ts":"2026-08-24T20:48:02.245Z","event_type":"price_change","market_id":"3824994","outcome_index":0,"market_type":"set2","local_side":"home","local_uid":"2026-08-24_angela_fita_boluda_lin_zhu","bid":0.32,"ask":0.43,"mid":0.375,"spread":0.11,"price":0.32,"size":88.0,"side":"BUY"}
{"ts":"2026-08-24T20:48:02.245Z","event_type":"price_change","market_id":"3824994","outcome_index":1,"market_type":"set2","local_side":"away","local_uid":"2026-08-24_angela_fita_boluda_lin_zhu","bid":0.57,"ask":0.68,"mid":0.625,"spread":0.11,"price":0.68,"size":88.0,"side":"SELL"}
{"ts":"2026-08-24T20:48:02.254Z","event_type":"best_bid_ask","market_id":"3824796","outcome_index":0,"market_type":"set2","local_side":"home","local_uid":"2026-08-24_victoria_jimenez_kasintseva_francisca_jorge","bid":0.5,"ask":0.63,"mid":0.565,"spread":0.13,"bid_size":null,"ask_size":null}
{"ts":"2026-08-24T20:48:02.254Z","event_type":"best_bid_ask","market_id":"3824796","outcome_index":1,"market_type":"set2","local_side":"away","local_uid":"2026-08-24_victoria_jimenez_kasintseva_francisca_jorge","bid":0.37,"ask":0.5,"mid":0.435,"spread":0.13,"bid_size":null,"ask_size":null}
{"ts":"2026-08-24T20:48:02.254Z","event_type":"price_change","market_id":"3824796","outcome_index":1,"market_type":"set2","local_side":"away","local_uid":"2026-08-24_victoria_jimenez_kasintseva_francisca_jorge","bid":0.37,"ask":0.5,"mid":0.435,"spread":0.13,"price":0.38,"size":0.0,"side":"BUY"}
{"ts":"2026-08-24T20:48:02.255Z","event_type":"price_change","market_id":"3824796","outcome_index":0,"market_type":"set2","local_side":"home","local_uid":"2026-08-24_victoria_jimenez_kasintseva_francisca_jorge","bid":0.5,"ask":0.63,"mid":0.565,"spread":0.13,"price":0.62,"size":0.0,"side":"SELL"}
{"ts":"2026-08-24T20:48:02.286Z","event_type":"best_bid_ask","market_id":"3824796","outcome_index":0,"market_type":"set2","local_side":"home","local_uid":"2026-08-24_victoria_jimenez_kasintseva_francisca_jorge","bid":0.5,"ask":0.66,"mid":0.58,"spread":0.16,"bid_size":null,"ask_size":null}
{"ts":"2026-08-24T20:48:02.286Z","event_type":"best_bid_ask","market_id":"3824796","outcome_index":1,"market_type":"set2","local_side":"away","local_uid":"2026-08-24_victoria_jimenez_kasintseva_francisca_jorge","bid":0.34,"ask":0.5,"mid":0.42,"spread":0.16,"bid_size":null,"ask_size":null}
{"ts":"2026-08-24T20:48:02.287Z","event_type":"price_change","market_id":"3824796","outcome_index":1,"market_type":"set2","local_side":"away","local_uid":"2026-08-24_victoria_jimenez_kasintseva_francisca_jorge","bid":0.34,"ask":0.5,"mid":0.42,"spread":0.16,"price":0.37,"size":0.0,"side":"BUY"}
{"ts":"2026-08-24T20:48:02.287Z","event_type":"price_change","market_id":"3824796","outcome_index":0,"market_type":"set2","local_side":"home","local_uid":"2026-08-24_victoria_jimenez_kasintseva_francisca_jorge","bid":0.5,"ask":0.66,"mid":0.58,"spread":0.16,"price":0.63,"size":0.0,"side":"SELL"}
{"ts":"2026-08-24T20:48:02.293Z","event_type":"best_bid_ask","market_id":"3824796","outcome_index":0,"market_type":"set2","local_side":"home","local_uid":"2026-08-24_victoria_jimenez_kasintseva_francisca_jorge","bid":0.5,"ask":0.65,"mid":0.575,"spread":0.15,"bid_size":null,"ask_size":null}
{"ts":"2026-08-24T20:48:02.293Z","event_type":"best_bid_ask","market_id":"3824796","outcome_index":1,"market_type":"set2","local_side":"away","local_uid":"2026-08-24_victoria_jimenez_kasintseva_francisca_jorge","bid":0.35,"ask":0.5,"mid":0.425,"spread":0.15,"bid_size":null,"ask_size":null}
{"ts":"2026-08-24T20:48:02.293Z","event_type":"price_change","market_id":"3824796","outcome_index":1,"market_type":"set2","local_side":"away","local_uid":"2026-08-24_victoria_jimenez_kasintseva_francisca_jorge","bid":0.35,"ask":0.5,"mid":0.425,"spread":0.15,"price":0.35,"size":6.0,"side":"BUY"}
{"ts":"2026-08-24T20:48:02.294Z","event_type":"price_change","market_id":"3824796","outcome_index":0,"market_type":"set2","local_side":"home","local_uid":"2026-08-24_victoria_jimenez_kasintseva_francisca_jorge","bid":0.5,"ask":0.65,"mid":0.575,"spread":0.15,"price":0.65,"size":6.0,"side":"SELL"}
{"ts":"2026-08-24T20:48:02.314Z","event_type":"best_bid_ask","market_id":"3824994","outcome_index":0,"market_type":"set2","local_side":"home","local_uid":"2026-08-24_angela_fita_boluda_lin_zhu","bid":0.33,"ask":0.43,"mid":0.38,"spread":0.1,"bid_size":null,"ask_size":null}
{"ts":"2026-08-24T20:48:02.315Z","event_type":"best_bid_ask","market_id":"3824994","outcome_index":1,"market_type":"set2","local_side":"away","local_uid":"2026-08-24_angela_fita_boluda_lin_zhu","bid":0.57,"ask":0.67,"mid":0.62,"spread":0.1,"bid_size":null,"ask_size":null}
{"ts":"2026-08-24T20:48:02.315Z","event_type":"price_change","market_id":"3824994","outcome_index":0,"market_type":"set2","local_side":"home","local_uid":"2026-08-24_angela_fita_boluda_lin_zhu","bid":0.33,"ask":0.43,"mid":0.38,"spread":0.1,"price":0.33,"size":150.0,"side":"BUY"}
{"ts":"2026-08-24T20:48:02.315Z","event_type":"price_change","market_id":"3824994","outcome_index":1,"market_type":"set2","local_side":"away","local_uid":"2026-08-24_angela_fita_boluda_lin_zhu","bid":0.57,"ask":0.67,"mid":0.62,"spread":0.1,"price":0.67,"size":150.0,"side":"SELL"}
{"ts":"2026-08-24T20:48:02.340Z","event_type":"best_bid_ask","market_id":"3824994","outcome_index":0,"market_type":"set2","local_side":"home","local_uid":"2026-08-24_angela_fita_boluda_lin_zhu","bid":0.33,"ask":0.42,"mid":0.375,"spread":0.09,"bid_size":null,"ask_size":null}
{"ts":"2026-08-24T20:48:02.340Z","event_type":"best_bid_ask","market_id":"3824994","outcome_index":1,"market_type":"set2","local_side":"away","local_uid":"2026-08-24_angela_fita_boluda_lin_zhu","bid":0.58,"ask":0.67,"mid":0.625,"spread":0.09,"bid_size":null,"ask_size":null}
{"ts":"2026-08-24T20:48:02.341Z","event_type":"price_change","market_id":"3824994","outcome_index":1,"market_type":"set2","local_side":"away","local_uid":"2026-08-24_angela_fita_boluda_lin_zhu","bid":0.58,"ask":0.67,"mid":0.625,"spread":0.09,"price":0.58,"size":150.0,"side":"BUY"}
{"ts":"2026-08-24T20:48:02.341Z","event_type":"price_change","market_id":"3824994","outcome_index":0,"market_type":"set2","local_side":"home","local_uid":"2026-08-24_angela_fita_boluda_lin_zhu","bid":0.33,"ask":0.42,"mid":0.375,"spread":0.09,"price":0.42,"size":150.0,"side":"SELL"}
{"ts":"2026-08-24T20:48:02.373Z","event_type":"best_bid_ask","market_id":"3824796","outcome_index":0,"market_type":"set2","local_side":"home","local_uid":"2026-08-24_victoria_jimenez_kasintseva_francisca_jorge","bid":0.47,"ask":0.65,"mid":0.56,"spread":0.18,"bid_size":null,"ask_size":null}
{"ts":"2026-08-24T20:48:02.377Z","event_type":"best_bid_ask","market_id":"3824796","outcome_index":1,"market_type":"set2","local_side":"away","local_uid":"2026-08-24_victoria_jimenez_kasintseva_francisca_jorge","bid":0.35,"ask":0.53,"mid":0.44,"spread":0.18,"bid_size":null,"ask_size":null}
{"ts":"2026-08-24T20:48:02.377Z","event_type":"price_change","market_id":"3824796","outcome_index":0,"market_type":"set2","local_side":"home","local_uid":"2026-08-24_victoria_jimenez_kasintseva_francisca_jorge","bid":0.47,"ask":0.65,"mid":0.56,"spread":0.18,"price":0.5,"size":0.0,"side":"BUY"}
{"ts":"2026-08-24T20:48:02.378Z","event_type":"price_change","market_id":"3824796","outcome_index":1,"market_type":"set2","local_side":"away","local_uid":"2026-08-24_victoria_jimenez_kasintseva_francisca_jorge","bid":0.35,"ask":0.53,"mid":0.44,"spread":0.18,"price":0.5,"size":0.0,"side":"SELL"}
{"ts":"2026-08-24T20:48:02.378Z","event_type":"best_bid_ask","market_id":"3824796","outcome_index":0,"market_type":"set2","local_side":"home","local_uid":"2026-08-24_victoria_jimenez_kasintseva_francisca_jorge","bid":0.46,"ask":0.65,"mid":0.555,"spread":0.19,"bid_size":null,"ask_size":null}
{"ts":"2026-08-24T20:48:02.379Z","event_type":"best_bid_ask","market_id":"3824796","outcome_index":1,"market_type":"set2","local_side":"away","local_uid":"2026-08-24_victoria_jimenez_kasintseva_francisca_jorge","bid":0.35,"ask":0.54,"mid":0.445,"spread":0.19,"bid_size":null,"ask_size":null}
{"ts":"2026-08-24T20:48:02.379Z","event_type":"price_change","market_id":"3824796","outcome_index":0,"market_type":"set2","local_side":"home","local_uid":"2026-08-24_victoria_jimenez_kasintseva_francisca_jorge","bid":0.46,"ask":0.65,"mid":0.555,"spread":0.19,"price":0.47,"size":0.0,"side":"BUY"}
{"ts":"2026-08-24T20:48:02.379Z","event_type":"price_change","market_id":"3824796","outcome_index":1,"market_type":"set2","local_side":"away","local_uid":"2026-08-24_victoria_jimenez_kasintseva_francisca_jorge","bid":0.35,"ask":0.54,"mid":0.445,"spread":0.19,"price":0.53,"size":0.0,"side":"SELL"}
{"ts":"2026-08-24T20:48:02.380Z","event_type":"best_bid_ask","market_id":"3824796","outcome_index":0,"market_type":"set2","local_side":"home","local_uid":"2026-08-24_victoria_jimenez_kasintseva_francisca_jorge","bid":0.47,"ask":0.65,"mid":0.56,"spread":0.18,"bid_size":null,"ask_size":null}
{"ts":"2026-08-24T20:48:02.381Z","event_type":"best_bid_ask","market_id":"3824796","outcome_index":1,"market_type":"set2","local_side":"away","local_uid":"2026-08-24_victoria_jimenez_kasintseva_francisca_jorge","bid":0.35,"ask":0.53,"mid":0.44,"spread":0.18,"bid_size":null,"ask_size":null}
{"ts":"2026-08-24T20:48:02.381Z","event_type":"price_change","market_id":"3824796","outcome_index":0,"market_type":"set2","local_side":"home","local_uid":"2026-08-24_victoria_jimenez_kasintseva_francisca_jorge","bid":0.47,"ask":0.65,"mid":0.56,"spread":0.18,"price":0.47,"size":20.66,"side":"BUY"}
{"ts":"2026-08-24T20:48:02.381Z","event_type":"price_change","market_id":"3824796","outcome_index":1,"market_type":"set2","local_side":"away","local_uid":"2026-08-24_victoria_jimenez_kasintseva_francisca_jorge","bid":0.35,"ask":0.53,"mid":0.44,"spread":0.18,"price":0.53,"size":20.66,"side":"SELL"}
{"ts":"2026-08-24T20:48:02.418Z","event_type":"best_bid_ask","market_id":"3824796","outcome_index":0,"market_type":"set2","local_side":"home","local_uid":"2026-08-24_victoria_jimenez_kasintseva_francisca_jorge","bid":0.46,"ask":0.65,"mid":0.555,"spread":0.19,"bid_size":null,"ask_size":null}
{"ts":"2026-08-24T20:48:02.419Z","event_type":"best_bid_ask","market_id":"3824796","outcome_index":1,"market_type":"set2","local_side":"away","local_uid":"2026-08-24_victoria_jimenez_kasintseva_francisca_jorge","bid":0.35,"ask":0.54,"mid":0.445,"spread":0.19,"bid_size":null,"ask_size":null}
{"ts":"2026-08-24T20:48:02.419Z","event_type":"price_change","market_id":"3824796","outcome_index":0,"market_type":"set2","local_side":"home","local_uid":"2026-08-24_victoria_jimenez_kasintseva_francisca_jorge","bid":0.46,"ask":0.65,"mid":0.555,"spread":0.19,"price":0.47,"size":0.0,"side":"BUY"}
{"ts":"2026-08-24T20:48:02.419Z","event_type":"price_change","market_id":"3824796","outcome_index":1,"market_type":"set2","local_side":"away","local_uid":"2026-08-24_victoria_jimenez_kasintseva_francisca_jorge","bid":0.35,"ask":0.54,"mid":0.445,"spread":0.19,"price":0.53,"size":0.0,"side":"SELL"}
{"ts":"2026-08-24T20:48:02.437Z","event_type":"best_bid_ask","market_id":"3826641","outcome_index":0,"market_type":"set2","local_side":"home","local_uid":"2026-08-24_jan_choinski_mees_rottgering","bid":0.49,"ask":0.61,"mid":0.55,"spread":0.12,"bid_size":null,"ask_size":null}
{"ts":"2026-08-24T20:48:02.438Z","event_type":"best_bid_ask","market_id":"3826641","outcome_index":1,"market_type":"set2","local_side":"away","local_uid":"2026-08-24_jan_choinski_mees_rottgering","bid":0.39,"ask":0.51,"mid":0.45,"spread":0.12,"bid_size":null,"ask_size":null}
{"ts":"2026-08-24T20:48:02.438Z","event_type":"price_change","market_id":"3826641","outcome_index":0,"market_type":"set2","local_side":"home","local_uid":"2026-08-24_jan_choinski_mees_rottgering","bid":0.49,"ask":0.61,"mid":0.55,"spread":0.12,"price":0.5,"size":0.0,"side":"BUY"}
{"ts":"2026-08-24T20:48:02.438Z","event_type":"price_change","market_id":"3826641","outcome_index":1,"market_type":"set2","local_side":"away","local_uid":"2026-08-24_jan_choinski_mees_rottgering","bid":0.39,"ask":0.51,"mid":0.45,"spread":0.12,"price":0.5,"size":0.0,"side":"SELL"}
{"ts":"2026-08-24T20:48:02.460Z","event_type":"best_bid_ask","market_id":"3826641","outcome_index":0,"market_type":"set2","local_side":"home","local_uid":"2026-08-24_jan_choinski_mees_rottgering","bid":0.48,"ask":0.61,"mid":0.545,"spread":0.13,"bid_size":null,"ask_size":null}
{"ts":"2026-08-24T20:48:02.461Z","event_type":"best_bid_ask","market_id":"3826641","outcome_index":1,"market_type":"set2","local_side":"away","local_uid":"2026-08-24_jan_choinski_mees_rottgering","bid":0.39,"ask":0.52,"mid":0.455,"spread":0.13,"bid_size":null,"ask_size":null}
{"ts":"2026-08-24T20:48:02.461Z","event_type":"price_change","market_id":"3826641","outcome_index":0,"market_type":"set2","local_side":"home","local_uid":"2026-08-24_jan_choinski_mees_rottgering","bid":0.48,"ask":0.61,"mid":0.545,"spread":0.13,"price":0.49,"size":0.0,"side":"BUY"}
{"ts":"2026-08-24T20:48:02.461Z","event_type":"price_change","market_id":"3826641","outcome_index":1,"market_type":"set2","local_side":"away","local_uid":"2026-08-24_jan_choinski_mees_rottgering","bid":0.39,"ask":0.52,"mid":0.455,"spread":0.13,"price":0.51,"size":0.0,"side":"SELL"}
{"ts":"2026-08-24T20:48:02.463Z","event_type":"best_bid_ask","market_id":"3824796","outcome_index":0,"market_type":"set2","local_side":"home","local_uid":"2026-08-24_victoria_jimenez_kasintseva_francisca_jorge","bid":0.46,"ask":0.64,"mid":0.55,"spread":0.18,"bid_size":null,"ask_size":null}
{"ts":"2026-08-24T20:48:02.463Z","event_type":"best_bid_ask","market_id":"3824796","outcome_index":1,"market_type":"set2","local_side":"away","local_uid":"2026-08-24_victoria_jimenez_kasintseva_francisca_jorge","bid":0.36,"ask":0.54,"mid":0.45,"spread":0.18,"bid_size":null,"ask_size":null}
{"ts":"2026-08-24T20:48:02.464Z","event_type":"price_change","market_id":"3824796","outcome_index":1,"market_type":"set2","local_side":"away","local_uid":"2026-08-24_victoria_jimenez_kasintseva_francisca_jorge","bid":0.36,"ask":0.54,"mid":0.45,"spread":0.18,"price":0.36,"size":50.0,"side":"BUY"}
{"ts":"2026-08-24T20:48:02.464Z","event_type":"price_change","market_id":"3824796","outcome_index":0,"market_type":"set2","local_side":"home","local_uid":"2026-08-24_victoria_jimenez_kasintseva_francisca_jorge","bid":0.46,"ask":0.64,"mid":0.55,"spread":0.18,"price":0.64,"size":50.0,"side":"SELL"}
{"ts":"2026-08-24T20:48:02.501Z","event_type":"price_change","market_id":"3825596","outcome_index":1,"market_type":"match","local_side":"away","local_uid":"2026-08-24_toby_samuel_francesco_maestrelli","bid":0.001,"ask":0.012,"mid":0.0065,"spread":0.011,"price":0.001,"size":9.08,"side":"BUY"}
{"ts":"2026-08-24T20:48:02.501Z","event_type":"price_change","market_id":"3825596","outcome_index":0,"market_type":"match","local_side":"home","local_uid":"2026-08-24_toby_samuel_francesco_maestrelli","bid":0.988,"ask":0.999,"mid":0.9935,"spread":0.011,"price":0.999,"size":9.08,"side":"SELL"}
{"ts":"2026-08-24T20:48:02.544Z","event_type":"best_bid_ask","market_id":"3826641","outcome_index":0,"market_type":"set2","local_side":"home","local_uid":"2026-08-24_jan_choinski_mees_rottgering","bid":0.48,"ask":0.63,"mid":0.555,"spread":0.15,"bid_size":null,"ask_size":null}
{"ts":"2026-08-24T20:48:02.544Z","event_type":"best_bid_ask","market_id":"3826641","outcome_index":1,"market_type":"set2","local_side":"away","local_uid":"2026-08-24_jan_choinski_mees_rottgering","bid":0.37,"ask":0.52,"mid":0.445,"spread":0.15,"bid_size":null,"ask_size":null}
{"ts":"2026-08-24T20:48:02.544Z","event_type":"price_change","market_id":"3826641","outcome_index":1,"market_type":"set2","local_side":"away","local_uid":"2026-08-24_jan_choinski_mees_rottgering","bid":0.37,"ask":0.52,"mid":0.445,"spread":0.15,"price":0.39,"size":0.0,"side":"BUY"}
{"ts":"2026-08-24T20:48:02.545Z","event_type":"price_change","market_id":"3826641","outcome_index":0,"market_type":"set2","local_side":"home","local_uid":"2026-08-24_jan_choinski_mees_rottgering","bid":0.48,"ask":0.63,"mid":0.555,"spread":0.15,"price":0.61,"size":0.0,"side":"SELL"}
{"ts":"2026-08-24T20:48:02.606Z","event_type":"best_bid_ask","market_id":"3824796","outcome_index":0,"market_type":"set2","local_side":"home","local_uid":"2026-08-24_victoria_jimenez_kasintseva_francisca_jorge","bid":0.46,"ask":0.65,"mid":0.555,"spread":0.19,"bid_size":null,"ask_size":null}
{"ts":"2026-08-24T20:48:02.606Z","event_type":"best_bid_ask","market_id":"3824796","outcome_index":1,"market_type":"set2","local_side":"away","local_uid":"2026-08-24_victoria_jimenez_kasintseva_francisca_jorge","bid":0.35,"ask":0.54,"mid":0.445,"spread":0.19,"bid_size":null,"ask_size":null}
{"ts":"2026-08-24T20:48:02.607Z","event_type":"price_change","market_id":"3824796","outcome_index":1,"market_type":"set2","local_side":"away","local_uid":"2026-08-24_victoria_jimenez_kasintseva_francisca_jorge","bid":0.35,"ask":0.54,"mid":0.445,"spread":0.19,"price":0.36,"size":0.0,"side":"BUY"}
{"ts":"2026-08-24T20:48:02.607Z","event_type":"price_change","market_id":"3824796","outcome_index":0,"market_type":"set2","local_side":"home","local_uid":"2026-08-24_victoria_jimenez_kasintseva_francisca_jorge","bid":0.46,"ask":0.65,"mid":0.555,"spread":0.19,"price":0.64,"size":0.0,"side":"SELL"}
{"ts":"2026-08-24T20:48:02.690Z","event_type":"best_bid_ask","market_id":"3823659","outcome_index":0,"market_type":"match","local_side":"home","local_uid":"2026-08-24_victoria_jimenez_kasintseva_francisca_jorge","bid":0.34,"ask":0.37,"mid":0.355,"spread":0.03,"bid_size":null,"ask_size":null}
{"ts":"2026-08-24T20:48:02.691Z","event_type":"best_bid_ask","market_id":"3823659","outcome_index":1,"market_type":"match","local_side":"away","local_uid":"2026-08-24_victoria_jimenez_kasintseva_francisca_jorge","bid":0.63,"ask":0.66,"mid":0.645,"spread":0.03,"bid_size":null,"ask_size":null}
{"ts":"2026-08-24T20:48:02.691Z","event_type":"price_change","market_id":"3823659","outcome_index":0,"market_type":"match","local_side":"home","local_uid":"2026-08-24_victoria_jimenez_kasintseva_francisca_jorge","bid":0.34,"ask":0.37,"mid":0.355,"spread":0.03,"price":0.36,"size":0.0,"side":"BUY"}
{"ts":"2026-08-24T20:48:02.691Z","event_type":"price_change","market_id":"3823659","outcome_index":1,"market_type":"match","local_side":"away","local_uid":"2026-08-24_victoria_jimenez_kasintseva_francisca_jorge","bid":0.63,"ask":0.66,"mid":0.645,"spread":0.03,"price":0.64,"size":0.0,"side":"SELL"}
{"ts":"2026-08-24T20:48:02.692Z","event_type":"best_bid_ask","market_id":"3823659","outcome_index":0,"market_type":"match","local_side":"home","local_uid":"2026-08-24_victoria_jimenez_kasintseva_francisca_jorge","bid":0.35,"ask":0.37,"mid":0.36,"spread":0.02,"bid_size":null,"ask_size":null}
{"ts":"2026-08-24T20:48:02.692Z","event_type":"best_bid_ask","market_id":"3823659","outcome_index":1,"market_type":"match","local_side":"away","local_uid":"2026-08-24_victoria_jimenez_kasintseva_francisca_jorge","bid":0.63,"ask":0.65,"mid":0.64,"spread":0.02,"bid_size":null,"ask_size":null}
{"ts":"2026-08-24T20:48:02.692Z","event_type":"price_change","market_id":"3823659","outcome_index":0,"market_type":"match","local_side":"home","local_uid":"2026-08-24_victoria_jimenez_kasintseva_francisca_jorge","bid":0.35,"ask":0.37,"mid":0.36,"spread":0.02,"price":0.35,"size":20.0,"side":"BUY"}
{"ts":"2026-08-24T20:48:02.693Z","event_type":"price_change","market_id":"3823659","outcome_index":1,"market_type":"match","local_side":"away","local_uid":"2026-08-24_victoria_jimenez_kasintseva_francisca_jorge","bid":0.63,"ask":0.65,"mid":0.64,"spread":0.02,"price":0.65,"size":20.0,"side":"SELL"}
{"ts":"2026-08-24T20:48:02.731Z","event_type":"best_bid_ask","market_id":"3823659","outcome_index":0,"market_type":"match","local_side":"home","local_uid":"2026-08-24_victoria_jimenez_kasintseva_francisca_jorge","bid":0.35,"ask":0.38,"mid":0.365,"spread":0.03,"bid_size":null,"ask_size":null}
{"ts":"2026-08-24T20:48:02.731Z","event_type":"best_bid_ask","market_id":"3823659","outcome_index":1,"market_type":"match","local_side":"away","local_uid":"2026-08-24_victoria_jimenez_kasintseva_francisca_jorge","bid":0.62,"ask":0.65,"mid":0.635,"spread":0.03,"bid_size":null,"ask_size":null}
{"ts":"2026-08-24T20:48:02.731Z","event_type":"price_change","market_id":"3823659","outcome_index":0,"market_type":"match","local_side":"home","local_uid":"2026-08-24_victoria_jimenez_kasintseva_francisca_jorge","bid":0.35,"ask":0.38,"mid":0.365,"spread":0.03,"price":0.34,"size":0.0,"side":"BUY"}
{"ts":"2026-08-24T20:48:02.732Z","event_type":"price_change","market_id":"3823659","outcome_index":1,"market_type":"match","local_side":"away","local_uid":"2026-08-24_victoria_jimenez_kasintseva_francisca_jorge","bid":0.62,"ask":0.65,"mid":0.635,"spread":0.03,"price":0.66,"size":0.0,"side":"SELL"}
{"ts":"2026-08-24T20:48:02.761Z","event_type":"best_bid_ask","market_id":"3823659","outcome_index":0,"market_type":"match","local_side":"home","local_uid":"2026-08-24_victoria_jimenez_kasintseva_francisca_jorge","bid":0.33,"ask":0.38,"mid":0.355,"spread":0.05,"bid_size":null,"ask_size":null}
{"ts":"2026-08-24T20:48:02.762Z","event_type":"best_bid_ask","market_id":"3823659","outcome_index":1,"market_type":"match","local_side":"away","local_uid":"2026-08-24_victoria_jimenez_kasintseva_francisca_jorge","bid":0.62,"ask":0.67,"mid":0.645,"spread":0.05,"bid_size":null,"ask_size":null}
{"ts":"2026-08-24T20:48:02.762Z","event_type":"price_change","market_id":"3823659","outcome_index":0,"market_type":"match","local_side":"home","local_uid":"2026-08-24_victoria_jimenez_kasintseva_francisca_jorge","bid":0.33,"ask":0.38,"mid":0.355,"spread":0.05,"price":0.35,"size":0.0,"side":"BUY"}
{"ts":"2026-08-24T20:48:02.762Z","event_type":"price_change","market_id":"3823659","outcome_index":1,"market_type":"match","local_side":"away","local_uid":"2026-08-24_victoria_jimenez_kasintseva_francisca_jorge","bid":0.62,"ask":0.67,"mid":0.645,"spread":0.05,"price":0.65,"size":0.0,"side":"SELL"}
{"ts":"2026-08-24T20:48:02.767Z","event_type":"best_bid_ask","market_id":"3823659","outcome_index":0,"market_type":"match","local_side":"home","local_uid":"2026-08-24_victoria_jimenez_kasintseva_francisca_jorge","bid":0.34,"ask":0.38,"mid":0.36,"spread":0.04,"bid_size":null,"ask_size":null}
{"ts":"2026-08-24T20:48:02.767Z","event_type":"best_bid_ask","market_id":"3823659","outcome_index":1,"market_type":"match","local_side":"away","local_uid":"2026-08-24_victoria_jimenez_kasintseva_francisca_jorge","bid":0.62,"ask":0.66,"mid":0.64,"spread":0.04,"bid_size":null,"ask_size":null}
{"ts":"2026-08-24T20:48:02.768Z","event_type":"price_change","market_id":"3823659","outcome_index":0,"market_type":"match","local_side":"home","local_uid":"2026-08-24_victoria_jimenez_kasintseva_francisca_jorge","bid":0.34,"ask":0.38,"mid":0.36,"spread":0.04,"price":0.34,"size":20.0,"side":"BUY"}
{"ts":"2026-08-24T20:48:02.768Z","event_type":"price_change","market_id":"3823659","outcome_index":1,"market_type":"match","local_side":"away","local_uid":"2026-08-24_victoria_jimenez_kasintseva_francisca_jorge","bid":0.62,"ask":0.66,"mid":0.64,"spread":0.04,"price":0.66,"size":20.0,"side":"SELL"}
{"ts":"2026-08-24T20:48:02.772Z","event_type":"best_bid_ask","market_id":"3825077","outcome_index":0,"market_type":"set1","local_side":"home","local_uid":"2026-08-24_polina_kudermetova_linda_fruhvirtova","bid":0.45,"ask":0.55,"mid":0.5,"spread":0.1,"bid_size":null,"ask_size":null}
{"ts":"2026-08-24T20:48:02.772Z","event_type":"best_bid_ask","market_id":"3825077","outcome_index":1,"market_type":"set1","local_side":"away","local_uid":"2026-08-24_polina_kudermetova_linda_fruhvirtova","bid":0.45,"ask":0.55,"mid":0.5,"spread":0.1,"bid_size":null,"ask_size":null}
{"ts":"2026-08-24T20:48:02.773Z","event_type":"price_change","market_id":"3825077","outcome_index":1,"market_type":"set1","local_side":"away","local_uid":"2026-08-24_polina_kudermetova_linda_fruhvirtova","bid":0.45,"ask":0.55,"mid":0.5,"spread":0.1,"price":0.45,"size":45.26,"side":"BUY"}
{"ts":"2026-08-24T20:48:02.773Z","event_type":"price_change","market_id":"3825077","outcome_index":0,"market_type":"set1","local_side":"home","local_uid":"2026-08-24_polina_kudermetova_linda_fruhvirtova","bid":0.45,"ask":0.55,"mid":0.5,"spread":0.1,"price":0.55,"size":45.26,"side":"SELL"}
{"ts":"2026-08-24T20:48:03.074Z","event_type":"best_bid_ask","market_id":"3825641","outcome_index":0,"market_type":"match","local_side":"home","local_uid":"2026-08-24_sebastian_gorzny_cruz_hewitt","bid":0.6,"ask":0.64,"mid":0.62,"spread":0.04,"bid_size":null,"ask_size":null}
{"ts":"2026-08-24T20:48:03.074Z","event_type":"best_bid_ask","market_id":"3825641","outcome_index":1,"market_type":"match","local_side":"away","local_uid":"2026-08-24_sebastian_gorzny_cruz_hewitt","bid":0.36,"ask":0.4,"mid":0.38,"spread":0.04,"bid_size":null,"ask_size":null}
{"ts":"2026-08-24T20:48:03.086Z","event_type":"price_change","market_id":"3825641","outcome_index":1,"market_type":"match","local_side":"away","local_uid":"2026-08-24_sebastian_gorzny_cruz_hewitt","bid":0.36,"ask":0.4,"mid":0.38,"spread":0.04,"price":0.36,"size":77.0,"side":"BUY"}
{"ts":"2026-08-24T20:48:03.086Z","event_type":"price_change","market_id":"3825641","outcome_index":0,"market_type":"match","local_side":"home","local_uid":"2026-08-24_sebastian_gorzny_cruz_hewitt","bid":0.6,"ask":0.64,"mid":0.62,"spread":0.04,"price":0.64,"size":77.0,"side":"SELL"}
{"ts":"2026-08-24T20:48:03.087Z","event_type":"book","market_id":"3825641","outcome_index":0,"market_type":"match","local_side":"home","local_uid":"2026-08-24_sebastian_gorzny_cruz_hewitt","bid":0.6,"ask":0.64,"mid":0.62,"spread":0.04,"bid_size":99.5,"ask_size":77.0}
{"ts":"2026-08-24T20:48:03.088Z","event_type":"book","market_id":"3825641","outcome_index":1,"market_type":"match","local_side":"away","local_uid":"2026-08-24_sebastian_gorzny_cruz_hewitt","bid":0.36,"ask":0.4,"mid":0.38,"spread":0.04,"bid_size":77.0,"ask_size":99.5}
{"ts":"2026-08-24T20:48:03.117Z","event_type":"best_bid_ask","market_id":"3825641","outcome_index":0,"market_type":"match","local_side":"home","local_uid":"2026-08-24_sebastian_gorzny_cruz_hewitt","bid":0.6,"ask":0.63,"mid":0.615,"spread":0.03,"bid_size":null,"ask_size":null}
{"ts":"2026-08-24T20:48:03.117Z","event_type":"best_bid_ask","market_id":"3825641","outcome_index":1,"market_type":"match","local_side":"away","local_uid":"2026-08-24_sebastian_gorzny_cruz_hewitt","bid":0.37,"ask":0.4,"mid":0.385,"spread":0.03,"bid_size":null,"ask_size":null}
{"ts":"2026-08-24T20:48:03.118Z","event_type":"price_change","market_id":"3825641","outcome_index":1,"market_type":"match","local_side":"away","local_uid":"2026-08-24_sebastian_gorzny_cruz_hewitt","bid":0.37,"ask":0.4,"mid":0.385,"spread":0.03,"price":0.37,"size":20.0,"side":"BUY"}
{"ts":"2026-08-24T20:48:03.118Z","event_type":"price_change","market_id":"3825641","outcome_index":0,"market_type":"match","local_side":"home","local_uid":"2026-08-24_sebastian_gorzny_cruz_hewitt","bid":0.6,"ask":0.63,"mid":0.615,"spread":0.03,"price":0.63,"size":20.0,"side":"SELL"}
{"ts":"2026-08-24T20:48:03.241Z","event_type":"best_bid_ask","market_id":"3824796","outcome_index":0,"market_type":"set2","local_side":"home","local_uid":"2026-08-24_victoria_jimenez_kasintseva_francisca_jorge","bid":0.46,"ask":0.67,"mid":0.565,"spread":0.21,"bid_size":null,"ask_size":null}
{"ts":"2026-08-24T20:48:03.241Z","event_type":"best_bid_ask","market_id":"3824796","outcome_index":1,"market_type":"set2","local_side":"away","local_uid":"2026-08-24_victoria_jimenez_kasintseva_francisca_jorge","bid":0.33,"ask":0.54,"mid":0.435,"spread":0.21,"bid_size":null,"ask_size":null}
{"ts":"2026-08-24T20:48:03.242Z","event_type":"price_change","market_id":"3824796","outcome_index":1,"market_type":"set2","local_side":"away","local_uid":"2026-08-24_victoria_jimenez_kasintseva_francisca_jorge","bid":0.33,"ask":0.54,"mid":0.435,"spread":0.21,"price":0.35,"size":0.0,"side":"BUY"}
{"ts":"2026-08-24T20:48:03.242Z","event_type":"price_change","market_id":"3824796","outcome_index":0,"market_type":"set2","local_side":"home","local_uid":"2026-08-24_victoria_jimenez_kasintseva_francisca_jorge","bid":0.46,"ask":0.67,"mid":0.565,"spread":0.21,"price":0.65,"size":0.0,"side":"SELL"}
{"ts":"2026-08-24T20:48:03.275Z","event_type":"last_trade_price","market_id":"3825641","outcome_index":1,"market_type":"match","local_side":"away","local_uid":"2026-08-24_sebastian_gorzny_cruz_hewitt","last_trade":0.36,"trade_size":23.0,"trade_side":"BUY","trade_notional":8.28}
{"ts":"2026-08-24T20:48:03.313Z","event_type":"best_bid_ask","market_id":"3824796","outcome_index":0,"market_type":"set2","local_side":"home","local_uid":"2026-08-24_victoria_jimenez_kasintseva_francisca_jorge","bid":0.46,"ask":0.66,"mid":0.56,"spread":0.2,"bid_size":null,"ask_size":null}
{"ts":"2026-08-24T20:48:03.313Z","event_type":"best_bid_ask","market_id":"3824796","outcome_index":1,"market_type":"set2","local_side":"away","local_uid":"2026-08-24_victoria_jimenez_kasintseva_francisca_jorge","bid":0.34,"ask":0.54,"mid":0.44,"spread":0.2,"bid_size":null,"ask_size":null}
{"ts":"2026-08-24T20:48:03.313Z","event_type":"price_change","market_id":"3824796","outcome_index":1,"market_type":"set2","local_side":"away","local_uid":"2026-08-24_victoria_jimenez_kasintseva_francisca_jorge","bid":0.34,"ask":0.54,"mid":0.44,"spread":0.2,"price":0.34,"size":28.04,"side":"BUY"}
{"ts":"2026-08-24T20:48:03.314Z","event_type":"price_change","market_id":"3824796","outcome_index":0,"market_type":"set2","local_side":"home","local_uid":"2026-08-24_victoria_jimenez_kasintseva_francisca_jorge","bid":0.46,"ask":0.66,"mid":0.56,"spread":0.2,"price":0.66,"size":28.04,"side":"SELL"}
{"ts":"2026-08-24T20:48:03.324Z","event_type":"best_bid_ask","market_id":"3823619","outcome_index":0,"market_type":"match","local_side":"home","local_uid":"2026-08-24_polina_kudermetova_linda_fruhvirtova","bid":0.55,"ask":0.57,"mid":0.56,"spread":0.02,"bid_size":null,"ask_size":null}
{"ts":"2026-08-24T20:48:03.324Z","event_type":"best_bid_ask","market_id":"3823619","outcome_index":1,"market_type":"match","local_side":"away","local_uid":"2026-08-24_polina_kudermetova_linda_fruhvirtova","bid":0.43,"ask":0.45,"mid":0.44,"spread":0.02,"bid_size":null,"ask_size":null}
{"ts":"2026-08-24T20:48:03.324Z","event_type":"price_change","market_id":"3823619","outcome_index":1,"market_type":"match","local_side":"away","local_uid":"2026-08-24_polina_kudermetova_linda_fruhvirtova","bid":0.43,"ask":0.45,"mid":0.44,"spread":0.02,"price":0.43,"size":1500.0,"side":"BUY"}
{"ts":"2026-08-24T20:48:03.324Z","event_type":"price_change","market_id":"3823619","outcome_index":0,"market_type":"match","local_side":"home","local_uid":"2026-08-24_polina_kudermetova_linda_fruhvirtova","bid":0.55,"ask":0.57,"mid":0.56,"spread":0.02,"price":0.57,"size":1500.0,"side":"SELL"}
{"ts":"2026-08-24T20:48:03.329Z","event_type":"best_bid_ask","market_id":"3823619","outcome_index":0,"market_type":"match","local_side":"home","local_uid":"2026-08-24_polina_kudermetova_linda_fruhvirtova","bid":0.55,"ask":0.56,"mid":0.555,"spread":0.01,"bid_size":null,"ask_size":null}
{"ts":"2026-08-24T20:48:03.330Z","event_type":"best_bid_ask","market_id":"3823619","outcome_index":1,"market_type":"match","local_side":"away","local_uid":"2026-08-24_polina_kudermetova_linda_fruhvirtova","bid":0.44,"ask":0.45,"mid":0.445,"spread":0.01,"bid_size":null,"ask_size":null}
{"ts":"2026-08-24T20:48:03.330Z","event_type":"price_change","market_id":"3823619","outcome_index":1,"market_type":"match","local_side":"away","local_uid":"2026-08-24_polina_kudermetova_linda_fruhvirtova","bid":0.44,"ask":0.45,"mid":0.445,"spread":0.01,"price":0.44,"size":5000.0,"side":"BUY"}
{"ts":"2026-08-24T20:48:03.330Z","event_type":"price_change","market_id":"3823619","outcome_index":0,"market_type":"match","local_side":"home","local_uid":"2026-08-24_polina_kudermetova_linda_fruhvirtova","bid":0.55,"ask":0.56,"mid":0.555,"spread":0.01,"price":0.56,"size":5000.0,"side":"SELL"}
{"ts":"2026-08-24T20:48:03.366Z","event_type":"best_bid_ask","market_id":"3823619","outcome_index":0,"market_type":"match","local_side":"home","local_uid":"2026-08-24_polina_kudermetova_linda_fruhvirtova","bid":0.55,"ask":0.58,"mid":0.565,"spread":0.03,"bid_size":null,"ask_size":null}
{"ts":"2026-08-24T20:48:03.366Z","event_type":"best_bid_ask","market_id":"3823619","outcome_index":1,"market_type":"match","local_side":"away","local_uid":"2026-08-24_polina_kudermetova_linda_fruhvirtova","bid":0.42,"ask":0.45,"mid":0.435,"spread":0.03,"bid_size":null,"ask_size":null}
{"ts":"2026-08-24T20:48:03.366Z","event_type":"price_change","market_id":"3823619","outcome_index":1,"market_type":"match","local_side":"away","local_uid":"2026-08-24_polina_kudermetova_linda_fruhvirtova","bid":0.42,"ask":0.45,"mid":0.435,"spread":0.03,"price":0.44,"size":0.0,"side":"BUY"}
{"ts":"2026-08-24T20:48:03.366Z","event_type":"price_change","market_id":"3823619","outcome_index":0,"market_type":"match","local_side":"home","local_uid":"2026-08-24_polina_kudermetova_linda_fruhvirtova","bid":0.55,"ask":0.58,"mid":0.565,"spread":0.03,"price":0.56,"size":0.0,"side":"SELL"}
{"ts":"2026-08-24T20:48:03.421Z","event_type":"best_bid_ask","market_id":"3825077","outcome_index":0,"market_type":"set1","local_side":"home","local_uid":"2026-08-24_polina_kudermetova_linda_fruhvirtova","bid":0.45,"ask":0.54,"mid":0.495,"spread":0.09,"bid_size":null,"ask_size":null}
{"ts":"2026-08-24T20:48:03.421Z","event_type":"best_bid_ask","market_id":"3825077","outcome_index":1,"market_type":"set1","local_side":"away","local_uid":"2026-08-24_polina_kudermetova_linda_fruhvirtova","bid":0.46,"ask":0.55,"mid":0.505,"spread":0.09,"bid_size":null,"ask_size":null}
{"ts":"2026-08-24T20:48:03.421Z","event_type":"price_change","market_id":"3825077","outcome_index":1,"market_type":"set1","local_side":"away","local_uid":"2026-08-24_polina_kudermetova_linda_fruhvirtova","bid":0.46,"ask":0.55,"mid":0.505,"spread":0.09,"price":0.46,"size":281.0,"side":"BUY"}
{"ts":"2026-08-24T20:48:03.422Z","event_type":"price_change","market_id":"3825077","outcome_index":0,"market_type":"set1","local_side":"home","local_uid":"2026-08-24_polina_kudermetova_linda_fruhvirtova","bid":0.45,"ask":0.54,"mid":0.495,"spread":0.09,"price":0.54,"size":281.0,"side":"SELL"}
{"ts":"2026-08-24T20:48:03.459Z","event_type":"best_bid_ask","market_id":"3825070","outcome_index":0,"market_type":"set2","local_side":"home","local_uid":"2026-08-24_polina_kudermetova_linda_fruhvirtova","bid":0.5,"ask":0.62,"mid":0.56,"spread":0.12,"bid_size":null,"ask_size":null}
{"ts":"2026-08-24T20:48:03.460Z","event_type":"best_bid_ask","market_id":"3825070","outcome_index":1,"market_type":"set2","local_side":"away","local_uid":"2026-08-24_polina_kudermetova_linda_fruhvirtova","bid":0.38,"ask":0.5,"mid":0.44,"spread":0.12,"bid_size":null,"ask_size":null}
{"ts":"2026-08-24T20:48:03.462Z","event_type":"price_change","market_id":"3825070","outcome_index":0,"market_type":"set2","local_side":"home","local_uid":"2026-08-24_polina_kudermetova_linda_fruhvirtova","bid":0.5,"ask":0.62,"mid":0.56,"spread":0.12,"price":0.52,"size":0.0,"side":"BUY"}
{"ts":"2026-08-24T20:48:03.462Z","event_type":"price_change","market_id":"3825070","outcome_index":1,"market_type":"set2","local_side":"away","local_uid":"2026-08-24_polina_kudermetova_linda_fruhvirtova","bid":0.38,"ask":0.5,"mid":0.44,"spread":0.12,"price":0.48,"size":0.0,"side":"SELL"}
{"ts":"2026-08-24T20:48:03.478Z","event_type":"best_bid_ask","market_id":"3823619","outcome_index":0,"market_type":"match","local_side":"home","local_uid":"2026-08-24_polina_kudermetova_linda_fruhvirtova","bid":0.55,"ask":0.56,"mid":0.555,"spread":0.01,"bid_size":null,"ask_size":null}
{"ts":"2026-08-24T20:48:03.479Z","event_type":"best_bid_ask","market_id":"3823619","outcome_index":1,"market_type":"match","local_side":"away","local_uid":"2026-08-24_polina_kudermetova_linda_fruhvirtova","bid":0.44,"ask":0.45,"mid":0.445,"spread":0.01,"bid_size":null,"ask_size":null}
{"ts":"2026-08-24T20:48:03.479Z","event_type":"price_change","market_id":"3823619","outcome_index":1,"market_type":"match","local_side":"away","local_uid":"2026-08-24_polina_kudermetova_linda_fruhvirtova","bid":0.44,"ask":0.45,"mid":0.445,"spread":0.01,"price":0.44,"size":14025.23,"side":"BUY"}
{"ts":"2026-08-24T20:48:03.479Z","event_type":"price_change","market_id":"3823619","outcome_index":0,"market_type":"match","local_side":"home","local_uid":"2026-08-24_polina_kudermetova_linda_fruhvirtova","bid":0.55,"ask":0.56,"mid":0.555,"spread":0.01,"price":0.56,"size":14025.23,"side":"SELL"}
{"ts":"2026-08-24T20:48:03.646Z","event_type":"best_bid_ask","market_id":"3823619","outcome_index":0,"market_type":"match","local_side":"home","local_uid":"2026-08-24_polina_kudermetova_linda_fruhvirtova","bid":0.54,"ask":0.56,"mid":0.55,"spread":0.02,"bid_size":null,"ask_size":null}
{"ts":"2026-08-24T20:48:03.646Z","event_type":"best_bid_ask","market_id":"3823619","outcome_index":1,"market_type":"match","local_side":"away","local_uid":"2026-08-24_polina_kudermetova_linda_fruhvirtova","bid":0.44,"ask":0.46,"mid":0.45,"spread":0.02,"bid_size":null,"ask_size":null}
{"ts":"2026-08-24T20:48:03.646Z","event_type":"price_change","market_id":"3823619","outcome_index":0,"market_type":"match","local_side":"home","local_uid":"2026-08-24_polina_kudermetova_linda_fruhvirtova","bid":0.54,"ask":0.56,"mid":0.55,"spread":0.02,"price":0.55,"size":0.0,"side":"BUY"}
{"ts":"2026-08-24T20:48:03.646Z","event_type":"price_change","market_id":"3823619","outcome_index":1,"market_type":"match","local_side":"away","local_uid":"2026-08-24_polina_kudermetova_linda_fruhvirtova","bid":0.44,"ask":0.46,"mid":0.45,"spread":0.02,"price":0.45,"size":0.0,"side":"SELL"}
{"ts":"2026-08-24T20:48:03.750Z","event_type":"best_bid_ask","market_id":"3825077","outcome_index":0,"market_type":"set1","local_side":"home","local_uid":"2026-08-24_polina_kudermetova_linda_fruhvirtova","bid":0.45,"ask":0.51,"mid":0.48,"spread":0.06,"bid_size":null,"ask_size":null}
{"ts":"2026-08-24T20:48:03.751Z","event_type":"best_bid_ask","market_id":"3825077","outcome_index":1,"market_type":"set1","local_side":"away","local_uid":"2026-08-24_polina_kudermetova_linda_fruhvirtova","bid":0.49,"ask":0.55,"mid":0.52,"spread":0.06,"bid_size":null,"ask_size":null}
{"ts":"2026-08-24T20:48:03.751Z","event_type":"price_change","market_id":"3825077","outcome_index":1,"market_type":"set1","local_side":"away","local_uid":"2026-08-24_polina_kudermetova_linda_fruhvirtova","bid":0.49,"ask":0.55,"mid":0.52,"spread":0.06,"price":0.49,"size":423.0,"side":"BUY"}
{"ts":"2026-08-24T20:48:03.751Z","event_type":"price_change","market_id":"3825077","outcome_index":0,"market_type":"set1","local_side":"home","local_uid":"2026-08-24_polina_kudermetova_linda_fruhvirtova","bid":0.45,"ask":0.51,"mid":0.48,"spread":0.06,"price":0.51,"size":423.0,"side":"SELL"}
{"ts":"2026-08-24T20:48:03.765Z","event_type":"best_bid_ask","market_id":"3825077","outcome_index":0,"market_type":"set1","local_side":"home","local_uid":"2026-08-24_polina_kudermetova_linda_fruhvirtova","bid":0.45,"ask":0.5,"mid":0.475,"spread":0.05,"bid_size":null,"ask_size":null}
{"ts":"2026-08-24T20:48:03.765Z","event_type":"best_bid_ask","market_id":"3825077","outcome_index":1,"market_type":"set1","local_side":"away","local_uid":"2026-08-24_polina_kudermetova_linda_fruhvirtova","bid":0.5,"ask":0.55,"mid":0.525,"spread":0.05,"bid_size":null,"ask_size":null}
{"ts":"2026-08-24T20:48:03.766Z","event_type":"price_change","market_id":"3825077","outcome_index":1,"market_type":"set1","local_side":"away","local_uid":"2026-08-24_polina_kudermetova_linda_fruhvirtova","bid":0.5,"ask":0.55,"mid":0.525,"spread":0.05,"price":0.5,"size":88.0,"side":"BUY"}
{"ts":"2026-08-24T20:48:03.766Z","event_type":"price_change","market_id":"3825077","outcome_index":0,"market_type":"set1","local_side":"home","local_uid":"2026-08-24_polina_kudermetova_linda_fruhvirtova","bid":0.45,"ask":0.5,"mid":0.475,"spread":0.05,"price":0.5,"size":88.0,"side":"SELL"}
{"ts":"2026-08-24T20:48:03.773Z","event_type":"best_bid_ask","market_id":"3823619","outcome_index":0,"market_type":"match","local_side":"home","local_uid":"2026-08-24_polina_kudermetova_linda_fruhvirtova","bid":0.54,"ask":0.55,"mid":0.545,"spread":0.01,"bid_size":null,"ask_size":null}
{"ts":"2026-08-24T20:48:03.773Z","event_type":"best_bid_ask","market_id":"3823619","outcome_index":1,"market_type":"match","local_side":"away","local_uid":"2026-08-24_polina_kudermetova_linda_fruhvirtova","bid":0.45,"ask":0.46,"mid":0.455,"spread":0.01,"bid_size":null,"ask_size":null}
{"ts":"2026-08-24T20:48:03.774Z","event_type":"price_change","market_id":"3823619","outcome_index":1,"market_type":"match","local_side":"away","local_uid":"2026-08-24_polina_kudermetova_linda_fruhvirtova","bid":0.45,"ask":0.46,"mid":0.455,"spread":0.01,"price":0.45,"size":497.52,"side":"BUY"}
{"ts":"2026-08-24T20:48:03.774Z","event_type":"price_change","market_id":"3823619","outcome_index":0,"market_type":"match","local_side":"home","local_uid":"2026-08-24_polina_kudermetova_linda_fruhvirtova","bid":0.54,"ask":0.55,"mid":0.545,"spread":0.01,"price":0.55,"size":497.52,"side":"SELL"}
{"ts":"2026-08-24T20:48:03.810Z","event_type":"best_bid_ask","market_id":"3825077","outcome_index":0,"market_type":"set1","local_side":"home","local_uid":"2026-08-24_polina_kudermetova_linda_fruhvirtova","bid":0.45,"ask":0.48,"mid":0.465,"spread":0.03,"bid_size":null,"ask_size":null}
{"ts":"2026-08-24T20:48:03.810Z","event_type":"best_bid_ask","market_id":"3825077","outcome_index":1,"market_type":"set1","local_side":"away","local_uid":"2026-08-24_polina_kudermetova_linda_fruhvirtova","bid":0.52,"ask":0.55,"mid":0.535,"spread":0.03,"bid_size":null,"ask_size":null}
{"ts":"2026-08-24T20:48:03.810Z","event_type":"price_change","market_id":"3825077","outcome_index":1,"market_type":"set1","local_side":"away","local_uid":"2026-08-24_polina_kudermetova_linda_fruhvirtova","bid":0.52,"ask":0.55,"mid":0.535,"spread":0.03,"price":0.52,"size":150.0,"side":"BUY"}
{"ts":"2026-08-24T20:48:03.811Z","event_type":"price_change","market_id":"3825077","outcome_index":0,"market_type":"set1","local_side":"home","local_uid":"2026-08-24_polina_kudermetova_linda_fruhvirtova","bid":0.45,"ask":0.48,"mid":0.465,"spread":0.03,"price":0.48,"size":150.0,"side":"SELL"}
{"ts":"2026-08-24T20:48:03.837Z","event_type":"best_bid_ask","market_id":"3825070","outcome_index":0,"market_type":"set2","local_side":"home","local_uid":"2026-08-24_polina_kudermetova_linda_fruhvirtova","bid":0.5,"ask":0.61,"mid":0.555,"spread":0.11,"bid_size":null,"ask_size":null}
{"ts":"2026-08-24T20:48:03.837Z","event_type":"best_bid_ask","market_id":"3825070","outcome_index":1,"market_type":"set2","local_side":"away","local_uid":"2026-08-24_polina_kudermetova_linda_fruhvirtova","bid":0.39,"ask":0.5,"mid":0.445,"spread":0.11,"bid_size":null,"ask_size":null}
{"ts":"2026-08-24T20:48:03.838Z","event_type":"price_change","market_id":"3825070","outcome_index":1,"market_type":"set2","local_side":"away","local_uid":"2026-08-24_polina_kudermetova_linda_fruhvirtova","bid":0.39,"ask":0.5,"mid":0.445,"spread":0.11,"price":0.39,"size":6.41,"side":"BUY"}
{"ts":"2026-08-24T20:48:03.838Z","event_type":"price_change","market_id":"3825070","outcome_index":0,"market_type":"set2","local_side":"home","local_uid":"2026-08-24_polina_kudermetova_linda_fruhvirtova","bid":0.5,"ask":0.61,"mid":0.555,"spread":0.11,"price":0.61,"size":6.41,"side":"SELL"}
{"ts":"2026-08-24T20:48:03.931Z","event_type":"best_bid_ask","market_id":"3825077","outcome_index":0,"market_type":"set1","local_side":"home","local_uid":"2026-08-24_polina_kudermetova_linda_fruhvirtova","bid":0.45,"ask":0.47,"mid":0.46,"spread":0.02,"bid_size":null,"ask_size":null}
{"ts":"2026-08-24T20:48:03.931Z","event_type":"best_bid_ask","market_id":"3825077","outcome_index":1,"market_type":"set1","local_side":"away","local_uid":"2026-08-24_polina_kudermetova_linda_fruhvirtova","bid":0.53,"ask":0.55,"mid":0.54,"spread":0.02,"bid_size":null,"ask_size":null}
{"ts":"2026-08-24T20:48:03.931Z","event_type":"price_change","market_id":"3825077","outcome_index":1,"market_type":"set1","local_side":"away","local_uid":"2026-08-24_polina_kudermetova_linda_fruhvirtova","bid":0.53,"ask":0.55,"mid":0.54,"spread":0.02,"price":0.53,"size":150.0,"side":"BUY"}
{"ts":"2026-08-24T20:48:03.931Z","event_type":"price_change","market_id":"3825077","outcome_index":0,"market_type":"set1","local_side":"home","local_uid":"2026-08-24_polina_kudermetova_linda_fruhvirtova","bid":0.45,"ask":0.47,"mid":0.46,"spread":0.02,"price":0.47,"size":150.0,"side":"SELL"}
{"ts":"2026-08-24T20:48:04.250Z","event_type":"price_change","market_id":"3802836","outcome_index":1,"market_type":"set1","local_side":"away","local_uid":"2026-08-24_edward_winter_andres_andrade","bid":0.999,"ask":1.0,"mid":0.9995,"spread":0.001,"price":0.01,"size":14111.0,"side":"BUY"}
{"ts":"2026-08-24T20:48:04.250Z","event_type":"price_change","market_id":"3802836","outcome_index":0,"market_type":"set1","local_side":"home","local_uid":"2026-08-24_edward_winter_andres_andrade","bid":0.0,"ask":0.001,"mid":0.0005,"spread":0.001,"price":0.99,"size":14111.0,"side":"SELL"}
{"ts":"2026-08-24T20:48:04.263Z","event_type":"price_change","market_id":"3802004","outcome_index":0,"market_type":"match","local_side":"home","local_uid":"2026-08-24_luis_guto_miguel_tyler_zink","bid":0.65,"ask":0.67,"mid":0.66,"spread":0.02,"price":0.56,"size":1777.0,"side":"BUY"}
{"ts":"2026-08-24T20:48:04.263Z","event_type":"price_change","market_id":"3802004","outcome_index":1,"market_type":"match","local_side":"away","local_uid":"2026-08-24_luis_guto_miguel_tyler_zink","bid":0.33,"ask":0.35,"mid":0.34,"spread":0.02,"price":0.44,"size":1777.0,"side":"SELL"}
{"ts":"2026-08-24T20:48:04.614Z","event_type":"best_bid_ask","market_id":"3826654","outcome_index":0,"market_type":"set2","local_side":"home","local_uid":"2026-08-24_sebastian_gorzny_cruz_hewitt","bid":0.12,"ask":0.32,"mid":0.22,"spread":0.2,"bid_size":null,"ask_size":null}
{"ts":"2026-08-24T20:48:04.615Z","event_type":"best_bid_ask","market_id":"3826654","outcome_index":1,"market_type":"set2","local_side":"away","local_uid":"2026-08-24_sebastian_gorzny_cruz_hewitt","bid":0.68,"ask":0.88,"mid":0.78,"spread":0.2,"bid_size":null,"ask_size":null}
{"ts":"2026-08-24T20:48:04.615Z","event_type":"price_change","market_id":"3826654","outcome_index":0,"market_type":"set2","local_side":"home","local_uid":"2026-08-24_sebastian_gorzny_cruz_hewitt","bid":0.12,"ask":0.32,"mid":0.22,"spread":0.2,"price":0.12,"size":88.0,"side":"BUY"}
{"ts":"2026-08-24T20:48:04.615Z","event_type":"price_change","market_id":"3826654","outcome_index":1,"market_type":"set2","local_side":"away","local_uid":"2026-08-24_sebastian_gorzny_cruz_hewitt","bid":0.68,"ask":0.88,"mid":0.78,"spread":0.2,"price":0.88,"size":88.0,"side":"SELL"}
{"ts":"2026-08-24T20:48:04.619Z","event_type":"best_bid_ask","market_id":"3826654","outcome_index":0,"market_type":"set2","local_side":"home","local_uid":"2026-08-24_sebastian_gorzny_cruz_hewitt","bid":0.12,"ask":0.24,"mid":0.18,"spread":0.12,"bid_size":null,"ask_size":null}
{"ts":"2026-08-24T20:48:04.620Z","event_type":"best_bid_ask","market_id":"3826654","outcome_index":1,"market_type":"set2","local_side":"away","local_uid":"2026-08-24_sebastian_gorzny_cruz_hewitt","bid":0.76,"ask":0.88,"mid":0.82,"spread":0.12,"bid_size":null,"ask_size":null}
{"ts":"2026-08-24T20:48:04.620Z","event_type":"price_change","market_id":"3826654","outcome_index":1,"market_type":"set2","local_side":"away","local_uid":"2026-08-24_sebastian_gorzny_cruz_hewitt","bid":0.76,"ask":0.88,"mid":0.82,"spread":0.12,"price":0.76,"size":88.0,"side":"BUY"}
{"ts":"2026-08-24T20:48:04.620Z","event_type":"price_change","market_id":"3826654","outcome_index":0,"market_type":"set2","local_side":"home","local_uid":"2026-08-24_sebastian_gorzny_cruz_hewitt","bid":0.12,"ask":0.24,"mid":0.18,"spread":0.12,"price":0.24,"size":88.0,"side":"SELL"}
{"ts":"2026-08-24T20:48:04.784Z","event_type":"price_change","market_id":"3825649","outcome_index":0,"market_type":"match","local_side":"home","local_uid":"2026-08-24_roman_safiullin_hugo_grenier","bid":0.84,"ask":0.85,"mid":0.845,"spread":0.01,"price":0.57,"size":0.0,"side":"BUY"}
{"ts":"2026-08-24T20:48:04.784Z","event_type":"price_change","market_id":"3825649","outcome_index":1,"market_type":"match","local_side":"away","local_uid":"2026-08-24_roman_safiullin_hugo_grenier","bid":0.15,"ask":0.16,"mid":0.155,"spread":0.01,"price":0.43,"size":0.0,"side":"SELL"}
{"ts":"2026-08-24T20:48:04.971Z","event_type":"best_bid_ask","market_id":"3823627","outcome_index":0,"market_type":"match","local_side":"home","local_uid":"2026-08-24_claire_liu_heather_watson","bid":0.4,"ask":0.46,"mid":0.43,"spread":0.06,"bid_size":null,"ask_size":null}
{"ts":"2026-08-24T20:48:04.972Z","event_type":"best_bid_ask","market_id":"3823627","outcome_index":1,"market_type":"match","local_side":"away","local_uid":"2026-08-24_claire_liu_heather_watson","bid":0.54,"ask":0.6,"mid":0.57,"spread":0.06,"bid_size":null,"ask_size":null}
{"ts":"2026-08-24T20:48:04.972Z","event_type":"price_change","market_id":"3823627","outcome_index":0,"market_type":"match","local_side":"home","local_uid":"2026-08-24_claire_liu_heather_watson","bid":0.4,"ask":0.46,"mid":0.43,"spread":0.06,"price":0.43,"size":0.0,"side":"BUY"}
{"ts":"2026-08-24T20:48:04.972Z","event_type":"price_change","market_id":"3823627","outcome_index":1,"market_type":"match","local_side":"away","local_uid":"2026-08-24_claire_liu_heather_watson","bid":0.54,"ask":0.6,"mid":0.57,"spread":0.06,"price":0.57,"size":0.0,"side":"SELL"}
{"ts":"2026-08-24T20:48:05.240Z","event_type":"best_bid_ask","market_id":"3826654","outcome_index":0,"market_type":"set2","local_side":"home","local_uid":"2026-08-24_sebastian_gorzny_cruz_hewitt","bid":0.12,"ask":0.23,"mid":0.175,"spread":0.11,"bid_size":null,"ask_size":null}
{"ts":"2026-08-24T20:48:05.240Z","event_type":"best_bid_ask","market_id":"3826654","outcome_index":1,"market_type":"set2","local_side":"away","local_uid":"2026-08-24_sebastian_gorzny_cruz_hewitt","bid":0.77,"ask":0.88,"mid":0.825,"spread":0.11,"bid_size":null,"ask_size":null}
{"ts":"2026-08-24T20:48:05.241Z","event_type":"price_change","market_id":"3826654","outcome_index":1,"market_type":"set2","local_side":"away","local_uid":"2026-08-24_sebastian_gorzny_cruz_hewitt","bid":0.77,"ask":0.88,"mid":0.825,"spread":0.11,"price":0.77,"size":22.0,"side":"BUY"}
{"ts":"2026-08-24T20:48:05.241Z","event_type":"price_change","market_id":"3826654","outcome_index":0,"market_type":"set2","local_side":"home","local_uid":"2026-08-24_sebastian_gorzny_cruz_hewitt","bid":0.12,"ask":0.23,"mid":0.175,"spread":0.11,"price":0.23,"size":22.0,"side":"SELL"}
{"ts":"2026-08-24T20:48:05.275Z","event_type":"best_bid_ask","market_id":"3825641","outcome_index":0,"market_type":"match","local_side":"home","local_uid":"2026-08-24_sebastian_gorzny_cruz_hewitt","bid":0.62,"ask":0.63,"mid":0.625,"spread":0.01,"bid_size":null,"ask_size":null}
{"ts":"2026-08-24T20:48:05.275Z","event_type":"best_bid_ask","market_id":"3825641","outcome_index":1,"market_type":"match","local_side":"away","local_uid":"2026-08-24_sebastian_gorzny_cruz_hewitt","bid":0.37,"ask":0.38,"mid":0.375,"spread":0.01,"bid_size":null,"ask_size":null}
{"ts":"2026-08-24T20:48:05.275Z","event_type":"price_change","market_id":"3825641","outcome_index":0,"market_type":"match","local_side":"home","local_uid":"2026-08-24_sebastian_gorzny_cruz_hewitt","bid":0.62,"ask":0.63,"mid":0.625,"spread":0.01,"price":0.62,"size":6867.74,"side":"BUY"}
{"ts":"2026-08-24T20:48:05.275Z","event_type":"price_change","market_id":"3825641","outcome_index":1,"market_type":"match","local_side":"away","local_uid":"2026-08-24_sebastian_gorzny_cruz_hewitt","bid":0.37,"ask":0.38,"mid":0.375,"spread":0.01,"price":0.38,"size":6867.74,"side":"SELL"}
{"ts":"2026-08-24T20:48:05.489Z","event_type":"best_bid_ask","market_id":"3823619","outcome_index":0,"market_type":"match","local_side":"home","local_uid":"2026-08-24_polina_kudermetova_linda_fruhvirtova","bid":0.53,"ask":0.55,"mid":0.54,"spread":0.02,"bid_size":null,"ask_size":null}
{"ts":"2026-08-24T20:48:05.495Z","event_type":"best_bid_ask","market_id":"3823619","outcome_index":1,"market_type":"match","local_side":"away","local_uid":"2026-08-24_polina_kudermetova_linda_fruhvirtova","bid":0.45,"ask":0.47,"mid":0.46,"spread":0.02,"bid_size":null,"ask_size":null}
{"ts":"2026-08-24T20:48:05.495Z","event_type":"price_change","market_id":"3823619","outcome_index":0,"market_type":"match","local_side":"home","local_uid":"2026-08-24_polina_kudermetova_linda_fruhvirtova","bid":0.53,"ask":0.55,"mid":0.54,"spread":0.02,"price":0.54,"size":0.0,"side":"BUY"}
{"ts":"2026-08-24T20:48:05.495Z","event_type":"price_change","market_id":"3823619","outcome_index":1,"market_type":"match","local_side":"away","local_uid":"2026-08-24_polina_kudermetova_linda_fruhvirtova","bid":0.45,"ask":0.47,"mid":0.46,"spread":0.02,"price":0.46,"size":0.0,"side":"SELL"}
{"ts":"2026-08-24T20:48:05.551Z","event_type":"best_bid_ask","market_id":"3823619","outcome_index":0,"market_type":"match","local_side":"home","local_uid":"2026-08-24_polina_kudermetova_linda_fruhvirtova","bid":0.53,"ask":0.54,"mid":0.535,"spread":0.01,"bid_size":null,"ask_size":null}
{"ts":"2026-08-24T20:48:05.551Z","event_type":"best_bid_ask","market_id":"3823619","outcome_index":1,"market_type":"match","local_side":"away","local_uid":"2026-08-24_polina_kudermetova_linda_fruhvirtova","bid":0.46,"ask":0.47,"mid":0.465,"spread":0.01,"bid_size":null,"ask_size":null}
{"ts":"2026-08-24T20:48:05.552Z","event_type":"price_change","market_id":"3823619","outcome_index":1,"market_type":"match","local_side":"away","local_uid":"2026-08-24_polina_kudermetova_linda_fruhvirtova","bid":0.46,"ask":0.47,"mid":0.465,"spread":0.01,"price":0.46,"size":14025.24,"side":"BUY"}
{"ts":"2026-08-24T20:48:05.552Z","event_type":"price_change","market_id":"3823619","outcome_index":0,"market_type":"match","local_side":"home","local_uid":"2026-08-24_polina_kudermetova_linda_fruhvirtova","bid":0.53,"ask":0.54,"mid":0.535,"spread":0.01,"price":0.54,"size":14025.24,"side":"SELL"}
{"ts":"2026-08-24T20:48:05.605Z","event_type":"price_change","market_id":"3823665","outcome_index":0,"market_type":"match","local_side":"home","local_uid":"2026-08-24_jazmin_ortenzi_himeno_sakatsume","bid":0.15,"ask":0.16,"mid":0.155,"spread":0.01,"price":0.15,"size":25829.35,"side":"BUY"}
{"ts":"2026-08-24T20:48:05.606Z","event_type":"price_change","market_id":"3823665","outcome_index":1,"market_type":"match","local_side":"away","local_uid":"2026-08-24_jazmin_ortenzi_himeno_sakatsume","bid":0.84,"ask":0.85,"mid":0.845,"spread":0.01,"price":0.85,"size":25829.35,"side":"SELL"}
{"ts":"2026-08-24T20:48:05.907Z","event_type":"best_bid_ask","market_id":"3823627","outcome_index":0,"market_type":"match","local_side":"home","local_uid":"2026-08-24_claire_liu_heather_watson","bid":0.4,"ask":0.45,"mid":0.425,"spread":0.05,"bid_size":null,"ask_size":null}
{"ts":"2026-08-24T20:48:05.907Z","event_type":"best_bid_ask","market_id":"3823627","outcome_index":1,"market_type":"match","local_side":"away","local_uid":"2026-08-24_claire_liu_heather_watson","bid":0.55,"ask":0.6,"mid":0.575,"spread":0.05,"bid_size":null,"ask_size":null}
{"ts":"2026-08-24T20:48:05.907Z","event_type":"price_change","market_id":"3823627","outcome_index":1,"market_type":"match","local_side":"away","local_uid":"2026-08-24_claire_liu_heather_watson","bid":0.55,"ask":0.6,"mid":0.575,"spread":0.05,"price":0.55,"size":100.0,"side":"BUY"}
{"ts":"2026-08-24T20:48:05.907Z","event_type":"price_change","market_id":"3823627","outcome_index":0,"market_type":"match","local_side":"home","local_uid":"2026-08-24_claire_liu_heather_watson","bid":0.4,"ask":0.45,"mid":0.425,"spread":0.05,"price":0.45,"size":100.0,"side":"SELL"}
{"ts":"2026-08-24T20:48:05.948Z","event_type":"best_bid_ask","market_id":"3824760","outcome_index":0,"market_type":"set2","local_side":"home","local_uid":"2026-08-24_jazmin_ortenzi_himeno_sakatsume","bid":0.21,"ask":0.31,"mid":0.26,"spread":0.1,"bid_size":null,"ask_size":null}
{"ts":"2026-08-24T20:48:05.948Z","event_type":"best_bid_ask","market_id":"3824760","outcome_index":1,"market_type":"set2","local_side":"away","local_uid":"2026-08-24_jazmin_ortenzi_himeno_sakatsume","bid":0.69,"ask":0.79,"mid":0.74,"spread":0.1,"bid_size":null,"ask_size":null}
{"ts":"2026-08-24T20:48:05.952Z","event_type":"price_change","market_id":"3824760","outcome_index":1,"market_type":"set2","local_side":"away","local_uid":"2026-08-24_jazmin_ortenzi_himeno_sakatsume","bid":0.69,"ask":0.79,"mid":0.74,"spread":0.1,"price":0.71,"size":0.0,"side":"BUY"}
{"ts":"2026-08-24T20:48:05.953Z","event_type":"price_change","market_id":"3824760","outcome_index":0,"market_type":"set2","local_side":"home","local_uid":"2026-08-24_jazmin_ortenzi_himeno_sakatsume","bid":0.21,"ask":0.31,"mid":0.26,"spread":0.1,"price":0.29,"size":0.0,"side":"SELL"}
{"ts":"2026-08-24T20:48:05.959Z","event_type":"best_bid_ask","market_id":"3823627","outcome_index":0,"market_type":"match","local_side":"home","local_uid":"2026-08-24_claire_liu_heather_watson","bid":0.4,"ask":0.44,"mid":0.42,"spread":0.04,"bid_size":null,"ask_size":null}
{"ts":"2026-08-24T20:48:05.959Z","event_type":"best_bid_ask","market_id":"3823627","outcome_index":1,"market_type":"match","local_side":"away","local_uid":"2026-08-24_claire_liu_heather_watson","bid":0.56,"ask":0.6,"mid":0.58,"spread":0.04,"bid_size":null,"ask_size":null}
{"ts":"2026-08-24T20:48:05.960Z","event_type":"price_change","market_id":"3823627","outcome_index":1,"market_type":"match","local_side":"away","local_uid":"2026-08-24_claire_liu_heather_watson","bid":0.56,"ask":0.6,"mid":0.58,"spread":0.04,"price":0.56,"size":20.0,"side":"BUY"}
{"ts":"2026-08-24T20:48:05.960Z","event_type":"price_change","market_id":"3823627","outcome_index":0,"market_type":"match","local_side":"home","local_uid":"2026-08-24_claire_liu_heather_watson","bid":0.4,"ask":0.44,"mid":0.42,"spread":0.04,"price":0.44,"size":20.0,"side":"SELL"}
{"ts":"2026-08-24T20:48:05.988Z","event_type":"best_bid_ask","market_id":"3824760","outcome_index":0,"market_type":"set2","local_side":"home","local_uid":"2026-08-24_jazmin_ortenzi_himeno_sakatsume","bid":0.21,"ask":0.3,"mid":0.255,"spread":0.09,"bid_size":null,"ask_size":null}
{"ts":"2026-08-24T20:48:05.988Z","event_type":"best_bid_ask","market_id":"3824760","outcome_index":1,"market_type":"set2","local_side":"away","local_uid":"2026-08-24_jazmin_ortenzi_himeno_sakatsume","bid":0.7,"ask":0.79,"mid":0.745,"spread":0.09,"bid_size":null,"ask_size":null}
{"ts":"2026-08-24T20:48:05.988Z","event_type":"price_change","market_id":"3824760","outcome_index":1,"market_type":"set2","local_side":"away","local_uid":"2026-08-24_jazmin_ortenzi_himeno_sakatsume","bid":0.7,"ask":0.79,"mid":0.745,"spread":0.09,"price":0.7,"size":25.58,"side":"BUY"}
{"ts":"2026-08-24T20:48:05.989Z","event_type":"price_change","market_id":"3824760","outcome_index":0,"market_type":"set2","local_side":"home","local_uid":"2026-08-24_jazmin_ortenzi_himeno_sakatsume","bid":0.21,"ask":0.3,"mid":0.255,"spread":0.09,"price":0.3,"size":25.58,"side":"SELL"}
{"ts":"2026-08-24T20:48:06.056Z","event_type":"best_bid_ask","market_id":"3823627","outcome_index":0,"market_type":"match","local_side":"home","local_uid":"2026-08-24_claire_liu_heather_watson","bid":0.4,"ask":0.41,"mid":0.405,"spread":0.01,"bid_size":null,"ask_size":null}
{"ts":"2026-08-24T20:48:06.056Z","event_type":"best_bid_ask","market_id":"3823627","outcome_index":1,"market_type":"match","local_side":"away","local_uid":"2026-08-24_claire_liu_heather_watson","bid":0.59,"ask":0.6,"mid":0.595,"spread":0.01,"bid_size":null,"ask_size":null}
{"ts":"2026-08-24T20:48:06.057Z","event_type":"price_change","market_id":"3823627","outcome_index":1,"market_type":"match","local_side":"away","local_uid":"2026-08-24_claire_liu_heather_watson","bid":0.59,"ask":0.6,"mid":0.595,"spread":0.01,"price":0.59,"size":1500.0,"side":"BUY"}
{"ts":"2026-08-24T20:48:06.057Z","event_type":"price_change","market_id":"3823627","outcome_index":0,"market_type":"match","local_side":"home","local_uid":"2026-08-24_claire_liu_heather_watson","bid":0.4,"ask":0.41,"mid":0.405,"spread":0.01,"price":0.41,"size":1500.0,"side":"SELL"}
{"ts":"2026-08-24T20:48:06.075Z","event_type":"best_bid_ask","market_id":"3823627","outcome_index":0,"market_type":"match","local_side":"home","local_uid":"2026-08-24_claire_liu_heather_watson","bid":0.4,"ask":0.44,"mid":0.42,"spread":0.04,"bid_size":null,"ask_size":null}
{"ts":"2026-08-24T20:48:06.075Z","event_type":"best_bid_ask","market_id":"3823627","outcome_index":1,"market_type":"match","local_side":"away","local_uid":"2026-08-24_claire_liu_heather_watson","bid":0.56,"ask":0.6,"mid":0.58,"spread":0.04,"bid_size":null,"ask_size":null}
{"ts":"2026-08-24T20:48:06.076Z","event_type":"price_change","market_id":"3823627","outcome_index":1,"market_type":"match","local_side":"away","local_uid":"2026-08-24_claire_liu_heather_watson","bid":0.56,"ask":0.6,"mid":0.58,"spread":0.04,"price":0.59,"size":0.0,"side":"BUY"}
{"ts":"2026-08-24T20:48:06.076Z","event_type":"price_change","market_id":"3823627","outcome_index":0,"market_type":"match","local_side":"home","local_uid":"2026-08-24_claire_liu_heather_watson","bid":0.4,"ask":0.44,"mid":0.42,"spread":0.04,"price":0.41,"size":0.0,"side":"SELL"}
{"ts":"2026-08-24T20:48:06.094Z","event_type":"best_bid_ask","market_id":"3823627","outcome_index":0,"market_type":"match","local_side":"home","local_uid":"2026-08-24_claire_liu_heather_watson","bid":0.39,"ask":0.4,"mid":0.395,"spread":0.01,"bid_size":null,"ask_size":null}
{"ts":"2026-08-24T20:48:06.094Z","event_type":"best_bid_ask","market_id":"3823627","outcome_index":1,"market_type":"match","local_side":"away","local_uid":"2026-08-24_claire_liu_heather_watson","bid":0.6,"ask":0.61,"mid":0.605,"spread":0.01,"bid_size":null,"ask_size":null}
{"ts":"2026-08-24T20:48:06.095Z","event_type":"price_change","market_id":"3823627","outcome_index":1,"market_type":"match","local_side":"away","local_uid":"2026-08-24_claire_liu_heather_watson","bid":0.6,"ask":0.61,"mid":0.605,"spread":0.01,"price":0.6,"size":4990.0,"side":"BUY"}
{"ts":"2026-08-24T20:48:06.095Z","event_type":"price_change","market_id":"3823627","outcome_index":0,"market_type":"match","local_side":"home","local_uid":"2026-08-24_claire_liu_heather_watson","bid":0.39,"ask":0.4,"mid":0.395,"spread":0.01,"price":0.4,"size":4990.0,"side":"SELL"}
{"ts":"2026-08-24T20:48:06.102Z","event_type":"book","market_id":"3823627","outcome_index":0,"market_type":"match","local_side":"home","local_uid":"2026-08-24_claire_liu_heather_watson","bid":0.39,"ask":0.4,"mid":0.395,"spread":0.01,"bid_size":30.0,"ask_size":4990.0}
{"ts":"2026-08-24T20:48:06.104Z","event_type":"book","market_id":"3823627","outcome_index":1,"market_type":"match","local_side":"away","local_uid":"2026-08-24_claire_liu_heather_watson","bid":0.6,"ask":0.61,"mid":0.605,"spread":0.01,"bid_size":4990.0,"ask_size":30.0}
{"ts":"2026-08-24T20:48:06.110Z","event_type":"best_bid_ask","market_id":"3823627","outcome_index":0,"market_type":"match","local_side":"home","local_uid":"2026-08-24_claire_liu_heather_watson","bid":0.37,"ask":0.4,"mid":0.385,"spread":0.03,"bid_size":null,"ask_size":null}
{"ts":"2026-08-24T20:48:06.110Z","event_type":"best_bid_ask","market_id":"3823627","outcome_index":1,"market_type":"match","local_side":"away","local_uid":"2026-08-24_claire_liu_heather_watson","bid":0.6,"ask":0.63,"mid":0.615,"spread":0.03,"bid_size":null,"ask_size":null}
{"ts":"2026-08-24T20:48:06.111Z","event_type":"price_change","market_id":"3823627","outcome_index":0,"market_type":"match","local_side":"home","local_uid":"2026-08-24_claire_liu_heather_watson","bid":0.37,"ask":0.4,"mid":0.385,"spread":0.03,"price":0.39,"size":0.0,"side":"BUY"}
{"ts":"2026-08-24T20:48:06.111Z","event_type":"price_change","market_id":"3823627","outcome_index":1,"market_type":"match","local_side":"away","local_uid":"2026-08-24_claire_liu_heather_watson","bid":0.6,"ask":0.63,"mid":0.615,"spread":0.03,"price":0.61,"size":0.0,"side":"SELL"}
{"ts":"2026-08-24T20:48:06.114Z","event_type":"book","market_id":"3823627","outcome_index":0,"market_type":"match","local_side":"home","local_uid":"2026-08-24_claire_liu_heather_watson","bid":0.37,"ask":0.4,"mid":0.385,"spread":0.03,"bid_size":1197.2,"ask_size":4990.0}
{"ts":"2026-08-24T20:48:06.115Z","event_type":"book","market_id":"3823627","outcome_index":1,"market_type":"match","local_side":"away","local_uid":"2026-08-24_claire_liu_heather_watson","bid":0.6,"ask":0.63,"mid":0.615,"spread":0.03,"bid_size":4990.0,"ask_size":1197.2}
{"ts":"2026-08-24T20:48:06.121Z","event_type":"best_bid_ask","market_id":"3823627","outcome_index":0,"market_type":"match","local_side":"home","local_uid":"2026-08-24_claire_liu_heather_watson","bid":0.38,"ask":0.4,"mid":0.39,"spread":0.02,"bid_size":null,"ask_size":null}
{"ts":"2026-08-24T20:48:06.121Z","event_type":"best_bid_ask","market_id":"3823627","outcome_index":1,"market_type":"match","local_side":"away","local_uid":"2026-08-24_claire_liu_heather_watson","bid":0.6,"ask":0.62,"mid":0.61,"spread":0.02,"bid_size":null,"ask_size":null}
{"ts":"2026-08-24T20:48:06.122Z","event_type":"price_change","market_id":"3823627","outcome_index":0,"market_type":"match","local_side":"home","local_uid":"2026-08-24_claire_liu_heather_watson","bid":0.38,"ask":0.4,"mid":0.39,"spread":0.02,"price":0.38,"size":10.0,"side":"BUY"}
{"ts":"2026-08-24T20:48:06.122Z","event_type":"price_change","market_id":"3823627","outcome_index":1,"market_type":"match","local_side":"away","local_uid":"2026-08-24_claire_liu_heather_watson","bid":0.6,"ask":0.62,"mid":0.61,"spread":0.02,"price":0.62,"size":10.0,"side":"SELL"}
{"ts":"2026-08-24T20:48:06.135Z","event_type":"last_trade_price","market_id":"3823627","outcome_index":1,"market_type":"match","local_side":"away","local_uid":"2026-08-24_claire_liu_heather_watson","last_trade":0.6,"trade_size":10.0,"trade_side":"BUY","trade_notional":6.0}
{"ts":"2026-08-24T20:48:06.149Z","event_type":"best_bid_ask","market_id":"3823627","outcome_index":0,"market_type":"match","local_side":"home","local_uid":"2026-08-24_claire_liu_heather_watson","bid":0.38,"ask":0.45,"mid":0.415,"spread":0.07,"bid_size":null,"ask_size":null}
{"ts":"2026-08-24T20:48:06.149Z","event_type":"best_bid_ask","market_id":"3823627","outcome_index":1,"market_type":"match","local_side":"away","local_uid":"2026-08-24_claire_liu_heather_watson","bid":0.55,"ask":0.62,"mid":0.585,"spread":0.07,"bid_size":null,"ask_size":null}
{"ts":"2026-08-24T20:48:06.151Z","event_type":"price_change","market_id":"3823627","outcome_index":1,"market_type":"match","local_side":"away","local_uid":"2026-08-24_claire_liu_heather_watson","bid":0.55,"ask":0.62,"mid":0.585,"spread":0.07,"price":0.6,"size":0.0,"side":"BUY"}
{"ts":"2026-08-24T20:48:06.151Z","event_type":"price_change","market_id":"3823627","outcome_index":0,"market_type":"match","local_side":"home","local_uid":"2026-08-24_claire_liu_heather_watson","bid":0.38,"ask":0.45,"mid":0.415,"spread":0.07,"price":0.4,"size":0.0,"side":"SELL"}
{"ts":"2026-08-24T20:48:06.156Z","event_type":"best_bid_ask","market_id":"3823627","outcome_index":0,"market_type":"match","local_side":"home","local_uid":"2026-08-24_claire_liu_heather_watson","bid":0.38,"ask":0.44,"mid":0.41,"spread":0.06,"bid_size":null,"ask_size":null}
{"ts":"2026-08-24T20:48:06.157Z","event_type":"best_bid_ask","market_id":"3823627","outcome_index":1,"market_type":"match","local_side":"away","local_uid":"2026-08-24_claire_liu_heather_watson","bid":0.56,"ask":0.62,"mid":0.59,"spread":0.06,"bid_size":null,"ask_size":null}
{"ts":"2026-08-24T20:48:06.157Z","event_type":"price_change","market_id":"3823627","outcome_index":1,"market_type":"match","local_side":"away","local_uid":"2026-08-24_claire_liu_heather_watson","bid":0.56,"ask":0.62,"mid":0.59,"spread":0.06,"price":0.56,"size":5.0,"side":"BUY"}
{"ts":"2026-08-24T20:48:06.157Z","event_type":"price_change","market_id":"3823627","outcome_index":0,"market_type":"match","local_side":"home","local_uid":"2026-08-24_claire_liu_heather_watson","bid":0.38,"ask":0.44,"mid":0.41,"spread":0.06,"price":0.44,"size":5.0,"side":"SELL"}
{"ts":"2026-08-24T20:48:06.166Z","event_type":"best_bid_ask","market_id":"3823627","outcome_index":0,"market_type":"match","local_side":"home","local_uid":"2026-08-24_claire_liu_heather_watson","bid":0.38,"ask":0.43,"mid":0.405,"spread":0.05,"bid_size":null,"ask_size":null}
{"ts":"2026-08-24T20:48:06.166Z","event_type":"best_bid_ask","market_id":"3823627","outcome_index":1,"market_type":"match","local_side":"away","local_uid":"2026-08-24_claire_liu_heather_watson","bid":0.57,"ask":0.62,"mid":0.595,"spread":0.05,"bid_size":null,"ask_size":null}
{"ts":"2026-08-24T20:48:06.169Z","event_type":"price_change","market_id":"3823627","outcome_index":1,"market_type":"match","local_side":"away","local_uid":"2026-08-24_claire_liu_heather_watson","bid":0.57,"ask":0.62,"mid":0.595,"spread":0.05,"price":0.57,"size":100.0,"side":"BUY"}
{"ts":"2026-08-24T20:48:06.169Z","event_type":"price_change","market_id":"3823627","outcome_index":0,"market_type":"match","local_side":"home","local_uid":"2026-08-24_claire_liu_heather_watson","bid":0.38,"ask":0.43,"mid":0.405,"spread":0.05,"price":0.43,"size":100.0,"side":"SELL"}
{"ts":"2026-08-24T20:48:06.176Z","event_type":"best_bid_ask","market_id":"3825077","outcome_index":0,"market_type":"set1","local_side":"home","local_uid":"2026-08-24_polina_kudermetova_linda_fruhvirtova","bid":0.45,"ask":0.46,"mid":0.455,"spread":0.01,"bid_size":null,"ask_size":null}
{"ts":"2026-08-24T20:48:06.176Z","event_type":"best_bid_ask","market_id":"3825077","outcome_index":1,"market_type":"set1","local_side":"away","local_uid":"2026-08-24_polina_kudermetova_linda_fruhvirtova","bid":0.54,"ask":0.55,"mid":0.545,"spread":0.01,"bid_size":null,"ask_size":null}
{"ts":"2026-08-24T20:48:06.176Z","event_type":"price_change","market_id":"3825077","outcome_index":1,"market_type":"set1","local_side":"away","local_uid":"2026-08-24_polina_kudermetova_linda_fruhvirtova","bid":0.54,"ask":0.55,"mid":0.545,"spread":0.01,"price":0.54,"size":1753.15,"side":"BUY"}
{"ts":"2026-08-24T20:48:06.176Z","event_type":"price_change","market_id":"3825077","outcome_index":0,"market_type":"set1","local_side":"home","local_uid":"2026-08-24_polina_kudermetova_linda_fruhvirtova","bid":0.45,"ask":0.46,"mid":0.455,"spread":0.01,"price":0.46,"size":1753.15,"side":"SELL"}
{"ts":"2026-08-24T20:48:06.196Z","event_type":"best_bid_ask","market_id":"3824761","outcome_index":0,"market_type":"set1","local_side":"home","local_uid":"2026-08-24_jazmin_ortenzi_himeno_sakatsume","bid":0.15,"ask":0.28,"mid":0.215,"spread":0.13,"bid_size":null,"ask_size":null}
{"ts":"2026-08-24T20:48:06.196Z","event_type":"best_bid_ask","market_id":"3824761","outcome_index":1,"market_type":"set1","local_side":"away","local_uid":"2026-08-24_jazmin_ortenzi_himeno_sakatsume","bid":0.72,"ask":0.85,"mid":0.785,"spread":0.13,"bid_size":null,"ask_size":null}
{"ts":"2026-08-24T20:48:06.199Z","event_type":"price_change","market_id":"3824761","outcome_index":0,"market_type":"set1","local_side":"home","local_uid":"2026-08-24_jazmin_ortenzi_himeno_sakatsume","bid":0.15,"ask":0.28,"mid":0.215,"spread":0.13,"price":0.18,"size":0.0,"side":"BUY"}
{"ts":"2026-08-24T20:48:06.199Z","event_type":"price_change","market_id":"3824761","outcome_index":1,"market_type":"set1","local_side":"away","local_uid":"2026-08-24_jazmin_ortenzi_himeno_sakatsume","bid":0.72,"ask":0.85,"mid":0.785,"spread":0.13,"price":0.82,"size":0.0,"side":"SELL"}
{"ts":"2026-08-24T20:48:06.229Z","event_type":"best_bid_ask","market_id":"3823627","outcome_index":0,"market_type":"match","local_side":"home","local_uid":"2026-08-24_claire_liu_heather_watson","bid":0.38,"ask":0.42,"mid":0.4,"spread":0.04,"bid_size":null,"ask_size":null}
{"ts":"2026-08-24T20:48:06.230Z","event_type":"best_bid_ask","market_id":"3823627","outcome_index":1,"market_type":"match","local_side":"away","local_uid":"2026-08-24_claire_liu_heather_watson","bid":0.58,"ask":0.62,"mid":0.6,"spread":0.04,"bid_size":null,"ask_size":null}
{"ts":"2026-08-24T20:48:06.230Z","event_type":"price_change","market_id":"3823627","outcome_index":1,"market_type":"match","local_side":"away","local_uid":"2026-08-24_claire_liu_heather_watson","bid":0.58,"ask":0.62,"mid":0.6,"spread":0.04,"price":0.58,"size":100.0,"side":"BUY"}
{"ts":"2026-08-24T20:48:06.230Z","event_type":"price_change","market_id":"3823627","outcome_index":0,"market_type":"match","local_side":"home","local_uid":"2026-08-24_claire_liu_heather_watson","bid":0.38,"ask":0.42,"mid":0.4,"spread":0.04,"price":0.42,"size":100.0,"side":"SELL"}
{"ts":"2026-08-24T20:48:06.239Z","event_type":"best_bid_ask","market_id":"3823627","outcome_index":0,"market_type":"match","local_side":"home","local_uid":"2026-08-24_claire_liu_heather_watson","bid":0.38,"ask":0.41,"mid":0.395,"spread":0.03,"bid_size":null,"ask_size":null}
{"ts":"2026-08-24T20:48:06.239Z","event_type":"best_bid_ask","market_id":"3823627","outcome_index":1,"market_type":"match","local_side":"away","local_uid":"2026-08-24_claire_liu_heather_watson","bid":0.59,"ask":0.62,"mid":0.605,"spread":0.03,"bid_size":null,"ask_size":null}
{"ts":"2026-08-24T20:48:06.240Z","event_type":"price_change","market_id":"3823627","outcome_index":1,"market_type":"match","local_side":"away","local_uid":"2026-08-24_claire_liu_heather_watson","bid":0.59,"ask":0.62,"mid":0.605,"spread":0.03,"price":0.59,"size":100.0,"side":"BUY"}
{"ts":"2026-08-24T20:48:06.240Z","event_type":"price_change","market_id":"3823627","outcome_index":0,"market_type":"match","local_side":"home","local_uid":"2026-08-24_claire_liu_heather_watson","bid":0.38,"ask":0.41,"mid":0.395,"spread":0.03,"price":0.41,"size":100.0,"side":"SELL"}
{"ts":"2026-08-24T20:48:06.290Z","event_type":"best_bid_ask","market_id":"3825070","outcome_index":0,"market_type":"set2","local_side":"home","local_uid":"2026-08-24_polina_kudermetova_linda_fruhvirtova","bid":0.5,"ask":0.6,"mid":0.55,"spread":0.1,"bid_size":null,"ask_size":null}
{"ts":"2026-08-24T20:48:06.291Z","event_type":"best_bid_ask","market_id":"3825070","outcome_index":1,"market_type":"set2","local_side":"away","local_uid":"2026-08-24_polina_kudermetova_linda_fruhvirtova","bid":0.4,"ask":0.5,"mid":0.45,"spread":0.1,"bid_size":null,"ask_size":null}
{"ts":"2026-08-24T20:48:06.291Z","event_type":"price_change","market_id":"3825070","outcome_index":1,"market_type":"set2","local_side":"away","local_uid":"2026-08-24_polina_kudermetova_linda_fruhvirtova","bid":0.4,"ask":0.5,"mid":0.45,"spread":0.1,"price":0.4,"size":1095.0,"side":"BUY"}
{"ts":"2026-08-24T20:48:06.291Z","event_type":"price_change","market_id":"3825070","outcome_index":0,"market_type":"set2","local_side":"home","local_uid":"2026-08-24_polina_kudermetova_linda_fruhvirtova","bid":0.5,"ask":0.6,"mid":0.55,"spread":0.1,"price":0.6,"size":1095.0,"side":"SELL"}
{"ts":"2026-08-24T20:48:06.302Z","event_type":"best_bid_ask","market_id":"3825070","outcome_index":0,"market_type":"set2","local_side":"home","local_uid":"2026-08-24_polina_kudermetova_linda_fruhvirtova","bid":0.53,"ask":0.6,"mid":0.565,"spread":0.07,"bid_size":null,"ask_size":null}
{"ts":"2026-08-24T20:48:06.302Z","event_type":"best_bid_ask","market_id":"3825070","outcome_index":1,"market_type":"set2","local_side":"away","local_uid":"2026-08-24_polina_kudermetova_linda_fruhvirtova","bid":0.4,"ask":0.47,"mid":0.435,"spread":0.07,"bid_size":null,"ask_size":null}
{"ts":"2026-08-24T20:48:06.302Z","event_type":"price_change","market_id":"3825070","outcome_index":0,"market_type":"set2","local_side":"home","local_uid":"2026-08-24_polina_kudermetova_linda_fruhvirtova","bid":0.53,"ask":0.6,"mid":0.565,"spread":0.07,"price":0.53,"size":150.0,"side":"BUY"}
{"ts":"2026-08-24T20:48:06.302Z","event_type":"price_change","market_id":"3825070","outcome_index":1,"market_type":"set2","local_side":"away","local_uid":"2026-08-24_polina_kudermetova_linda_fruhvirtova","bid":0.4,"ask":0.47,"mid":0.435,"spread":0.07,"price":0.47,"size":150.0,"side":"SELL"}
{"ts":"2026-08-24T20:48:06.308Z","event_type":"last_trade_price","market_id":"3823627","outcome_index":1,"market_type":"match","local_side":"away","local_uid":"2026-08-24_claire_liu_heather_watson","last_trade":0.62,"trade_size":105.0,"trade_side":"BUY","trade_notional":65.1}
{"ts":"2026-08-24T20:48:06.311Z","event_type":"best_bid_ask","market_id":"3823627","outcome_index":0,"market_type":"match","local_side":"home","local_uid":"2026-08-24_claire_liu_heather_watson","bid":0.38,"ask":0.4,"mid":0.39,"spread":0.02,"bid_size":null,"ask_size":null}
{"ts":"2026-08-24T20:48:06.311Z","event_type":"best_bid_ask","market_id":"3823627","outcome_index":1,"market_type":"match","local_side":"away","local_uid":"2026-08-24_claire_liu_heather_watson","bid":0.6,"ask":0.62,"mid":0.61,"spread":0.02,"bid_size":null,"ask_size":null}
{"ts":"2026-08-24T20:48:06.312Z","event_type":"price_change","market_id":"3823627","outcome_index":1,"market_type":"match","local_side":"away","local_uid":"2026-08-24_claire_liu_heather_watson","bid":0.6,"ask":0.62,"mid":0.61,"spread":0.02,"price":0.6,"size":154.0,"side":"BUY"}
{"ts":"2026-08-24T20:48:06.312Z","event_type":"price_change","market_id":"3823627","outcome_index":0,"market_type":"match","local_side":"home","local_uid":"2026-08-24_claire_liu_heather_watson","bid":0.38,"ask":0.4,"mid":0.39,"spread":0.02,"price":0.4,"size":154.0,"side":"SELL"}
{"ts":"2026-08-24T20:48:06.446Z","event_type":"best_bid_ask","market_id":"3825070","outcome_index":0,"market_type":"set2","local_side":"home","local_uid":"2026-08-24_polina_kudermetova_linda_fruhvirtova","bid":0.53,"ask":0.59,"mid":0.56,"spread":0.06,"bid_size":null,"ask_size":null}
{"ts":"2026-08-24T20:48:06.446Z","event_type":"best_bid_ask","market_id":"3825070","outcome_index":1,"market_type":"set2","local_side":"away","local_uid":"2026-08-24_polina_kudermetova_linda_fruhvirtova","bid":0.41,"ask":0.47,"mid":0.44,"spread":0.06,"bid_size":null,"ask_size":null}
{"ts":"2026-08-24T20:48:06.447Z","event_type":"price_change","market_id":"3825070","outcome_index":1,"market_type":"set2","local_side":"away","local_uid":"2026-08-24_polina_kudermetova_linda_fruhvirtova","bid":0.41,"ask":0.47,"mid":0.44,"spread":0.06,"price":0.41,"size":468.0,"side":"BUY"}
{"ts":"2026-08-24T20:48:06.447Z","event_type":"price_change","market_id":"3825070","outcome_index":0,"market_type":"set2","local_side":"home","local_uid":"2026-08-24_polina_kudermetova_linda_fruhvirtova","bid":0.53,"ask":0.59,"mid":0.56,"spread":0.06,"price":0.59,"size":468.0,"side":"SELL"}
{"ts":"2026-08-24T20:48:06.460Z","event_type":"best_bid_ask","market_id":"3823627","outcome_index":0,"market_type":"match","local_side":"home","local_uid":"2026-08-24_claire_liu_heather_watson","bid":0.38,"ask":0.39,"mid":0.385,"spread":0.01,"bid_size":null,"ask_size":null}
{"ts":"2026-08-24T20:48:06.460Z","event_type":"best_bid_ask","market_id":"3823627","outcome_index":1,"market_type":"match","local_side":"away","local_uid":"2026-08-24_claire_liu_heather_watson","bid":0.61,"ask":0.62,"mid":0.615,"spread":0.01,"bid_size":null,"ask_size":null}
{"ts":"2026-08-24T20:48:06.461Z","event_type":"price_change","market_id":"3823627","outcome_index":1,"market_type":"match","local_side":"away","local_uid":"2026-08-24_claire_liu_heather_watson","bid":0.61,"ask":0.62,"mid":0.615,"spread":0.01,"price":0.61,"size":20.0,"side":"BUY"}
{"ts":"2026-08-24T20:48:06.461Z","event_type":"price_change","market_id":"3823627","outcome_index":0,"market_type":"match","local_side":"home","local_uid":"2026-08-24_claire_liu_heather_watson","bid":0.38,"ask":0.39,"mid":0.385,"spread":0.01,"price":0.39,"size":20.0,"side":"SELL"}
{"ts":"2026-08-24T20:48:06.474Z","event_type":"best_bid_ask","market_id":"3825070","outcome_index":0,"market_type":"set2","local_side":"home","local_uid":"2026-08-24_polina_kudermetova_linda_fruhvirtova","bid":0.53,"ask":0.6,"mid":0.565,"spread":0.07,"bid_size":null,"ask_size":null}
{"ts":"2026-08-24T20:48:06.478Z","event_type":"best_bid_ask","market_id":"3825070","outcome_index":1,"market_type":"set2","local_side":"away","local_uid":"2026-08-24_polina_kudermetova_linda_fruhvirtova","bid":0.4,"ask":0.47,"mid":0.435,"spread":0.07,"bid_size":null,"ask_size":null}
{"ts":"2026-08-24T20:48:06.479Z","event_type":"price_change","market_id":"3825070","outcome_index":1,"market_type":"set2","local_side":"away","local_uid":"2026-08-24_polina_kudermetova_linda_fruhvirtova","bid":0.4,"ask":0.47,"mid":0.435,"spread":0.07,"price":0.41,"size":0.0,"side":"BUY"}
{"ts":"2026-08-24T20:48:06.479Z","event_type":"price_change","market_id":"3825070","outcome_index":0,"market_type":"set2","local_side":"home","local_uid":"2026-08-24_polina_kudermetova_linda_fruhvirtova","bid":0.53,"ask":0.6,"mid":0.565,"spread":0.07,"price":0.59,"size":0.0,"side":"SELL"}
{"ts":"2026-08-24T20:48:06.668Z","event_type":"best_bid_ask","market_id":"3823665","outcome_index":0,"market_type":"match","local_side":"home","local_uid":"2026-08-24_jazmin_ortenzi_himeno_sakatsume","bid":0.15,"ask":0.17,"mid":0.16,"spread":0.02,"bid_size":null,"ask_size":null}
{"ts":"2026-08-24T20:48:06.679Z","event_type":"best_bid_ask","market_id":"3823665","outcome_index":1,"market_type":"match","local_side":"away","local_uid":"2026-08-24_jazmin_ortenzi_himeno_sakatsume","bid":0.83,"ask":0.85,"mid":0.84,"spread":0.02,"bid_size":null,"ask_size":null}
{"ts":"2026-08-24T20:48:06.680Z","event_type":"price_change","market_id":"3823665","outcome_index":1,"market_type":"match","local_side":"away","local_uid":"2026-08-24_jazmin_ortenzi_himeno_sakatsume","bid":0.83,"ask":0.85,"mid":0.84,"spread":0.02,"price":0.84,"size":0.0,"side":"BUY"}
{"ts":"2026-08-24T20:48:06.680Z","event_type":"price_change","market_id":"3823665","outcome_index":0,"market_type":"match","local_side":"home","local_uid":"2026-08-24_jazmin_ortenzi_himeno_sakatsume","bid":0.15,"ask":0.17,"mid":0.16,"spread":0.02,"price":0.16,"size":0.0,"side":"SELL"}
{"ts":"2026-08-24T20:48:06.681Z","event_type":"best_bid_ask","market_id":"3825070","outcome_index":0,"market_type":"set2","local_side":"home","local_uid":"2026-08-24_polina_kudermetova_linda_fruhvirtova","bid":0.53,"ask":0.59,"mid":0.56,"spread":0.06,"bid_size":null,"ask_size":null}
{"ts":"2026-08-24T20:48:06.681Z","event_type":"best_bid_ask","market_id":"3825070","outcome_index":1,"market_type":"set2","local_side":"away","local_uid":"2026-08-24_polina_kudermetova_linda_fruhvirtova","bid":0.41,"ask":0.47,"mid":0.44,"spread":0.06,"bid_size":null,"ask_size":null}
{"ts":"2026-08-24T20:48:06.681Z","event_type":"price_change","market_id":"3825070","outcome_index":1,"market_type":"set2","local_side":"away","local_uid":"2026-08-24_polina_kudermetova_linda_fruhvirtova","bid":0.41,"ask":0.47,"mid":0.44,"spread":0.06,"price":0.41,"size":1281.0,"side":"BUY"}
{"ts":"2026-08-24T20:48:06.681Z","event_type":"price_change","market_id":"3825070","outcome_index":0,"market_type":"set2","local_side":"home","local_uid":"2026-08-24_polina_kudermetova_linda_fruhvirtova","bid":0.53,"ask":0.59,"mid":0.56,"spread":0.06,"price":0.59,"size":1281.0,"side":"SELL"}
{"ts":"2026-08-24T20:48:06.814Z","event_type":"best_bid_ask","market_id":"3825040","outcome_index":0,"market_type":"set2","local_side":"home","local_uid":"2026-08-24_greet_minnen_jeline_vandromme","bid":0.3,"ask":0.39,"mid":0.345,"spread":0.09,"bid_size":null,"ask_size":null}
{"ts":"2026-08-24T20:48:06.814Z","event_type":"best_bid_ask","market_id":"3825040","outcome_index":1,"market_type":"set2","local_side":"away","local_uid":"2026-08-24_greet_minnen_jeline_vandromme","bid":0.61,"ask":0.7,"mid":0.655,"spread":0.09,"bid_size":null,"ask_size":null}
{"ts":"2026-08-24T20:48:06.815Z","event_type":"price_change","market_id":"3825040","outcome_index":0,"market_type":"set2","local_side":"home","local_uid":"2026-08-24_greet_minnen_jeline_vandromme","bid":0.3,"ask":0.39,"mid":0.345,"spread":0.09,"price":0.31,"size":0.0,"side":"BUY"}
{"ts":"2026-08-24T20:48:06.815Z","event_type":"price_change","market_id":"3825040","outcome_index":1,"market_type":"set2","local_side":"away","local_uid":"2026-08-24_greet_minnen_jeline_vandromme","bid":0.61,"ask":0.7,"mid":0.655,"spread":0.09,"price":0.69,"size":0.0,"side":"SELL"}
{"ts":"2026-08-24T20:48:06.816Z","event_type":"best_bid_ask","market_id":"3825040","outcome_index":0,"market_type":"set2","local_side":"home","local_uid":"2026-08-24_greet_minnen_jeline_vandromme","bid":0.31,"ask":0.39,"mid":0.35,"spread":0.08,"bid_size":null,"ask_size":null}
{"ts":"2026-08-24T20:48:06.816Z","event_type":"best_bid_ask","market_id":"3825040","outcome_index":1,"market_type":"set2","local_side":"away","local_uid":"2026-08-24_greet_minnen_jeline_vandromme","bid":0.61,"ask":0.69,"mid":0.65,"spread":0.08,"bid_size":null,"ask_size":null}
{"ts":"2026-08-24T20:48:06.817Z","event_type":"price_change","market_id":"3825040","outcome_index":0,"market_type":"set2","local_side":"home","local_uid":"2026-08-24_greet_minnen_jeline_vandromme","bid":0.31,"ask":0.39,"mid":0.35,"spread":0.08,"price":0.31,"size":656.0,"side":"BUY"}
{"ts":"2026-08-24T20:48:06.817Z","event_type":"price_change","market_id":"3825040","outcome_index":1,"market_type":"set2","local_side":"away","local_uid":"2026-08-24_greet_minnen_jeline_vandromme","bid":0.61,"ask":0.69,"mid":0.65,"spread":0.08,"price":0.69,"size":656.0,"side":"SELL"}
{"ts":"2026-08-24T20:48:06.874Z","event_type":"book","market_id":"3825077","outcome_index":0,"market_type":"set1","local_side":"home","local_uid":"2026-08-24_polina_kudermetova_linda_fruhvirtova","bid":0.45,"ask":0.46,"mid":0.455,"spread":0.01,"bid_size":24.54,"ask_size":2003.15}
{"ts":"2026-08-24T20:48:06.874Z","event_type":"book","market_id":"3825077","outcome_index":1,"market_type":"set1","local_side":"away","local_uid":"2026-08-24_polina_kudermetova_linda_fruhvirtova","bid":0.54,"ask":0.55,"mid":0.545,"spread":0.01,"bid_size":2003.15,"ask_size":24.54}
{"ts":"2026-08-24T20:48:06.876Z","event_type":"best_bid_ask","market_id":"3825040","outcome_index":0,"market_type":"set2","local_side":"home","local_uid":"2026-08-24_greet_minnen_jeline_vandromme","bid":0.3,"ask":0.39,"mid":0.345,"spread":0.09,"bid_size":null,"ask_size":null}
{"ts":"2026-08-24T20:48:06.877Z","event_type":"best_bid_ask","market_id":"3825040","outcome_index":1,"market_type":"set2","local_side":"away","local_uid":"2026-08-24_greet_minnen_jeline_vandromme","bid":0.61,"ask":0.7,"mid":0.655,"spread":0.09,"bid_size":null,"ask_size":null}
{"ts":"2026-08-24T20:48:06.877Z","event_type":"price_change","market_id":"3825040","outcome_index":0,"market_type":"set2","local_side":"home","local_uid":"2026-08-24_greet_minnen_jeline_vandromme","bid":0.3,"ask":0.39,"mid":0.345,"spread":0.09,"price":0.31,"size":0.0,"side":"BUY"}
{"ts":"2026-08-24T20:48:06.877Z","event_type":"price_change","market_id":"3825040","outcome_index":1,"market_type":"set2","local_side":"away","local_uid":"2026-08-24_greet_minnen_jeline_vandromme","bid":0.61,"ask":0.7,"mid":0.655,"spread":0.09,"price":0.69,"size":0.0,"side":"SELL"}
{"ts":"2026-08-24T20:48:06.891Z","event_type":"best_bid_ask","market_id":"3825040","outcome_index":0,"market_type":"set2","local_side":"home","local_uid":"2026-08-24_greet_minnen_jeline_vandromme","bid":0.31,"ask":0.39,"mid":0.35,"spread":0.08,"bid_size":null,"ask_size":null}
{"ts":"2026-08-24T20:48:06.891Z","event_type":"best_bid_ask","market_id":"3825040","outcome_index":1,"market_type":"set2","local_side":"away","local_uid":"2026-08-24_greet_minnen_jeline_vandromme","bid":0.61,"ask":0.69,"mid":0.65,"spread":0.08,"bid_size":null,"ask_size":null}
{"ts":"2026-08-24T20:48:06.891Z","event_type":"price_change","market_id":"3825040","outcome_index":0,"market_type":"set2","local_side":"home","local_uid":"2026-08-24_greet_minnen_jeline_vandromme","bid":0.31,"ask":0.39,"mid":0.35,"spread":0.08,"price":0.31,"size":625.0,"side":"BUY"}
{"ts":"2026-08-24T20:48:06.891Z","event_type":"price_change","market_id":"3825040","outcome_index":1,"market_type":"set2","local_side":"away","local_uid":"2026-08-24_greet_minnen_jeline_vandromme","bid":0.61,"ask":0.69,"mid":0.65,"spread":0.08,"price":0.69,"size":625.0,"side":"SELL"}
{"ts":"2026-08-24T20:48:06.892Z","event_type":"best_bid_ask","market_id":"3825040","outcome_index":0,"market_type":"set2","local_side":"home","local_uid":"2026-08-24_greet_minnen_jeline_vandromme","bid":0.31,"ask":0.4,"mid":0.355,"spread":0.09,"bid_size":null,"ask_size":null}
{"ts":"2026-08-24T20:48:06.892Z","event_type":"best_bid_ask","market_id":"3825040","outcome_index":1,"market_type":"set2","local_side":"away","local_uid":"2026-08-24_greet_minnen_jeline_vandromme","bid":0.6,"ask":0.69,"mid":0.645,"spread":0.09,"bid_size":null,"ask_size":null}
{"ts":"2026-08-24T20:48:06.892Z","event_type":"price_change","market_id":"3825040","outcome_index":1,"market_type":"set2","local_side":"away","local_uid":"2026-08-24_greet_minnen_jeline_vandromme","bid":0.6,"ask":0.69,"mid":0.645,"spread":0.09,"price":0.61,"size":0.0,"side":"BUY"}
{"ts":"2026-08-24T20:48:06.893Z","event_type":"price_change","market_id":"3825040","outcome_index":0,"market_type":"set2","local_side":"home","local_uid":"2026-08-24_greet_minnen_jeline_vandromme","bid":0.31,"ask":0.4,"mid":0.355,"spread":0.09,"price":0.39,"size":0.0,"side":"SELL"}
{"ts":"2026-08-24T20:48:06.920Z","event_type":"best_bid_ask","market_id":"3825040","outcome_index":0,"market_type":"set2","local_side":"home","local_uid":"2026-08-24_greet_minnen_jeline_vandromme","bid":0.27,"ask":0.4,"mid":0.335,"spread":0.13,"bid_size":null,"ask_size":null}
{"ts":"2026-08-24T20:48:06.920Z","event_type":"best_bid_ask","market_id":"3825040","outcome_index":1,"market_type":"set2","local_side":"away","local_uid":"2026-08-24_greet_minnen_jeline_vandromme","bid":0.6,"ask":0.73,"mid":0.665,"spread":0.13,"bid_size":null,"ask_size":null}
{"ts":"2026-08-24T20:48:06.924Z","event_type":"price_change","market_id":"3825040","outcome_index":0,"market_type":"set2","local_side":"home","local_uid":"2026-08-24_greet_minnen_jeline_vandromme","bid":0.27,"ask":0.4,"mid":0.335,"spread":0.13,"price":0.31,"size":0.0,"side":"BUY"}
{"ts":"2026-08-24T20:48:06.924Z","event_type":"price_change","market_id":"3825040","outcome_index":1,"market_type":"set2","local_side":"away","local_uid":"2026-08-24_greet_minnen_jeline_vandromme","bid":0.6,"ask":0.73,"mid":0.665,"spread":0.13,"price":0.69,"size":0.0,"side":"SELL"}
{"ts":"2026-08-24T20:48:06.925Z","event_type":"best_bid_ask","market_id":"3825040","outcome_index":0,"market_type":"set2","local_side":"home","local_uid":"2026-08-24_greet_minnen_jeline_vandromme","bid":0.28,"ask":0.4,"mid":0.34,"spread":0.12,"bid_size":null,"ask_size":null}
{"ts":"2026-08-24T20:48:06.925Z","event_type":"best_bid_ask","market_id":"3825040","outcome_index":1,"market_type":"set2","local_side":"away","local_uid":"2026-08-24_greet_minnen_jeline_vandromme","bid":0.6,"ask":0.72,"mid":0.66,"spread":0.12,"bid_size":null,"ask_size":null}
{"ts":"2026-08-24T20:48:06.926Z","event_type":"price_change","market_id":"3825040","outcome_index":0,"market_type":"set2","local_side":"home","local_uid":"2026-08-24_greet_minnen_jeline_vandromme","bid":0.28,"ask":0.4,"mid":0.34,"spread":0.12,"price":0.28,"size":150.0,"side":"BUY"}
{"ts":"2026-08-24T20:48:06.926Z","event_type":"price_change","market_id":"3825040","outcome_index":1,"market_type":"set2","local_side":"away","local_uid":"2026-08-24_greet_minnen_jeline_vandromme","bid":0.6,"ask":0.72,"mid":0.66,"spread":0.12,"price":0.72,"size":150.0,"side":"SELL"}
{"ts":"2026-08-24T20:48:06.938Z","event_type":"best_bid_ask","market_id":"3825040","outcome_index":0,"market_type":"set2","local_side":"home","local_uid":"2026-08-24_greet_minnen_jeline_vandromme","bid":0.29,"ask":0.4,"mid":0.345,"spread":0.11,"bid_size":null,"ask_size":null}
{"ts":"2026-08-24T20:48:06.938Z","event_type":"best_bid_ask","market_id":"3825040","outcome_index":1,"market_type":"set2","local_side":"away","local_uid":"2026-08-24_greet_minnen_jeline_vandromme","bid":0.6,"ask":0.71,"mid":0.655,"spread":0.11,"bid_size":null,"ask_size":null}
{"ts":"2026-08-24T20:48:06.939Z","event_type":"price_change","market_id":"3825040","outcome_index":0,"market_type":"set2","local_side":"home","local_uid":"2026-08-24_greet_minnen_jeline_vandromme","bid":0.29,"ask":0.4,"mid":0.345,"spread":0.11,"price":0.29,"size":1531.0,"side":"BUY"}
{"ts":"2026-08-24T20:48:06.939Z","event_type":"price_change","market_id":"3825040","outcome_index":1,"market_type":"set2","local_side":"away","local_uid":"2026-08-24_greet_minnen_jeline_vandromme","bid":0.6,"ask":0.71,"mid":0.655,"spread":0.11,"price":0.71,"size":1531.0,"side":"SELL"}
{"ts":"2026-08-24T20:48:06.950Z","event_type":"last_trade_price","market_id":"3825077","outcome_index":1,"market_type":"set1","local_side":"away","local_uid":"2026-08-24_polina_kudermetova_linda_fruhvirtova","last_trade":0.55,"trade_size":5.4545,"trade_side":"BUY","trade_notional":3.0}
{"ts":"2026-08-24T20:48:07.150Z","event_type":"best_bid_ask","market_id":"3824761","outcome_index":0,"market_type":"set1","local_side":"home","local_uid":"2026-08-24_jazmin_ortenzi_himeno_sakatsume","bid":0.15,"ask":0.3,"mid":0.225,"spread":0.15,"bid_size":null,"ask_size":null}
{"ts":"2026-08-24T20:48:07.158Z","event_type":"best_bid_ask","market_id":"3824761","outcome_index":1,"market_type":"set1","local_side":"away","local_uid":"2026-08-24_jazmin_ortenzi_himeno_sakatsume","bid":0.7,"ask":0.85,"mid":0.775,"spread":0.15,"bid_size":null,"ask_size":null}
{"ts":"2026-08-24T20:48:07.158Z","event_type":"price_change","market_id":"3824761","outcome_index":0,"market_type":"set1","local_side":"home","local_uid":"2026-08-24_jazmin_ortenzi_himeno_sakatsume","bid":0.15,"ask":0.3,"mid":0.225,"spread":0.15,"price":0.15,"size":281.0,"side":"BUY"}
{"ts":"2026-08-24T20:48:07.159Z","event_type":"price_change","market_id":"3824761","outcome_index":1,"market_type":"set1","local_side":"away","local_uid":"2026-08-24_jazmin_ortenzi_himeno_sakatsume","bid":0.7,"ask":0.85,"mid":0.775,"spread":0.15,"price":0.85,"size":281.0,"side":"SELL"}
{"ts":"2026-08-24T20:48:07.164Z","event_type":"best_bid_ask","market_id":"3825053","outcome_index":0,"market_type":"set1","local_side":"home","local_uid":"2026-08-24_robin_montgomery_kayla_cross","bid":0.88,"ask":0.93,"mid":0.905,"spread":0.05,"bid_size":null,"ask_size":null}
{"ts":"2026-08-24T20:48:07.165Z","event_type":"best_bid_ask","market_id":"3825053","outcome_index":1,"market_type":"set1","local_side":"away","local_uid":"2026-08-24_robin_montgomery_kayla_cross","bid":0.07,"ask":0.12,"mid":0.095,"spread":0.05,"bid_size":null,"ask_size":null}
{"ts":"2026-08-24T20:48:07.173Z","event_type":"price_change","market_id":"3825053","outcome_index":0,"market_type":"set1","local_side":"home","local_uid":"2026-08-24_robin_montgomery_kayla_cross","bid":0.88,"ask":0.93,"mid":0.905,"spread":0.05,"price":0.89,"size":0.0,"side":"BUY"}
{"ts":"2026-08-24T20:48:07.173Z","event_type":"price_change","market_id":"3825053","outcome_index":1,"market_type":"set1","local_side":"away","local_uid":"2026-08-24_robin_montgomery_kayla_cross","bid":0.07,"ask":0.12,"mid":0.095,"spread":0.05,"price":0.11,"size":0.0,"side":"SELL"}
{"ts":"2026-08-24T20:48:07.211Z","event_type":"best_bid_ask","market_id":"3825053","outcome_index":0,"market_type":"set1","local_side":"home","local_uid":"2026-08-24_robin_montgomery_kayla_cross","bid":0.87,"ask":0.93,"mid":0.9,"spread":0.06,"bid_size":null,"ask_size":null}
{"ts":"2026-08-24T20:48:07.211Z","event_type":"best_bid_ask","market_id":"3825053","outcome_index":1,"market_type":"set1","local_side":"away","local_uid":"2026-08-24_robin_montgomery_kayla_cross","bid":0.07,"ask":0.13,"mid":0.1,"spread":0.06,"bid_size":null,"ask_size":null}
{"ts":"2026-08-24T20:48:07.211Z","event_type":"price_change","market_id":"3825053","outcome_index":0,"market_type":"set1","local_side":"home","local_uid":"2026-08-24_robin_montgomery_kayla_cross","bid":0.87,"ask":0.93,"mid":0.9,"spread":0.06,"price":0.88,"size":0.0,"side":"BUY"}
{"ts":"2026-08-24T20:48:07.211Z","event_type":"price_change","market_id":"3825053","outcome_index":1,"market_type":"set1","local_side":"away","local_uid":"2026-08-24_robin_montgomery_kayla_cross","bid":0.07,"ask":0.13,"mid":0.1,"spread":0.06,"price":0.12,"size":0.0,"side":"SELL"}
{"ts":"2026-08-24T20:48:07.212Z","event_type":"best_bid_ask","market_id":"3825053","outcome_index":0,"market_type":"set1","local_side":"home","local_uid":"2026-08-24_robin_montgomery_kayla_cross","bid":0.88,"ask":0.93,"mid":0.905,"spread":0.05,"bid_size":null,"ask_size":null}
{"ts":"2026-08-24T20:48:07.212Z","event_type":"best_bid_ask","market_id":"3825053","outcome_index":1,"market_type":"set1","local_side":"away","local_uid":"2026-08-24_robin_montgomery_kayla_cross","bid":0.07,"ask":0.12,"mid":0.095,"spread":0.05,"bid_size":null,"ask_size":null}
{"ts":"2026-08-24T20:48:07.213Z","event_type":"price_change","market_id":"3825053","outcome_index":0,"market_type":"set1","local_side":"home","local_uid":"2026-08-24_robin_montgomery_kayla_cross","bid":0.88,"ask":0.93,"mid":0.905,"spread":0.05,"price":0.88,"size":150.0,"side":"BUY"}
{"ts":"2026-08-24T20:48:07.213Z","event_type":"price_change","market_id":"3825053","outcome_index":1,"market_type":"set1","local_side":"away","local_uid":"2026-08-24_robin_montgomery_kayla_cross","bid":0.07,"ask":0.12,"mid":0.095,"spread":0.05,"price":0.12,"size":150.0,"side":"SELL"}
{"ts":"2026-08-24T20:48:07.222Z","event_type":"best_bid_ask","market_id":"3824761","outcome_index":0,"market_type":"set1","local_side":"home","local_uid":"2026-08-24_jazmin_ortenzi_himeno_sakatsume","bid":0.15,"ask":0.29,"mid":0.22,"spread":0.14,"bid_size":null,"ask_size":null}
{"ts":"2026-08-24T20:48:07.222Z","event_type":"best_bid_ask","market_id":"3824761","outcome_index":1,"market_type":"set1","local_side":"away","local_uid":"2026-08-24_jazmin_ortenzi_himeno_sakatsume","bid":0.71,"ask":0.85,"mid":0.78,"spread":0.14,"bid_size":null,"ask_size":null}
{"ts":"2026-08-24T20:48:07.223Z","event_type":"price_change","market_id":"3824761","outcome_index":1,"market_type":"set1","local_side":"away","local_uid":"2026-08-24_jazmin_ortenzi_himeno_sakatsume","bid":0.71,"ask":0.85,"mid":0.78,"spread":0.14,"price":0.71,"size":250.0,"side":"BUY"}
{"ts":"2026-08-24T20:48:07.223Z","event_type":"price_change","market_id":"3824761","outcome_index":0,"market_type":"set1","local_side":"home","local_uid":"2026-08-24_jazmin_ortenzi_himeno_sakatsume","bid":0.15,"ask":0.29,"mid":0.22,"spread":0.14,"price":0.29,"size":250.0,"side":"SELL"}
{"ts":"2026-08-24T20:48:07.281Z","event_type":"best_bid_ask","market_id":"3825053","outcome_index":0,"market_type":"set1","local_side":"home","local_uid":"2026-08-24_robin_montgomery_kayla_cross","bid":0.87,"ask":0.93,"mid":0.9,"spread":0.06,"bid_size":null,"ask_size":null}
{"ts":"2026-08-24T20:48:07.281Z","event_type":"best_bid_ask","market_id":"3825053","outcome_index":1,"market_type":"set1","local_side":"away","local_uid":"2026-08-24_robin_montgomery_kayla_cross","bid":0.07,"ask":0.13,"mid":0.1,"spread":0.06,"bid_size":null,"ask_size":null}
{"ts":"2026-08-24T20:48:07.282Z","event_type":"price_change","market_id":"3825053","outcome_index":0,"market_type":"set1","local_side":"home","local_uid":"2026-08-24_robin_montgomery_kayla_cross","bid":0.87,"ask":0.93,"mid":0.9,"spread":0.06,"price":0.88,"size":0.0,"side":"BUY"}
{"ts":"2026-08-24T20:48:07.282Z","event_type":"price_change","market_id":"3825053","outcome_index":1,"market_type":"set1","local_side":"away","local_uid":"2026-08-24_robin_montgomery_kayla_cross","bid":0.07,"ask":0.13,"mid":0.1,"spread":0.06,"price":0.12,"size":0.0,"side":"SELL"}
{"ts":"2026-08-24T20:48:07.295Z","event_type":"best_bid_ask","market_id":"3825053","outcome_index":0,"market_type":"set1","local_side":"home","local_uid":"2026-08-24_robin_montgomery_kayla_cross","bid":0.88,"ask":0.93,"mid":0.905,"spread":0.05,"bid_size":null,"ask_size":null}
{"ts":"2026-08-24T20:48:07.296Z","event_type":"best_bid_ask","market_id":"3825053","outcome_index":1,"market_type":"set1","local_side":"away","local_uid":"2026-08-24_robin_montgomery_kayla_cross","bid":0.07,"ask":0.12,"mid":0.095,"spread":0.05,"bid_size":null,"ask_size":null}
{"ts":"2026-08-24T20:48:07.296Z","event_type":"price_change","market_id":"3825053","outcome_index":0,"market_type":"set1","local_side":"home","local_uid":"2026-08-24_robin_montgomery_kayla_cross","bid":0.88,"ask":0.93,"mid":0.905,"spread":0.05,"price":0.88,"size":21.7,"side":"BUY"}
{"ts":"2026-08-24T20:48:07.296Z","event_type":"price_change","market_id":"3825053","outcome_index":1,"market_type":"set1","local_side":"away","local_uid":"2026-08-24_robin_montgomery_kayla_cross","bid":0.07,"ask":0.12,"mid":0.095,"spread":0.05,"price":0.12,"size":21.7,"side":"SELL"}
{"ts":"2026-08-24T20:48:07.298Z","event_type":"last_trade_price","market_id":"3823627","outcome_index":1,"market_type":"match","local_side":"away","local_uid":"2026-08-24_claire_liu_heather_watson","last_trade":0.62,"trade_size":9.6774,"trade_side":"BUY","trade_notional":6.0}
{"ts":"2026-08-24T20:48:07.319Z","event_type":"best_bid_ask","market_id":"3823627","outcome_index":0,"market_type":"match","local_side":"home","local_uid":"2026-08-24_claire_liu_heather_watson","bid":0.37,"ask":0.39,"mid":0.38,"spread":0.02,"bid_size":null,"ask_size":null}
{"ts":"2026-08-24T20:48:07.319Z","event_type":"best_bid_ask","market_id":"3823627","outcome_index":1,"market_type":"match","local_side":"away","local_uid":"2026-08-24_claire_liu_heather_watson","bid":0.61,"ask":0.63,"mid":0.62,"spread":0.02,"bid_size":null,"ask_size":null}
{"ts":"2026-08-24T20:48:07.320Z","event_type":"price_change","market_id":"3823627","outcome_index":0,"market_type":"match","local_side":"home","local_uid":"2026-08-24_claire_liu_heather_watson","bid":0.37,"ask":0.39,"mid":0.38,"spread":0.02,"price":0.38,"size":0.0,"side":"BUY"}
{"ts":"2026-08-24T20:48:07.320Z","event_type":"price_change","market_id":"3823627","outcome_index":1,"market_type":"match","local_side":"away","local_uid":"2026-08-24_claire_liu_heather_watson","bid":0.61,"ask":0.63,"mid":0.62,"spread":0.02,"price":0.62,"size":0.0,"side":"SELL"}
{"ts":"2026-08-24T20:48:07.341Z","event_type":"best_bid_ask","market_id":"3825053","outcome_index":0,"market_type":"set1","local_side":"home","local_uid":"2026-08-24_robin_montgomery_kayla_cross","bid":0.86,"ask":0.93,"mid":0.895,"spread":0.07,"bid_size":null,"ask_size":null}
{"ts":"2026-08-24T20:48:07.344Z","event_type":"best_bid_ask","market_id":"3825053","outcome_index":1,"market_type":"set1","local_side":"away","local_uid":"2026-08-24_robin_montgomery_kayla_cross","bid":0.07,"ask":0.14,"mid":0.105,"spread":0.07,"bid_size":null,"ask_size":null}
{"ts":"2026-08-24T20:48:07.344Z","event_type":"price_change","market_id":"3825053","outcome_index":0,"market_type":"set1","local_side":"home","local_uid":"2026-08-24_robin_montgomery_kayla_cross","bid":0.86,"ask":0.93,"mid":0.895,"spread":0.07,"price":0.88,"size":0.0,"side":"BUY"}
{"ts":"2026-08-24T20:48:07.344Z","event_type":"price_change","market_id":"3825053","outcome_index":1,"market_type":"set1","local_side":"away","local_uid":"2026-08-24_robin_montgomery_kayla_cross","bid":0.07,"ask":0.14,"mid":0.105,"spread":0.07,"price":0.12,"size":0.0,"side":"SELL"}
{"ts":"2026-08-24T20:48:07.831Z","event_type":"best_bid_ask","market_id":"3824761","outcome_index":0,"market_type":"set1","local_side":"home","local_uid":"2026-08-24_jazmin_ortenzi_himeno_sakatsume","bid":0.14,"ask":0.29,"mid":0.215,"spread":0.15,"bid_size":null,"ask_size":null}
{"ts":"2026-08-24T20:48:07.831Z","event_type":"best_bid_ask","market_id":"3824761","outcome_index":1,"market_type":"set1","local_side":"away","local_uid":"2026-08-24_jazmin_ortenzi_himeno_sakatsume","bid":0.71,"ask":0.86,"mid":0.785,"spread":0.15,"bid_size":null,"ask_size":null}
{"ts":"2026-08-24T20:48:07.831Z","event_type":"price_change","market_id":"3824761","outcome_index":0,"market_type":"set1","local_side":"home","local_uid":"2026-08-24_jazmin_ortenzi_himeno_sakatsume","bid":0.14,"ask":0.29,"mid":0.215,"spread":0.15,"price":0.15,"size":0.0,"side":"BUY"}
{"ts":"2026-08-24T20:48:07.832Z","event_type":"price_change","market_id":"3824761","outcome_index":1,"market_type":"set1","local_side":"away","local_uid":"2026-08-24_jazmin_ortenzi_himeno_sakatsume","bid":0.71,"ask":0.86,"mid":0.785,"spread":0.15,"price":0.85,"size":0.0,"side":"SELL"}
{"ts":"2026-08-24T20:48:08.087Z","event_type":"book","market_id":"3823627","outcome_index":0,"market_type":"match","local_side":"home","local_uid":"2026-08-24_claire_liu_heather_watson","bid":0.37,"ask":0.39,"mid":0.38,"spread":0.02,"bid_size":321.85,"ask_size":4584.22}
{"ts":"2026-08-24T20:48:08.087Z","event_type":"book","market_id":"3823627","outcome_index":1,"market_type":"match","local_side":"away","local_uid":"2026-08-24_claire_liu_heather_watson","bid":0.61,"ask":0.63,"mid":0.62,"spread":0.02,"bid_size":4584.22,"ask_size":321.85}
{"ts":"2026-08-24T20:48:08.094Z","event_type":"best_bid_ask","market_id":"3823627","outcome_index":0,"market_type":"match","local_side":"home","local_uid":"2026-08-24_claire_liu_heather_watson","bid":0.37,"ask":0.38,"mid":0.375,"spread":0.01,"bid_size":null,"ask_size":null}
{"ts":"2026-08-24T20:48:08.094Z","event_type":"best_bid_ask","market_id":"3823627","outcome_index":1,"market_type":"match","local_side":"away","local_uid":"2026-08-24_claire_liu_heather_watson","bid":0.62,"ask":0.63,"mid":0.625,"spread":0.01,"bid_size":null,"ask_size":null}
{"ts":"2026-08-24T20:48:08.095Z","event_type":"price_change","market_id":"3823627","outcome_index":1,"market_type":"match","local_side":"away","local_uid":"2026-08-24_claire_liu_heather_watson","bid":0.62,"ask":0.63,"mid":0.625,"spread":0.01,"price":0.62,"size":40.0,"side":"BUY"}
{"ts":"2026-08-24T20:48:08.095Z","event_type":"price_change","market_id":"3823627","outcome_index":0,"market_type":"match","local_side":"home","local_uid":"2026-08-24_claire_liu_heather_watson","bid":0.37,"ask":0.38,"mid":0.375,"spread":0.01,"price":0.38,"size":40.0,"side":"SELL"}
{"ts":"2026-08-24T20:48:08.300Z","event_type":"best_bid_ask","market_id":"3825053","outcome_index":0,"market_type":"set1","local_side":"home","local_uid":"2026-08-24_robin_montgomery_kayla_cross","bid":0.86,"ask":0.94,"mid":0.9,"spread":0.08,"bid_size":null,"ask_size":null}
{"ts":"2026-08-24T20:48:08.300Z","event_type":"best_bid_ask","market_id":"3825053","outcome_index":1,"market_type":"set1","local_side":"away","local_uid":"2026-08-24_robin_montgomery_kayla_cross","bid":0.06,"ask":0.14,"mid":0.1,"spread":0.08,"bid_size":null,"ask_size":null}
{"ts":"2026-08-24T20:48:08.301Z","event_type":"price_change","market_id":"3825053","outcome_index":0,"market_type":"set1","local_side":"home","local_uid":"2026-08-24_robin_montgomery_kayla_cross","bid":0.86,"ask":0.94,"mid":0.9,"spread":0.08,"price":0.85,"size":226.0,"side":"BUY"}
{"ts":"2026-08-24T20:48:08.301Z","event_type":"price_change","market_id":"3825053","outcome_index":1,"market_type":"set1","local_side":"away","local_uid":"2026-08-24_robin_montgomery_kayla_cross","bid":0.06,"ask":0.14,"mid":0.1,"spread":0.08,"price":0.15,"size":226.0,"side":"SELL"}
{"ts":"2026-08-24T20:48:08.301Z","event_type":"last_trade_price","market_id":"3823627","outcome_index":1,"market_type":"match","local_side":"away","local_uid":"2026-08-24_claire_liu_heather_watson","last_trade":0.63,"trade_size":2.3492,"trade_side":"BUY","trade_notional":1.48}
{"ts":"2026-08-24T20:48:08.422Z","event_type":"last_trade_price","market_id":"3823627","outcome_index":1,"market_type":"match","local_side":"away","local_uid":"2026-08-24_claire_liu_heather_watson","last_trade":0.63,"trade_size":1.6984,"trade_side":"BUY","trade_notional":1.07}
{"ts":"2026-08-24T20:48:08.432Z","event_type":"best_bid_ask","market_id":"3823627","outcome_index":0,"market_type":"match","local_side":"home","local_uid":"2026-08-24_claire_liu_heather_watson","bid":0.37,"ask":0.39,"mid":0.38,"spread":0.02,"bid_size":null,"ask_size":null}
{"ts":"2026-08-24T20:48:08.432Z","event_type":"best_bid_ask","market_id":"3823627","outcome_index":1,"market_type":"match","local_side":"away","local_uid":"2026-08-24_claire_liu_heather_watson","bid":0.61,"ask":0.63,"mid":0.62,"spread":0.02,"bid_size":null,"ask_size":null}
{"ts":"2026-08-24T20:48:08.432Z","event_type":"price_change","market_id":"3823627","outcome_index":1,"market_type":"match","local_side":"away","local_uid":"2026-08-24_claire_liu_heather_watson","bid":0.61,"ask":0.63,"mid":0.62,"spread":0.02,"price":0.62,"size":0.0,"side":"BUY"}
{"ts":"2026-08-24T20:48:08.433Z","event_type":"price_change","market_id":"3823627","outcome_index":0,"market_type":"match","local_side":"home","local_uid":"2026-08-24_claire_liu_heather_watson","bid":0.37,"ask":0.39,"mid":0.38,"spread":0.02,"price":0.38,"size":0.0,"side":"SELL"}
{"ts":"2026-08-24T20:48:08.440Z","event_type":"best_bid_ask","market_id":"3823627","outcome_index":0,"market_type":"match","local_side":"home","local_uid":"2026-08-24_claire_liu_heather_watson","bid":0.37,"ask":0.38,"mid":0.375,"spread":0.01,"bid_size":null,"ask_size":null}
{"ts":"2026-08-24T20:48:08.440Z","event_type":"best_bid_ask","market_id":"3823627","outcome_index":1,"market_type":"match","local_side":"away","local_uid":"2026-08-24_claire_liu_heather_watson","bid":0.62,"ask":0.63,"mid":0.625,"spread":0.01,"bid_size":null,"ask_size":null}
{"ts":"2026-08-24T20:48:08.440Z","event_type":"price_change","market_id":"3823627","outcome_index":1,"market_type":"match","local_side":"away","local_uid":"2026-08-24_claire_liu_heather_watson","bid":0.62,"ask":0.63,"mid":0.625,"spread":0.01,"price":0.62,"size":150.0,"side":"BUY"}
{"ts":"2026-08-24T20:48:08.440Z","event_type":"price_change","market_id":"3823627","outcome_index":0,"market_type":"match","local_side":"home","local_uid":"2026-08-24_claire_liu_heather_watson","bid":0.37,"ask":0.38,"mid":0.375,"spread":0.01,"price":0.38,"size":150.0,"side":"SELL"}
{"ts":"2026-08-24T20:48:08.445Z","event_type":"best_bid_ask","market_id":"3823627","outcome_index":0,"market_type":"match","local_side":"home","local_uid":"2026-08-24_claire_liu_heather_watson","bid":0.37,"ask":0.39,"mid":0.38,"spread":0.02,"bid_size":null,"ask_size":null}
{"ts":"2026-08-24T20:48:08.445Z","event_type":"best_bid_ask","market_id":"3823627","outcome_index":1,"market_type":"match","local_side":"away","local_uid":"2026-08-24_claire_liu_heather_watson","bid":0.61,"ask":0.63,"mid":0.62,"spread":0.02,"bid_size":null,"ask_size":null}
{"ts":"2026-08-24T20:48:08.446Z","event_type":"price_change","market_id":"3823627","outcome_index":1,"market_type":"match","local_side":"away","local_uid":"2026-08-24_claire_liu_heather_watson","bid":0.61,"ask":0.63,"mid":0.62,"spread":0.02,"price":0.62,"size":0.0,"side":"BUY"}
{"ts":"2026-08-24T20:48:08.446Z","event_type":"price_change","market_id":"3823627","outcome_index":0,"market_type":"match","local_side":"home","local_uid":"2026-08-24_claire_liu_heather_watson","bid":0.37,"ask":0.39,"mid":0.38,"spread":0.02,"price":0.38,"size":0.0,"side":"SELL"}
{"ts":"2026-08-24T20:48:08.461Z","event_type":"best_bid_ask","market_id":"3823627","outcome_index":0,"market_type":"match","local_side":"home","local_uid":"2026-08-24_claire_liu_heather_watson","bid":0.37,"ask":0.38,"mid":0.375,"spread":0.01,"bid_size":null,"ask_size":null}
{"ts":"2026-08-24T20:48:08.461Z","event_type":"best_bid_ask","market_id":"3823627","outcome_index":1,"market_type":"match","local_side":"away","local_uid":"2026-08-24_claire_liu_heather_watson","bid":0.62,"ask":0.63,"mid":0.625,"spread":0.01,"bid_size":null,"ask_size":null}
{"ts":"2026-08-24T20:48:08.461Z","event_type":"price_change","market_id":"3823627","outcome_index":1,"market_type":"match","local_side":"away","local_uid":"2026-08-24_claire_liu_heather_watson","bid":0.62,"ask":0.63,"mid":0.625,"spread":0.01,"price":0.62,"size":150.0,"side":"BUY"}
{"ts":"2026-08-24T20:48:08.462Z","event_type":"price_change","market_id":"3823627","outcome_index":0,"market_type":"match","local_side":"home","local_uid":"2026-08-24_claire_liu_heather_watson","bid":0.37,"ask":0.38,"mid":0.375,"spread":0.01,"price":0.38,"size":150.0,"side":"SELL"}
{"ts":"2026-08-24T20:48:08.502Z","event_type":"best_bid_ask","market_id":"3823627","outcome_index":0,"market_type":"match","local_side":"home","local_uid":"2026-08-24_claire_liu_heather_watson","bid":0.37,"ask":0.39,"mid":0.38,"spread":0.02,"bid_size":null,"ask_size":null}
{"ts":"2026-08-24T20:48:08.502Z","event_type":"best_bid_ask","market_id":"3823627","outcome_index":1,"market_type":"match","local_side":"away","local_uid":"2026-08-24_claire_liu_heather_watson","bid":0.61,"ask":0.63,"mid":0.62,"spread":0.02,"bid_size":null,"ask_size":null}
{"ts":"2026-08-24T20:48:08.502Z","event_type":"price_change","market_id":"3823627","outcome_index":1,"market_type":"match","local_side":"away","local_uid":"2026-08-24_claire_liu_heather_watson","bid":0.61,"ask":0.63,"mid":0.62,"spread":0.02,"price":0.62,"size":0.0,"side":"BUY"}
{"ts":"2026-08-24T20:48:08.502Z","event_type":"price_change","market_id":"3823627","outcome_index":0,"market_type":"match","local_side":"home","local_uid":"2026-08-24_claire_liu_heather_watson","bid":0.37,"ask":0.39,"mid":0.38,"spread":0.02,"price":0.38,"size":0.0,"side":"SELL"}
{"ts":"2026-08-24T20:48:08.516Z","event_type":"best_bid_ask","market_id":"3823627","outcome_index":0,"market_type":"match","local_side":"home","local_uid":"2026-08-24_claire_liu_heather_watson","bid":0.37,"ask":0.38,"mid":0.375,"spread":0.01,"bid_size":null,"ask_size":null}
{"ts":"2026-08-24T20:48:08.517Z","event_type":"best_bid_ask","market_id":"3823627","outcome_index":1,"market_type":"match","local_side":"away","local_uid":"2026-08-24_claire_liu_heather_watson","bid":0.62,"ask":0.63,"mid":0.625,"spread":0.01,"bid_size":null,"ask_size":null}
{"ts":"2026-08-24T20:48:08.517Z","event_type":"price_change","market_id":"3823627","outcome_index":1,"market_type":"match","local_side":"away","local_uid":"2026-08-24_claire_liu_heather_watson","bid":0.62,"ask":0.63,"mid":0.625,"spread":0.01,"price":0.62,"size":150.0,"side":"BUY"}
{"ts":"2026-08-24T20:48:08.517Z","event_type":"price_change","market_id":"3823627","outcome_index":0,"market_type":"match","local_side":"home","local_uid":"2026-08-24_claire_liu_heather_watson","bid":0.37,"ask":0.38,"mid":0.375,"spread":0.01,"price":0.38,"size":150.0,"side":"SELL"}
{"ts":"2026-08-24T20:48:08.713Z","event_type":"best_bid_ask","market_id":"3825641","outcome_index":0,"market_type":"match","local_side":"home","local_uid":"2026-08-24_sebastian_gorzny_cruz_hewitt","bid":0.61,"ask":0.63,"mid":0.62,"spread":0.02,"bid_size":null,"ask_size":null}
{"ts":"2026-08-24T20:48:08.714Z","event_type":"best_bid_ask","market_id":"3825641","outcome_index":1,"market_type":"match","local_side":"away","local_uid":"2026-08-24_sebastian_gorzny_cruz_hewitt","bid":0.37,"ask":0.39,"mid":0.38,"spread":0.02,"bid_size":null,"ask_size":null}
{"ts":"2026-08-24T20:48:08.714Z","event_type":"price_change","market_id":"3825641","outcome_index":1,"market_type":"match","local_side":"away","local_uid":"2026-08-24_sebastian_gorzny_cruz_hewitt","bid":0.37,"ask":0.39,"mid":0.38,"spread":0.02,"price":0.38,"size":0.0,"side":"SELL"}
{"ts":"2026-08-24T20:48:08.714Z","event_type":"price_change","market_id":"3825641","outcome_index":0,"market_type":"match","local_side":"home","local_uid":"2026-08-24_sebastian_gorzny_cruz_hewitt","bid":0.61,"ask":0.63,"mid":0.62,"spread":0.02,"price":0.62,"size":0.0,"side":"BUY"}
{"ts":"2026-08-24T20:48:08.720Z","event_type":"best_bid_ask","market_id":"3826654","outcome_index":0,"market_type":"set2","local_side":"home","local_uid":"2026-08-24_sebastian_gorzny_cruz_hewitt","bid":0.11,"ask":0.23,"mid":0.17,"spread":0.12,"bid_size":null,"ask_size":null}
{"ts":"2026-08-24T20:48:08.720Z","event_type":"best_bid_ask","market_id":"3826654","outcome_index":1,"market_type":"set2","local_side":"away","local_uid":"2026-08-24_sebastian_gorzny_cruz_hewitt","bid":0.77,"ask":0.89,"mid":0.83,"spread":0.12,"bid_size":null,"ask_size":null}
{"ts":"2026-08-24T20:48:08.720Z","event_type":"price_change","market_id":"3826654","outcome_index":0,"market_type":"set2","local_side":"home","local_uid":"2026-08-24_sebastian_gorzny_cruz_hewitt","bid":0.11,"ask":0.23,"mid":0.17,"spread":0.12,"price":0.12,"size":0.0,"side":"BUY"}
{"ts":"2026-08-24T20:48:08.721Z","event_type":"price_change","market_id":"3826654","outcome_index":1,"market_type":"set2","local_side":"away","local_uid":"2026-08-24_sebastian_gorzny_cruz_hewitt","bid":0.77,"ask":0.89,"mid":0.83,"spread":0.12,"price":0.88,"size":0.0,"side":"SELL"}
{"ts":"2026-08-24T20:48:08.721Z","event_type":"best_bid_ask","market_id":"3826654","outcome_index":0,"market_type":"set2","local_side":"home","local_uid":"2026-08-24_sebastian_gorzny_cruz_hewitt","bid":0.0,"ask":0.23,"mid":0.115,"spread":0.23,"bid_size":null,"ask_size":null}
{"ts":"2026-08-24T20:48:08.721Z","event_type":"best_bid_ask","market_id":"3826654","outcome_index":1,"market_type":"set2","local_side":"away","local_uid":"2026-08-24_sebastian_gorzny_cruz_hewitt","bid":0.77,"ask":1.0,"mid":0.885,"spread":0.23,"bid_size":null,"ask_size":null}
{"ts":"2026-08-24T20:48:08.721Z","event_type":"price_change","market_id":"3826654","outcome_index":0,"market_type":"set2","local_side":"home","local_uid":"2026-08-24_sebastian_gorzny_cruz_hewitt","bid":0.0,"ask":0.23,"mid":0.115,"spread":0.23,"price":0.11,"size":0.0,"side":"BUY"}
{"ts":"2026-08-24T20:48:08.722Z","event_type":"price_change","market_id":"3826654","outcome_index":1,"market_type":"set2","local_side":"away","local_uid":"2026-08-24_sebastian_gorzny_cruz_hewitt","bid":0.77,"ask":1.0,"mid":0.885,"spread":0.23,"price":0.89,"size":0.0,"side":"SELL"}
{"ts":"2026-08-24T20:48:08.725Z","event_type":"best_bid_ask","market_id":"3826654","outcome_index":0,"market_type":"set2","local_side":"home","local_uid":"2026-08-24_sebastian_gorzny_cruz_hewitt","bid":0.09,"ask":0.23,"mid":0.16,"spread":0.14,"bid_size":null,"ask_size":null}
{"ts":"2026-08-24T20:48:08.725Z","event_type":"best_bid_ask","market_id":"3826654","outcome_index":1,"market_type":"set2","local_side":"away","local_uid":"2026-08-24_sebastian_gorzny_cruz_hewitt","bid":0.77,"ask":0.91,"mid":0.84,"spread":0.14,"bid_size":null,"ask_size":null}
{"ts":"2026-08-24T20:48:08.725Z","event_type":"price_change","market_id":"3826654","outcome_index":0,"market_type":"set2","local_side":"home","local_uid":"2026-08-24_sebastian_gorzny_cruz_hewitt","bid":0.09,"ask":0.23,"mid":0.16,"spread":0.14,"price":0.09,"size":44.0,"side":"BUY"}
{"ts":"2026-08-24T20:48:08.726Z","event_type":"price_change","market_id":"3826654","outcome_index":1,"market_type":"set2","local_side":"away","local_uid":"2026-08-24_sebastian_gorzny_cruz_hewitt","bid":0.77,"ask":0.91,"mid":0.84,"spread":0.14,"price":0.91,"size":44.0,"side":"SELL"}
{"ts":"2026-08-24T20:48:08.734Z","event_type":"best_bid_ask","market_id":"3826654","outcome_index":0,"market_type":"set2","local_side":"home","local_uid":"2026-08-24_sebastian_gorzny_cruz_hewitt","bid":0.08,"ask":0.23,"mid":0.155,"spread":0.15,"bid_size":null,"ask_size":null}
{"ts":"2026-08-24T20:48:08.734Z","event_type":"best_bid_ask","market_id":"3826654","outcome_index":1,"market_type":"set2","local_side":"away","local_uid":"2026-08-24_sebastian_gorzny_cruz_hewitt","bid":0.77,"ask":0.92,"mid":0.845,"spread":0.15,"bid_size":null,"ask_size":null}
{"ts":"2026-08-24T20:48:08.735Z","event_type":"price_change","market_id":"3826654","outcome_index":0,"market_type":"set2","local_side":"home","local_uid":"2026-08-24_sebastian_gorzny_cruz_hewitt","bid":0.08,"ask":0.23,"mid":0.155,"spread":0.15,"price":0.09,"size":0.0,"side":"BUY"}
{"ts":"2026-08-24T20:48:08.736Z","event_type":"price_change","market_id":"3826654","outcome_index":1,"market_type":"set2","local_side":"away","local_uid":"2026-08-24_sebastian_gorzny_cruz_hewitt","bid":0.77,"ask":0.92,"mid":0.845,"spread":0.15,"price":0.91,"size":0.0,"side":"SELL"}
{"ts":"2026-08-24T20:48:08.736Z","event_type":"best_bid_ask","market_id":"3826654","outcome_index":0,"market_type":"set2","local_side":"home","local_uid":"2026-08-24_sebastian_gorzny_cruz_hewitt","bid":0.0,"ask":0.23,"mid":0.115,"spread":0.23,"bid_size":null,"ask_size":null}
{"ts":"2026-08-24T20:48:08.736Z","event_type":"best_bid_ask","market_id":"3826654","outcome_index":1,"market_type":"set2","local_side":"away","local_uid":"2026-08-24_sebastian_gorzny_cruz_hewitt","bid":0.77,"ask":1.0,"mid":0.885,"spread":0.23,"bid_size":null,"ask_size":null}
{"ts":"2026-08-24T20:48:08.737Z","event_type":"price_change","market_id":"3826654","outcome_index":0,"market_type":"set2","local_side":"home","local_uid":"2026-08-24_sebastian_gorzny_cruz_hewitt","bid":0.0,"ask":0.23,"mid":0.115,"spread":0.23,"price":0.08,"size":0.0,"side":"BUY"}
{"ts":"2026-08-24T20:48:08.737Z","event_type":"price_change","market_id":"3826654","outcome_index":1,"market_type":"set2","local_side":"away","local_uid":"2026-08-24_sebastian_gorzny_cruz_hewitt","bid":0.77,"ask":1.0,"mid":0.885,"spread":0.23,"price":0.92,"size":0.0,"side":"SELL"}
{"ts":"2026-08-24T20:48:08.782Z","event_type":"best_bid_ask","market_id":"3826654","outcome_index":0,"market_type":"set2","local_side":"home","local_uid":"2026-08-24_sebastian_gorzny_cruz_hewitt","bid":0.07,"ask":0.23,"mid":0.15,"spread":0.16,"bid_size":null,"ask_size":null}
{"ts":"2026-08-24T20:48:08.782Z","event_type":"best_bid_ask","market_id":"3826654","outcome_index":1,"market_type":"set2","local_side":"away","local_uid":"2026-08-24_sebastian_gorzny_cruz_hewitt","bid":0.77,"ask":0.93,"mid":0.85,"spread":0.16,"bid_size":null,"ask_size":null}
{"ts":"2026-08-24T20:48:08.783Z","event_type":"price_change","market_id":"3826654","outcome_index":0,"market_type":"set2","local_side":"home","local_uid":"2026-08-24_sebastian_gorzny_cruz_hewitt","bid":0.07,"ask":0.23,"mid":0.15,"spread":0.16,"price":0.07,"size":11.0,"side":"BUY"}
{"ts":"2026-08-24T20:48:08.783Z","event_type":"price_change","market_id":"3826654","outcome_index":1,"market_type":"set2","local_side":"away","local_uid":"2026-08-24_sebastian_gorzny_cruz_hewitt","bid":0.77,"ask":0.93,"mid":0.85,"spread":0.16,"price":0.93,"size":11.0,"side":"SELL"}
{"ts":"2026-08-24T20:48:08.788Z","event_type":"best_bid_ask","market_id":"3825641","outcome_index":0,"market_type":"match","local_side":"home","local_uid":"2026-08-24_sebastian_gorzny_cruz_hewitt","bid":0.6,"ask":0.63,"mid":0.615,"spread":0.03,"bid_size":null,"ask_size":null}
{"ts":"2026-08-24T20:48:08.789Z","event_type":"best_bid_ask","market_id":"3825641","outcome_index":1,"market_type":"match","local_side":"away","local_uid":"2026-08-24_sebastian_gorzny_cruz_hewitt","bid":0.37,"ask":0.4,"mid":0.385,"spread":0.03,"bid_size":null,"ask_size":null}
{"ts":"2026-08-24T20:48:08.790Z","event_type":"price_change","market_id":"3825641","outcome_index":0,"market_type":"match","local_side":"home","local_uid":"2026-08-24_sebastian_gorzny_cruz_hewitt","bid":0.6,"ask":0.63,"mid":0.615,"spread":0.03,"price":0.61,"size":0.0,"side":"BUY"}
{"ts":"2026-08-24T20:48:08.790Z","event_type":"price_change","market_id":"3825641","outcome_index":1,"market_type":"match","local_side":"away","local_uid":"2026-08-24_sebastian_gorzny_cruz_hewitt","bid":0.37,"ask":0.4,"mid":0.385,"spread":0.03,"price":0.39,"size":0.0,"side":"SELL"}
{"ts":"2026-08-24T20:48:08.908Z","event_type":"best_bid_ask","market_id":"3826654","outcome_index":0,"market_type":"set2","local_side":"home","local_uid":"2026-08-24_sebastian_gorzny_cruz_hewitt","bid":0.07,"ask":0.24,"mid":0.155,"spread":0.17,"bid_size":null,"ask_size":null}
{"ts":"2026-08-24T20:48:08.909Z","event_type":"best_bid_ask","market_id":"3826654","outcome_index":1,"market_type":"set2","local_side":"away","local_uid":"2026-08-24_sebastian_gorzny_cruz_hewitt","bid":0.76,"ask":0.93,"mid":0.845,"spread":0.17,"bid_size":null,"ask_size":null}
{"ts":"2026-08-24T20:48:08.909Z","event_type":"price_change","market_id":"3826654","outcome_index":1,"market_type":"set2","local_side":"away","local_uid":"2026-08-24_sebastian_gorzny_cruz_hewitt","bid":0.76,"ask":0.93,"mid":0.845,"spread":0.17,"price":0.77,"size":0.0,"side":"BUY"}
{"ts":"2026-08-24T20:48:08.909Z","event_type":"price_change","market_id":"3826654","outcome_index":0,"market_type":"set2","local_side":"home","local_uid":"2026-08-24_sebastian_gorzny_cruz_hewitt","bid":0.07,"ask":0.24,"mid":0.155,"spread":0.17,"price":0.23,"size":0.0,"side":"SELL"}
{"ts":"2026-08-24T20:48:08.918Z","event_type":"best_bid_ask","market_id":"3826654","outcome_index":0,"market_type":"set2","local_side":"home","local_uid":"2026-08-24_sebastian_gorzny_cruz_hewitt","bid":0.07,"ask":0.25,"mid":0.16,"spread":0.18,"bid_size":null,"ask_size":null}
{"ts":"2026-08-24T20:48:08.918Z","event_type":"best_bid_ask","market_id":"3826654","outcome_index":1,"market_type":"set2","local_side":"away","local_uid":"2026-08-24_sebastian_gorzny_cruz_hewitt","bid":0.75,"ask":0.93,"mid":0.84,"spread":0.18,"bid_size":null,"ask_size":null}
{"ts":"2026-08-24T20:48:08.919Z","event_type":"price_change","market_id":"3826654","outcome_index":1,"market_type":"set2","local_side":"away","local_uid":"2026-08-24_sebastian_gorzny_cruz_hewitt","bid":0.75,"ask":0.93,"mid":0.84,"spread":0.18,"price":0.76,"size":0.0,"side":"BUY"}
{"ts":"2026-08-24T20:48:08.919Z","event_type":"price_change","market_id":"3826654","outcome_index":0,"market_type":"set2","local_side":"home","local_uid":"2026-08-24_sebastian_gorzny_cruz_hewitt","bid":0.07,"ask":0.25,"mid":0.16,"spread":0.18,"price":0.24,"size":0.0,"side":"SELL"}
{"ts":"2026-08-24T20:48:09.179Z","event_type":"best_bid_ask","market_id":"3823623","outcome_index":0,"market_type":"match","local_side":"home","local_uid":"2026-08-24_robin_montgomery_kayla_cross","bid":0.88,"ask":0.9,"mid":0.89,"spread":0.02,"bid_size":null,"ask_size":null}
{"ts":"2026-08-24T20:48:09.179Z","event_type":"best_bid_ask","market_id":"3823623","outcome_index":1,"market_type":"match","local_side":"away","local_uid":"2026-08-24_robin_montgomery_kayla_cross","bid":0.1,"ask":0.12,"mid":0.11,"spread":0.02,"bid_size":null,"ask_size":null}
{"ts":"2026-08-24T20:48:09.179Z","event_type":"price_change","market_id":"3823623","outcome_index":1,"market_type":"match","local_side":"away","local_uid":"2026-08-24_robin_montgomery_kayla_cross","bid":0.1,"ask":0.12,"mid":0.11,"spread":0.02,"price":0.11,"size":0.0,"side":"BUY"}
{"ts":"2026-08-24T20:48:09.180Z","event_type":"price_change","market_id":"3823623","outcome_index":0,"market_type":"match","local_side":"home","local_uid":"2026-08-24_robin_montgomery_kayla_cross","bid":0.88,"ask":0.9,"mid":0.89,"spread":0.02,"price":0.89,"size":0.0,"side":"SELL"}
{"ts":"2026-08-24T20:48:09.660Z","event_type":"best_bid_ask","market_id":"3826894","outcome_index":0,"market_type":"set1","local_side":"home","local_uid":"2026-08-24_raul_brancaccio_thiago_seyboth_wild","bid":0.05,"ask":0.15,"mid":0.1,"spread":0.1,"bid_size":null,"ask_size":null}
{"ts":"2026-08-24T20:48:09.661Z","event_type":"best_bid_ask","market_id":"3826894","outcome_index":1,"market_type":"set1","local_side":"away","local_uid":"2026-08-24_raul_brancaccio_thiago_seyboth_wild","bid":0.85,"ask":0.95,"mid":0.9,"spread":0.1,"bid_size":null,"ask_size":null}
{"ts":"2026-08-24T20:48:09.661Z","event_type":"price_change","market_id":"3826894","outcome_index":0,"market_type":"set1","local_side":"home","local_uid":"2026-08-24_raul_brancaccio_thiago_seyboth_wild","bid":0.05,"ask":0.15,"mid":0.1,"spread":0.1,"price":0.06,"size":0.0,"side":"BUY"}
{"ts":"2026-08-24T20:48:09.661Z","event_type":"price_change","market_id":"3826894","outcome_index":1,"market_type":"set1","local_side":"away","local_uid":"2026-08-24_raul_brancaccio_thiago_seyboth_wild","bid":0.85,"ask":0.95,"mid":0.9,"spread":0.1,"price":0.94,"size":0.0,"side":"SELL"}
{"ts":"2026-08-24T20:48:09.779Z","event_type":"best_bid_ask","market_id":"3823659","outcome_index":0,"market_type":"match","local_side":"home","local_uid":"2026-08-24_victoria_jimenez_kasintseva_francisca_jorge","bid":0.35,"ask":0.38,"mid":0.365,"spread":0.03,"bid_size":null,"ask_size":null}
{"ts":"2026-08-24T20:48:09.779Z","event_type":"best_bid_ask","market_id":"3823659","outcome_index":1,"market_type":"match","local_side":"away","local_uid":"2026-08-24_victoria_jimenez_kasintseva_francisca_jorge","bid":0.62,"ask":0.65,"mid":0.635,"spread":0.03,"bid_size":null,"ask_size":null}
{"ts":"2026-08-24T20:48:09.779Z","event_type":"price_change","market_id":"3823659","outcome_index":0,"market_type":"match","local_side":"home","local_uid":"2026-08-24_victoria_jimenez_kasintseva_francisca_jorge","bid":0.35,"ask":0.38,"mid":0.365,"spread":0.03,"price":0.35,"size":1146.0,"side":"BUY"}
{"ts":"2026-08-24T20:48:09.780Z","event_type":"price_change","market_id":"3823659","outcome_index":1,"market_type":"match","local_side":"away","local_uid":"2026-08-24_victoria_jimenez_kasintseva_francisca_jorge","bid":0.62,"ask":0.65,"mid":0.635,"spread":0.03,"price":0.65,"size":1146.0,"side":"SELL"}
{"ts":"2026-08-24T20:48:09.803Z","event_type":"best_bid_ask","market_id":"3823659","outcome_index":0,"market_type":"match","local_side":"home","local_uid":"2026-08-24_victoria_jimenez_kasintseva_francisca_jorge","bid":0.36,"ask":0.38,"mid":0.37,"spread":0.02,"bid_size":null,"ask_size":null}
{"ts":"2026-08-24T20:48:09.803Z","event_type":"best_bid_ask","market_id":"3823659","outcome_index":1,"market_type":"match","local_side":"away","local_uid":"2026-08-24_victoria_jimenez_kasintseva_francisca_jorge","bid":0.62,"ask":0.64,"mid":0.63,"spread":0.02,"bid_size":null,"ask_size":null}
{"ts":"2026-08-24T20:48:09.804Z","event_type":"price_change","market_id":"3823659","outcome_index":0,"market_type":"match","local_side":"home","local_uid":"2026-08-24_victoria_jimenez_kasintseva_francisca_jorge","bid":0.36,"ask":0.38,"mid":0.37,"spread":0.02,"price":0.36,"size":100.0,"side":"BUY"}
{"ts":"2026-08-24T20:48:09.804Z","event_type":"price_change","market_id":"3823659","outcome_index":1,"market_type":"match","local_side":"away","local_uid":"2026-08-24_victoria_jimenez_kasintseva_francisca_jorge","bid":0.62,"ask":0.64,"mid":0.63,"spread":0.02,"price":0.64,"size":100.0,"side":"SELL"}
{"ts":"2026-08-24T20:48:09.830Z","event_type":"best_bid_ask","market_id":"3825053","outcome_index":0,"market_type":"set1","local_side":"home","local_uid":"2026-08-24_robin_montgomery_kayla_cross","bid":0.86,"ask":0.95,"mid":0.905,"spread":0.09,"bid_size":null,"ask_size":null}
{"ts":"2026-08-24T20:48:09.831Z","event_type":"best_bid_ask","market_id":"3825053","outcome_index":1,"market_type":"set1","local_side":"away","local_uid":"2026-08-24_robin_montgomery_kayla_cross","bid":0.05,"ask":0.14,"mid":0.095,"spread":0.09,"bid_size":null,"ask_size":null}
{"ts":"2026-08-24T20:48:09.831Z","event_type":"price_change","market_id":"3825053","outcome_index":1,"market_type":"set1","local_side":"away","local_uid":"2026-08-24_robin_montgomery_kayla_cross","bid":0.05,"ask":0.14,"mid":0.095,"spread":0.09,"price":0.06,"size":0.0,"side":"BUY"}
{"ts":"2026-08-24T20:48:09.831Z","event_type":"price_change","market_id":"3825053","outcome_index":0,"market_type":"set1","local_side":"home","local_uid":"2026-08-24_robin_montgomery_kayla_cross","bid":0.86,"ask":0.95,"mid":0.905,"spread":0.09,"price":0.94,"size":0.0,"side":"SELL"}
{"ts":"2026-08-24T20:48:09.847Z","event_type":"best_bid_ask","market_id":"3823659","outcome_index":0,"market_type":"match","local_side":"home","local_uid":"2026-08-24_victoria_jimenez_kasintseva_francisca_jorge","bid":0.37,"ask":0.38,"mid":0.375,"spread":0.01,"bid_size":null,"ask_size":null}
{"ts":"2026-08-24T20:48:09.848Z","event_type":"best_bid_ask","market_id":"3823659","outcome_index":1,"market_type":"match","local_side":"away","local_uid":"2026-08-24_victoria_jimenez_kasintseva_francisca_jorge","bid":0.62,"ask":0.63,"mid":0.625,"spread":0.01,"bid_size":null,"ask_size":null}
{"ts":"2026-08-24T20:48:09.848Z","event_type":"price_change","market_id":"3823659","outcome_index":0,"market_type":"match","local_side":"home","local_uid":"2026-08-24_victoria_jimenez_kasintseva_francisca_jorge","bid":0.37,"ask":0.38,"mid":0.375,"spread":0.01,"price":0.37,"size":161.0,"side":"BUY"}
{"ts":"2026-08-24T20:48:09.848Z","event_type":"price_change","market_id":"3823659","outcome_index":1,"market_type":"match","local_side":"away","local_uid":"2026-08-24_victoria_jimenez_kasintseva_francisca_jorge","bid":0.62,"ask":0.63,"mid":0.625,"spread":0.01,"price":0.63,"size":161.0,"side":"SELL"}
{"ts":"2026-08-24T20:48:09.947Z","event_type":"best_bid_ask","market_id":"3826654","outcome_index":0,"market_type":"set2","local_side":"home","local_uid":"2026-08-24_sebastian_gorzny_cruz_hewitt","bid":0.06,"ask":0.25,"mid":0.155,"spread":0.19,"bid_size":null,"ask_size":null}
{"ts":"2026-08-24T20:48:09.948Z","event_type":"best_bid_ask","market_id":"3826654","outcome_index":1,"market_type":"set2","local_side":"away","local_uid":"2026-08-24_sebastian_gorzny_cruz_hewitt","bid":0.75,"ask":0.94,"mid":0.845,"spread":0.19,"bid_size":null,"ask_size":null}
{"ts":"2026-08-24T20:48:09.948Z","event_type":"price_change","market_id":"3826654","outcome_index":0,"market_type":"set2","local_side":"home","local_uid":"2026-08-24_sebastian_gorzny_cruz_hewitt","bid":0.06,"ask":0.25,"mid":0.155,"spread":0.19,"price":0.07,"size":0.0,"side":"BUY"}
{"ts":"2026-08-24T20:48:09.948Z","event_type":"price_change","market_id":"3826654","outcome_index":1,"market_type":"set2","local_side":"away","local_uid":"2026-08-24_sebastian_gorzny_cruz_hewitt","bid":0.75,"ask":0.94,"mid":0.845,"spread":0.19,"price":0.93,"size":0.0,"side":"SELL"}
{"ts":"2026-08-24T20:48:09.949Z","event_type":"best_bid_ask","market_id":"3826654","outcome_index":0,"market_type":"set2","local_side":"home","local_uid":"2026-08-24_sebastian_gorzny_cruz_hewitt","bid":0.0,"ask":0.25,"mid":0.125,"spread":0.25,"bid_size":null,"ask_size":null}
{"ts":"2026-08-24T20:48:09.949Z","event_type":"best_bid_ask","market_id":"3826654","outcome_index":1,"market_type":"set2","local_side":"away","local_uid":"2026-08-24_sebastian_gorzny_cruz_hewitt","bid":0.75,"ask":1.0,"mid":0.875,"spread":0.25,"bid_size":null,"ask_size":null}
{"ts":"2026-08-24T20:48:09.950Z","event_type":"price_change","market_id":"3826654","outcome_index":0,"market_type":"set2","local_side":"home","local_uid":"2026-08-24_sebastian_gorzny_cruz_hewitt","bid":0.0,"ask":0.25,"mid":0.125,"spread":0.25,"price":0.06,"size":0.0,"side":"BUY"}
{"ts":"2026-08-24T20:48:09.950Z","event_type":"price_change","market_id":"3826654","outcome_index":1,"market_type":"set2","local_side":"away","local_uid":"2026-08-24_sebastian_gorzny_cruz_hewitt","bid":0.75,"ask":1.0,"mid":0.875,"spread":0.25,"price":0.94,"size":0.0,"side":"SELL"}
{"ts":"2026-08-24T20:48:10.080Z","event_type":"best_bid_ask","market_id":"3825641","outcome_index":0,"market_type":"match","local_side":"home","local_uid":"2026-08-24_sebastian_gorzny_cruz_hewitt","bid":0.6,"ask":0.64,"mid":0.62,"spread":0.04,"bid_size":null,"ask_size":null}
{"ts":"2026-08-24T20:48:10.080Z","event_type":"best_bid_ask","market_id":"3825641","outcome_index":1,"market_type":"match","local_side":"away","local_uid":"2026-08-24_sebastian_gorzny_cruz_hewitt","bid":0.36,"ask":0.4,"mid":0.38,"spread":0.04,"bid_size":null,"ask_size":null}
{"ts":"2026-08-24T20:48:10.081Z","event_type":"price_change","market_id":"3825641","outcome_index":1,"market_type":"match","local_side":"away","local_uid":"2026-08-24_sebastian_gorzny_cruz_hewitt","bid":0.36,"ask":0.4,"mid":0.38,"spread":0.04,"price":0.37,"size":0.0,"side":"BUY"}
{"ts":"2026-08-24T20:48:10.081Z","event_type":"price_change","market_id":"3825641","outcome_index":0,"market_type":"match","local_side":"home","local_uid":"2026-08-24_sebastian_gorzny_cruz_hewitt","bid":0.6,"ask":0.64,"mid":0.62,"spread":0.04,"price":0.63,"size":0.0,"side":"SELL"}
{"ts":"2026-08-24T20:48:10.135Z","event_type":"last_trade_price","market_id":"3825641","outcome_index":0,"market_type":"match","local_side":"home","local_uid":"2026-08-24_sebastian_gorzny_cruz_hewitt","last_trade":0.63,"trade_size":20.0,"trade_side":"BUY","trade_notional":12.6}
{"ts":"2026-08-24T20:48:10.364Z","event_type":"price_change","market_id":"3823653","outcome_index":0,"market_type":"match","local_side":"home","local_uid":"2026-08-24_gabriela_knutson_varvara_lepchenko","bid":0.59,"ask":0.6,"mid":0.595,"spread":0.01,"price":0.56,"size":5200.0,"side":"BUY"}
{"ts":"2026-08-24T20:48:10.365Z","event_type":"price_change","market_id":"3823653","outcome_index":1,"market_type":"match","local_side":"away","local_uid":"2026-08-24_gabriela_knutson_varvara_lepchenko","bid":0.4,"ask":0.41,"mid":0.405,"spread":0.01,"price":0.44,"size":5200.0,"side":"SELL"}
{"ts":"2026-08-24T20:48:10.390Z","event_type":"best_bid_ask","market_id":"3824761","outcome_index":0,"market_type":"set1","local_side":"home","local_uid":"2026-08-24_jazmin_ortenzi_himeno_sakatsume","bid":0.14,"ask":0.28,"mid":0.21,"spread":0.14,"bid_size":null,"ask_size":null}
{"ts":"2026-08-24T20:48:10.390Z","event_type":"best_bid_ask","market_id":"3824761","outcome_index":1,"market_type":"set1","local_side":"away","local_uid":"2026-08-24_jazmin_ortenzi_himeno_sakatsume","bid":0.72,"ask":0.86,"mid":0.79,"spread":0.14,"bid_size":null,"ask_size":null}
{"ts":"2026-08-24T20:48:10.391Z","event_type":"price_change","market_id":"3824761","outcome_index":1,"market_type":"set1","local_side":"away","local_uid":"2026-08-24_jazmin_ortenzi_himeno_sakatsume","bid":0.72,"ask":0.86,"mid":0.79,"spread":0.14,"price":0.72,"size":88.0,"side":"BUY"}
{"ts":"2026-08-24T20:48:10.391Z","event_type":"price_change","market_id":"3824761","outcome_index":0,"market_type":"set1","local_side":"home","local_uid":"2026-08-24_jazmin_ortenzi_himeno_sakatsume","bid":0.14,"ask":0.28,"mid":0.21,"spread":0.14,"price":0.28,"size":88.0,"side":"SELL"}
{"ts":"2026-08-24T20:48:10.395Z","event_type":"best_bid_ask","market_id":"3824761","outcome_index":0,"market_type":"set1","local_side":"home","local_uid":"2026-08-24_jazmin_ortenzi_himeno_sakatsume","bid":0.15,"ask":0.28,"mid":0.215,"spread":0.13,"bid_size":null,"ask_size":null}
{"ts":"2026-08-24T20:48:10.396Z","event_type":"best_bid_ask","market_id":"3824761","outcome_index":1,"market_type":"set1","local_side":"away","local_uid":"2026-08-24_jazmin_ortenzi_himeno_sakatsume","bid":0.72,"ask":0.85,"mid":0.785,"spread":0.13,"bid_size":null,"ask_size":null}
{"ts":"2026-08-24T20:48:10.396Z","event_type":"price_change","market_id":"3824761","outcome_index":0,"market_type":"set1","local_side":"home","local_uid":"2026-08-24_jazmin_ortenzi_himeno_sakatsume","bid":0.15,"ask":0.28,"mid":0.215,"spread":0.13,"price":0.15,"size":3000.0,"side":"BUY"}
{"ts":"2026-08-24T20:48:10.396Z","event_type":"price_change","market_id":"3824761","outcome_index":1,"market_type":"set1","local_side":"away","local_uid":"2026-08-24_jazmin_ortenzi_himeno_sakatsume","bid":0.72,"ask":0.85,"mid":0.785,"spread":0.13,"price":0.85,"size":3000.0,"side":"SELL"}
{"ts":"2026-08-24T20:48:10.409Z","event_type":"best_bid_ask","market_id":"3824761","outcome_index":0,"market_type":"set1","local_side":"home","local_uid":"2026-08-24_jazmin_ortenzi_himeno_sakatsume","bid":0.15,"ask":0.27,"mid":0.21,"spread":0.12,"bid_size":null,"ask_size":null}
{"ts":"2026-08-24T20:48:10.409Z","event_type":"best_bid_ask","market_id":"3824761","outcome_index":1,"market_type":"set1","local_side":"away","local_uid":"2026-08-24_jazmin_ortenzi_himeno_sakatsume","bid":0.73,"ask":0.85,"mid":0.79,"spread":0.12,"bid_size":null,"ask_size":null}
{"ts":"2026-08-24T20:48:10.411Z","event_type":"price_change","market_id":"3824761","outcome_index":1,"market_type":"set1","local_side":"away","local_uid":"2026-08-24_jazmin_ortenzi_himeno_sakatsume","bid":0.73,"ask":0.85,"mid":0.79,"spread":0.12,"price":0.73,"size":88.0,"side":"BUY"}
{"ts":"2026-08-24T20:48:10.411Z","event_type":"price_change","market_id":"3824761","outcome_index":0,"market_type":"set1","local_side":"home","local_uid":"2026-08-24_jazmin_ortenzi_himeno_sakatsume","bid":0.15,"ask":0.27,"mid":0.21,"spread":0.12,"price":0.27,"size":88.0,"side":"SELL"}
{"ts":"2026-08-24T20:48:10.427Z","event_type":"best_bid_ask","market_id":"3825077","outcome_index":0,"market_type":"set1","local_side":"home","local_uid":"2026-08-24_polina_kudermetova_linda_fruhvirtova","bid":0.45,"ask":0.47,"mid":0.46,"spread":0.02,"bid_size":null,"ask_size":null}
{"ts":"2026-08-24T20:48:10.428Z","event_type":"best_bid_ask","market_id":"3825077","outcome_index":1,"market_type":"set1","local_side":"away","local_uid":"2026-08-24_polina_kudermetova_linda_fruhvirtova","bid":0.53,"ask":0.55,"mid":0.54,"spread":0.02,"bid_size":null,"ask_size":null}
{"ts":"2026-08-24T20:48:10.428Z","event_type":"price_change","market_id":"3825077","outcome_index":0,"market_type":"set1","local_side":"home","local_uid":"2026-08-24_polina_kudermetova_linda_fruhvirtova","bid":0.45,"ask":0.47,"mid":0.46,"spread":0.02,"price":0.46,"size":0.0,"side":"SELL"}
{"ts":"2026-08-24T20:48:10.428Z","event_type":"price_change","market_id":"3825077","outcome_index":1,"market_type":"set1","local_side":"away","local_uid":"2026-08-24_polina_kudermetova_linda_fruhvirtova","bid":0.53,"ask":0.55,"mid":0.54,"spread":0.02,"price":0.54,"size":0.0,"side":"BUY"}
{"ts":"2026-08-24T20:48:10.436Z","event_type":"best_bid_ask","market_id":"3824761","outcome_index":0,"market_type":"set1","local_side":"home","local_uid":"2026-08-24_jazmin_ortenzi_himeno_sakatsume","bid":0.14,"ask":0.27,"mid":0.205,"spread":0.13,"bid_size":null,"ask_size":null}
{"ts":"2026-08-24T20:48:10.436Z","event_type":"best_bid_ask","market_id":"3824761","outcome_index":1,"market_type":"set1","local_side":"away","local_uid":"2026-08-24_jazmin_ortenzi_himeno_sakatsume","bid":0.73,"ask":0.86,"mid":0.795,"spread":0.13,"bid_size":null,"ask_size":null}
{"ts":"2026-08-24T20:48:10.436Z","event_type":"price_change","market_id":"3824761","outcome_index":0,"market_type":"set1","local_side":"home","local_uid":"2026-08-24_jazmin_ortenzi_himeno_sakatsume","bid":0.14,"ask":0.27,"mid":0.205,"spread":0.13,"price":0.15,"size":0.0,"side":"BUY"}
{"ts":"2026-08-24T20:48:10.437Z","event_type":"price_change","market_id":"3824761","outcome_index":1,"market_type":"set1","local_side":"away","local_uid":"2026-08-24_jazmin_ortenzi_himeno_sakatsume","bid":0.73,"ask":0.86,"mid":0.795,"spread":0.13,"price":0.85,"size":0.0,"side":"SELL"}
{"ts":"2026-08-24T20:48:10.469Z","event_type":"best_bid_ask","market_id":"3824761","outcome_index":0,"market_type":"set1","local_side":"home","local_uid":"2026-08-24_jazmin_ortenzi_himeno_sakatsume","bid":0.16,"ask":0.27,"mid":0.215,"spread":0.11,"bid_size":null,"ask_size":null}
{"ts":"2026-08-24T20:48:10.469Z","event_type":"best_bid_ask","market_id":"3824761","outcome_index":1,"market_type":"set1","local_side":"away","local_uid":"2026-08-24_jazmin_ortenzi_himeno_sakatsume","bid":0.73,"ask":0.84,"mid":0.785,"spread":0.11,"bid_size":null,"ask_size":null}
{"ts":"2026-08-24T20:48:10.469Z","event_type":"price_change","market_id":"3824761","outcome_index":0,"market_type":"set1","local_side":"home","local_uid":"2026-08-24_jazmin_ortenzi_himeno_sakatsume","bid":0.16,"ask":0.27,"mid":0.215,"spread":0.11,"price":0.16,"size":3000.0,"side":"BUY"}
{"ts":"2026-08-24T20:48:10.469Z","event_type":"price_change","market_id":"3824761","outcome_index":1,"market_type":"set1","local_side":"away","local_uid":"2026-08-24_jazmin_ortenzi_himeno_sakatsume","bid":0.73,"ask":0.84,"mid":0.785,"spread":0.11,"price":0.84,"size":3000.0,"side":"SELL"}
{"ts":"2026-08-24T20:48:10.485Z","event_type":"best_bid_ask","market_id":"3824761","outcome_index":0,"market_type":"set1","local_side":"home","local_uid":"2026-08-24_jazmin_ortenzi_himeno_sakatsume","bid":0.16,"ask":0.26,"mid":0.21,"spread":0.1,"bid_size":null,"ask_size":null}
{"ts":"2026-08-24T20:48:10.486Z","event_type":"best_bid_ask","market_id":"3824761","outcome_index":1,"market_type":"set1","local_side":"away","local_uid":"2026-08-24_jazmin_ortenzi_himeno_sakatsume","bid":0.74,"ask":0.84,"mid":0.79,"spread":0.1,"bid_size":null,"ask_size":null}
{"ts":"2026-08-24T20:48:10.486Z","event_type":"price_change","market_id":"3824761","outcome_index":1,"market_type":"set1","local_side":"away","local_uid":"2026-08-24_jazmin_ortenzi_himeno_sakatsume","bid":0.74,"ask":0.84,"mid":0.79,"spread":0.1,"price":0.74,"size":150.0,"side":"BUY"}
{"ts":"2026-08-24T20:48:10.486Z","event_type":"price_change","market_id":"3824761","outcome_index":0,"market_type":"set1","local_side":"home","local_uid":"2026-08-24_jazmin_ortenzi_himeno_sakatsume","bid":0.16,"ask":0.26,"mid":0.21,"spread":0.1,"price":0.26,"size":150.0,"side":"SELL"}
{"ts":"2026-08-24T20:48:10.527Z","event_type":"best_bid_ask","market_id":"3824761","outcome_index":0,"market_type":"set1","local_side":"home","local_uid":"2026-08-24_jazmin_ortenzi_himeno_sakatsume","bid":0.15,"ask":0.26,"mid":0.205,"spread":0.11,"bid_size":null,"ask_size":null}
{"ts":"2026-08-24T20:48:10.527Z","event_type":"best_bid_ask","market_id":"3824761","outcome_index":1,"market_type":"set1","local_side":"away","local_uid":"2026-08-24_jazmin_ortenzi_himeno_sakatsume","bid":0.74,"ask":0.85,"mid":0.795,"spread":0.11,"bid_size":null,"ask_size":null}
{"ts":"2026-08-24T20:48:10.527Z","event_type":"price_change","market_id":"3824761","outcome_index":0,"market_type":"set1","local_side":"home","local_uid":"2026-08-24_jazmin_ortenzi_himeno_sakatsume","bid":0.15,"ask":0.26,"mid":0.205,"spread":0.11,"price":0.16,"size":0.0,"side":"BUY"}
{"ts":"2026-08-24T20:48:10.527Z","event_type":"price_change","market_id":"3824761","outcome_index":1,"market_type":"set1","local_side":"away","local_uid":"2026-08-24_jazmin_ortenzi_himeno_sakatsume","bid":0.74,"ask":0.85,"mid":0.795,"spread":0.11,"price":0.84,"size":0.0,"side":"SELL"}
{"ts":"2026-08-24T20:48:10.528Z","event_type":"best_bid_ask","market_id":"3824761","outcome_index":0,"market_type":"set1","local_side":"home","local_uid":"2026-08-24_jazmin_ortenzi_himeno_sakatsume","bid":0.17,"ask":0.26,"mid":0.215,"spread":0.09,"bid_size":null,"ask_size":null}
{"ts":"2026-08-24T20:48:10.528Z","event_type":"best_bid_ask","market_id":"3824761","outcome_index":1,"market_type":"set1","local_side":"away","local_uid":"2026-08-24_jazmin_ortenzi_himeno_sakatsume","bid":0.74,"ask":0.83,"mid":0.785,"spread":0.09,"bid_size":null,"ask_size":null}
{"ts":"2026-08-24T20:48:10.528Z","event_type":"price_change","market_id":"3824761","outcome_index":0,"market_type":"set1","local_side":"home","local_uid":"2026-08-24_jazmin_ortenzi_himeno_sakatsume","bid":0.17,"ask":0.26,"mid":0.215,"spread":0.09,"price":0.17,"size":437.0,"side":"BUY"}
{"ts":"2026-08-24T20:48:10.528Z","event_type":"price_change","market_id":"3824761","outcome_index":1,"market_type":"set1","local_side":"away","local_uid":"2026-08-24_jazmin_ortenzi_himeno_sakatsume","bid":0.74,"ask":0.83,"mid":0.785,"spread":0.09,"price":0.83,"size":437.0,"side":"SELL"}
{"ts":"2026-08-24T20:48:10.539Z","event_type":"best_bid_ask","market_id":"3824761","outcome_index":0,"market_type":"set1","local_side":"home","local_uid":"2026-08-24_jazmin_ortenzi_himeno_sakatsume","bid":0.15,"ask":0.26,"mid":0.205,"spread":0.11,"bid_size":null,"ask_size":null}
{"ts":"2026-08-24T20:48:10.539Z","event_type":"best_bid_ask","market_id":"3824761","outcome_index":1,"market_type":"set1","local_side":"away","local_uid":"2026-08-24_jazmin_ortenzi_himeno_sakatsume","bid":0.74,"ask":0.85,"mid":0.795,"spread":0.11,"bid_size":null,"ask_size":null}
{"ts":"2026-08-24T20:48:10.539Z","event_type":"price_change","market_id":"3824761","outcome_index":0,"market_type":"set1","local_side":"home","local_uid":"2026-08-24_jazmin_ortenzi_himeno_sakatsume","bid":0.15,"ask":0.26,"mid":0.205,"spread":0.11,"price":0.17,"size":0.0,"side":"BUY"}
{"ts":"2026-08-24T20:48:10.539Z","event_type":"price_change","market_id":"3824761","outcome_index":1,"market_type":"set1","local_side":"away","local_uid":"2026-08-24_jazmin_ortenzi_himeno_sakatsume","bid":0.74,"ask":0.85,"mid":0.795,"spread":0.11,"price":0.83,"size":0.0,"side":"SELL"}
{"ts":"2026-08-24T20:48:10.542Z","event_type":"best_bid_ask","market_id":"3824761","outcome_index":0,"market_type":"set1","local_side":"home","local_uid":"2026-08-24_jazmin_ortenzi_himeno_sakatsume","bid":0.17,"ask":0.26,"mid":0.215,"spread":0.09,"bid_size":null,"ask_size":null}
{"ts":"2026-08-24T20:48:10.542Z","event_type":"best_bid_ask","market_id":"3824761","outcome_index":1,"market_type":"set1","local_side":"away","local_uid":"2026-08-24_jazmin_ortenzi_himeno_sakatsume","bid":0.74,"ask":0.83,"mid":0.785,"spread":0.09,"bid_size":null,"ask_size":null}
{"ts":"2026-08-24T20:48:10.543Z","event_type":"price_change","market_id":"3824761","outcome_index":0,"market_type":"set1","local_side":"home","local_uid":"2026-08-24_jazmin_ortenzi_himeno_sakatsume","bid":0.17,"ask":0.26,"mid":0.215,"spread":0.09,"price":0.17,"size":1187.0,"side":"BUY"}
{"ts":"2026-08-24T20:48:10.543Z","event_type":"price_change","market_id":"3824761","outcome_index":1,"market_type":"set1","local_side":"away","local_uid":"2026-08-24_jazmin_ortenzi_himeno_sakatsume","bid":0.74,"ask":0.83,"mid":0.785,"spread":0.09,"price":0.83,"size":1187.0,"side":"SELL"}
{"ts":"2026-08-24T20:48:10.820Z","event_type":"best_bid_ask","market_id":"3823629","outcome_index":0,"market_type":"match","local_side":"home","local_uid":"2026-08-24_angela_fita_boluda_lin_zhu","bid":0.5,"ask":0.52,"mid":0.51,"spread":0.02,"bid_size":null,"ask_size":null}
{"ts":"2026-08-24T20:48:10.821Z","event_type":"best_bid_ask","market_id":"3823629","outcome_index":1,"market_type":"match","local_side":"away","local_uid":"2026-08-24_angela_fita_boluda_lin_zhu","bid":0.48,"ask":0.5,"mid":0.49,"spread":0.02,"bid_size":null,"ask_size":null}
{"ts":"2026-08-24T20:48:10.821Z","event_type":"price_change","market_id":"3823629","outcome_index":0,"market_type":"match","local_side":"home","local_uid":"2026-08-24_angela_fita_boluda_lin_zhu","bid":0.5,"ask":0.52,"mid":0.51,"spread":0.02,"price":0.51,"size":0.0,"side":"BUY"}
{"ts":"2026-08-24T20:48:10.821Z","event_type":"price_change","market_id":"3823629","outcome_index":1,"market_type":"match","local_side":"away","local_uid":"2026-08-24_angela_fita_boluda_lin_zhu","bid":0.48,"ask":0.5,"mid":0.49,"spread":0.02,"price":0.49,"size":0.0,"side":"SELL"}
{"ts":"2026-08-24T20:48:10.882Z","event_type":"best_bid_ask","market_id":"3823629","outcome_index":0,"market_type":"match","local_side":"home","local_uid":"2026-08-24_angela_fita_boluda_lin_zhu","bid":0.5,"ask":0.51,"mid":0.505,"spread":0.01,"bid_size":null,"ask_size":null}
{"ts":"2026-08-24T20:48:10.882Z","event_type":"best_bid_ask","market_id":"3823629","outcome_index":1,"market_type":"match","local_side":"away","local_uid":"2026-08-24_angela_fita_boluda_lin_zhu","bid":0.49,"ask":0.5,"mid":0.495,"spread":0.01,"bid_size":null,"ask_size":null}
{"ts":"2026-08-24T20:48:10.882Z","event_type":"price_change","market_id":"3823629","outcome_index":1,"market_type":"match","local_side":"away","local_uid":"2026-08-24_angela_fita_boluda_lin_zhu","bid":0.49,"ask":0.5,"mid":0.495,"spread":0.01,"price":0.49,"size":5106.0,"side":"BUY"}
{"ts":"2026-08-24T20:48:10.882Z","event_type":"price_change","market_id":"3823629","outcome_index":0,"market_type":"match","local_side":"home","local_uid":"2026-08-24_angela_fita_boluda_lin_zhu","bid":0.5,"ask":0.51,"mid":0.505,"spread":0.01,"price":0.51,"size":5106.0,"side":"SELL"}
{"ts":"2026-08-24T20:48:11.205Z","event_type":"best_bid_ask","market_id":"3824761","outcome_index":0,"market_type":"set1","local_side":"home","local_uid":"2026-08-24_jazmin_ortenzi_himeno_sakatsume","bid":0.17,"ask":0.25,"mid":0.21,"spread":0.08,"bid_size":null,"ask_size":null}
{"ts":"2026-08-24T20:48:11.206Z","event_type":"best_bid_ask","market_id":"3824761","outcome_index":1,"market_type":"set1","local_side":"away","local_uid":"2026-08-24_jazmin_ortenzi_himeno_sakatsume","bid":0.75,"ask":0.83,"mid":0.79,"spread":0.08,"bid_size":null,"ask_size":null}
{"ts":"2026-08-24T20:48:11.206Z","event_type":"price_change","market_id":"3824761","outcome_index":1,"market_type":"set1","local_side":"away","local_uid":"2026-08-24_jazmin_ortenzi_himeno_sakatsume","bid":0.75,"ask":0.83,"mid":0.79,"spread":0.08,"price":0.75,"size":250.0,"side":"BUY"}
{"ts":"2026-08-24T20:48:11.206Z","event_type":"price_change","market_id":"3824761","outcome_index":0,"market_type":"set1","local_side":"home","local_uid":"2026-08-24_jazmin_ortenzi_himeno_sakatsume","bid":0.17,"ask":0.25,"mid":0.21,"spread":0.08,"price":0.25,"size":250.0,"side":"SELL"}
{"ts":"2026-08-24T20:48:11.277Z","event_type":"best_bid_ask","market_id":"3823665","outcome_index":0,"market_type":"match","local_side":"home","local_uid":"2026-08-24_jazmin_ortenzi_himeno_sakatsume","bid":0.15,"ask":0.16,"mid":0.155,"spread":0.01,"bid_size":null,"ask_size":null}
{"ts":"2026-08-24T20:48:11.277Z","event_type":"best_bid_ask","market_id":"3823665","outcome_index":1,"market_type":"match","local_side":"away","local_uid":"2026-08-24_jazmin_ortenzi_himeno_sakatsume","bid":0.84,"ask":0.85,"mid":0.845,"spread":0.01,"bid_size":null,"ask_size":null}
{"ts":"2026-08-24T20:48:11.281Z","event_type":"price_change","market_id":"3823665","outcome_index":1,"market_type":"match","local_side":"away","local_uid":"2026-08-24_jazmin_ortenzi_himeno_sakatsume","bid":0.84,"ask":0.85,"mid":0.845,"spread":0.01,"price":0.84,"size":2453.57,"side":"BUY"}
{"ts":"2026-08-24T20:48:11.281Z","event_type":"price_change","market_id":"3823665","outcome_index":0,"market_type":"match","local_side":"home","local_uid":"2026-08-24_jazmin_ortenzi_himeno_sakatsume","bid":0.15,"ask":0.16,"mid":0.155,"spread":0.01,"price":0.16,"size":2453.57,"side":"SELL"}
{"ts":"2026-08-24T20:48:11.303Z","event_type":"price_change","market_id":"3826795","outcome_index":1,"market_type":"set2","local_side":"away","local_uid":"2026-08-24_andrea_guerrieri_august_holmgren","bid":0.999,"ask":1.0,"mid":0.9995,"spread":0.001,"price":0.01,"size":14111.0,"side":"BUY"}
{"ts":"2026-08-24T20:48:11.303Z","event_type":"price_change","market_id":"3826795","outcome_index":0,"market_type":"set2","local_side":"home","local_uid":"2026-08-24_andrea_guerrieri_august_holmgren","bid":0.0,"ask":0.001,"mid":0.0005,"spread":0.001,"price":0.99,"size":14111.0,"side":"SELL"}
{"ts":"2026-08-24T20:48:11.412Z","event_type":"best_bid_ask","market_id":"3824761","outcome_index":0,"market_type":"set1","local_side":"home","local_uid":"2026-08-24_jazmin_ortenzi_himeno_sakatsume","bid":0.18,"ask":0.25,"mid":0.215,"spread":0.07,"bid_size":null,"ask_size":null}
{"ts":"2026-08-24T20:48:11.414Z","event_type":"best_bid_ask","market_id":"3824761","outcome_index":1,"market_type":"set1","local_side":"away","local_uid":"2026-08-24_jazmin_ortenzi_himeno_sakatsume","bid":0.75,"ask":0.82,"mid":0.785,"spread":0.07,"bid_size":null,"ask_size":null}
{"ts":"2026-08-24T20:48:11.414Z","event_type":"price_change","market_id":"3824761","outcome_index":0,"market_type":"set1","local_side":"home","local_uid":"2026-08-24_jazmin_ortenzi_himeno_sakatsume","bid":0.18,"ask":0.25,"mid":0.215,"spread":0.07,"price":0.18,"size":200.0,"side":"BUY"}
{"ts":"2026-08-24T20:48:11.414Z","event_type":"price_change","market_id":"3824761","outcome_index":1,"market_type":"set1","local_side":"away","local_uid":"2026-08-24_jazmin_ortenzi_himeno_sakatsume","bid":0.75,"ask":0.82,"mid":0.785,"spread":0.07,"price":0.82,"size":200.0,"side":"SELL"}
{"ts":"2026-08-24T20:48:11.515Z","event_type":"price_change","market_id":"3825610","outcome_index":1,"market_type":"match","local_side":"away","local_uid":"2026-08-24_stefano_napolitano_mackenzie_mcdonald","bid":0.8,"ask":0.81,"mid":0.805,"spread":0.01,"price":0.79,"size":5429.23,"side":"BUY"}
{"ts":"2026-08-24T20:48:11.516Z","event_type":"price_change","market_id":"3825610","outcome_index":0,"market_type":"match","local_side":"home","local_uid":"2026-08-24_stefano_napolitano_mackenzie_mcdonald","bid":0.19,"ask":0.2,"mid":0.195,"spread":0.01,"price":0.21,"size":5429.23,"side":"SELL"}
{"ts":"2026-08-24T20:48:11.572Z","event_type":"best_bid_ask","market_id":"3826654","outcome_index":0,"market_type":"set2","local_side":"home","local_uid":"2026-08-24_sebastian_gorzny_cruz_hewitt","bid":0.0,"ask":0.13,"mid":0.065,"spread":0.13,"bid_size":null,"ask_size":null}
{"ts":"2026-08-24T20:48:11.580Z","event_type":"best_bid_ask","market_id":"3826654","outcome_index":1,"market_type":"set2","local_side":"away","local_uid":"2026-08-24_sebastian_gorzny_cruz_hewitt","bid":0.87,"ask":1.0,"mid":0.935,"spread":0.13,"bid_size":null,"ask_size":null}
{"ts":"2026-08-24T20:48:11.580Z","event_type":"price_change","market_id":"3826654","outcome_index":1,"market_type":"set2","local_side":"away","local_uid":"2026-08-24_sebastian_gorzny_cruz_hewitt","bid":0.87,"ask":1.0,"mid":0.935,"spread":0.13,"price":0.87,"size":88.0,"side":"BUY"}
{"ts":"2026-08-24T20:48:11.580Z","event_type":"price_change","market_id":"3826654","outcome_index":0,"market_type":"set2","local_side":"home","local_uid":"2026-08-24_sebastian_gorzny_cruz_hewitt","bid":0.0,"ask":0.13,"mid":0.065,"spread":0.13,"price":0.13,"size":88.0,"side":"SELL"}
{"ts":"2026-08-24T20:48:11.581Z","event_type":"best_bid_ask","market_id":"3826654","outcome_index":0,"market_type":"set2","local_side":"home","local_uid":"2026-08-24_sebastian_gorzny_cruz_hewitt","bid":0.05,"ask":0.13,"mid":0.09,"spread":0.08,"bid_size":null,"ask_size":null}
{"ts":"2026-08-24T20:48:11.581Z","event_type":"best_bid_ask","market_id":"3826654","outcome_index":1,"market_type":"set2","local_side":"away","local_uid":"2026-08-24_sebastian_gorzny_cruz_hewitt","bid":0.87,"ask":0.95,"mid":0.91,"spread":0.08,"bid_size":null,"ask_size":null}
{"ts":"2026-08-24T20:48:11.581Z","event_type":"price_change","market_id":"3826654","outcome_index":0,"market_type":"set2","local_side":"home","local_uid":"2026-08-24_sebastian_gorzny_cruz_hewitt","bid":0.05,"ask":0.13,"mid":0.09,"spread":0.08,"price":0.05,"size":423.0,"side":"BUY"}
{"ts":"2026-08-24T20:48:11.581Z","event_type":"price_change","market_id":"3826654","outcome_index":1,"market_type":"set2","local_side":"away","local_uid":"2026-08-24_sebastian_gorzny_cruz_hewitt","bid":0.87,"ask":0.95,"mid":0.91,"spread":0.08,"price":0.95,"size":423.0,"side":"SELL"}
{"ts":"2026-08-24T20:48:11.582Z","event_type":"best_bid_ask","market_id":"3826654","outcome_index":0,"market_type":"set2","local_side":"home","local_uid":"2026-08-24_sebastian_gorzny_cruz_hewitt","bid":0.06,"ask":0.13,"mid":0.095,"spread":0.07,"bid_size":null,"ask_size":null}
{"ts":"2026-08-24T20:48:11.583Z","event_type":"best_bid_ask","market_id":"3826654","outcome_index":1,"market_type":"set2","local_side":"away","local_uid":"2026-08-24_sebastian_gorzny_cruz_hewitt","bid":0.87,"ask":0.94,"mid":0.905,"spread":0.07,"bid_size":null,"ask_size":null}
{"ts":"2026-08-24T20:48:11.583Z","event_type":"price_change","market_id":"3826654","outcome_index":0,"market_type":"set2","local_side":"home","local_uid":"2026-08-24_sebastian_gorzny_cruz_hewitt","bid":0.06,"ask":0.13,"mid":0.095,"spread":0.07,"price":0.06,"size":88.0,"side":"BUY"}
{"ts":"2026-08-24T20:48:11.583Z","event_type":"price_change","market_id":"3826654","outcome_index":1,"market_type":"set2","local_side":"away","local_uid":"2026-08-24_sebastian_gorzny_cruz_hewitt","bid":0.87,"ask":0.94,"mid":0.905,"spread":0.07,"price":0.94,"size":88.0,"side":"SELL"}
{"ts":"2026-08-24T20:48:11.710Z","event_type":"best_bid_ask","market_id":"3823627","outcome_index":0,"market_type":"match","local_side":"home","local_uid":"2026-08-24_claire_liu_heather_watson","bid":0.36,"ask":0.38,"mid":0.37,"spread":0.02,"bid_size":null,"ask_size":null}
{"ts":"2026-08-24T20:48:11.710Z","event_type":"best_bid_ask","market_id":"3823627","outcome_index":1,"market_type":"match","local_side":"away","local_uid":"2026-08-24_claire_liu_heather_watson","bid":0.62,"ask":0.64,"mid":0.63,"spread":0.02,"bid_size":null,"ask_size":null}
{"ts":"2026-08-24T20:48:11.711Z","event_type":"price_change","market_id":"3823627","outcome_index":1,"market_type":"match","local_side":"away","local_uid":"2026-08-24_claire_liu_heather_watson","bid":0.62,"ask":0.64,"mid":0.63,"spread":0.02,"price":0.63,"size":0.0,"side":"SELL"}
{"ts":"2026-08-24T20:48:11.711Z","event_type":"price_change","market_id":"3823627","outcome_index":0,"market_type":"match","local_side":"home","local_uid":"2026-08-24_claire_liu_heather_watson","bid":0.36,"ask":0.38,"mid":0.37,"spread":0.02,"price":0.37,"size":0.0,"side":"BUY"}
{"ts":"2026-08-24T20:48:11.719Z","event_type":"best_bid_ask","market_id":"3823627","outcome_index":0,"market_type":"match","local_side":"home","local_uid":"2026-08-24_claire_liu_heather_watson","bid":0.37,"ask":0.38,"mid":0.375,"spread":0.01,"bid_size":null,"ask_size":null}
{"ts":"2026-08-24T20:48:11.719Z","event_type":"best_bid_ask","market_id":"3823627","outcome_index":1,"market_type":"match","local_side":"away","local_uid":"2026-08-24_claire_liu_heather_watson","bid":0.62,"ask":0.63,"mid":0.625,"spread":0.01,"bid_size":null,"ask_size":null}
{"ts":"2026-08-24T20:48:11.720Z","event_type":"price_change","market_id":"3823627","outcome_index":0,"market_type":"match","local_side":"home","local_uid":"2026-08-24_claire_liu_heather_watson","bid":0.37,"ask":0.38,"mid":0.375,"spread":0.01,"price":0.37,"size":12.0,"side":"BUY"}
{"ts":"2026-08-24T20:48:11.720Z","event_type":"price_change","market_id":"3823627","outcome_index":1,"market_type":"match","local_side":"away","local_uid":"2026-08-24_claire_liu_heather_watson","bid":0.62,"ask":0.63,"mid":0.625,"spread":0.01,"price":0.63,"size":12.0,"side":"SELL"}
{"ts":"2026-08-24T20:48:12.434Z","event_type":"price_change","market_id":"3825620","outcome_index":1,"market_type":"match","local_side":"away","local_uid":"2026-08-24_andrea_guerrieri_august_holmgren","bid":0.05,"ask":0.06,"mid":0.055,"spread":0.01,"price":0.03,"size":18019.57,"side":"BUY"}
{"ts":"2026-08-24T20:48:12.434Z","event_type":"price_change","market_id":"3825620","outcome_index":0,"market_type":"match","local_side":"home","local_uid":"2026-08-24_andrea_guerrieri_august_holmgren","bid":0.94,"ask":0.95,"mid":0.945,"spread":0.01,"price":0.97,"size":18019.57,"side":"SELL"}
{"ts":"2026-08-24T20:48:12.595Z","event_type":"price_change","market_id":"3826888","outcome_index":0,"market_type":"set1","local_side":"home","local_uid":"2026-08-24_stefano_napolitano_mackenzie_mcdonald","bid":0.24,"ask":0.28,"mid":0.26,"spread":0.04,"price":0.2,"size":6478.0,"side":"BUY"}
{"ts":"2026-08-24T20:48:12.595Z","event_type":"price_change","market_id":"3826888","outcome_index":1,"market_type":"set1","local_side":"away","local_uid":"2026-08-24_stefano_napolitano_mackenzie_mcdonald","bid":0.72,"ask":0.76,"mid":0.74,"spread":0.04,"price":0.8,"size":6478.0,"side":"SELL"}
{"ts":"2026-08-24T20:48:12.596Z","event_type":"best_bid_ask","market_id":"3825053","outcome_index":0,"market_type":"set1","local_side":"home","local_uid":"2026-08-24_robin_montgomery_kayla_cross","bid":0.87,"ask":0.95,"mid":0.91,"spread":0.08,"bid_size":null,"ask_size":null}
{"ts":"2026-08-24T20:48:12.596Z","event_type":"best_bid_ask","market_id":"3825053","outcome_index":1,"market_type":"set1","local_side":"away","local_uid":"2026-08-24_robin_montgomery_kayla_cross","bid":0.05,"ask":0.13,"mid":0.09,"spread":0.08,"bid_size":null,"ask_size":null}
{"ts":"2026-08-24T20:48:12.596Z","event_type":"price_change","market_id":"3825053","outcome_index":0,"market_type":"set1","local_side":"home","local_uid":"2026-08-24_robin_montgomery_kayla_cross","bid":0.87,"ask":0.95,"mid":0.91,"spread":0.08,"price":0.87,"size":88.0,"side":"BUY"}
{"ts":"2026-08-24T20:48:12.597Z","event_type":"price_change","market_id":"3825053","outcome_index":1,"market_type":"set1","local_side":"away","local_uid":"2026-08-24_robin_montgomery_kayla_cross","bid":0.05,"ask":0.13,"mid":0.09,"spread":0.08,"price":0.13,"size":88.0,"side":"SELL"}
{"ts":"2026-08-24T20:48:12.597Z","event_type":"price_change","market_id":"3825643","outcome_index":0,"market_type":"match","local_side":"home","local_uid":"2026-08-24_jan_choinski_mees_rottgering","bid":0.56,"ask":0.58,"mid":0.57,"spread":0.02,"price":0.55,"size":3808.5,"side":"BUY"}
{"ts":"2026-08-24T20:48:12.597Z","event_type":"price_change","market_id":"3825643","outcome_index":1,"market_type":"match","local_side":"away","local_uid":"2026-08-24_jan_choinski_mees_rottgering","bid":0.42,"ask":0.44,"mid":0.43,"spread":0.02,"price":0.45,"size":3808.5,"side":"SELL"}
{"ts":"2026-08-24T20:48:12.706Z","event_type":"best_bid_ask","market_id":"3825053","outcome_index":0,"market_type":"set1","local_side":"home","local_uid":"2026-08-24_robin_montgomery_kayla_cross","bid":0.88,"ask":0.95,"mid":0.915,"spread":0.07,"bid_size":null,"ask_size":null}
{"ts":"2026-08-24T20:48:12.712Z","event_type":"best_bid_ask","market_id":"3825053","outcome_index":1,"market_type":"set1","local_side":"away","local_uid":"2026-08-24_robin_montgomery_kayla_cross","bid":0.05,"ask":0.12,"mid":0.085,"spread":0.07,"bid_size":null,"ask_size":null}
{"ts":"2026-08-24T20:48:12.712Z","event_type":"price_change","market_id":"3825053","outcome_index":0,"market_type":"set1","local_side":"home","local_uid":"2026-08-24_robin_montgomery_kayla_cross","bid":0.88,"ask":0.95,"mid":0.915,"spread":0.07,"price":0.88,"size":88.0,"side":"BUY"}
{"ts":"2026-08-24T20:48:12.712Z","event_type":"price_change","market_id":"3825053","outcome_index":1,"market_type":"set1","local_side":"away","local_uid":"2026-08-24_robin_montgomery_kayla_cross","bid":0.05,"ask":0.12,"mid":0.085,"spread":0.07,"price":0.12,"size":88.0,"side":"SELL"}
{"ts":"2026-08-24T20:48:12.770Z","event_type":"best_bid_ask","market_id":"3825053","outcome_index":0,"market_type":"set1","local_side":"home","local_uid":"2026-08-24_robin_montgomery_kayla_cross","bid":0.89,"ask":0.95,"mid":0.92,"spread":0.06,"bid_size":null,"ask_size":null}
{"ts":"2026-08-24T20:48:12.770Z","event_type":"best_bid_ask","market_id":"3825053","outcome_index":1,"market_type":"set1","local_side":"away","local_uid":"2026-08-24_robin_montgomery_kayla_cross","bid":0.05,"ask":0.11,"mid":0.08,"spread":0.06,"bid_size":null,"ask_size":null}
{"ts":"2026-08-24T20:48:12.770Z","event_type":"price_change","market_id":"3825053","outcome_index":0,"market_type":"set1","local_side":"home","local_uid":"2026-08-24_robin_montgomery_kayla_cross","bid":0.89,"ask":0.95,"mid":0.92,"spread":0.06,"price":0.89,"size":40.74,"side":"BUY"}
{"ts":"2026-08-24T20:48:12.770Z","event_type":"price_change","market_id":"3825053","outcome_index":1,"market_type":"set1","local_side":"away","local_uid":"2026-08-24_robin_montgomery_kayla_cross","bid":0.05,"ask":0.11,"mid":0.08,"spread":0.06,"price":0.11,"size":40.74,"side":"SELL"}
{"ts":"2026-08-24T20:48:13.021Z","event_type":"best_bid_ask","market_id":"3826654","outcome_index":0,"market_type":"set2","local_side":"home","local_uid":"2026-08-24_sebastian_gorzny_cruz_hewitt","bid":0.07,"ask":0.13,"mid":0.1,"spread":0.06,"bid_size":null,"ask_size":null}
{"ts":"2026-08-24T20:48:13.022Z","event_type":"best_bid_ask","market_id":"3826654","outcome_index":1,"market_type":"set2","local_side":"away","local_uid":"2026-08-24_sebastian_gorzny_cruz_hewitt","bid":0.87,"ask":0.93,"mid":0.9,"spread":0.06,"bid_size":null,"ask_size":null}
{"ts":"2026-08-24T20:48:13.022Z","event_type":"price_change","market_id":"3826654","outcome_index":0,"market_type":"set2","local_side":"home","local_uid":"2026-08-24_sebastian_gorzny_cruz_hewitt","bid":0.07,"ask":0.13,"mid":0.1,"spread":0.06,"price":0.07,"size":22.0,"side":"BUY"}
{"ts":"2026-08-24T20:48:13.022Z","event_type":"price_change","market_id":"3826654","outcome_index":1,"market_type":"set2","local_side":"away","local_uid":"2026-08-24_sebastian_gorzny_cruz_hewitt","bid":0.87,"ask":0.93,"mid":0.9,"spread":0.06,"price":0.93,"size":22.0,"side":"SELL"}
{"ts":"2026-08-24T20:48:13.052Z","event_type":"price_change","market_id":"3823647","outcome_index":0,"market_type":"match","local_side":"home","local_uid":"2026-08-24_eva_vedder_bianca_andreescu","bid":0.17,"ask":0.18,"mid":0.175,"spread":0.01,"price":0.14,"size":32500.89,"side":"BUY"}
{"ts":"2026-08-24T20:48:13.052Z","event_type":"price_change","market_id":"3823647","outcome_index":1,"market_type":"match","local_side":"away","local_uid":"2026-08-24_eva_vedder_bianca_andreescu","bid":0.82,"ask":0.83,"mid":0.825,"spread":0.01,"price":0.86,"size":32500.89,"side":"SELL"}
{"ts":"2026-08-24T20:48:13.082Z","event_type":"best_bid_ask","market_id":"3826654","outcome_index":0,"market_type":"set2","local_side":"home","local_uid":"2026-08-24_sebastian_gorzny_cruz_hewitt","bid":0.06,"ask":0.13,"mid":0.095,"spread":0.07,"bid_size":null,"ask_size":null}
{"ts":"2026-08-24T20:48:13.082Z","event_type":"best_bid_ask","market_id":"3826654","outcome_index":1,"market_type":"set2","local_side":"away","local_uid":"2026-08-24_sebastian_gorzny_cruz_hewitt","bid":0.87,"ask":0.94,"mid":0.905,"spread":0.07,"bid_size":null,"ask_size":null}
{"ts":"2026-08-24T20:48:13.082Z","event_type":"price_change","market_id":"3826654","outcome_index":0,"market_type":"set2","local_side":"home","local_uid":"2026-08-24_sebastian_gorzny_cruz_hewitt","bid":0.06,"ask":0.13,"mid":0.095,"spread":0.07,"price":0.07,"size":0.0,"side":"BUY"}
{"ts":"2026-08-24T20:48:13.083Z","event_type":"price_change","market_id":"3826654","outcome_index":1,"market_type":"set2","local_side":"away","local_uid":"2026-08-24_sebastian_gorzny_cruz_hewitt","bid":0.87,"ask":0.94,"mid":0.905,"spread":0.07,"price":0.93,"size":0.0,"side":"SELL"}
{"ts":"2026-08-24T20:48:13.226Z","event_type":"best_bid_ask","market_id":"3825053","outcome_index":0,"market_type":"set1","local_side":"home","local_uid":"2026-08-24_robin_montgomery_kayla_cross","bid":0.89,"ask":0.94,"mid":0.915,"spread":0.05,"bid_size":null,"ask_size":null}
{"ts":"2026-08-24T20:48:13.227Z","event_type":"best_bid_ask","market_id":"3825053","outcome_index":1,"market_type":"set1","local_side":"away","local_uid":"2026-08-24_robin_montgomery_kayla_cross","bid":0.06,"ask":0.11,"mid":0.085,"spread":0.05,"bid_size":null,"ask_size":null}
{"ts":"2026-08-24T20:48:13.227Z","event_type":"price_change","market_id":"3825053","outcome_index":1,"market_type":"set1","local_side":"away","local_uid":"2026-08-24_robin_montgomery_kayla_cross","bid":0.06,"ask":0.11,"mid":0.085,"spread":0.05,"price":0.06,"size":250.0,"side":"BUY"}
{"ts":"2026-08-24T20:48:13.227Z","event_type":"price_change","market_id":"3825053","outcome_index":0,"market_type":"set1","local_side":"home","local_uid":"2026-08-24_robin_montgomery_kayla_cross","bid":0.89,"ask":0.94,"mid":0.915,"spread":0.05,"price":0.94,"size":250.0,"side":"SELL"}
{"ts":"2026-08-24T20:48:13.703Z","event_type":"price_change","market_id":"3827008","outcome_index":1,"market_type":"set1","local_side":"away","local_uid":"2026-08-24_pol_martin_tiffon_tom_gentzsch","bid":0.61,"ask":0.63,"mid":0.62,"spread":0.02,"price":0.5,"size":39.22,"side":"BUY"}
{"ts":"2026-08-24T20:48:13.704Z","event_type":"price_change","market_id":"3827008","outcome_index":0,"market_type":"set1","local_side":"home","local_uid":"2026-08-24_pol_martin_tiffon_tom_gentzsch","bid":0.37,"ask":0.39,"mid":0.38,"spread":0.02,"price":0.5,"size":39.22,"side":"SELL"}
{"ts":"2026-08-24T20:48:13.713Z","event_type":"best_bid_ask","market_id":"3823627","outcome_index":0,"market_type":"match","local_side":"home","local_uid":"2026-08-24_claire_liu_heather_watson","bid":0.36,"ask":0.38,"mid":0.37,"spread":0.02,"bid_size":null,"ask_size":null}
{"ts":"2026-08-24T20:48:13.713Z","event_type":"best_bid_ask","market_id":"3823627","outcome_index":1,"market_type":"match","local_side":"away","local_uid":"2026-08-24_claire_liu_heather_watson","bid":0.62,"ask":0.64,"mid":0.63,"spread":0.02,"bid_size":null,"ask_size":null}
{"ts":"2026-08-24T20:48:13.713Z","event_type":"price_change","market_id":"3823627","outcome_index":0,"market_type":"match","local_side":"home","local_uid":"2026-08-24_claire_liu_heather_watson","bid":0.36,"ask":0.38,"mid":0.37,"spread":0.02,"price":0.37,"size":0.0,"side":"BUY"}
{"ts":"2026-08-24T20:48:13.713Z","event_type":"price_change","market_id":"3823627","outcome_index":1,"market_type":"match","local_side":"away","local_uid":"2026-08-24_claire_liu_heather_watson","bid":0.62,"ask":0.64,"mid":0.63,"spread":0.02,"price":0.63,"size":0.0,"side":"SELL"}
{"ts":"2026-08-24T20:48:13.716Z","event_type":"best_bid_ask","market_id":"3826733","outcome_index":0,"market_type":"set1","local_side":"home","local_uid":"2026-08-24_harry_wendelken_stefano_travaglia","bid":0.86,"ask":0.91,"mid":0.885,"spread":0.05,"bid_size":null,"ask_size":null}
{"ts":"2026-08-24T20:48:13.717Z","event_type":"best_bid_ask","market_id":"3826733","outcome_index":1,"market_type":"set1","local_side":"away","local_uid":"2026-08-24_harry_wendelken_stefano_travaglia","bid":0.09,"ask":0.14,"mid":0.115,"spread":0.05,"bid_size":null,"ask_size":null}
{"ts":"2026-08-24T20:48:13.717Z","event_type":"price_change","market_id":"3826733","outcome_index":1,"market_type":"set1","local_side":"away","local_uid":"2026-08-24_harry_wendelken_stefano_travaglia","bid":0.09,"ask":0.14,"mid":0.115,"spread":0.05,"price":0.1,"size":0.0,"side":"BUY"}
{"ts":"2026-08-24T20:48:13.717Z","event_type":"price_change","market_id":"3826733","outcome_index":0,"market_type":"set1","local_side":"home","local_uid":"2026-08-24_harry_wendelken_stefano_travaglia","bid":0.86,"ask":0.91,"mid":0.885,"spread":0.05,"price":0.9,"size":0.0,"side":"SELL"}
{"ts":"2026-08-24T20:48:13.777Z","event_type":"best_bid_ask","market_id":"3823627","outcome_index":0,"market_type":"match","local_side":"home","local_uid":"2026-08-24_claire_liu_heather_watson","bid":0.36,"ask":0.37,"mid":0.365,"spread":0.01,"bid_size":null,"ask_size":null}
{"ts":"2026-08-24T20:48:13.778Z","event_type":"best_bid_ask","market_id":"3823627","outcome_index":1,"market_type":"match","local_side":"away","local_uid":"2026-08-24_claire_liu_heather_watson","bid":0.63,"ask":0.64,"mid":0.635,"spread":0.01,"bid_size":null,"ask_size":null}
{"ts":"2026-08-24T20:48:13.778Z","event_type":"price_change","market_id":"3823627","outcome_index":1,"market_type":"match","local_side":"away","local_uid":"2026-08-24_claire_liu_heather_watson","bid":0.63,"ask":0.64,"mid":0.635,"spread":0.01,"price":0.63,"size":20.0,"side":"BUY"}
{"ts":"2026-08-24T20:48:13.778Z","event_type":"price_change","market_id":"3823627","outcome_index":0,"market_type":"match","local_side":"home","local_uid":"2026-08-24_claire_liu_heather_watson","bid":0.36,"ask":0.37,"mid":0.365,"spread":0.01,"price":0.37,"size":20.0,"side":"SELL"}
{"ts":"2026-08-24T20:48:13.854Z","event_type":"best_bid_ask","market_id":"3826738","outcome_index":0,"market_type":"set2","local_side":"home","local_uid":"2026-08-24_harry_wendelken_stefano_travaglia","bid":0.5,"ask":0.6,"mid":0.55,"spread":0.1,"bid_size":null,"ask_size":null}
{"ts":"2026-08-24T20:48:13.855Z","event_type":"best_bid_ask","market_id":"3826738","outcome_index":1,"market_type":"set2","local_side":"away","local_uid":"2026-08-24_harry_wendelken_stefano_travaglia","bid":0.4,"ask":0.5,"mid":0.45,"spread":0.1,"bid_size":null,"ask_size":null}
{"ts":"2026-08-24T20:48:13.855Z","event_type":"price_change","market_id":"3826738","outcome_index":1,"market_type":"set2","local_side":"away","local_uid":"2026-08-24_harry_wendelken_stefano_travaglia","bid":0.4,"ask":0.5,"mid":0.45,"spread":0.1,"price":0.41,"size":0.0,"side":"BUY"}
{"ts":"2026-08-24T20:48:13.855Z","event_type":"price_change","market_id":"3826738","outcome_index":0,"market_type":"set2","local_side":"home","local_uid":"2026-08-24_harry_wendelken_stefano_travaglia","bid":0.5,"ask":0.6,"mid":0.55,"spread":0.1,"price":0.59,"size":0.0,"side":"SELL"}
{"ts":"2026-08-24T20:48:14.117Z","event_type":"best_bid_ask","market_id":"3826738","outcome_index":0,"market_type":"set2","local_side":"home","local_uid":"2026-08-24_harry_wendelken_stefano_travaglia","bid":0.5,"ask":0.59,"mid":0.545,"spread":0.09,"bid_size":null,"ask_size":null}
{"ts":"2026-08-24T20:48:14.117Z","event_type":"best_bid_ask","market_id":"3826738","outcome_index":1,"market_type":"set2","local_side":"away","local_uid":"2026-08-24_harry_wendelken_stefano_travaglia","bid":0.41,"ask":0.5,"mid":0.455,"spread":0.09,"bid_size":null,"ask_size":null}
{"ts":"2026-08-24T20:48:14.118Z","event_type":"price_change","market_id":"3826738","outcome_index":1,"market_type":"set2","local_side":"away","local_uid":"2026-08-24_harry_wendelken_stefano_travaglia","bid":0.41,"ask":0.5,"mid":0.455,"spread":0.09,"price":0.41,"size":7.0,"side":"BUY"}
{"ts":"2026-08-24T20:48:14.118Z","event_type":"price_change","market_id":"3826738","outcome_index":0,"market_type":"set2","local_side":"home","local_uid":"2026-08-24_harry_wendelken_stefano_travaglia","bid":0.5,"ask":0.59,"mid":0.545,"spread":0.09,"price":0.59,"size":7.0,"side":"SELL"}
{"ts":"2026-08-24T20:48:14.133Z","event_type":"best_bid_ask","market_id":"3825070","outcome_index":0,"market_type":"set2","local_side":"home","local_uid":"2026-08-24_polina_kudermetova_linda_fruhvirtova","bid":0.5,"ask":0.59,"mid":0.545,"spread":0.09,"bid_size":null,"ask_size":null}
{"ts":"2026-08-24T20:48:14.133Z","event_type":"best_bid_ask","market_id":"3825070","outcome_index":1,"market_type":"set2","local_side":"away","local_uid":"2026-08-24_polina_kudermetova_linda_fruhvirtova","bid":0.41,"ask":0.5,"mid":0.455,"spread":0.09,"bid_size":null,"ask_size":null}
{"ts":"2026-08-24T20:48:14.133Z","event_type":"price_change","market_id":"3825070","outcome_index":0,"market_type":"set2","local_side":"home","local_uid":"2026-08-24_polina_kudermetova_linda_fruhvirtova","bid":0.5,"ask":0.59,"mid":0.545,"spread":0.09,"price":0.53,"size":0.0,"side":"BUY"}
{"ts":"2026-08-24T20:48:14.134Z","event_type":"price_change","market_id":"3825070","outcome_index":1,"market_type":"set2","local_side":"away","local_uid":"2026-08-24_polina_kudermetova_linda_fruhvirtova","bid":0.41,"ask":0.5,"mid":0.455,"spread":0.09,"price":0.47,"size":0.0,"side":"SELL"}
