{"ts":"2026-08-24T20:47:50.297Z","event_type":"price_change","market_id":"3823623","outcome_index":1,"market_type":"match","local_side":"away","local_uid":"2026-08-24_robin_montgomery_kayla_cross","bid":0.12,"ask":0.13,"mid":0.125,"spread":0.01,"price":0.13,"size":294.46,"side":"SELL"}
{"ts":"2026-08-24T20:47:50.584Z","event_type":"best_bid_ask","market_id":"3826919","outcome_index":0,"market_type":"set2","local_side":"home","local_uid":"2026-08-24_dalibor_svrcina_felipe_meligeni_alves","bid":0.44,"ask":0.56,"mid":0.5,"spread":0.12,"bid_size":null,"ask_size":null}
{"ts":"2026-08-24T20:47:50.585Z","event_type":"best_bid_ask","market_id":"3826919","outcome_index":1,"market_type":"set2","local_side":"away","local_uid":"2026-08-24_dalibor_svrcina_felipe_meligeni_alves","bid":0.44,"ask":0.56,"mid":0.5,"spread":0.12,"bid_size":null,"ask_size":null}
{"ts":"2026-08-24T20:47:50.585Z","event_type":"price_change","market_id":"3826919","outcome_index":0,"market_type":"set2","local_side":"home","local_uid":"2026-08-24_dalibor_svrcina_felipe_meligeni_alves","bid":0.44,"ask":0.56,"mid":0.5,"spread":0.12,"price":0.44,"size":67.43,"side":"BUY"}
{"ts":"2026-08-24T20:47:50.585Z","event_type":"price_change","market_id":"3826919","outcome_index":1,"market_type":"set2","local_side":"away","local_uid":"2026-08-24_dalibor_svrcina_felipe_meligeni_alves","bid":0.44,"ask":0.56,"mid":0.5,"spread":0.12,"price":0.56,"size":67.43,"side":"SELL"}
{"ts":"2026-08-24T20:47:51.129Z","event_type":"best_bid_ask","market_id":"3826733","outcome_index":0,"market_type":"set1","local_side":"home","local_uid":"2026-08-24_harry_wendelken_stefano_travaglia","bid":0.86,"ask":0.9,"mid":0.88,"spread":0.04,"bid_size":null,"ask_size":null}
{"ts":"2026-08-24T20:47:51.129Z","event_type":"best_bid_ask","market_id":"3826733","outcome_index":1,"market_type":"set1","local_side":"away","local_uid":"2026-08-24_harry_wendelken_stefano_travaglia","bid":0.1,"ask":0.14,"mid":0.12,"spread":0.04,"bid_size":null,"ask_size":null}
{"ts":"2026-08-24T20:47:51.130Z","event_type":"price_change","market_id":"3826733","outcome_index":1,"market_type":"set1","local_side":"away","local_uid":"2026-08-24_harry_wendelken_stefano_travaglia","bid":0.1,"ask":0.14,"mid":0.12,"spread":0.04,"price":0.1,"size":1753.15,"side":"BUY"}
{"ts":"2026-08-24T20:47:51.130Z","event_type":"price_change","market_id":"3826733","outcome_index":0,"market_type":"set1","local_side":"home","local_uid":"2026-08-24_harry_wendelken_stefano_travaglia","bid":0.86,"ask":0.9,"mid":0.88,"spread":0.04,"price":0.9,"size":1753.15,"side":"SELL"}
{"ts":"2026-08-24T20:47:51.151Z","event_type":"best_bid_ask","market_id":"3825604","outcome_index":0,"market_type":"match","local_side":"home","local_uid":"2026-08-24_dalibor_svrcina_felipe_meligeni_alves","bid":0.78,"ask":0.83,"mid":0.805,"spread":0.05,"bid_size":null,"ask_size":null}
{"ts":"2026-08-24T20:47:51.152Z","event_type":"best_bid_ask","market_id":"3825604","outcome_index":1,"market_type":"match","local_side":"away","local_uid":"2026-08-24_dalibor_svrcina_felipe_meligeni_alves","bid":0.17,"ask":0.22,"mid":0.195,"spread":0.05,"bid_size":null,"ask_size":null}
{"ts":"2026-08-24T20:47:51.152Z","event_type":"price_change","market_id":"3825604","outcome_index":1,"market_type":"match","local_side":"away","local_uid":"2026-08-24_dalibor_svrcina_felipe_meligeni_alves","bid":0.17,"ask":0.22,"mid":0.195,"spread":0.05,"price":0.17,"size":10.0,"side":"BUY"}
{"ts":"2026-08-24T20:47:51.152Z","event_type":"price_change","market_id":"3825604","outcome_index":0,"market_type":"match","local_side":"home","local_uid":"2026-08-24_dalibor_svrcina_felipe_meligeni_alves","bid":0.78,"ask":0.83,"mid":0.805,"spread":0.05,"price":0.83,"size":10.0,"side":"SELL"}
{"ts":"2026-08-24T20:47:51.220Z","event_type":"best_bid_ask","market_id":"3825077","outcome_index":0,"market_type":"set1","local_side":"home","local_uid":"2026-08-24_polina_kudermetova_linda_fruhvirtova","bid":0.45,"ask":0.56,"mid":0.505,"spread":0.11,"bid_size":null,"ask_size":null}
{"ts":"2026-08-24T20:47:51.220Z","event_type":"best_bid_ask","market_id":"3825077","outcome_index":1,"market_type":"set1","local_side":"away","local_uid":"2026-08-24_polina_kudermetova_linda_fruhvirtova","bid":0.44,"ask":0.55,"mid":0.495,"spread":0.11,"bid_size":null,"ask_size":null}
{"ts":"2026-08-24T20:47:51.221Z","event_type":"price_change","market_id":"3825077","outcome_index":1,"market_type":"set1","local_side":"away","local_uid":"2026-08-24_polina_kudermetova_linda_fruhvirtova","bid":0.44,"ask":0.55,"mid":0.495,"spread":0.11,"price":0.48,"size":0.0,"side":"BUY"}
{"ts":"2026-08-24T20:47:51.221Z","event_type":"price_change","market_id":"3825077","outcome_index":0,"market_type":"set1","local_side":"home","local_uid":"2026-08-24_polina_kudermetova_linda_fruhvirtova","bid":0.45,"ask":0.56,"mid":0.505,"spread":0.11,"price":0.52,"size":0.0,"side":"SELL"}
{"ts":"2026-08-24T20:47:51.228Z","event_type":"best_bid_ask","market_id":"3825077","outcome_index":0,"market_type":"set1","local_side":"home","local_uid":"2026-08-24_polina_kudermetova_linda_fruhvirtova","bid":0.45,"ask":0.55,"mid":0.5,"spread":0.1,"bid_size":null,"ask_size":null}
{"ts":"2026-08-24T20:47:51.228Z","event_type":"best_bid_ask","market_id":"3825077","outcome_index":1,"market_type":"set1","local_side":"away","local_uid":"2026-08-24_polina_kudermetova_linda_fruhvirtova","bid":0.45,"ask":0.55,"mid":0.5,"spread":0.1,"bid_size":null,"ask_size":null}
{"ts":"2026-08-24T20:47:51.228Z","event_type":"price_change","market_id":"3825077","outcome_index":1,"market_type":"set1","local_side":"away","local_uid":"2026-08-24_polina_kudermetova_linda_fruhvirtova","bid":0.45,"ask":0.55,"mid":0.5,"spread":0.1,"price":0.45,"size":15.0,"side":"BUY"}
{"ts":"2026-08-24T20:47:51.228Z","event_type":"price_change","market_id":"3825077","outcome_index":0,"market_type":"set1","local_side":"home","local_uid":"2026-08-24_polina_kudermetova_linda_fruhvirtova","bid":0.45,"ask":0.55,"mid":0.5,"spread":0.1,"price":0.55,"size":15.0,"side":"SELL"}
{"ts":"2026-08-24T20:47:51.243Z","event_type":"best_bid_ask","market_id":"3826738","outcome_index":0,"market_type":"set2","local_side":"home","local_uid":"2026-08-24_harry_wendelken_stefano_travaglia","bid":0.5,"ask":0.59,"mid":0.545,"spread":0.09,"bid_size":null,"ask_size":null}
{"ts":"2026-08-24T20:47:51.244Z","event_type":"best_bid_ask","market_id":"3826738","outcome_index":1,"market_type":"set2","local_side":"away","local_uid":"2026-08-24_harry_wendelken_stefano_travaglia","bid":0.41,"ask":0.5,"mid":0.455,"spread":0.09,"bid_size":null,"ask_size":null}
{"ts":"2026-08-24T20:47:51.244Z","event_type":"best_bid_ask","market_id":"3826654","outcome_index":0,"market_type":"set2","local_side":"home","local_uid":"2026-08-24_sebastian_gorzny_cruz_hewitt","bid":0.17,"ask":0.25,"mid":0.21,"spread":0.08,"bid_size":null,"ask_size":null}
{"ts":"2026-08-24T20:47:51.244Z","event_type":"best_bid_ask","market_id":"3826654","outcome_index":1,"market_type":"set2","local_side":"away","local_uid":"2026-08-24_sebastian_gorzny_cruz_hewitt","bid":0.75,"ask":0.83,"mid":0.79,"spread":0.08,"bid_size":null,"ask_size":null}
{"ts":"2026-08-24T20:47:51.245Z","event_type":"price_change","market_id":"3826654","outcome_index":0,"market_type":"set2","local_side":"home","local_uid":"2026-08-24_sebastian_gorzny_cruz_hewitt","bid":0.17,"ask":0.25,"mid":0.21,"spread":0.08,"price":0.17,"size":1542.0,"side":"BUY"}
{"ts":"2026-08-24T20:47:51.245Z","event_type":"price_change","market_id":"3826654","outcome_index":1,"market_type":"set2","local_side":"away","local_uid":"2026-08-24_sebastian_gorzny_cruz_hewitt","bid":0.75,"ask":0.83,"mid":0.79,"spread":0.08,"price":0.83,"size":1542.0,"side":"SELL"}
{"ts":"2026-08-24T20:47:51.245Z","event_type":"price_change","market_id":"3826738","outcome_index":1,"market_type":"set2","local_side":"away","local_uid":"2026-08-24_harry_wendelken_stefano_travaglia","bid":0.41,"ask":0.5,"mid":0.455,"spread":0.09,"price":0.41,"size":1095.0,"side":"BUY"}
{"ts":"2026-08-24T20:47:51.245Z","event_type":"price_change","market_id":"3826738","outcome_index":0,"market_type":"set2","local_side":"home","local_uid":"2026-08-24_harry_wendelken_stefano_travaglia","bid":0.5,"ask":0.59,"mid":0.545,"spread":0.09,"price":0.59,"size":1095.0,"side":"SELL"}
{"ts":"2026-08-24T20:47:51.269Z","event_type":"best_bid_ask","market_id":"3823619","outcome_index":0,"market_type":"match","local_side":"home","local_uid":"2026-08-24_polina_kudermetova_linda_fruhvirtova","bid":0.56,"ask":0.58,"mid":0.57,"spread":0.02,"bid_size":null,"ask_size":null}
{"ts":"2026-08-24T20:47:51.270Z","event_type":"best_bid_ask","market_id":"3823619","outcome_index":1,"market_type":"match","local_side":"away","local_uid":"2026-08-24_polina_kudermetova_linda_fruhvirtova","bid":0.42,"ask":0.44,"mid":0.43,"spread":0.02,"bid_size":null,"ask_size":null}
{"ts":"2026-08-24T20:47:51.270Z","event_type":"price_change","market_id":"3823619","outcome_index":0,"market_type":"match","local_side":"home","local_uid":"2026-08-24_polina_kudermetova_linda_fruhvirtova","bid":0.56,"ask":0.58,"mid":0.57,"spread":0.02,"price":0.57,"size":0.0,"side":"BUY"}
{"ts":"2026-08-24T20:47:51.270Z","event_type":"price_change","market_id":"3823619","outcome_index":1,"market_type":"match","local_side":"away","local_uid":"2026-08-24_polina_kudermetova_linda_fruhvirtova","bid":0.42,"ask":0.44,"mid":0.43,"spread":0.02,"price":0.43,"size":0.0,"side":"SELL"}
{"ts":"2026-08-24T20:47:51.280Z","event_type":"price_change","market_id":"3823625","outcome_index":1,"market_type":"match","local_side":"away","local_uid":"2026-08-24_greet_minnen_jeline_vandromme","bid":0.82,"ask":0.83,"mid":0.825,"spread":0.01,"price":0.62,"size":28.0,"side":"BUY"}
{"ts":"2026-08-24T20:47:51.281Z","event_type":"price_change","market_id":"3823625","outcome_index":0,"market_type":"match","local_side":"home","local_uid":"2026-08-24_greet_minnen_jeline_vandromme","bid":0.17,"ask":0.18,"mid":0.175,"spread":0.01,"price":0.38,"size":28.0,"side":"SELL"}
{"ts":"2026-08-24T20:47:51.739Z","event_type":"best_bid_ask","market_id":"3824796","outcome_index":0,"market_type":"set2","local_side":"home","local_uid":"2026-08-24_victoria_jimenez_kasintseva_francisca_jorge","bid":0.52,"ask":0.62,"mid":0.57,"spread":0.1,"bid_size":null,"ask_size":null}
{"ts":"2026-08-24T20:47:51.740Z","event_type":"best_bid_ask","market_id":"3824796","outcome_index":1,"market_type":"set2","local_side":"away","local_uid":"2026-08-24_victoria_jimenez_kasintseva_francisca_jorge","bid":0.38,"ask":0.48,"mid":0.43,"spread":0.1,"bid_size":null,"ask_size":null}
{"ts":"2026-08-24T20:47:51.740Z","event_type":"price_change","market_id":"3824796","outcome_index":1,"market_type":"set2","local_side":"away","local_uid":"2026-08-24_victoria_jimenez_kasintseva_francisca_jorge","bid":0.38,"ask":0.48,"mid":0.43,"spread":0.1,"price":0.39,"size":0.0,"side":"BUY"}
{"ts":"2026-08-24T20:47:51.740Z","event_type":"price_change","market_id":"3824796","outcome_index":0,"market_type":"set2","local_side":"home","local_uid":"2026-08-24_victoria_jimenez_kasintseva_francisca_jorge","bid":0.52,"ask":0.62,"mid":0.57,"spread":0.1,"price":0.61,"size":0.0,"side":"SELL"}
{"ts":"2026-08-24T20:47:52.028Z","event_type":"best_bid_ask","market_id":"3823619","outcome_index":0,"market_type":"match","local_side":"home","local_uid":"2026-08-24_polina_kudermetova_linda_fruhvirtova","bid":0.55,"ask":0.58,"mid":0.565,"spread":0.03,"bid_size":null,"ask_size":null}
{"ts":"2026-08-24T20:47:52.028Z","event_type":"best_bid_ask","market_id":"3823619","outcome_index":1,"market_type":"match","local_side":"away","local_uid":"2026-08-24_polina_kudermetova_linda_fruhvirtova","bid":0.42,"ask":0.45,"mid":0.435,"spread":0.03,"bid_size":null,"ask_size":null}
{"ts":"2026-08-24T20:47:52.029Z","event_type":"price_change","market_id":"3823619","outcome_index":0,"market_type":"match","local_side":"home","local_uid":"2026-08-24_polina_kudermetova_linda_fruhvirtova","bid":0.55,"ask":0.58,"mid":0.565,"spread":0.03,"price":0.56,"size":0.0,"side":"BUY"}
{"ts":"2026-08-24T20:47:52.029Z","event_type":"price_change","market_id":"3823619","outcome_index":1,"market_type":"match","local_side":"away","local_uid":"2026-08-24_polina_kudermetova_linda_fruhvirtova","bid":0.42,"ask":0.45,"mid":0.435,"spread":0.03,"price":0.44,"size":0.0,"side":"SELL"}
{"ts":"2026-08-24T20:47:52.300Z","event_type":"best_bid_ask","market_id":"3823627","outcome_index":0,"market_type":"match","local_side":"home","local_uid":"2026-08-24_claire_liu_heather_watson","bid":0.44,"ask":0.46,"mid":0.45,"spread":0.02,"bid_size":null,"ask_size":null}
{"ts":"2026-08-24T20:47:52.301Z","event_type":"best_bid_ask","market_id":"3823627","outcome_index":1,"market_type":"match","local_side":"away","local_uid":"2026-08-24_claire_liu_heather_watson","bid":0.54,"ask":0.56,"mid":0.55,"spread":0.02,"bid_size":null,"ask_size":null}
{"ts":"2026-08-24T20:47:52.301Z","event_type":"price_change","market_id":"3823627","outcome_index":0,"market_type":"match","local_side":"home","local_uid":"2026-08-24_claire_liu_heather_watson","bid":0.44,"ask":0.46,"mid":0.45,"spread":0.02,"price":0.45,"size":0.0,"side":"BUY"}
{"ts":"2026-08-24T20:47:52.301Z","event_type":"price_change","market_id":"3823627","outcome_index":1,"market_type":"match","local_side":"away","local_uid":"2026-08-24_claire_liu_heather_watson","bid":0.54,"ask":0.56,"mid":0.55,"spread":0.02,"price":0.55,"size":0.0,"side":"SELL"}
{"ts":"2026-08-24T20:47:52.307Z","event_type":"best_bid_ask","market_id":"3824796","outcome_index":0,"market_type":"set2","local_side":"home","local_uid":"2026-08-24_victoria_jimenez_kasintseva_francisca_jorge","bid":0.52,"ask":0.61,"mid":0.565,"spread":0.09,"bid_size":null,"ask_size":null}
{"ts":"2026-08-24T20:47:52.307Z","event_type":"best_bid_ask","market_id":"3824796","outcome_index":1,"market_type":"set2","local_side":"away","local_uid":"2026-08-24_victoria_jimenez_kasintseva_francisca_jorge","bid":0.39,"ask":0.48,"mid":0.435,"spread":0.09,"bid_size":null,"ask_size":null}
{"ts":"2026-08-24T20:47:52.308Z","event_type":"price_change","market_id":"3824796","outcome_index":1,"market_type":"set2","local_side":"away","local_uid":"2026-08-24_victoria_jimenez_kasintseva_francisca_jorge","bid":0.39,"ask":0.48,"mid":0.435,"spread":0.09,"price":0.39,"size":12.87,"side":"BUY"}
{"ts":"2026-08-24T20:47:52.308Z","event_type":"price_change","market_id":"3824796","outcome_index":0,"market_type":"set2","local_side":"home","local_uid":"2026-08-24_victoria_jimenez_kasintseva_francisca_jorge","bid":0.52,"ask":0.61,"mid":0.565,"spread":0.09,"price":0.61,"size":12.87,"side":"SELL"}
{"ts":"2026-08-24T20:47:52.337Z","event_type":"best_bid_ask","market_id":"3823627","outcome_index":0,"market_type":"match","local_side":"home","local_uid":"2026-08-24_claire_liu_heather_watson","bid":0.43,"ask":0.46,"mid":0.445,"spread":0.03,"bid_size":null,"ask_size":null}
{"ts":"2026-08-24T20:47:52.337Z","event_type":"best_bid_ask","market_id":"3823627","outcome_index":1,"market_type":"match","local_side":"away","local_uid":"2026-08-24_claire_liu_heather_watson","bid":0.54,"ask":0.57,"mid":0.555,"spread":0.03,"bid_size":null,"ask_size":null}
{"ts":"2026-08-24T20:47:52.338Z","event_type":"price_change","market_id":"3823627","outcome_index":0,"market_type":"match","local_side":"home","local_uid":"2026-08-24_claire_liu_heather_watson","bid":0.43,"ask":0.46,"mid":0.445,"spread":0.03,"price":0.44,"size":0.0,"side":"BUY"}
{"ts":"2026-08-24T20:47:52.338Z","event_type":"price_change","market_id":"3823627","outcome_index":1,"market_type":"match","local_side":"away","local_uid":"2026-08-24_claire_liu_heather_watson","bid":0.54,"ask":0.57,"mid":0.555,"spread":0.03,"price":0.56,"size":0.0,"side":"SELL"}
{"ts":"2026-08-24T20:47:52.340Z","event_type":"best_bid_ask","market_id":"3823627","outcome_index":0,"market_type":"match","local_side":"home","local_uid":"2026-08-24_claire_liu_heather_watson","bid":0.44,"ask":0.46,"mid":0.45,"spread":0.02,"bid_size":null,"ask_size":null}
{"ts":"2026-08-24T20:47:52.340Z","event_type":"best_bid_ask","market_id":"3823627","outcome_index":1,"market_type":"match","local_side":"away","local_uid":"2026-08-24_claire_liu_heather_watson","bid":0.54,"ask":0.56,"mid":0.55,"spread":0.02,"bid_size":null,"ask_size":null}
{"ts":"2026-08-24T20:47:52.340Z","event_type":"price_change","market_id":"3823627","outcome_index":0,"market_type":"match","local_side":"home","local_uid":"2026-08-24_claire_liu_heather_watson","bid":0.44,"ask":0.46,"mid":0.45,"spread":0.02,"price":0.44,"size":10.0,"side":"BUY"}
{"ts":"2026-08-24T20:47:52.340Z","event_type":"price_change","market_id":"3823627","outcome_index":1,"market_type":"match","local_side":"away","local_uid":"2026-08-24_claire_liu_heather_watson","bid":0.54,"ask":0.56,"mid":0.55,"spread":0.02,"price":0.56,"size":10.0,"side":"SELL"}
{"ts":"2026-08-24T20:47:52.341Z","event_type":"best_bid_ask","market_id":"3824796","outcome_index":0,"market_type":"set2","local_side":"home","local_uid":"2026-08-24_victoria_jimenez_kasintseva_francisca_jorge","bid":0.48,"ask":0.61,"mid":0.545,"spread":0.13,"bid_size":null,"ask_size":null}
{"ts":"2026-08-24T20:47:52.341Z","event_type":"best_bid_ask","market_id":"3824796","outcome_index":1,"market_type":"set2","local_side":"away","local_uid":"2026-08-24_victoria_jimenez_kasintseva_francisca_jorge","bid":0.39,"ask":0.52,"mid":0.455,"spread":0.13,"bid_size":null,"ask_size":null}
{"ts":"2026-08-24T20:47:52.341Z","event_type":"price_change","market_id":"3824796","outcome_index":0,"market_type":"set2","local_side":"home","local_uid":"2026-08-24_victoria_jimenez_kasintseva_francisca_jorge","bid":0.48,"ask":0.61,"mid":0.545,"spread":0.13,"price":0.52,"size":0.0,"side":"BUY"}
{"ts":"2026-08-24T20:47:52.341Z","event_type":"price_change","market_id":"3824796","outcome_index":1,"market_type":"set2","local_side":"away","local_uid":"2026-08-24_victoria_jimenez_kasintseva_francisca_jorge","bid":0.39,"ask":0.52,"mid":0.455,"spread":0.13,"price":0.48,"size":0.0,"side":"SELL"}
{"ts":"2026-08-24T20:47:52.342Z","event_type":"best_bid_ask","market_id":"3824796","outcome_index":0,"market_type":"set2","local_side":"home","local_uid":"2026-08-24_victoria_jimenez_kasintseva_francisca_jorge","bid":0.48,"ask":0.62,"mid":0.55,"spread":0.14,"bid_size":null,"ask_size":null}
{"ts":"2026-08-24T20:47:52.342Z","event_type":"best_bid_ask","market_id":"3824796","outcome_index":1,"market_type":"set2","local_side":"away","local_uid":"2026-08-24_victoria_jimenez_kasintseva_francisca_jorge","bid":0.38,"ask":0.52,"mid":0.45,"spread":0.14,"bid_size":null,"ask_size":null}
{"ts":"2026-08-24T20:47:52.343Z","event_type":"price_change","market_id":"3824796","outcome_index":1,"market_type":"set2","local_side":"away","local_uid":"2026-08-24_victoria_jimenez_kasintseva_francisca_jorge","bid":0.38,"ask":0.52,"mid":0.45,"spread":0.14,"price":0.39,"size":0.0,"side":"BUY"}
{"ts":"2026-08-24T20:47:52.343Z","event_type":"price_change","market_id":"3824796","outcome_index":0,"market_type":"set2","local_side":"home","local_uid":"2026-08-24_victoria_jimenez_kasintseva_francisca_jorge","bid":0.48,"ask":0.62,"mid":0.55,"spread":0.14,"price":0.61,"size":0.0,"side":"SELL"}
{"ts":"2026-08-24T20:47:52.449Z","event_type":"best_bid_ask","market_id":"3823659","outcome_index":0,"market_type":"match","local_side":"home","local_uid":"2026-08-24_victoria_jimenez_kasintseva_francisca_jorge","bid":0.35,"ask":0.37,"mid":0.36,"spread":0.02,"bid_size":null,"ask_size":null}
{"ts":"2026-08-24T20:47:52.449Z","event_type":"best_bid_ask","market_id":"3823659","outcome_index":1,"market_type":"match","local_side":"away","local_uid":"2026-08-24_victoria_jimenez_kasintseva_francisca_jorge","bid":0.63,"ask":0.65,"mid":0.64,"spread":0.02,"bid_size":null,"ask_size":null}
{"ts":"2026-08-24T20:47:52.450Z","event_type":"price_change","market_id":"3823659","outcome_index":1,"market_type":"match","local_side":"away","local_uid":"2026-08-24_victoria_jimenez_kasintseva_francisca_jorge","bid":0.63,"ask":0.65,"mid":0.64,"spread":0.02,"price":0.64,"size":0.0,"side":"BUY"}
{"ts":"2026-08-24T20:47:52.450Z","event_type":"price_change","market_id":"3823659","outcome_index":0,"market_type":"match","local_side":"home","local_uid":"2026-08-24_victoria_jimenez_kasintseva_francisca_jorge","bid":0.35,"ask":0.37,"mid":0.36,"spread":0.02,"price":0.36,"size":0.0,"side":"SELL"}
{"ts":"2026-08-24T20:47:52.451Z","event_type":"best_bid_ask","market_id":"3823659","outcome_index":0,"market_type":"match","local_side":"home","local_uid":"2026-08-24_victoria_jimenez_kasintseva_francisca_jorge","bid":0.36,"ask":0.37,"mid":0.365,"spread":0.01,"bid_size":null,"ask_size":null}
{"ts":"2026-08-24T20:47:52.452Z","event_type":"best_bid_ask","market_id":"3823659","outcome_index":1,"market_type":"match","local_side":"away","local_uid":"2026-08-24_victoria_jimenez_kasintseva_francisca_jorge","bid":0.63,"ask":0.64,"mid":0.635,"spread":0.01,"bid_size":null,"ask_size":null}
{"ts":"2026-08-24T20:47:52.452Z","event_type":"price_change","market_id":"3823659","outcome_index":0,"market_type":"match","local_side":"home","local_uid":"2026-08-24_victoria_jimenez_kasintseva_francisca_jorge","bid":0.36,"ask":0.37,"mid":0.365,"spread":0.01,"price":0.36,"size":20.0,"side":"BUY"}
{"ts":"2026-08-24T20:47:52.452Z","event_type":"price_change","market_id":"3823659","outcome_index":1,"market_type":"match","local_side":"away","local_uid":"2026-08-24_victoria_jimenez_kasintseva_francisca_jorge","bid":0.63,"ask":0.64,"mid":0.635,"spread":0.01,"price":0.64,"size":20.0,"side":"SELL"}
{"ts":"2026-08-24T20:47:52.483Z","event_type":"best_bid_ask","market_id":"3823659","outcome_index":0,"market_type":"match","local_side":"home","local_uid":"2026-08-24_victoria_jimenez_kasintseva_francisca_jorge","bid":0.36,"ask":0.38,"mid":0.37,"spread":0.02,"bid_size":null,"ask_size":null}
{"ts":"2026-08-24T20:47:52.484Z","event_type":"best_bid_ask","market_id":"3823659","outcome_index":1,"market_type":"match","local_side":"away","local_uid":"2026-08-24_victoria_jimenez_kasintseva_francisca_jorge","bid":0.62,"ask":0.64,"mid":0.63,"spread":0.02,"bid_size":null,"ask_size":null}
{"ts":"2026-08-24T20:47:52.484Z","event_type":"price_change","market_id":"3823659","outcome_index":1,"market_type":"match","local_side":"away","local_uid":"2026-08-24_victoria_jimenez_kasintseva_francisca_jorge","bid":0.62,"ask":0.64,"mid":0.63,"spread":0.02,"price":0.63,"size":0.0,"side":"BUY"}
{"ts":"2026-08-24T20:47:52.484Z","event_type":"price_change","market_id":"3823659","outcome_index":0,"market_type":"match","local_side":"home","local_uid":"2026-08-24_victoria_jimenez_kasintseva_francisca_jorge","bid":0.36,"ask":0.38,"mid":0.37,"spread":0.02,"price":0.37,"size":0.0,"side":"SELL"}
{"ts":"2026-08-24T20:47:52.579Z","event_type":"best_bid_ask","market_id":"3823659","outcome_index":0,"market_type":"match","local_side":"home","local_uid":"2026-08-24_victoria_jimenez_kasintseva_francisca_jorge","bid":0.36,"ask":0.37,"mid":0.365,"spread":0.01,"bid_size":null,"ask_size":null}
{"ts":"2026-08-24T20:47:52.580Z","event_type":"best_bid_ask","market_id":"3823659","outcome_index":1,"market_type":"match","local_side":"away","local_uid":"2026-08-24_victoria_jimenez_kasintseva_francisca_jorge","bid":0.63,"ask":0.64,"mid":0.635,"spread":0.01,"bid_size":null,"ask_size":null}
{"ts":"2026-08-24T20:47:52.580Z","event_type":"price_change","market_id":"3823659","outcome_index":1,"market_type":"match","local_side":"away","local_uid":"2026-08-24_victoria_jimenez_kasintseva_francisca_jorge","bid":0.63,"ask":0.64,"mid":0.635,"spread":0.01,"price":0.63,"size":40.0,"side":"BUY"}
{"ts":"2026-08-24T20:47:52.580Z","event_type":"price_change","market_id":"3823659","outcome_index":0,"market_type":"match","local_side":"home","local_uid":"2026-08-24_victoria_jimenez_kasintseva_francisca_jorge","bid":0.36,"ask":0.37,"mid":0.365,"spread":0.01,"price":0.37,"size":40.0,"side":"SELL"}
{"ts":"2026-08-24T20:47:52.596Z","event_type":"best_bid_ask","market_id":"3824796","outcome_index":0,"market_type":"set2","local_side":"home","local_uid":"2026-08-24_victoria_jimenez_kasintseva_francisca_jorge","bid":0.48,"ask":0.63,"mid":0.555,"spread":0.15,"bid_size":null,"ask_size":null}
{"ts":"2026-08-24T20:47:52.596Z","event_type":"best_bid_ask","market_id":"3824796","outcome_index":1,"market_type":"set2","local_side":"away","local_uid":"2026-08-24_victoria_jimenez_kasintseva_francisca_jorge","bid":0.37,"ask":0.52,"mid":0.445,"spread":0.15,"bid_size":null,"ask_size":null}
{"ts":"2026-08-24T20:47:52.597Z","event_type":"price_change","market_id":"3824796","outcome_index":1,"market_type":"set2","local_side":"away","local_uid":"2026-08-24_victoria_jimenez_kasintseva_francisca_jorge","bid":0.37,"ask":0.52,"mid":0.445,"spread":0.15,"price":0.38,"size":0.0,"side":"BUY"}
{"ts":"2026-08-24T20:47:52.597Z","event_type":"price_change","market_id":"3824796","outcome_index":0,"market_type":"set2","local_side":"home","local_uid":"2026-08-24_victoria_jimenez_kasintseva_francisca_jorge","bid":0.48,"ask":0.63,"mid":0.555,"spread":0.15,"price":0.62,"size":0.0,"side":"SELL"}
{"ts":"2026-08-24T20:47:52.612Z","event_type":"best_bid_ask","market_id":"3824796","outcome_index":0,"market_type":"set2","local_side":"home","local_uid":"2026-08-24_victoria_jimenez_kasintseva_francisca_jorge","bid":0.45,"ask":0.63,"mid":0.54,"spread":0.18,"bid_size":null,"ask_size":null}
{"ts":"2026-08-24T20:47:52.612Z","event_type":"best_bid_ask","market_id":"3824796","outcome_index":1,"market_type":"set2","local_side":"away","local_uid":"2026-08-24_victoria_jimenez_kasintseva_francisca_jorge","bid":0.37,"ask":0.55,"mid":0.46,"spread":0.18,"bid_size":null,"ask_size":null}
{"ts":"2026-08-24T20:47:52.613Z","event_type":"price_change","market_id":"3824796","outcome_index":0,"market_type":"set2","local_side":"home","local_uid":"2026-08-24_victoria_jimenez_kasintseva_francisca_jorge","bid":0.45,"ask":0.63,"mid":0.54,"spread":0.18,"price":0.48,"size":0.0,"side":"BUY"}
{"ts":"2026-08-24T20:47:52.613Z","event_type":"price_change","market_id":"3824796","outcome_index":1,"market_type":"set2","local_side":"away","local_uid":"2026-08-24_victoria_jimenez_kasintseva_francisca_jorge","bid":0.37,"ask":0.55,"mid":0.46,"spread":0.18,"price":0.52,"size":0.0,"side":"SELL"}
{"ts":"2026-08-24T20:47:52.637Z","event_type":"best_bid_ask","market_id":"3823659","outcome_index":0,"market_type":"match","local_side":"home","local_uid":"2026-08-24_victoria_jimenez_kasintseva_francisca_jorge","bid":0.36,"ask":0.38,"mid":0.37,"spread":0.02,"bid_size":null,"ask_size":null}
{"ts":"2026-08-24T20:47:52.637Z","event_type":"best_bid_ask","market_id":"3823659","outcome_index":1,"market_type":"match","local_side":"away","local_uid":"2026-08-24_victoria_jimenez_kasintseva_francisca_jorge","bid":0.62,"ask":0.64,"mid":0.63,"spread":0.02,"bid_size":null,"ask_size":null}
{"ts":"2026-08-24T20:47:52.638Z","event_type":"price_change","market_id":"3823659","outcome_index":1,"market_type":"match","local_side":"away","local_uid":"2026-08-24_victoria_jimenez_kasintseva_francisca_jorge","bid":0.62,"ask":0.64,"mid":0.63,"spread":0.02,"price":0.63,"size":0.0,"side":"BUY"}
{"ts":"2026-08-24T20:47:52.638Z","event_type":"price_change","market_id":"3823659","outcome_index":0,"market_type":"match","local_side":"home","local_uid":"2026-08-24_victoria_jimenez_kasintseva_francisca_jorge","bid":0.36,"ask":0.38,"mid":0.37,"spread":0.02,"price":0.37,"size":0.0,"side":"SELL"}
{"ts":"2026-08-24T20:47:52.694Z","event_type":"price_change","market_id":"3825592","outcome_index":0,"market_type":"match","local_side":"home","local_uid":"2026-08-24_francesco_passaro_felix_gill","bid":0.54,"ask":0.55,"mid":0.545,"spread":0.01,"price":0.44,"size":7610.81,"side":"BUY"}
{"ts":"2026-08-24T20:47:52.694Z","event_type":"price_change","market_id":"3825592","outcome_index":1,"market_type":"match","local_side":"away","local_uid":"2026-08-24_francesco_passaro_felix_gill","bid":0.45,"ask":0.46,"mid":0.455,"spread":0.01,"price":0.56,"size":7610.81,"side":"SELL"}
{"ts":"2026-08-24T20:47:52.716Z","event_type":"best_bid_ask","market_id":"3825604","outcome_index":0,"market_type":"match","local_side":"home","local_uid":"2026-08-24_dalibor_svrcina_felipe_meligeni_alves","bid":0.78,"ask":0.84,"mid":0.81,"spread":0.06,"bid_size":null,"ask_size":null}
{"ts":"2026-08-24T20:47:52.716Z","event_type":"best_bid_ask","market_id":"3825604","outcome_index":1,"market_type":"match","local_side":"away","local_uid":"2026-08-24_dalibor_svrcina_felipe_meligeni_alves","bid":0.16,"ask":0.22,"mid":0.19,"spread":0.06,"bid_size":null,"ask_size":null}
{"ts":"2026-08-24T20:47:52.716Z","event_type":"price_change","market_id":"3825604","outcome_index":1,"market_type":"match","local_side":"away","local_uid":"2026-08-24_dalibor_svrcina_felipe_meligeni_alves","bid":0.16,"ask":0.22,"mid":0.19,"spread":0.06,"price":0.17,"size":0.0,"side":"BUY"}
{"ts":"2026-08-24T20:47:52.716Z","event_type":"price_change","market_id":"3825604","outcome_index":0,"market_type":"match","local_side":"home","local_uid":"2026-08-24_dalibor_svrcina_felipe_meligeni_alves","bid":0.78,"ask":0.84,"mid":0.81,"spread":0.06,"price":0.83,"size":0.0,"side":"SELL"}
{"ts":"2026-08-24T20:47:52.770Z","event_type":"best_bid_ask","market_id":"3825604","outcome_index":0,"market_type":"match","local_side":"home","local_uid":"2026-08-24_dalibor_svrcina_felipe_meligeni_alves","bid":0.78,"ask":0.85,"mid":0.815,"spread":0.07,"bid_size":null,"ask_size":null}
{"ts":"2026-08-24T20:47:52.770Z","event_type":"best_bid_ask","market_id":"3825604","outcome_index":1,"market_type":"match","local_side":"away","local_uid":"2026-08-24_dalibor_svrcina_felipe_meligeni_alves","bid":0.15,"ask":0.22,"mid":0.185,"spread":0.07,"bid_size":null,"ask_size":null}
{"ts":"2026-08-24T20:47:52.770Z","event_type":"price_change","market_id":"3825604","outcome_index":1,"market_type":"match","local_side":"away","local_uid":"2026-08-24_dalibor_svrcina_felipe_meligeni_alves","bid":0.15,"ask":0.22,"mid":0.185,"spread":0.07,"price":0.16,"size":0.0,"side":"BUY"}
{"ts":"2026-08-24T20:47:52.771Z","event_type":"price_change","market_id":"3825604","outcome_index":0,"market_type":"match","local_side":"home","local_uid":"2026-08-24_dalibor_svrcina_felipe_meligeni_alves","bid":0.78,"ask":0.85,"mid":0.815,"spread":0.07,"price":0.84,"size":0.0,"side":"SELL"}
{"ts":"2026-08-24T20:47:53.104Z","event_type":"best_bid_ask","market_id":"3825608","outcome_index":0,"market_type":"match","local_side":"home","local_uid":"2026-08-24_raul_brancaccio_thiago_seyboth_wild","bid":0.22,"ask":0.24,"mid":0.23,"spread":0.02,"bid_size":null,"ask_size":null}
{"ts":"2026-08-24T20:47:53.105Z","event_type":"best_bid_ask","market_id":"3825608","outcome_index":1,"market_type":"match","local_side":"away","local_uid":"2026-08-24_raul_brancaccio_thiago_seyboth_wild","bid":0.76,"ask":0.78,"mid":0.77,"spread":0.02,"bid_size":null,"ask_size":null}
{"ts":"2026-08-24T20:47:53.105Z","event_type":"price_change","market_id":"3825608","outcome_index":1,"market_type":"match","local_side":"away","local_uid":"2026-08-24_raul_brancaccio_thiago_seyboth_wild","bid":0.76,"ask":0.78,"mid":0.77,"spread":0.02,"price":0.77,"size":0.0,"side":"BUY"}
{"ts":"2026-08-24T20:47:53.105Z","event_type":"price_change","market_id":"3825608","outcome_index":0,"market_type":"match","local_side":"home","local_uid":"2026-08-24_raul_brancaccio_thiago_seyboth_wild","bid":0.22,"ask":0.24,"mid":0.23,"spread":0.02,"price":0.23,"size":0.0,"side":"SELL"}
{"ts":"2026-08-24T20:47:53.144Z","event_type":"price_change","market_id":"3825631","outcome_index":1,"market_type":"match","local_side":"away","local_uid":"2026-08-24_harry_wendelken_stefano_travaglia","bid":0.35,"ask":0.36,"mid":0.355,"spread":0.01,"price":0.27,"size":17378.0,"side":"BUY"}
{"ts":"2026-08-24T20:47:53.144Z","event_type":"price_change","market_id":"3825631","outcome_index":0,"market_type":"match","local_side":"home","local_uid":"2026-08-24_harry_wendelken_stefano_travaglia","bid":0.64,"ask":0.65,"mid":0.645,"spread":0.01,"price":0.73,"size":17378.0,"side":"SELL"}
{"ts":"2026-08-24T20:47:53.154Z","event_type":"best_bid_ask","market_id":"3824796","outcome_index":0,"market_type":"set2","local_side":"home","local_uid":"2026-08-24_victoria_jimenez_kasintseva_francisca_jorge","bid":0.45,"ask":0.64,"mid":0.545,"spread":0.19,"bid_size":null,"ask_size":null}
{"ts":"2026-08-24T20:47:53.154Z","event_type":"best_bid_ask","market_id":"3824796","outcome_index":1,"market_type":"set2","local_side":"away","local_uid":"2026-08-24_victoria_jimenez_kasintseva_francisca_jorge","bid":0.36,"ask":0.55,"mid":0.455,"spread":0.19,"bid_size":null,"ask_size":null}
{"ts":"2026-08-24T20:47:53.155Z","event_type":"price_change","market_id":"3824796","outcome_index":1,"market_type":"set2","local_side":"away","local_uid":"2026-08-24_victoria_jimenez_kasintseva_francisca_jorge","bid":0.36,"ask":0.55,"mid":0.455,"spread":0.19,"price":0.37,"size":0.0,"side":"BUY"}
{"ts":"2026-08-24T20:47:53.155Z","event_type":"price_change","market_id":"3824796","outcome_index":0,"market_type":"set2","local_side":"home","local_uid":"2026-08-24_victoria_jimenez_kasintseva_francisca_jorge","bid":0.45,"ask":0.64,"mid":0.545,"spread":0.19,"price":0.63,"size":0.0,"side":"SELL"}
{"ts":"2026-08-24T20:47:53.156Z","event_type":"best_bid_ask","market_id":"3824796","outcome_index":0,"market_type":"set2","local_side":"home","local_uid":"2026-08-24_victoria_jimenez_kasintseva_francisca_jorge","bid":0.45,"ask":0.65,"mid":0.55,"spread":0.2,"bid_size":null,"ask_size":null}
{"ts":"2026-08-24T20:47:53.156Z","event_type":"best_bid_ask","market_id":"3824796","outcome_index":1,"market_type":"set2","local_side":"away","local_uid":"2026-08-24_victoria_jimenez_kasintseva_francisca_jorge","bid":0.35,"ask":0.55,"mid":0.45,"spread":0.2,"bid_size":null,"ask_size":null}
{"ts":"2026-08-24T20:47:53.157Z","event_type":"price_change","market_id":"3824796","outcome_index":1,"market_type":"set2","local_side":"away","local_uid":"2026-08-24_victoria_jimenez_kasintseva_francisca_jorge","bid":0.35,"ask":0.55,"mid":0.45,"spread":0.2,"price":0.36,"size":0.0,"side":"BUY"}
{"ts":"2026-08-24T20:47:53.157Z","event_type":"price_change","market_id":"3824796","outcome_index":0,"market_type":"set2","local_side":"home","local_uid":"2026-08-24_victoria_jimenez_kasintseva_francisca_jorge","bid":0.45,"ask":0.65,"mid":0.55,"spread":0.2,"price":0.64,"size":0.0,"side":"SELL"}
{"ts":"2026-08-24T20:47:53.203Z","event_type":"best_bid_ask","market_id":"3825604","outcome_index":0,"market_type":"match","local_side":"home","local_uid":"2026-08-24_dalibor_svrcina_felipe_meligeni_alves","bid":0.78,"ask":0.83,"mid":0.805,"spread":0.05,"bid_size":null,"ask_size":null}
{"ts":"2026-08-24T20:47:53.203Z","event_type":"best_bid_ask","market_id":"3825604","outcome_index":1,"market_type":"match","local_side":"away","local_uid":"2026-08-24_dalibor_svrcina_felipe_meligeni_alves","bid":0.17,"ask":0.22,"mid":0.195,"spread":0.05,"bid_size":null,"ask_size":null}
{"ts":"2026-08-24T20:47:53.204Z","event_type":"price_change","market_id":"3825604","outcome_index":1,"market_type":"match","local_side":"away","local_uid":"2026-08-24_dalibor_svrcina_felipe_meligeni_alves","bid":0.17,"ask":0.22,"mid":0.195,"spread":0.05,"price":0.17,"size":100.0,"side":"BUY"}
{"ts":"2026-08-24T20:47:53.204Z","event_type":"price_change","market_id":"3825604","outcome_index":0,"market_type":"match","local_side":"home","local_uid":"2026-08-24_dalibor_svrcina_felipe_meligeni_alves","bid":0.78,"ask":0.83,"mid":0.805,"spread":0.05,"price":0.83,"size":100.0,"side":"SELL"}
{"ts":"2026-08-24T20:47:53.212Z","event_type":"best_bid_ask","market_id":"3824796","outcome_index":0,"market_type":"set2","local_side":"home","local_uid":"2026-08-24_victoria_jimenez_kasintseva_francisca_jorge","bid":0.45,"ask":0.67,"mid":0.56,"spread":0.22,"bid_size":null,"ask_size":null}
{"ts":"2026-08-24T20:47:53.213Z","event_type":"best_bid_ask","market_id":"3824796","outcome_index":1,"market_type":"set2","local_side":"away","local_uid":"2026-08-24_victoria_jimenez_kasintseva_francisca_jorge","bid":0.33,"ask":0.55,"mid":0.44,"spread":0.22,"bid_size":null,"ask_size":null}
{"ts":"2026-08-24T20:47:53.213Z","event_type":"price_change","market_id":"3824796","outcome_index":1,"market_type":"set2","local_side":"away","local_uid":"2026-08-24_victoria_jimenez_kasintseva_francisca_jorge","bid":0.33,"ask":0.55,"mid":0.44,"spread":0.22,"price":0.35,"size":0.0,"side":"BUY"}
{"ts":"2026-08-24T20:47:53.213Z","event_type":"price_change","market_id":"3824796","outcome_index":0,"market_type":"set2","local_side":"home","local_uid":"2026-08-24_victoria_jimenez_kasintseva_francisca_jorge","bid":0.45,"ask":0.67,"mid":0.56,"spread":0.22,"price":0.65,"size":0.0,"side":"SELL"}
{"ts":"2026-08-24T20:47:53.225Z","event_type":"price_change","market_id":"3825570","outcome_index":0,"market_type":"match","local_side":"home","local_uid":"2026-08-24_jenson_brooksby_stefanos_tsitsipas","bid":0.42,"ask":0.43,"mid":0.425,"spread":0.01,"price":0.38,"size":10773.52,"side":"BUY"}
{"ts":"2026-08-24T20:47:53.225Z","event_type":"price_change","market_id":"3825570","outcome_index":1,"market_type":"match","local_side":"away","local_uid":"2026-08-24_jenson_brooksby_stefanos_tsitsipas","bid":0.57,"ask":0.58,"mid":0.575,"spread":0.01,"price":0.62,"size":10773.52,"side":"SELL"}
{"ts":"2026-08-24T20:47:53.271Z","event_type":"best_bid_ask","market_id":"3825604","outcome_index":0,"market_type":"match","local_side":"home","local_uid":"2026-08-24_dalibor_svrcina_felipe_meligeni_alves","bid":0.78,"ask":0.84,"mid":0.81,"spread":0.06,"bid_size":null,"ask_size":null}
{"ts":"2026-08-24T20:47:53.272Z","event_type":"best_bid_ask","market_id":"3825604","outcome_index":1,"market_type":"match","local_side":"away","local_uid":"2026-08-24_dalibor_svrcina_felipe_meligeni_alves","bid":0.16,"ask":0.22,"mid":0.19,"spread":0.06,"bid_size":null,"ask_size":null}
{"ts":"2026-08-24T20:47:53.272Z","event_type":"price_change","market_id":"3825604","outcome_index":1,"market_type":"match","local_side":"away","local_uid":"2026-08-24_dalibor_svrcina_felipe_meligeni_alves","bid":0.16,"ask":0.22,"mid":0.19,"spread":0.06,"price":0.17,"size":0.0,"side":"BUY"}
{"ts":"2026-08-24T20:47:53.272Z","event_type":"price_change","market_id":"3825604","outcome_index":0,"market_type":"match","local_side":"home","local_uid":"2026-08-24_dalibor_svrcina_felipe_meligeni_alves","bid":0.78,"ask":0.84,"mid":0.81,"spread":0.06,"price":0.83,"size":0.0,"side":"SELL"}
{"ts":"2026-08-24T20:47:53.273Z","event_type":"best_bid_ask","market_id":"3825604","outcome_index":0,"market_type":"match","local_side":"home","local_uid":"2026-08-24_dalibor_svrcina_felipe_meligeni_alves","bid":0.78,"ask":0.83,"mid":0.805,"spread":0.05,"bid_size":null,"ask_size":null}
{"ts":"2026-08-24T20:47:53.273Z","event_type":"best_bid_ask","market_id":"3825604","outcome_index":1,"market_type":"match","local_side":"away","local_uid":"2026-08-24_dalibor_svrcina_felipe_meligeni_alves","bid":0.17,"ask":0.22,"mid":0.195,"spread":0.05,"bid_size":null,"ask_size":null}
{"ts":"2026-08-24T20:47:53.274Z","event_type":"price_change","market_id":"3825604","outcome_index":1,"market_type":"match","local_side":"away","local_uid":"2026-08-24_dalibor_svrcina_felipe_meligeni_alves","bid":0.17,"ask":0.22,"mid":0.195,"spread":0.05,"price":0.17,"size":14.0,"side":"BUY"}
{"ts":"2026-08-24T20:47:53.274Z","event_type":"price_change","market_id":"3825604","outcome_index":0,"market_type":"match","local_side":"home","local_uid":"2026-08-24_dalibor_svrcina_felipe_meligeni_alves","bid":0.78,"ask":0.83,"mid":0.805,"spread":0.05,"price":0.83,"size":14.0,"side":"SELL"}
{"ts":"2026-08-24T20:47:53.438Z","event_type":"price_change","market_id":"3827165","outcome_index":0,"market_type":"set2","local_side":"home","local_uid":"2026-08-24_jenson_brooksby_stefanos_tsitsipas","bid":0.39,"ask":0.48,"mid":0.435,"spread":0.09,"price":0.39,"size":2423.0,"side":"BUY"}
{"ts":"2026-08-24T20:47:53.438Z","event_type":"price_change","market_id":"3827165","outcome_index":1,"market_type":"set2","local_side":"away","local_uid":"2026-08-24_jenson_brooksby_stefanos_tsitsipas","bid":0.52,"ask":0.61,"mid":0.565,"spread":0.09,"price":0.61,"size":2423.0,"side":"SELL"}
{"ts":"2026-08-24T20:47:53.689Z","event_type":"price_change","market_id":"3826161","outcome_index":1,"market_type":"set2","local_side":"away","local_uid":"2026-08-24_daniel_altmaier_francisco_comesana","bid":0.49,"ask":0.52,"mid":0.505,"spread":0.03,"price":0.46,"size":3402.24,"side":"BUY"}
{"ts":"2026-08-24T20:47:53.690Z","event_type":"price_change","market_id":"3826161","outcome_index":0,"market_type":"set2","local_side":"home","local_uid":"2026-08-24_daniel_altmaier_francisco_comesana","bid":0.48,"ask":0.51,"mid":0.495,"spread":0.03,"price":0.54,"size":3402.24,"side":"SELL"}
{"ts":"2026-08-24T20:47:53.724Z","event_type":"best_bid_ask","market_id":"3823659","outcome_index":0,"market_type":"match","local_side":"home","local_uid":"2026-08-24_victoria_jimenez_kasintseva_francisca_jorge","bid":0.36,"ask":0.37,"mid":0.365,"spread":0.01,"bid_size":null,"ask_size":null}
{"ts":"2026-08-24T20:47:53.724Z","event_type":"best_bid_ask","market_id":"3823659","outcome_index":1,"market_type":"match","local_side":"away","local_uid":"2026-08-24_victoria_jimenez_kasintseva_francisca_jorge","bid":0.63,"ask":0.64,"mid":0.635,"spread":0.01,"bid_size":null,"ask_size":null}
{"ts":"2026-08-24T20:47:53.724Z","event_type":"price_change","market_id":"3823659","outcome_index":1,"market_type":"match","local_side":"away","local_uid":"2026-08-24_victoria_jimenez_kasintseva_francisca_jorge","bid":0.63,"ask":0.64,"mid":0.635,"spread":0.01,"price":0.63,"size":870.0,"side":"BUY"}
{"ts":"2026-08-24T20:47:53.725Z","event_type":"price_change","market_id":"3823659","outcome_index":0,"market_type":"match","local_side":"home","local_uid":"2026-08-24_victoria_jimenez_kasintseva_francisca_jorge","bid":0.36,"ask":0.37,"mid":0.365,"spread":0.01,"price":0.37,"size":870.0,"side":"SELL"}
{"ts":"2026-08-24T20:47:54.192Z","event_type":"best_bid_ask","market_id":"3825077","outcome_index":0,"market_type":"set1","local_side":"home","local_uid":"2026-08-24_polina_kudermetova_linda_fruhvirtova","bid":0.45,"ask":0.54,"mid":0.495,"spread":0.09,"bid_size":null,"ask_size":null}
{"ts":"2026-08-24T20:47:54.192Z","event_type":"best_bid_ask","market_id":"3825077","outcome_index":1,"market_type":"set1","local_side":"away","local_uid":"2026-08-24_polina_kudermetova_linda_fruhvirtova","bid":0.46,"ask":0.55,"mid":0.505,"spread":0.09,"bid_size":null,"ask_size":null}
{"ts":"2026-08-24T20:47:54.193Z","event_type":"price_change","market_id":"3825077","outcome_index":1,"market_type":"set1","local_side":"away","local_uid":"2026-08-24_polina_kudermetova_linda_fruhvirtova","bid":0.46,"ask":0.55,"mid":0.505,"spread":0.09,"price":0.46,"size":88.0,"side":"BUY"}
{"ts":"2026-08-24T20:47:54.193Z","event_type":"price_change","market_id":"3825077","outcome_index":0,"market_type":"set1","local_side":"home","local_uid":"2026-08-24_polina_kudermetova_linda_fruhvirtova","bid":0.45,"ask":0.54,"mid":0.495,"spread":0.09,"price":0.54,"size":88.0,"side":"SELL"}
{"ts":"2026-08-24T20:47:54.198Z","event_type":"best_bid_ask","market_id":"3825077","outcome_index":0,"market_type":"set1","local_side":"home","local_uid":"2026-08-24_polina_kudermetova_linda_fruhvirtova","bid":0.45,"ask":0.53,"mid":0.49,"spread":0.08,"bid_size":null,"ask_size":null}
{"ts":"2026-08-24T20:47:54.198Z","event_type":"best_bid_ask","market_id":"3825077","outcome_index":1,"market_type":"set1","local_side":"away","local_uid":"2026-08-24_polina_kudermetova_linda_fruhvirtova","bid":0.47,"ask":0.55,"mid":0.51,"spread":0.08,"bid_size":null,"ask_size":null}
{"ts":"2026-08-24T20:47:54.198Z","event_type":"price_change","market_id":"3825077","outcome_index":1,"market_type":"set1","local_side":"away","local_uid":"2026-08-24_polina_kudermetova_linda_fruhvirtova","bid":0.47,"ask":0.55,"mid":0.51,"spread":0.08,"price":0.47,"size":1693.0,"side":"BUY"}
{"ts":"2026-08-24T20:47:54.198Z","event_type":"price_change","market_id":"3825077","outcome_index":0,"market_type":"set1","local_side":"home","local_uid":"2026-08-24_polina_kudermetova_linda_fruhvirtova","bid":0.45,"ask":0.53,"mid":0.49,"spread":0.08,"price":0.53,"size":1693.0,"side":"SELL"}
{"ts":"2026-08-24T20:47:54.218Z","event_type":"best_bid_ask","market_id":"3825604","outcome_index":0,"market_type":"match","local_side":"home","local_uid":"2026-08-24_dalibor_svrcina_felipe_meligeni_alves","bid":0.78,"ask":0.84,"mid":0.81,"spread":0.06,"bid_size":null,"ask_size":null}
{"ts":"2026-08-24T20:47:54.219Z","event_type":"best_bid_ask","market_id":"3825604","outcome_index":1,"market_type":"match","local_side":"away","local_uid":"2026-08-24_dalibor_svrcina_felipe_meligeni_alves","bid":0.16,"ask":0.22,"mid":0.19,"spread":0.06,"bid_size":null,"ask_size":null}
{"ts":"2026-08-24T20:47:54.219Z","event_type":"price_change","market_id":"3825604","outcome_index":1,"market_type":"match","local_side":"away","local_uid":"2026-08-24_dalibor_svrcina_felipe_meligeni_alves","bid":0.16,"ask":0.22,"mid":0.19,"spread":0.06,"price":0.17,"size":0.0,"side":"BUY"}
{"ts":"2026-08-24T20:47:54.219Z","event_type":"price_change","market_id":"3825604","outcome_index":0,"market_type":"match","local_side":"home","local_uid":"2026-08-24_dalibor_svrcina_felipe_meligeni_alves","bid":0.78,"ask":0.84,"mid":0.81,"spread":0.06,"price":0.83,"size":0.0,"side":"SELL"}
{"ts":"2026-08-24T20:47:54.266Z","event_type":"best_bid_ask","market_id":"3823659","outcome_index":0,"market_type":"match","local_side":"home","local_uid":"2026-08-24_victoria_jimenez_kasintseva_francisca_jorge","bid":0.34,"ask":0.37,"mid":0.355,"spread":0.03,"bid_size":null,"ask_size":null}
{"ts":"2026-08-24T20:47:54.266Z","event_type":"best_bid_ask","market_id":"3823659","outcome_index":1,"market_type":"match","local_side":"away","local_uid":"2026-08-24_victoria_jimenez_kasintseva_francisca_jorge","bid":0.63,"ask":0.66,"mid":0.645,"spread":0.03,"bid_size":null,"ask_size":null}
{"ts":"2026-08-24T20:47:54.267Z","event_type":"price_change","market_id":"3823659","outcome_index":0,"market_type":"match","local_side":"home","local_uid":"2026-08-24_victoria_jimenez_kasintseva_francisca_jorge","bid":0.34,"ask":0.37,"mid":0.355,"spread":0.03,"price":0.36,"size":0.0,"side":"BUY"}
{"ts":"2026-08-24T20:47:54.267Z","event_type":"price_change","market_id":"3823659","outcome_index":1,"market_type":"match","local_side":"away","local_uid":"2026-08-24_victoria_jimenez_kasintseva_francisca_jorge","bid":0.63,"ask":0.66,"mid":0.645,"spread":0.03,"price":0.64,"size":0.0,"side":"SELL"}
{"ts":"2026-08-24T20:47:54.268Z","event_type":"best_bid_ask","market_id":"3823659","outcome_index":0,"market_type":"match","local_side":"home","local_uid":"2026-08-24_victoria_jimenez_kasintseva_francisca_jorge","bid":0.35,"ask":0.37,"mid":0.36,"spread":0.02,"bid_size":null,"ask_size":null}
{"ts":"2026-08-24T20:47:54.269Z","event_type":"best_bid_ask","market_id":"3823659","outcome_index":1,"market_type":"match","local_side":"away","local_uid":"2026-08-24_victoria_jimenez_kasintseva_francisca_jorge","bid":0.63,"ask":0.65,"mid":0.64,"spread":0.02,"bid_size":null,"ask_size":null}
{"ts":"2026-08-24T20:47:54.269Z","event_type":"price_change","market_id":"3823659","outcome_index":0,"market_type":"match","local_side":"home","local_uid":"2026-08-24_victoria_jimenez_kasintseva_francisca_jorge","bid":0.35,"ask":0.37,"mid":0.36,"spread":0.02,"price":0.35,"size":20.0,"side":"BUY"}
{"ts":"2026-08-24T20:47:54.269Z","event_type":"price_change","market_id":"3823659","outcome_index":1,"market_type":"match","local_side":"away","local_uid":"2026-08-24_victoria_jimenez_kasintseva_francisca_jorge","bid":0.63,"ask":0.65,"mid":0.64,"spread":0.02,"price":0.65,"size":20.0,"side":"SELL"}
{"ts":"2026-08-24T20:47:54.389Z","event_type":"best_bid_ask","market_id":"3825077","outcome_index":0,"market_type":"set1","local_side":"home","local_uid":"2026-08-24_polina_kudermetova_linda_fruhvirtova","bid":0.45,"ask":0.52,"mid":0.485,"spread":0.07,"bid_size":null,"ask_size":null}
{"ts":"2026-08-24T20:47:54.390Z","event_type":"best_bid_ask","market_id":"3825077","outcome_index":1,"market_type":"set1","local_side":"away","local_uid":"2026-08-24_polina_kudermetova_linda_fruhvirtova","bid":0.48,"ask":0.55,"mid":0.515,"spread":0.07,"bid_size":null,"ask_size":null}
{"ts":"2026-08-24T20:47:54.391Z","event_type":"price_change","market_id":"3825077","outcome_index":1,"market_type":"set1","local_side":"away","local_uid":"2026-08-24_polina_kudermetova_linda_fruhvirtova","bid":0.48,"ask":0.55,"mid":0.515,"spread":0.07,"price":0.48,"size":73.8,"side":"BUY"}
{"ts":"2026-08-24T20:47:54.391Z","event_type":"price_change","market_id":"3825077","outcome_index":0,"market_type":"set1","local_side":"home","local_uid":"2026-08-24_polina_kudermetova_linda_fruhvirtova","bid":0.45,"ask":0.52,"mid":0.485,"spread":0.07,"price":0.52,"size":73.8,"side":"SELL"}
{"ts":"2026-08-24T20:47:54.417Z","event_type":"best_bid_ask","market_id":"3823619","outcome_index":0,"market_type":"match","local_side":"home","local_uid":"2026-08-24_polina_kudermetova_linda_fruhvirtova","bid":0.55,"ask":0.57,"mid":0.56,"spread":0.02,"bid_size":null,"ask_size":null}
{"ts":"2026-08-24T20:47:54.417Z","event_type":"best_bid_ask","market_id":"3823619","outcome_index":1,"market_type":"match","local_side":"away","local_uid":"2026-08-24_polina_kudermetova_linda_fruhvirtova","bid":0.43,"ask":0.45,"mid":0.44,"spread":0.02,"bid_size":null,"ask_size":null}
{"ts":"2026-08-24T20:47:54.418Z","event_type":"price_change","market_id":"3823619","outcome_index":1,"market_type":"match","local_side":"away","local_uid":"2026-08-24_polina_kudermetova_linda_fruhvirtova","bid":0.43,"ask":0.45,"mid":0.44,"spread":0.02,"price":0.43,"size":50.0,"side":"BUY"}
{"ts":"2026-08-24T20:47:54.418Z","event_type":"price_change","market_id":"3823619","outcome_index":0,"market_type":"match","local_side":"home","local_uid":"2026-08-24_polina_kudermetova_linda_fruhvirtova","bid":0.55,"ask":0.57,"mid":0.56,"spread":0.02,"price":0.57,"size":50.0,"side":"SELL"}
{"ts":"2026-08-24T20:47:54.459Z","event_type":"best_bid_ask","market_id":"3825070","outcome_index":0,"market_type":"set2","local_side":"home","local_uid":"2026-08-24_polina_kudermetova_linda_fruhvirtova","bid":0.53,"ask":0.62,"mid":0.575,"spread":0.09,"bid_size":null,"ask_size":null}
{"ts":"2026-08-24T20:47:54.460Z","event_type":"best_bid_ask","market_id":"3825070","outcome_index":1,"market_type":"set2","local_side":"away","local_uid":"2026-08-24_polina_kudermetova_linda_fruhvirtova","bid":0.38,"ask":0.47,"mid":0.425,"spread":0.09,"bid_size":null,"ask_size":null}
{"ts":"2026-08-24T20:47:54.460Z","event_type":"price_change","market_id":"3825070","outcome_index":0,"market_type":"set2","local_side":"home","local_uid":"2026-08-24_polina_kudermetova_linda_fruhvirtova","bid":0.53,"ask":0.62,"mid":0.575,"spread":0.09,"price":0.53,"size":49.69,"side":"BUY"}
{"ts":"2026-08-24T20:47:54.460Z","event_type":"price_change","market_id":"3825070","outcome_index":1,"market_type":"set2","local_side":"away","local_uid":"2026-08-24_polina_kudermetova_linda_fruhvirtova","bid":0.38,"ask":0.47,"mid":0.425,"spread":0.09,"price":0.47,"size":49.69,"side":"SELL"}
{"ts":"2026-08-24T20:47:54.480Z","event_type":"price_change","market_id":"3824875","outcome_index":0,"market_type":"set2","local_side":"home","local_uid":"2026-08-24_eva_vedder_bianca_andreescu","bid":0.21,"ask":0.25,"mid":0.23,"spread":0.04,"price":0.2,"size":70.4,"side":"BUY"}
{"ts":"2026-08-24T20:47:54.481Z","event_type":"price_change","market_id":"3824875","outcome_index":1,"market_type":"set2","local_side":"away","local_uid":"2026-08-24_eva_vedder_bianca_andreescu","bid":0.75,"ask":0.79,"mid":0.77,"spread":0.04,"price":0.8,"size":70.4,"side":"SELL"}
{"ts":"2026-08-24T20:47:54.500Z","event_type":"best_bid_ask","market_id":"3825070","outcome_index":0,"market_type":"set2","local_side":"home","local_uid":"2026-08-24_polina_kudermetova_linda_fruhvirtova","bid":0.53,"ask":0.61,"mid":0.57,"spread":0.08,"bid_size":null,"ask_size":null}
{"ts":"2026-08-24T20:47:54.501Z","event_type":"best_bid_ask","market_id":"3825070","outcome_index":1,"market_type":"set2","local_side":"away","local_uid":"2026-08-24_polina_kudermetova_linda_fruhvirtova","bid":0.39,"ask":0.47,"mid":0.43,"spread":0.08,"bid_size":null,"ask_size":null}
{"ts":"2026-08-24T20:47:54.501Z","event_type":"price_change","market_id":"3825070","outcome_index":1,"market_type":"set2","local_side":"away","local_uid":"2026-08-24_polina_kudermetova_linda_fruhvirtova","bid":0.39,"ask":0.47,"mid":0.43,"spread":0.08,"price":0.39,"size":6.41,"side":"BUY"}
{"ts":"2026-08-24T20:47:54.501Z","event_type":"price_change","market_id":"3825070","outcome_index":0,"market_type":"set2","local_side":"home","local_uid":"2026-08-24_polina_kudermetova_linda_fruhvirtova","bid":0.53,"ask":0.61,"mid":0.57,"spread":0.08,"price":0.61,"size":6.41,"side":"SELL"}
{"ts":"2026-08-24T20:47:54.550Z","event_type":"best_bid_ask","market_id":"3823623","outcome_index":0,"market_type":"match","local_side":"home","local_uid":"2026-08-24_robin_montgomery_kayla_cross","bid":0.87,"ask":0.89,"mid":0.88,"spread":0.02,"bid_size":null,"ask_size":null}
{"ts":"2026-08-24T20:47:54.551Z","event_type":"best_bid_ask","market_id":"3823623","outcome_index":1,"market_type":"match","local_side":"away","local_uid":"2026-08-24_robin_montgomery_kayla_cross","bid":0.11,"ask":0.13,"mid":0.12,"spread":0.02,"bid_size":null,"ask_size":null}
{"ts":"2026-08-24T20:47:54.551Z","event_type":"price_change","market_id":"3823623","outcome_index":1,"market_type":"match","local_side":"away","local_uid":"2026-08-24_robin_montgomery_kayla_cross","bid":0.11,"ask":0.13,"mid":0.12,"spread":0.02,"price":0.12,"size":0.0,"side":"BUY"}
{"ts":"2026-08-24T20:47:54.551Z","event_type":"price_change","market_id":"3823623","outcome_index":0,"market_type":"match","local_side":"home","local_uid":"2026-08-24_robin_montgomery_kayla_cross","bid":0.87,"ask":0.89,"mid":0.88,"spread":0.02,"price":0.88,"size":0.0,"side":"SELL"}
{"ts":"2026-08-24T20:47:54.590Z","event_type":"best_bid_ask","market_id":"3823659","outcome_index":0,"market_type":"match","local_side":"home","local_uid":"2026-08-24_victoria_jimenez_kasintseva_francisca_jorge","bid":0.33,"ask":0.37,"mid":0.35,"spread":0.04,"bid_size":null,"ask_size":null}
{"ts":"2026-08-24T20:47:54.590Z","event_type":"best_bid_ask","market_id":"3823659","outcome_index":1,"market_type":"match","local_side":"away","local_uid":"2026-08-24_victoria_jimenez_kasintseva_francisca_jorge","bid":0.63,"ask":0.67,"mid":0.65,"spread":0.04,"bid_size":null,"ask_size":null}
{"ts":"2026-08-24T20:47:54.591Z","event_type":"price_change","market_id":"3823659","outcome_index":0,"market_type":"match","local_side":"home","local_uid":"2026-08-24_victoria_jimenez_kasintseva_francisca_jorge","bid":0.33,"ask":0.37,"mid":0.35,"spread":0.04,"price":0.35,"size":0.0,"side":"BUY"}
{"ts":"2026-08-24T20:47:54.591Z","event_type":"price_change","market_id":"3823659","outcome_index":1,"market_type":"match","local_side":"away","local_uid":"2026-08-24_victoria_jimenez_kasintseva_francisca_jorge","bid":0.63,"ask":0.67,"mid":0.65,"spread":0.04,"price":0.65,"size":0.0,"side":"SELL"}
{"ts":"2026-08-24T20:47:54.592Z","event_type":"best_bid_ask","market_id":"3823659","outcome_index":0,"market_type":"match","local_side":"home","local_uid":"2026-08-24_victoria_jimenez_kasintseva_francisca_jorge","bid":0.34,"ask":0.37,"mid":0.355,"spread":0.03,"bid_size":null,"ask_size":null}
{"ts":"2026-08-24T20:47:54.592Z","event_type":"best_bid_ask","market_id":"3823659","outcome_index":1,"market_type":"match","local_side":"away","local_uid":"2026-08-24_victoria_jimenez_kasintseva_francisca_jorge","bid":0.63,"ask":0.66,"mid":0.645,"spread":0.03,"bid_size":null,"ask_size":null}
{"ts":"2026-08-24T20:47:54.592Z","event_type":"price_change","market_id":"3823659","outcome_index":0,"market_type":"match","local_side":"home","local_uid":"2026-08-24_victoria_jimenez_kasintseva_francisca_jorge","bid":0.34,"ask":0.37,"mid":0.355,"spread":0.03,"price":0.34,"size":20.0,"side":"BUY"}
{"ts":"2026-08-24T20:47:54.592Z","event_type":"price_change","market_id":"3823659","outcome_index":1,"market_type":"match","local_side":"away","local_uid":"2026-08-24_victoria_jimenez_kasintseva_francisca_jorge","bid":0.63,"ask":0.66,"mid":0.645,"spread":0.03,"price":0.66,"size":20.0,"side":"SELL"}
{"ts":"2026-08-24T20:47:54.609Z","event_type":"best_bid_ask","market_id":"3825070","outcome_index":0,"market_type":"set2","local_side":"home","local_uid":"2026-08-24_polina_kudermetova_linda_fruhvirtova","bid":0.53,"ask":0.62,"mid":0.575,"spread":0.09,"bid_size":null,"ask_size":null}
{"ts":"2026-08-24T20:47:54.609Z","event_type":"best_bid_ask","market_id":"3825070","outcome_index":1,"market_type":"set2","local_side":"away","local_uid":"2026-08-24_polina_kudermetova_linda_fruhvirtova","bid":0.38,"ask":0.47,"mid":0.425,"spread":0.09,"bid_size":null,"ask_size":null}
{"ts":"2026-08-24T20:47:54.610Z","event_type":"price_change","market_id":"3825070","outcome_index":1,"market_type":"set2","local_side":"away","local_uid":"2026-08-24_polina_kudermetova_linda_fruhvirtova","bid":0.38,"ask":0.47,"mid":0.425,"spread":0.09,"price":0.39,"size":0.0,"side":"BUY"}
{"ts":"2026-08-24T20:47:54.610Z","event_type":"price_change","market_id":"3825070","outcome_index":0,"market_type":"set2","local_side":"home","local_uid":"2026-08-24_polina_kudermetova_linda_fruhvirtova","bid":0.53,"ask":0.62,"mid":0.575,"spread":0.09,"price":0.61,"size":0.0,"side":"SELL"}
{"ts":"2026-08-24T20:47:54.676Z","event_type":"best_bid_ask","market_id":"3825070","outcome_index":0,"market_type":"set2","local_side":"home","local_uid":"2026-08-24_polina_kudermetova_linda_fruhvirtova","bid":0.53,"ask":0.61,"mid":0.57,"spread":0.08,"bid_size":null,"ask_size":null}
{"ts":"2026-08-24T20:47:54.676Z","event_type":"best_bid_ask","market_id":"3825070","outcome_index":1,"market_type":"set2","local_side":"away","local_uid":"2026-08-24_polina_kudermetova_linda_fruhvirtova","bid":0.39,"ask":0.47,"mid":0.43,"spread":0.08,"bid_size":null,"ask_size":null}
{"ts":"2026-08-24T20:47:54.677Z","event_type":"price_change","market_id":"3825070","outcome_index":1,"market_type":"set2","local_side":"away","local_uid":"2026-08-24_polina_kudermetova_linda_fruhvirtova","bid":0.39,"ask":0.47,"mid":0.43,"spread":0.08,"price":0.39,"size":6.41,"side":"BUY"}
{"ts":"2026-08-24T20:47:54.677Z","event_type":"price_change","market_id":"3825070","outcome_index":0,"market_type":"set2","local_side":"home","local_uid":"2026-08-24_polina_kudermetova_linda_fruhvirtova","bid":0.53,"ask":0.61,"mid":0.57,"spread":0.08,"price":0.61,"size":6.41,"side":"SELL"}
{"ts":"2026-08-24T20:47:54.687Z","event_type":"best_bid_ask","market_id":"3823623","outcome_index":0,"market_type":"match","local_side":"home","local_uid":"2026-08-24_robin_montgomery_kayla_cross","bid":0.88,"ask":0.89,"mid":0.885,"spread":0.01,"bid_size":null,"ask_size":null}
{"ts":"2026-08-24T20:47:54.687Z","event_type":"best_bid_ask","market_id":"3823623","outcome_index":1,"market_type":"match","local_side":"away","local_uid":"2026-08-24_robin_montgomery_kayla_cross","bid":0.11,"ask":0.12,"mid":0.115,"spread":0.01,"bid_size":null,"ask_size":null}
{"ts":"2026-08-24T20:47:54.687Z","event_type":"price_change","market_id":"3823623","outcome_index":0,"market_type":"match","local_side":"home","local_uid":"2026-08-24_robin_montgomery_kayla_cross","bid":0.88,"ask":0.89,"mid":0.885,"spread":0.01,"price":0.88,"size":14025.25,"side":"BUY"}
{"ts":"2026-08-24T20:47:54.687Z","event_type":"price_change","market_id":"3823623","outcome_index":1,"market_type":"match","local_side":"away","local_uid":"2026-08-24_robin_montgomery_kayla_cross","bid":0.11,"ask":0.12,"mid":0.115,"spread":0.01,"price":0.12,"size":14025.25,"side":"SELL"}
{"ts":"2026-08-24T20:47:54.699Z","event_type":"price_change","market_id":"3826719","outcome_index":1,"market_type":"set2","local_side":"away","local_uid":"2026-08-24_laslo_djere_alexandre_muller","bid":0.39,"ask":0.47,"mid":0.43,"spread":0.08,"price":0.39,"size":3163.0,"side":"BUY"}
{"ts":"2026-08-24T20:47:54.699Z","event_type":"price_change","market_id":"3826719","outcome_index":0,"market_type":"set2","local_side":"home","local_uid":"2026-08-24_laslo_djere_alexandre_muller","bid":0.53,"ask":0.61,"mid":0.57,"spread":0.08,"price":0.61,"size":3163.0,"side":"SELL"}
{"ts":"2026-08-24T20:47:54.739Z","event_type":"best_bid_ask","market_id":"3825070","outcome_index":0,"market_type":"set2","local_side":"home","local_uid":"2026-08-24_polina_kudermetova_linda_fruhvirtova","bid":0.53,"ask":0.62,"mid":0.575,"spread":0.09,"bid_size":null,"ask_size":null}
{"ts":"2026-08-24T20:47:54.739Z","event_type":"best_bid_ask","market_id":"3825070","outcome_index":1,"market_type":"set2","local_side":"away","local_uid":"2026-08-24_polina_kudermetova_linda_fruhvirtova","bid":0.38,"ask":0.47,"mid":0.425,"spread":0.09,"bid_size":null,"ask_size":null}
{"ts":"2026-08-24T20:47:54.739Z","event_type":"price_change","market_id":"3825070","outcome_index":1,"market_type":"set2","local_side":"away","local_uid":"2026-08-24_polina_kudermetova_linda_fruhvirtova","bid":0.38,"ask":0.47,"mid":0.425,"spread":0.09,"price":0.39,"size":0.0,"side":"BUY"}
{"ts":"2026-08-24T20:47:54.740Z","event_type":"price_change","market_id":"3825070","outcome_index":0,"market_type":"set2","local_side":"home","local_uid":"2026-08-24_polina_kudermetova_linda_fruhvirtova","bid":0.53,"ask":0.62,"mid":0.575,"spread":0.09,"price":0.61,"size":0.0,"side":"SELL"}
{"ts":"2026-08-24T20:47:54.745Z","event_type":"best_bid_ask","market_id":"3825077","outcome_index":0,"market_type":"set1","local_side":"home","local_uid":"2026-08-24_polina_kudermetova_linda_fruhvirtova","bid":0.45,"ask":0.51,"mid":0.48,"spread":0.06,"bid_size":null,"ask_size":null}
{"ts":"2026-08-24T20:47:54.746Z","event_type":"best_bid_ask","market_id":"3825077","outcome_index":1,"market_type":"set1","local_side":"away","local_uid":"2026-08-24_polina_kudermetova_linda_fruhvirtova","bid":0.49,"ask":0.55,"mid":0.52,"spread":0.06,"bid_size":null,"ask_size":null}
{"ts":"2026-08-24T20:47:54.746Z","event_type":"price_change","market_id":"3825077","outcome_index":1,"market_type":"set1","local_side":"away","local_uid":"2026-08-24_polina_kudermetova_linda_fruhvirtova","bid":0.49,"ask":0.55,"mid":0.52,"spread":0.06,"price":0.49,"size":15.0,"side":"BUY"}
{"ts":"2026-08-24T20:47:54.746Z","event_type":"price_change","market_id":"3825077","outcome_index":0,"market_type":"set1","local_side":"home","local_uid":"2026-08-24_polina_kudermetova_linda_fruhvirtova","bid":0.45,"ask":0.51,"mid":0.48,"spread":0.06,"price":0.51,"size":15.0,"side":"SELL"}
{"ts":"2026-08-24T20:47:54.757Z","event_type":"price_change","market_id":"3824985","outcome_index":0,"market_type":"set1","local_side":"home","local_uid":"2026-08-24_angela_fita_boluda_lin_zhu","bid":0.999,"ask":1.0,"mid":0.9995,"spread":0.001,"price":0.01,"size":14111.0,"side":"BUY"}
{"ts":"2026-08-24T20:47:54.757Z","event_type":"price_change","market_id":"3824985","outcome_index":1,"market_type":"set1","local_side":"away","local_uid":"2026-08-24_angela_fita_boluda_lin_zhu","bid":0.0,"ask":0.001,"mid":0.0005,"spread":0.001,"price":0.99,"size":14111.0,"side":"SELL"}
{"ts":"2026-08-24T20:47:54.795Z","event_type":"best_bid_ask","market_id":"3825053","outcome_index":0,"market_type":"set1","local_side":"home","local_uid":"2026-08-24_robin_montgomery_kayla_cross","bid":0.86,"ask":0.93,"mid":0.895,"spread":0.07,"bid_size":null,"ask_size":null}
{"ts":"2026-08-24T20:47:54.796Z","event_type":"best_bid_ask","market_id":"3825053","outcome_index":1,"market_type":"set1","local_side":"away","local_uid":"2026-08-24_robin_montgomery_kayla_cross","bid":0.07,"ask":0.14,"mid":0.105,"spread":0.07,"bid_size":null,"ask_size":null}
{"ts":"2026-08-24T20:47:54.796Z","event_type":"price_change","market_id":"3825053","outcome_index":0,"market_type":"set1","local_side":"home","local_uid":"2026-08-24_robin_montgomery_kayla_cross","bid":0.86,"ask":0.93,"mid":0.895,"spread":0.07,"price":0.86,"size":211.0,"side":"BUY"}
{"ts":"2026-08-24T20:47:54.796Z","event_type":"price_change","market_id":"3825053","outcome_index":1,"market_type":"set1","local_side":"away","local_uid":"2026-08-24_robin_montgomery_kayla_cross","bid":0.07,"ask":0.14,"mid":0.105,"spread":0.07,"price":0.14,"size":211.0,"side":"SELL"}
{"ts":"2026-08-24T20:47:54.799Z","event_type":"best_bid_ask","market_id":"3825053","outcome_index":0,"market_type":"set1","local_side":"home","local_uid":"2026-08-24_robin_montgomery_kayla_cross","bid":0.87,"ask":0.93,"mid":0.9,"spread":0.06,"bid_size":null,"ask_size":null}
{"ts":"2026-08-24T20:47:54.799Z","event_type":"best_bid_ask","market_id":"3825053","outcome_index":1,"market_type":"set1","local_side":"away","local_uid":"2026-08-24_robin_montgomery_kayla_cross","bid":0.07,"ask":0.13,"mid":0.1,"spread":0.06,"bid_size":null,"ask_size":null}
{"ts":"2026-08-24T20:47:54.800Z","event_type":"price_change","market_id":"3825053","outcome_index":0,"market_type":"set1","local_side":"home","local_uid":"2026-08-24_robin_montgomery_kayla_cross","bid":0.87,"ask":0.93,"mid":0.9,"spread":0.06,"price":0.87,"size":88.0,"side":"BUY"}
{"ts":"2026-08-24T20:47:54.800Z","event_type":"price_change","market_id":"3825053","outcome_index":1,"market_type":"set1","local_side":"away","local_uid":"2026-08-24_robin_montgomery_kayla_cross","bid":0.07,"ask":0.13,"mid":0.1,"spread":0.06,"price":0.13,"size":88.0,"side":"SELL"}
{"ts":"2026-08-24T20:47:54.810Z","event_type":"best_bid_ask","market_id":"3825070","outcome_index":0,"market_type":"set2","local_side":"home","local_uid":"2026-08-24_polina_kudermetova_linda_fruhvirtova","bid":0.53,"ask":0.61,"mid":0.57,"spread":0.08,"bid_size":null,"ask_size":null}
{"ts":"2026-08-24T20:47:54.811Z","event_type":"best_bid_ask","market_id":"3825070","outcome_index":1,"market_type":"set2","local_side":"away","local_uid":"2026-08-24_polina_kudermetova_linda_fruhvirtova","bid":0.39,"ask":0.47,"mid":0.43,"spread":0.08,"bid_size":null,"ask_size":null}
{"ts":"2026-08-24T20:47:54.811Z","event_type":"price_change","market_id":"3825070","outcome_index":1,"market_type":"set2","local_side":"away","local_uid":"2026-08-24_polina_kudermetova_linda_fruhvirtova","bid":0.39,"ask":0.47,"mid":0.43,"spread":0.08,"price":0.39,"size":6.41,"side":"BUY"}
{"ts":"2026-08-24T20:47:54.811Z","event_type":"price_change","market_id":"3825070","outcome_index":0,"market_type":"set2","local_side":"home","local_uid":"2026-08-24_polina_kudermetova_linda_fruhvirtova","bid":0.53,"ask":0.61,"mid":0.57,"spread":0.08,"price":0.61,"size":6.41,"side":"SELL"}
{"ts":"2026-08-24T20:47:54.847Z","event_type":"best_bid_ask","market_id":"3825051","outcome_index":0,"market_type":"set2","local_side":"home","local_uid":"2026-08-24_robin_montgomery_kayla_cross","bid":0.68,"ask":0.78,"mid":0.73,"spread":0.1,"bid_size":null,"ask_size":null}
{"ts":"2026-08-24T20:47:54.847Z","event_type":"best_bid_ask","market_id":"3825051","outcome_index":1,"market_type":"set2","local_side":"away","local_uid":"2026-08-24_robin_montgomery_kayla_cross","bid":0.22,"ask":0.32,"mid":0.27,"spread":0.1,"bid_size":null,"ask_size":null}
{"ts":"2026-08-24T20:47:54.848Z","event_type":"price_change","market_id":"3825051","outcome_index":0,"market_type":"set2","local_side":"home","local_uid":"2026-08-24_robin_montgomery_kayla_cross","bid":0.68,"ask":0.78,"mid":0.73,"spread":0.1,"price":0.68,"size":196.0,"side":"BUY"}
{"ts":"2026-08-24T20:47:54.848Z","event_type":"price_change","market_id":"3825051","outcome_index":1,"market_type":"set2","local_side":"away","local_uid":"2026-08-24_robin_montgomery_kayla_cross","bid":0.22,"ask":0.32,"mid":0.27,"spread":0.1,"price":0.32,"size":196.0,"side":"SELL"}
{"ts":"2026-08-24T20:47:54.851Z","event_type":"best_bid_ask","market_id":"3825053","outcome_index":0,"market_type":"set1","local_side":"home","local_uid":"2026-08-24_robin_montgomery_kayla_cross","bid":0.88,"ask":0.93,"mid":0.905,"spread":0.05,"bid_size":null,"ask_size":null}
{"ts":"2026-08-24T20:47:54.851Z","event_type":"best_bid_ask","market_id":"3825053","outcome_index":1,"market_type":"set1","local_side":"away","local_uid":"2026-08-24_robin_montgomery_kayla_cross","bid":0.07,"ask":0.12,"mid":0.095,"spread":0.05,"bid_size":null,"ask_size":null}
{"ts":"2026-08-24T20:47:54.852Z","event_type":"price_change","market_id":"3825053","outcome_index":0,"market_type":"set1","local_side":"home","local_uid":"2026-08-24_robin_montgomery_kayla_cross","bid":0.88,"ask":0.93,"mid":0.905,"spread":0.05,"price":0.88,"size":134.37,"side":"BUY"}
{"ts":"2026-08-24T20:47:54.852Z","event_type":"price_change","market_id":"3825053","outcome_index":1,"market_type":"set1","local_side":"away","local_uid":"2026-08-24_robin_montgomery_kayla_cross","bid":0.07,"ask":0.12,"mid":0.095,"spread":0.05,"price":0.12,"size":134.37,"side":"SELL"}
{"ts":"2026-08-24T20:47:54.888Z","event_type":"best_bid_ask","market_id":"3824796","outcome_index":0,"market_type":"set2","local_side":"home","local_uid":"2026-08-24_victoria_jimenez_kasintseva_francisca_jorge","bid":0.46,"ask":0.67,"mid":0.565,"spread":0.21,"bid_size":null,"ask_size":null}
{"ts":"2026-08-24T20:47:54.888Z","event_type":"best_bid_ask","market_id":"3824796","outcome_index":1,"market_type":"set2","local_side":"away","local_uid":"2026-08-24_victoria_jimenez_kasintseva_francisca_jorge","bid":0.33,"ask":0.54,"mid":0.435,"spread":0.21,"bid_size":null,"ask_size":null}
{"ts":"2026-08-24T20:47:54.889Z","event_type":"price_change","market_id":"3824796","outcome_index":0,"market_type":"set2","local_side":"home","local_uid":"2026-08-24_victoria_jimenez_kasintseva_francisca_jorge","bid":0.46,"ask":0.67,"mid":0.565,"spread":0.21,"price":0.46,"size":150.0,"side":"BUY"}
{"ts":"2026-08-24T20:47:54.889Z","event_type":"price_change","market_id":"3824796","outcome_index":1,"market_type":"set2","local_side":"away","local_uid":"2026-08-24_victoria_jimenez_kasintseva_francisca_jorge","bid":0.33,"ask":0.54,"mid":0.435,"spread":0.21,"price":0.54,"size":150.0,"side":"SELL"}
{"ts":"2026-08-24T20:47:54.914Z","event_type":"best_bid_ask","market_id":"3826654","outcome_index":0,"market_type":"set2","local_side":"home","local_uid":"2026-08-24_sebastian_gorzny_cruz_hewitt","bid":0.15,"ask":0.25,"mid":0.2,"spread":0.1,"bid_size":null,"ask_size":null}
{"ts":"2026-08-24T20:47:54.915Z","event_type":"best_bid_ask","market_id":"3826654","outcome_index":1,"market_type":"set2","local_side":"away","local_uid":"2026-08-24_sebastian_gorzny_cruz_hewitt","bid":0.75,"ask":0.85,"mid":0.8,"spread":0.1,"bid_size":null,"ask_size":null}
{"ts":"2026-08-24T20:47:54.915Z","event_type":"price_change","market_id":"3826654","outcome_index":0,"market_type":"set2","local_side":"home","local_uid":"2026-08-24_sebastian_gorzny_cruz_hewitt","bid":0.15,"ask":0.25,"mid":0.2,"spread":0.1,"price":0.17,"size":0.0,"side":"BUY"}
{"ts":"2026-08-24T20:47:54.915Z","event_type":"price_change","market_id":"3826654","outcome_index":1,"market_type":"set2","local_side":"away","local_uid":"2026-08-24_sebastian_gorzny_cruz_hewitt","bid":0.75,"ask":0.85,"mid":0.8,"spread":0.1,"price":0.83,"size":0.0,"side":"SELL"}
{"ts":"2026-08-24T20:47:54.931Z","event_type":"best_bid_ask","market_id":"3826654","outcome_index":0,"market_type":"set2","local_side":"home","local_uid":"2026-08-24_sebastian_gorzny_cruz_hewitt","bid":0.17,"ask":0.25,"mid":0.21,"spread":0.08,"bid_size":null,"ask_size":null}
{"ts":"2026-08-24T20:47:54.931Z","event_type":"best_bid_ask","market_id":"3826654","outcome_index":1,"market_type":"set2","local_side":"away","local_uid":"2026-08-24_sebastian_gorzny_cruz_hewitt","bid":0.75,"ask":0.83,"mid":0.79,"spread":0.08,"bid_size":null,"ask_size":null}
{"ts":"2026-08-24T20:47:54.932Z","event_type":"price_change","market_id":"3826654","outcome_index":0,"market_type":"set2","local_side":"home","local_uid":"2026-08-24_sebastian_gorzny_cruz_hewitt","bid":0.17,"ask":0.25,"mid":0.21,"spread":0.08,"price":0.17,"size":1530.0,"side":"BUY"}
{"ts":"2026-08-24T20:47:54.932Z","event_type":"price_change","market_id":"3826654","outcome_index":1,"market_type":"set2","local_side":"away","local_uid":"2026-08-24_sebastian_gorzny_cruz_hewitt","bid":0.75,"ask":0.83,"mid":0.79,"spread":0.08,"price":0.83,"size":1530.0,"side":"SELL"}
{"ts":"2026-08-24T20:47:54.981Z","event_type":"best_bid_ask","market_id":"3825051","outcome_index":0,"market_type":"set2","local_side":"home","local_uid":"2026-08-24_robin_montgomery_kayla_cross","bid":0.68,"ask":0.79,"mid":0.735,"spread":0.11,"bid_size":null,"ask_size":null}
{"ts":"2026-08-24T20:47:54.982Z","event_type":"best_bid_ask","market_id":"3825051","outcome_index":1,"market_type":"set2","local_side":"away","local_uid":"2026-08-24_robin_montgomery_kayla_cross","bid":0.21,"ask":0.32,"mid":0.265,"spread":0.11,"bid_size":null,"ask_size":null}
{"ts":"2026-08-24T20:47:54.982Z","event_type":"price_change","market_id":"3825051","outcome_index":1,"market_type":"set2","local_side":"away","local_uid":"2026-08-24_robin_montgomery_kayla_cross","bid":0.21,"ask":0.32,"mid":0.265,"spread":0.11,"price":0.22,"size":0.0,"side":"BUY"}
{"ts":"2026-08-24T20:47:54.982Z","event_type":"price_change","market_id":"3825051","outcome_index":0,"market_type":"set2","local_side":"home","local_uid":"2026-08-24_robin_montgomery_kayla_cross","bid":0.68,"ask":0.79,"mid":0.735,"spread":0.11,"price":0.78,"size":0.0,"side":"SELL"}
{"ts":"2026-08-24T20:47:55.126Z","event_type":"best_bid_ask","market_id":"3825053","outcome_index":0,"market_type":"set1","local_side":"home","local_uid":"2026-08-24_robin_montgomery_kayla_cross","bid":0.88,"ask":0.94,"mid":0.91,"spread":0.06,"bid_size":null,"ask_size":null}
{"ts":"2026-08-24T20:47:55.126Z","event_type":"best_bid_ask","market_id":"3825053","outcome_index":1,"market_type":"set1","local_side":"away","local_uid":"2026-08-24_robin_montgomery_kayla_cross","bid":0.06,"ask":0.12,"mid":0.09,"spread":0.06,"bid_size":null,"ask_size":null}
{"ts":"2026-08-24T20:47:55.127Z","event_type":"price_change","market_id":"3825053","outcome_index":0,"market_type":"set1","local_side":"home","local_uid":"2026-08-24_robin_montgomery_kayla_cross","bid":0.88,"ask":0.94,"mid":0.91,"spread":0.06,"price":0.82,"size":1726.0,"side":"BUY"}
{"ts":"2026-08-24T20:47:55.127Z","event_type":"price_change","market_id":"3825053","outcome_index":1,"market_type":"set1","local_side":"away","local_uid":"2026-08-24_robin_montgomery_kayla_cross","bid":0.06,"ask":0.12,"mid":0.09,"spread":0.06,"price":0.18,"size":1726.0,"side":"SELL"}
{"ts":"2026-08-24T20:47:55.196Z","event_type":"best_bid_ask","market_id":"3824796","outcome_index":0,"market_type":"set2","local_side":"home","local_uid":"2026-08-24_victoria_jimenez_kasintseva_francisca_jorge","bid":0.46,"ask":0.66,"mid":0.56,"spread":0.2,"bid_size":null,"ask_size":null}
{"ts":"2026-08-24T20:47:55.196Z","event_type":"best_bid_ask","market_id":"3824796","outcome_index":1,"market_type":"set2","local_side":"away","local_uid":"2026-08-24_victoria_jimenez_kasintseva_francisca_jorge","bid":0.34,"ask":0.54,"mid":0.44,"spread":0.2,"bid_size":null,"ask_size":null}
{"ts":"2026-08-24T20:47:55.197Z","event_type":"price_change","market_id":"3824796","outcome_index":1,"market_type":"set2","local_side":"away","local_uid":"2026-08-24_victoria_jimenez_kasintseva_francisca_jorge","bid":0.34,"ask":0.54,"mid":0.44,"spread":0.2,"price":0.34,"size":28.04,"side":"BUY"}
{"ts":"2026-08-24T20:47:55.197Z","event_type":"price_change","market_id":"3824796","outcome_index":0,"market_type":"set2","local_side":"home","local_uid":"2026-08-24_victoria_jimenez_kasintseva_francisca_jorge","bid":0.46,"ask":0.66,"mid":0.56,"spread":0.2,"price":0.66,"size":28.04,"side":"SELL"}
{"ts":"2026-08-24T20:47:55.206Z","event_type":"best_bid_ask","market_id":"3825053","outcome_index":0,"market_type":"set1","local_side":"home","local_uid":"2026-08-24_robin_montgomery_kayla_cross","bid":0.88,"ask":0.93,"mid":0.905,"spread":0.05,"bid_size":null,"ask_size":null}
{"ts":"2026-08-24T20:47:55.206Z","event_type":"best_bid_ask","market_id":"3825053","outcome_index":1,"market_type":"set1","local_side":"away","local_uid":"2026-08-24_robin_montgomery_kayla_cross","bid":0.07,"ask":0.12,"mid":0.095,"spread":0.05,"bid_size":null,"ask_size":null}
{"ts":"2026-08-24T20:47:55.207Z","event_type":"price_change","market_id":"3825053","outcome_index":1,"market_type":"set1","local_side":"away","local_uid":"2026-08-24_robin_montgomery_kayla_cross","bid":0.07,"ask":0.12,"mid":0.095,"spread":0.05,"price":0.07,"size":250.0,"side":"BUY"}
{"ts":"2026-08-24T20:47:55.207Z","event_type":"price_change","market_id":"3825053","outcome_index":0,"market_type":"set1","local_side":"home","local_uid":"2026-08-24_robin_montgomery_kayla_cross","bid":0.88,"ask":0.93,"mid":0.905,"spread":0.05,"price":0.93,"size":250.0,"side":"SELL"}
{"ts":"2026-08-24T20:47:55.531Z","event_type":"best_bid_ask","market_id":"3825070","outcome_index":0,"market_type":"set2","local_side":"home","local_uid":"2026-08-24_polina_kudermetova_linda_fruhvirtova","bid":0.53,"ask":0.62,"mid":0.575,"spread":0.09,"bid_size":null,"ask_size":null}
{"ts":"2026-08-24T20:47:55.531Z","event_type":"best_bid_ask","market_id":"3825070","outcome_index":1,"market_type":"set2","local_side":"away","local_uid":"2026-08-24_polina_kudermetova_linda_fruhvirtova","bid":0.38,"ask":0.47,"mid":0.425,"spread":0.09,"bid_size":null,"ask_size":null}
{"ts":"2026-08-24T20:47:55.531Z","event_type":"price_change","market_id":"3825070","outcome_index":1,"market_type":"set2","local_side":"away","local_uid":"2026-08-24_polina_kudermetova_linda_fruhvirtova","bid":0.38,"ask":0.47,"mid":0.425,"spread":0.09,"price":0.39,"size":0.0,"side":"BUY"}
{"ts":"2026-08-24T20:47:55.531Z","event_type":"price_change","market_id":"3825070","outcome_index":0,"market_type":"set2","local_side":"home","local_uid":"2026-08-24_polina_kudermetova_linda_fruhvirtova","bid":0.53,"ask":0.62,"mid":0.575,"spread":0.09,"price":0.61,"size":0.0,"side":"SELL"}
{"ts":"2026-08-24T20:47:55.598Z","event_type":"best_bid_ask","market_id":"3825070","outcome_index":0,"market_type":"set2","local_side":"home","local_uid":"2026-08-24_polina_kudermetova_linda_fruhvirtova","bid":0.53,"ask":0.61,"mid":0.57,"spread":0.08,"bid_size":null,"ask_size":null}
{"ts":"2026-08-24T20:47:55.599Z","event_type":"best_bid_ask","market_id":"3825070","outcome_index":1,"market_type":"set2","local_side":"away","local_uid":"2026-08-24_polina_kudermetova_linda_fruhvirtova","bid":0.39,"ask":0.47,"mid":0.43,"spread":0.08,"bid_size":null,"ask_size":null}
{"ts":"2026-08-24T20:47:55.599Z","event_type":"price_change","market_id":"3825070","outcome_index":1,"market_type":"set2","local_side":"away","local_uid":"2026-08-24_polina_kudermetova_linda_fruhvirtova","bid":0.39,"ask":0.47,"mid":0.43,"spread":0.08,"price":0.39,"size":6.41,"side":"BUY"}
{"ts":"2026-08-24T20:47:55.599Z","event_type":"price_change","market_id":"3825070","outcome_index":0,"market_type":"set2","local_side":"home","local_uid":"2026-08-24_polina_kudermetova_linda_fruhvirtova","bid":0.53,"ask":0.61,"mid":0.57,"spread":0.08,"price":0.61,"size":6.41,"side":"SELL"}
{"ts":"2026-08-24T20:47:55.784Z","event_type":"best_bid_ask","market_id":"3824875","outcome_index":0,"market_type":"set2","local_side":"home","local_uid":"2026-08-24_eva_vedder_bianca_andreescu","bid":0.22,"ask":0.25,"mid":0.235,"spread":0.03,"bid_size":null,"ask_size":null}
{"ts":"2026-08-24T20:47:55.785Z","event_type":"best_bid_ask","market_id":"3824875","outcome_index":1,"market_type":"set2","local_side":"away","local_uid":"2026-08-24_eva_vedder_bianca_andreescu","bid":0.75,"ask":0.78,"mid":0.765,"spread":0.03,"bid_size":null,"ask_size":null}
{"ts":"2026-08-24T20:47:55.785Z","event_type":"price_change","market_id":"3824875","outcome_index":1,"market_type":"set2","local_side":"away","local_uid":"2026-08-24_eva_vedder_bianca_andreescu","bid":0.75,"ask":0.78,"mid":0.765,"spread":0.03,"price":0.78,"size":50.0,"side":"SELL"}
{"ts":"2026-08-24T20:47:55.785Z","event_type":"price_change","market_id":"3824875","outcome_index":0,"market_type":"set2","local_side":"home","local_uid":"2026-08-24_eva_vedder_bianca_andreescu","bid":0.22,"ask":0.25,"mid":0.235,"spread":0.03,"price":0.22,"size":50.0,"side":"BUY"}
{"ts":"2026-08-24T20:47:55.824Z","event_type":"best_bid_ask","market_id":"3825051","outcome_index":0,"market_type":"set2","local_side":"home","local_uid":"2026-08-24_robin_montgomery_kayla_cross","bid":0.69,"ask":0.79,"mid":0.74,"spread":0.1,"bid_size":null,"ask_size":null}
{"ts":"2026-08-24T20:47:55.824Z","event_type":"best_bid_ask","market_id":"3825051","outcome_index":1,"market_type":"set2","local_side":"away","local_uid":"2026-08-24_robin_montgomery_kayla_cross","bid":0.21,"ask":0.31,"mid":0.26,"spread":0.1,"bid_size":null,"ask_size":null}
{"ts":"2026-08-24T20:47:55.825Z","event_type":"best_bid_ask","market_id":"3823623","outcome_index":0,"market_type":"match","local_side":"home","local_uid":"2026-08-24_robin_montgomery_kayla_cross","bid":0.88,"ask":0.9,"mid":0.89,"spread":0.02,"bid_size":null,"ask_size":null}
{"ts":"2026-08-24T20:47:55.825Z","event_type":"price_change","market_id":"3825051","outcome_index":0,"market_type":"set2","local_side":"home","local_uid":"2026-08-24_robin_montgomery_kayla_cross","bid":0.69,"ask":0.79,"mid":0.74,"spread":0.1,"price":0.69,"size":11.0,"side":"BUY"}
{"ts":"2026-08-24T20:47:55.825Z","event_type":"price_change","market_id":"3825051","outcome_index":1,"market_type":"set2","local_side":"away","local_uid":"2026-08-24_robin_montgomery_kayla_cross","bid":0.21,"ask":0.31,"mid":0.26,"spread":0.1,"price":0.31,"size":11.0,"side":"SELL"}
{"ts":"2026-08-24T20:47:55.825Z","event_type":"best_bid_ask","market_id":"3823623","outcome_index":1,"market_type":"match","local_side":"away","local_uid":"2026-08-24_robin_montgomery_kayla_cross","bid":0.1,"ask":0.12,"mid":0.11,"spread":0.02,"bid_size":null,"ask_size":null}
{"ts":"2026-08-24T20:47:55.826Z","event_type":"price_change","market_id":"3823623","outcome_index":1,"market_type":"match","local_side":"away","local_uid":"2026-08-24_robin_montgomery_kayla_cross","bid":0.1,"ask":0.12,"mid":0.11,"spread":0.02,"price":0.11,"size":0.0,"side":"BUY"}
{"ts":"2026-08-24T20:47:55.826Z","event_type":"price_change","market_id":"3823623","outcome_index":0,"market_type":"match","local_side":"home","local_uid":"2026-08-24_robin_montgomery_kayla_cross","bid":0.88,"ask":0.9,"mid":0.89,"spread":0.02,"price":0.89,"size":0.0,"side":"SELL"}
{"ts":"2026-08-24T20:47:56.288Z","event_type":"best_bid_ask","market_id":"3823659","outcome_index":0,"market_type":"match","local_side":"home","local_uid":"2026-08-24_victoria_jimenez_kasintseva_francisca_jorge","bid":0.34,"ask":0.38,"mid":0.36,"spread":0.04,"bid_size":null,"ask_size":null}
{"ts":"2026-08-24T20:47:56.289Z","event_type":"best_bid_ask","market_id":"3823659","outcome_index":1,"market_type":"match","local_side":"away","local_uid":"2026-08-24_victoria_jimenez_kasintseva_francisca_jorge","bid":0.62,"ask":0.66,"mid":0.64,"spread":0.04,"bid_size":null,"ask_size":null}
{"ts":"2026-08-24T20:47:56.289Z","event_type":"price_change","market_id":"3823659","outcome_index":1,"market_type":"match","local_side":"away","local_uid":"2026-08-24_victoria_jimenez_kasintseva_francisca_jorge","bid":0.62,"ask":0.66,"mid":0.64,"spread":0.04,"price":0.63,"size":0.0,"side":"BUY"}
{"ts":"2026-08-24T20:47:56.290Z","event_type":"price_change","market_id":"3823659","outcome_index":0,"market_type":"match","local_side":"home","local_uid":"2026-08-24_victoria_jimenez_kasintseva_francisca_jorge","bid":0.34,"ask":0.38,"mid":0.36,"spread":0.04,"price":0.37,"size":0.0,"side":"SELL"}
{"ts":"2026-08-24T20:47:56.333Z","event_type":"best_bid_ask","market_id":"3824875","outcome_index":0,"market_type":"set2","local_side":"home","local_uid":"2026-08-24_eva_vedder_bianca_andreescu","bid":0.2,"ask":0.25,"mid":0.225,"spread":0.05,"bid_size":null,"ask_size":null}
{"ts":"2026-08-24T20:47:56.334Z","event_type":"best_bid_ask","market_id":"3824875","outcome_index":1,"market_type":"set2","local_side":"away","local_uid":"2026-08-24_eva_vedder_bianca_andreescu","bid":0.75,"ask":0.8,"mid":0.775,"spread":0.05,"bid_size":null,"ask_size":null}
{"ts":"2026-08-24T20:47:56.334Z","event_type":"price_change","market_id":"3824875","outcome_index":1,"market_type":"set2","local_side":"away","local_uid":"2026-08-24_eva_vedder_bianca_andreescu","bid":0.75,"ask":0.8,"mid":0.775,"spread":0.05,"price":0.78,"size":0.0,"side":"SELL"}
{"ts":"2026-08-24T20:47:56.334Z","event_type":"price_change","market_id":"3824875","outcome_index":0,"market_type":"set2","local_side":"home","local_uid":"2026-08-24_eva_vedder_bianca_andreescu","bid":0.2,"ask":0.25,"mid":0.225,"spread":0.05,"price":0.22,"size":0.0,"side":"BUY"}
{"ts":"2026-08-24T20:47:56.345Z","event_type":"best_bid_ask","market_id":"3824875","outcome_index":0,"market_type":"set2","local_side":"home","local_uid":"2026-08-24_eva_vedder_bianca_andreescu","bid":0.19,"ask":0.25,"mid":0.22,"spread":0.06,"bid_size":null,"ask_size":null}
{"ts":"2026-08-24T20:47:56.346Z","event_type":"best_bid_ask","market_id":"3824875","outcome_index":1,"market_type":"set2","local_side":"away","local_uid":"2026-08-24_eva_vedder_bianca_andreescu","bid":0.75,"ask":0.81,"mid":0.78,"spread":0.06,"bid_size":null,"ask_size":null}
{"ts":"2026-08-24T20:47:56.346Z","event_type":"price_change","market_id":"3824875","outcome_index":0,"market_type":"set2","local_side":"home","local_uid":"2026-08-24_eva_vedder_bianca_andreescu","bid":0.19,"ask":0.25,"mid":0.22,"spread":0.06,"price":0.2,"size":0.0,"side":"BUY"}
{"ts":"2026-08-24T20:47:56.346Z","event_type":"price_change","market_id":"3824875","outcome_index":1,"market_type":"set2","local_side":"away","local_uid":"2026-08-24_eva_vedder_bianca_andreescu","bid":0.75,"ask":0.81,"mid":0.78,"spread":0.06,"price":0.8,"size":0.0,"side":"SELL"}
{"ts":"2026-08-24T20:47:56.429Z","event_type":"best_bid_ask","market_id":"3824875","outcome_index":0,"market_type":"set2","local_side":"home","local_uid":"2026-08-24_eva_vedder_bianca_andreescu","bid":0.21,"ask":0.25,"mid":0.23,"spread":0.04,"bid_size":null,"ask_size":null}
{"ts":"2026-08-24T20:47:56.430Z","event_type":"best_bid_ask","market_id":"3824875","outcome_index":1,"market_type":"set2","local_side":"away","local_uid":"2026-08-24_eva_vedder_bianca_andreescu","bid":0.75,"ask":0.79,"mid":0.77,"spread":0.04,"bid_size":null,"ask_size":null}
{"ts":"2026-08-24T20:47:56.430Z","event_type":"price_change","market_id":"3824875","outcome_index":0,"market_type":"set2","local_side":"home","local_uid":"2026-08-24_eva_vedder_bianca_andreescu","bid":0.21,"ask":0.25,"mid":0.23,"spread":0.04,"price":0.21,"size":23.81,"side":"BUY"}
{"ts":"2026-08-24T20:47:56.430Z","event_type":"price_change","market_id":"3824875","outcome_index":1,"market_type":"set2","local_side":"away","local_uid":"2026-08-24_eva_vedder_bianca_andreescu","bid":0.75,"ask":0.79,"mid":0.77,"spread":0.04,"price":0.79,"size":23.81,"side":"SELL"}
{"ts":"2026-08-24T20:47:56.436Z","event_type":"best_bid_ask","market_id":"3825604","outcome_index":0,"market_type":"match","local_side":"home","local_uid":"2026-08-24_dalibor_svrcina_felipe_meligeni_alves","bid":0.78,"ask":0.83,"mid":0.805,"spread":0.05,"bid_size":null,"ask_size":null}
{"ts":"2026-08-24T20:47:56.437Z","event_type":"best_bid_ask","market_id":"3825604","outcome_index":1,"market_type":"match","local_side":"away","local_uid":"2026-08-24_dalibor_svrcina_felipe_meligeni_alves","bid":0.17,"ask":0.22,"mid":0.195,"spread":0.05,"bid_size":null,"ask_size":null}
{"ts":"2026-08-24T20:47:56.437Z","event_type":"price_change","market_id":"3825604","outcome_index":1,"market_type":"match","local_side":"away","local_uid":"2026-08-24_dalibor_svrcina_felipe_meligeni_alves","bid":0.17,"ask":0.22,"mid":0.195,"spread":0.05,"price":0.17,"size":100.0,"side":"BUY"}
{"ts":"2026-08-24T20:47:56.437Z","event_type":"price_change","market_id":"3825604","outcome_index":0,"market_type":"match","local_side":"home","local_uid":"2026-08-24_dalibor_svrcina_felipe_meligeni_alves","bid":0.78,"ask":0.83,"mid":0.805,"spread":0.05,"price":0.83,"size":100.0,"side":"SELL"}
{"ts":"2026-08-24T20:47:56.503Z","event_type":"best_bid_ask","market_id":"3825070","outcome_index":0,"market_type":"set2","local_side":"home","local_uid":"2026-08-24_polina_kudermetova_linda_fruhvirtova","bid":0.53,"ask":0.62,"mid":0.575,"spread":0.09,"bid_size":null,"ask_size":null}
{"ts":"2026-08-24T20:47:56.503Z","event_type":"best_bid_ask","market_id":"3825070","outcome_index":1,"market_type":"set2","local_side":"away","local_uid":"2026-08-24_polina_kudermetova_linda_fruhvirtova","bid":0.38,"ask":0.47,"mid":0.425,"spread":0.09,"bid_size":null,"ask_size":null}
{"ts":"2026-08-24T20:47:56.503Z","event_type":"price_change","market_id":"3825070","outcome_index":1,"market_type":"set2","local_side":"away","local_uid":"2026-08-24_polina_kudermetova_linda_fruhvirtova","bid":0.38,"ask":0.47,"mid":0.425,"spread":0.09,"price":0.39,"size":0.0,"side":"BUY"}
{"ts":"2026-08-24T20:47:56.504Z","event_type":"price_change","market_id":"3825070","outcome_index":0,"market_type":"set2","local_side":"home","local_uid":"2026-08-24_polina_kudermetova_linda_fruhvirtova","bid":0.53,"ask":0.62,"mid":0.575,"spread":0.09,"price":0.61,"size":0.0,"side":"SELL"}
{"ts":"2026-08-24T20:47:56.526Z","event_type":"best_bid_ask","market_id":"3824994","outcome_index":0,"market_type":"set2","local_side":"home","local_uid":"2026-08-24_angela_fita_boluda_lin_zhu","bid":0.36,"ask":0.47,"mid":0.415,"spread":0.11,"bid_size":null,"ask_size":null}
{"ts":"2026-08-24T20:47:56.526Z","event_type":"best_bid_ask","market_id":"3824994","outcome_index":1,"market_type":"set2","local_side":"away","local_uid":"2026-08-24_angela_fita_boluda_lin_zhu","bid":0.53,"ask":0.64,"mid":0.585,"spread":0.11,"bid_size":null,"ask_size":null}
{"ts":"2026-08-24T20:47:56.526Z","event_type":"price_change","market_id":"3824994","outcome_index":1,"market_type":"set2","local_side":"away","local_uid":"2026-08-24_angela_fita_boluda_lin_zhu","bid":0.53,"ask":0.64,"mid":0.585,"spread":0.11,"price":0.54,"size":0.0,"side":"BUY"}
{"ts":"2026-08-24T20:47:56.527Z","event_type":"price_change","market_id":"3824994","outcome_index":0,"market_type":"set2","local_side":"home","local_uid":"2026-08-24_angela_fita_boluda_lin_zhu","bid":0.36,"ask":0.47,"mid":0.415,"spread":0.11,"price":0.46,"size":0.0,"side":"SELL"}
{"ts":"2026-08-24T20:47:56.530Z","event_type":"best_bid_ask","market_id":"3824994","outcome_index":0,"market_type":"set2","local_side":"home","local_uid":"2026-08-24_angela_fita_boluda_lin_zhu","bid":0.35,"ask":0.47,"mid":0.41,"spread":0.12,"bid_size":null,"ask_size":null}
{"ts":"2026-08-24T20:47:56.530Z","event_type":"best_bid_ask","market_id":"3824994","outcome_index":1,"market_type":"set2","local_side":"away","local_uid":"2026-08-24_angela_fita_boluda_lin_zhu","bid":0.53,"ask":0.65,"mid":0.59,"spread":0.12,"bid_size":null,"ask_size":null}
{"ts":"2026-08-24T20:47:56.531Z","event_type":"price_change","market_id":"3824994","outcome_index":0,"market_type":"set2","local_side":"home","local_uid":"2026-08-24_angela_fita_boluda_lin_zhu","bid":0.35,"ask":0.47,"mid":0.41,"spread":0.12,"price":0.36,"size":0.0,"side":"BUY"}
{"ts":"2026-08-24T20:47:56.531Z","event_type":"price_change","market_id":"3824994","outcome_index":1,"market_type":"set2","local_side":"away","local_uid":"2026-08-24_angela_fita_boluda_lin_zhu","bid":0.53,"ask":0.65,"mid":0.59,"spread":0.12,"price":0.64,"size":0.0,"side":"SELL"}
{"ts":"2026-08-24T20:47:56.544Z","event_type":"best_bid_ask","market_id":"3825604","outcome_index":0,"market_type":"match","local_side":"home","local_uid":"2026-08-24_dalibor_svrcina_felipe_meligeni_alves","bid":0.78,"ask":0.84,"mid":0.81,"spread":0.06,"bid_size":null,"ask_size":null}
{"ts":"2026-08-24T20:47:56.544Z","event_type":"best_bid_ask","market_id":"3825604","outcome_index":1,"market_type":"match","local_side":"away","local_uid":"2026-08-24_dalibor_svrcina_felipe_meligeni_alves","bid":0.16,"ask":0.22,"mid":0.19,"spread":0.06,"bid_size":null,"ask_size":null}
{"ts":"2026-08-24T20:47:56.545Z","event_type":"price_change","market_id":"3825604","outcome_index":1,"market_type":"match","local_side":"away","local_uid":"2026-08-24_dalibor_svrcina_felipe_meligeni_alves","bid":0.16,"ask":0.22,"mid":0.19,"spread":0.06,"price":0.15,"size":63.97,"side":"BUY"}
{"ts":"2026-08-24T20:47:56.545Z","event_type":"price_change","market_id":"3825604","outcome_index":0,"market_type":"match","local_side":"home","local_uid":"2026-08-24_dalibor_svrcina_felipe_meligeni_alves","bid":0.78,"ask":0.84,"mid":0.81,"spread":0.06,"price":0.85,"size":63.97,"side":"SELL"}
{"ts":"2026-08-24T20:47:56.564Z","event_type":"best_bid_ask","market_id":"3824994","outcome_index":0,"market_type":"set2","local_side":"home","local_uid":"2026-08-24_angela_fita_boluda_lin_zhu","bid":0.35,"ask":0.52,"mid":0.435,"spread":0.17,"bid_size":null,"ask_size":null}
{"ts":"2026-08-24T20:47:56.564Z","event_type":"best_bid_ask","market_id":"3824994","outcome_index":1,"market_type":"set2","local_side":"away","local_uid":"2026-08-24_angela_fita_boluda_lin_zhu","bid":0.48,"ask":0.65,"mid":0.565,"spread":0.17,"bid_size":null,"ask_size":null}
{"ts":"2026-08-24T20:47:56.565Z","event_type":"price_change","market_id":"3824994","outcome_index":1,"market_type":"set2","local_side":"away","local_uid":"2026-08-24_angela_fita_boluda_lin_zhu","bid":0.48,"ask":0.65,"mid":0.565,"spread":0.17,"price":0.53,"size":0.0,"side":"BUY"}
{"ts":"2026-08-24T20:47:56.565Z","event_type":"price_change","market_id":"3824994","outcome_index":0,"market_type":"set2","local_side":"home","local_uid":"2026-08-24_angela_fita_boluda_lin_zhu","bid":0.35,"ask":0.52,"mid":0.435,"spread":0.17,"price":0.47,"size":0.0,"side":"SELL"}
{"ts":"2026-08-24T20:47:56.572Z","event_type":"best_bid_ask","market_id":"3825070","outcome_index":0,"market_type":"set2","local_side":"home","local_uid":"2026-08-24_polina_kudermetova_linda_fruhvirtova","bid":0.53,"ask":0.61,"mid":0.57,"spread":0.08,"bid_size":null,"ask_size":null}
{"ts":"2026-08-24T20:47:56.573Z","event_type":"best_bid_ask","market_id":"3825070","outcome_index":1,"market_type":"set2","local_side":"away","local_uid":"2026-08-24_polina_kudermetova_linda_fruhvirtova","bid":0.39,"ask":0.47,"mid":0.43,"spread":0.08,"bid_size":null,"ask_size":null}
{"ts":"2026-08-24T20:47:56.576Z","event_type":"price_change","market_id":"3825070","outcome_index":1,"market_type":"set2","local_side":"away","local_uid":"2026-08-24_polina_kudermetova_linda_fruhvirtova","bid":0.39,"ask":0.47,"mid":0.43,"spread":0.08,"price":0.39,"size":6.41,"side":"BUY"}
{"ts":"2026-08-24T20:47:56.577Z","event_type":"price_change","market_id":"3825070","outcome_index":0,"market_type":"set2","local_side":"home","local_uid":"2026-08-24_polina_kudermetova_linda_fruhvirtova","bid":0.53,"ask":0.61,"mid":0.57,"spread":0.08,"price":0.61,"size":6.41,"side":"SELL"}
{"ts":"2026-08-24T20:47:56.580Z","event_type":"best_bid_ask","market_id":"3823629","outcome_index":0,"market_type":"match","local_side":"home","local_uid":"2026-08-24_angela_fita_boluda_lin_zhu","bid":0.53,"ask":0.55,"mid":0.54,"spread":0.02,"bid_size":null,"ask_size":null}
{"ts":"2026-08-24T20:47:56.580Z","event_type":"best_bid_ask","market_id":"3823629","outcome_index":1,"market_type":"match","local_side":"away","local_uid":"2026-08-24_angela_fita_boluda_lin_zhu","bid":0.45,"ask":0.47,"mid":0.46,"spread":0.02,"bid_size":null,"ask_size":null}
{"ts":"2026-08-24T20:47:56.580Z","event_type":"price_change","market_id":"3823629","outcome_index":0,"market_type":"match","local_side":"home","local_uid":"2026-08-24_angela_fita_boluda_lin_zhu","bid":0.53,"ask":0.55,"mid":0.54,"spread":0.02,"price":0.53,"size":2671.6,"side":"BUY"}
{"ts":"2026-08-24T20:47:56.580Z","event_type":"price_change","market_id":"3823629","outcome_index":1,"market_type":"match","local_side":"away","local_uid":"2026-08-24_angela_fita_boluda_lin_zhu","bid":0.45,"ask":0.47,"mid":0.46,"spread":0.02,"price":0.47,"size":2671.6,"side":"SELL"}
{"ts":"2026-08-24T20:47:56.592Z","event_type":"best_bid_ask","market_id":"3824994","outcome_index":0,"market_type":"set2","local_side":"home","local_uid":"2026-08-24_angela_fita_boluda_lin_zhu","bid":0.35,"ask":0.51,"mid":0.43,"spread":0.16,"bid_size":null,"ask_size":null}
{"ts":"2026-08-24T20:47:56.592Z","event_type":"best_bid_ask","market_id":"3824994","outcome_index":1,"market_type":"set2","local_side":"away","local_uid":"2026-08-24_angela_fita_boluda_lin_zhu","bid":0.49,"ask":0.65,"mid":0.57,"spread":0.16,"bid_size":null,"ask_size":null}
{"ts":"2026-08-24T20:47:56.594Z","event_type":"price_change","market_id":"3824994","outcome_index":1,"market_type":"set2","local_side":"away","local_uid":"2026-08-24_angela_fita_boluda_lin_zhu","bid":0.49,"ask":0.65,"mid":0.57,"spread":0.16,"price":0.49,"size":32.96,"side":"BUY"}
{"ts":"2026-08-24T20:47:56.595Z","event_type":"price_change","market_id":"3824994","outcome_index":0,"market_type":"set2","local_side":"home","local_uid":"2026-08-24_angela_fita_boluda_lin_zhu","bid":0.35,"ask":0.51,"mid":0.43,"spread":0.16,"price":0.51,"size":32.96,"side":"SELL"}
{"ts":"2026-08-24T20:47:56.601Z","event_type":"best_bid_ask","market_id":"3823629","outcome_index":0,"market_type":"match","local_side":"home","local_uid":"2026-08-24_angela_fita_boluda_lin_zhu","bid":0.53,"ask":0.54,"mid":0.535,"spread":0.01,"bid_size":null,"ask_size":null}
{"ts":"2026-08-24T20:47:56.601Z","event_type":"best_bid_ask","market_id":"3823629","outcome_index":1,"market_type":"match","local_side":"away","local_uid":"2026-08-24_angela_fita_boluda_lin_zhu","bid":0.46,"ask":0.47,"mid":0.465,"spread":0.01,"bid_size":null,"ask_size":null}
{"ts":"2026-08-24T20:47:56.601Z","event_type":"price_change","market_id":"3823629","outcome_index":1,"market_type":"match","local_side":"away","local_uid":"2026-08-24_angela_fita_boluda_lin_zhu","bid":0.46,"ask":0.47,"mid":0.465,"spread":0.01,"price":0.46,"size":918.9,"side":"BUY"}
{"ts":"2026-08-24T20:47:56.602Z","event_type":"price_change","market_id":"3823629","outcome_index":0,"market_type":"match","local_side":"home","local_uid":"2026-08-24_angela_fita_boluda_lin_zhu","bid":0.53,"ask":0.54,"mid":0.535,"spread":0.01,"price":0.54,"size":918.9,"side":"SELL"}
{"ts":"2026-08-24T20:47:56.618Z","event_type":"best_bid_ask","market_id":"3824994","outcome_index":0,"market_type":"set2","local_side":"home","local_uid":"2026-08-24_angela_fita_boluda_lin_zhu","bid":0.35,"ask":0.52,"mid":0.435,"spread":0.17,"bid_size":null,"ask_size":null}
{"ts":"2026-08-24T20:47:56.618Z","event_type":"best_bid_ask","market_id":"3824994","outcome_index":1,"market_type":"set2","local_side":"away","local_uid":"2026-08-24_angela_fita_boluda_lin_zhu","bid":0.48,"ask":0.65,"mid":0.565,"spread":0.17,"bid_size":null,"ask_size":null}
{"ts":"2026-08-24T20:47:56.618Z","event_type":"price_change","market_id":"3824994","outcome_index":1,"market_type":"set2","local_side":"away","local_uid":"2026-08-24_angela_fita_boluda_lin_zhu","bid":0.48,"ask":0.65,"mid":0.565,"spread":0.17,"price":0.49,"size":0.0,"side":"BUY"}
{"ts":"2026-08-24T20:47:56.619Z","event_type":"price_change","market_id":"3824994","outcome_index":0,"market_type":"set2","local_side":"home","local_uid":"2026-08-24_angela_fita_boluda_lin_zhu","bid":0.35,"ask":0.52,"mid":0.435,"spread":0.17,"price":0.51,"size":0.0,"side":"SELL"}
{"ts":"2026-08-24T20:47:56.677Z","event_type":"best_bid_ask","market_id":"3826654","outcome_index":0,"market_type":"set2","local_side":"home","local_uid":"2026-08-24_sebastian_gorzny_cruz_hewitt","bid":0.15,"ask":0.25,"mid":0.2,"spread":0.1,"bid_size":null,"ask_size":null}
{"ts":"2026-08-24T20:47:56.678Z","event_type":"best_bid_ask","market_id":"3826654","outcome_index":1,"market_type":"set2","local_side":"away","local_uid":"2026-08-24_sebastian_gorzny_cruz_hewitt","bid":0.75,"ask":0.85,"mid":0.8,"spread":0.1,"bid_size":null,"ask_size":null}
{"ts":"2026-08-24T20:47:56.678Z","event_type":"price_change","market_id":"3826654","outcome_index":0,"market_type":"set2","local_side":"home","local_uid":"2026-08-24_sebastian_gorzny_cruz_hewitt","bid":0.15,"ask":0.25,"mid":0.2,"spread":0.1,"price":0.17,"size":0.0,"side":"BUY"}
{"ts":"2026-08-24T20:47:56.678Z","event_type":"price_change","market_id":"3826654","outcome_index":1,"market_type":"set2","local_side":"away","local_uid":"2026-08-24_sebastian_gorzny_cruz_hewitt","bid":0.75,"ask":0.85,"mid":0.8,"spread":0.1,"price":0.83,"size":0.0,"side":"SELL"}
{"ts":"2026-08-24T20:47:56.692Z","event_type":"best_bid_ask","market_id":"3826654","outcome_index":0,"market_type":"set2","local_side":"home","local_uid":"2026-08-24_sebastian_gorzny_cruz_hewitt","bid":0.17,"ask":0.25,"mid":0.21,"spread":0.08,"bid_size":null,"ask_size":null}
{"ts":"2026-08-24T20:47:56.692Z","event_type":"best_bid_ask","market_id":"3826654","outcome_index":1,"market_type":"set2","local_side":"away","local_uid":"2026-08-24_sebastian_gorzny_cruz_hewitt","bid":0.75,"ask":0.83,"mid":0.79,"spread":0.08,"bid_size":null,"ask_size":null}
{"ts":"2026-08-24T20:47:56.692Z","event_type":"price_change","market_id":"3826654","outcome_index":0,"market_type":"set2","local_side":"home","local_uid":"2026-08-24_sebastian_gorzny_cruz_hewitt","bid":0.17,"ask":0.25,"mid":0.21,"spread":0.08,"price":0.17,"size":1511.0,"side":"BUY"}
{"ts":"2026-08-24T20:47:56.693Z","event_type":"price_change","market_id":"3826654","outcome_index":1,"market_type":"set2","local_side":"away","local_uid":"2026-08-24_sebastian_gorzny_cruz_hewitt","bid":0.75,"ask":0.83,"mid":0.79,"spread":0.08,"price":0.83,"size":1511.0,"side":"SELL"}
{"ts":"2026-08-24T20:47:56.763Z","event_type":"best_bid_ask","market_id":"3823629","outcome_index":0,"market_type":"match","local_side":"home","local_uid":"2026-08-24_angela_fita_boluda_lin_zhu","bid":0.52,"ask":0.54,"mid":0.53,"spread":0.02,"bid_size":null,"ask_size":null}
{"ts":"2026-08-24T20:47:56.763Z","event_type":"best_bid_ask","market_id":"3823629","outcome_index":1,"market_type":"match","local_side":"away","local_uid":"2026-08-24_angela_fita_boluda_lin_zhu","bid":0.46,"ask":0.48,"mid":0.47,"spread":0.02,"bid_size":null,"ask_size":null}
{"ts":"2026-08-24T20:47:56.764Z","event_type":"price_change","market_id":"3823629","outcome_index":0,"market_type":"match","local_side":"home","local_uid":"2026-08-24_angela_fita_boluda_lin_zhu","bid":0.52,"ask":0.54,"mid":0.53,"spread":0.02,"price":0.53,"size":0.0,"side":"BUY"}
{"ts":"2026-08-24T20:47:56.764Z","event_type":"price_change","market_id":"3823629","outcome_index":1,"market_type":"match","local_side":"away","local_uid":"2026-08-24_angela_fita_boluda_lin_zhu","bid":0.46,"ask":0.48,"mid":0.47,"spread":0.02,"price":0.47,"size":0.0,"side":"SELL"}
{"ts":"2026-08-24T20:47:56.860Z","event_type":"best_bid_ask","market_id":"3823629","outcome_index":0,"market_type":"match","local_side":"home","local_uid":"2026-08-24_angela_fita_boluda_lin_zhu","bid":0.51,"ask":0.54,"mid":0.525,"spread":0.03,"bid_size":null,"ask_size":null}
{"ts":"2026-08-24T20:47:56.860Z","event_type":"best_bid_ask","market_id":"3823629","outcome_index":1,"market_type":"match","local_side":"away","local_uid":"2026-08-24_angela_fita_boluda_lin_zhu","bid":0.46,"ask":0.49,"mid":0.475,"spread":0.03,"bid_size":null,"ask_size":null}
{"ts":"2026-08-24T20:47:56.861Z","event_type":"price_change","market_id":"3823629","outcome_index":0,"market_type":"match","local_side":"home","local_uid":"2026-08-24_angela_fita_boluda_lin_zhu","bid":0.51,"ask":0.54,"mid":0.525,"spread":0.03,"price":0.52,"size":0.0,"side":"BUY"}
{"ts":"2026-08-24T20:47:56.861Z","event_type":"price_change","market_id":"3823629","outcome_index":1,"market_type":"match","local_side":"away","local_uid":"2026-08-24_angela_fita_boluda_lin_zhu","bid":0.46,"ask":0.49,"mid":0.475,"spread":0.03,"price":0.48,"size":0.0,"side":"SELL"}
{"ts":"2026-08-24T20:47:57.254Z","event_type":"price_change","market_id":"3823649","outcome_index":0,"market_type":"match","local_side":"home","local_uid":"2026-08-24_caroline_dolehide_veronika_podrez","bid":0.72,"ask":0.73,"mid":0.725,"spread":0.01,"price":0.47,"size":0.0,"side":"BUY"}
{"ts":"2026-08-24T20:47:57.254Z","event_type":"price_change","market_id":"3823649","outcome_index":1,"market_type":"match","local_side":"away","local_uid":"2026-08-24_caroline_dolehide_veronika_podrez","bid":0.27,"ask":0.28,"mid":0.275,"spread":0.01,"price":0.53,"size":0.0,"side":"SELL"}
{"ts":"2026-08-24T20:47:57.283Z","event_type":"best_bid_ask","market_id":"3825051","outcome_index":0,"market_type":"set2","local_side":"home","local_uid":"2026-08-24_robin_montgomery_kayla_cross","bid":0.69,"ask":0.78,"mid":0.735,"spread":0.09,"bid_size":null,"ask_size":null}
{"ts":"2026-08-24T20:47:57.284Z","event_type":"best_bid_ask","market_id":"3825051","outcome_index":1,"market_type":"set2","local_side":"away","local_uid":"2026-08-24_robin_montgomery_kayla_cross","bid":0.22,"ask":0.31,"mid":0.265,"spread":0.09,"bid_size":null,"ask_size":null}
{"ts":"2026-08-24T20:47:57.284Z","event_type":"price_change","market_id":"3825051","outcome_index":1,"market_type":"set2","local_side":"away","local_uid":"2026-08-24_robin_montgomery_kayla_cross","bid":0.22,"ask":0.31,"mid":0.265,"spread":0.09,"price":0.22,"size":50.0,"side":"BUY"}
{"ts":"2026-08-24T20:47:57.284Z","event_type":"price_change","market_id":"3825051","outcome_index":0,"market_type":"set2","local_side":"home","local_uid":"2026-08-24_robin_montgomery_kayla_cross","bid":0.69,"ask":0.78,"mid":0.735,"spread":0.09,"price":0.78,"size":50.0,"side":"SELL"}
{"ts":"2026-08-24T20:47:57.286Z","event_type":"best_bid_ask","market_id":"3823659","outcome_index":0,"market_type":"match","local_side":"home","local_uid":"2026-08-24_victoria_jimenez_kasintseva_francisca_jorge","bid":0.34,"ask":0.37,"mid":0.355,"spread":0.03,"bid_size":null,"ask_size":null}
{"ts":"2026-08-24T20:47:57.286Z","event_type":"best_bid_ask","market_id":"3823659","outcome_index":1,"market_type":"match","local_side":"away","local_uid":"2026-08-24_victoria_jimenez_kasintseva_francisca_jorge","bid":0.63,"ask":0.66,"mid":0.645,"spread":0.03,"bid_size":null,"ask_size":null}
{"ts":"2026-08-24T20:47:57.286Z","event_type":"price_change","market_id":"3823659","outcome_index":1,"market_type":"match","local_side":"away","local_uid":"2026-08-24_victoria_jimenez_kasintseva_francisca_jorge","bid":0.63,"ask":0.66,"mid":0.645,"spread":0.03,"price":0.63,"size":100.0,"side":"BUY"}
{"ts":"2026-08-24T20:47:57.286Z","event_type":"price_change","market_id":"3823659","outcome_index":0,"market_type":"match","local_side":"home","local_uid":"2026-08-24_victoria_jimenez_kasintseva_francisca_jorge","bid":0.34,"ask":0.37,"mid":0.355,"spread":0.03,"price":0.37,"size":100.0,"side":"SELL"}
{"ts":"2026-08-24T20:47:57.287Z","event_type":"best_bid_ask","market_id":"3824796","outcome_index":0,"market_type":"set2","local_side":"home","local_uid":"2026-08-24_victoria_jimenez_kasintseva_francisca_jorge","bid":0.47,"ask":0.66,"mid":0.565,"spread":0.19,"bid_size":null,"ask_size":null}
{"ts":"2026-08-24T20:47:57.287Z","event_type":"best_bid_ask","market_id":"3824796","outcome_index":1,"market_type":"set2","local_side":"away","local_uid":"2026-08-24_victoria_jimenez_kasintseva_francisca_jorge","bid":0.34,"ask":0.53,"mid":0.435,"spread":0.19,"bid_size":null,"ask_size":null}
{"ts":"2026-08-24T20:47:57.288Z","event_type":"price_change","market_id":"3824796","outcome_index":0,"market_type":"set2","local_side":"home","local_uid":"2026-08-24_victoria_jimenez_kasintseva_francisca_jorge","bid":0.47,"ask":0.66,"mid":0.565,"spread":0.19,"price":0.47,"size":423.0,"side":"BUY"}
{"ts":"2026-08-24T20:47:57.288Z","event_type":"price_change","market_id":"3824796","outcome_index":1,"market_type":"set2","local_side":"away","local_uid":"2026-08-24_victoria_jimenez_kasintseva_francisca_jorge","bid":0.34,"ask":0.53,"mid":0.435,"spread":0.19,"price":0.53,"size":423.0,"side":"SELL"}
{"ts":"2026-08-24T20:47:57.292Z","event_type":"best_bid_ask","market_id":"3824796","outcome_index":0,"market_type":"set2","local_side":"home","local_uid":"2026-08-24_victoria_jimenez_kasintseva_francisca_jorge","bid":0.48,"ask":0.66,"mid":0.57,"spread":0.18,"bid_size":null,"ask_size":null}
{"ts":"2026-08-24T20:47:57.292Z","event_type":"best_bid_ask","market_id":"3824796","outcome_index":1,"market_type":"set2","local_side":"away","local_uid":"2026-08-24_victoria_jimenez_kasintseva_francisca_jorge","bid":0.34,"ask":0.52,"mid":0.43,"spread":0.18,"bid_size":null,"ask_size":null}
{"ts":"2026-08-24T20:47:57.293Z","event_type":"price_change","market_id":"3824796","outcome_index":0,"market_type":"set2","local_side":"home","local_uid":"2026-08-24_victoria_jimenez_kasintseva_francisca_jorge","bid":0.48,"ask":0.66,"mid":0.57,"spread":0.18,"price":0.48,"size":88.0,"side":"BUY"}
{"ts":"2026-08-24T20:47:57.293Z","event_type":"price_change","market_id":"3824796","outcome_index":1,"market_type":"set2","local_side":"away","local_uid":"2026-08-24_victoria_jimenez_kasintseva_francisca_jorge","bid":0.34,"ask":0.52,"mid":0.43,"spread":0.18,"price":0.52,"size":88.0,"side":"SELL"}
{"ts":"2026-08-24T20:47:57.304Z","event_type":"best_bid_ask","market_id":"3824796","outcome_index":0,"market_type":"set2","local_side":"home","local_uid":"2026-08-24_victoria_jimenez_kasintseva_francisca_jorge","bid":0.48,"ask":0.65,"mid":0.565,"spread":0.17,"bid_size":null,"ask_size":null}
{"ts":"2026-08-24T20:47:57.305Z","event_type":"best_bid_ask","market_id":"3824796","outcome_index":1,"market_type":"set2","local_side":"away","local_uid":"2026-08-24_victoria_jimenez_kasintseva_francisca_jorge","bid":0.35,"ask":0.52,"mid":0.435,"spread":0.17,"bid_size":null,"ask_size":null}
{"ts":"2026-08-24T20:47:57.305Z","event_type":"price_change","market_id":"3824796","outcome_index":1,"market_type":"set2","local_side":"away","local_uid":"2026-08-24_victoria_jimenez_kasintseva_francisca_jorge","bid":0.35,"ask":0.52,"mid":0.435,"spread":0.17,"price":0.35,"size":423.0,"side":"BUY"}
{"ts":"2026-08-24T20:47:57.305Z","event_type":"price_change","market_id":"3824796","outcome_index":0,"market_type":"set2","local_side":"home","local_uid":"2026-08-24_victoria_jimenez_kasintseva_francisca_jorge","bid":0.48,"ask":0.65,"mid":0.565,"spread":0.17,"price":0.65,"size":423.0,"side":"SELL"}
{"ts":"2026-08-24T20:47:57.306Z","event_type":"best_bid_ask","market_id":"3824796","outcome_index":0,"market_type":"set2","local_side":"home","local_uid":"2026-08-24_victoria_jimenez_kasintseva_francisca_jorge","bid":0.48,"ask":0.64,"mid":0.56,"spread":0.16,"bid_size":null,"ask_size":null}
{"ts":"2026-08-24T20:47:57.306Z","event_type":"best_bid_ask","market_id":"3824796","outcome_index":1,"market_type":"set2","local_side":"away","local_uid":"2026-08-24_victoria_jimenez_kasintseva_francisca_jorge","bid":0.36,"ask":0.52,"mid":0.44,"spread":0.16,"bid_size":null,"ask_size":null}
{"ts":"2026-08-24T20:47:57.306Z","event_type":"price_change","market_id":"3824796","outcome_index":1,"market_type":"set2","local_side":"away","local_uid":"2026-08-24_victoria_jimenez_kasintseva_francisca_jorge","bid":0.36,"ask":0.52,"mid":0.44,"spread":0.16,"price":0.36,"size":423.0,"side":"BUY"}
{"ts":"2026-08-24T20:47:57.307Z","event_type":"price_change","market_id":"3824796","outcome_index":0,"market_type":"set2","local_side":"home","local_uid":"2026-08-24_victoria_jimenez_kasintseva_francisca_jorge","bid":0.48,"ask":0.64,"mid":0.56,"spread":0.16,"price":0.64,"size":423.0,"side":"SELL"}
{"ts":"2026-08-24T20:47:57.307Z","event_type":"best_bid_ask","market_id":"3825053","outcome_index":0,"market_type":"set1","local_side":"home","local_uid":"2026-08-24_robin_montgomery_kayla_cross","bid":0.89,"ask":0.93,"mid":0.91,"spread":0.04,"bid_size":null,"ask_size":null}
{"ts":"2026-08-24T20:47:57.307Z","event_type":"best_bid_ask","market_id":"3825053","outcome_index":1,"market_type":"set1","local_side":"away","local_uid":"2026-08-24_robin_montgomery_kayla_cross","bid":0.07,"ask":0.11,"mid":0.09,"spread":0.04,"bid_size":null,"ask_size":null}
{"ts":"2026-08-24T20:47:57.308Z","event_type":"price_change","market_id":"3825053","outcome_index":0,"market_type":"set1","local_side":"home","local_uid":"2026-08-24_robin_montgomery_kayla_cross","bid":0.89,"ask":0.93,"mid":0.91,"spread":0.04,"price":0.89,"size":150.0,"side":"BUY"}
{"ts":"2026-08-24T20:47:57.308Z","event_type":"price_change","market_id":"3825053","outcome_index":1,"market_type":"set1","local_side":"away","local_uid":"2026-08-24_robin_montgomery_kayla_cross","bid":0.07,"ask":0.11,"mid":0.09,"spread":0.04,"price":0.11,"size":150.0,"side":"SELL"}
{"ts":"2026-08-24T20:47:57.312Z","event_type":"best_bid_ask","market_id":"3824796","outcome_index":0,"market_type":"set2","local_side":"home","local_uid":"2026-08-24_victoria_jimenez_kasintseva_francisca_jorge","bid":0.48,"ask":0.63,"mid":0.555,"spread":0.15,"bid_size":null,"ask_size":null}
{"ts":"2026-08-24T20:47:57.312Z","event_type":"best_bid_ask","market_id":"3824796","outcome_index":1,"market_type":"set2","local_side":"away","local_uid":"2026-08-24_victoria_jimenez_kasintseva_francisca_jorge","bid":0.37,"ask":0.52,"mid":0.445,"spread":0.15,"bid_size":null,"ask_size":null}
{"ts":"2026-08-24T20:47:57.313Z","event_type":"price_change","market_id":"3824796","outcome_index":1,"market_type":"set2","local_side":"away","local_uid":"2026-08-24_victoria_jimenez_kasintseva_francisca_jorge","bid":0.37,"ask":0.52,"mid":0.445,"spread":0.15,"price":0.37,"size":88.0,"side":"BUY"}
{"ts":"2026-08-24T20:47:57.313Z","event_type":"price_change","market_id":"3824796","outcome_index":0,"market_type":"set2","local_side":"home","local_uid":"2026-08-24_victoria_jimenez_kasintseva_francisca_jorge","bid":0.48,"ask":0.63,"mid":0.555,"spread":0.15,"price":0.63,"size":88.0,"side":"SELL"}
{"ts":"2026-08-24T20:47:57.317Z","event_type":"best_bid_ask","market_id":"3824796","outcome_index":0,"market_type":"set2","local_side":"home","local_uid":"2026-08-24_victoria_jimenez_kasintseva_francisca_jorge","bid":0.49,"ask":0.63,"mid":0.56,"spread":0.14,"bid_size":null,"ask_size":null}
{"ts":"2026-08-24T20:47:57.317Z","event_type":"best_bid_ask","market_id":"3824796","outcome_index":1,"market_type":"set2","local_side":"away","local_uid":"2026-08-24_victoria_jimenez_kasintseva_francisca_jorge","bid":0.37,"ask":0.51,"mid":0.44,"spread":0.14,"bid_size":null,"ask_size":null}
{"ts":"2026-08-24T20:47:57.317Z","event_type":"price_change","market_id":"3824796","outcome_index":0,"market_type":"set2","local_side":"home","local_uid":"2026-08-24_victoria_jimenez_kasintseva_francisca_jorge","bid":0.49,"ask":0.63,"mid":0.56,"spread":0.14,"price":0.49,"size":3000.0,"side":"BUY"}
{"ts":"2026-08-24T20:47:57.318Z","event_type":"price_change","market_id":"3824796","outcome_index":1,"market_type":"set2","local_side":"away","local_uid":"2026-08-24_victoria_jimenez_kasintseva_francisca_jorge","bid":0.37,"ask":0.51,"mid":0.44,"spread":0.14,"price":0.51,"size":3000.0,"side":"SELL"}
{"ts":"2026-08-24T20:47:57.335Z","event_type":"best_bid_ask","market_id":"3824796","outcome_index":0,"market_type":"set2","local_side":"home","local_uid":"2026-08-24_victoria_jimenez_kasintseva_francisca_jorge","bid":0.48,"ask":0.63,"mid":0.555,"spread":0.15,"bid_size":null,"ask_size":null}
{"ts":"2026-08-24T20:47:57.335Z","event_type":"best_bid_ask","market_id":"3824796","outcome_index":1,"market_type":"set2","local_side":"away","local_uid":"2026-08-24_victoria_jimenez_kasintseva_francisca_jorge","bid":0.37,"ask":0.52,"mid":0.445,"spread":0.15,"bid_size":null,"ask_size":null}
{"ts":"2026-08-24T20:47:57.335Z","event_type":"price_change","market_id":"3824796","outcome_index":0,"market_type":"set2","local_side":"home","local_uid":"2026-08-24_victoria_jimenez_kasintseva_francisca_jorge","bid":0.48,"ask":0.63,"mid":0.555,"spread":0.15,"price":0.49,"size":0.0,"side":"BUY"}
{"ts":"2026-08-24T20:47:57.336Z","event_type":"price_change","market_id":"3824796","outcome_index":1,"market_type":"set2","local_side":"away","local_uid":"2026-08-24_victoria_jimenez_kasintseva_francisca_jorge","bid":0.37,"ask":0.52,"mid":0.445,"spread":0.15,"price":0.51,"size":0.0,"side":"SELL"}
{"ts":"2026-08-24T20:47:57.344Z","event_type":"best_bid_ask","market_id":"3824796","outcome_index":0,"market_type":"set2","local_side":"home","local_uid":"2026-08-24_victoria_jimenez_kasintseva_francisca_jorge","bid":0.5,"ask":0.63,"mid":0.565,"spread":0.13,"bid_size":null,"ask_size":null}
{"ts":"2026-08-24T20:47:57.345Z","event_type":"best_bid_ask","market_id":"3824796","outcome_index":1,"market_type":"set2","local_side":"away","local_uid":"2026-08-24_victoria_jimenez_kasintseva_francisca_jorge","bid":0.37,"ask":0.5,"mid":0.435,"spread":0.13,"bid_size":null,"ask_size":null}
{"ts":"2026-08-24T20:47:57.346Z","event_type":"price_change","market_id":"3824796","outcome_index":0,"market_type":"set2","local_side":"home","local_uid":"2026-08-24_victoria_jimenez_kasintseva_francisca_jorge","bid":0.5,"ask":0.63,"mid":0.565,"spread":0.13,"price":0.5,"size":3000.0,"side":"BUY"}
{"ts":"2026-08-24T20:47:57.346Z","event_type":"price_change","market_id":"3824796","outcome_index":1,"market_type":"set2","local_side":"away","local_uid":"2026-08-24_victoria_jimenez_kasintseva_francisca_jorge","bid":0.37,"ask":0.5,"mid":0.435,"spread":0.13,"price":0.5,"size":3000.0,"side":"SELL"}
{"ts":"2026-08-24T20:47:57.355Z","event_type":"best_bid_ask","market_id":"3824796","outcome_index":0,"market_type":"set2","local_side":"home","local_uid":"2026-08-24_victoria_jimenez_kasintseva_francisca_jorge","bid":0.5,"ask":0.62,"mid":0.56,"spread":0.12,"bid_size":null,"ask_size":null}
{"ts":"2026-08-24T20:47:57.355Z","event_type":"best_bid_ask","market_id":"3824796","outcome_index":1,"market_type":"set2","local_side":"away","local_uid":"2026-08-24_victoria_jimenez_kasintseva_francisca_jorge","bid":0.38,"ask":0.5,"mid":0.44,"spread":0.12,"bid_size":null,"ask_size":null}
{"ts":"2026-08-24T20:47:57.355Z","event_type":"price_change","market_id":"3824796","outcome_index":1,"market_type":"set2","local_side":"away","local_uid":"2026-08-24_victoria_jimenez_kasintseva_francisca_jorge","bid":0.38,"ask":0.5,"mid":0.44,"spread":0.12,"price":0.38,"size":150.0,"side":"BUY"}
{"ts":"2026-08-24T20:47:57.355Z","event_type":"price_change","market_id":"3824796","outcome_index":0,"market_type":"set2","local_side":"home","local_uid":"2026-08-24_victoria_jimenez_kasintseva_francisca_jorge","bid":0.5,"ask":0.62,"mid":0.56,"spread":0.12,"price":0.62,"size":150.0,"side":"SELL"}
{"ts":"2026-08-24T20:47:57.424Z","event_type":"best_bid_ask","market_id":"3823659","outcome_index":0,"market_type":"match","local_side":"home","local_uid":"2026-08-24_victoria_jimenez_kasintseva_francisca_jorge","bid":0.35,"ask":0.37,"mid":0.36,"spread":0.02,"bid_size":null,"ask_size":null}
{"ts":"2026-08-24T20:47:57.425Z","event_type":"best_bid_ask","market_id":"3823659","outcome_index":1,"market_type":"match","local_side":"away","local_uid":"2026-08-24_victoria_jimenez_kasintseva_francisca_jorge","bid":0.63,"ask":0.65,"mid":0.64,"spread":0.02,"bid_size":null,"ask_size":null}
{"ts":"2026-08-24T20:47:57.425Z","event_type":"price_change","market_id":"3823659","outcome_index":0,"market_type":"match","local_side":"home","local_uid":"2026-08-24_victoria_jimenez_kasintseva_francisca_jorge","bid":0.35,"ask":0.37,"mid":0.36,"spread":0.02,"price":0.35,"size":870.0,"side":"BUY"}
{"ts":"2026-08-24T20:47:57.425Z","event_type":"price_change","market_id":"3823659","outcome_index":1,"market_type":"match","local_side":"away","local_uid":"2026-08-24_victoria_jimenez_kasintseva_francisca_jorge","bid":0.63,"ask":0.65,"mid":0.64,"spread":0.02,"price":0.65,"size":870.0,"side":"SELL"}
{"ts":"2026-08-24T20:47:57.453Z","event_type":"best_bid_ask","market_id":"3802014","outcome_index":0,"market_type":"match","local_side":"home","local_uid":"2026-08-24_edward_winter_andres_andrade","bid":0.07,"ask":0.08,"mid":0.075,"spread":0.01,"bid_size":null,"ask_size":null}
{"ts":"2026-08-24T20:47:57.453Z","event_type":"best_bid_ask","market_id":"3802014","outcome_index":1,"market_type":"match","local_side":"away","local_uid":"2026-08-24_edward_winter_andres_andrade","bid":0.92,"ask":0.93,"mid":0.925,"spread":0.01,"bid_size":null,"ask_size":null}
{"ts":"2026-08-24T20:47:57.454Z","event_type":"price_change","market_id":"3802014","outcome_index":1,"market_type":"match","local_side":"away","local_uid":"2026-08-24_edward_winter_andres_andrade","bid":0.92,"ask":0.93,"mid":0.925,"spread":0.01,"price":0.92,"size":600.0,"side":"BUY"}
{"ts":"2026-08-24T20:47:57.454Z","event_type":"price_change","market_id":"3802014","outcome_index":0,"market_type":"match","local_side":"home","local_uid":"2026-08-24_edward_winter_andres_andrade","bid":0.07,"ask":0.08,"mid":0.075,"spread":0.01,"price":0.08,"size":600.0,"side":"SELL"}
{"ts":"2026-08-24T20:47:57.469Z","event_type":"best_bid_ask","market_id":"3823659","outcome_index":0,"market_type":"match","local_side":"home","local_uid":"2026-08-24_victoria_jimenez_kasintseva_francisca_jorge","bid":0.36,"ask":0.37,"mid":0.365,"spread":0.01,"bid_size":null,"ask_size":null}
{"ts":"2026-08-24T20:47:57.469Z","event_type":"best_bid_ask","market_id":"3823659","outcome_index":1,"market_type":"match","local_side":"away","local_uid":"2026-08-24_victoria_jimenez_kasintseva_francisca_jorge","bid":0.63,"ask":0.64,"mid":0.635,"spread":0.01,"bid_size":null,"ask_size":null}
{"ts":"2026-08-24T20:47:57.469Z","event_type":"price_change","market_id":"3823659","outcome_index":0,"market_type":"match","local_side":"home","local_uid":"2026-08-24_victoria_jimenez_kasintseva_francisca_jorge","bid":0.36,"ask":0.37,"mid":0.365,"spread":0.01,"price":0.36,"size":20.0,"side":"BUY"}
{"ts":"2026-08-24T20:47:57.470Z","event_type":"price_change","market_id":"3823659","outcome_index":1,"market_type":"match","local_side":"away","local_uid":"2026-08-24_victoria_jimenez_kasintseva_francisca_jorge","bid":0.63,"ask":0.64,"mid":0.635,"spread":0.01,"price":0.64,"size":20.0,"side":"SELL"}
{"ts":"2026-08-24T20:47:57.479Z","event_type":"best_bid_ask","market_id":"3802014","outcome_index":0,"market_type":"match","local_side":"home","local_uid":"2026-08-24_edward_winter_andres_andrade","bid":0.07,"ask":0.1,"mid":0.085,"spread":0.03,"bid_size":null,"ask_size":null}
{"ts":"2026-08-24T20:47:57.479Z","event_type":"best_bid_ask","market_id":"3802014","outcome_index":1,"market_type":"match","local_side":"away","local_uid":"2026-08-24_edward_winter_andres_andrade","bid":0.9,"ask":0.93,"mid":0.915,"spread":0.03,"bid_size":null,"ask_size":null}
{"ts":"2026-08-24T20:47:57.480Z","event_type":"price_change","market_id":"3802014","outcome_index":1,"market_type":"match","local_side":"away","local_uid":"2026-08-24_edward_winter_andres_andrade","bid":0.9,"ask":0.93,"mid":0.915,"spread":0.03,"price":0.92,"size":0.0,"side":"BUY"}
{"ts":"2026-08-24T20:47:57.480Z","event_type":"price_change","market_id":"3802014","outcome_index":0,"market_type":"match","local_side":"home","local_uid":"2026-08-24_edward_winter_andres_andrade","bid":0.07,"ask":0.1,"mid":0.085,"spread":0.03,"price":0.08,"size":0.0,"side":"SELL"}
{"ts":"2026-08-24T20:47:57.513Z","event_type":"best_bid_ask","market_id":"3824994","outcome_index":0,"market_type":"set2","local_side":"home","local_uid":"2026-08-24_angela_fita_boluda_lin_zhu","bid":0.34,"ask":0.52,"mid":0.43,"spread":0.18,"bid_size":null,"ask_size":null}
{"ts":"2026-08-24T20:47:57.514Z","event_type":"best_bid_ask","market_id":"3824994","outcome_index":1,"market_type":"set2","local_side":"away","local_uid":"2026-08-24_angela_fita_boluda_lin_zhu","bid":0.48,"ask":0.66,"mid":0.57,"spread":0.18,"bid_size":null,"ask_size":null}
{"ts":"2026-08-24T20:47:57.514Z","event_type":"price_change","market_id":"3824994","outcome_index":0,"market_type":"set2","local_side":"home","local_uid":"2026-08-24_angela_fita_boluda_lin_zhu","bid":0.34,"ask":0.52,"mid":0.43,"spread":0.18,"price":0.35,"size":0.0,"side":"BUY"}
{"ts":"2026-08-24T20:47:57.514Z","event_type":"price_change","market_id":"3824994","outcome_index":1,"market_type":"set2","local_side":"away","local_uid":"2026-08-24_angela_fita_boluda_lin_zhu","bid":0.48,"ask":0.66,"mid":0.57,"spread":0.18,"price":0.65,"size":0.0,"side":"SELL"}
{"ts":"2026-08-24T20:47:57.515Z","event_type":"best_bid_ask","market_id":"3824994","outcome_index":0,"market_type":"set2","local_side":"home","local_uid":"2026-08-24_angela_fita_boluda_lin_zhu","bid":0.32,"ask":0.52,"mid":0.42,"spread":0.2,"bid_size":null,"ask_size":null}
{"ts":"2026-08-24T20:47:57.515Z","event_type":"best_bid_ask","market_id":"3824994","outcome_index":1,"market_type":"set2","local_side":"away","local_uid":"2026-08-24_angela_fita_boluda_lin_zhu","bid":0.48,"ask":0.68,"mid":0.58,"spread":0.2,"bid_size":null,"ask_size":null}
{"ts":"2026-08-24T20:47:57.515Z","event_type":"price_change","market_id":"3824994","outcome_index":0,"market_type":"set2","local_side":"home","local_uid":"2026-08-24_angela_fita_boluda_lin_zhu","bid":0.32,"ask":0.52,"mid":0.42,"spread":0.2,"price":0.34,"size":0.0,"side":"BUY"}
{"ts":"2026-08-24T20:47:57.515Z","event_type":"price_change","market_id":"3824994","outcome_index":1,"market_type":"set2","local_side":"away","local_uid":"2026-08-24_angela_fita_boluda_lin_zhu","bid":0.48,"ask":0.68,"mid":0.58,"spread":0.2,"price":0.66,"size":0.0,"side":"SELL"}
{"ts":"2026-08-24T20:47:57.537Z","event_type":"best_bid_ask","market_id":"3825070","outcome_index":0,"market_type":"set2","local_side":"home","local_uid":"2026-08-24_polina_kudermetova_linda_fruhvirtova","bid":0.53,"ask":0.62,"mid":0.575,"spread":0.09,"bid_size":null,"ask_size":null}
{"ts":"2026-08-24T20:47:57.537Z","event_type":"best_bid_ask","market_id":"3825070","outcome_index":1,"market_type":"set2","local_side":"away","local_uid":"2026-08-24_polina_kudermetova_linda_fruhvirtova","bid":0.38,"ask":0.47,"mid":0.425,"spread":0.09,"bid_size":null,"ask_size":null}
{"ts":"2026-08-24T20:47:57.537Z","event_type":"price_change","market_id":"3825070","outcome_index":1,"market_type":"set2","local_side":"away","local_uid":"2026-08-24_polina_kudermetova_linda_fruhvirtova","bid":0.38,"ask":0.47,"mid":0.425,"spread":0.09,"price":0.39,"size":0.0,"side":"BUY"}
{"ts":"2026-08-24T20:47:57.538Z","event_type":"price_change","market_id":"3825070","outcome_index":0,"market_type":"set2","local_side":"home","local_uid":"2026-08-24_polina_kudermetova_linda_fruhvirtova","bid":0.53,"ask":0.62,"mid":0.575,"spread":0.09,"price":0.61,"size":0.0,"side":"SELL"}
{"ts":"2026-08-24T20:47:57.608Z","event_type":"best_bid_ask","market_id":"3825070","outcome_index":0,"market_type":"set2","local_side":"home","local_uid":"2026-08-24_polina_kudermetova_linda_fruhvirtova","bid":0.53,"ask":0.61,"mid":0.57,"spread":0.08,"bid_size":null,"ask_size":null}
{"ts":"2026-08-24T20:47:57.609Z","event_type":"best_bid_ask","market_id":"3825070","outcome_index":1,"market_type":"set2","local_side":"away","local_uid":"2026-08-24_polina_kudermetova_linda_fruhvirtova","bid":0.39,"ask":0.47,"mid":0.43,"spread":0.08,"bid_size":null,"ask_size":null}
{"ts":"2026-08-24T20:47:57.609Z","event_type":"price_change","market_id":"3825070","outcome_index":1,"market_type":"set2","local_side":"away","local_uid":"2026-08-24_polina_kudermetova_linda_fruhvirtova","bid":0.39,"ask":0.47,"mid":0.43,"spread":0.08,"price":0.39,"size":6.41,"side":"BUY"}
{"ts":"2026-08-24T20:47:57.609Z","event_type":"price_change","market_id":"3825070","outcome_index":0,"market_type":"set2","local_side":"home","local_uid":"2026-08-24_polina_kudermetova_linda_fruhvirtova","bid":0.53,"ask":0.61,"mid":0.57,"spread":0.08,"price":0.61,"size":6.41,"side":"SELL"}
{"ts":"2026-08-24T20:47:57.676Z","event_type":"best_bid_ask","market_id":"3802014","outcome_index":0,"market_type":"match","local_side":"home","local_uid":"2026-08-24_edward_winter_andres_andrade","bid":0.07,"ask":0.09,"mid":0.08,"spread":0.02,"bid_size":null,"ask_size":null}
{"ts":"2026-08-24T20:47:57.677Z","event_type":"best_bid_ask","market_id":"3802014","outcome_index":1,"market_type":"match","local_side":"away","local_uid":"2026-08-24_edward_winter_andres_andrade","bid":0.91,"ask":0.93,"mid":0.92,"spread":0.02,"bid_size":null,"ask_size":null}
{"ts":"2026-08-24T20:47:57.677Z","event_type":"price_change","market_id":"3802014","outcome_index":1,"market_type":"match","local_side":"away","local_uid":"2026-08-24_edward_winter_andres_andrade","bid":0.91,"ask":0.93,"mid":0.92,"spread":0.02,"price":0.91,"size":870.0,"side":"BUY"}
{"ts":"2026-08-24T20:47:57.677Z","event_type":"price_change","market_id":"3802014","outcome_index":0,"market_type":"match","local_side":"home","local_uid":"2026-08-24_edward_winter_andres_andrade","bid":0.07,"ask":0.09,"mid":0.08,"spread":0.02,"price":0.09,"size":870.0,"side":"SELL"}
{"ts":"2026-08-24T20:47:57.711Z","event_type":"best_bid_ask","market_id":"3802014","outcome_index":0,"market_type":"match","local_side":"home","local_uid":"2026-08-24_edward_winter_andres_andrade","bid":0.06,"ask":0.09,"mid":0.075,"spread":0.03,"bid_size":null,"ask_size":null}
{"ts":"2026-08-24T20:47:57.712Z","event_type":"best_bid_ask","market_id":"3802014","outcome_index":1,"market_type":"match","local_side":"away","local_uid":"2026-08-24_edward_winter_andres_andrade","bid":0.91,"ask":0.94,"mid":0.925,"spread":0.03,"bid_size":null,"ask_size":null}
{"ts":"2026-08-24T20:47:57.712Z","event_type":"price_change","market_id":"3802014","outcome_index":1,"market_type":"match","local_side":"away","local_uid":"2026-08-24_edward_winter_andres_andrade","bid":0.91,"ask":0.94,"mid":0.925,"spread":0.03,"price":0.93,"size":0.0,"side":"SELL"}
{"ts":"2026-08-24T20:47:57.712Z","event_type":"price_change","market_id":"3802014","outcome_index":0,"market_type":"match","local_side":"home","local_uid":"2026-08-24_edward_winter_andres_andrade","bid":0.06,"ask":0.09,"mid":0.075,"spread":0.03,"price":0.07,"size":0.0,"side":"BUY"}
{"ts":"2026-08-24T20:47:57.763Z","event_type":"best_bid_ask","market_id":"3802014","outcome_index":0,"market_type":"match","local_side":"home","local_uid":"2026-08-24_edward_winter_andres_andrade","bid":0.06,"ask":0.08,"mid":0.07,"spread":0.02,"bid_size":null,"ask_size":null}
{"ts":"2026-08-24T20:47:57.763Z","event_type":"best_bid_ask","market_id":"3802014","outcome_index":1,"market_type":"match","local_side":"away","local_uid":"2026-08-24_edward_winter_andres_andrade","bid":0.92,"ask":0.94,"mid":0.93,"spread":0.02,"bid_size":null,"ask_size":null}
{"ts":"2026-08-24T20:47:57.763Z","event_type":"price_change","market_id":"3802014","outcome_index":1,"market_type":"match","local_side":"away","local_uid":"2026-08-24_edward_winter_andres_andrade","bid":0.92,"ask":0.94,"mid":0.93,"spread":0.02,"price":0.92,"size":59.0,"side":"BUY"}
{"ts":"2026-08-24T20:47:57.764Z","event_type":"price_change","market_id":"3802014","outcome_index":0,"market_type":"match","local_side":"home","local_uid":"2026-08-24_edward_winter_andres_andrade","bid":0.06,"ask":0.08,"mid":0.07,"spread":0.02,"price":0.08,"size":59.0,"side":"SELL"}
{"ts":"2026-08-24T20:47:57.920Z","event_type":"price_change","market_id":"3825606","outcome_index":0,"market_type":"match","local_side":"home","local_uid":"2026-08-24_keegan_smith_alexis_galarneau","bid":0.43,"ask":0.44,"mid":0.435,"spread":0.01,"price":0.22,"size":0.0,"side":"BUY"}
{"ts":"2026-08-24T20:47:57.921Z","event_type":"price_change","market_id":"3825606","outcome_index":1,"market_type":"match","local_side":"away","local_uid":"2026-08-24_keegan_smith_alexis_galarneau","bid":0.56,"ask":0.57,"mid":0.565,"spread":0.01,"price":0.78,"size":0.0,"side":"SELL"}
{"ts":"2026-08-24T20:47:57.930Z","event_type":"best_bid_ask","market_id":"3802014","outcome_index":0,"market_type":"match","local_side":"home","local_uid":"2026-08-24_edward_winter_andres_andrade","bid":0.06,"ask":0.07,"mid":0.065,"spread":0.01,"bid_size":null,"ask_size":null}
{"ts":"2026-08-24T20:47:57.931Z","event_type":"best_bid_ask","market_id":"3802014","outcome_index":1,"market_type":"match","local_side":"away","local_uid":"2026-08-24_edward_winter_andres_andrade","bid":0.93,"ask":0.94,"mid":0.935,"spread":0.01,"bid_size":null,"ask_size":null}
{"ts":"2026-08-24T20:47:57.931Z","event_type":"price_change","market_id":"3802014","outcome_index":1,"market_type":"match","local_side":"away","local_uid":"2026-08-24_edward_winter_andres_andrade","bid":0.93,"ask":0.94,"mid":0.935,"spread":0.01,"price":0.93,"size":494.47,"side":"BUY"}
{"ts":"2026-08-24T20:47:57.931Z","event_type":"price_change","market_id":"3802014","outcome_index":0,"market_type":"match","local_side":"home","local_uid":"2026-08-24_edward_winter_andres_andrade","bid":0.06,"ask":0.07,"mid":0.065,"spread":0.01,"price":0.07,"size":494.47,"side":"SELL"}
{"ts":"2026-08-24T20:47:58.316Z","event_type":"price_change","market_id":"3823621","outcome_index":0,"market_type":"match","local_side":"home","local_uid":"2026-08-24_carson_branstine_clervie_ngounoue","bid":0.41,"ask":0.42,"mid":0.415,"spread":0.01,"price":0.4,"size":6865.95,"side":"BUY"}
{"ts":"2026-08-24T20:47:58.316Z","event_type":"price_change","market_id":"3823621","outcome_index":1,"market_type":"match","local_side":"away","local_uid":"2026-08-24_carson_branstine_clervie_ngounoue","bid":0.58,"ask":0.59,"mid":0.585,"spread":0.01,"price":0.6,"size":6865.95,"side":"SELL"}
{"ts":"2026-08-24T20:47:58.579Z","event_type":"price_change","market_id":"3825057","outcome_index":0,"market_type":"set1","local_side":"home","local_uid":"2026-08-24_carson_branstine_clervie_ngounoue","bid":0.42,"ask":0.45,"mid":0.435,"spread":0.03,"price":0.42,"size":342.09,"side":"BUY"}
{"ts":"2026-08-24T20:47:58.579Z","event_type":"price_change","market_id":"3825057","outcome_index":1,"market_type":"set1","local_side":"away","local_uid":"2026-08-24_carson_branstine_clervie_ngounoue","bid":0.55,"ask":0.58,"mid":0.565,"spread":0.03,"price":0.58,"size":342.09,"side":"SELL"}
{"ts":"2026-08-24T20:47:58.579Z","event_type":"best_bid_ask","market_id":"3825604","outcome_index":0,"market_type":"match","local_side":"home","local_uid":"2026-08-24_dalibor_svrcina_felipe_meligeni_alves","bid":0.78,"ask":0.83,"mid":0.805,"spread":0.05,"bid_size":null,"ask_size":null}
{"ts":"2026-08-24T20:47:58.580Z","event_type":"best_bid_ask","market_id":"3825604","outcome_index":1,"market_type":"match","local_side":"away","local_uid":"2026-08-24_dalibor_svrcina_felipe_meligeni_alves","bid":0.17,"ask":0.22,"mid":0.195,"spread":0.05,"bid_size":null,"ask_size":null}
{"ts":"2026-08-24T20:47:58.580Z","event_type":"price_change","market_id":"3825604","outcome_index":1,"market_type":"match","local_side":"away","local_uid":"2026-08-24_dalibor_svrcina_felipe_meligeni_alves","bid":0.17,"ask":0.22,"mid":0.195,"spread":0.05,"price":0.17,"size":100.0,"side":"BUY"}
{"ts":"2026-08-24T20:47:58.580Z","event_type":"price_change","market_id":"3825604","outcome_index":0,"market_type":"match","local_side":"home","local_uid":"2026-08-24_dalibor_svrcina_felipe_meligeni_alves","bid":0.78,"ask":0.83,"mid":0.805,"spread":0.05,"price":0.83,"size":100.0,"side":"SELL"}
{"ts":"2026-08-24T20:47:58.589Z","event_type":"best_bid_ask","market_id":"3823623","outcome_index":0,"market_type":"match","local_side":"home","local_uid":"2026-08-24_robin_montgomery_kayla_cross","bid":0.88,"ask":0.89,"mid":0.885,"spread":0.01,"bid_size":null,"ask_size":null}
{"ts":"2026-08-24T20:47:58.589Z","event_type":"best_bid_ask","market_id":"3823623","outcome_index":1,"market_type":"match","local_side":"away","local_uid":"2026-08-24_robin_montgomery_kayla_cross","bid":0.11,"ask":0.12,"mid":0.115,"spread":0.01,"bid_size":null,"ask_size":null}
{"ts":"2026-08-24T20:47:58.590Z","event_type":"price_change","market_id":"3823623","outcome_index":0,"market_type":"match","local_side":"home","local_uid":"2026-08-24_robin_montgomery_kayla_cross","bid":0.88,"ask":0.89,"mid":0.885,"spread":0.01,"price":0.89,"size":25.19,"side":"SELL"}
{"ts":"2026-08-24T20:47:58.590Z","event_type":"price_change","market_id":"3823623","outcome_index":1,"market_type":"match","local_side":"away","local_uid":"2026-08-24_robin_montgomery_kayla_cross","bid":0.11,"ask":0.12,"mid":0.115,"spread":0.01,"price":0.11,"size":25.19,"side":"BUY"}
{"ts":"2026-08-24T20:47:58.592Z","event_type":"best_bid_ask","market_id":"3825070","outcome_index":0,"market_type":"set2","local_side":"home","local_uid":"2026-08-24_polina_kudermetova_linda_fruhvirtova","bid":0.53,"ask":0.62,"mid":0.575,"spread":0.09,"bid_size":null,"ask_size":null}
{"ts":"2026-08-24T20:47:58.592Z","event_type":"best_bid_ask","market_id":"3825070","outcome_index":1,"market_type":"set2","local_side":"away","local_uid":"2026-08-24_polina_kudermetova_linda_fruhvirtova","bid":0.38,"ask":0.47,"mid":0.425,"spread":0.09,"bid_size":null,"ask_size":null}
{"ts":"2026-08-24T20:47:58.593Z","event_type":"price_change","market_id":"3825070","outcome_index":1,"market_type":"set2","local_side":"away","local_uid":"2026-08-24_polina_kudermetova_linda_fruhvirtova","bid":0.38,"ask":0.47,"mid":0.425,"spread":0.09,"price":0.39,"size":0.0,"side":"BUY"}
{"ts":"2026-08-24T20:47:58.593Z","event_type":"price_change","market_id":"3825070","outcome_index":0,"market_type":"set2","local_side":"home","local_uid":"2026-08-24_polina_kudermetova_linda_fruhvirtova","bid":0.53,"ask":0.62,"mid":0.575,"spread":0.09,"price":0.61,"size":0.0,"side":"SELL"}
{"ts":"2026-08-24T20:47:58.608Z","event_type":"best_bid_ask","market_id":"3825070","outcome_index":0,"market_type":"set2","local_side":"home","local_uid":"2026-08-24_polina_kudermetova_linda_fruhvirtova","bid":0.53,"ask":0.61,"mid":0.57,"spread":0.08,"bid_size":null,"ask_size":null}
{"ts":"2026-08-24T20:47:58.608Z","event_type":"best_bid_ask","market_id":"3825070","outcome_index":1,"market_type":"set2","local_side":"away","local_uid":"2026-08-24_polina_kudermetova_linda_fruhvirtova","bid":0.39,"ask":0.47,"mid":0.43,"spread":0.08,"bid_size":null,"ask_size":null}
{"ts":"2026-08-24T20:47:58.608Z","event_type":"price_change","market_id":"3825070","outcome_index":1,"market_type":"set2","local_side":"away","local_uid":"2026-08-24_polina_kudermetova_linda_fruhvirtova","bid":0.39,"ask":0.47,"mid":0.43,"spread":0.08,"price":0.39,"size":6.41,"side":"BUY"}
{"ts":"2026-08-24T20:47:58.608Z","event_type":"price_change","market_id":"3825070","outcome_index":0,"market_type":"set2","local_side":"home","local_uid":"2026-08-24_polina_kudermetova_linda_fruhvirtova","bid":0.53,"ask":0.61,"mid":0.57,"spread":0.08,"price":0.61,"size":6.41,"side":"SELL"}
{"ts":"2026-08-24T20:47:58.616Z","event_type":"best_bid_ask","market_id":"3825604","outcome_index":0,"market_type":"match","local_side":"home","local_uid":"2026-08-24_dalibor_svrcina_felipe_meligeni_alves","bid":0.78,"ask":0.84,"mid":0.81,"spread":0.06,"bid_size":null,"ask_size":null}
{"ts":"2026-08-24T20:47:58.616Z","event_type":"best_bid_ask","market_id":"3825604","outcome_index":1,"market_type":"match","local_side":"away","local_uid":"2026-08-24_dalibor_svrcina_felipe_meligeni_alves","bid":0.16,"ask":0.22,"mid":0.19,"spread":0.06,"bid_size":null,"ask_size":null}
{"ts":"2026-08-24T20:47:58.616Z","event_type":"price_change","market_id":"3825604","outcome_index":1,"market_type":"match","local_side":"away","local_uid":"2026-08-24_dalibor_svrcina_felipe_meligeni_alves","bid":0.16,"ask":0.22,"mid":0.19,"spread":0.06,"price":0.17,"size":0.0,"side":"BUY"}
{"ts":"2026-08-24T20:47:58.617Z","event_type":"price_change","market_id":"3825604","outcome_index":0,"market_type":"match","local_side":"home","local_uid":"2026-08-24_dalibor_svrcina_felipe_meligeni_alves","bid":0.78,"ask":0.84,"mid":0.81,"spread":0.06,"price":0.83,"size":0.0,"side":"SELL"}
{"ts":"2026-08-24T20:47:58.653Z","event_type":"best_bid_ask","market_id":"3825070","outcome_index":0,"market_type":"set2","local_side":"home","local_uid":"2026-08-24_polina_kudermetova_linda_fruhvirtova","bid":0.53,"ask":0.62,"mid":0.575,"spread":0.09,"bid_size":null,"ask_size":null}
{"ts":"2026-08-24T20:47:58.653Z","event_type":"best_bid_ask","market_id":"3825070","outcome_index":1,"market_type":"set2","local_side":"away","local_uid":"2026-08-24_polina_kudermetova_linda_fruhvirtova","bid":0.38,"ask":0.47,"mid":0.425,"spread":0.09,"bid_size":null,"ask_size":null}
{"ts":"2026-08-24T20:47:58.654Z","event_type":"price_change","market_id":"3825070","outcome_index":1,"market_type":"set2","local_side":"away","local_uid":"2026-08-24_polina_kudermetova_linda_fruhvirtova","bid":0.38,"ask":0.47,"mid":0.425,"spread":0.09,"price":0.39,"size":0.0,"side":"BUY"}
{"ts":"2026-08-24T20:47:58.654Z","event_type":"price_change","market_id":"3825070","outcome_index":0,"market_type":"set2","local_side":"home","local_uid":"2026-08-24_polina_kudermetova_linda_fruhvirtova","bid":0.53,"ask":0.62,"mid":0.575,"spread":0.09,"price":0.61,"size":0.0,"side":"SELL"}
{"ts":"2026-08-24T20:47:58.723Z","event_type":"best_bid_ask","market_id":"3825070","outcome_index":0,"market_type":"set2","local_side":"home","local_uid":"2026-08-24_polina_kudermetova_linda_fruhvirtova","bid":0.53,"ask":0.61,"mid":0.57,"spread":0.08,"bid_size":null,"ask_size":null}
{"ts":"2026-08-24T20:47:58.724Z","event_type":"best_bid_ask","market_id":"3825070","outcome_index":1,"market_type":"set2","local_side":"away","local_uid":"2026-08-24_polina_kudermetova_linda_fruhvirtova","bid":0.39,"ask":0.47,"mid":0.43,"spread":0.08,"bid_size":null,"ask_size":null}
{"ts":"2026-08-24T20:47:58.724Z","event_type":"price_change","market_id":"3825070","outcome_index":1,"market_type":"set2","local_side":"away","local_uid":"2026-08-24_polina_kudermetova_linda_fruhvirtova","bid":0.39,"ask":0.47,"mid":0.43,"spread":0.08,"price":0.39,"size":6.41,"side":"BUY"}
{"ts":"2026-08-24T20:47:58.724Z","event_type":"price_change","market_id":"3825070","outcome_index":0,"market_type":"set2","local_side":"home","local_uid":"2026-08-24_polina_kudermetova_linda_fruhvirtova","bid":0.53,"ask":0.61,"mid":0.57,"spread":0.08,"price":0.61,"size":6.41,"side":"SELL"}
{"ts":"2026-08-24T20:47:59.395Z","event_type":"best_bid_ask","market_id":"3823629","outcome_index":0,"market_type":"match","local_side":"home","local_uid":"2026-08-24_angela_fita_boluda_lin_zhu","bid":0.51,"ask":0.57,"mid":0.54,"spread":0.06,"bid_size":null,"ask_size":null}
{"ts":"2026-08-24T20:47:59.396Z","event_type":"best_bid_ask","market_id":"3823629","outcome_index":1,"market_type":"match","local_side":"away","local_uid":"2026-08-24_angela_fita_boluda_lin_zhu","bid":0.43,"ask":0.49,"mid":0.46,"spread":0.06,"bid_size":null,"ask_size":null}
{"ts":"2026-08-24T20:47:59.396Z","event_type":"price_change","market_id":"3823629","outcome_index":1,"market_type":"match","local_side":"away","local_uid":"2026-08-24_angela_fita_boluda_lin_zhu","bid":0.43,"ask":0.49,"mid":0.46,"spread":0.06,"price":0.46,"size":0.0,"side":"BUY"}
{"ts":"2026-08-24T20:47:59.396Z","event_type":"price_change","market_id":"3823629","outcome_index":0,"market_type":"match","local_side":"home","local_uid":"2026-08-24_angela_fita_boluda_lin_zhu","bid":0.51,"ask":0.57,"mid":0.54,"spread":0.06,"price":0.54,"size":0.0,"side":"SELL"}
{"ts":"2026-08-24T20:47:59.424Z","event_type":"best_bid_ask","market_id":"3823629","outcome_index":0,"market_type":"match","local_side":"home","local_uid":"2026-08-24_angela_fita_boluda_lin_zhu","bid":0.52,"ask":0.57,"mid":0.545,"spread":0.05,"bid_size":null,"ask_size":null}
{"ts":"2026-08-24T20:47:59.424Z","event_type":"best_bid_ask","market_id":"3823629","outcome_index":1,"market_type":"match","local_side":"away","local_uid":"2026-08-24_angela_fita_boluda_lin_zhu","bid":0.43,"ask":0.48,"mid":0.455,"spread":0.05,"bid_size":null,"ask_size":null}
{"ts":"2026-08-24T20:47:59.424Z","event_type":"price_change","market_id":"3823629","outcome_index":0,"market_type":"match","local_side":"home","local_uid":"2026-08-24_angela_fita_boluda_lin_zhu","bid":0.52,"ask":0.57,"mid":0.545,"spread":0.05,"price":0.52,"size":20.0,"side":"BUY"}
{"ts":"2026-08-24T20:47:59.424Z","event_type":"price_change","market_id":"3823629","outcome_index":1,"market_type":"match","local_side":"away","local_uid":"2026-08-24_angela_fita_boluda_lin_zhu","bid":0.43,"ask":0.48,"mid":0.455,"spread":0.05,"price":0.48,"size":20.0,"side":"SELL"}
{"ts":"2026-08-24T20:47:59.467Z","event_type":"best_bid_ask","market_id":"3823629","outcome_index":0,"market_type":"match","local_side":"home","local_uid":"2026-08-24_angela_fita_boluda_lin_zhu","bid":0.52,"ask":0.56,"mid":0.54,"spread":0.04,"bid_size":null,"ask_size":null}
{"ts":"2026-08-24T20:47:59.468Z","event_type":"best_bid_ask","market_id":"3823629","outcome_index":1,"market_type":"match","local_side":"away","local_uid":"2026-08-24_angela_fita_boluda_lin_zhu","bid":0.44,"ask":0.48,"mid":0.46,"spread":0.04,"bid_size":null,"ask_size":null}
{"ts":"2026-08-24T20:47:59.468Z","event_type":"price_change","market_id":"3823629","outcome_index":1,"market_type":"match","local_side":"away","local_uid":"2026-08-24_angela_fita_boluda_lin_zhu","bid":0.44,"ask":0.48,"mid":0.46,"spread":0.04,"price":0.44,"size":70.0,"side":"BUY"}
{"ts":"2026-08-24T20:47:59.468Z","event_type":"price_change","market_id":"3823629","outcome_index":0,"market_type":"match","local_side":"home","local_uid":"2026-08-24_angela_fita_boluda_lin_zhu","bid":0.52,"ask":0.56,"mid":0.54,"spread":0.04,"price":0.56,"size":70.0,"side":"SELL"}
{"ts":"2026-08-24T20:47:59.536Z","event_type":"best_bid_ask","market_id":"3825070","outcome_index":0,"market_type":"set2","local_side":"home","local_uid":"2026-08-24_polina_kudermetova_linda_fruhvirtova","bid":0.53,"ask":0.62,"mid":0.575,"spread":0.09,"bid_size":null,"ask_size":null}
{"ts":"2026-08-24T20:47:59.536Z","event_type":"best_bid_ask","market_id":"3825070","outcome_index":1,"market_type":"set2","local_side":"away","local_uid":"2026-08-24_polina_kudermetova_linda_fruhvirtova","bid":0.38,"ask":0.47,"mid":0.425,"spread":0.09,"bid_size":null,"ask_size":null}
{"ts":"2026-08-24T20:47:59.536Z","event_type":"price_change","market_id":"3825070","outcome_index":1,"market_type":"set2","local_side":"away","local_uid":"2026-08-24_polina_kudermetova_linda_fruhvirtova","bid":0.38,"ask":0.47,"mid":0.425,"spread":0.09,"price":0.39,"size":0.0,"side":"BUY"}
{"ts":"2026-08-24T20:47:59.536Z","event_type":"price_change","market_id":"3825070","outcome_index":0,"market_type":"set2","local_side":"home","local_uid":"2026-08-24_polina_kudermetova_linda_fruhvirtova","bid":0.53,"ask":0.62,"mid":0.575,"spread":0.09,"price":0.61,"size":0.0,"side":"SELL"}
{"ts":"2026-08-24T20:47:59.555Z","event_type":"best_bid_ask","market_id":"3823629","outcome_index":0,"market_type":"match","local_side":"home","local_uid":"2026-08-24_angela_fita_boluda_lin_zhu","bid":0.52,"ask":0.54,"mid":0.53,"spread":0.02,"bid_size":null,"ask_size":null}
{"ts":"2026-08-24T20:47:59.555Z","event_type":"best_bid_ask","market_id":"3823629","outcome_index":1,"market_type":"match","local_side":"away","local_uid":"2026-08-24_angela_fita_boluda_lin_zhu","bid":0.46,"ask":0.48,"mid":0.47,"spread":0.02,"bid_size":null,"ask_size":null}
{"ts":"2026-08-24T20:47:59.555Z","event_type":"price_change","market_id":"3823629","outcome_index":1,"market_type":"match","local_side":"away","local_uid":"2026-08-24_angela_fita_boluda_lin_zhu","bid":0.46,"ask":0.48,"mid":0.47,"spread":0.02,"price":0.46,"size":5000.0,"side":"BUY"}
{"ts":"2026-08-24T20:47:59.556Z","event_type":"price_change","market_id":"3823629","outcome_index":0,"market_type":"match","local_side":"home","local_uid":"2026-08-24_angela_fita_boluda_lin_zhu","bid":0.52,"ask":0.54,"mid":0.53,"spread":0.02,"price":0.54,"size":5000.0,"side":"SELL"}
{"ts":"2026-08-24T20:47:59.587Z","event_type":"best_bid_ask","market_id":"3823629","outcome_index":0,"market_type":"match","local_side":"home","local_uid":"2026-08-24_angela_fita_boluda_lin_zhu","bid":0.52,"ask":0.56,"mid":0.54,"spread":0.04,"bid_size":null,"ask_size":null}
{"ts":"2026-08-24T20:47:59.588Z","event_type":"best_bid_ask","market_id":"3823629","outcome_index":1,"market_type":"match","local_side":"away","local_uid":"2026-08-24_angela_fita_boluda_lin_zhu","bid":0.44,"ask":0.48,"mid":0.46,"spread":0.04,"bid_size":null,"ask_size":null}
{"ts":"2026-08-24T20:47:59.588Z","event_type":"price_change","market_id":"3823629","outcome_index":1,"market_type":"match","local_side":"away","local_uid":"2026-08-24_angela_fita_boluda_lin_zhu","bid":0.44,"ask":0.48,"mid":0.46,"spread":0.04,"price":0.46,"size":0.0,"side":"BUY"}
{"ts":"2026-08-24T20:47:59.588Z","event_type":"price_change","market_id":"3823629","outcome_index":0,"market_type":"match","local_side":"home","local_uid":"2026-08-24_angela_fita_boluda_lin_zhu","bid":0.52,"ask":0.56,"mid":0.54,"spread":0.04,"price":0.54,"size":0.0,"side":"SELL"}
{"ts":"2026-08-24T20:47:59.598Z","event_type":"best_bid_ask","market_id":"3823629","outcome_index":0,"market_type":"match","local_side":"home","local_uid":"2026-08-24_angela_fita_boluda_lin_zhu","bid":0.51,"ask":0.56,"mid":0.535,"spread":0.05,"bid_size":null,"ask_size":null}
{"ts":"2026-08-24T20:47:59.598Z","event_type":"best_bid_ask","market_id":"3823629","outcome_index":1,"market_type":"match","local_side":"away","local_uid":"2026-08-24_angela_fita_boluda_lin_zhu","bid":0.44,"ask":0.49,"mid":0.465,"spread":0.05,"bid_size":null,"ask_size":null}
{"ts":"2026-08-24T20:47:59.601Z","event_type":"price_change","market_id":"3823629","outcome_index":0,"market_type":"match","local_side":"home","local_uid":"2026-08-24_angela_fita_boluda_lin_zhu","bid":0.51,"ask":0.56,"mid":0.535,"spread":0.05,"price":0.52,"size":0.0,"side":"BUY"}
{"ts":"2026-08-24T20:47:59.601Z","event_type":"price_change","market_id":"3823629","outcome_index":1,"market_type":"match","local_side":"away","local_uid":"2026-08-24_angela_fita_boluda_lin_zhu","bid":0.44,"ask":0.49,"mid":0.465,"spread":0.05,"price":0.48,"size":0.0,"side":"SELL"}
{"ts":"2026-08-24T20:47:59.603Z","event_type":"best_bid_ask","market_id":"3823629","outcome_index":0,"market_type":"match","local_side":"home","local_uid":"2026-08-24_angela_fita_boluda_lin_zhu","bid":0.51,"ask":0.57,"mid":0.54,"spread":0.06,"bid_size":null,"ask_size":null}
{"ts":"2026-08-24T20:47:59.603Z","event_type":"best_bid_ask","market_id":"3823629","outcome_index":1,"market_type":"match","local_side":"away","local_uid":"2026-08-24_angela_fita_boluda_lin_zhu","bid":0.43,"ask":0.49,"mid":0.46,"spread":0.06,"bid_size":null,"ask_size":null}
{"ts":"2026-08-24T20:47:59.604Z","event_type":"price_change","market_id":"3823629","outcome_index":1,"market_type":"match","local_side":"away","local_uid":"2026-08-24_angela_fita_boluda_lin_zhu","bid":0.43,"ask":0.49,"mid":0.46,"spread":0.06,"price":0.44,"size":0.0,"side":"BUY"}
{"ts":"2026-08-24T20:47:59.604Z","event_type":"price_change","market_id":"3823629","outcome_index":0,"market_type":"match","local_side":"home","local_uid":"2026-08-24_angela_fita_boluda_lin_zhu","bid":0.51,"ask":0.57,"mid":0.54,"spread":0.06,"price":0.56,"size":0.0,"side":"SELL"}
{"ts":"2026-08-24T20:47:59.610Z","event_type":"best_bid_ask","market_id":"3825070","outcome_index":0,"market_type":"set2","local_side":"home","local_uid":"2026-08-24_polina_kudermetova_linda_fruhvirtova","bid":0.53,"ask":0.61,"mid":0.57,"spread":0.08,"bid_size":null,"ask_size":null}
{"ts":"2026-08-24T20:47:59.610Z","event_type":"best_bid_ask","market_id":"3825070","outcome_index":1,"market_type":"set2","local_side":"away","local_uid":"2026-08-24_polina_kudermetova_linda_fruhvirtova","bid":0.39,"ask":0.47,"mid":0.43,"spread":0.08,"bid_size":null,"ask_size":null}
{"ts":"2026-08-24T20:47:59.611Z","event_type":"price_change","market_id":"3825070","outcome_index":1,"market_type":"set2","local_side":"away","local_uid":"2026-08-24_polina_kudermetova_linda_fruhvirtova","bid":0.39,"ask":0.47,"mid":0.43,"spread":0.08,"price":0.39,"size":6.41,"side":"BUY"}
{"ts":"2026-08-24T20:47:59.611Z","event_type":"price_change","market_id":"3825070","outcome_index":0,"market_type":"set2","local_side":"home","local_uid":"2026-08-24_polina_kudermetova_linda_fruhvirtova","bid":0.53,"ask":0.61,"mid":0.57,"spread":0.08,"price":0.61,"size":6.41,"side":"SELL"}
{"ts":"2026-08-24T20:47:59.629Z","event_type":"best_bid_ask","market_id":"3823629","outcome_index":0,"market_type":"match","local_side":"home","local_uid":"2026-08-24_angela_fita_boluda_lin_zhu","bid":0.52,"ask":0.57,"mid":0.545,"spread":0.05,"bid_size":null,"ask_size":null}
{"ts":"2026-08-24T20:47:59.630Z","event_type":"best_bid_ask","market_id":"3823629","outcome_index":1,"market_type":"match","local_side":"away","local_uid":"2026-08-24_angela_fita_boluda_lin_zhu","bid":0.43,"ask":0.48,"mid":0.455,"spread":0.05,"bid_size":null,"ask_size":null}
{"ts":"2026-08-24T20:47:59.630Z","event_type":"price_change","market_id":"3823629","outcome_index":0,"market_type":"match","local_side":"home","local_uid":"2026-08-24_angela_fita_boluda_lin_zhu","bid":0.52,"ask":0.57,"mid":0.545,"spread":0.05,"price":0.52,"size":10.0,"side":"BUY"}
{"ts":"2026-08-24T20:47:59.630Z","event_type":"price_change","market_id":"3823629","outcome_index":1,"market_type":"match","local_side":"away","local_uid":"2026-08-24_angela_fita_boluda_lin_zhu","bid":0.43,"ask":0.48,"mid":0.455,"spread":0.05,"price":0.48,"size":10.0,"side":"SELL"}
{"ts":"2026-08-24T20:47:59.642Z","event_type":"best_bid_ask","market_id":"3823627","outcome_index":0,"market_type":"match","local_side":"home","local_uid":"2026-08-24_claire_liu_heather_watson","bid":0.43,"ask":0.46,"mid":0.445,"spread":0.03,"bid_size":null,"ask_size":null}
{"ts":"2026-08-24T20:47:59.643Z","event_type":"best_bid_ask","market_id":"3823627","outcome_index":1,"market_type":"match","local_side":"away","local_uid":"2026-08-24_claire_liu_heather_watson","bid":0.54,"ask":0.57,"mid":0.555,"spread":0.03,"bid_size":null,"ask_size":null}
{"ts":"2026-08-24T20:47:59.643Z","event_type":"price_change","market_id":"3823627","outcome_index":0,"market_type":"match","local_side":"home","local_uid":"2026-08-24_claire_liu_heather_watson","bid":0.43,"ask":0.46,"mid":0.445,"spread":0.03,"price":0.44,"size":0.0,"side":"BUY"}
{"ts":"2026-08-24T20:47:59.643Z","event_type":"price_change","market_id":"3823627","outcome_index":1,"market_type":"match","local_side":"away","local_uid":"2026-08-24_claire_liu_heather_watson","bid":0.54,"ask":0.57,"mid":0.555,"spread":0.03,"price":0.56,"size":0.0,"side":"SELL"}
{"ts":"2026-08-24T20:47:59.660Z","event_type":"price_change","market_id":"3825635","outcome_index":0,"market_type":"match","local_side":"home","local_uid":"2026-08-24_laslo_djere_alexandre_muller","bid":0.59,"ask":0.6,"mid":0.595,"spread":0.01,"price":0.28,"size":0.0,"side":"BUY"}
{"ts":"2026-08-24T20:47:59.660Z","event_type":"price_change","market_id":"3825635","outcome_index":1,"market_type":"match","local_side":"away","local_uid":"2026-08-24_laslo_djere_alexandre_muller","bid":0.4,"ask":0.41,"mid":0.405,"spread":0.01,"price":0.72,"size":0.0,"side":"SELL"}
{"ts":"2026-08-24T20:47:59.757Z","event_type":"best_bid_ask","market_id":"3823629","outcome_index":0,"market_type":"match","local_side":"home","local_uid":"2026-08-24_angela_fita_boluda_lin_zhu","bid":0.52,"ask":0.56,"mid":0.54,"spread":0.04,"bid_size":null,"ask_size":null}
{"ts":"2026-08-24T20:47:59.757Z","event_type":"best_bid_ask","market_id":"3823629","outcome_index":1,"market_type":"match","local_side":"away","local_uid":"2026-08-24_angela_fita_boluda_lin_zhu","bid":0.44,"ask":0.48,"mid":0.46,"spread":0.04,"bid_size":null,"ask_size":null}
{"ts":"2026-08-24T20:47:59.758Z","event_type":"price_change","market_id":"3823629","outcome_index":1,"market_type":"match","local_side":"away","local_uid":"2026-08-24_angela_fita_boluda_lin_zhu","bid":0.44,"ask":0.48,"mid":0.46,"spread":0.04,"price":0.44,"size":88.0,"side":"BUY"}
{"ts":"2026-08-24T20:47:59.758Z","event_type":"price_change","market_id":"3823629","outcome_index":0,"market_type":"match","local_side":"home","local_uid":"2026-08-24_angela_fita_boluda_lin_zhu","bid":0.52,"ask":0.56,"mid":0.54,"spread":0.04,"price":0.56,"size":88.0,"side":"SELL"}
{"ts":"2026-08-24T20:47:59.763Z","event_type":"best_bid_ask","market_id":"3824994","outcome_index":0,"market_type":"set2","local_side":"home","local_uid":"2026-08-24_angela_fita_boluda_lin_zhu","bid":0.32,"ask":0.45,"mid":0.385,"spread":0.13,"bid_size":null,"ask_size":null}
{"ts":"2026-08-24T20:47:59.763Z","event_type":"best_bid_ask","market_id":"3824994","outcome_index":1,"market_type":"set2","local_side":"away","local_uid":"2026-08-24_angela_fita_boluda_lin_zhu","bid":0.55,"ask":0.68,"mid":0.615,"spread":0.13,"bid_size":null,"ask_size":null}
{"ts":"2026-08-24T20:47:59.763Z","event_type":"price_change","market_id":"3824994","outcome_index":1,"market_type":"set2","local_side":"away","local_uid":"2026-08-24_angela_fita_boluda_lin_zhu","bid":0.55,"ask":0.68,"mid":0.615,"spread":0.13,"price":0.55,"size":88.0,"side":"BUY"}
{"ts":"2026-08-24T20:47:59.764Z","event_type":"price_change","market_id":"3824994","outcome_index":0,"market_type":"set2","local_side":"home","local_uid":"2026-08-24_angela_fita_boluda_lin_zhu","bid":0.32,"ask":0.45,"mid":0.385,"spread":0.13,"price":0.45,"size":88.0,"side":"SELL"}
{"ts":"2026-08-24T20:47:59.790Z","event_type":"best_bid_ask","market_id":"3823629","outcome_index":0,"market_type":"match","local_side":"home","local_uid":"2026-08-24_angela_fita_boluda_lin_zhu","bid":0.52,"ask":0.55,"mid":0.535,"spread":0.03,"bid_size":null,"ask_size":null}
{"ts":"2026-08-24T20:47:59.790Z","event_type":"best_bid_ask","market_id":"3823629","outcome_index":1,"market_type":"match","local_side":"away","local_uid":"2026-08-24_angela_fita_boluda_lin_zhu","bid":0.45,"ask":0.48,"mid":0.465,"spread":0.03,"bid_size":null,"ask_size":null}
{"ts":"2026-08-24T20:47:59.791Z","event_type":"price_change","market_id":"3823629","outcome_index":1,"market_type":"match","local_side":"away","local_uid":"2026-08-24_angela_fita_boluda_lin_zhu","bid":0.45,"ask":0.48,"mid":0.465,"spread":0.03,"price":0.45,"size":150.0,"side":"BUY"}
{"ts":"2026-08-24T20:47:59.791Z","event_type":"price_change","market_id":"3823629","outcome_index":0,"market_type":"match","local_side":"home","local_uid":"2026-08-24_angela_fita_boluda_lin_zhu","bid":0.52,"ask":0.55,"mid":0.535,"spread":0.03,"price":0.55,"size":150.0,"side":"SELL"}
{"ts":"2026-08-24T20:47:59.807Z","event_type":"best_bid_ask","market_id":"3824994","outcome_index":0,"market_type":"set2","local_side":"home","local_uid":"2026-08-24_angela_fita_boluda_lin_zhu","bid":0.32,"ask":0.44,"mid":0.38,"spread":0.12,"bid_size":null,"ask_size":null}
{"ts":"2026-08-24T20:47:59.807Z","event_type":"best_bid_ask","market_id":"3824994","outcome_index":1,"market_type":"set2","local_side":"away","local_uid":"2026-08-24_angela_fita_boluda_lin_zhu","bid":0.56,"ask":0.68,"mid":0.62,"spread":0.12,"bid_size":null,"ask_size":null}
{"ts":"2026-08-24T20:47:59.808Z","event_type":"price_change","market_id":"3824994","outcome_index":1,"market_type":"set2","local_side":"away","local_uid":"2026-08-24_angela_fita_boluda_lin_zhu","bid":0.56,"ask":0.68,"mid":0.62,"spread":0.12,"price":0.56,"size":150.0,"side":"BUY"}
{"ts":"2026-08-24T20:47:59.808Z","event_type":"price_change","market_id":"3824994","outcome_index":0,"market_type":"set2","local_side":"home","local_uid":"2026-08-24_angela_fita_boluda_lin_zhu","bid":0.32,"ask":0.44,"mid":0.38,"spread":0.12,"price":0.44,"size":150.0,"side":"SELL"}
{"ts":"2026-08-24T20:47:59.810Z","event_type":"best_bid_ask","market_id":"3824994","outcome_index":0,"market_type":"set2","local_side":"home","local_uid":"2026-08-24_angela_fita_boluda_lin_zhu","bid":0.32,"ask":0.43,"mid":0.375,"spread":0.11,"bid_size":null,"ask_size":null}
{"ts":"2026-08-24T20:47:59.810Z","event_type":"best_bid_ask","market_id":"3824994","outcome_index":1,"market_type":"set2","local_side":"away","local_uid":"2026-08-24_angela_fita_boluda_lin_zhu","bid":0.57,"ask":0.68,"mid":0.625,"spread":0.11,"bid_size":null,"ask_size":null}
{"ts":"2026-08-24T20:47:59.810Z","event_type":"price_change","market_id":"3824994","outcome_index":1,"market_type":"set2","local_side":"away","local_uid":"2026-08-24_angela_fita_boluda_lin_zhu","bid":0.57,"ask":0.68,"mid":0.625,"spread":0.11,"price":0.57,"size":150.0,"side":"BUY"}
{"ts":"2026-08-24T20:47:59.810Z","event_type":"price_change","market_id":"3824994","outcome_index":0,"market_type":"set2","local_side":"home","local_uid":"2026-08-24_angela_fita_boluda_lin_zhu","bid":0.32,"ask":0.43,"mid":0.375,"spread":0.11,"price":0.43,"size":150.0,"side":"SELL"}
{"ts":"2026-08-24T20:47:59.826Z","event_type":"best_bid_ask","market_id":"3823629","outcome_index":0,"market_type":"match","local_side":"home","local_uid":"2026-08-24_angela_fita_boluda_lin_zhu","bid":0.52,"ask":0.53,"mid":0.525,"spread":0.01,"bid_size":null,"ask_size":null}
{"ts":"2026-08-24T20:47:59.826Z","event_type":"best_bid_ask","market_id":"3823629","outcome_index":1,"market_type":"match","local_side":"away","local_uid":"2026-08-24_angela_fita_boluda_lin_zhu","bid":0.47,"ask":0.48,"mid":0.475,"spread":0.01,"bid_size":null,"ask_size":null}
{"ts":"2026-08-24T20:47:59.826Z","event_type":"price_change","market_id":"3823629","outcome_index":1,"market_type":"match","local_side":"away","local_uid":"2026-08-24_angela_fita_boluda_lin_zhu","bid":0.47,"ask":0.48,"mid":0.475,"spread":0.01,"price":0.47,"size":100.0,"side":"BUY"}
{"ts":"2026-08-24T20:47:59.827Z","event_type":"price_change","market_id":"3823629","outcome_index":0,"market_type":"match","local_side":"home","local_uid":"2026-08-24_angela_fita_boluda_lin_zhu","bid":0.52,"ask":0.53,"mid":0.525,"spread":0.01,"price":0.53,"size":100.0,"side":"SELL"}
{"ts":"2026-08-24T20:47:59.859Z","event_type":"best_bid_ask","market_id":"3823629","outcome_index":0,"market_type":"match","local_side":"home","local_uid":"2026-08-24_angela_fita_boluda_lin_zhu","bid":0.51,"ask":0.53,"mid":0.52,"spread":0.02,"bid_size":null,"ask_size":null}
{"ts":"2026-08-24T20:47:59.859Z","event_type":"best_bid_ask","market_id":"3823629","outcome_index":1,"market_type":"match","local_side":"away","local_uid":"2026-08-24_angela_fita_boluda_lin_zhu","bid":0.47,"ask":0.49,"mid":0.48,"spread":0.02,"bid_size":null,"ask_size":null}
{"ts":"2026-08-24T20:47:59.860Z","event_type":"price_change","market_id":"3823629","outcome_index":0,"market_type":"match","local_side":"home","local_uid":"2026-08-24_angela_fita_boluda_lin_zhu","bid":0.51,"ask":0.53,"mid":0.52,"spread":0.02,"price":0.52,"size":0.0,"side":"BUY"}
{"ts":"2026-08-24T20:47:59.860Z","event_type":"price_change","market_id":"3823629","outcome_index":1,"market_type":"match","local_side":"away","local_uid":"2026-08-24_angela_fita_boluda_lin_zhu","bid":0.47,"ask":0.49,"mid":0.48,"spread":0.02,"price":0.48,"size":0.0,"side":"SELL"}
{"ts":"2026-08-24T20:47:59.897Z","event_type":"price_change","market_id":"3823661","outcome_index":0,"market_type":"match","local_side":"home","local_uid":"2026-08-24_mia_ristic_ayana_akli","bid":0.99,"ask":1.0,"mid":0.995,"spread":0.01,"price":0.01,"size":323560.49,"side":"BUY"}
{"ts":"2026-08-24T20:47:59.897Z","event_type":"price_change","market_id":"3823661","outcome_index":1,"market_type":"match","local_side":"away","local_uid":"2026-08-24_mia_ristic_ayana_akli","bid":0.0,"ask":0.01,"mid":0.005,"spread":0.01,"price":0.99,"size":323560.49,"side":"SELL"}
{"ts":"2026-08-24T20:47:59.981Z","event_type":"best_bid_ask","market_id":"3823629","outcome_index":0,"market_type":"match","local_side":"home","local_uid":"2026-08-24_angela_fita_boluda_lin_zhu","bid":0.51,"ask":0.52,"mid":0.515,"spread":0.01,"bid_size":null,"ask_size":null}
{"ts":"2026-08-24T20:47:59.985Z","event_type":"best_bid_ask","market_id":"3823629","outcome_index":1,"market_type":"match","local_side":"away","local_uid":"2026-08-24_angela_fita_boluda_lin_zhu","bid":0.48,"ask":0.49,"mid":0.485,"spread":0.01,"bid_size":null,"ask_size":null}
{"ts":"2026-08-24T20:47:59.986Z","event_type":"price_change","market_id":"3823629","outcome_index":1,"market_type":"match","local_side":"away","local_uid":"2026-08-24_angela_fita_boluda_lin_zhu","bid":0.48,"ask":0.49,"mid":0.485,"spread":0.01,"price":0.48,"size":158.0,"side":"BUY"}
{"ts":"2026-08-24T20:47:59.986Z","event_type":"price_change","market_id":"3823629","outcome_index":0,"market_type":"match","local_side":"home","local_uid":"2026-08-24_angela_fita_boluda_lin_zhu","bid":0.51,"ask":0.52,"mid":0.515,"spread":0.01,"price":0.52,"size":158.0,"side":"SELL"}
{"ts":"2026-08-24T20:48:00.187Z","event_type":"last_trade_price","market_id":"3825641","outcome_index":1,"market_type":"match","local_side":"away","local_uid":"2026-08-24_sebastian_gorzny_cruz_hewitt","last_trade":0.36,"trade_size":40.5278,"trade_side":"BUY","trade_notional":14.59}
{"ts":"2026-08-24T20:48:00.219Z","event_type":"best_bid_ask","market_id":"3826654","outcome_index":0,"market_type":"set2","local_side":"home","local_uid":"2026-08-24_sebastian_gorzny_cruz_hewitt","bid":0.15,"ask":0.25,"mid":0.2,"spread":0.1,"bid_size":null,"ask_size":null}
{"ts":"2026-08-24T20:48:00.219Z","event_type":"best_bid_ask","market_id":"3826654","outcome_index":1,"market_type":"set2","local_side":"away","local_uid":"2026-08-24_sebastian_gorzny_cruz_hewitt","bid":0.75,"ask":0.85,"mid":0.8,"spread":0.1,"bid_size":null,"ask_size":null}
{"ts":"2026-08-24T20:48:00.220Z","event_type":"price_change","market_id":"3826654","outcome_index":0,"market_type":"set2","local_side":"home","local_uid":"2026-08-24_sebastian_gorzny_cruz_hewitt","bid":0.15,"ask":0.25,"mid":0.2,"spread":0.1,"price":0.17,"size":0.0,"side":"BUY"}
{"ts":"2026-08-24T20:48:00.220Z","event_type":"price_change","market_id":"3826654","outcome_index":1,"market_type":"set2","local_side":"away","local_uid":"2026-08-24_sebastian_gorzny_cruz_hewitt","bid":0.75,"ask":0.85,"mid":0.8,"spread":0.1,"price":0.83,"size":0.0,"side":"SELL"}
{"ts":"2026-08-24T20:48:00.241Z","event_type":"best_bid_ask","market_id":"3826654","outcome_index":0,"market_type":"set2","local_side":"home","local_uid":"2026-08-24_sebastian_gorzny_cruz_hewitt","bid":0.17,"ask":0.25,"mid":0.21,"spread":0.08,"bid_size":null,"ask_size":null}
{"ts":"2026-08-24T20:48:00.241Z","event_type":"best_bid_ask","market_id":"3826654","outcome_index":1,"market_type":"set2","local_side":"away","local_uid":"2026-08-24_sebastian_gorzny_cruz_hewitt","bid":0.75,"ask":0.83,"mid":0.79,"spread":0.08,"bid_size":null,"ask_size":null}
{"ts":"2026-08-24T20:48:00.244Z","event_type":"price_change","market_id":"3826654","outcome_index":0,"market_type":"set2","local_side":"home","local_uid":"2026-08-24_sebastian_gorzny_cruz_hewitt","bid":0.17,"ask":0.25,"mid":0.21,"spread":0.08,"price":0.17,"size":812.0,"side":"BUY"}
{"ts":"2026-08-24T20:48:00.244Z","event_type":"price_change","market_id":"3826654","outcome_index":1,"market_type":"set2","local_side":"away","local_uid":"2026-08-24_sebastian_gorzny_cruz_hewitt","bid":0.75,"ask":0.83,"mid":0.79,"spread":0.08,"price":0.83,"size":812.0,"side":"SELL"}
{"ts":"2026-08-24T20:48:00.280Z","event_type":"best_bid_ask","market_id":"3826654","outcome_index":0,"market_type":"set2","local_side":"home","local_uid":"2026-08-24_sebastian_gorzny_cruz_hewitt","bid":0.15,"ask":0.25,"mid":0.2,"spread":0.1,"bid_size":null,"ask_size":null}
{"ts":"2026-08-24T20:48:00.281Z","event_type":"best_bid_ask","market_id":"3826654","outcome_index":1,"market_type":"set2","local_side":"away","local_uid":"2026-08-24_sebastian_gorzny_cruz_hewitt","bid":0.75,"ask":0.85,"mid":0.8,"spread":0.1,"bid_size":null,"ask_size":null}
{"ts":"2026-08-24T20:48:00.284Z","event_type":"price_change","market_id":"3826654","outcome_index":0,"market_type":"set2","local_side":"home","local_uid":"2026-08-24_sebastian_gorzny_cruz_hewitt","bid":0.15,"ask":0.25,"mid":0.2,"spread":0.1,"price":0.17,"size":0.0,"side":"BUY"}
{"ts":"2026-08-24T20:48:00.284Z","event_type":"price_change","market_id":"3826654","outcome_index":1,"market_type":"set2","local_side":"away","local_uid":"2026-08-24_sebastian_gorzny_cruz_hewitt","bid":0.75,"ask":0.85,"mid":0.8,"spread":0.1,"price":0.83,"size":0.0,"side":"SELL"}
{"ts":"2026-08-24T20:48:00.342Z","event_type":"best_bid_ask","market_id":"3826654","outcome_index":0,"market_type":"set2","local_side":"home","local_uid":"2026-08-24_sebastian_gorzny_cruz_hewitt","bid":0.15,"ask":0.29,"mid":0.22,"spread":0.14,"bid_size":null,"ask_size":null}
{"ts":"2026-08-24T20:48:00.342Z","event_type":"best_bid_ask","market_id":"3826654","outcome_index":1,"market_type":"set2","local_side":"away","local_uid":"2026-08-24_sebastian_gorzny_cruz_hewitt","bid":0.71,"ask":0.85,"mid":0.78,"spread":0.14,"bid_size":null,"ask_size":null}
{"ts":"2026-08-24T20:48:00.345Z","event_type":"price_change","market_id":"3826654","outcome_index":1,"market_type":"set2","local_side":"away","local_uid":"2026-08-24_sebastian_gorzny_cruz_hewitt","bid":0.71,"ask":0.85,"mid":0.78,"spread":0.14,"price":0.75,"size":0.0,"side":"BUY"}
{"ts":"2026-08-24T20:48:00.345Z","event_type":"price_change","market_id":"3826654","outcome_index":0,"market_type":"set2","local_side":"home","local_uid":"2026-08-24_sebastian_gorzny_cruz_hewitt","bid":0.15,"ask":0.29,"mid":0.22,"spread":0.14,"price":0.25,"size":0.0,"side":"SELL"}
{"ts":"2026-08-24T20:48:00.416Z","event_type":"best_bid_ask","market_id":"3826654","outcome_index":0,"market_type":"set2","local_side":"home","local_uid":"2026-08-24_sebastian_gorzny_cruz_hewitt","bid":0.15,"ask":0.28,"mid":0.215,"spread":0.13,"bid_size":null,"ask_size":null}
{"ts":"2026-08-24T20:48:00.416Z","event_type":"best_bid_ask","market_id":"3826654","outcome_index":1,"market_type":"set2","local_side":"away","local_uid":"2026-08-24_sebastian_gorzny_cruz_hewitt","bid":0.72,"ask":0.85,"mid":0.785,"spread":0.13,"bid_size":null,"ask_size":null}
{"ts":"2026-08-24T20:48:00.416Z","event_type":"price_change","market_id":"3826654","outcome_index":1,"market_type":"set2","local_side":"away","local_uid":"2026-08-24_sebastian_gorzny_cruz_hewitt","bid":0.72,"ask":0.85,"mid":0.785,"spread":0.13,"price":0.72,"size":26.0,"side":"BUY"}
{"ts":"2026-08-24T20:48:00.417Z","event_type":"price_change","market_id":"3826654","outcome_index":0,"market_type":"set2","local_side":"home","local_uid":"2026-08-24_sebastian_gorzny_cruz_hewitt","bid":0.15,"ask":0.28,"mid":0.215,"spread":0.13,"price":0.28,"size":26.0,"side":"SELL"}
{"ts":"2026-08-24T20:48:00.417Z","event_type":"best_bid_ask","market_id":"3826654","outcome_index":0,"market_type":"set2","local_side":"home","local_uid":"2026-08-24_sebastian_gorzny_cruz_hewitt","bid":0.14,"ask":0.28,"mid":0.21,"spread":0.14,"bid_size":null,"ask_size":null}
{"ts":"2026-08-24T20:48:00.418Z","event_type":"best_bid_ask","market_id":"3826654","outcome_index":1,"market_type":"set2","local_side":"away","local_uid":"2026-08-24_sebastian_gorzny_cruz_hewitt","bid":0.72,"ask":0.86,"mid":0.79,"spread":0.14,"bid_size":null,"ask_size":null}
{"ts":"2026-08-24T20:48:00.418Z","event_type":"price_change","market_id":"3826654","outcome_index":0,"market_type":"set2","local_side":"home","local_uid":"2026-08-24_sebastian_gorzny_cruz_hewitt","bid":0.14,"ask":0.28,"mid":0.21,"spread":0.14,"price":0.15,"size":0.0,"side":"BUY"}
{"ts":"2026-08-24T20:48:00.418Z","event_type":"price_change","market_id":"3826654","outcome_index":1,"market_type":"set2","local_side":"away","local_uid":"2026-08-24_sebastian_gorzny_cruz_hewitt","bid":0.72,"ask":0.86,"mid":0.79,"spread":0.14,"price":0.85,"size":0.0,"side":"SELL"}
{"ts":"2026-08-24T20:48:00.420Z","event_type":"best_bid_ask","market_id":"3826654","outcome_index":0,"market_type":"set2","local_side":"home","local_uid":"2026-08-24_sebastian_gorzny_cruz_hewitt","bid":0.14,"ask":0.27,"mid":0.205,"spread":0.13,"bid_size":null,"ask_size":null}
{"ts":"2026-08-24T20:48:00.420Z","event_type":"best_bid_ask","market_id":"3826654","outcome_index":1,"market_type":"set2","local_side":"away","local_uid":"2026-08-24_sebastian_gorzny_cruz_hewitt","bid":0.73,"ask":0.86,"mid":0.795,"spread":0.13,"bid_size":null,"ask_size":null}
{"ts":"2026-08-24T20:48:00.421Z","event_type":"price_change","market_id":"3826654","outcome_index":1,"market_type":"set2","local_side":"away","local_uid":"2026-08-24_sebastian_gorzny_cruz_hewitt","bid":0.73,"ask":0.86,"mid":0.795,"spread":0.13,"price":0.73,"size":44.0,"side":"BUY"}
{"ts":"2026-08-24T20:48:00.421Z","event_type":"price_change","market_id":"3826654","outcome_index":0,"market_type":"set2","local_side":"home","local_uid":"2026-08-24_sebastian_gorzny_cruz_hewitt","bid":0.14,"ask":0.27,"mid":0.205,"spread":0.13,"price":0.27,"size":44.0,"side":"SELL"}
{"ts":"2026-08-24T20:48:00.443Z","event_type":"best_bid_ask","market_id":"3826654","outcome_index":0,"market_type":"set2","local_side":"home","local_uid":"2026-08-24_sebastian_gorzny_cruz_hewitt","bid":0.13,"ask":0.27,"mid":0.2,"spread":0.14,"bid_size":null,"ask_size":null}
{"ts":"2026-08-24T20:48:00.443Z","event_type":"best_bid_ask","market_id":"3826654","outcome_index":1,"market_type":"set2","local_side":"away","local_uid":"2026-08-24_sebastian_gorzny_cruz_hewitt","bid":0.73,"ask":0.87,"mid":0.8,"spread":0.14,"bid_size":null,"ask_size":null}
{"ts":"2026-08-24T20:48:00.444Z","event_type":"price_change","market_id":"3826654","outcome_index":0,"market_type":"set2","local_side":"home","local_uid":"2026-08-24_sebastian_gorzny_cruz_hewitt","bid":0.13,"ask":0.27,"mid":0.2,"spread":0.14,"price":0.14,"size":0.0,"side":"BUY"}
{"ts":"2026-08-24T20:48:00.444Z","event_type":"price_change","market_id":"3826654","outcome_index":1,"market_type":"set2","local_side":"away","local_uid":"2026-08-24_sebastian_gorzny_cruz_hewitt","bid":0.73,"ask":0.87,"mid":0.8,"spread":0.14,"price":0.86,"size":0.0,"side":"SELL"}
{"ts":"2026-08-24T20:48:00.524Z","event_type":"best_bid_ask","market_id":"3826654","outcome_index":0,"market_type":"set2","local_side":"home","local_uid":"2026-08-24_sebastian_gorzny_cruz_hewitt","bid":0.1,"ask":0.27,"mid":0.185,"spread":0.17,"bid_size":null,"ask_size":null}
{"ts":"2026-08-24T20:48:00.525Z","event_type":"best_bid_ask","market_id":"3826654","outcome_index":1,"market_type":"set2","local_side":"away","local_uid":"2026-08-24_sebastian_gorzny_cruz_hewitt","bid":0.73,"ask":0.9,"mid":0.815,"spread":0.17,"bid_size":null,"ask_size":null}
{"ts":"2026-08-24T20:48:00.525Z","event_type":"price_change","market_id":"3826654","outcome_index":0,"market_type":"set2","local_side":"home","local_uid":"2026-08-24_sebastian_gorzny_cruz_hewitt","bid":0.1,"ask":0.27,"mid":0.185,"spread":0.17,"price":0.13,"size":0.0,"side":"BUY"}
{"ts":"2026-08-24T20:48:00.525Z","event_type":"price_change","market_id":"3826654","outcome_index":1,"market_type":"set2","local_side":"away","local_uid":"2026-08-24_sebastian_gorzny_cruz_hewitt","bid":0.73,"ask":0.9,"mid":0.815,"spread":0.17,"price":0.87,"size":0.0,"side":"SELL"}
{"ts":"2026-08-24T20:48:00.723Z","event_type":"best_bid_ask","market_id":"3825070","outcome_index":0,"market_type":"set2","local_side":"home","local_uid":"2026-08-24_polina_kudermetova_linda_fruhvirtova","bid":0.53,"ask":0.62,"mid":0.575,"spread":0.09,"bid_size":null,"ask_size":null}
{"ts":"2026-08-24T20:48:00.723Z","event_type":"best_bid_ask","market_id":"3825070","outcome_index":1,"market_type":"set2","local_side":"away","local_uid":"2026-08-24_polina_kudermetova_linda_fruhvirtova","bid":0.38,"ask":0.47,"mid":0.425,"spread":0.09,"bid_size":null,"ask_size":null}
{"ts":"2026-08-24T20:48:00.723Z","event_type":"price_change","market_id":"3825070","outcome_index":1,"market_type":"set2","local_side":"away","local_uid":"2026-08-24_polina_kudermetova_linda_fruhvirtova","bid":0.38,"ask":0.47,"mid":0.425,"spread":0.09,"price":0.39,"size":0.0,"side":"BUY"}
{"ts":"2026-08-24T20:48:00.724Z","event_type":"price_change","market_id":"3825070","outcome_index":0,"market_type":"set2","local_side":"home","local_uid":"2026-08-24_polina_kudermetova_linda_fruhvirtova","bid":0.53,"ask":0.62,"mid":0.575,"spread":0.09,"price":0.61,"size":0.0,"side":"SELL"}
{"ts":"2026-08-24T20:48:00.732Z","event_type":"best_bid_ask","market_id":"3826654","outcome_index":0,"market_type":"set2","local_side":"home","local_uid":"2026-08-24_sebastian_gorzny_cruz_hewitt","bid":0.1,"ask":0.26,"mid":0.18,"spread":0.16,"bid_size":null,"ask_size":null}
{"ts":"2026-08-24T20:48:00.732Z","event_type":"best_bid_ask","market_id":"3826654","outcome_index":1,"market_type":"set2","local_side":"away","local_uid":"2026-08-24_sebastian_gorzny_cruz_hewitt","bid":0.74,"ask":0.9,"mid":0.82,"spread":0.16,"bid_size":null,"ask_size":null}
{"ts":"2026-08-24T20:48:00.732Z","event_type":"price_change","market_id":"3826654","outcome_index":1,"market_type":"set2","local_side":"away","local_uid":"2026-08-24_sebastian_gorzny_cruz_hewitt","bid":0.74,"ask":0.9,"mid":0.82,"spread":0.16,"price":0.74,"size":44.0,"side":"BUY"}
{"ts":"2026-08-24T20:48:00.732Z","event_type":"price_change","market_id":"3826654","outcome_index":0,"market_type":"set2","local_side":"home","local_uid":"2026-08-24_sebastian_gorzny_cruz_hewitt","bid":0.1,"ask":0.26,"mid":0.18,"spread":0.16,"price":0.26,"size":44.0,"side":"SELL"}
{"ts":"2026-08-24T20:48:00.739Z","event_type":"price_change","market_id":"3823657","outcome_index":1,"market_type":"match","local_side":"away","local_uid":"2026-08-24_ekaterine_gorgodze_katarzyna_kawa","bid":0.59,"ask":0.6,"mid":0.595,"spread":0.01,"price":0.5,"size":63.69,"side":"BUY"}
{"ts":"2026-08-24T20:48:00.739Z","event_type":"price_change","market_id":"3823657","outcome_index":0,"market_type":"match","local_side":"home","local_uid":"2026-08-24_ekaterine_gorgodze_katarzyna_kawa","bid":0.4,"ask":0.41,"mid":0.405,"spread":0.01,"price":0.5,"size":63.69,"side":"SELL"}
{"ts":"2026-08-24T20:48:00.742Z","event_type":"best_bid_ask","market_id":"3826654","outcome_index":0,"market_type":"set2","local_side":"home","local_uid":"2026-08-24_sebastian_gorzny_cruz_hewitt","bid":0.08,"ask":0.26,"mid":0.17,"spread":0.18,"bid_size":null,"ask_size":null}
{"ts":"2026-08-24T20:48:00.742Z","event_type":"best_bid_ask","market_id":"3826654","outcome_index":1,"market_type":"set2","local_side":"away","local_uid":"2026-08-24_sebastian_gorzny_cruz_hewitt","bid":0.74,"ask":0.92,"mid":0.83,"spread":0.18,"bid_size":null,"ask_size":null}
{"ts":"2026-08-24T20:48:00.742Z","event_type":"price_change","market_id":"3826654","outcome_index":0,"market_type":"set2","local_side":"home","local_uid":"2026-08-24_sebastian_gorzny_cruz_hewitt","bid":0.08,"ask":0.26,"mid":0.17,"spread":0.18,"price":0.1,"size":0.0,"side":"BUY"}
{"ts":"2026-08-24T20:48:00.742Z","event_type":"price_change","market_id":"3826654","outcome_index":1,"market_type":"set2","local_side":"away","local_uid":"2026-08-24_sebastian_gorzny_cruz_hewitt","bid":0.74,"ask":0.92,"mid":0.83,"spread":0.18,"price":0.9,"size":0.0,"side":"SELL"}
{"ts":"2026-08-24T20:48:00.744Z","event_type":"best_bid_ask","market_id":"3826654","outcome_index":0,"market_type":"set2","local_side":"home","local_uid":"2026-08-24_sebastian_gorzny_cruz_hewitt","bid":0.08,"ask":0.28,"mid":0.18,"spread":0.2,"bid_size":null,"ask_size":null}
{"ts":"2026-08-24T20:48:00.745Z","event_type":"best_bid_ask","market_id":"3826654","outcome_index":1,"market_type":"set2","local_side":"away","local_uid":"2026-08-24_sebastian_gorzny_cruz_hewitt","bid":0.72,"ask":0.92,"mid":0.82,"spread":0.2,"bid_size":null,"ask_size":null}
{"ts":"2026-08-24T20:48:00.745Z","event_type":"price_change","market_id":"3826654","outcome_index":1,"market_type":"set2","local_side":"away","local_uid":"2026-08-24_sebastian_gorzny_cruz_hewitt","bid":0.72,"ask":0.92,"mid":0.82,"spread":0.2,"price":0.74,"size":0.0,"side":"BUY"}
{"ts":"2026-08-24T20:48:00.745Z","event_type":"price_change","market_id":"3826654","outcome_index":0,"market_type":"set2","local_side":"home","local_uid":"2026-08-24_sebastian_gorzny_cruz_hewitt","bid":0.08,"ask":0.28,"mid":0.18,"spread":0.2,"price":0.26,"size":0.0,"side":"SELL"}
{"ts":"2026-08-24T20:48:00.746Z","event_type":"best_bid_ask","market_id":"3826654","outcome_index":0,"market_type":"set2","local_side":"home","local_uid":"2026-08-24_sebastian_gorzny_cruz_hewitt","bid":0.08,"ask":0.39,"mid":0.235,"spread":0.31,"bid_size":null,"ask_size":null}
{"ts":"2026-08-24T20:48:00.747Z","event_type":"best_bid_ask","market_id":"3826654","outcome_index":1,"market_type":"set2","local_side":"away","local_uid":"2026-08-24_sebastian_gorzny_cruz_hewitt","bid":0.61,"ask":0.92,"mid":0.765,"spread":0.31,"bid_size":null,"ask_size":null}
{"ts":"2026-08-24T20:48:00.747Z","event_type":"price_change","market_id":"3826654","outcome_index":1,"market_type":"set2","local_side":"away","local_uid":"2026-08-24_sebastian_gorzny_cruz_hewitt","bid":0.61,"ask":0.92,"mid":0.765,"spread":0.31,"price":0.72,"size":0.0,"side":"BUY"}
{"ts":"2026-08-24T20:48:00.747Z","event_type":"price_change","market_id":"3826654","outcome_index":0,"market_type":"set2","local_side":"home","local_uid":"2026-08-24_sebastian_gorzny_cruz_hewitt","bid":0.08,"ask":0.39,"mid":0.235,"spread":0.31,"price":0.28,"size":0.0,"side":"SELL"}
{"ts":"2026-08-24T20:48:00.748Z","event_type":"best_bid_ask","market_id":"3825070","outcome_index":0,"market_type":"set2","local_side":"home","local_uid":"2026-08-24_polina_kudermetova_linda_fruhvirtova","bid":0.53,"ask":0.61,"mid":0.57,"spread":0.08,"bid_size":null,"ask_size":null}
{"ts":"2026-08-24T20:48:00.748Z","event_type":"best_bid_ask","market_id":"3825070","outcome_index":1,"market_type":"set2","local_side":"away","local_uid":"2026-08-24_polina_kudermetova_linda_fruhvirtova","bid":0.39,"ask":0.47,"mid":0.43,"spread":0.08,"bid_size":null,"ask_size":null}
{"ts":"2026-08-24T20:48:00.748Z","event_type":"price_change","market_id":"3825070","outcome_index":1,"market_type":"set2","local_side":"away","local_uid":"2026-08-24_polina_kudermetova_linda_fruhvirtova","bid":0.39,"ask":0.47,"mid":0.43,"spread":0.08,"price":0.39,"size":6.41,"side":"BUY"}
{"ts":"2026-08-24T20:48:00.749Z","event_type":"price_change","market_id":"3825070","outcome_index":0,"market_type":"set2","local_side":"home","local_uid":"2026-08-24_polina_kudermetova_linda_fruhvirtova","bid":0.53,"ask":0.61,"mid":0.57,"spread":0.08,"price":0.61,"size":6.41,"side":"SELL"}
{"ts":"2026-08-24T20:48:00.751Z","event_type":"best_bid_ask","market_id":"3826654","outcome_index":0,"market_type":"set2","local_side":"home","local_uid":"2026-08-24_sebastian_gorzny_cruz_hewitt","bid":0.08,"ask":1.0,"mid":0.54,"spread":0.92,"bid_size":null,"ask_size":null}
{"ts":"2026-08-24T20:48:00.752Z","event_type":"best_bid_ask","market_id":"3826654","outcome_index":1,"market_type":"set2","local_side":"away","local_uid":"2026-08-24_sebastian_gorzny_cruz_hewitt","bid":0.0,"ask":0.92,"mid":0.46,"spread":0.92,"bid_size":null,"ask_size":null}
{"ts":"2026-08-24T20:48:00.752Z","event_type":"price_change","market_id":"3826654","outcome_index":1,"market_type":"set2","local_side":"away","local_uid":"2026-08-24_sebastian_gorzny_cruz_hewitt","bid":0.0,"ask":0.92,"mid":0.46,"spread":0.92,"price":0.61,"size":0.0,"side":"BUY"}
{"ts":"2026-08-24T20:48:00.752Z","event_type":"price_change","market_id":"3826654","outcome_index":0,"market_type":"set2","local_side":"home","local_uid":"2026-08-24_sebastian_gorzny_cruz_hewitt","bid":0.08,"ask":1.0,"mid":0.54,"spread":0.92,"price":0.39,"size":0.0,"side":"SELL"}
{"ts":"2026-08-24T20:48:00.754Z","event_type":"best_bid_ask","market_id":"3826654","outcome_index":0,"market_type":"set2","local_side":"home","local_uid":"2026-08-24_sebastian_gorzny_cruz_hewitt","bid":0.08,"ask":0.28,"mid":0.18,"spread":0.2,"bid_size":null,"ask_size":null}
{"ts":"2026-08-24T20:48:00.754Z","event_type":"best_bid_ask","market_id":"3826654","outcome_index":1,"market_type":"set2","local_side":"away","local_uid":"2026-08-24_sebastian_gorzny_cruz_hewitt","bid":0.72,"ask":0.92,"mid":0.82,"spread":0.2,"bid_size":null,"ask_size":null}
{"ts":"2026-08-24T20:48:00.755Z","event_type":"price_change","market_id":"3826654","outcome_index":1,"market_type":"set2","local_side":"away","local_uid":"2026-08-24_sebastian_gorzny_cruz_hewitt","bid":0.72,"ask":0.92,"mid":0.82,"spread":0.2,"price":0.72,"size":26.0,"side":"BUY"}
{"ts":"2026-08-24T20:48:00.755Z","event_type":"price_change","market_id":"3826654","outcome_index":0,"market_type":"set2","local_side":"home","local_uid":"2026-08-24_sebastian_gorzny_cruz_hewitt","bid":0.08,"ask":0.28,"mid":0.18,"spread":0.2,"price":0.28,"size":26.0,"side":"SELL"}
{"ts":"2026-08-24T20:48:00.760Z","event_type":"best_bid_ask","market_id":"3826654","outcome_index":0,"market_type":"set2","local_side":"home","local_uid":"2026-08-24_sebastian_gorzny_cruz_hewitt","bid":0.07,"ask":0.28,"mid":0.175,"spread":0.21,"bid_size":null,"ask_size":null}
{"ts":"2026-08-24T20:48:00.760Z","event_type":"best_bid_ask","market_id":"3826654","outcome_index":1,"market_type":"set2","local_side":"away","local_uid":"2026-08-24_sebastian_gorzny_cruz_hewitt","bid":0.72,"ask":0.93,"mid":0.825,"spread":0.21,"bid_size":null,"ask_size":null}
{"ts":"2026-08-24T20:48:00.761Z","event_type":"price_change","market_id":"3826654","outcome_index":0,"market_type":"set2","local_side":"home","local_uid":"2026-08-24_sebastian_gorzny_cruz_hewitt","bid":0.07,"ask":0.28,"mid":0.175,"spread":0.21,"price":0.08,"size":0.0,"side":"BUY"}
{"ts":"2026-08-24T20:48:00.761Z","event_type":"price_change","market_id":"3826654","outcome_index":1,"market_type":"set2","local_side":"away","local_uid":"2026-08-24_sebastian_gorzny_cruz_hewitt","bid":0.72,"ask":0.93,"mid":0.825,"spread":0.21,"price":0.92,"size":0.0,"side":"SELL"}
{"ts":"2026-08-24T20:48:00.773Z","event_type":"best_bid_ask","market_id":"3826654","outcome_index":0,"market_type":"set2","local_side":"home","local_uid":"2026-08-24_sebastian_gorzny_cruz_hewitt","bid":0.06,"ask":0.28,"mid":0.17,"spread":0.22,"bid_size":null,"ask_size":null}
{"ts":"2026-08-24T20:48:00.773Z","event_type":"best_bid_ask","market_id":"3826654","outcome_index":1,"market_type":"set2","local_side":"away","local_uid":"2026-08-24_sebastian_gorzny_cruz_hewitt","bid":0.72,"ask":0.94,"mid":0.83,"spread":0.22,"bid_size":null,"ask_size":null}
{"ts":"2026-08-24T20:48:00.774Z","event_type":"price_change","market_id":"3826654","outcome_index":0,"market_type":"set2","local_side":"home","local_uid":"2026-08-24_sebastian_gorzny_cruz_hewitt","bid":0.06,"ask":0.28,"mid":0.17,"spread":0.22,"price":0.07,"size":0.0,"side":"BUY"}
{"ts":"2026-08-24T20:48:00.774Z","event_type":"price_change","market_id":"3826654","outcome_index":1,"market_type":"set2","local_side":"away","local_uid":"2026-08-24_sebastian_gorzny_cruz_hewitt","bid":0.72,"ask":0.94,"mid":0.83,"spread":0.22,"price":0.93,"size":0.0,"side":"SELL"}
{"ts":"2026-08-24T20:48:00.774Z","event_type":"best_bid_ask","market_id":"3826654","outcome_index":0,"market_type":"set2","local_side":"home","local_uid":"2026-08-24_sebastian_gorzny_cruz_hewitt","bid":0.05,"ask":0.28,"mid":0.165,"spread":0.23,"bid_size":null,"ask_size":null}
{"ts":"2026-08-24T20:48:00.774Z","event_type":"best_bid_ask","market_id":"3826654","outcome_index":1,"market_type":"set2","local_side":"away","local_uid":"2026-08-24_sebastian_gorzny_cruz_hewitt","bid":0.72,"ask":0.95,"mid":0.835,"spread":0.23,"bid_size":null,"ask_size":null}
{"ts":"2026-08-24T20:48:00.775Z","event_type":"price_change","market_id":"3826654","outcome_index":0,"market_type":"set2","local_side":"home","local_uid":"2026-08-24_sebastian_gorzny_cruz_hewitt","bid":0.05,"ask":0.28,"mid":0.165,"spread":0.23,"price":0.06,"size":0.0,"side":"BUY"}
{"ts":"2026-08-24T20:48:00.775Z","event_type":"price_change","market_id":"3826654","outcome_index":1,"market_type":"set2","local_side":"away","local_uid":"2026-08-24_sebastian_gorzny_cruz_hewitt","bid":0.72,"ask":0.95,"mid":0.835,"spread":0.23,"price":0.94,"size":0.0,"side":"SELL"}
{"ts":"2026-08-24T20:48:00.775Z","event_type":"best_bid_ask","market_id":"3826654","outcome_index":0,"market_type":"set2","local_side":"home","local_uid":"2026-08-24_sebastian_gorzny_cruz_hewitt","bid":0.09,"ask":0.28,"mid":0.185,"spread":0.19,"bid_size":null,"ask_size":null}
{"ts":"2026-08-24T20:48:00.776Z","event_type":"best_bid_ask","market_id":"3826654","outcome_index":1,"market_type":"set2","local_side":"away","local_uid":"2026-08-24_sebastian_gorzny_cruz_hewitt","bid":0.72,"ask":0.91,"mid":0.815,"spread":0.19,"bid_size":null,"ask_size":null}
{"ts":"2026-08-24T20:48:00.776Z","event_type":"price_change","market_id":"3826654","outcome_index":0,"market_type":"set2","local_side":"home","local_uid":"2026-08-24_sebastian_gorzny_cruz_hewitt","bid":0.09,"ask":0.28,"mid":0.185,"spread":0.19,"price":0.09,"size":44.0,"side":"BUY"}
{"ts":"2026-08-24T20:48:00.776Z","event_type":"price_change","market_id":"3826654","outcome_index":1,"market_type":"set2","local_side":"away","local_uid":"2026-08-24_sebastian_gorzny_cruz_hewitt","bid":0.72,"ask":0.91,"mid":0.815,"spread":0.19,"price":0.91,"size":44.0,"side":"SELL"}
{"ts":"2026-08-24T20:48:00.793Z","event_type":"best_bid_ask","market_id":"3825070","outcome_index":0,"market_type":"set2","local_side":"home","local_uid":"2026-08-24_polina_kudermetova_linda_fruhvirtova","bid":0.52,"ask":0.61,"mid":0.565,"spread":0.09,"bid_size":null,"ask_size":null}
{"ts":"2026-08-24T20:48:00.793Z","event_type":"best_bid_ask","market_id":"3825070","outcome_index":1,"market_type":"set2","local_side":"away","local_uid":"2026-08-24_polina_kudermetova_linda_fruhvirtova","bid":0.39,"ask":0.48,"mid":0.435,"spread":0.09,"bid_size":null,"ask_size":null}
{"ts":"2026-08-24T20:48:00.794Z","event_type":"price_change","market_id":"3825070","outcome_index":0,"market_type":"set2","local_side":"home","local_uid":"2026-08-24_polina_kudermetova_linda_fruhvirtova","bid":0.52,"ask":0.61,"mid":0.565,"spread":0.09,"price":0.53,"size":0.0,"side":"BUY"}
{"ts":"2026-08-24T20:48:00.794Z","event_type":"price_change","market_id":"3825070","outcome_index":1,"market_type":"set2","local_side":"away","local_uid":"2026-08-24_polina_kudermetova_linda_fruhvirtova","bid":0.39,"ask":0.48,"mid":0.435,"spread":0.09,"price":0.47,"size":0.0,"side":"SELL"}
{"ts":"2026-08-24T20:48:00.798Z","event_type":"best_bid_ask","market_id":"3826654","outcome_index":0,"market_type":"set2","local_side":"home","local_uid":"2026-08-24_sebastian_gorzny_cruz_hewitt","bid":0.08,"ask":0.28,"mid":0.18,"spread":0.2,"bid_size":null,"ask_size":null}
{"ts":"2026-08-24T20:48:00.799Z","event_type":"best_bid_ask","market_id":"3826654","outcome_index":1,"market_type":"set2","local_side":"away","local_uid":"2026-08-24_sebastian_gorzny_cruz_hewitt","bid":0.72,"ask":0.92,"mid":0.82,"spread":0.2,"bid_size":null,"ask_size":null}
{"ts":"2026-08-24T20:48:00.799Z","event_type":"price_change","market_id":"3826654","outcome_index":0,"market_type":"set2","local_side":"home","local_uid":"2026-08-24_sebastian_gorzny_cruz_hewitt","bid":0.08,"ask":0.28,"mid":0.18,"spread":0.2,"price":0.09,"size":0.0,"side":"BUY"}
{"ts":"2026-08-24T20:48:00.799Z","event_type":"price_change","market_id":"3826654","outcome_index":1,"market_type":"set2","local_side":"away","local_uid":"2026-08-24_sebastian_gorzny_cruz_hewitt","bid":0.72,"ask":0.92,"mid":0.82,"spread":0.2,"price":0.91,"size":0.0,"side":"SELL"}
{"ts":"2026-08-24T20:48:00.800Z","event_type":"best_bid_ask","market_id":"3826654","outcome_index":0,"market_type":"set2","local_side":"home","local_uid":"2026-08-24_sebastian_gorzny_cruz_hewitt","bid":0.06,"ask":0.28,"mid":0.17,"spread":0.22,"bid_size":null,"ask_size":null}
{"ts":"2026-08-24T20:48:00.800Z","event_type":"best_bid_ask","market_id":"3826654","outcome_index":1,"market_type":"set2","local_side":"away","local_uid":"2026-08-24_sebastian_gorzny_cruz_hewitt","bid":0.72,"ask":0.94,"mid":0.83,"spread":0.22,"bid_size":null,"ask_size":null}
{"ts":"2026-08-24T20:48:00.801Z","event_type":"price_change","market_id":"3826654","outcome_index":0,"market_type":"set2","local_side":"home","local_uid":"2026-08-24_sebastian_gorzny_cruz_hewitt","bid":0.06,"ask":0.28,"mid":0.17,"spread":0.22,"price":0.08,"size":0.0,"side":"BUY"}
{"ts":"2026-08-24T20:48:00.801Z","event_type":"price_change","market_id":"3826654","outcome_index":1,"market_type":"set2","local_side":"away","local_uid":"2026-08-24_sebastian_gorzny_cruz_hewitt","bid":0.72,"ask":0.94,"mid":0.83,"spread":0.22,"price":0.92,"size":0.0,"side":"SELL"}
{"ts":"2026-08-24T20:48:00.802Z","event_type":"best_bid_ask","market_id":"3826654","outcome_index":0,"market_type":"set2","local_side":"home","local_uid":"2026-08-24_sebastian_gorzny_cruz_hewitt","bid":0.0,"ask":0.28,"mid":0.14,"spread":0.28,"bid_size":null,"ask_size":null}
{"ts":"2026-08-24T20:48:00.802Z","event_type":"best_bid_ask","market_id":"3826654","outcome_index":1,"market_type":"set2","local_side":"away","local_uid":"2026-08-24_sebastian_gorzny_cruz_hewitt","bid":0.72,"ask":1.0,"mid":0.86,"spread":0.28,"bid_size":null,"ask_size":null}
{"ts":"2026-08-24T20:48:00.803Z","event_type":"price_change","market_id":"3826654","outcome_index":0,"market_type":"set2","local_side":"home","local_uid":"2026-08-24_sebastian_gorzny_cruz_hewitt","bid":0.0,"ask":0.28,"mid":0.14,"spread":0.28,"price":0.06,"size":0.0,"side":"BUY"}
{"ts":"2026-08-24T20:48:00.803Z","event_type":"price_change","market_id":"3826654","outcome_index":1,"market_type":"set2","local_side":"away","local_uid":"2026-08-24_sebastian_gorzny_cruz_hewitt","bid":0.72,"ask":1.0,"mid":0.86,"spread":0.28,"price":0.94,"size":0.0,"side":"SELL"}
{"ts":"2026-08-24T20:48:00.804Z","event_type":"best_bid_ask","market_id":"3826654","outcome_index":0,"market_type":"set2","local_side":"home","local_uid":"2026-08-24_sebastian_gorzny_cruz_hewitt","bid":0.07,"ask":0.28,"mid":0.175,"spread":0.21,"bid_size":null,"ask_size":null}
{"ts":"2026-08-24T20:48:00.805Z","event_type":"best_bid_ask","market_id":"3826654","outcome_index":1,"market_type":"set2","local_side":"away","local_uid":"2026-08-24_sebastian_gorzny_cruz_hewitt","bid":0.72,"ask":0.93,"mid":0.825,"spread":0.21,"bid_size":null,"ask_size":null}
{"ts":"2026-08-24T20:48:00.805Z","event_type":"price_change","market_id":"3826654","outcome_index":0,"market_type":"set2","local_side":"home","local_uid":"2026-08-24_sebastian_gorzny_cruz_hewitt","bid":0.07,"ask":0.28,"mid":0.175,"spread":0.21,"price":0.07,"size":11.0,"side":"BUY"}
{"ts":"2026-08-24T20:48:00.805Z","event_type":"price_change","market_id":"3826654","outcome_index":1,"market_type":"set2","local_side":"away","local_uid":"2026-08-24_sebastian_gorzny_cruz_hewitt","bid":0.72,"ask":0.93,"mid":0.825,"spread":0.21,"price":0.93,"size":11.0,"side":"SELL"}
{"ts":"2026-08-24T20:48:00.809Z","event_type":"best_bid_ask","market_id":"3825070","outcome_index":0,"market_type":"set2","local_side":"home","local_uid":"2026-08-24_polina_kudermetova_linda_fruhvirtova","bid":0.52,"ask":0.62,"mid":0.57,"spread":0.1,"bid_size":null,"ask_size":null}
{"ts":"2026-08-24T20:48:00.809Z","event_type":"best_bid_ask","market_id":"3825070","outcome_index":1,"market_type":"set2","local_side":"away","local_uid":"2026-08-24_polina_kudermetova_linda_fruhvirtova","bid":0.38,"ask":0.48,"mid":0.43,"spread":0.1,"bid_size":null,"ask_size":null}
{"ts":"2026-08-24T20:48:00.809Z","event_type":"price_change","market_id":"3825070","outcome_index":1,"market_type":"set2","local_side":"away","local_uid":"2026-08-24_polina_kudermetova_linda_fruhvirtova","bid":0.38,"ask":0.48,"mid":0.43,"spread":0.1,"price":0.39,"size":0.0,"side":"BUY"}
{"ts":"2026-08-24T20:48:00.810Z","event_type":"price_change","market_id":"3825070","outcome_index":0,"market_type":"set2","local_side":"home","local_uid":"2026-08-24_polina_kudermetova_linda_fruhvirtova","bid":0.52,"ask":0.62,"mid":0.57,"spread":0.1,"price":0.61,"size":0.0,"side":"SELL"}
{"ts":"2026-08-24T20:48:00.812Z","event_type":"best_bid_ask","market_id":"3826654","outcome_index":0,"market_type":"set2","local_side":"home","local_uid":"2026-08-24_sebastian_gorzny_cruz_hewitt","bid":0.07,"ask":0.26,"mid":0.165,"spread":0.19,"bid_size":null,"ask_size":null}
{"ts":"2026-08-24T20:48:00.813Z","event_type":"best_bid_ask","market_id":"3826654","outcome_index":1,"market_type":"set2","local_side":"away","local_uid":"2026-08-24_sebastian_gorzny_cruz_hewitt","bid":0.74,"ask":0.93,"mid":0.835,"spread":0.19,"bid_size":null,"ask_size":null}
{"ts":"2026-08-24T20:48:00.813Z","event_type":"price_change","market_id":"3826654","outcome_index":1,"market_type":"set2","local_side":"away","local_uid":"2026-08-24_sebastian_gorzny_cruz_hewitt","bid":0.74,"ask":0.93,"mid":0.835,"spread":0.19,"price":0.74,"size":44.0,"side":"BUY"}
{"ts":"2026-08-24T20:48:00.813Z","event_type":"price_change","market_id":"3826654","outcome_index":0,"market_type":"set2","local_side":"home","local_uid":"2026-08-24_sebastian_gorzny_cruz_hewitt","bid":0.07,"ask":0.26,"mid":0.165,"spread":0.19,"price":0.26,"size":44.0,"side":"SELL"}
{"ts":"2026-08-24T20:48:00.819Z","event_type":"best_bid_ask","market_id":"3826654","outcome_index":0,"market_type":"set2","local_side":"home","local_uid":"2026-08-24_sebastian_gorzny_cruz_hewitt","bid":0.08,"ask":0.26,"mid":0.17,"spread":0.18,"bid_size":null,"ask_size":null}
{"ts":"2026-08-24T20:48:00.819Z","event_type":"best_bid_ask","market_id":"3826654","outcome_index":1,"market_type":"set2","local_side":"away","local_uid":"2026-08-24_sebastian_gorzny_cruz_hewitt","bid":0.74,"ask":0.92,"mid":0.83,"spread":0.18,"bid_size":null,"ask_size":null}
{"ts":"2026-08-24T20:48:00.820Z","event_type":"price_change","market_id":"3826654","outcome_index":0,"market_type":"set2","local_side":"home","local_uid":"2026-08-24_sebastian_gorzny_cruz_hewitt","bid":0.08,"ask":0.26,"mid":0.17,"spread":0.18,"price":0.08,"size":88.0,"side":"BUY"}
{"ts":"2026-08-24T20:48:00.820Z","event_type":"price_change","market_id":"3826654","outcome_index":1,"market_type":"set2","local_side":"away","local_uid":"2026-08-24_sebastian_gorzny_cruz_hewitt","bid":0.74,"ask":0.92,"mid":0.83,"spread":0.18,"price":0.92,"size":88.0,"side":"SELL"}
{"ts":"2026-08-24T20:48:00.841Z","event_type":"best_bid_ask","market_id":"3826654","outcome_index":0,"market_type":"set2","local_side":"home","local_uid":"2026-08-24_sebastian_gorzny_cruz_hewitt","bid":0.07,"ask":0.26,"mid":0.165,"spread":0.19,"bid_size":null,"ask_size":null}
{"ts":"2026-08-24T20:48:00.841Z","event_type":"best_bid_ask","market_id":"3826654","outcome_index":1,"market_type":"set2","local_side":"away","local_uid":"2026-08-24_sebastian_gorzny_cruz_hewitt","bid":0.74,"ask":0.93,"mid":0.835,"spread":0.19,"bid_size":null,"ask_size":null}
{"ts":"2026-08-24T20:48:00.841Z","event_type":"price_change","market_id":"3826654","outcome_index":0,"market_type":"set2","local_side":"home","local_uid":"2026-08-24_sebastian_gorzny_cruz_hewitt","bid":0.07,"ask":0.26,"mid":0.165,"spread":0.19,"price":0.08,"size":0.0,"side":"BUY"}
{"ts":"2026-08-24T20:48:00.842Z","event_type":"price_change","market_id":"3826654","outcome_index":1,"market_type":"set2","local_side":"away","local_uid":"2026-08-24_sebastian_gorzny_cruz_hewitt","bid":0.74,"ask":0.93,"mid":0.835,"spread":0.19,"price":0.92,"size":0.0,"side":"SELL"}
{"ts":"2026-08-24T20:48:00.857Z","event_type":"best_bid_ask","market_id":"3826654","outcome_index":0,"market_type":"set2","local_side":"home","local_uid":"2026-08-24_sebastian_gorzny_cruz_hewitt","bid":0.06,"ask":0.26,"mid":0.16,"spread":0.2,"bid_size":null,"ask_size":null}
{"ts":"2026-08-24T20:48:00.858Z","event_type":"best_bid_ask","market_id":"3826654","outcome_index":1,"market_type":"set2","local_side":"away","local_uid":"2026-08-24_sebastian_gorzny_cruz_hewitt","bid":0.74,"ask":0.94,"mid":0.84,"spread":0.2,"bid_size":null,"ask_size":null}
{"ts":"2026-08-24T20:48:00.860Z","event_type":"price_change","market_id":"3826654","outcome_index":0,"market_type":"set2","local_side":"home","local_uid":"2026-08-24_sebastian_gorzny_cruz_hewitt","bid":0.06,"ask":0.26,"mid":0.16,"spread":0.2,"price":0.07,"size":0.0,"side":"BUY"}
{"ts":"2026-08-24T20:48:00.860Z","event_type":"price_change","market_id":"3826654","outcome_index":1,"market_type":"set2","local_side":"away","local_uid":"2026-08-24_sebastian_gorzny_cruz_hewitt","bid":0.74,"ask":0.94,"mid":0.84,"spread":0.2,"price":0.93,"size":0.0,"side":"SELL"}
