{"ts":"2026-08-23T17:53:02.201Z","event_type":"price_change","market_id":"3790323","outcome_index":0,"market_type":"set2","local_side":"home","local_uid":"2026-08-23_felix_balshaw_sebastian_gorzny","bid":0.5,"ask":0.64,"mid":0.57,"spread":0.14,"price":0.63,"size":0.0,"side":"SELL"}
{"ts":"2026-08-23T17:53:02.212Z","event_type":"best_bid_ask","market_id":"3790323","outcome_index":0,"market_type":"set2","local_side":"home","local_uid":"2026-08-23_felix_balshaw_sebastian_gorzny","bid":0.5,"ask":0.65,"mid":0.575,"spread":0.15,"bid_size":null,"ask_size":null}
{"ts":"2026-08-23T17:53:02.212Z","event_type":"best_bid_ask","market_id":"3790323","outcome_index":1,"market_type":"set2","local_side":"away","local_uid":"2026-08-23_felix_balshaw_sebastian_gorzny","bid":0.35,"ask":0.5,"mid":0.425,"spread":0.15,"bid_size":null,"ask_size":null}
{"ts":"2026-08-23T17:53:02.213Z","event_type":"price_change","market_id":"3790323","outcome_index":1,"market_type":"set2","local_side":"away","local_uid":"2026-08-23_felix_balshaw_sebastian_gorzny","bid":0.35,"ask":0.5,"mid":0.425,"spread":0.15,"price":0.36,"size":0.0,"side":"BUY"}
{"ts":"2026-08-23T17:53:02.213Z","event_type":"price_change","market_id":"3790323","outcome_index":0,"market_type":"set2","local_side":"home","local_uid":"2026-08-23_felix_balshaw_sebastian_gorzny","bid":0.5,"ask":0.65,"mid":0.575,"spread":0.15,"price":0.64,"size":0.0,"side":"SELL"}
{"ts":"2026-08-23T17:53:02.228Z","event_type":"best_bid_ask","market_id":"3790323","outcome_index":0,"market_type":"set2","local_side":"home","local_uid":"2026-08-23_felix_balshaw_sebastian_gorzny","bid":0.5,"ask":1.0,"mid":0.75,"spread":0.5,"bid_size":null,"ask_size":null}
{"ts":"2026-08-23T17:53:02.229Z","event_type":"best_bid_ask","market_id":"3790323","outcome_index":1,"market_type":"set2","local_side":"away","local_uid":"2026-08-23_felix_balshaw_sebastian_gorzny","bid":0.0,"ask":0.5,"mid":0.25,"spread":0.5,"bid_size":null,"ask_size":null}
{"ts":"2026-08-23T17:53:02.229Z","event_type":"price_change","market_id":"3790323","outcome_index":1,"market_type":"set2","local_side":"away","local_uid":"2026-08-23_felix_balshaw_sebastian_gorzny","bid":0.0,"ask":0.5,"mid":0.25,"spread":0.5,"price":0.35,"size":0.0,"side":"BUY"}
{"ts":"2026-08-23T17:53:02.229Z","event_type":"price_change","market_id":"3790323","outcome_index":0,"market_type":"set2","local_side":"home","local_uid":"2026-08-23_felix_balshaw_sebastian_gorzny","bid":0.5,"ask":1.0,"mid":0.75,"spread":0.5,"price":0.65,"size":0.0,"side":"SELL"}
{"ts":"2026-08-23T17:53:02.239Z","event_type":"best_bid_ask","market_id":"3790323","outcome_index":0,"market_type":"set2","local_side":"home","local_uid":"2026-08-23_felix_balshaw_sebastian_gorzny","bid":0.46,"ask":1.0,"mid":0.73,"spread":0.54,"bid_size":null,"ask_size":null}
{"ts":"2026-08-23T17:53:02.239Z","event_type":"best_bid_ask","market_id":"3790323","outcome_index":1,"market_type":"set2","local_side":"away","local_uid":"2026-08-23_felix_balshaw_sebastian_gorzny","bid":0.0,"ask":0.54,"mid":0.27,"spread":0.54,"bid_size":null,"ask_size":null}
{"ts":"2026-08-23T17:53:02.239Z","event_type":"price_change","market_id":"3790323","outcome_index":0,"market_type":"set2","local_side":"home","local_uid":"2026-08-23_felix_balshaw_sebastian_gorzny","bid":0.46,"ask":1.0,"mid":0.73,"spread":0.54,"price":0.5,"size":0.0,"side":"BUY"}
{"ts":"2026-08-23T17:53:02.239Z","event_type":"price_change","market_id":"3790323","outcome_index":1,"market_type":"set2","local_side":"away","local_uid":"2026-08-23_felix_balshaw_sebastian_gorzny","bid":0.0,"ask":0.54,"mid":0.27,"spread":0.54,"price":0.5,"size":0.0,"side":"SELL"}
{"ts":"2026-08-23T17:53:02.256Z","event_type":"best_bid_ask","market_id":"3790323","outcome_index":0,"market_type":"set2","local_side":"home","local_uid":"2026-08-23_felix_balshaw_sebastian_gorzny","bid":0.46,"ask":0.65,"mid":0.555,"spread":0.19,"bid_size":null,"ask_size":null}
{"ts":"2026-08-23T17:53:02.256Z","event_type":"best_bid_ask","market_id":"3790323","outcome_index":1,"market_type":"set2","local_side":"away","local_uid":"2026-08-23_felix_balshaw_sebastian_gorzny","bid":0.35,"ask":0.54,"mid":0.445,"spread":0.19,"bid_size":null,"ask_size":null}
{"ts":"2026-08-23T17:53:02.256Z","event_type":"price_change","market_id":"3790323","outcome_index":1,"market_type":"set2","local_side":"away","local_uid":"2026-08-23_felix_balshaw_sebastian_gorzny","bid":0.35,"ask":0.54,"mid":0.445,"spread":0.19,"price":0.35,"size":150.0,"side":"BUY"}
{"ts":"2026-08-23T17:53:02.256Z","event_type":"price_change","market_id":"3790323","outcome_index":0,"market_type":"set2","local_side":"home","local_uid":"2026-08-23_felix_balshaw_sebastian_gorzny","bid":0.46,"ask":0.65,"mid":0.555,"spread":0.19,"price":0.65,"size":150.0,"side":"SELL"}
{"ts":"2026-08-23T17:53:02.256Z","event_type":"best_bid_ask","market_id":"3790323","outcome_index":0,"market_type":"set2","local_side":"home","local_uid":"2026-08-23_felix_balshaw_sebastian_gorzny","bid":0.46,"ask":0.64,"mid":0.55,"spread":0.18,"bid_size":null,"ask_size":null}
{"ts":"2026-08-23T17:53:02.256Z","event_type":"best_bid_ask","market_id":"3790323","outcome_index":1,"market_type":"set2","local_side":"away","local_uid":"2026-08-23_felix_balshaw_sebastian_gorzny","bid":0.36,"ask":0.54,"mid":0.45,"spread":0.18,"bid_size":null,"ask_size":null}
{"ts":"2026-08-23T17:53:02.256Z","event_type":"price_change","market_id":"3790323","outcome_index":1,"market_type":"set2","local_side":"away","local_uid":"2026-08-23_felix_balshaw_sebastian_gorzny","bid":0.36,"ask":0.54,"mid":0.45,"spread":0.18,"price":0.36,"size":101.84,"side":"BUY"}
{"ts":"2026-08-23T17:53:02.256Z","event_type":"price_change","market_id":"3790323","outcome_index":0,"market_type":"set2","local_side":"home","local_uid":"2026-08-23_felix_balshaw_sebastian_gorzny","bid":0.46,"ask":0.64,"mid":0.55,"spread":0.18,"price":0.64,"size":101.84,"side":"SELL"}
{"ts":"2026-08-23T17:53:02.278Z","event_type":"best_bid_ask","market_id":"3790323","outcome_index":0,"market_type":"set2","local_side":"home","local_uid":"2026-08-23_felix_balshaw_sebastian_gorzny","bid":0.5,"ask":0.64,"mid":0.57,"spread":0.14,"bid_size":null,"ask_size":null}
{"ts":"2026-08-23T17:53:02.278Z","event_type":"best_bid_ask","market_id":"3790323","outcome_index":1,"market_type":"set2","local_side":"away","local_uid":"2026-08-23_felix_balshaw_sebastian_gorzny","bid":0.36,"ask":0.5,"mid":0.43,"spread":0.14,"bid_size":null,"ask_size":null}
{"ts":"2026-08-23T17:53:02.278Z","event_type":"price_change","market_id":"3790323","outcome_index":0,"market_type":"set2","local_side":"home","local_uid":"2026-08-23_felix_balshaw_sebastian_gorzny","bid":0.5,"ask":0.64,"mid":0.57,"spread":0.14,"price":0.5,"size":13.82,"side":"BUY"}
{"ts":"2026-08-23T17:53:02.279Z","event_type":"price_change","market_id":"3790323","outcome_index":1,"market_type":"set2","local_side":"away","local_uid":"2026-08-23_felix_balshaw_sebastian_gorzny","bid":0.36,"ask":0.5,"mid":0.43,"spread":0.14,"price":0.5,"size":13.82,"side":"SELL"}
{"ts":"2026-08-23T17:53:02.475Z","event_type":"best_bid_ask","market_id":"3790397","outcome_index":0,"market_type":"set2","local_side":"home","local_uid":"2026-08-23_hugo_grenier_mees_rottgering","bid":0.31,"ask":0.42,"mid":0.365,"spread":0.11,"bid_size":null,"ask_size":null}
{"ts":"2026-08-23T17:53:02.475Z","event_type":"best_bid_ask","market_id":"3790397","outcome_index":1,"market_type":"set2","local_side":"away","local_uid":"2026-08-23_hugo_grenier_mees_rottgering","bid":0.58,"ask":0.69,"mid":0.635,"spread":0.11,"bid_size":null,"ask_size":null}
{"ts":"2026-08-23T17:53:02.475Z","event_type":"price_change","market_id":"3790397","outcome_index":1,"market_type":"set2","local_side":"away","local_uid":"2026-08-23_hugo_grenier_mees_rottgering","bid":0.58,"ask":0.69,"mid":0.635,"spread":0.11,"price":0.59,"size":0.0,"side":"BUY"}
{"ts":"2026-08-23T17:53:02.475Z","event_type":"price_change","market_id":"3790397","outcome_index":0,"market_type":"set2","local_side":"home","local_uid":"2026-08-23_hugo_grenier_mees_rottgering","bid":0.31,"ask":0.42,"mid":0.365,"spread":0.11,"price":0.41,"size":0.0,"side":"SELL"}
{"ts":"2026-08-23T17:53:02.515Z","event_type":"best_bid_ask","market_id":"3790397","outcome_index":0,"market_type":"set2","local_side":"home","local_uid":"2026-08-23_hugo_grenier_mees_rottgering","bid":0.31,"ask":0.39,"mid":0.35,"spread":0.08,"bid_size":null,"ask_size":null}
{"ts":"2026-08-23T17:53:02.516Z","event_type":"best_bid_ask","market_id":"3790397","outcome_index":1,"market_type":"set2","local_side":"away","local_uid":"2026-08-23_hugo_grenier_mees_rottgering","bid":0.61,"ask":0.69,"mid":0.65,"spread":0.08,"bid_size":null,"ask_size":null}
{"ts":"2026-08-23T17:53:02.516Z","event_type":"price_change","market_id":"3790397","outcome_index":1,"market_type":"set2","local_side":"away","local_uid":"2026-08-23_hugo_grenier_mees_rottgering","bid":0.61,"ask":0.69,"mid":0.65,"spread":0.08,"price":0.61,"size":34.44,"side":"BUY"}
{"ts":"2026-08-23T17:53:02.516Z","event_type":"price_change","market_id":"3790397","outcome_index":0,"market_type":"set2","local_side":"home","local_uid":"2026-08-23_hugo_grenier_mees_rottgering","bid":0.31,"ask":0.39,"mid":0.35,"spread":0.08,"price":0.39,"size":34.44,"side":"SELL"}
{"ts":"2026-08-23T17:53:03.049Z","event_type":"best_bid_ask","market_id":"3790394","outcome_index":0,"market_type":"set1","local_side":"home","local_uid":"2026-08-23_hugo_grenier_mees_rottgering","bid":0.27,"ask":0.33,"mid":0.3,"spread":0.06,"bid_size":null,"ask_size":null}
{"ts":"2026-08-23T17:53:03.050Z","event_type":"best_bid_ask","market_id":"3790394","outcome_index":1,"market_type":"set1","local_side":"away","local_uid":"2026-08-23_hugo_grenier_mees_rottgering","bid":0.67,"ask":0.73,"mid":0.7,"spread":0.06,"bid_size":null,"ask_size":null}
{"ts":"2026-08-23T17:53:03.050Z","event_type":"price_change","market_id":"3790394","outcome_index":1,"market_type":"set1","local_side":"away","local_uid":"2026-08-23_hugo_grenier_mees_rottgering","bid":0.67,"ask":0.73,"mid":0.7,"spread":0.06,"price":0.67,"size":37.39,"side":"BUY"}
{"ts":"2026-08-23T17:53:03.050Z","event_type":"price_change","market_id":"3790394","outcome_index":0,"market_type":"set1","local_side":"home","local_uid":"2026-08-23_hugo_grenier_mees_rottgering","bid":0.27,"ask":0.33,"mid":0.3,"spread":0.06,"price":0.33,"size":37.39,"side":"SELL"}
{"ts":"2026-08-23T17:53:03.059Z","event_type":"best_bid_ask","market_id":"3789925","outcome_index":0,"market_type":"match","local_side":"home","local_uid":"2026-08-23_pierre_hugues_herbert_quinn_vandecasteele","bid":0.83,"ask":0.84,"mid":0.835,"spread":0.01,"bid_size":null,"ask_size":null}
{"ts":"2026-08-23T17:53:03.059Z","event_type":"best_bid_ask","market_id":"3789925","outcome_index":1,"market_type":"match","local_side":"away","local_uid":"2026-08-23_pierre_hugues_herbert_quinn_vandecasteele","bid":0.16,"ask":0.17,"mid":0.165,"spread":0.01,"bid_size":null,"ask_size":null}
{"ts":"2026-08-23T17:53:03.059Z","event_type":"price_change","market_id":"3789925","outcome_index":1,"market_type":"match","local_side":"away","local_uid":"2026-08-23_pierre_hugues_herbert_quinn_vandecasteele","bid":0.16,"ask":0.17,"mid":0.165,"spread":0.01,"price":0.16,"size":3372.5,"side":"BUY"}
{"ts":"2026-08-23T17:53:03.059Z","event_type":"price_change","market_id":"3789925","outcome_index":0,"market_type":"match","local_side":"home","local_uid":"2026-08-23_pierre_hugues_herbert_quinn_vandecasteele","bid":0.83,"ask":0.84,"mid":0.835,"spread":0.01,"price":0.84,"size":3372.5,"side":"SELL"}
{"ts":"2026-08-23T17:53:03.059Z","event_type":"book","market_id":"3789925","outcome_index":0,"market_type":"match","local_side":"home","local_uid":"2026-08-23_pierre_hugues_herbert_quinn_vandecasteele","bid":0.83,"ask":0.84,"mid":0.835,"spread":0.01,"bid_size":1569.08,"ask_size":3372.5}
{"ts":"2026-08-23T17:53:03.060Z","event_type":"book","market_id":"3789925","outcome_index":1,"market_type":"match","local_side":"away","local_uid":"2026-08-23_pierre_hugues_herbert_quinn_vandecasteele","bid":0.16,"ask":0.17,"mid":0.165,"spread":0.01,"bid_size":3372.5,"ask_size":1569.08}
{"ts":"2026-08-23T17:53:03.107Z","event_type":"last_trade_price","market_id":"3789925","outcome_index":1,"market_type":"match","local_side":"away","local_uid":"2026-08-23_pierre_hugues_herbert_quinn_vandecasteele","last_trade":0.16,"trade_size":15.0,"trade_side":"BUY","trade_notional":2.4}
{"ts":"2026-08-23T17:53:03.117Z","event_type":"last_trade_price","market_id":"3789997","outcome_index":1,"market_type":"match","local_side":"away","local_uid":"2026-08-23_oscar_weightman_alec_deckers","last_trade":0.95,"trade_size":11.0,"trade_side":"BUY","trade_notional":10.45}
{"ts":"2026-08-23T17:53:03.233Z","event_type":"best_bid_ask","market_id":"3789929","outcome_index":0,"market_type":"match","local_side":"home","local_uid":"2026-08-23_felix_balshaw_sebastian_gorzny","bid":0.31,"ask":0.33,"mid":0.32,"spread":0.02,"bid_size":null,"ask_size":null}
{"ts":"2026-08-23T17:53:03.234Z","event_type":"best_bid_ask","market_id":"3789929","outcome_index":1,"market_type":"match","local_side":"away","local_uid":"2026-08-23_felix_balshaw_sebastian_gorzny","bid":0.67,"ask":0.69,"mid":0.68,"spread":0.02,"bid_size":null,"ask_size":null}
{"ts":"2026-08-23T17:53:03.234Z","event_type":"price_change","market_id":"3789929","outcome_index":1,"market_type":"match","local_side":"away","local_uid":"2026-08-23_felix_balshaw_sebastian_gorzny","bid":0.67,"ask":0.69,"mid":0.68,"spread":0.02,"price":0.68,"size":0.0,"side":"BUY"}
{"ts":"2026-08-23T17:53:03.234Z","event_type":"price_change","market_id":"3789929","outcome_index":0,"market_type":"match","local_side":"home","local_uid":"2026-08-23_felix_balshaw_sebastian_gorzny","bid":0.31,"ask":0.33,"mid":0.32,"spread":0.02,"price":0.32,"size":0.0,"side":"SELL"}
{"ts":"2026-08-23T17:53:03.253Z","event_type":"best_bid_ask","market_id":"3790415","outcome_index":0,"market_type":"set2","local_side":"home","local_uid":"2026-08-23_pierre_hugues_herbert_quinn_vandecasteele","bid":0.62,"ask":0.73,"mid":0.675,"spread":0.11,"bid_size":null,"ask_size":null}
{"ts":"2026-08-23T17:53:03.253Z","event_type":"best_bid_ask","market_id":"3790415","outcome_index":1,"market_type":"set2","local_side":"away","local_uid":"2026-08-23_pierre_hugues_herbert_quinn_vandecasteele","bid":0.27,"ask":0.38,"mid":0.325,"spread":0.11,"bid_size":null,"ask_size":null}
{"ts":"2026-08-23T17:53:03.253Z","event_type":"price_change","market_id":"3790415","outcome_index":0,"market_type":"set2","local_side":"home","local_uid":"2026-08-23_pierre_hugues_herbert_quinn_vandecasteele","bid":0.62,"ask":0.73,"mid":0.675,"spread":0.11,"price":0.62,"size":150.0,"side":"BUY"}
{"ts":"2026-08-23T17:53:03.253Z","event_type":"price_change","market_id":"3790415","outcome_index":1,"market_type":"set2","local_side":"away","local_uid":"2026-08-23_pierre_hugues_herbert_quinn_vandecasteele","bid":0.27,"ask":0.38,"mid":0.325,"spread":0.11,"price":0.38,"size":150.0,"side":"SELL"}
{"ts":"2026-08-23T17:53:03.287Z","event_type":"best_bid_ask","market_id":"3790415","outcome_index":0,"market_type":"set2","local_side":"home","local_uid":"2026-08-23_pierre_hugues_herbert_quinn_vandecasteele","bid":0.62,"ask":0.72,"mid":0.67,"spread":0.1,"bid_size":null,"ask_size":null}
{"ts":"2026-08-23T17:53:03.287Z","event_type":"best_bid_ask","market_id":"3790415","outcome_index":1,"market_type":"set2","local_side":"away","local_uid":"2026-08-23_pierre_hugues_herbert_quinn_vandecasteele","bid":0.28,"ask":0.38,"mid":0.33,"spread":0.1,"bid_size":null,"ask_size":null}
{"ts":"2026-08-23T17:53:03.287Z","event_type":"price_change","market_id":"3790415","outcome_index":1,"market_type":"set2","local_side":"away","local_uid":"2026-08-23_pierre_hugues_herbert_quinn_vandecasteele","bid":0.28,"ask":0.38,"mid":0.33,"spread":0.1,"price":0.28,"size":150.0,"side":"BUY"}
{"ts":"2026-08-23T17:53:03.287Z","event_type":"price_change","market_id":"3790415","outcome_index":0,"market_type":"set2","local_side":"home","local_uid":"2026-08-23_pierre_hugues_herbert_quinn_vandecasteele","bid":0.62,"ask":0.72,"mid":0.67,"spread":0.1,"price":0.72,"size":150.0,"side":"SELL"}
{"ts":"2026-08-23T17:53:04.140Z","event_type":"last_trade_price","market_id":"3789997","outcome_index":1,"market_type":"match","local_side":"away","local_uid":"2026-08-23_oscar_weightman_alec_deckers","last_trade":0.95,"trade_size":2.5263,"trade_side":"BUY","trade_notional":2.4}
{"ts":"2026-08-23T17:53:04.364Z","event_type":"price_change","market_id":"3780820","outcome_index":1,"market_type":"match","local_side":"away","local_uid":"2026-08-23_sho_shimabukuro_miomir_kecmanovic","bid":0.68,"ask":0.69,"mid":0.685,"spread":0.01,"price":0.44,"size":0.0,"side":"BUY"}
{"ts":"2026-08-23T17:53:04.364Z","event_type":"price_change","market_id":"3780820","outcome_index":0,"market_type":"match","local_side":"home","local_uid":"2026-08-23_sho_shimabukuro_miomir_kecmanovic","bid":0.31,"ask":0.32,"mid":0.315,"spread":0.01,"price":0.56,"size":0.0,"side":"SELL"}
{"ts":"2026-08-23T17:53:04.634Z","event_type":"best_bid_ask","market_id":"3790394","outcome_index":0,"market_type":"set1","local_side":"home","local_uid":"2026-08-23_hugo_grenier_mees_rottgering","bid":0.27,"ask":0.34,"mid":0.305,"spread":0.07,"bid_size":null,"ask_size":null}
{"ts":"2026-08-23T17:53:04.635Z","event_type":"best_bid_ask","market_id":"3790394","outcome_index":1,"market_type":"set1","local_side":"away","local_uid":"2026-08-23_hugo_grenier_mees_rottgering","bid":0.66,"ask":0.73,"mid":0.695,"spread":0.07,"bid_size":null,"ask_size":null}
{"ts":"2026-08-23T17:53:04.635Z","event_type":"price_change","market_id":"3790394","outcome_index":1,"market_type":"set1","local_side":"away","local_uid":"2026-08-23_hugo_grenier_mees_rottgering","bid":0.66,"ask":0.73,"mid":0.695,"spread":0.07,"price":0.67,"size":0.0,"side":"BUY"}
{"ts":"2026-08-23T17:53:04.635Z","event_type":"price_change","market_id":"3790394","outcome_index":0,"market_type":"set1","local_side":"home","local_uid":"2026-08-23_hugo_grenier_mees_rottgering","bid":0.27,"ask":0.34,"mid":0.305,"spread":0.07,"price":0.33,"size":0.0,"side":"SELL"}
{"ts":"2026-08-23T17:53:04.658Z","event_type":"best_bid_ask","market_id":"3790394","outcome_index":0,"market_type":"set1","local_side":"home","local_uid":"2026-08-23_hugo_grenier_mees_rottgering","bid":0.27,"ask":0.35,"mid":0.31,"spread":0.08,"bid_size":null,"ask_size":null}
{"ts":"2026-08-23T17:53:04.658Z","event_type":"best_bid_ask","market_id":"3790394","outcome_index":1,"market_type":"set1","local_side":"away","local_uid":"2026-08-23_hugo_grenier_mees_rottgering","bid":0.65,"ask":0.73,"mid":0.69,"spread":0.08,"bid_size":null,"ask_size":null}
{"ts":"2026-08-23T17:53:04.658Z","event_type":"price_change","market_id":"3790394","outcome_index":1,"market_type":"set1","local_side":"away","local_uid":"2026-08-23_hugo_grenier_mees_rottgering","bid":0.65,"ask":0.73,"mid":0.69,"spread":0.08,"price":0.66,"size":0.0,"side":"BUY"}
{"ts":"2026-08-23T17:53:04.658Z","event_type":"price_change","market_id":"3790394","outcome_index":0,"market_type":"set1","local_side":"home","local_uid":"2026-08-23_hugo_grenier_mees_rottgering","bid":0.27,"ask":0.35,"mid":0.31,"spread":0.08,"price":0.34,"size":0.0,"side":"SELL"}
{"ts":"2026-08-23T17:53:04.666Z","event_type":"best_bid_ask","market_id":"3790394","outcome_index":0,"market_type":"set1","local_side":"home","local_uid":"2026-08-23_hugo_grenier_mees_rottgering","bid":0.27,"ask":0.34,"mid":0.305,"spread":0.07,"bid_size":null,"ask_size":null}
{"ts":"2026-08-23T17:53:04.667Z","event_type":"best_bid_ask","market_id":"3790394","outcome_index":1,"market_type":"set1","local_side":"away","local_uid":"2026-08-23_hugo_grenier_mees_rottgering","bid":0.66,"ask":0.73,"mid":0.695,"spread":0.07,"bid_size":null,"ask_size":null}
{"ts":"2026-08-23T17:53:04.667Z","event_type":"price_change","market_id":"3790394","outcome_index":1,"market_type":"set1","local_side":"away","local_uid":"2026-08-23_hugo_grenier_mees_rottgering","bid":0.66,"ask":0.73,"mid":0.695,"spread":0.07,"price":0.66,"size":150.0,"side":"BUY"}
{"ts":"2026-08-23T17:53:04.667Z","event_type":"price_change","market_id":"3790394","outcome_index":0,"market_type":"set1","local_side":"home","local_uid":"2026-08-23_hugo_grenier_mees_rottgering","bid":0.27,"ask":0.34,"mid":0.305,"spread":0.07,"price":0.34,"size":150.0,"side":"SELL"}
{"ts":"2026-08-23T17:53:06.236Z","event_type":"best_bid_ask","market_id":"3789931","outcome_index":0,"market_type":"match","local_side":"home","local_uid":"2026-08-23_stefanos_sakellaridis_luca_van_assche","bid":0.05,"ask":0.07,"mid":0.06,"spread":0.02,"bid_size":null,"ask_size":null}
{"ts":"2026-08-23T17:53:06.236Z","event_type":"best_bid_ask","market_id":"3789931","outcome_index":1,"market_type":"match","local_side":"away","local_uid":"2026-08-23_stefanos_sakellaridis_luca_van_assche","bid":0.93,"ask":0.95,"mid":0.94,"spread":0.02,"bid_size":null,"ask_size":null}
{"ts":"2026-08-23T17:53:06.237Z","event_type":"price_change","market_id":"3789931","outcome_index":0,"market_type":"match","local_side":"home","local_uid":"2026-08-23_stefanos_sakellaridis_luca_van_assche","bid":0.05,"ask":0.07,"mid":0.06,"spread":0.02,"price":0.06,"size":0.0,"side":"BUY"}
{"ts":"2026-08-23T17:53:06.237Z","event_type":"price_change","market_id":"3789931","outcome_index":1,"market_type":"match","local_side":"away","local_uid":"2026-08-23_stefanos_sakellaridis_luca_van_assche","bid":0.93,"ask":0.95,"mid":0.94,"spread":0.02,"price":0.94,"size":0.0,"side":"SELL"}
{"ts":"2026-08-23T17:53:06.246Z","event_type":"best_bid_ask","market_id":"3789931","outcome_index":0,"market_type":"match","local_side":"home","local_uid":"2026-08-23_stefanos_sakellaridis_luca_van_assche","bid":0.06,"ask":0.07,"mid":0.065,"spread":0.01,"bid_size":null,"ask_size":null}
{"ts":"2026-08-23T17:53:06.246Z","event_type":"best_bid_ask","market_id":"3789931","outcome_index":1,"market_type":"match","local_side":"away","local_uid":"2026-08-23_stefanos_sakellaridis_luca_van_assche","bid":0.93,"ask":0.94,"mid":0.935,"spread":0.01,"bid_size":null,"ask_size":null}
{"ts":"2026-08-23T17:53:06.247Z","event_type":"price_change","market_id":"3789931","outcome_index":0,"market_type":"match","local_side":"home","local_uid":"2026-08-23_stefanos_sakellaridis_luca_van_assche","bid":0.06,"ask":0.07,"mid":0.065,"spread":0.01,"price":0.06,"size":5.0,"side":"BUY"}
{"ts":"2026-08-23T17:53:06.247Z","event_type":"price_change","market_id":"3789931","outcome_index":1,"market_type":"match","local_side":"away","local_uid":"2026-08-23_stefanos_sakellaridis_luca_van_assche","bid":0.93,"ask":0.94,"mid":0.935,"spread":0.01,"price":0.94,"size":5.0,"side":"SELL"}
{"ts":"2026-08-23T17:53:06.298Z","event_type":"best_bid_ask","market_id":"3789931","outcome_index":0,"market_type":"match","local_side":"home","local_uid":"2026-08-23_stefanos_sakellaridis_luca_van_assche","bid":0.05,"ask":0.07,"mid":0.06,"spread":0.02,"bid_size":null,"ask_size":null}
{"ts":"2026-08-23T17:53:06.298Z","event_type":"best_bid_ask","market_id":"3789931","outcome_index":1,"market_type":"match","local_side":"away","local_uid":"2026-08-23_stefanos_sakellaridis_luca_van_assche","bid":0.93,"ask":0.95,"mid":0.94,"spread":0.02,"bid_size":null,"ask_size":null}
{"ts":"2026-08-23T17:53:06.298Z","event_type":"price_change","market_id":"3789931","outcome_index":0,"market_type":"match","local_side":"home","local_uid":"2026-08-23_stefanos_sakellaridis_luca_van_assche","bid":0.05,"ask":0.07,"mid":0.06,"spread":0.02,"price":0.06,"size":0.0,"side":"BUY"}
{"ts":"2026-08-23T17:53:06.298Z","event_type":"price_change","market_id":"3789931","outcome_index":1,"market_type":"match","local_side":"away","local_uid":"2026-08-23_stefanos_sakellaridis_luca_van_assche","bid":0.93,"ask":0.95,"mid":0.94,"spread":0.02,"price":0.94,"size":0.0,"side":"SELL"}
{"ts":"2026-08-23T17:53:07.312Z","event_type":"price_change","market_id":"3795964","outcome_index":1,"market_type":"match","local_side":"away","local_uid":"2026-08-23_nicholas_gore_dan_martin","bid":0.991,"ask":0.997,"mid":0.994,"spread":0.006,"price":0.98,"size":250.0,"side":"BUY"}
{"ts":"2026-08-23T17:53:07.313Z","event_type":"price_change","market_id":"3795964","outcome_index":0,"market_type":"match","local_side":"home","local_uid":"2026-08-23_nicholas_gore_dan_martin","bid":0.003,"ask":0.009,"mid":0.006,"spread":0.006,"price":0.02,"size":250.0,"side":"SELL"}
{"ts":"2026-08-23T17:53:07.556Z","event_type":"price_change","market_id":"3780836","outcome_index":1,"market_type":"match","local_side":"away","local_uid":"2026-08-23_rinky_hijikata_darwin_blanch","bid":0.33,"ask":0.34,"mid":0.335,"spread":0.01,"price":0.31,"size":22517.99,"side":"BUY"}
{"ts":"2026-08-23T17:53:07.556Z","event_type":"price_change","market_id":"3780836","outcome_index":0,"market_type":"match","local_side":"home","local_uid":"2026-08-23_rinky_hijikata_darwin_blanch","bid":0.66,"ask":0.67,"mid":0.665,"spread":0.01,"price":0.69,"size":22517.99,"side":"SELL"}
{"ts":"2026-08-23T17:53:07.569Z","event_type":"best_bid_ask","market_id":"3790415","outcome_index":0,"market_type":"set2","local_side":"home","local_uid":"2026-08-23_pierre_hugues_herbert_quinn_vandecasteele","bid":0.62,"ask":0.73,"mid":0.675,"spread":0.11,"bid_size":null,"ask_size":null}
{"ts":"2026-08-23T17:53:07.569Z","event_type":"best_bid_ask","market_id":"3790415","outcome_index":1,"market_type":"set2","local_side":"away","local_uid":"2026-08-23_pierre_hugues_herbert_quinn_vandecasteele","bid":0.27,"ask":0.38,"mid":0.325,"spread":0.11,"bid_size":null,"ask_size":null}
{"ts":"2026-08-23T17:53:07.569Z","event_type":"price_change","market_id":"3790415","outcome_index":1,"market_type":"set2","local_side":"away","local_uid":"2026-08-23_pierre_hugues_herbert_quinn_vandecasteele","bid":0.27,"ask":0.38,"mid":0.325,"spread":0.11,"price":0.28,"size":0.0,"side":"BUY"}
{"ts":"2026-08-23T17:53:07.569Z","event_type":"price_change","market_id":"3790415","outcome_index":0,"market_type":"set2","local_side":"home","local_uid":"2026-08-23_pierre_hugues_herbert_quinn_vandecasteele","bid":0.62,"ask":0.73,"mid":0.675,"spread":0.11,"price":0.72,"size":0.0,"side":"SELL"}
{"ts":"2026-08-23T17:53:07.595Z","event_type":"best_bid_ask","market_id":"3790415","outcome_index":0,"market_type":"set2","local_side":"home","local_uid":"2026-08-23_pierre_hugues_herbert_quinn_vandecasteele","bid":0.62,"ask":0.72,"mid":0.67,"spread":0.1,"bid_size":null,"ask_size":null}
{"ts":"2026-08-23T17:53:07.595Z","event_type":"best_bid_ask","market_id":"3790415","outcome_index":1,"market_type":"set2","local_side":"away","local_uid":"2026-08-23_pierre_hugues_herbert_quinn_vandecasteele","bid":0.28,"ask":0.38,"mid":0.33,"spread":0.1,"bid_size":null,"ask_size":null}
{"ts":"2026-08-23T17:53:07.595Z","event_type":"price_change","market_id":"3790415","outcome_index":1,"market_type":"set2","local_side":"away","local_uid":"2026-08-23_pierre_hugues_herbert_quinn_vandecasteele","bid":0.28,"ask":0.38,"mid":0.33,"spread":0.1,"price":0.28,"size":150.0,"side":"BUY"}
{"ts":"2026-08-23T17:53:07.595Z","event_type":"price_change","market_id":"3790415","outcome_index":0,"market_type":"set2","local_side":"home","local_uid":"2026-08-23_pierre_hugues_herbert_quinn_vandecasteele","bid":0.62,"ask":0.72,"mid":0.67,"spread":0.1,"price":0.72,"size":150.0,"side":"SELL"}
{"ts":"2026-08-23T17:53:07.666Z","event_type":"best_bid_ask","market_id":"3790415","outcome_index":0,"market_type":"set2","local_side":"home","local_uid":"2026-08-23_pierre_hugues_herbert_quinn_vandecasteele","bid":0.62,"ask":0.71,"mid":0.665,"spread":0.09,"bid_size":null,"ask_size":null}
{"ts":"2026-08-23T17:53:07.666Z","event_type":"best_bid_ask","market_id":"3790415","outcome_index":1,"market_type":"set2","local_side":"away","local_uid":"2026-08-23_pierre_hugues_herbert_quinn_vandecasteele","bid":0.29,"ask":0.38,"mid":0.335,"spread":0.09,"bid_size":null,"ask_size":null}
{"ts":"2026-08-23T17:53:07.666Z","event_type":"price_change","market_id":"3790415","outcome_index":1,"market_type":"set2","local_side":"away","local_uid":"2026-08-23_pierre_hugues_herbert_quinn_vandecasteele","bid":0.29,"ask":0.38,"mid":0.335,"spread":0.09,"price":0.29,"size":88.0,"side":"BUY"}
{"ts":"2026-08-23T17:53:07.666Z","event_type":"price_change","market_id":"3790415","outcome_index":0,"market_type":"set2","local_side":"home","local_uid":"2026-08-23_pierre_hugues_herbert_quinn_vandecasteele","bid":0.62,"ask":0.71,"mid":0.665,"spread":0.09,"price":0.71,"size":88.0,"side":"SELL"}
{"ts":"2026-08-23T17:53:07.669Z","event_type":"best_bid_ask","market_id":"3790415","outcome_index":0,"market_type":"set2","local_side":"home","local_uid":"2026-08-23_pierre_hugues_herbert_quinn_vandecasteele","bid":0.63,"ask":0.71,"mid":0.67,"spread":0.08,"bid_size":null,"ask_size":null}
{"ts":"2026-08-23T17:53:07.669Z","event_type":"best_bid_ask","market_id":"3790415","outcome_index":1,"market_type":"set2","local_side":"away","local_uid":"2026-08-23_pierre_hugues_herbert_quinn_vandecasteele","bid":0.29,"ask":0.37,"mid":0.33,"spread":0.08,"bid_size":null,"ask_size":null}
{"ts":"2026-08-23T17:53:07.669Z","event_type":"price_change","market_id":"3790415","outcome_index":0,"market_type":"set2","local_side":"home","local_uid":"2026-08-23_pierre_hugues_herbert_quinn_vandecasteele","bid":0.63,"ask":0.71,"mid":0.67,"spread":0.08,"price":0.63,"size":150.0,"side":"BUY"}
{"ts":"2026-08-23T17:53:07.669Z","event_type":"price_change","market_id":"3790415","outcome_index":1,"market_type":"set2","local_side":"away","local_uid":"2026-08-23_pierre_hugues_herbert_quinn_vandecasteele","bid":0.29,"ask":0.37,"mid":0.33,"spread":0.08,"price":0.37,"size":150.0,"side":"SELL"}
{"ts":"2026-08-23T17:53:07.730Z","event_type":"best_bid_ask","market_id":"3790415","outcome_index":0,"market_type":"set2","local_side":"home","local_uid":"2026-08-23_pierre_hugues_herbert_quinn_vandecasteele","bid":0.63,"ask":0.7,"mid":0.665,"spread":0.07,"bid_size":null,"ask_size":null}
{"ts":"2026-08-23T17:53:07.730Z","event_type":"best_bid_ask","market_id":"3790415","outcome_index":1,"market_type":"set2","local_side":"away","local_uid":"2026-08-23_pierre_hugues_herbert_quinn_vandecasteele","bid":0.3,"ask":0.37,"mid":0.335,"spread":0.07,"bid_size":null,"ask_size":null}
{"ts":"2026-08-23T17:53:07.730Z","event_type":"price_change","market_id":"3790415","outcome_index":1,"market_type":"set2","local_side":"away","local_uid":"2026-08-23_pierre_hugues_herbert_quinn_vandecasteele","bid":0.3,"ask":0.37,"mid":0.335,"spread":0.07,"price":0.3,"size":150.0,"side":"BUY"}
{"ts":"2026-08-23T17:53:07.730Z","event_type":"price_change","market_id":"3790415","outcome_index":0,"market_type":"set2","local_side":"home","local_uid":"2026-08-23_pierre_hugues_herbert_quinn_vandecasteele","bid":0.63,"ask":0.7,"mid":0.665,"spread":0.07,"price":0.7,"size":150.0,"side":"SELL"}
{"ts":"2026-08-23T17:53:07.921Z","event_type":"price_change","market_id":"3795946","outcome_index":1,"market_type":"match","local_side":"away","local_uid":"2026-08-23_arthur_fils_frances_tiafoe","bid":0.33,"ask":0.34,"mid":0.335,"spread":0.01,"price":0.32,"size":113892.92,"side":"BUY"}
{"ts":"2026-08-23T17:53:07.921Z","event_type":"price_change","market_id":"3795946","outcome_index":0,"market_type":"match","local_side":"home","local_uid":"2026-08-23_arthur_fils_frances_tiafoe","bid":0.66,"ask":0.67,"mid":0.665,"spread":0.01,"price":0.68,"size":113892.92,"side":"SELL"}
{"ts":"2026-08-23T17:53:08.226Z","event_type":"best_bid_ask","market_id":"3790323","outcome_index":0,"market_type":"set2","local_side":"home","local_uid":"2026-08-23_felix_balshaw_sebastian_gorzny","bid":0.46,"ask":0.64,"mid":0.55,"spread":0.18,"bid_size":null,"ask_size":null}
{"ts":"2026-08-23T17:53:08.226Z","event_type":"best_bid_ask","market_id":"3790323","outcome_index":1,"market_type":"set2","local_side":"away","local_uid":"2026-08-23_felix_balshaw_sebastian_gorzny","bid":0.36,"ask":0.54,"mid":0.45,"spread":0.18,"bid_size":null,"ask_size":null}
{"ts":"2026-08-23T17:53:08.226Z","event_type":"price_change","market_id":"3790323","outcome_index":0,"market_type":"set2","local_side":"home","local_uid":"2026-08-23_felix_balshaw_sebastian_gorzny","bid":0.46,"ask":0.64,"mid":0.55,"spread":0.18,"price":0.5,"size":0.0,"side":"BUY"}
{"ts":"2026-08-23T17:53:08.226Z","event_type":"price_change","market_id":"3790323","outcome_index":1,"market_type":"set2","local_side":"away","local_uid":"2026-08-23_felix_balshaw_sebastian_gorzny","bid":0.36,"ask":0.54,"mid":0.45,"spread":0.18,"price":0.5,"size":0.0,"side":"SELL"}
{"ts":"2026-08-23T17:53:08.301Z","event_type":"best_bid_ask","market_id":"3790323","outcome_index":0,"market_type":"set2","local_side":"home","local_uid":"2026-08-23_felix_balshaw_sebastian_gorzny","bid":0.46,"ask":0.65,"mid":0.555,"spread":0.19,"bid_size":null,"ask_size":null}
{"ts":"2026-08-23T17:53:08.301Z","event_type":"best_bid_ask","market_id":"3790323","outcome_index":1,"market_type":"set2","local_side":"away","local_uid":"2026-08-23_felix_balshaw_sebastian_gorzny","bid":0.35,"ask":0.54,"mid":0.445,"spread":0.19,"bid_size":null,"ask_size":null}
{"ts":"2026-08-23T17:53:08.301Z","event_type":"price_change","market_id":"3790323","outcome_index":1,"market_type":"set2","local_side":"away","local_uid":"2026-08-23_felix_balshaw_sebastian_gorzny","bid":0.35,"ask":0.54,"mid":0.445,"spread":0.19,"price":0.36,"size":0.0,"side":"BUY"}
{"ts":"2026-08-23T17:53:08.301Z","event_type":"price_change","market_id":"3790323","outcome_index":0,"market_type":"set2","local_side":"home","local_uid":"2026-08-23_felix_balshaw_sebastian_gorzny","bid":0.46,"ask":0.65,"mid":0.555,"spread":0.19,"price":0.64,"size":0.0,"side":"SELL"}
{"ts":"2026-08-23T17:53:08.339Z","event_type":"best_bid_ask","market_id":"3790323","outcome_index":0,"market_type":"set2","local_side":"home","local_uid":"2026-08-23_felix_balshaw_sebastian_gorzny","bid":0.46,"ask":0.64,"mid":0.55,"spread":0.18,"bid_size":null,"ask_size":null}
{"ts":"2026-08-23T17:53:08.339Z","event_type":"best_bid_ask","market_id":"3790323","outcome_index":1,"market_type":"set2","local_side":"away","local_uid":"2026-08-23_felix_balshaw_sebastian_gorzny","bid":0.36,"ask":0.54,"mid":0.45,"spread":0.18,"bid_size":null,"ask_size":null}
{"ts":"2026-08-23T17:53:08.340Z","event_type":"price_change","market_id":"3790323","outcome_index":1,"market_type":"set2","local_side":"away","local_uid":"2026-08-23_felix_balshaw_sebastian_gorzny","bid":0.36,"ask":0.54,"mid":0.45,"spread":0.18,"price":0.36,"size":74.78,"side":"BUY"}
{"ts":"2026-08-23T17:53:08.340Z","event_type":"price_change","market_id":"3790323","outcome_index":0,"market_type":"set2","local_side":"home","local_uid":"2026-08-23_felix_balshaw_sebastian_gorzny","bid":0.46,"ask":0.64,"mid":0.55,"spread":0.18,"price":0.64,"size":74.78,"side":"SELL"}
{"ts":"2026-08-23T17:53:09.115Z","event_type":"price_change","market_id":"3780824","outcome_index":1,"market_type":"match","local_side":"away","local_uid":"2026-08-23_dino_prizmic_cruz_hewitt","bid":0.49,"ask":0.5,"mid":0.495,"spread":0.01,"price":0.33,"size":0.0,"side":"BUY"}
{"ts":"2026-08-23T17:53:09.115Z","event_type":"price_change","market_id":"3780824","outcome_index":0,"market_type":"match","local_side":"home","local_uid":"2026-08-23_dino_prizmic_cruz_hewitt","bid":0.5,"ask":0.51,"mid":0.505,"spread":0.01,"price":0.67,"size":0.0,"side":"SELL"}
{"ts":"2026-08-23T17:53:10.707Z","event_type":"best_bid_ask","market_id":"3790394","outcome_index":0,"market_type":"set1","local_side":"home","local_uid":"2026-08-23_hugo_grenier_mees_rottgering","bid":0.26,"ask":0.34,"mid":0.3,"spread":0.08,"bid_size":null,"ask_size":null}
{"ts":"2026-08-23T17:53:10.707Z","event_type":"best_bid_ask","market_id":"3790394","outcome_index":1,"market_type":"set1","local_side":"away","local_uid":"2026-08-23_hugo_grenier_mees_rottgering","bid":0.66,"ask":0.74,"mid":0.7,"spread":0.08,"bid_size":null,"ask_size":null}
{"ts":"2026-08-23T17:53:10.707Z","event_type":"price_change","market_id":"3790394","outcome_index":0,"market_type":"set1","local_side":"home","local_uid":"2026-08-23_hugo_grenier_mees_rottgering","bid":0.26,"ask":0.34,"mid":0.3,"spread":0.08,"price":0.27,"size":0.0,"side":"BUY"}
{"ts":"2026-08-23T17:53:10.707Z","event_type":"price_change","market_id":"3790394","outcome_index":1,"market_type":"set1","local_side":"away","local_uid":"2026-08-23_hugo_grenier_mees_rottgering","bid":0.66,"ask":0.74,"mid":0.7,"spread":0.08,"price":0.73,"size":0.0,"side":"SELL"}
{"ts":"2026-08-23T17:53:10.787Z","event_type":"best_bid_ask","market_id":"3790397","outcome_index":0,"market_type":"set2","local_side":"home","local_uid":"2026-08-23_hugo_grenier_mees_rottgering","bid":0.31,"ask":0.42,"mid":0.365,"spread":0.11,"bid_size":null,"ask_size":null}
{"ts":"2026-08-23T17:53:10.787Z","event_type":"best_bid_ask","market_id":"3790397","outcome_index":1,"market_type":"set2","local_side":"away","local_uid":"2026-08-23_hugo_grenier_mees_rottgering","bid":0.58,"ask":0.69,"mid":0.635,"spread":0.11,"bid_size":null,"ask_size":null}
{"ts":"2026-08-23T17:53:10.787Z","event_type":"price_change","market_id":"3790397","outcome_index":1,"market_type":"set2","local_side":"away","local_uid":"2026-08-23_hugo_grenier_mees_rottgering","bid":0.58,"ask":0.69,"mid":0.635,"spread":0.11,"price":0.61,"size":0.0,"side":"BUY"}
{"ts":"2026-08-23T17:53:10.787Z","event_type":"price_change","market_id":"3790397","outcome_index":0,"market_type":"set2","local_side":"home","local_uid":"2026-08-23_hugo_grenier_mees_rottgering","bid":0.31,"ask":0.42,"mid":0.365,"spread":0.11,"price":0.39,"size":0.0,"side":"SELL"}
{"ts":"2026-08-23T17:53:10.794Z","event_type":"best_bid_ask","market_id":"3790394","outcome_index":0,"market_type":"set1","local_side":"home","local_uid":"2026-08-23_hugo_grenier_mees_rottgering","bid":0.26,"ask":0.35,"mid":0.305,"spread":0.09,"bid_size":null,"ask_size":null}
{"ts":"2026-08-23T17:53:10.794Z","event_type":"best_bid_ask","market_id":"3790394","outcome_index":1,"market_type":"set1","local_side":"away","local_uid":"2026-08-23_hugo_grenier_mees_rottgering","bid":0.65,"ask":0.74,"mid":0.695,"spread":0.09,"bid_size":null,"ask_size":null}
{"ts":"2026-08-23T17:53:10.795Z","event_type":"price_change","market_id":"3790394","outcome_index":0,"market_type":"set1","local_side":"home","local_uid":"2026-08-23_hugo_grenier_mees_rottgering","bid":0.26,"ask":0.35,"mid":0.305,"spread":0.09,"price":0.25,"size":88.0,"side":"BUY"}
{"ts":"2026-08-23T17:53:10.795Z","event_type":"price_change","market_id":"3790394","outcome_index":1,"market_type":"set1","local_side":"away","local_uid":"2026-08-23_hugo_grenier_mees_rottgering","bid":0.65,"ask":0.74,"mid":0.695,"spread":0.09,"price":0.75,"size":88.0,"side":"SELL"}
{"ts":"2026-08-23T17:53:10.799Z","event_type":"best_bid_ask","market_id":"3790394","outcome_index":0,"market_type":"set1","local_side":"home","local_uid":"2026-08-23_hugo_grenier_mees_rottgering","bid":0.25,"ask":0.35,"mid":0.3,"spread":0.1,"bid_size":null,"ask_size":null}
{"ts":"2026-08-23T17:53:10.799Z","event_type":"best_bid_ask","market_id":"3790394","outcome_index":1,"market_type":"set1","local_side":"away","local_uid":"2026-08-23_hugo_grenier_mees_rottgering","bid":0.65,"ask":0.75,"mid":0.7,"spread":0.1,"bid_size":null,"ask_size":null}
{"ts":"2026-08-23T17:53:10.800Z","event_type":"price_change","market_id":"3790394","outcome_index":0,"market_type":"set1","local_side":"home","local_uid":"2026-08-23_hugo_grenier_mees_rottgering","bid":0.25,"ask":0.35,"mid":0.3,"spread":0.1,"price":0.26,"size":0.0,"side":"BUY"}
{"ts":"2026-08-23T17:53:10.800Z","event_type":"price_change","market_id":"3790394","outcome_index":1,"market_type":"set1","local_side":"away","local_uid":"2026-08-23_hugo_grenier_mees_rottgering","bid":0.65,"ask":0.75,"mid":0.7,"spread":0.1,"price":0.74,"size":0.0,"side":"SELL"}
{"ts":"2026-08-23T17:53:10.814Z","event_type":"best_bid_ask","market_id":"3790397","outcome_index":0,"market_type":"set2","local_side":"home","local_uid":"2026-08-23_hugo_grenier_mees_rottgering","bid":0.3,"ask":0.42,"mid":0.36,"spread":0.12,"bid_size":null,"ask_size":null}
{"ts":"2026-08-23T17:53:10.814Z","event_type":"best_bid_ask","market_id":"3790397","outcome_index":1,"market_type":"set2","local_side":"away","local_uid":"2026-08-23_hugo_grenier_mees_rottgering","bid":0.58,"ask":0.7,"mid":0.64,"spread":0.12,"bid_size":null,"ask_size":null}
{"ts":"2026-08-23T17:53:10.815Z","event_type":"price_change","market_id":"3790397","outcome_index":0,"market_type":"set2","local_side":"home","local_uid":"2026-08-23_hugo_grenier_mees_rottgering","bid":0.3,"ask":0.42,"mid":0.36,"spread":0.12,"price":0.31,"size":0.0,"side":"BUY"}
{"ts":"2026-08-23T17:53:10.815Z","event_type":"price_change","market_id":"3790397","outcome_index":1,"market_type":"set2","local_side":"away","local_uid":"2026-08-23_hugo_grenier_mees_rottgering","bid":0.58,"ask":0.7,"mid":0.64,"spread":0.12,"price":0.69,"size":0.0,"side":"SELL"}
{"ts":"2026-08-23T17:53:10.815Z","event_type":"best_bid_ask","market_id":"3790394","outcome_index":0,"market_type":"set1","local_side":"home","local_uid":"2026-08-23_hugo_grenier_mees_rottgering","bid":0.24,"ask":0.35,"mid":0.295,"spread":0.11,"bid_size":null,"ask_size":null}
{"ts":"2026-08-23T17:53:10.815Z","event_type":"best_bid_ask","market_id":"3790394","outcome_index":1,"market_type":"set1","local_side":"away","local_uid":"2026-08-23_hugo_grenier_mees_rottgering","bid":0.65,"ask":0.76,"mid":0.705,"spread":0.11,"bid_size":null,"ask_size":null}
{"ts":"2026-08-23T17:53:10.815Z","event_type":"price_change","market_id":"3790394","outcome_index":0,"market_type":"set1","local_side":"home","local_uid":"2026-08-23_hugo_grenier_mees_rottgering","bid":0.24,"ask":0.35,"mid":0.295,"spread":0.11,"price":0.25,"size":0.0,"side":"BUY"}
{"ts":"2026-08-23T17:53:10.815Z","event_type":"price_change","market_id":"3790394","outcome_index":1,"market_type":"set1","local_side":"away","local_uid":"2026-08-23_hugo_grenier_mees_rottgering","bid":0.65,"ask":0.76,"mid":0.705,"spread":0.11,"price":0.75,"size":0.0,"side":"SELL"}
{"ts":"2026-08-23T17:53:10.818Z","event_type":"best_bid_ask","market_id":"3790394","outcome_index":0,"market_type":"set1","local_side":"home","local_uid":"2026-08-23_hugo_grenier_mees_rottgering","bid":0.23,"ask":0.35,"mid":0.29,"spread":0.12,"bid_size":null,"ask_size":null}
{"ts":"2026-08-23T17:53:10.818Z","event_type":"best_bid_ask","market_id":"3790394","outcome_index":1,"market_type":"set1","local_side":"away","local_uid":"2026-08-23_hugo_grenier_mees_rottgering","bid":0.65,"ask":0.77,"mid":0.71,"spread":0.12,"bid_size":null,"ask_size":null}
{"ts":"2026-08-23T17:53:10.818Z","event_type":"price_change","market_id":"3790394","outcome_index":0,"market_type":"set1","local_side":"home","local_uid":"2026-08-23_hugo_grenier_mees_rottgering","bid":0.23,"ask":0.35,"mid":0.29,"spread":0.12,"price":0.24,"size":0.0,"side":"BUY"}
{"ts":"2026-08-23T17:53:10.818Z","event_type":"price_change","market_id":"3790394","outcome_index":1,"market_type":"set1","local_side":"away","local_uid":"2026-08-23_hugo_grenier_mees_rottgering","bid":0.65,"ask":0.77,"mid":0.71,"spread":0.12,"price":0.76,"size":0.0,"side":"SELL"}
{"ts":"2026-08-23T17:53:10.818Z","event_type":"best_bid_ask","market_id":"3790397","outcome_index":0,"market_type":"set2","local_side":"home","local_uid":"2026-08-23_hugo_grenier_mees_rottgering","bid":0.3,"ask":0.41,"mid":0.355,"spread":0.11,"bid_size":null,"ask_size":null}
{"ts":"2026-08-23T17:53:10.818Z","event_type":"best_bid_ask","market_id":"3790397","outcome_index":1,"market_type":"set2","local_side":"away","local_uid":"2026-08-23_hugo_grenier_mees_rottgering","bid":0.59,"ask":0.7,"mid":0.645,"spread":0.11,"bid_size":null,"ask_size":null}
{"ts":"2026-08-23T17:53:10.818Z","event_type":"price_change","market_id":"3790397","outcome_index":1,"market_type":"set2","local_side":"away","local_uid":"2026-08-23_hugo_grenier_mees_rottgering","bid":0.59,"ask":0.7,"mid":0.645,"spread":0.11,"price":0.59,"size":103.81,"side":"BUY"}
{"ts":"2026-08-23T17:53:10.818Z","event_type":"price_change","market_id":"3790397","outcome_index":0,"market_type":"set2","local_side":"home","local_uid":"2026-08-23_hugo_grenier_mees_rottgering","bid":0.3,"ask":0.41,"mid":0.355,"spread":0.11,"price":0.41,"size":103.81,"side":"SELL"}
{"ts":"2026-08-23T17:53:10.825Z","event_type":"best_bid_ask","market_id":"3790394","outcome_index":0,"market_type":"set1","local_side":"home","local_uid":"2026-08-23_hugo_grenier_mees_rottgering","bid":0.23,"ask":0.34,"mid":0.285,"spread":0.11,"bid_size":null,"ask_size":null}
{"ts":"2026-08-23T17:53:10.825Z","event_type":"best_bid_ask","market_id":"3790394","outcome_index":1,"market_type":"set1","local_side":"away","local_uid":"2026-08-23_hugo_grenier_mees_rottgering","bid":0.66,"ask":0.77,"mid":0.715,"spread":0.11,"bid_size":null,"ask_size":null}
{"ts":"2026-08-23T17:53:10.825Z","event_type":"price_change","market_id":"3790394","outcome_index":1,"market_type":"set1","local_side":"away","local_uid":"2026-08-23_hugo_grenier_mees_rottgering","bid":0.66,"ask":0.77,"mid":0.715,"spread":0.11,"price":0.66,"size":37.39,"side":"BUY"}
{"ts":"2026-08-23T17:53:10.825Z","event_type":"price_change","market_id":"3790394","outcome_index":0,"market_type":"set1","local_side":"home","local_uid":"2026-08-23_hugo_grenier_mees_rottgering","bid":0.23,"ask":0.34,"mid":0.285,"spread":0.11,"price":0.34,"size":37.39,"side":"SELL"}
{"ts":"2026-08-23T17:53:10.826Z","event_type":"best_bid_ask","market_id":"3790394","outcome_index":0,"market_type":"set1","local_side":"home","local_uid":"2026-08-23_hugo_grenier_mees_rottgering","bid":0.24,"ask":0.34,"mid":0.29,"spread":0.1,"bid_size":null,"ask_size":null}
{"ts":"2026-08-23T17:53:10.826Z","event_type":"best_bid_ask","market_id":"3790394","outcome_index":1,"market_type":"set1","local_side":"away","local_uid":"2026-08-23_hugo_grenier_mees_rottgering","bid":0.66,"ask":0.76,"mid":0.71,"spread":0.1,"bid_size":null,"ask_size":null}
{"ts":"2026-08-23T17:53:10.826Z","event_type":"price_change","market_id":"3790394","outcome_index":0,"market_type":"set1","local_side":"home","local_uid":"2026-08-23_hugo_grenier_mees_rottgering","bid":0.24,"ask":0.34,"mid":0.29,"spread":0.1,"price":0.24,"size":32.96,"side":"BUY"}
{"ts":"2026-08-23T17:53:10.826Z","event_type":"price_change","market_id":"3790394","outcome_index":1,"market_type":"set1","local_side":"away","local_uid":"2026-08-23_hugo_grenier_mees_rottgering","bid":0.66,"ask":0.76,"mid":0.71,"spread":0.1,"price":0.76,"size":32.96,"side":"SELL"}
{"ts":"2026-08-23T17:53:10.860Z","event_type":"best_bid_ask","market_id":"3790397","outcome_index":0,"market_type":"set2","local_side":"home","local_uid":"2026-08-23_hugo_grenier_mees_rottgering","bid":0.3,"ask":0.42,"mid":0.36,"spread":0.12,"bid_size":null,"ask_size":null}
{"ts":"2026-08-23T17:53:10.860Z","event_type":"best_bid_ask","market_id":"3790397","outcome_index":1,"market_type":"set2","local_side":"away","local_uid":"2026-08-23_hugo_grenier_mees_rottgering","bid":0.58,"ask":0.7,"mid":0.64,"spread":0.12,"bid_size":null,"ask_size":null}
{"ts":"2026-08-23T17:53:10.860Z","event_type":"price_change","market_id":"3790397","outcome_index":1,"market_type":"set2","local_side":"away","local_uid":"2026-08-23_hugo_grenier_mees_rottgering","bid":0.58,"ask":0.7,"mid":0.64,"spread":0.12,"price":0.59,"size":0.0,"side":"BUY"}
{"ts":"2026-08-23T17:53:10.860Z","event_type":"price_change","market_id":"3790397","outcome_index":0,"market_type":"set2","local_side":"home","local_uid":"2026-08-23_hugo_grenier_mees_rottgering","bid":0.3,"ask":0.42,"mid":0.36,"spread":0.12,"price":0.41,"size":0.0,"side":"SELL"}
{"ts":"2026-08-23T17:53:10.864Z","event_type":"best_bid_ask","market_id":"3790397","outcome_index":0,"market_type":"set2","local_side":"home","local_uid":"2026-08-23_hugo_grenier_mees_rottgering","bid":0.31,"ask":0.42,"mid":0.365,"spread":0.11,"bid_size":null,"ask_size":null}
{"ts":"2026-08-23T17:53:10.864Z","event_type":"best_bid_ask","market_id":"3790397","outcome_index":1,"market_type":"set2","local_side":"away","local_uid":"2026-08-23_hugo_grenier_mees_rottgering","bid":0.58,"ask":0.69,"mid":0.635,"spread":0.11,"bid_size":null,"ask_size":null}
{"ts":"2026-08-23T17:53:10.864Z","event_type":"price_change","market_id":"3790397","outcome_index":0,"market_type":"set2","local_side":"home","local_uid":"2026-08-23_hugo_grenier_mees_rottgering","bid":0.31,"ask":0.42,"mid":0.365,"spread":0.11,"price":0.31,"size":30.01,"side":"BUY"}
{"ts":"2026-08-23T17:53:10.864Z","event_type":"price_change","market_id":"3790397","outcome_index":1,"market_type":"set2","local_side":"away","local_uid":"2026-08-23_hugo_grenier_mees_rottgering","bid":0.58,"ask":0.69,"mid":0.635,"spread":0.11,"price":0.69,"size":30.01,"side":"SELL"}
{"ts":"2026-08-23T17:53:10.864Z","event_type":"best_bid_ask","market_id":"3790394","outcome_index":0,"market_type":"set1","local_side":"home","local_uid":"2026-08-23_hugo_grenier_mees_rottgering","bid":0.23,"ask":0.36,"mid":0.295,"spread":0.13,"bid_size":null,"ask_size":null}
{"ts":"2026-08-23T17:53:10.865Z","event_type":"best_bid_ask","market_id":"3790394","outcome_index":1,"market_type":"set1","local_side":"away","local_uid":"2026-08-23_hugo_grenier_mees_rottgering","bid":0.64,"ask":0.77,"mid":0.705,"spread":0.13,"bid_size":null,"ask_size":null}
{"ts":"2026-08-23T17:53:10.865Z","event_type":"price_change","market_id":"3790394","outcome_index":1,"market_type":"set1","local_side":"away","local_uid":"2026-08-23_hugo_grenier_mees_rottgering","bid":0.64,"ask":0.77,"mid":0.705,"spread":0.13,"price":0.66,"size":0.0,"side":"BUY"}
{"ts":"2026-08-23T17:53:10.865Z","event_type":"price_change","market_id":"3790394","outcome_index":0,"market_type":"set1","local_side":"home","local_uid":"2026-08-23_hugo_grenier_mees_rottgering","bid":0.23,"ask":0.36,"mid":0.295,"spread":0.13,"price":0.34,"size":0.0,"side":"SELL"}
{"ts":"2026-08-23T17:53:10.895Z","event_type":"best_bid_ask","market_id":"3790394","outcome_index":0,"market_type":"set1","local_side":"home","local_uid":"2026-08-23_hugo_grenier_mees_rottgering","bid":0.22,"ask":0.36,"mid":0.29,"spread":0.14,"bid_size":null,"ask_size":null}
{"ts":"2026-08-23T17:53:10.895Z","event_type":"best_bid_ask","market_id":"3790394","outcome_index":1,"market_type":"set1","local_side":"away","local_uid":"2026-08-23_hugo_grenier_mees_rottgering","bid":0.64,"ask":0.78,"mid":0.71,"spread":0.14,"bid_size":null,"ask_size":null}
{"ts":"2026-08-23T17:53:10.895Z","event_type":"price_change","market_id":"3790394","outcome_index":0,"market_type":"set1","local_side":"home","local_uid":"2026-08-23_hugo_grenier_mees_rottgering","bid":0.22,"ask":0.36,"mid":0.29,"spread":0.14,"price":0.23,"size":0.0,"side":"BUY"}
{"ts":"2026-08-23T17:53:10.895Z","event_type":"price_change","market_id":"3790394","outcome_index":1,"market_type":"set1","local_side":"away","local_uid":"2026-08-23_hugo_grenier_mees_rottgering","bid":0.64,"ask":0.78,"mid":0.71,"spread":0.14,"price":0.77,"size":0.0,"side":"SELL"}
{"ts":"2026-08-23T17:53:10.895Z","event_type":"best_bid_ask","market_id":"3790394","outcome_index":0,"market_type":"set1","local_side":"home","local_uid":"2026-08-23_hugo_grenier_mees_rottgering","bid":0.22,"ask":0.37,"mid":0.295,"spread":0.15,"bid_size":null,"ask_size":null}
{"ts":"2026-08-23T17:53:10.895Z","event_type":"best_bid_ask","market_id":"3790394","outcome_index":1,"market_type":"set1","local_side":"away","local_uid":"2026-08-23_hugo_grenier_mees_rottgering","bid":0.63,"ask":0.78,"mid":0.705,"spread":0.15,"bid_size":null,"ask_size":null}
{"ts":"2026-08-23T17:53:10.896Z","event_type":"price_change","market_id":"3790394","outcome_index":1,"market_type":"set1","local_side":"away","local_uid":"2026-08-23_hugo_grenier_mees_rottgering","bid":0.63,"ask":0.78,"mid":0.705,"spread":0.15,"price":0.64,"size":0.0,"side":"BUY"}
{"ts":"2026-08-23T17:53:10.896Z","event_type":"price_change","market_id":"3790394","outcome_index":0,"market_type":"set1","local_side":"home","local_uid":"2026-08-23_hugo_grenier_mees_rottgering","bid":0.22,"ask":0.37,"mid":0.295,"spread":0.15,"price":0.36,"size":0.0,"side":"SELL"}
{"ts":"2026-08-23T17:53:10.900Z","event_type":"best_bid_ask","market_id":"3790394","outcome_index":0,"market_type":"set1","local_side":"home","local_uid":"2026-08-23_hugo_grenier_mees_rottgering","bid":0.22,"ask":0.38,"mid":0.3,"spread":0.16,"bid_size":null,"ask_size":null}
{"ts":"2026-08-23T17:53:10.900Z","event_type":"best_bid_ask","market_id":"3790394","outcome_index":1,"market_type":"set1","local_side":"away","local_uid":"2026-08-23_hugo_grenier_mees_rottgering","bid":0.62,"ask":0.78,"mid":0.7,"spread":0.16,"bid_size":null,"ask_size":null}
{"ts":"2026-08-23T17:53:10.900Z","event_type":"price_change","market_id":"3790394","outcome_index":1,"market_type":"set1","local_side":"away","local_uid":"2026-08-23_hugo_grenier_mees_rottgering","bid":0.62,"ask":0.78,"mid":0.7,"spread":0.16,"price":0.63,"size":0.0,"side":"BUY"}
{"ts":"2026-08-23T17:53:10.900Z","event_type":"price_change","market_id":"3790394","outcome_index":0,"market_type":"set1","local_side":"home","local_uid":"2026-08-23_hugo_grenier_mees_rottgering","bid":0.22,"ask":0.38,"mid":0.3,"spread":0.16,"price":0.37,"size":0.0,"side":"SELL"}
{"ts":"2026-08-23T17:53:10.904Z","event_type":"best_bid_ask","market_id":"3790394","outcome_index":0,"market_type":"set1","local_side":"home","local_uid":"2026-08-23_hugo_grenier_mees_rottgering","bid":0.23,"ask":0.38,"mid":0.305,"spread":0.15,"bid_size":null,"ask_size":null}
{"ts":"2026-08-23T17:53:10.904Z","event_type":"best_bid_ask","market_id":"3790394","outcome_index":1,"market_type":"set1","local_side":"away","local_uid":"2026-08-23_hugo_grenier_mees_rottgering","bid":0.62,"ask":0.77,"mid":0.695,"spread":0.15,"bid_size":null,"ask_size":null}
{"ts":"2026-08-23T17:53:10.904Z","event_type":"price_change","market_id":"3790394","outcome_index":0,"market_type":"set1","local_side":"home","local_uid":"2026-08-23_hugo_grenier_mees_rottgering","bid":0.23,"ask":0.38,"mid":0.305,"spread":0.15,"price":0.23,"size":11.0,"side":"BUY"}
{"ts":"2026-08-23T17:53:10.904Z","event_type":"price_change","market_id":"3790394","outcome_index":1,"market_type":"set1","local_side":"away","local_uid":"2026-08-23_hugo_grenier_mees_rottgering","bid":0.62,"ask":0.77,"mid":0.695,"spread":0.15,"price":0.77,"size":11.0,"side":"SELL"}
{"ts":"2026-08-23T17:53:10.905Z","event_type":"best_bid_ask","market_id":"3790394","outcome_index":0,"market_type":"set1","local_side":"home","local_uid":"2026-08-23_hugo_grenier_mees_rottgering","bid":0.23,"ask":0.37,"mid":0.3,"spread":0.14,"bid_size":null,"ask_size":null}
{"ts":"2026-08-23T17:53:10.905Z","event_type":"best_bid_ask","market_id":"3790394","outcome_index":1,"market_type":"set1","local_side":"away","local_uid":"2026-08-23_hugo_grenier_mees_rottgering","bid":0.63,"ask":0.77,"mid":0.7,"spread":0.14,"bid_size":null,"ask_size":null}
{"ts":"2026-08-23T17:53:10.905Z","event_type":"price_change","market_id":"3790394","outcome_index":1,"market_type":"set1","local_side":"away","local_uid":"2026-08-23_hugo_grenier_mees_rottgering","bid":0.63,"ask":0.77,"mid":0.7,"spread":0.14,"price":0.63,"size":150.0,"side":"BUY"}
{"ts":"2026-08-23T17:53:10.905Z","event_type":"price_change","market_id":"3790394","outcome_index":0,"market_type":"set1","local_side":"home","local_uid":"2026-08-23_hugo_grenier_mees_rottgering","bid":0.23,"ask":0.37,"mid":0.3,"spread":0.14,"price":0.37,"size":150.0,"side":"SELL"}
{"ts":"2026-08-23T17:53:10.907Z","event_type":"best_bid_ask","market_id":"3790397","outcome_index":0,"market_type":"set2","local_side":"home","local_uid":"2026-08-23_hugo_grenier_mees_rottgering","bid":0.3,"ask":0.42,"mid":0.36,"spread":0.12,"bid_size":null,"ask_size":null}
{"ts":"2026-08-23T17:53:10.907Z","event_type":"best_bid_ask","market_id":"3790397","outcome_index":1,"market_type":"set2","local_side":"away","local_uid":"2026-08-23_hugo_grenier_mees_rottgering","bid":0.58,"ask":0.7,"mid":0.64,"spread":0.12,"bid_size":null,"ask_size":null}
{"ts":"2026-08-23T17:53:10.907Z","event_type":"price_change","market_id":"3790397","outcome_index":0,"market_type":"set2","local_side":"home","local_uid":"2026-08-23_hugo_grenier_mees_rottgering","bid":0.3,"ask":0.42,"mid":0.36,"spread":0.12,"price":0.31,"size":0.0,"side":"BUY"}
{"ts":"2026-08-23T17:53:10.907Z","event_type":"price_change","market_id":"3790397","outcome_index":1,"market_type":"set2","local_side":"away","local_uid":"2026-08-23_hugo_grenier_mees_rottgering","bid":0.58,"ask":0.7,"mid":0.64,"spread":0.12,"price":0.69,"size":0.0,"side":"SELL"}
{"ts":"2026-08-23T17:53:10.971Z","event_type":"best_bid_ask","market_id":"3790397","outcome_index":0,"market_type":"set2","local_side":"home","local_uid":"2026-08-23_hugo_grenier_mees_rottgering","bid":0.31,"ask":0.42,"mid":0.365,"spread":0.11,"bid_size":null,"ask_size":null}
{"ts":"2026-08-23T17:53:10.971Z","event_type":"best_bid_ask","market_id":"3790397","outcome_index":1,"market_type":"set2","local_side":"away","local_uid":"2026-08-23_hugo_grenier_mees_rottgering","bid":0.58,"ask":0.69,"mid":0.635,"spread":0.11,"bid_size":null,"ask_size":null}
{"ts":"2026-08-23T17:53:10.971Z","event_type":"price_change","market_id":"3790397","outcome_index":0,"market_type":"set2","local_side":"home","local_uid":"2026-08-23_hugo_grenier_mees_rottgering","bid":0.31,"ask":0.42,"mid":0.365,"spread":0.11,"price":0.31,"size":11.71,"side":"BUY"}
{"ts":"2026-08-23T17:53:10.971Z","event_type":"price_change","market_id":"3790397","outcome_index":1,"market_type":"set2","local_side":"away","local_uid":"2026-08-23_hugo_grenier_mees_rottgering","bid":0.58,"ask":0.69,"mid":0.635,"spread":0.11,"price":0.69,"size":11.71,"side":"SELL"}
{"ts":"2026-08-23T17:53:11.039Z","event_type":"best_bid_ask","market_id":"3789929","outcome_index":0,"market_type":"match","local_side":"home","local_uid":"2026-08-23_felix_balshaw_sebastian_gorzny","bid":0.32,"ask":0.33,"mid":0.325,"spread":0.01,"bid_size":null,"ask_size":null}
{"ts":"2026-08-23T17:53:11.039Z","event_type":"best_bid_ask","market_id":"3789929","outcome_index":1,"market_type":"match","local_side":"away","local_uid":"2026-08-23_felix_balshaw_sebastian_gorzny","bid":0.67,"ask":0.68,"mid":0.675,"spread":0.01,"bid_size":null,"ask_size":null}
{"ts":"2026-08-23T17:53:11.039Z","event_type":"price_change","market_id":"3789929","outcome_index":0,"market_type":"match","local_side":"home","local_uid":"2026-08-23_felix_balshaw_sebastian_gorzny","bid":0.32,"ask":0.33,"mid":0.325,"spread":0.01,"price":0.32,"size":6000.0,"side":"BUY"}
{"ts":"2026-08-23T17:53:11.039Z","event_type":"price_change","market_id":"3789929","outcome_index":1,"market_type":"match","local_side":"away","local_uid":"2026-08-23_felix_balshaw_sebastian_gorzny","bid":0.67,"ask":0.68,"mid":0.675,"spread":0.01,"price":0.68,"size":6000.0,"side":"SELL"}
{"ts":"2026-08-23T17:53:11.070Z","event_type":"best_bid_ask","market_id":"3789929","outcome_index":0,"market_type":"match","local_side":"home","local_uid":"2026-08-23_felix_balshaw_sebastian_gorzny","bid":0.31,"ask":0.33,"mid":0.32,"spread":0.02,"bid_size":null,"ask_size":null}
{"ts":"2026-08-23T17:53:11.070Z","event_type":"best_bid_ask","market_id":"3789929","outcome_index":1,"market_type":"match","local_side":"away","local_uid":"2026-08-23_felix_balshaw_sebastian_gorzny","bid":0.67,"ask":0.69,"mid":0.68,"spread":0.02,"bid_size":null,"ask_size":null}
{"ts":"2026-08-23T17:53:11.070Z","event_type":"price_change","market_id":"3789929","outcome_index":0,"market_type":"match","local_side":"home","local_uid":"2026-08-23_felix_balshaw_sebastian_gorzny","bid":0.31,"ask":0.33,"mid":0.32,"spread":0.02,"price":0.32,"size":0.0,"side":"BUY"}
{"ts":"2026-08-23T17:53:11.070Z","event_type":"price_change","market_id":"3789929","outcome_index":1,"market_type":"match","local_side":"away","local_uid":"2026-08-23_felix_balshaw_sebastian_gorzny","bid":0.67,"ask":0.69,"mid":0.68,"spread":0.02,"price":0.68,"size":0.0,"side":"SELL"}
{"ts":"2026-08-23T17:53:11.099Z","event_type":"best_bid_ask","market_id":"3790394","outcome_index":0,"market_type":"set1","local_side":"home","local_uid":"2026-08-23_hugo_grenier_mees_rottgering","bid":0.21,"ask":0.37,"mid":0.29,"spread":0.16,"bid_size":null,"ask_size":null}
{"ts":"2026-08-23T17:53:11.099Z","event_type":"best_bid_ask","market_id":"3790394","outcome_index":1,"market_type":"set1","local_side":"away","local_uid":"2026-08-23_hugo_grenier_mees_rottgering","bid":0.63,"ask":0.79,"mid":0.71,"spread":0.16,"bid_size":null,"ask_size":null}
{"ts":"2026-08-23T17:53:11.100Z","event_type":"price_change","market_id":"3790394","outcome_index":0,"market_type":"set1","local_side":"home","local_uid":"2026-08-23_hugo_grenier_mees_rottgering","bid":0.21,"ask":0.37,"mid":0.29,"spread":0.16,"price":0.23,"size":0.0,"side":"BUY"}
{"ts":"2026-08-23T17:53:11.100Z","event_type":"price_change","market_id":"3790394","outcome_index":1,"market_type":"set1","local_side":"away","local_uid":"2026-08-23_hugo_grenier_mees_rottgering","bid":0.63,"ask":0.79,"mid":0.71,"spread":0.16,"price":0.77,"size":0.0,"side":"SELL"}
{"ts":"2026-08-23T17:53:11.114Z","event_type":"best_bid_ask","market_id":"3789929","outcome_index":0,"market_type":"match","local_side":"home","local_uid":"2026-08-23_felix_balshaw_sebastian_gorzny","bid":0.32,"ask":0.33,"mid":0.325,"spread":0.01,"bid_size":null,"ask_size":null}
{"ts":"2026-08-23T17:53:11.114Z","event_type":"best_bid_ask","market_id":"3789929","outcome_index":1,"market_type":"match","local_side":"away","local_uid":"2026-08-23_felix_balshaw_sebastian_gorzny","bid":0.67,"ask":0.68,"mid":0.675,"spread":0.01,"bid_size":null,"ask_size":null}
{"ts":"2026-08-23T17:53:11.114Z","event_type":"price_change","market_id":"3789929","outcome_index":0,"market_type":"match","local_side":"home","local_uid":"2026-08-23_felix_balshaw_sebastian_gorzny","bid":0.32,"ask":0.33,"mid":0.325,"spread":0.01,"price":0.32,"size":30.0,"side":"BUY"}
{"ts":"2026-08-23T17:53:11.114Z","event_type":"price_change","market_id":"3789929","outcome_index":1,"market_type":"match","local_side":"away","local_uid":"2026-08-23_felix_balshaw_sebastian_gorzny","bid":0.67,"ask":0.68,"mid":0.675,"spread":0.01,"price":0.68,"size":30.0,"side":"SELL"}
{"ts":"2026-08-23T17:53:11.227Z","event_type":"price_change","market_id":"3795958","outcome_index":0,"market_type":"match","local_side":"home","local_uid":"2026-08-23_bruno_kuzuhara_kody_pearson","bid":0.961,"ask":0.967,"mid":0.964,"spread":0.006,"price":0.956,"size":0.0,"side":"BUY"}
{"ts":"2026-08-23T17:53:11.227Z","event_type":"price_change","market_id":"3795958","outcome_index":1,"market_type":"match","local_side":"away","local_uid":"2026-08-23_bruno_kuzuhara_kody_pearson","bid":0.033,"ask":0.039,"mid":0.036,"spread":0.006,"price":0.044,"size":0.0,"side":"SELL"}
{"ts":"2026-08-23T17:53:11.230Z","event_type":"best_bid_ask","market_id":"3790323","outcome_index":0,"market_type":"set2","local_side":"home","local_uid":"2026-08-23_felix_balshaw_sebastian_gorzny","bid":0.52,"ask":0.64,"mid":0.58,"spread":0.12,"bid_size":null,"ask_size":null}
{"ts":"2026-08-23T17:53:11.230Z","event_type":"best_bid_ask","market_id":"3790323","outcome_index":1,"market_type":"set2","local_side":"away","local_uid":"2026-08-23_felix_balshaw_sebastian_gorzny","bid":0.36,"ask":0.48,"mid":0.42,"spread":0.12,"bid_size":null,"ask_size":null}
{"ts":"2026-08-23T17:53:11.230Z","event_type":"price_change","market_id":"3790323","outcome_index":0,"market_type":"set2","local_side":"home","local_uid":"2026-08-23_felix_balshaw_sebastian_gorzny","bid":0.52,"ask":0.64,"mid":0.58,"spread":0.12,"price":0.52,"size":88.0,"side":"BUY"}
{"ts":"2026-08-23T17:53:11.230Z","event_type":"price_change","market_id":"3790323","outcome_index":1,"market_type":"set2","local_side":"away","local_uid":"2026-08-23_felix_balshaw_sebastian_gorzny","bid":0.36,"ask":0.48,"mid":0.42,"spread":0.12,"price":0.48,"size":88.0,"side":"SELL"}
{"ts":"2026-08-23T17:53:11.300Z","event_type":"best_bid_ask","market_id":"3790323","outcome_index":0,"market_type":"set2","local_side":"home","local_uid":"2026-08-23_felix_balshaw_sebastian_gorzny","bid":0.52,"ask":1.0,"mid":0.76,"spread":0.48,"bid_size":null,"ask_size":null}
{"ts":"2026-08-23T17:53:11.301Z","event_type":"best_bid_ask","market_id":"3790323","outcome_index":1,"market_type":"set2","local_side":"away","local_uid":"2026-08-23_felix_balshaw_sebastian_gorzny","bid":0.0,"ask":0.48,"mid":0.24,"spread":0.48,"bid_size":null,"ask_size":null}
{"ts":"2026-08-23T17:53:11.301Z","event_type":"price_change","market_id":"3790323","outcome_index":1,"market_type":"set2","local_side":"away","local_uid":"2026-08-23_felix_balshaw_sebastian_gorzny","bid":0.0,"ask":0.48,"mid":0.24,"spread":0.48,"price":0.36,"size":0.0,"side":"BUY"}
{"ts":"2026-08-23T17:53:11.301Z","event_type":"price_change","market_id":"3790323","outcome_index":0,"market_type":"set2","local_side":"home","local_uid":"2026-08-23_felix_balshaw_sebastian_gorzny","bid":0.52,"ask":1.0,"mid":0.76,"spread":0.48,"price":0.64,"size":0.0,"side":"SELL"}
{"ts":"2026-08-23T17:53:11.312Z","event_type":"best_bid_ask","market_id":"3790323","outcome_index":0,"market_type":"set2","local_side":"home","local_uid":"2026-08-23_felix_balshaw_sebastian_gorzny","bid":0.54,"ask":1.0,"mid":0.77,"spread":0.46,"bid_size":null,"ask_size":null}
{"ts":"2026-08-23T17:53:11.312Z","event_type":"best_bid_ask","market_id":"3790323","outcome_index":1,"market_type":"set2","local_side":"away","local_uid":"2026-08-23_felix_balshaw_sebastian_gorzny","bid":0.0,"ask":0.46,"mid":0.23,"spread":0.46,"bid_size":null,"ask_size":null}
{"ts":"2026-08-23T17:53:11.313Z","event_type":"price_change","market_id":"3790323","outcome_index":0,"market_type":"set2","local_side":"home","local_uid":"2026-08-23_felix_balshaw_sebastian_gorzny","bid":0.54,"ask":1.0,"mid":0.77,"spread":0.46,"price":0.54,"size":150.0,"side":"BUY"}
{"ts":"2026-08-23T17:53:11.313Z","event_type":"price_change","market_id":"3790323","outcome_index":1,"market_type":"set2","local_side":"away","local_uid":"2026-08-23_felix_balshaw_sebastian_gorzny","bid":0.0,"ask":0.46,"mid":0.23,"spread":0.46,"price":0.46,"size":150.0,"side":"SELL"}
{"ts":"2026-08-23T17:53:11.321Z","event_type":"best_bid_ask","market_id":"3790323","outcome_index":0,"market_type":"set2","local_side":"home","local_uid":"2026-08-23_felix_balshaw_sebastian_gorzny","bid":0.54,"ask":0.67,"mid":0.605,"spread":0.13,"bid_size":null,"ask_size":null}
{"ts":"2026-08-23T17:53:11.324Z","event_type":"best_bid_ask","market_id":"3790323","outcome_index":1,"market_type":"set2","local_side":"away","local_uid":"2026-08-23_felix_balshaw_sebastian_gorzny","bid":0.33,"ask":0.46,"mid":0.395,"spread":0.13,"bid_size":null,"ask_size":null}
{"ts":"2026-08-23T17:53:11.324Z","event_type":"price_change","market_id":"3790323","outcome_index":1,"market_type":"set2","local_side":"away","local_uid":"2026-08-23_felix_balshaw_sebastian_gorzny","bid":0.33,"ask":0.46,"mid":0.395,"spread":0.13,"price":0.33,"size":150.0,"side":"BUY"}
{"ts":"2026-08-23T17:53:11.324Z","event_type":"price_change","market_id":"3790323","outcome_index":0,"market_type":"set2","local_side":"home","local_uid":"2026-08-23_felix_balshaw_sebastian_gorzny","bid":0.54,"ask":0.67,"mid":0.605,"spread":0.13,"price":0.67,"size":150.0,"side":"SELL"}
{"ts":"2026-08-23T17:53:11.335Z","event_type":"best_bid_ask","market_id":"3790323","outcome_index":0,"market_type":"set2","local_side":"home","local_uid":"2026-08-23_felix_balshaw_sebastian_gorzny","bid":0.54,"ask":0.64,"mid":0.59,"spread":0.1,"bid_size":null,"ask_size":null}
{"ts":"2026-08-23T17:53:11.335Z","event_type":"best_bid_ask","market_id":"3790323","outcome_index":1,"market_type":"set2","local_side":"away","local_uid":"2026-08-23_felix_balshaw_sebastian_gorzny","bid":0.36,"ask":0.46,"mid":0.41,"spread":0.1,"bid_size":null,"ask_size":null}
{"ts":"2026-08-23T17:53:11.335Z","event_type":"price_change","market_id":"3790323","outcome_index":1,"market_type":"set2","local_side":"away","local_uid":"2026-08-23_felix_balshaw_sebastian_gorzny","bid":0.36,"ask":0.46,"mid":0.41,"spread":0.1,"price":0.36,"size":54.72,"side":"BUY"}
{"ts":"2026-08-23T17:53:11.335Z","event_type":"price_change","market_id":"3790323","outcome_index":0,"market_type":"set2","local_side":"home","local_uid":"2026-08-23_felix_balshaw_sebastian_gorzny","bid":0.54,"ask":0.64,"mid":0.59,"spread":0.1,"price":0.64,"size":54.72,"side":"SELL"}
{"ts":"2026-08-23T17:53:11.341Z","event_type":"best_bid_ask","market_id":"3790397","outcome_index":0,"market_type":"set2","local_side":"home","local_uid":"2026-08-23_hugo_grenier_mees_rottgering","bid":0.31,"ask":0.41,"mid":0.36,"spread":0.1,"bid_size":null,"ask_size":null}
{"ts":"2026-08-23T17:53:11.341Z","event_type":"best_bid_ask","market_id":"3790397","outcome_index":1,"market_type":"set2","local_side":"away","local_uid":"2026-08-23_hugo_grenier_mees_rottgering","bid":0.59,"ask":0.69,"mid":0.64,"spread":0.1,"bid_size":null,"ask_size":null}
{"ts":"2026-08-23T17:53:11.342Z","event_type":"price_change","market_id":"3790397","outcome_index":1,"market_type":"set2","local_side":"away","local_uid":"2026-08-23_hugo_grenier_mees_rottgering","bid":0.59,"ask":0.69,"mid":0.64,"spread":0.1,"price":0.59,"size":31.49,"side":"BUY"}
{"ts":"2026-08-23T17:53:11.342Z","event_type":"price_change","market_id":"3790397","outcome_index":0,"market_type":"set2","local_side":"home","local_uid":"2026-08-23_hugo_grenier_mees_rottgering","bid":0.31,"ask":0.41,"mid":0.36,"spread":0.1,"price":0.41,"size":31.49,"side":"SELL"}
{"ts":"2026-08-23T17:53:11.346Z","event_type":"best_bid_ask","market_id":"3790394","outcome_index":0,"market_type":"set1","local_side":"home","local_uid":"2026-08-23_hugo_grenier_mees_rottgering","bid":0.21,"ask":0.41,"mid":0.31,"spread":0.2,"bid_size":null,"ask_size":null}
{"ts":"2026-08-23T17:53:11.346Z","event_type":"best_bid_ask","market_id":"3790394","outcome_index":1,"market_type":"set1","local_side":"away","local_uid":"2026-08-23_hugo_grenier_mees_rottgering","bid":0.59,"ask":0.79,"mid":0.69,"spread":0.2,"bid_size":null,"ask_size":null}
{"ts":"2026-08-23T17:53:11.347Z","event_type":"price_change","market_id":"3790394","outcome_index":1,"market_type":"set1","local_side":"away","local_uid":"2026-08-23_hugo_grenier_mees_rottgering","bid":0.59,"ask":0.79,"mid":0.69,"spread":0.2,"price":0.63,"size":0.0,"side":"BUY"}
{"ts":"2026-08-23T17:53:11.347Z","event_type":"price_change","market_id":"3790394","outcome_index":0,"market_type":"set1","local_side":"home","local_uid":"2026-08-23_hugo_grenier_mees_rottgering","bid":0.21,"ask":0.41,"mid":0.31,"spread":0.2,"price":0.37,"size":0.0,"side":"SELL"}
{"ts":"2026-08-23T17:53:11.357Z","event_type":"best_bid_ask","market_id":"3790394","outcome_index":0,"market_type":"set1","local_side":"home","local_uid":"2026-08-23_hugo_grenier_mees_rottgering","bid":0.21,"ask":0.42,"mid":0.315,"spread":0.21,"bid_size":null,"ask_size":null}
{"ts":"2026-08-23T17:53:11.357Z","event_type":"best_bid_ask","market_id":"3790394","outcome_index":1,"market_type":"set1","local_side":"away","local_uid":"2026-08-23_hugo_grenier_mees_rottgering","bid":0.58,"ask":0.79,"mid":0.685,"spread":0.21,"bid_size":null,"ask_size":null}
{"ts":"2026-08-23T17:53:11.358Z","event_type":"price_change","market_id":"3790394","outcome_index":1,"market_type":"set1","local_side":"away","local_uid":"2026-08-23_hugo_grenier_mees_rottgering","bid":0.58,"ask":0.79,"mid":0.685,"spread":0.21,"price":0.59,"size":0.0,"side":"BUY"}
{"ts":"2026-08-23T17:53:11.358Z","event_type":"price_change","market_id":"3790394","outcome_index":0,"market_type":"set1","local_side":"home","local_uid":"2026-08-23_hugo_grenier_mees_rottgering","bid":0.21,"ask":0.42,"mid":0.315,"spread":0.21,"price":0.41,"size":0.0,"side":"SELL"}
{"ts":"2026-08-23T17:53:11.474Z","event_type":"best_bid_ask","market_id":"3790394","outcome_index":0,"market_type":"set1","local_side":"home","local_uid":"2026-08-23_hugo_grenier_mees_rottgering","bid":0.16,"ask":0.42,"mid":0.29,"spread":0.26,"bid_size":null,"ask_size":null}
{"ts":"2026-08-23T17:53:11.474Z","event_type":"best_bid_ask","market_id":"3790394","outcome_index":1,"market_type":"set1","local_side":"away","local_uid":"2026-08-23_hugo_grenier_mees_rottgering","bid":0.58,"ask":0.84,"mid":0.71,"spread":0.26,"bid_size":null,"ask_size":null}
{"ts":"2026-08-23T17:53:11.474Z","event_type":"price_change","market_id":"3790394","outcome_index":0,"market_type":"set1","local_side":"home","local_uid":"2026-08-23_hugo_grenier_mees_rottgering","bid":0.16,"ask":0.42,"mid":0.29,"spread":0.26,"price":0.21,"size":0.0,"side":"BUY"}
{"ts":"2026-08-23T17:53:11.474Z","event_type":"price_change","market_id":"3790394","outcome_index":1,"market_type":"set1","local_side":"away","local_uid":"2026-08-23_hugo_grenier_mees_rottgering","bid":0.58,"ask":0.84,"mid":0.71,"spread":0.26,"price":0.79,"size":0.0,"side":"SELL"}
{"ts":"2026-08-23T17:53:11.623Z","event_type":"best_bid_ask","market_id":"3790394","outcome_index":0,"market_type":"set1","local_side":"home","local_uid":"2026-08-23_hugo_grenier_mees_rottgering","bid":0.16,"ask":0.41,"mid":0.285,"spread":0.25,"bid_size":null,"ask_size":null}
{"ts":"2026-08-23T17:53:11.623Z","event_type":"best_bid_ask","market_id":"3790394","outcome_index":1,"market_type":"set1","local_side":"away","local_uid":"2026-08-23_hugo_grenier_mees_rottgering","bid":0.59,"ask":0.84,"mid":0.715,"spread":0.25,"bid_size":null,"ask_size":null}
{"ts":"2026-08-23T17:53:11.623Z","event_type":"price_change","market_id":"3790394","outcome_index":1,"market_type":"set1","local_side":"away","local_uid":"2026-08-23_hugo_grenier_mees_rottgering","bid":0.59,"ask":0.84,"mid":0.715,"spread":0.25,"price":0.59,"size":11.0,"side":"BUY"}
{"ts":"2026-08-23T17:53:11.623Z","event_type":"price_change","market_id":"3790394","outcome_index":0,"market_type":"set1","local_side":"home","local_uid":"2026-08-23_hugo_grenier_mees_rottgering","bid":0.16,"ask":0.41,"mid":0.285,"spread":0.25,"price":0.41,"size":11.0,"side":"SELL"}
{"ts":"2026-08-23T17:53:11.871Z","event_type":"best_bid_ask","market_id":"3795958","outcome_index":0,"market_type":"match","local_side":"home","local_uid":"2026-08-23_bruno_kuzuhara_kody_pearson","bid":0.96,"ask":0.967,"mid":0.9635,"spread":0.007,"bid_size":null,"ask_size":null}
{"ts":"2026-08-23T17:53:11.871Z","event_type":"best_bid_ask","market_id":"3795958","outcome_index":1,"market_type":"match","local_side":"away","local_uid":"2026-08-23_bruno_kuzuhara_kody_pearson","bid":0.033,"ask":0.04,"mid":0.0365,"spread":0.007,"bid_size":null,"ask_size":null}
{"ts":"2026-08-23T17:53:11.883Z","event_type":"best_bid_ask","market_id":"3790323","outcome_index":0,"market_type":"set2","local_side":"home","local_uid":"2026-08-23_felix_balshaw_sebastian_gorzny","bid":0.54,"ask":0.66,"mid":0.6,"spread":0.12,"bid_size":null,"ask_size":null}
{"ts":"2026-08-23T17:53:11.883Z","event_type":"best_bid_ask","market_id":"3790323","outcome_index":1,"market_type":"set2","local_side":"away","local_uid":"2026-08-23_felix_balshaw_sebastian_gorzny","bid":0.34,"ask":0.46,"mid":0.4,"spread":0.12,"bid_size":null,"ask_size":null}
{"ts":"2026-08-23T17:53:11.884Z","event_type":"price_change","market_id":"3790323","outcome_index":1,"market_type":"set2","local_side":"away","local_uid":"2026-08-23_felix_balshaw_sebastian_gorzny","bid":0.34,"ask":0.46,"mid":0.4,"spread":0.12,"price":0.36,"size":0.0,"side":"BUY"}
{"ts":"2026-08-23T17:53:11.884Z","event_type":"price_change","market_id":"3790323","outcome_index":0,"market_type":"set2","local_side":"home","local_uid":"2026-08-23_felix_balshaw_sebastian_gorzny","bid":0.54,"ask":0.66,"mid":0.6,"spread":0.12,"price":0.64,"size":0.0,"side":"SELL"}
{"ts":"2026-08-23T17:53:11.923Z","event_type":"best_bid_ask","market_id":"3790323","outcome_index":0,"market_type":"set2","local_side":"home","local_uid":"2026-08-23_felix_balshaw_sebastian_gorzny","bid":0.54,"ask":0.65,"mid":0.595,"spread":0.11,"bid_size":null,"ask_size":null}
{"ts":"2026-08-23T17:53:11.924Z","event_type":"best_bid_ask","market_id":"3790323","outcome_index":1,"market_type":"set2","local_side":"away","local_uid":"2026-08-23_felix_balshaw_sebastian_gorzny","bid":0.35,"ask":0.46,"mid":0.405,"spread":0.11,"bid_size":null,"ask_size":null}
{"ts":"2026-08-23T17:53:11.924Z","event_type":"price_change","market_id":"3790323","outcome_index":1,"market_type":"set2","local_side":"away","local_uid":"2026-08-23_felix_balshaw_sebastian_gorzny","bid":0.35,"ask":0.46,"mid":0.405,"spread":0.11,"price":0.35,"size":74.78,"side":"BUY"}
{"ts":"2026-08-23T17:53:11.924Z","event_type":"price_change","market_id":"3790323","outcome_index":0,"market_type":"set2","local_side":"home","local_uid":"2026-08-23_felix_balshaw_sebastian_gorzny","bid":0.54,"ask":0.65,"mid":0.595,"spread":0.11,"price":0.65,"size":74.78,"side":"SELL"}
{"ts":"2026-08-23T17:53:11.977Z","event_type":"best_bid_ask","market_id":"3790397","outcome_index":0,"market_type":"set2","local_side":"home","local_uid":"2026-08-23_hugo_grenier_mees_rottgering","bid":0.31,"ask":0.42,"mid":0.365,"spread":0.11,"bid_size":null,"ask_size":null}
{"ts":"2026-08-23T17:53:11.977Z","event_type":"best_bid_ask","market_id":"3790397","outcome_index":1,"market_type":"set2","local_side":"away","local_uid":"2026-08-23_hugo_grenier_mees_rottgering","bid":0.58,"ask":0.69,"mid":0.635,"spread":0.11,"bid_size":null,"ask_size":null}
{"ts":"2026-08-23T17:53:11.977Z","event_type":"price_change","market_id":"3790397","outcome_index":1,"market_type":"set2","local_side":"away","local_uid":"2026-08-23_hugo_grenier_mees_rottgering","bid":0.58,"ask":0.69,"mid":0.635,"spread":0.11,"price":0.59,"size":0.0,"side":"BUY"}
{"ts":"2026-08-23T17:53:11.977Z","event_type":"price_change","market_id":"3790397","outcome_index":0,"market_type":"set2","local_side":"home","local_uid":"2026-08-23_hugo_grenier_mees_rottgering","bid":0.31,"ask":0.42,"mid":0.365,"spread":0.11,"price":0.41,"size":0.0,"side":"SELL"}
{"ts":"2026-08-23T17:53:12.015Z","event_type":"best_bid_ask","market_id":"3790397","outcome_index":0,"market_type":"set2","local_side":"home","local_uid":"2026-08-23_hugo_grenier_mees_rottgering","bid":0.31,"ask":0.41,"mid":0.36,"spread":0.1,"bid_size":null,"ask_size":null}
{"ts":"2026-08-23T17:53:12.015Z","event_type":"best_bid_ask","market_id":"3790397","outcome_index":1,"market_type":"set2","local_side":"away","local_uid":"2026-08-23_hugo_grenier_mees_rottgering","bid":0.59,"ask":0.69,"mid":0.64,"spread":0.1,"bid_size":null,"ask_size":null}
{"ts":"2026-08-23T17:53:12.015Z","event_type":"price_change","market_id":"3790397","outcome_index":1,"market_type":"set2","local_side":"away","local_uid":"2026-08-23_hugo_grenier_mees_rottgering","bid":0.59,"ask":0.69,"mid":0.64,"spread":0.1,"price":0.59,"size":129.88,"side":"BUY"}
{"ts":"2026-08-23T17:53:12.015Z","event_type":"price_change","market_id":"3790397","outcome_index":0,"market_type":"set2","local_side":"home","local_uid":"2026-08-23_hugo_grenier_mees_rottgering","bid":0.31,"ask":0.41,"mid":0.36,"spread":0.1,"price":0.41,"size":129.88,"side":"SELL"}
{"ts":"2026-08-23T17:53:12.059Z","event_type":"book","market_id":"3789929","outcome_index":0,"market_type":"match","local_side":"home","local_uid":"2026-08-23_felix_balshaw_sebastian_gorzny","bid":0.32,"ask":0.33,"mid":0.325,"spread":0.01,"bid_size":14491.1,"ask_size":22.96}
{"ts":"2026-08-23T17:53:12.060Z","event_type":"book","market_id":"3789929","outcome_index":1,"market_type":"match","local_side":"away","local_uid":"2026-08-23_felix_balshaw_sebastian_gorzny","bid":0.67,"ask":0.68,"mid":0.675,"spread":0.01,"bid_size":22.96,"ask_size":14491.1}
{"ts":"2026-08-23T17:53:12.061Z","event_type":"book","market_id":"3795958","outcome_index":0,"market_type":"match","local_side":"home","local_uid":"2026-08-23_bruno_kuzuhara_kody_pearson","bid":0.96,"ask":0.967,"mid":0.9635,"spread":0.007,"bid_size":4.5,"ask_size":11687.7}
{"ts":"2026-08-23T17:53:12.061Z","event_type":"book","market_id":"3795958","outcome_index":1,"market_type":"match","local_side":"away","local_uid":"2026-08-23_bruno_kuzuhara_kody_pearson","bid":0.033,"ask":0.04,"mid":0.0365,"spread":0.007,"bid_size":11687.7,"ask_size":4.5}
{"ts":"2026-08-23T17:53:12.061Z","event_type":"best_bid_ask","market_id":"3795960","outcome_index":0,"market_type":"match","local_side":"home","local_uid":"2026-08-23_enmanuel_munoz_thomas_fancutt","bid":0.001,"ask":0.008,"mid":0.0045,"spread":0.007,"bid_size":null,"ask_size":null}
{"ts":"2026-08-23T17:53:12.061Z","event_type":"best_bid_ask","market_id":"3795960","outcome_index":1,"market_type":"match","local_side":"away","local_uid":"2026-08-23_enmanuel_munoz_thomas_fancutt","bid":0.992,"ask":0.999,"mid":0.9955,"spread":0.007,"bid_size":null,"ask_size":null}
{"ts":"2026-08-23T17:53:12.062Z","event_type":"book","market_id":"3795960","outcome_index":0,"market_type":"match","local_side":"home","local_uid":"2026-08-23_enmanuel_munoz_thomas_fancutt","bid":0.001,"ask":0.008,"mid":0.0045,"spread":0.007,"bid_size":174.6,"ask_size":3956.0}
{"ts":"2026-08-23T17:53:12.062Z","event_type":"book","market_id":"3795960","outcome_index":1,"market_type":"match","local_side":"away","local_uid":"2026-08-23_enmanuel_munoz_thomas_fancutt","bid":0.992,"ask":0.999,"mid":0.9955,"spread":0.007,"bid_size":3956.0,"ask_size":174.6}
{"ts":"2026-08-23T17:53:12.062Z","event_type":"best_bid_ask","market_id":"3789929","outcome_index":0,"market_type":"match","local_side":"home","local_uid":"2026-08-23_felix_balshaw_sebastian_gorzny","bid":0.33,"ask":0.34,"mid":0.335,"spread":0.01,"bid_size":null,"ask_size":null}
{"ts":"2026-08-23T17:53:12.062Z","event_type":"best_bid_ask","market_id":"3789929","outcome_index":1,"market_type":"match","local_side":"away","local_uid":"2026-08-23_felix_balshaw_sebastian_gorzny","bid":0.66,"ask":0.67,"mid":0.665,"spread":0.01,"bid_size":null,"ask_size":null}
{"ts":"2026-08-23T17:53:12.063Z","event_type":"price_change","market_id":"3789929","outcome_index":0,"market_type":"match","local_side":"home","local_uid":"2026-08-23_felix_balshaw_sebastian_gorzny","bid":0.33,"ask":0.34,"mid":0.335,"spread":0.01,"price":0.33,"size":77.04,"side":"BUY"}
{"ts":"2026-08-23T17:53:12.063Z","event_type":"price_change","market_id":"3789929","outcome_index":1,"market_type":"match","local_side":"away","local_uid":"2026-08-23_felix_balshaw_sebastian_gorzny","bid":0.66,"ask":0.67,"mid":0.665,"spread":0.01,"price":0.67,"size":77.04,"side":"SELL"}
{"ts":"2026-08-23T17:53:12.063Z","event_type":"book","market_id":"3789929","outcome_index":0,"market_type":"match","local_side":"home","local_uid":"2026-08-23_felix_balshaw_sebastian_gorzny","bid":0.33,"ask":0.34,"mid":0.335,"spread":0.01,"bid_size":77.04,"ask_size":10.0}
{"ts":"2026-08-23T17:53:12.063Z","event_type":"book","market_id":"3789929","outcome_index":1,"market_type":"match","local_side":"away","local_uid":"2026-08-23_felix_balshaw_sebastian_gorzny","bid":0.66,"ask":0.67,"mid":0.665,"spread":0.01,"bid_size":10.0,"ask_size":77.04}
{"ts":"2026-08-23T17:53:12.099Z","event_type":"last_trade_price","market_id":"3789929","outcome_index":0,"market_type":"match","local_side":"home","local_uid":"2026-08-23_felix_balshaw_sebastian_gorzny","last_trade":0.33,"trade_size":10.0303,"trade_side":"BUY","trade_notional":3.31}
{"ts":"2026-08-23T17:53:12.111Z","event_type":"last_trade_price","market_id":"3795958","outcome_index":1,"market_type":"match","local_side":"away","local_uid":"2026-08-23_bruno_kuzuhara_kody_pearson","last_trade":0.04,"trade_size":310.5,"trade_side":"BUY","trade_notional":12.42}
{"ts":"2026-08-23T17:53:12.130Z","event_type":"best_bid_ask","market_id":"3789929","outcome_index":0,"market_type":"match","local_side":"home","local_uid":"2026-08-23_felix_balshaw_sebastian_gorzny","bid":0.33,"ask":0.35,"mid":0.34,"spread":0.02,"bid_size":null,"ask_size":null}
{"ts":"2026-08-23T17:53:12.130Z","event_type":"best_bid_ask","market_id":"3789929","outcome_index":1,"market_type":"match","local_side":"away","local_uid":"2026-08-23_felix_balshaw_sebastian_gorzny","bid":0.65,"ask":0.67,"mid":0.66,"spread":0.02,"bid_size":null,"ask_size":null}
{"ts":"2026-08-23T17:53:12.130Z","event_type":"price_change","market_id":"3789929","outcome_index":1,"market_type":"match","local_side":"away","local_uid":"2026-08-23_felix_balshaw_sebastian_gorzny","bid":0.65,"ask":0.67,"mid":0.66,"spread":0.02,"price":0.66,"size":0.0,"side":"BUY"}
{"ts":"2026-08-23T17:53:12.130Z","event_type":"price_change","market_id":"3789929","outcome_index":0,"market_type":"match","local_side":"home","local_uid":"2026-08-23_felix_balshaw_sebastian_gorzny","bid":0.33,"ask":0.35,"mid":0.34,"spread":0.02,"price":0.34,"size":0.0,"side":"SELL"}
{"ts":"2026-08-23T17:53:12.208Z","event_type":"last_trade_price","market_id":"3789929","outcome_index":0,"market_type":"match","local_side":"home","local_uid":"2026-08-23_felix_balshaw_sebastian_gorzny","last_trade":0.33,"trade_size":22.96,"trade_side":"BUY","trade_notional":7.5768}
{"ts":"2026-08-23T17:53:12.224Z","event_type":"best_bid_ask","market_id":"3790397","outcome_index":0,"market_type":"set2","local_side":"home","local_uid":"2026-08-23_hugo_grenier_mees_rottgering","bid":0.31,"ask":0.42,"mid":0.365,"spread":0.11,"bid_size":null,"ask_size":null}
{"ts":"2026-08-23T17:53:12.224Z","event_type":"best_bid_ask","market_id":"3790397","outcome_index":1,"market_type":"set2","local_side":"away","local_uid":"2026-08-23_hugo_grenier_mees_rottgering","bid":0.58,"ask":0.69,"mid":0.635,"spread":0.11,"bid_size":null,"ask_size":null}
{"ts":"2026-08-23T17:53:12.224Z","event_type":"price_change","market_id":"3790397","outcome_index":1,"market_type":"set2","local_side":"away","local_uid":"2026-08-23_hugo_grenier_mees_rottgering","bid":0.58,"ask":0.69,"mid":0.635,"spread":0.11,"price":0.59,"size":0.0,"side":"BUY"}
{"ts":"2026-08-23T17:53:12.224Z","event_type":"price_change","market_id":"3790397","outcome_index":0,"market_type":"set2","local_side":"home","local_uid":"2026-08-23_hugo_grenier_mees_rottgering","bid":0.31,"ask":0.42,"mid":0.365,"spread":0.11,"price":0.41,"size":0.0,"side":"SELL"}
{"ts":"2026-08-23T17:53:12.254Z","event_type":"best_bid_ask","market_id":"3789929","outcome_index":0,"market_type":"match","local_side":"home","local_uid":"2026-08-23_felix_balshaw_sebastian_gorzny","bid":0.34,"ask":0.35,"mid":0.345,"spread":0.01,"bid_size":null,"ask_size":null}
{"ts":"2026-08-23T17:53:12.254Z","event_type":"best_bid_ask","market_id":"3789929","outcome_index":1,"market_type":"match","local_side":"away","local_uid":"2026-08-23_felix_balshaw_sebastian_gorzny","bid":0.65,"ask":0.66,"mid":0.655,"spread":0.01,"bid_size":null,"ask_size":null}
{"ts":"2026-08-23T17:53:12.255Z","event_type":"price_change","market_id":"3789929","outcome_index":0,"market_type":"match","local_side":"home","local_uid":"2026-08-23_felix_balshaw_sebastian_gorzny","bid":0.34,"ask":0.35,"mid":0.345,"spread":0.01,"price":0.34,"size":3494.12,"side":"BUY"}
{"ts":"2026-08-23T17:53:12.255Z","event_type":"price_change","market_id":"3789929","outcome_index":1,"market_type":"match","local_side":"away","local_uid":"2026-08-23_felix_balshaw_sebastian_gorzny","bid":0.65,"ask":0.66,"mid":0.655,"spread":0.01,"price":0.66,"size":3494.12,"side":"SELL"}
{"ts":"2026-08-23T17:53:12.260Z","event_type":"best_bid_ask","market_id":"3790397","outcome_index":0,"market_type":"set2","local_side":"home","local_uid":"2026-08-23_hugo_grenier_mees_rottgering","bid":0.31,"ask":0.41,"mid":0.36,"spread":0.1,"bid_size":null,"ask_size":null}
{"ts":"2026-08-23T17:53:12.261Z","event_type":"best_bid_ask","market_id":"3790397","outcome_index":1,"market_type":"set2","local_side":"away","local_uid":"2026-08-23_hugo_grenier_mees_rottgering","bid":0.59,"ask":0.69,"mid":0.64,"spread":0.1,"bid_size":null,"ask_size":null}
{"ts":"2026-08-23T17:53:12.261Z","event_type":"price_change","market_id":"3790397","outcome_index":1,"market_type":"set2","local_side":"away","local_uid":"2026-08-23_hugo_grenier_mees_rottgering","bid":0.59,"ask":0.69,"mid":0.64,"spread":0.1,"price":0.59,"size":59.78,"side":"BUY"}
{"ts":"2026-08-23T17:53:12.262Z","event_type":"price_change","market_id":"3790397","outcome_index":0,"market_type":"set2","local_side":"home","local_uid":"2026-08-23_hugo_grenier_mees_rottgering","bid":0.31,"ask":0.41,"mid":0.36,"spread":0.1,"price":0.41,"size":59.78,"side":"SELL"}
{"ts":"2026-08-23T17:53:12.283Z","event_type":"last_trade_price","market_id":"3795960","outcome_index":1,"market_type":"match","local_side":"away","local_uid":"2026-08-23_enmanuel_munoz_thomas_fancutt","last_trade":0.999,"trade_size":200.2348,"trade_side":"BUY","trade_notional":200.0346}
{"ts":"2026-08-23T17:53:12.505Z","event_type":"price_change","market_id":"3795972","outcome_index":0,"market_type":"match","local_side":"home","local_uid":"2026-08-23_siddhant_banthia_matt_kuhar","bid":0.3,"ask":0.31,"mid":0.305,"spread":0.01,"price":0.29,"size":2604.55,"side":"BUY"}
{"ts":"2026-08-23T17:53:12.505Z","event_type":"price_change","market_id":"3795972","outcome_index":1,"market_type":"match","local_side":"away","local_uid":"2026-08-23_siddhant_banthia_matt_kuhar","bid":0.69,"ask":0.7,"mid":0.695,"spread":0.01,"price":0.71,"size":2604.55,"side":"SELL"}
{"ts":"2026-08-23T17:53:12.547Z","event_type":"price_change","market_id":"3795956","outcome_index":1,"market_type":"match","local_side":"away","local_uid":"2026-08-23_evan_zhu_arthur_reymond","bid":0.49,"ask":0.5,"mid":0.495,"spread":0.01,"price":0.05,"size":10.0,"side":"BUY"}
{"ts":"2026-08-23T17:53:12.547Z","event_type":"price_change","market_id":"3795956","outcome_index":0,"market_type":"match","local_side":"home","local_uid":"2026-08-23_evan_zhu_arthur_reymond","bid":0.5,"ask":0.51,"mid":0.505,"spread":0.01,"price":0.95,"size":10.0,"side":"SELL"}
{"ts":"2026-08-23T17:53:12.611Z","event_type":"best_bid_ask","market_id":"3790334","outcome_index":0,"market_type":"set2","local_side":"home","local_uid":"2026-08-23_abdullah_shelbayh_dhakshineswar_suresh","bid":0.48,"ask":0.54,"mid":0.51,"spread":0.06,"bid_size":null,"ask_size":null}
{"ts":"2026-08-23T17:53:12.611Z","event_type":"best_bid_ask","market_id":"3790334","outcome_index":1,"market_type":"set2","local_side":"away","local_uid":"2026-08-23_abdullah_shelbayh_dhakshineswar_suresh","bid":0.46,"ask":0.52,"mid":0.49,"spread":0.06,"bid_size":null,"ask_size":null}
{"ts":"2026-08-23T17:53:12.611Z","event_type":"price_change","market_id":"3790334","outcome_index":1,"market_type":"set2","local_side":"away","local_uid":"2026-08-23_abdullah_shelbayh_dhakshineswar_suresh","bid":0.46,"ask":0.52,"mid":0.49,"spread":0.06,"price":0.47,"size":0.0,"side":"BUY"}
{"ts":"2026-08-23T17:53:12.611Z","event_type":"price_change","market_id":"3790334","outcome_index":0,"market_type":"set2","local_side":"home","local_uid":"2026-08-23_abdullah_shelbayh_dhakshineswar_suresh","bid":0.48,"ask":0.54,"mid":0.51,"spread":0.06,"price":0.53,"size":0.0,"side":"SELL"}
{"ts":"2026-08-23T17:53:12.715Z","event_type":"best_bid_ask","market_id":"3790334","outcome_index":0,"market_type":"set2","local_side":"home","local_uid":"2026-08-23_abdullah_shelbayh_dhakshineswar_suresh","bid":0.48,"ask":1.0,"mid":0.74,"spread":0.52,"bid_size":null,"ask_size":null}
{"ts":"2026-08-23T17:53:12.715Z","event_type":"best_bid_ask","market_id":"3790334","outcome_index":1,"market_type":"set2","local_side":"away","local_uid":"2026-08-23_abdullah_shelbayh_dhakshineswar_suresh","bid":0.0,"ask":0.52,"mid":0.26,"spread":0.52,"bid_size":null,"ask_size":null}
{"ts":"2026-08-23T17:53:12.715Z","event_type":"price_change","market_id":"3790334","outcome_index":1,"market_type":"set2","local_side":"away","local_uid":"2026-08-23_abdullah_shelbayh_dhakshineswar_suresh","bid":0.0,"ask":0.52,"mid":0.26,"spread":0.52,"price":0.46,"size":0.0,"side":"BUY"}
{"ts":"2026-08-23T17:53:12.715Z","event_type":"price_change","market_id":"3790334","outcome_index":0,"market_type":"set2","local_side":"home","local_uid":"2026-08-23_abdullah_shelbayh_dhakshineswar_suresh","bid":0.48,"ask":1.0,"mid":0.74,"spread":0.52,"price":0.54,"size":0.0,"side":"SELL"}
{"ts":"2026-08-23T17:53:12.717Z","event_type":"best_bid_ask","market_id":"3790334","outcome_index":0,"market_type":"set2","local_side":"home","local_uid":"2026-08-23_abdullah_shelbayh_dhakshineswar_suresh","bid":0.48,"ask":0.59,"mid":0.535,"spread":0.11,"bid_size":null,"ask_size":null}
{"ts":"2026-08-23T17:53:12.717Z","event_type":"best_bid_ask","market_id":"3790334","outcome_index":1,"market_type":"set2","local_side":"away","local_uid":"2026-08-23_abdullah_shelbayh_dhakshineswar_suresh","bid":0.41,"ask":0.52,"mid":0.465,"spread":0.11,"bid_size":null,"ask_size":null}
{"ts":"2026-08-23T17:53:12.717Z","event_type":"price_change","market_id":"3790334","outcome_index":1,"market_type":"set2","local_side":"away","local_uid":"2026-08-23_abdullah_shelbayh_dhakshineswar_suresh","bid":0.41,"ask":0.52,"mid":0.465,"spread":0.11,"price":0.41,"size":26.0,"side":"BUY"}
{"ts":"2026-08-23T17:53:12.717Z","event_type":"price_change","market_id":"3790334","outcome_index":0,"market_type":"set2","local_side":"home","local_uid":"2026-08-23_abdullah_shelbayh_dhakshineswar_suresh","bid":0.48,"ask":0.59,"mid":0.535,"spread":0.11,"price":0.59,"size":26.0,"side":"SELL"}
{"ts":"2026-08-23T17:53:12.719Z","event_type":"best_bid_ask","market_id":"3790334","outcome_index":0,"market_type":"set2","local_side":"home","local_uid":"2026-08-23_abdullah_shelbayh_dhakshineswar_suresh","bid":0.48,"ask":0.58,"mid":0.53,"spread":0.1,"bid_size":null,"ask_size":null}
{"ts":"2026-08-23T17:53:12.719Z","event_type":"best_bid_ask","market_id":"3790334","outcome_index":1,"market_type":"set2","local_side":"away","local_uid":"2026-08-23_abdullah_shelbayh_dhakshineswar_suresh","bid":0.42,"ask":0.52,"mid":0.47,"spread":0.1,"bid_size":null,"ask_size":null}
{"ts":"2026-08-23T17:53:12.719Z","event_type":"price_change","market_id":"3790334","outcome_index":1,"market_type":"set2","local_side":"away","local_uid":"2026-08-23_abdullah_shelbayh_dhakshineswar_suresh","bid":0.42,"ask":0.52,"mid":0.47,"spread":0.1,"price":0.42,"size":22.0,"side":"BUY"}
{"ts":"2026-08-23T17:53:12.719Z","event_type":"price_change","market_id":"3790334","outcome_index":0,"market_type":"set2","local_side":"home","local_uid":"2026-08-23_abdullah_shelbayh_dhakshineswar_suresh","bid":0.48,"ask":0.58,"mid":0.53,"spread":0.1,"price":0.58,"size":22.0,"side":"SELL"}
{"ts":"2026-08-23T17:53:12.744Z","event_type":"best_bid_ask","market_id":"3790334","outcome_index":0,"market_type":"set2","local_side":"home","local_uid":"2026-08-23_abdullah_shelbayh_dhakshineswar_suresh","bid":0.48,"ask":0.55,"mid":0.515,"spread":0.07,"bid_size":null,"ask_size":null}
{"ts":"2026-08-23T17:53:12.744Z","event_type":"best_bid_ask","market_id":"3790334","outcome_index":1,"market_type":"set2","local_side":"away","local_uid":"2026-08-23_abdullah_shelbayh_dhakshineswar_suresh","bid":0.45,"ask":0.52,"mid":0.485,"spread":0.07,"bid_size":null,"ask_size":null}
{"ts":"2026-08-23T17:53:12.744Z","event_type":"price_change","market_id":"3790334","outcome_index":1,"market_type":"set2","local_side":"away","local_uid":"2026-08-23_abdullah_shelbayh_dhakshineswar_suresh","bid":0.45,"ask":0.52,"mid":0.485,"spread":0.07,"price":0.45,"size":130.68,"side":"BUY"}
{"ts":"2026-08-23T17:53:12.744Z","event_type":"price_change","market_id":"3790334","outcome_index":0,"market_type":"set2","local_side":"home","local_uid":"2026-08-23_abdullah_shelbayh_dhakshineswar_suresh","bid":0.48,"ask":0.55,"mid":0.515,"spread":0.07,"price":0.55,"size":130.68,"side":"SELL"}
{"ts":"2026-08-23T17:53:12.926Z","event_type":"price_change","market_id":"3793656","outcome_index":1,"market_type":"set2","local_side":"away","local_uid":"2026-08-24_lilli_tagger_yuliia_starodubtseva","bid":0.35,"ask":0.41,"mid":0.38,"spread":0.06,"price":0.31,"size":742.04,"side":"BUY"}
{"ts":"2026-08-23T17:53:12.926Z","event_type":"price_change","market_id":"3793656","outcome_index":0,"market_type":"set2","local_side":"home","local_uid":"2026-08-24_lilli_tagger_yuliia_starodubtseva","bid":0.59,"ask":0.65,"mid":0.62,"spread":0.06,"price":0.69,"size":742.04,"side":"SELL"}
{"ts":"2026-08-23T17:53:13.007Z","event_type":"price_change","market_id":"3802004","outcome_index":1,"market_type":"match","local_side":"away","local_uid":"2026-08-24_luis_guto_miguel_tyler_zink","bid":0.62,"ask":0.63,"mid":0.625,"spread":0.01,"price":0.7,"size":0.0,"side":"SELL"}
{"ts":"2026-08-23T17:53:13.007Z","event_type":"price_change","market_id":"3802004","outcome_index":0,"market_type":"match","local_side":"home","local_uid":"2026-08-24_luis_guto_miguel_tyler_zink","bid":0.37,"ask":0.38,"mid":0.375,"spread":0.01,"price":0.3,"size":0.0,"side":"BUY"}
{"ts":"2026-08-23T17:53:13.063Z","event_type":"best_bid_ask","market_id":"3795958","outcome_index":0,"market_type":"match","local_side":"home","local_uid":"2026-08-23_bruno_kuzuhara_kody_pearson","bid":0.954,"ask":0.96,"mid":0.957,"spread":0.006,"bid_size":null,"ask_size":null}
{"ts":"2026-08-23T17:53:13.063Z","event_type":"best_bid_ask","market_id":"3795958","outcome_index":1,"market_type":"match","local_side":"away","local_uid":"2026-08-23_bruno_kuzuhara_kody_pearson","bid":0.04,"ask":0.046,"mid":0.043,"spread":0.006,"bid_size":null,"ask_size":null}
{"ts":"2026-08-23T17:53:13.063Z","event_type":"price_change","market_id":"3795958","outcome_index":1,"market_type":"match","local_side":"away","local_uid":"2026-08-23_bruno_kuzuhara_kody_pearson","bid":0.04,"ask":0.046,"mid":0.043,"spread":0.006,"price":0.04,"size":320.5,"side":"BUY"}
{"ts":"2026-08-23T17:53:13.063Z","event_type":"price_change","market_id":"3795958","outcome_index":0,"market_type":"match","local_side":"home","local_uid":"2026-08-23_bruno_kuzuhara_kody_pearson","bid":0.954,"ask":0.96,"mid":0.957,"spread":0.006,"price":0.96,"size":320.5,"side":"SELL"}
{"ts":"2026-08-23T17:53:13.063Z","event_type":"book","market_id":"3795958","outcome_index":0,"market_type":"match","local_side":"home","local_uid":"2026-08-23_bruno_kuzuhara_kody_pearson","bid":0.954,"ask":0.96,"mid":0.957,"spread":0.006,"bid_size":500.0,"ask_size":320.5}
{"ts":"2026-08-23T17:53:13.064Z","event_type":"book","market_id":"3795958","outcome_index":1,"market_type":"match","local_side":"away","local_uid":"2026-08-23_bruno_kuzuhara_kody_pearson","bid":0.04,"ask":0.046,"mid":0.043,"spread":0.006,"bid_size":320.5,"ask_size":500.0}
{"ts":"2026-08-23T17:53:13.139Z","event_type":"last_trade_price","market_id":"3795958","outcome_index":1,"market_type":"match","local_side":"away","local_uid":"2026-08-23_bruno_kuzuhara_kody_pearson","last_trade":0.04,"trade_size":4.5,"trade_side":"BUY","trade_notional":0.18}
{"ts":"2026-08-23T17:53:13.262Z","event_type":"price_change","market_id":"3795950","outcome_index":1,"market_type":"match","local_side":"away","local_uid":"2026-08-24_sebastian_baez_hubert_hurkacz","bid":0.68,"ask":0.69,"mid":0.685,"spread":0.01,"price":0.34,"size":336.16,"side":"BUY"}
{"ts":"2026-08-23T17:53:13.262Z","event_type":"price_change","market_id":"3795950","outcome_index":0,"market_type":"match","local_side":"home","local_uid":"2026-08-24_sebastian_baez_hubert_hurkacz","bid":0.31,"ask":0.32,"mid":0.315,"spread":0.01,"price":0.66,"size":336.16,"side":"SELL"}
{"ts":"2026-08-23T17:53:13.265Z","event_type":"best_bid_ask","market_id":"3790323","outcome_index":0,"market_type":"set2","local_side":"home","local_uid":"2026-08-23_felix_balshaw_sebastian_gorzny","bid":0.54,"ask":0.67,"mid":0.605,"spread":0.13,"bid_size":null,"ask_size":null}
{"ts":"2026-08-23T17:53:13.265Z","event_type":"best_bid_ask","market_id":"3790323","outcome_index":1,"market_type":"set2","local_side":"away","local_uid":"2026-08-23_felix_balshaw_sebastian_gorzny","bid":0.33,"ask":0.46,"mid":0.395,"spread":0.13,"bid_size":null,"ask_size":null}
{"ts":"2026-08-23T17:53:13.265Z","event_type":"price_change","market_id":"3790323","outcome_index":1,"market_type":"set2","local_side":"away","local_uid":"2026-08-23_felix_balshaw_sebastian_gorzny","bid":0.33,"ask":0.46,"mid":0.395,"spread":0.13,"price":0.35,"size":0.0,"side":"BUY"}
{"ts":"2026-08-23T17:53:13.265Z","event_type":"price_change","market_id":"3790323","outcome_index":0,"market_type":"set2","local_side":"home","local_uid":"2026-08-23_felix_balshaw_sebastian_gorzny","bid":0.54,"ask":0.67,"mid":0.605,"spread":0.13,"price":0.65,"size":0.0,"side":"SELL"}
{"ts":"2026-08-23T17:53:13.308Z","event_type":"best_bid_ask","market_id":"3790323","outcome_index":0,"market_type":"set2","local_side":"home","local_uid":"2026-08-23_felix_balshaw_sebastian_gorzny","bid":0.54,"ask":0.65,"mid":0.595,"spread":0.11,"bid_size":null,"ask_size":null}
{"ts":"2026-08-23T17:53:13.308Z","event_type":"best_bid_ask","market_id":"3790323","outcome_index":1,"market_type":"set2","local_side":"away","local_uid":"2026-08-23_felix_balshaw_sebastian_gorzny","bid":0.35,"ask":0.46,"mid":0.405,"spread":0.11,"bid_size":null,"ask_size":null}
{"ts":"2026-08-23T17:53:13.308Z","event_type":"price_change","market_id":"3790323","outcome_index":1,"market_type":"set2","local_side":"away","local_uid":"2026-08-23_felix_balshaw_sebastian_gorzny","bid":0.35,"ask":0.46,"mid":0.405,"spread":0.11,"price":0.35,"size":150.0,"side":"BUY"}
{"ts":"2026-08-23T17:53:13.308Z","event_type":"price_change","market_id":"3790323","outcome_index":0,"market_type":"set2","local_side":"home","local_uid":"2026-08-23_felix_balshaw_sebastian_gorzny","bid":0.54,"ask":0.65,"mid":0.595,"spread":0.11,"price":0.65,"size":150.0,"side":"SELL"}
{"ts":"2026-08-23T17:53:13.309Z","event_type":"best_bid_ask","market_id":"3790323","outcome_index":0,"market_type":"set2","local_side":"home","local_uid":"2026-08-23_felix_balshaw_sebastian_gorzny","bid":0.55,"ask":0.65,"mid":0.6,"spread":0.1,"bid_size":null,"ask_size":null}
{"ts":"2026-08-23T17:53:13.309Z","event_type":"best_bid_ask","market_id":"3790323","outcome_index":1,"market_type":"set2","local_side":"away","local_uid":"2026-08-23_felix_balshaw_sebastian_gorzny","bid":0.35,"ask":0.45,"mid":0.4,"spread":0.1,"bid_size":null,"ask_size":null}
{"ts":"2026-08-23T17:53:13.309Z","event_type":"price_change","market_id":"3790323","outcome_index":0,"market_type":"set2","local_side":"home","local_uid":"2026-08-23_felix_balshaw_sebastian_gorzny","bid":0.55,"ask":0.65,"mid":0.6,"spread":0.1,"price":0.55,"size":150.0,"side":"BUY"}
{"ts":"2026-08-23T17:53:13.309Z","event_type":"price_change","market_id":"3790323","outcome_index":1,"market_type":"set2","local_side":"away","local_uid":"2026-08-23_felix_balshaw_sebastian_gorzny","bid":0.35,"ask":0.45,"mid":0.4,"spread":0.1,"price":0.45,"size":150.0,"side":"SELL"}
{"ts":"2026-08-23T17:53:13.517Z","event_type":"best_bid_ask","market_id":"3790394","outcome_index":0,"market_type":"set1","local_side":"home","local_uid":"2026-08-23_hugo_grenier_mees_rottgering","bid":0.17,"ask":0.41,"mid":0.29,"spread":0.24,"bid_size":null,"ask_size":null}
{"ts":"2026-08-23T17:53:13.517Z","event_type":"best_bid_ask","market_id":"3790394","outcome_index":1,"market_type":"set1","local_side":"away","local_uid":"2026-08-23_hugo_grenier_mees_rottgering","bid":0.59,"ask":0.83,"mid":0.71,"spread":0.24,"bid_size":null,"ask_size":null}
{"ts":"2026-08-23T17:53:13.517Z","event_type":"price_change","market_id":"3790394","outcome_index":0,"market_type":"set1","local_side":"home","local_uid":"2026-08-23_hugo_grenier_mees_rottgering","bid":0.17,"ask":0.41,"mid":0.29,"spread":0.24,"price":0.17,"size":103.52,"side":"BUY"}
{"ts":"2026-08-23T17:53:13.517Z","event_type":"price_change","market_id":"3790394","outcome_index":1,"market_type":"set1","local_side":"away","local_uid":"2026-08-23_hugo_grenier_mees_rottgering","bid":0.59,"ask":0.83,"mid":0.71,"spread":0.24,"price":0.83,"size":103.52,"side":"SELL"}
{"ts":"2026-08-23T17:53:13.555Z","event_type":"best_bid_ask","market_id":"3789927","outcome_index":0,"market_type":"match","local_side":"home","local_uid":"2026-08-23_hugo_grenier_mees_rottgering","bid":0.25,"ask":0.27,"mid":0.26,"spread":0.02,"bid_size":null,"ask_size":null}
{"ts":"2026-08-23T17:53:13.555Z","event_type":"best_bid_ask","market_id":"3789927","outcome_index":1,"market_type":"match","local_side":"away","local_uid":"2026-08-23_hugo_grenier_mees_rottgering","bid":0.73,"ask":0.75,"mid":0.74,"spread":0.02,"bid_size":null,"ask_size":null}
{"ts":"2026-08-23T17:53:13.556Z","event_type":"price_change","market_id":"3789927","outcome_index":0,"market_type":"match","local_side":"home","local_uid":"2026-08-23_hugo_grenier_mees_rottgering","bid":0.25,"ask":0.27,"mid":0.26,"spread":0.02,"price":0.26,"size":0.0,"side":"BUY"}
{"ts":"2026-08-23T17:53:13.556Z","event_type":"price_change","market_id":"3789927","outcome_index":1,"market_type":"match","local_side":"away","local_uid":"2026-08-23_hugo_grenier_mees_rottgering","bid":0.73,"ask":0.75,"mid":0.74,"spread":0.02,"price":0.74,"size":0.0,"side":"SELL"}
{"ts":"2026-08-23T17:53:13.576Z","event_type":"best_bid_ask","market_id":"3790394","outcome_index":0,"market_type":"set1","local_side":"home","local_uid":"2026-08-23_hugo_grenier_mees_rottgering","bid":0.16,"ask":0.41,"mid":0.285,"spread":0.25,"bid_size":null,"ask_size":null}
{"ts":"2026-08-23T17:53:13.576Z","event_type":"best_bid_ask","market_id":"3790394","outcome_index":1,"market_type":"set1","local_side":"away","local_uid":"2026-08-23_hugo_grenier_mees_rottgering","bid":0.59,"ask":0.84,"mid":0.715,"spread":0.25,"bid_size":null,"ask_size":null}
{"ts":"2026-08-23T17:53:13.576Z","event_type":"price_change","market_id":"3790394","outcome_index":0,"market_type":"set1","local_side":"home","local_uid":"2026-08-23_hugo_grenier_mees_rottgering","bid":0.16,"ask":0.41,"mid":0.285,"spread":0.25,"price":0.17,"size":0.0,"side":"BUY"}
{"ts":"2026-08-23T17:53:13.576Z","event_type":"price_change","market_id":"3790394","outcome_index":1,"market_type":"set1","local_side":"away","local_uid":"2026-08-23_hugo_grenier_mees_rottgering","bid":0.59,"ask":0.84,"mid":0.715,"spread":0.25,"price":0.83,"size":0.0,"side":"SELL"}
{"ts":"2026-08-23T17:53:13.612Z","event_type":"best_bid_ask","market_id":"3790394","outcome_index":0,"market_type":"set1","local_side":"home","local_uid":"2026-08-23_hugo_grenier_mees_rottgering","bid":0.17,"ask":0.41,"mid":0.29,"spread":0.24,"bid_size":null,"ask_size":null}
{"ts":"2026-08-23T17:53:13.613Z","event_type":"best_bid_ask","market_id":"3790394","outcome_index":1,"market_type":"set1","local_side":"away","local_uid":"2026-08-23_hugo_grenier_mees_rottgering","bid":0.59,"ask":0.83,"mid":0.71,"spread":0.24,"bid_size":null,"ask_size":null}
{"ts":"2026-08-23T17:53:13.613Z","event_type":"price_change","market_id":"3790394","outcome_index":0,"market_type":"set1","local_side":"home","local_uid":"2026-08-23_hugo_grenier_mees_rottgering","bid":0.17,"ask":0.41,"mid":0.29,"spread":0.24,"price":0.17,"size":101.41,"side":"BUY"}
{"ts":"2026-08-23T17:53:13.613Z","event_type":"price_change","market_id":"3790394","outcome_index":1,"market_type":"set1","local_side":"away","local_uid":"2026-08-23_hugo_grenier_mees_rottgering","bid":0.59,"ask":0.83,"mid":0.71,"spread":0.24,"price":0.83,"size":101.41,"side":"SELL"}
{"ts":"2026-08-23T17:53:13.638Z","event_type":"best_bid_ask","market_id":"3790394","outcome_index":0,"market_type":"set1","local_side":"home","local_uid":"2026-08-23_hugo_grenier_mees_rottgering","bid":0.17,"ask":0.4,"mid":0.285,"spread":0.23,"bid_size":null,"ask_size":null}
{"ts":"2026-08-23T17:53:13.638Z","event_type":"best_bid_ask","market_id":"3790394","outcome_index":1,"market_type":"set1","local_side":"away","local_uid":"2026-08-23_hugo_grenier_mees_rottgering","bid":0.6,"ask":0.83,"mid":0.715,"spread":0.23,"bid_size":null,"ask_size":null}
{"ts":"2026-08-23T17:53:13.638Z","event_type":"price_change","market_id":"3790394","outcome_index":1,"market_type":"set1","local_side":"away","local_uid":"2026-08-23_hugo_grenier_mees_rottgering","bid":0.6,"ask":0.83,"mid":0.715,"spread":0.23,"price":0.6,"size":42.8,"side":"BUY"}
{"ts":"2026-08-23T17:53:13.638Z","event_type":"price_change","market_id":"3790394","outcome_index":0,"market_type":"set1","local_side":"home","local_uid":"2026-08-23_hugo_grenier_mees_rottgering","bid":0.17,"ask":0.4,"mid":0.285,"spread":0.23,"price":0.4,"size":42.8,"side":"SELL"}
{"ts":"2026-08-23T17:53:13.745Z","event_type":"best_bid_ask","market_id":"3790334","outcome_index":0,"market_type":"set2","local_side":"home","local_uid":"2026-08-23_abdullah_shelbayh_dhakshineswar_suresh","bid":0.48,"ask":0.58,"mid":0.53,"spread":0.1,"bid_size":null,"ask_size":null}
{"ts":"2026-08-23T17:53:13.746Z","event_type":"best_bid_ask","market_id":"3790334","outcome_index":1,"market_type":"set2","local_side":"away","local_uid":"2026-08-23_abdullah_shelbayh_dhakshineswar_suresh","bid":0.42,"ask":0.52,"mid":0.47,"spread":0.1,"bid_size":null,"ask_size":null}
{"ts":"2026-08-23T17:53:13.746Z","event_type":"price_change","market_id":"3790334","outcome_index":1,"market_type":"set2","local_side":"away","local_uid":"2026-08-23_abdullah_shelbayh_dhakshineswar_suresh","bid":0.42,"ask":0.52,"mid":0.47,"spread":0.1,"price":0.45,"size":0.0,"side":"BUY"}
{"ts":"2026-08-23T17:53:13.746Z","event_type":"price_change","market_id":"3790334","outcome_index":0,"market_type":"set2","local_side":"home","local_uid":"2026-08-23_abdullah_shelbayh_dhakshineswar_suresh","bid":0.48,"ask":0.58,"mid":0.53,"spread":0.1,"price":0.55,"size":0.0,"side":"SELL"}
{"ts":"2026-08-23T17:53:13.845Z","event_type":"price_change","market_id":"3780826","outcome_index":1,"market_type":"match","local_side":"away","local_uid":"2026-08-23_giovanni_mpetshi_perricard_jenson_brooksby","bid":0.62,"ask":0.63,"mid":0.625,"spread":0.01,"price":0.61,"size":6977.15,"side":"BUY"}
{"ts":"2026-08-23T17:53:13.845Z","event_type":"price_change","market_id":"3780826","outcome_index":0,"market_type":"match","local_side":"home","local_uid":"2026-08-23_giovanni_mpetshi_perricard_jenson_brooksby","bid":0.37,"ask":0.38,"mid":0.375,"spread":0.01,"price":0.39,"size":6977.15,"side":"SELL"}
{"ts":"2026-08-23T17:53:14.578Z","event_type":"best_bid_ask","market_id":"3790334","outcome_index":0,"market_type":"set2","local_side":"home","local_uid":"2026-08-23_abdullah_shelbayh_dhakshineswar_suresh","bid":0.48,"ask":0.59,"mid":0.535,"spread":0.11,"bid_size":null,"ask_size":null}
{"ts":"2026-08-23T17:53:14.579Z","event_type":"best_bid_ask","market_id":"3790334","outcome_index":1,"market_type":"set2","local_side":"away","local_uid":"2026-08-23_abdullah_shelbayh_dhakshineswar_suresh","bid":0.41,"ask":0.52,"mid":0.465,"spread":0.11,"bid_size":null,"ask_size":null}
{"ts":"2026-08-23T17:53:14.579Z","event_type":"price_change","market_id":"3790334","outcome_index":1,"market_type":"set2","local_side":"away","local_uid":"2026-08-23_abdullah_shelbayh_dhakshineswar_suresh","bid":0.41,"ask":0.52,"mid":0.465,"spread":0.11,"price":0.42,"size":0.0,"side":"BUY"}
{"ts":"2026-08-23T17:53:14.579Z","event_type":"price_change","market_id":"3790334","outcome_index":0,"market_type":"set2","local_side":"home","local_uid":"2026-08-23_abdullah_shelbayh_dhakshineswar_suresh","bid":0.48,"ask":0.59,"mid":0.535,"spread":0.11,"price":0.58,"size":0.0,"side":"SELL"}
{"ts":"2026-08-23T17:53:14.579Z","event_type":"best_bid_ask","market_id":"3790334","outcome_index":0,"market_type":"set2","local_side":"home","local_uid":"2026-08-23_abdullah_shelbayh_dhakshineswar_suresh","bid":0.48,"ask":0.6,"mid":0.54,"spread":0.12,"bid_size":null,"ask_size":null}
{"ts":"2026-08-23T17:53:14.579Z","event_type":"best_bid_ask","market_id":"3790334","outcome_index":1,"market_type":"set2","local_side":"away","local_uid":"2026-08-23_abdullah_shelbayh_dhakshineswar_suresh","bid":0.4,"ask":0.52,"mid":0.46,"spread":0.12,"bid_size":null,"ask_size":null}
{"ts":"2026-08-23T17:53:14.579Z","event_type":"price_change","market_id":"3790334","outcome_index":1,"market_type":"set2","local_side":"away","local_uid":"2026-08-23_abdullah_shelbayh_dhakshineswar_suresh","bid":0.4,"ask":0.52,"mid":0.46,"spread":0.12,"price":0.41,"size":0.0,"side":"BUY"}
{"ts":"2026-08-23T17:53:14.579Z","event_type":"price_change","market_id":"3790334","outcome_index":0,"market_type":"set2","local_side":"home","local_uid":"2026-08-23_abdullah_shelbayh_dhakshineswar_suresh","bid":0.48,"ask":0.6,"mid":0.54,"spread":0.12,"price":0.59,"size":0.0,"side":"SELL"}
{"ts":"2026-08-23T17:53:14.584Z","event_type":"best_bid_ask","market_id":"3790334","outcome_index":0,"market_type":"set2","local_side":"home","local_uid":"2026-08-23_abdullah_shelbayh_dhakshineswar_suresh","bid":0.48,"ask":0.58,"mid":0.53,"spread":0.1,"bid_size":null,"ask_size":null}
{"ts":"2026-08-23T17:53:14.584Z","event_type":"best_bid_ask","market_id":"3790334","outcome_index":1,"market_type":"set2","local_side":"away","local_uid":"2026-08-23_abdullah_shelbayh_dhakshineswar_suresh","bid":0.42,"ask":0.52,"mid":0.47,"spread":0.1,"bid_size":null,"ask_size":null}
{"ts":"2026-08-23T17:53:14.584Z","event_type":"price_change","market_id":"3790334","outcome_index":1,"market_type":"set2","local_side":"away","local_uid":"2026-08-23_abdullah_shelbayh_dhakshineswar_suresh","bid":0.42,"ask":0.52,"mid":0.47,"spread":0.1,"price":0.42,"size":211.0,"side":"BUY"}
{"ts":"2026-08-23T17:53:14.584Z","event_type":"price_change","market_id":"3790334","outcome_index":0,"market_type":"set2","local_side":"home","local_uid":"2026-08-23_abdullah_shelbayh_dhakshineswar_suresh","bid":0.48,"ask":0.58,"mid":0.53,"spread":0.1,"price":0.58,"size":211.0,"side":"SELL"}
{"ts":"2026-08-23T17:53:14.584Z","event_type":"best_bid_ask","market_id":"3790334","outcome_index":0,"market_type":"set2","local_side":"home","local_uid":"2026-08-23_abdullah_shelbayh_dhakshineswar_suresh","bid":0.48,"ask":0.57,"mid":0.525,"spread":0.09,"bid_size":null,"ask_size":null}
{"ts":"2026-08-23T17:53:14.584Z","event_type":"best_bid_ask","market_id":"3790334","outcome_index":1,"market_type":"set2","local_side":"away","local_uid":"2026-08-23_abdullah_shelbayh_dhakshineswar_suresh","bid":0.43,"ask":0.52,"mid":0.475,"spread":0.09,"bid_size":null,"ask_size":null}
{"ts":"2026-08-23T17:53:14.584Z","event_type":"price_change","market_id":"3790334","outcome_index":1,"market_type":"set2","local_side":"away","local_uid":"2026-08-23_abdullah_shelbayh_dhakshineswar_suresh","bid":0.43,"ask":0.52,"mid":0.475,"spread":0.09,"price":0.43,"size":88.0,"side":"BUY"}
{"ts":"2026-08-23T17:53:14.584Z","event_type":"price_change","market_id":"3790334","outcome_index":0,"market_type":"set2","local_side":"home","local_uid":"2026-08-23_abdullah_shelbayh_dhakshineswar_suresh","bid":0.48,"ask":0.57,"mid":0.525,"spread":0.09,"price":0.57,"size":88.0,"side":"SELL"}
{"ts":"2026-08-23T17:53:14.630Z","event_type":"best_bid_ask","market_id":"3790334","outcome_index":0,"market_type":"set2","local_side":"home","local_uid":"2026-08-23_abdullah_shelbayh_dhakshineswar_suresh","bid":0.48,"ask":0.58,"mid":0.53,"spread":0.1,"bid_size":null,"ask_size":null}
{"ts":"2026-08-23T17:53:14.630Z","event_type":"best_bid_ask","market_id":"3790334","outcome_index":1,"market_type":"set2","local_side":"away","local_uid":"2026-08-23_abdullah_shelbayh_dhakshineswar_suresh","bid":0.42,"ask":0.52,"mid":0.47,"spread":0.1,"bid_size":null,"ask_size":null}
{"ts":"2026-08-23T17:53:14.630Z","event_type":"price_change","market_id":"3790334","outcome_index":1,"market_type":"set2","local_side":"away","local_uid":"2026-08-23_abdullah_shelbayh_dhakshineswar_suresh","bid":0.42,"ask":0.52,"mid":0.47,"spread":0.1,"price":0.43,"size":0.0,"side":"BUY"}
{"ts":"2026-08-23T17:53:14.630Z","event_type":"price_change","market_id":"3790334","outcome_index":0,"market_type":"set2","local_side":"home","local_uid":"2026-08-23_abdullah_shelbayh_dhakshineswar_suresh","bid":0.48,"ask":0.58,"mid":0.53,"spread":0.1,"price":0.57,"size":0.0,"side":"SELL"}
{"ts":"2026-08-23T17:53:14.633Z","event_type":"best_bid_ask","market_id":"3790334","outcome_index":0,"market_type":"set2","local_side":"home","local_uid":"2026-08-23_abdullah_shelbayh_dhakshineswar_suresh","bid":0.48,"ask":0.57,"mid":0.525,"spread":0.09,"bid_size":null,"ask_size":null}
{"ts":"2026-08-23T17:53:14.633Z","event_type":"best_bid_ask","market_id":"3790334","outcome_index":1,"market_type":"set2","local_side":"away","local_uid":"2026-08-23_abdullah_shelbayh_dhakshineswar_suresh","bid":0.43,"ask":0.52,"mid":0.475,"spread":0.09,"bid_size":null,"ask_size":null}
{"ts":"2026-08-23T17:53:14.633Z","event_type":"price_change","market_id":"3790334","outcome_index":1,"market_type":"set2","local_side":"away","local_uid":"2026-08-23_abdullah_shelbayh_dhakshineswar_suresh","bid":0.43,"ask":0.52,"mid":0.475,"spread":0.09,"price":0.43,"size":44.0,"side":"BUY"}
{"ts":"2026-08-23T17:53:14.633Z","event_type":"price_change","market_id":"3790334","outcome_index":0,"market_type":"set2","local_side":"home","local_uid":"2026-08-23_abdullah_shelbayh_dhakshineswar_suresh","bid":0.48,"ask":0.57,"mid":0.525,"spread":0.09,"price":0.57,"size":44.0,"side":"SELL"}
{"ts":"2026-08-23T17:53:14.682Z","event_type":"best_bid_ask","market_id":"3790334","outcome_index":0,"market_type":"set2","local_side":"home","local_uid":"2026-08-23_abdullah_shelbayh_dhakshineswar_suresh","bid":0.48,"ask":1.0,"mid":0.74,"spread":0.52,"bid_size":null,"ask_size":null}
{"ts":"2026-08-23T17:53:14.682Z","event_type":"best_bid_ask","market_id":"3790334","outcome_index":1,"market_type":"set2","local_side":"away","local_uid":"2026-08-23_abdullah_shelbayh_dhakshineswar_suresh","bid":0.0,"ask":0.52,"mid":0.26,"spread":0.52,"bid_size":null,"ask_size":null}
{"ts":"2026-08-23T17:53:14.682Z","event_type":"price_change","market_id":"3790334","outcome_index":1,"market_type":"set2","local_side":"away","local_uid":"2026-08-23_abdullah_shelbayh_dhakshineswar_suresh","bid":0.0,"ask":0.52,"mid":0.26,"spread":0.52,"price":0.43,"size":0.0,"side":"BUY"}
{"ts":"2026-08-23T17:53:14.682Z","event_type":"price_change","market_id":"3790334","outcome_index":0,"market_type":"set2","local_side":"home","local_uid":"2026-08-23_abdullah_shelbayh_dhakshineswar_suresh","bid":0.48,"ask":1.0,"mid":0.74,"spread":0.52,"price":0.57,"size":0.0,"side":"SELL"}
{"ts":"2026-08-23T17:53:14.683Z","event_type":"best_bid_ask","market_id":"3790334","outcome_index":0,"market_type":"set2","local_side":"home","local_uid":"2026-08-23_abdullah_shelbayh_dhakshineswar_suresh","bid":0.48,"ask":0.59,"mid":0.535,"spread":0.11,"bid_size":null,"ask_size":null}
{"ts":"2026-08-23T17:53:14.683Z","event_type":"best_bid_ask","market_id":"3790334","outcome_index":1,"market_type":"set2","local_side":"away","local_uid":"2026-08-23_abdullah_shelbayh_dhakshineswar_suresh","bid":0.41,"ask":0.52,"mid":0.465,"spread":0.11,"bid_size":null,"ask_size":null}
{"ts":"2026-08-23T17:53:14.683Z","event_type":"price_change","market_id":"3790334","outcome_index":1,"market_type":"set2","local_side":"away","local_uid":"2026-08-23_abdullah_shelbayh_dhakshineswar_suresh","bid":0.41,"ask":0.52,"mid":0.465,"spread":0.11,"price":0.41,"size":88.0,"side":"BUY"}
{"ts":"2026-08-23T17:53:14.683Z","event_type":"price_change","market_id":"3790334","outcome_index":0,"market_type":"set2","local_side":"home","local_uid":"2026-08-23_abdullah_shelbayh_dhakshineswar_suresh","bid":0.48,"ask":0.59,"mid":0.535,"spread":0.11,"price":0.59,"size":88.0,"side":"SELL"}
{"ts":"2026-08-23T17:53:14.720Z","event_type":"best_bid_ask","market_id":"3790334","outcome_index":0,"market_type":"set2","local_side":"home","local_uid":"2026-08-23_abdullah_shelbayh_dhakshineswar_suresh","bid":0.48,"ask":0.58,"mid":0.53,"spread":0.1,"bid_size":null,"ask_size":null}
{"ts":"2026-08-23T17:53:14.720Z","event_type":"best_bid_ask","market_id":"3790334","outcome_index":1,"market_type":"set2","local_side":"away","local_uid":"2026-08-23_abdullah_shelbayh_dhakshineswar_suresh","bid":0.42,"ask":0.52,"mid":0.47,"spread":0.1,"bid_size":null,"ask_size":null}
{"ts":"2026-08-23T17:53:14.720Z","event_type":"price_change","market_id":"3790334","outcome_index":1,"market_type":"set2","local_side":"away","local_uid":"2026-08-23_abdullah_shelbayh_dhakshineswar_suresh","bid":0.42,"ask":0.52,"mid":0.47,"spread":0.1,"price":0.42,"size":44.0,"side":"BUY"}
{"ts":"2026-08-23T17:53:14.720Z","event_type":"price_change","market_id":"3790334","outcome_index":0,"market_type":"set2","local_side":"home","local_uid":"2026-08-23_abdullah_shelbayh_dhakshineswar_suresh","bid":0.48,"ask":0.58,"mid":0.53,"spread":0.1,"price":0.58,"size":44.0,"side":"SELL"}
{"ts":"2026-08-23T17:53:14.902Z","event_type":"best_bid_ask","market_id":"3790334","outcome_index":0,"market_type":"set2","local_side":"home","local_uid":"2026-08-23_abdullah_shelbayh_dhakshineswar_suresh","bid":0.48,"ask":0.56,"mid":0.52,"spread":0.08,"bid_size":null,"ask_size":null}
{"ts":"2026-08-23T17:53:14.902Z","event_type":"best_bid_ask","market_id":"3790334","outcome_index":1,"market_type":"set2","local_side":"away","local_uid":"2026-08-23_abdullah_shelbayh_dhakshineswar_suresh","bid":0.44,"ask":0.52,"mid":0.48,"spread":0.08,"bid_size":null,"ask_size":null}
{"ts":"2026-08-23T17:53:14.902Z","event_type":"price_change","market_id":"3790334","outcome_index":1,"market_type":"set2","local_side":"away","local_uid":"2026-08-23_abdullah_shelbayh_dhakshineswar_suresh","bid":0.44,"ask":0.52,"mid":0.48,"spread":0.08,"price":0.44,"size":150.0,"side":"BUY"}
{"ts":"2026-08-23T17:53:14.902Z","event_type":"price_change","market_id":"3790334","outcome_index":0,"market_type":"set2","local_side":"home","local_uid":"2026-08-23_abdullah_shelbayh_dhakshineswar_suresh","bid":0.48,"ask":0.56,"mid":0.52,"spread":0.08,"price":0.56,"size":150.0,"side":"SELL"}
{"ts":"2026-08-23T17:53:15.402Z","event_type":"best_bid_ask","market_id":"3790334","outcome_index":0,"market_type":"set2","local_side":"home","local_uid":"2026-08-23_abdullah_shelbayh_dhakshineswar_suresh","bid":0.48,"ask":0.55,"mid":0.515,"spread":0.07,"bid_size":null,"ask_size":null}
{"ts":"2026-08-23T17:53:15.403Z","event_type":"best_bid_ask","market_id":"3790334","outcome_index":1,"market_type":"set2","local_side":"away","local_uid":"2026-08-23_abdullah_shelbayh_dhakshineswar_suresh","bid":0.45,"ask":0.52,"mid":0.485,"spread":0.07,"bid_size":null,"ask_size":null}
{"ts":"2026-08-23T17:53:15.403Z","event_type":"price_change","market_id":"3790334","outcome_index":1,"market_type":"set2","local_side":"away","local_uid":"2026-08-23_abdullah_shelbayh_dhakshineswar_suresh","bid":0.45,"ask":0.52,"mid":0.485,"spread":0.07,"price":0.45,"size":25.09,"side":"BUY"}
{"ts":"2026-08-23T17:53:15.403Z","event_type":"price_change","market_id":"3790334","outcome_index":0,"market_type":"set2","local_side":"home","local_uid":"2026-08-23_abdullah_shelbayh_dhakshineswar_suresh","bid":0.48,"ask":0.55,"mid":0.515,"spread":0.07,"price":0.55,"size":25.09,"side":"SELL"}
{"ts":"2026-08-23T17:53:15.474Z","event_type":"best_bid_ask","market_id":"3790334","outcome_index":0,"market_type":"set2","local_side":"home","local_uid":"2026-08-23_abdullah_shelbayh_dhakshineswar_suresh","bid":0.48,"ask":0.56,"mid":0.52,"spread":0.08,"bid_size":null,"ask_size":null}
{"ts":"2026-08-23T17:53:15.474Z","event_type":"best_bid_ask","market_id":"3790334","outcome_index":1,"market_type":"set2","local_side":"away","local_uid":"2026-08-23_abdullah_shelbayh_dhakshineswar_suresh","bid":0.44,"ask":0.52,"mid":0.48,"spread":0.08,"bid_size":null,"ask_size":null}
{"ts":"2026-08-23T17:53:15.474Z","event_type":"price_change","market_id":"3790334","outcome_index":1,"market_type":"set2","local_side":"away","local_uid":"2026-08-23_abdullah_shelbayh_dhakshineswar_suresh","bid":0.44,"ask":0.52,"mid":0.48,"spread":0.08,"price":0.45,"size":0.0,"side":"BUY"}
{"ts":"2026-08-23T17:53:15.474Z","event_type":"price_change","market_id":"3790334","outcome_index":0,"market_type":"set2","local_side":"home","local_uid":"2026-08-23_abdullah_shelbayh_dhakshineswar_suresh","bid":0.48,"ask":0.56,"mid":0.52,"spread":0.08,"price":0.55,"size":0.0,"side":"SELL"}
{"ts":"2026-08-23T17:53:15.510Z","event_type":"best_bid_ask","market_id":"3790334","outcome_index":0,"market_type":"set2","local_side":"home","local_uid":"2026-08-23_abdullah_shelbayh_dhakshineswar_suresh","bid":0.48,"ask":0.55,"mid":0.515,"spread":0.07,"bid_size":null,"ask_size":null}
{"ts":"2026-08-23T17:53:15.510Z","event_type":"best_bid_ask","market_id":"3790334","outcome_index":1,"market_type":"set2","local_side":"away","local_uid":"2026-08-23_abdullah_shelbayh_dhakshineswar_suresh","bid":0.45,"ask":0.52,"mid":0.485,"spread":0.07,"bid_size":null,"ask_size":null}
{"ts":"2026-08-23T17:53:15.510Z","event_type":"price_change","market_id":"3790334","outcome_index":1,"market_type":"set2","local_side":"away","local_uid":"2026-08-23_abdullah_shelbayh_dhakshineswar_suresh","bid":0.45,"ask":0.52,"mid":0.485,"spread":0.07,"price":0.45,"size":150.0,"side":"BUY"}
{"ts":"2026-08-23T17:53:15.510Z","event_type":"price_change","market_id":"3790334","outcome_index":0,"market_type":"set2","local_side":"home","local_uid":"2026-08-23_abdullah_shelbayh_dhakshineswar_suresh","bid":0.48,"ask":0.55,"mid":0.515,"spread":0.07,"price":0.55,"size":150.0,"side":"SELL"}
{"ts":"2026-08-23T17:53:16.074Z","event_type":"price_change","market_id":"3792973","outcome_index":0,"market_type":"match","local_side":"home","local_uid":"2026-08-23_anna_bondar_en_shuo_liang","bid":0.74,"ask":0.75,"mid":0.745,"spread":0.01,"price":0.58,"size":5.0,"side":"BUY"}
{"ts":"2026-08-23T17:53:16.074Z","event_type":"price_change","market_id":"3792973","outcome_index":1,"market_type":"match","local_side":"away","local_uid":"2026-08-23_anna_bondar_en_shuo_liang","bid":0.25,"ask":0.26,"mid":0.255,"spread":0.01,"price":0.42,"size":5.0,"side":"SELL"}
{"ts":"2026-08-23T17:53:16.246Z","event_type":"best_bid_ask","market_id":"3790334","outcome_index":0,"market_type":"set2","local_side":"home","local_uid":"2026-08-23_abdullah_shelbayh_dhakshineswar_suresh","bid":0.48,"ask":0.54,"mid":0.51,"spread":0.06,"bid_size":null,"ask_size":null}
{"ts":"2026-08-23T17:53:16.247Z","event_type":"best_bid_ask","market_id":"3790334","outcome_index":1,"market_type":"set2","local_side":"away","local_uid":"2026-08-23_abdullah_shelbayh_dhakshineswar_suresh","bid":0.46,"ask":0.52,"mid":0.49,"spread":0.06,"bid_size":null,"ask_size":null}
{"ts":"2026-08-23T17:53:16.247Z","event_type":"price_change","market_id":"3790334","outcome_index":1,"market_type":"set2","local_side":"away","local_uid":"2026-08-23_abdullah_shelbayh_dhakshineswar_suresh","bid":0.46,"ask":0.52,"mid":0.49,"spread":0.06,"price":0.46,"size":150.0,"side":"BUY"}
{"ts":"2026-08-23T17:53:16.247Z","event_type":"price_change","market_id":"3790334","outcome_index":0,"market_type":"set2","local_side":"home","local_uid":"2026-08-23_abdullah_shelbayh_dhakshineswar_suresh","bid":0.48,"ask":0.54,"mid":0.51,"spread":0.06,"price":0.54,"size":150.0,"side":"SELL"}
{"ts":"2026-08-23T17:53:16.298Z","event_type":"best_bid_ask","market_id":"3790334","outcome_index":0,"market_type":"set2","local_side":"home","local_uid":"2026-08-23_abdullah_shelbayh_dhakshineswar_suresh","bid":0.48,"ask":0.55,"mid":0.515,"spread":0.07,"bid_size":null,"ask_size":null}
{"ts":"2026-08-23T17:53:16.299Z","event_type":"best_bid_ask","market_id":"3790334","outcome_index":1,"market_type":"set2","local_side":"away","local_uid":"2026-08-23_abdullah_shelbayh_dhakshineswar_suresh","bid":0.45,"ask":0.52,"mid":0.485,"spread":0.07,"bid_size":null,"ask_size":null}
{"ts":"2026-08-23T17:53:16.299Z","event_type":"price_change","market_id":"3790334","outcome_index":1,"market_type":"set2","local_side":"away","local_uid":"2026-08-23_abdullah_shelbayh_dhakshineswar_suresh","bid":0.45,"ask":0.52,"mid":0.485,"spread":0.07,"price":0.46,"size":0.0,"side":"BUY"}
{"ts":"2026-08-23T17:53:16.299Z","event_type":"price_change","market_id":"3790334","outcome_index":0,"market_type":"set2","local_side":"home","local_uid":"2026-08-23_abdullah_shelbayh_dhakshineswar_suresh","bid":0.48,"ask":0.55,"mid":0.515,"spread":0.07,"price":0.54,"size":0.0,"side":"SELL"}
{"ts":"2026-08-23T17:53:16.503Z","event_type":"best_bid_ask","market_id":"3790334","outcome_index":0,"market_type":"set2","local_side":"home","local_uid":"2026-08-23_abdullah_shelbayh_dhakshineswar_suresh","bid":0.48,"ask":0.54,"mid":0.51,"spread":0.06,"bid_size":null,"ask_size":null}
{"ts":"2026-08-23T17:53:16.504Z","event_type":"best_bid_ask","market_id":"3790334","outcome_index":1,"market_type":"set2","local_side":"away","local_uid":"2026-08-23_abdullah_shelbayh_dhakshineswar_suresh","bid":0.46,"ask":0.52,"mid":0.49,"spread":0.06,"bid_size":null,"ask_size":null}
{"ts":"2026-08-23T17:53:16.505Z","event_type":"price_change","market_id":"3790334","outcome_index":1,"market_type":"set2","local_side":"away","local_uid":"2026-08-23_abdullah_shelbayh_dhakshineswar_suresh","bid":0.46,"ask":0.52,"mid":0.49,"spread":0.06,"price":0.46,"size":98.89,"side":"BUY"}
{"ts":"2026-08-23T17:53:16.505Z","event_type":"price_change","market_id":"3790334","outcome_index":0,"market_type":"set2","local_side":"home","local_uid":"2026-08-23_abdullah_shelbayh_dhakshineswar_suresh","bid":0.48,"ask":0.54,"mid":0.51,"spread":0.06,"price":0.54,"size":98.89,"side":"SELL"}
{"ts":"2026-08-23T17:53:16.554Z","event_type":"best_bid_ask","market_id":"3790334","outcome_index":0,"market_type":"set2","local_side":"home","local_uid":"2026-08-23_abdullah_shelbayh_dhakshineswar_suresh","bid":0.48,"ask":0.56,"mid":0.52,"spread":0.08,"bid_size":null,"ask_size":null}
{"ts":"2026-08-23T17:53:16.555Z","event_type":"best_bid_ask","market_id":"3790334","outcome_index":1,"market_type":"set2","local_side":"away","local_uid":"2026-08-23_abdullah_shelbayh_dhakshineswar_suresh","bid":0.44,"ask":0.52,"mid":0.48,"spread":0.08,"bid_size":null,"ask_size":null}
{"ts":"2026-08-23T17:53:16.555Z","event_type":"price_change","market_id":"3790334","outcome_index":1,"market_type":"set2","local_side":"away","local_uid":"2026-08-23_abdullah_shelbayh_dhakshineswar_suresh","bid":0.44,"ask":0.52,"mid":0.48,"spread":0.08,"price":0.46,"size":0.0,"side":"BUY"}
{"ts":"2026-08-23T17:53:16.555Z","event_type":"price_change","market_id":"3790334","outcome_index":0,"market_type":"set2","local_side":"home","local_uid":"2026-08-23_abdullah_shelbayh_dhakshineswar_suresh","bid":0.48,"ask":0.56,"mid":0.52,"spread":0.08,"price":0.54,"size":0.0,"side":"SELL"}
{"ts":"2026-08-23T17:53:16.568Z","event_type":"best_bid_ask","market_id":"3790334","outcome_index":0,"market_type":"set2","local_side":"home","local_uid":"2026-08-23_abdullah_shelbayh_dhakshineswar_suresh","bid":0.48,"ask":0.55,"mid":0.515,"spread":0.07,"bid_size":null,"ask_size":null}
{"ts":"2026-08-23T17:53:16.568Z","event_type":"best_bid_ask","market_id":"3790334","outcome_index":1,"market_type":"set2","local_side":"away","local_uid":"2026-08-23_abdullah_shelbayh_dhakshineswar_suresh","bid":0.45,"ask":0.52,"mid":0.485,"spread":0.07,"bid_size":null,"ask_size":null}
{"ts":"2026-08-23T17:53:16.568Z","event_type":"price_change","market_id":"3790334","outcome_index":1,"market_type":"set2","local_side":"away","local_uid":"2026-08-23_abdullah_shelbayh_dhakshineswar_suresh","bid":0.45,"ask":0.52,"mid":0.485,"spread":0.07,"price":0.45,"size":49.2,"side":"BUY"}
{"ts":"2026-08-23T17:53:16.568Z","event_type":"price_change","market_id":"3790334","outcome_index":0,"market_type":"set2","local_side":"home","local_uid":"2026-08-23_abdullah_shelbayh_dhakshineswar_suresh","bid":0.48,"ask":0.55,"mid":0.515,"spread":0.07,"price":0.55,"size":49.2,"side":"SELL"}
{"ts":"2026-08-23T17:53:16.591Z","event_type":"best_bid_ask","market_id":"3790334","outcome_index":0,"market_type":"set2","local_side":"home","local_uid":"2026-08-23_abdullah_shelbayh_dhakshineswar_suresh","bid":0.48,"ask":0.54,"mid":0.51,"spread":0.06,"bid_size":null,"ask_size":null}
{"ts":"2026-08-23T17:53:16.591Z","event_type":"best_bid_ask","market_id":"3790334","outcome_index":1,"market_type":"set2","local_side":"away","local_uid":"2026-08-23_abdullah_shelbayh_dhakshineswar_suresh","bid":0.46,"ask":0.52,"mid":0.49,"spread":0.06,"bid_size":null,"ask_size":null}
{"ts":"2026-08-23T17:53:16.591Z","event_type":"price_change","market_id":"3790334","outcome_index":1,"market_type":"set2","local_side":"away","local_uid":"2026-08-23_abdullah_shelbayh_dhakshineswar_suresh","bid":0.46,"ask":0.52,"mid":0.49,"spread":0.06,"price":0.46,"size":98.89,"side":"BUY"}
{"ts":"2026-08-23T17:53:16.591Z","event_type":"price_change","market_id":"3790334","outcome_index":0,"market_type":"set2","local_side":"home","local_uid":"2026-08-23_abdullah_shelbayh_dhakshineswar_suresh","bid":0.48,"ask":0.54,"mid":0.51,"spread":0.06,"price":0.54,"size":98.89,"side":"SELL"}
{"ts":"2026-08-23T17:53:16.631Z","event_type":"best_bid_ask","market_id":"3790334","outcome_index":0,"market_type":"set2","local_side":"home","local_uid":"2026-08-23_abdullah_shelbayh_dhakshineswar_suresh","bid":0.48,"ask":0.56,"mid":0.52,"spread":0.08,"bid_size":null,"ask_size":null}
{"ts":"2026-08-23T17:53:16.631Z","event_type":"best_bid_ask","market_id":"3790334","outcome_index":1,"market_type":"set2","local_side":"away","local_uid":"2026-08-23_abdullah_shelbayh_dhakshineswar_suresh","bid":0.44,"ask":0.52,"mid":0.48,"spread":0.08,"bid_size":null,"ask_size":null}
{"ts":"2026-08-23T17:53:16.631Z","event_type":"price_change","market_id":"3790334","outcome_index":1,"market_type":"set2","local_side":"away","local_uid":"2026-08-23_abdullah_shelbayh_dhakshineswar_suresh","bid":0.44,"ask":0.52,"mid":0.48,"spread":0.08,"price":0.46,"size":0.0,"side":"BUY"}
{"ts":"2026-08-23T17:53:16.631Z","event_type":"price_change","market_id":"3790334","outcome_index":0,"market_type":"set2","local_side":"home","local_uid":"2026-08-23_abdullah_shelbayh_dhakshineswar_suresh","bid":0.48,"ask":0.56,"mid":0.52,"spread":0.08,"price":0.54,"size":0.0,"side":"SELL"}
{"ts":"2026-08-23T17:53:16.642Z","event_type":"best_bid_ask","market_id":"3790334","outcome_index":0,"market_type":"set2","local_side":"home","local_uid":"2026-08-23_abdullah_shelbayh_dhakshineswar_suresh","bid":0.48,"ask":0.55,"mid":0.515,"spread":0.07,"bid_size":null,"ask_size":null}
{"ts":"2026-08-23T17:53:16.642Z","event_type":"best_bid_ask","market_id":"3790334","outcome_index":1,"market_type":"set2","local_side":"away","local_uid":"2026-08-23_abdullah_shelbayh_dhakshineswar_suresh","bid":0.45,"ask":0.52,"mid":0.485,"spread":0.07,"bid_size":null,"ask_size":null}
{"ts":"2026-08-23T17:53:16.642Z","event_type":"price_change","market_id":"3790334","outcome_index":1,"market_type":"set2","local_side":"away","local_uid":"2026-08-23_abdullah_shelbayh_dhakshineswar_suresh","bid":0.45,"ask":0.52,"mid":0.485,"spread":0.07,"price":0.45,"size":150.0,"side":"BUY"}
{"ts":"2026-08-23T17:53:16.642Z","event_type":"price_change","market_id":"3790334","outcome_index":0,"market_type":"set2","local_side":"home","local_uid":"2026-08-23_abdullah_shelbayh_dhakshineswar_suresh","bid":0.48,"ask":0.55,"mid":0.515,"spread":0.07,"price":0.55,"size":150.0,"side":"SELL"}
{"ts":"2026-08-23T17:53:16.648Z","event_type":"best_bid_ask","market_id":"3790323","outcome_index":0,"market_type":"set2","local_side":"home","local_uid":"2026-08-23_felix_balshaw_sebastian_gorzny","bid":0.55,"ask":0.64,"mid":0.595,"spread":0.09,"bid_size":null,"ask_size":null}
{"ts":"2026-08-23T17:53:16.648Z","event_type":"best_bid_ask","market_id":"3790323","outcome_index":1,"market_type":"set2","local_side":"away","local_uid":"2026-08-23_felix_balshaw_sebastian_gorzny","bid":0.36,"ask":0.45,"mid":0.405,"spread":0.09,"bid_size":null,"ask_size":null}
{"ts":"2026-08-23T17:53:16.649Z","event_type":"price_change","market_id":"3790323","outcome_index":1,"market_type":"set2","local_side":"away","local_uid":"2026-08-23_felix_balshaw_sebastian_gorzny","bid":0.36,"ask":0.45,"mid":0.405,"spread":0.09,"price":0.36,"size":150.0,"side":"BUY"}
{"ts":"2026-08-23T17:53:16.649Z","event_type":"price_change","market_id":"3790323","outcome_index":0,"market_type":"set2","local_side":"home","local_uid":"2026-08-23_felix_balshaw_sebastian_gorzny","bid":0.55,"ask":0.64,"mid":0.595,"spread":0.09,"price":0.64,"size":150.0,"side":"SELL"}
{"ts":"2026-08-23T17:53:16.671Z","event_type":"best_bid_ask","market_id":"3790334","outcome_index":0,"market_type":"set2","local_side":"home","local_uid":"2026-08-23_abdullah_shelbayh_dhakshineswar_suresh","bid":0.48,"ask":0.53,"mid":0.505,"spread":0.05,"bid_size":null,"ask_size":null}
{"ts":"2026-08-23T17:53:16.671Z","event_type":"best_bid_ask","market_id":"3790334","outcome_index":1,"market_type":"set2","local_side":"away","local_uid":"2026-08-23_abdullah_shelbayh_dhakshineswar_suresh","bid":0.47,"ask":0.52,"mid":0.495,"spread":0.05,"bid_size":null,"ask_size":null}
{"ts":"2026-08-23T17:53:16.671Z","event_type":"price_change","market_id":"3790334","outcome_index":1,"market_type":"set2","local_side":"away","local_uid":"2026-08-23_abdullah_shelbayh_dhakshineswar_suresh","bid":0.47,"ask":0.52,"mid":0.495,"spread":0.05,"price":0.47,"size":150.0,"side":"BUY"}
{"ts":"2026-08-23T17:53:16.671Z","event_type":"price_change","market_id":"3790334","outcome_index":0,"market_type":"set2","local_side":"home","local_uid":"2026-08-23_abdullah_shelbayh_dhakshineswar_suresh","bid":0.48,"ask":0.53,"mid":0.505,"spread":0.05,"price":0.53,"size":150.0,"side":"SELL"}
{"ts":"2026-08-23T17:53:16.780Z","event_type":"best_bid_ask","market_id":"3790334","outcome_index":0,"market_type":"set2","local_side":"home","local_uid":"2026-08-23_abdullah_shelbayh_dhakshineswar_suresh","bid":0.48,"ask":0.52,"mid":0.5,"spread":0.04,"bid_size":null,"ask_size":null}
{"ts":"2026-08-23T17:53:16.780Z","event_type":"best_bid_ask","market_id":"3790334","outcome_index":1,"market_type":"set2","local_side":"away","local_uid":"2026-08-23_abdullah_shelbayh_dhakshineswar_suresh","bid":0.48,"ask":0.52,"mid":0.5,"spread":0.04,"bid_size":null,"ask_size":null}
{"ts":"2026-08-23T17:53:16.781Z","event_type":"price_change","market_id":"3790334","outcome_index":1,"market_type":"set2","local_side":"away","local_uid":"2026-08-23_abdullah_shelbayh_dhakshineswar_suresh","bid":0.48,"ask":0.52,"mid":0.5,"spread":0.04,"price":0.48,"size":21.0,"side":"BUY"}
{"ts":"2026-08-23T17:53:16.781Z","event_type":"price_change","market_id":"3790334","outcome_index":0,"market_type":"set2","local_side":"home","local_uid":"2026-08-23_abdullah_shelbayh_dhakshineswar_suresh","bid":0.48,"ask":0.52,"mid":0.5,"spread":0.04,"price":0.52,"size":21.0,"side":"SELL"}
{"ts":"2026-08-23T17:53:16.786Z","event_type":"best_bid_ask","market_id":"3790323","outcome_index":0,"market_type":"set2","local_side":"home","local_uid":"2026-08-23_felix_balshaw_sebastian_gorzny","bid":0.55,"ask":0.63,"mid":0.59,"spread":0.08,"bid_size":null,"ask_size":null}
{"ts":"2026-08-23T17:53:16.786Z","event_type":"best_bid_ask","market_id":"3790323","outcome_index":1,"market_type":"set2","local_side":"away","local_uid":"2026-08-23_felix_balshaw_sebastian_gorzny","bid":0.37,"ask":0.45,"mid":0.41,"spread":0.08,"bid_size":null,"ask_size":null}
{"ts":"2026-08-23T17:53:16.786Z","event_type":"price_change","market_id":"3790323","outcome_index":1,"market_type":"set2","local_side":"away","local_uid":"2026-08-23_felix_balshaw_sebastian_gorzny","bid":0.37,"ask":0.45,"mid":0.41,"spread":0.08,"price":0.37,"size":150.0,"side":"BUY"}
{"ts":"2026-08-23T17:53:16.786Z","event_type":"price_change","market_id":"3790323","outcome_index":0,"market_type":"set2","local_side":"home","local_uid":"2026-08-23_felix_balshaw_sebastian_gorzny","bid":0.55,"ask":0.63,"mid":0.59,"spread":0.08,"price":0.63,"size":150.0,"side":"SELL"}
{"ts":"2026-08-23T17:53:17.859Z","event_type":"price_change","market_id":"3793672","outcome_index":0,"market_type":"set2","local_side":"home","local_uid":"2026-08-24_alycia_parks_petra_marcinko","bid":0.42,"ask":0.51,"mid":0.465,"spread":0.09,"price":0.18,"size":0.0,"side":"BUY"}
{"ts":"2026-08-23T17:53:17.859Z","event_type":"price_change","market_id":"3793672","outcome_index":1,"market_type":"set2","local_side":"away","local_uid":"2026-08-24_alycia_parks_petra_marcinko","bid":0.49,"ask":0.58,"mid":0.535,"spread":0.09,"price":0.82,"size":0.0,"side":"SELL"}
{"ts":"2026-08-23T17:53:19.254Z","event_type":"last_trade_price","market_id":"3789925","outcome_index":0,"market_type":"match","local_side":"home","local_uid":"2026-08-23_pierre_hugues_herbert_quinn_vandecasteele","last_trade":0.84,"trade_size":1.98,"trade_side":"BUY","trade_notional":1.6632}
{"ts":"2026-08-23T17:53:19.514Z","event_type":"price_change","market_id":"3780846","outcome_index":1,"market_type":"match","local_side":"away","local_uid":"2026-08-23_martin_landaluce_mattia_bellucci","bid":0.46,"ask":0.47,"mid":0.465,"spread":0.01,"price":0.28,"size":0.0,"side":"BUY"}
{"ts":"2026-08-23T17:53:19.515Z","event_type":"price_change","market_id":"3780846","outcome_index":0,"market_type":"match","local_side":"home","local_uid":"2026-08-23_martin_landaluce_mattia_bellucci","bid":0.53,"ask":0.54,"mid":0.535,"spread":0.01,"price":0.72,"size":0.0,"side":"SELL"}
{"ts":"2026-08-23T17:53:20.088Z","event_type":"best_bid_ask","market_id":"3789927","outcome_index":0,"market_type":"match","local_side":"home","local_uid":"2026-08-23_hugo_grenier_mees_rottgering","bid":0.27,"ask":0.29,"mid":0.28,"spread":0.02,"bid_size":null,"ask_size":null}
{"ts":"2026-08-23T17:53:20.089Z","event_type":"best_bid_ask","market_id":"3789927","outcome_index":1,"market_type":"match","local_side":"away","local_uid":"2026-08-23_hugo_grenier_mees_rottgering","bid":0.71,"ask":0.73,"mid":0.72,"spread":0.02,"bid_size":null,"ask_size":null}
{"ts":"2026-08-23T17:53:20.089Z","event_type":"price_change","market_id":"3789927","outcome_index":0,"market_type":"match","local_side":"home","local_uid":"2026-08-23_hugo_grenier_mees_rottgering","bid":0.27,"ask":0.29,"mid":0.28,"spread":0.02,"price":0.27,"size":5999.75,"side":"BUY"}
{"ts":"2026-08-23T17:53:20.089Z","event_type":"price_change","market_id":"3789927","outcome_index":1,"market_type":"match","local_side":"away","local_uid":"2026-08-23_hugo_grenier_mees_rottgering","bid":0.71,"ask":0.73,"mid":0.72,"spread":0.02,"price":0.73,"size":5999.75,"side":"SELL"}
{"ts":"2026-08-23T17:53:20.195Z","event_type":"book","market_id":"3789927","outcome_index":0,"market_type":"match","local_side":"home","local_uid":"2026-08-23_hugo_grenier_mees_rottgering","bid":0.27,"ask":0.29,"mid":0.28,"spread":0.02,"bid_size":5999.75,"ask_size":877.9}
{"ts":"2026-08-23T17:53:20.196Z","event_type":"book","market_id":"3789927","outcome_index":1,"market_type":"match","local_side":"away","local_uid":"2026-08-23_hugo_grenier_mees_rottgering","bid":0.71,"ask":0.73,"mid":0.72,"spread":0.02,"bid_size":877.9,"ask_size":5999.75}
{"ts":"2026-08-23T17:53:20.196Z","event_type":"best_bid_ask","market_id":"3789927","outcome_index":0,"market_type":"match","local_side":"home","local_uid":"2026-08-23_hugo_grenier_mees_rottgering","bid":0.28,"ask":0.29,"mid":0.285,"spread":0.01,"bid_size":null,"ask_size":null}
{"ts":"2026-08-23T17:53:20.196Z","event_type":"best_bid_ask","market_id":"3789927","outcome_index":1,"market_type":"match","local_side":"away","local_uid":"2026-08-23_hugo_grenier_mees_rottgering","bid":0.71,"ask":0.72,"mid":0.715,"spread":0.01,"bid_size":null,"ask_size":null}
{"ts":"2026-08-23T17:53:20.196Z","event_type":"price_change","market_id":"3789927","outcome_index":0,"market_type":"match","local_side":"home","local_uid":"2026-08-23_hugo_grenier_mees_rottgering","bid":0.28,"ask":0.29,"mid":0.285,"spread":0.01,"price":0.28,"size":22.0,"side":"BUY"}
{"ts":"2026-08-23T17:53:20.196Z","event_type":"price_change","market_id":"3789927","outcome_index":1,"market_type":"match","local_side":"away","local_uid":"2026-08-23_hugo_grenier_mees_rottgering","bid":0.71,"ask":0.72,"mid":0.715,"spread":0.01,"price":0.72,"size":22.0,"side":"SELL"}
{"ts":"2026-08-23T17:53:20.200Z","event_type":"best_bid_ask","market_id":"3789927","outcome_index":0,"market_type":"match","local_side":"home","local_uid":"2026-08-23_hugo_grenier_mees_rottgering","bid":0.27,"ask":0.29,"mid":0.28,"spread":0.02,"bid_size":null,"ask_size":null}
{"ts":"2026-08-23T17:53:20.200Z","event_type":"best_bid_ask","market_id":"3789927","outcome_index":1,"market_type":"match","local_side":"away","local_uid":"2026-08-23_hugo_grenier_mees_rottgering","bid":0.71,"ask":0.73,"mid":0.72,"spread":0.02,"bid_size":null,"ask_size":null}
{"ts":"2026-08-23T17:53:20.201Z","event_type":"price_change","market_id":"3789927","outcome_index":0,"market_type":"match","local_side":"home","local_uid":"2026-08-23_hugo_grenier_mees_rottgering","bid":0.27,"ask":0.29,"mid":0.28,"spread":0.02,"price":0.28,"size":0.0,"side":"BUY"}
{"ts":"2026-08-23T17:53:20.201Z","event_type":"price_change","market_id":"3789927","outcome_index":1,"market_type":"match","local_side":"away","local_uid":"2026-08-23_hugo_grenier_mees_rottgering","bid":0.71,"ask":0.73,"mid":0.72,"spread":0.02,"price":0.72,"size":0.0,"side":"SELL"}
{"ts":"2026-08-23T17:53:20.201Z","event_type":"best_bid_ask","market_id":"3789927","outcome_index":0,"market_type":"match","local_side":"home","local_uid":"2026-08-23_hugo_grenier_mees_rottgering","bid":0.25,"ask":0.29,"mid":0.27,"spread":0.04,"bid_size":null,"ask_size":null}
{"ts":"2026-08-23T17:53:20.201Z","event_type":"best_bid_ask","market_id":"3789927","outcome_index":1,"market_type":"match","local_side":"away","local_uid":"2026-08-23_hugo_grenier_mees_rottgering","bid":0.71,"ask":0.75,"mid":0.73,"spread":0.04,"bid_size":null,"ask_size":null}
{"ts":"2026-08-23T17:53:20.201Z","event_type":"price_change","market_id":"3789927","outcome_index":0,"market_type":"match","local_side":"home","local_uid":"2026-08-23_hugo_grenier_mees_rottgering","bid":0.25,"ask":0.29,"mid":0.27,"spread":0.04,"price":0.27,"size":0.0,"side":"BUY"}
{"ts":"2026-08-23T17:53:20.201Z","event_type":"price_change","market_id":"3789927","outcome_index":1,"market_type":"match","local_side":"away","local_uid":"2026-08-23_hugo_grenier_mees_rottgering","bid":0.71,"ask":0.75,"mid":0.73,"spread":0.04,"price":0.73,"size":0.0,"side":"SELL"}
{"ts":"2026-08-23T17:53:20.203Z","event_type":"last_trade_price","market_id":"3789927","outcome_index":0,"market_type":"match","local_side":"home","local_uid":"2026-08-23_hugo_grenier_mees_rottgering","last_trade":0.27,"trade_size":0.25,"trade_side":"BUY","trade_notional":0.0675}
{"ts":"2026-08-23T17:53:20.205Z","event_type":"best_bid_ask","market_id":"3789927","outcome_index":0,"market_type":"match","local_side":"home","local_uid":"2026-08-23_hugo_grenier_mees_rottgering","bid":0.28,"ask":0.29,"mid":0.285,"spread":0.01,"bid_size":null,"ask_size":null}
{"ts":"2026-08-23T17:53:20.205Z","event_type":"best_bid_ask","market_id":"3789927","outcome_index":1,"market_type":"match","local_side":"away","local_uid":"2026-08-23_hugo_grenier_mees_rottgering","bid":0.71,"ask":0.72,"mid":0.715,"spread":0.01,"bid_size":null,"ask_size":null}
{"ts":"2026-08-23T17:53:20.205Z","event_type":"price_change","market_id":"3789927","outcome_index":0,"market_type":"match","local_side":"home","local_uid":"2026-08-23_hugo_grenier_mees_rottgering","bid":0.28,"ask":0.29,"mid":0.285,"spread":0.01,"price":0.28,"size":390.0,"side":"BUY"}
{"ts":"2026-08-23T17:53:20.205Z","event_type":"price_change","market_id":"3789927","outcome_index":1,"market_type":"match","local_side":"away","local_uid":"2026-08-23_hugo_grenier_mees_rottgering","bid":0.71,"ask":0.72,"mid":0.715,"spread":0.01,"price":0.72,"size":390.0,"side":"SELL"}
{"ts":"2026-08-23T17:53:20.266Z","event_type":"best_bid_ask","market_id":"3789927","outcome_index":0,"market_type":"match","local_side":"home","local_uid":"2026-08-23_hugo_grenier_mees_rottgering","bid":0.27,"ask":0.29,"mid":0.28,"spread":0.02,"bid_size":null,"ask_size":null}
{"ts":"2026-08-23T17:53:20.266Z","event_type":"best_bid_ask","market_id":"3789927","outcome_index":1,"market_type":"match","local_side":"away","local_uid":"2026-08-23_hugo_grenier_mees_rottgering","bid":0.71,"ask":0.73,"mid":0.72,"spread":0.02,"bid_size":null,"ask_size":null}
{"ts":"2026-08-23T17:53:20.267Z","event_type":"price_change","market_id":"3789927","outcome_index":0,"market_type":"match","local_side":"home","local_uid":"2026-08-23_hugo_grenier_mees_rottgering","bid":0.27,"ask":0.29,"mid":0.28,"spread":0.02,"price":0.28,"size":0.0,"side":"BUY"}
{"ts":"2026-08-23T17:53:20.267Z","event_type":"price_change","market_id":"3789927","outcome_index":1,"market_type":"match","local_side":"away","local_uid":"2026-08-23_hugo_grenier_mees_rottgering","bid":0.71,"ask":0.73,"mid":0.72,"spread":0.02,"price":0.72,"size":0.0,"side":"SELL"}
{"ts":"2026-08-23T17:53:20.280Z","event_type":"best_bid_ask","market_id":"3790394","outcome_index":0,"market_type":"set1","local_side":"home","local_uid":"2026-08-23_hugo_grenier_mees_rottgering","bid":0.28,"ask":0.4,"mid":0.34,"spread":0.12,"bid_size":null,"ask_size":null}
{"ts":"2026-08-23T17:53:20.280Z","event_type":"best_bid_ask","market_id":"3790394","outcome_index":1,"market_type":"set1","local_side":"away","local_uid":"2026-08-23_hugo_grenier_mees_rottgering","bid":0.6,"ask":0.72,"mid":0.66,"spread":0.12,"bid_size":null,"ask_size":null}
{"ts":"2026-08-23T17:53:20.281Z","event_type":"price_change","market_id":"3790394","outcome_index":0,"market_type":"set1","local_side":"home","local_uid":"2026-08-23_hugo_grenier_mees_rottgering","bid":0.28,"ask":0.4,"mid":0.34,"spread":0.12,"price":0.28,"size":423.0,"side":"BUY"}
{"ts":"2026-08-23T17:53:20.281Z","event_type":"price_change","market_id":"3790394","outcome_index":1,"market_type":"set1","local_side":"away","local_uid":"2026-08-23_hugo_grenier_mees_rottgering","bid":0.6,"ask":0.72,"mid":0.66,"spread":0.12,"price":0.72,"size":423.0,"side":"SELL"}
{"ts":"2026-08-23T17:53:20.290Z","event_type":"best_bid_ask","market_id":"3789927","outcome_index":0,"market_type":"match","local_side":"home","local_uid":"2026-08-23_hugo_grenier_mees_rottgering","bid":0.28,"ask":0.29,"mid":0.285,"spread":0.01,"bid_size":null,"ask_size":null}
{"ts":"2026-08-23T17:53:20.290Z","event_type":"best_bid_ask","market_id":"3789927","outcome_index":1,"market_type":"match","local_side":"away","local_uid":"2026-08-23_hugo_grenier_mees_rottgering","bid":0.71,"ask":0.72,"mid":0.715,"spread":0.01,"bid_size":null,"ask_size":null}
{"ts":"2026-08-23T17:53:20.292Z","event_type":"price_change","market_id":"3789927","outcome_index":0,"market_type":"match","local_side":"home","local_uid":"2026-08-23_hugo_grenier_mees_rottgering","bid":0.28,"ask":0.29,"mid":0.285,"spread":0.01,"price":0.28,"size":46.0,"side":"BUY"}
{"ts":"2026-08-23T17:53:20.292Z","event_type":"price_change","market_id":"3789927","outcome_index":1,"market_type":"match","local_side":"away","local_uid":"2026-08-23_hugo_grenier_mees_rottgering","bid":0.71,"ask":0.72,"mid":0.715,"spread":0.01,"price":0.72,"size":46.0,"side":"SELL"}
{"ts":"2026-08-23T17:53:20.292Z","event_type":"best_bid_ask","market_id":"3790394","outcome_index":0,"market_type":"set1","local_side":"home","local_uid":"2026-08-23_hugo_grenier_mees_rottgering","bid":0.29,"ask":0.4,"mid":0.345,"spread":0.11,"bid_size":null,"ask_size":null}
{"ts":"2026-08-23T17:53:20.292Z","event_type":"best_bid_ask","market_id":"3790394","outcome_index":1,"market_type":"set1","local_side":"away","local_uid":"2026-08-23_hugo_grenier_mees_rottgering","bid":0.6,"ask":0.71,"mid":0.655,"spread":0.11,"bid_size":null,"ask_size":null}
{"ts":"2026-08-23T17:53:20.294Z","event_type":"price_change","market_id":"3790394","outcome_index":0,"market_type":"set1","local_side":"home","local_uid":"2026-08-23_hugo_grenier_mees_rottgering","bid":0.29,"ask":0.4,"mid":0.345,"spread":0.11,"price":0.29,"size":88.0,"side":"BUY"}
{"ts":"2026-08-23T17:53:20.294Z","event_type":"price_change","market_id":"3790394","outcome_index":1,"market_type":"set1","local_side":"away","local_uid":"2026-08-23_hugo_grenier_mees_rottgering","bid":0.6,"ask":0.71,"mid":0.655,"spread":0.11,"price":0.71,"size":88.0,"side":"SELL"}
{"ts":"2026-08-23T17:53:20.300Z","event_type":"best_bid_ask","market_id":"3790397","outcome_index":0,"market_type":"set2","local_side":"home","local_uid":"2026-08-23_hugo_grenier_mees_rottgering","bid":0.3,"ask":0.41,"mid":0.355,"spread":0.11,"bid_size":null,"ask_size":null}
{"ts":"2026-08-23T17:53:20.300Z","event_type":"best_bid_ask","market_id":"3790397","outcome_index":1,"market_type":"set2","local_side":"away","local_uid":"2026-08-23_hugo_grenier_mees_rottgering","bid":0.59,"ask":0.7,"mid":0.645,"spread":0.11,"bid_size":null,"ask_size":null}
{"ts":"2026-08-23T17:53:20.300Z","event_type":"price_change","market_id":"3790397","outcome_index":0,"market_type":"set2","local_side":"home","local_uid":"2026-08-23_hugo_grenier_mees_rottgering","bid":0.3,"ask":0.41,"mid":0.355,"spread":0.11,"price":0.31,"size":0.0,"side":"BUY"}
{"ts":"2026-08-23T17:53:20.300Z","event_type":"price_change","market_id":"3790397","outcome_index":1,"market_type":"set2","local_side":"away","local_uid":"2026-08-23_hugo_grenier_mees_rottgering","bid":0.59,"ask":0.7,"mid":0.645,"spread":0.11,"price":0.69,"size":0.0,"side":"SELL"}
{"ts":"2026-08-23T17:53:20.302Z","event_type":"best_bid_ask","market_id":"3790397","outcome_index":0,"market_type":"set2","local_side":"home","local_uid":"2026-08-23_hugo_grenier_mees_rottgering","bid":0.3,"ask":0.42,"mid":0.36,"spread":0.12,"bid_size":null,"ask_size":null}
{"ts":"2026-08-23T17:53:20.303Z","event_type":"best_bid_ask","market_id":"3790397","outcome_index":1,"market_type":"set2","local_side":"away","local_uid":"2026-08-23_hugo_grenier_mees_rottgering","bid":0.58,"ask":0.7,"mid":0.64,"spread":0.12,"bid_size":null,"ask_size":null}
{"ts":"2026-08-23T17:53:20.303Z","event_type":"price_change","market_id":"3790397","outcome_index":1,"market_type":"set2","local_side":"away","local_uid":"2026-08-23_hugo_grenier_mees_rottgering","bid":0.58,"ask":0.7,"mid":0.64,"spread":0.12,"price":0.59,"size":0.0,"side":"BUY"}
{"ts":"2026-08-23T17:53:20.303Z","event_type":"price_change","market_id":"3790397","outcome_index":0,"market_type":"set2","local_side":"home","local_uid":"2026-08-23_hugo_grenier_mees_rottgering","bid":0.3,"ask":0.42,"mid":0.36,"spread":0.12,"price":0.41,"size":0.0,"side":"SELL"}
{"ts":"2026-08-23T17:53:20.312Z","event_type":"best_bid_ask","market_id":"3789927","outcome_index":0,"market_type":"match","local_side":"home","local_uid":"2026-08-23_hugo_grenier_mees_rottgering","bid":0.28,"ask":0.3,"mid":0.29,"spread":0.02,"bid_size":null,"ask_size":null}
{"ts":"2026-08-23T17:53:20.312Z","event_type":"best_bid_ask","market_id":"3789927","outcome_index":1,"market_type":"match","local_side":"away","local_uid":"2026-08-23_hugo_grenier_mees_rottgering","bid":0.7,"ask":0.72,"mid":0.71,"spread":0.02,"bid_size":null,"ask_size":null}
{"ts":"2026-08-23T17:53:20.313Z","event_type":"price_change","market_id":"3789927","outcome_index":1,"market_type":"match","local_side":"away","local_uid":"2026-08-23_hugo_grenier_mees_rottgering","bid":0.7,"ask":0.72,"mid":0.71,"spread":0.02,"price":0.7,"size":833.59,"side":"BUY"}
{"ts":"2026-08-23T17:53:20.313Z","event_type":"price_change","market_id":"3789927","outcome_index":0,"market_type":"match","local_side":"home","local_uid":"2026-08-23_hugo_grenier_mees_rottgering","bid":0.28,"ask":0.3,"mid":0.29,"spread":0.02,"price":0.3,"size":833.59,"side":"SELL"}
{"ts":"2026-08-23T17:53:20.323Z","event_type":"best_bid_ask","market_id":"3790394","outcome_index":0,"market_type":"set1","local_side":"home","local_uid":"2026-08-23_hugo_grenier_mees_rottgering","bid":0.3,"ask":0.4,"mid":0.35,"spread":0.1,"bid_size":null,"ask_size":null}
{"ts":"2026-08-23T17:53:20.323Z","event_type":"best_bid_ask","market_id":"3790394","outcome_index":1,"market_type":"set1","local_side":"away","local_uid":"2026-08-23_hugo_grenier_mees_rottgering","bid":0.6,"ask":0.7,"mid":0.65,"spread":0.1,"bid_size":null,"ask_size":null}
{"ts":"2026-08-23T17:53:20.323Z","event_type":"price_change","market_id":"3790394","outcome_index":0,"market_type":"set1","local_side":"home","local_uid":"2026-08-23_hugo_grenier_mees_rottgering","bid":0.3,"ask":0.4,"mid":0.35,"spread":0.1,"price":0.3,"size":150.0,"side":"BUY"}
{"ts":"2026-08-23T17:53:20.323Z","event_type":"price_change","market_id":"3790394","outcome_index":1,"market_type":"set1","local_side":"away","local_uid":"2026-08-23_hugo_grenier_mees_rottgering","bid":0.6,"ask":0.7,"mid":0.65,"spread":0.1,"price":0.7,"size":150.0,"side":"SELL"}
{"ts":"2026-08-23T17:53:20.343Z","event_type":"best_bid_ask","market_id":"3790397","outcome_index":0,"market_type":"set2","local_side":"home","local_uid":"2026-08-23_hugo_grenier_mees_rottgering","bid":0.31,"ask":0.42,"mid":0.365,"spread":0.11,"bid_size":null,"ask_size":null}
{"ts":"2026-08-23T17:53:20.344Z","event_type":"best_bid_ask","market_id":"3790397","outcome_index":1,"market_type":"set2","local_side":"away","local_uid":"2026-08-23_hugo_grenier_mees_rottgering","bid":0.58,"ask":0.69,"mid":0.635,"spread":0.11,"bid_size":null,"ask_size":null}
{"ts":"2026-08-23T17:53:20.344Z","event_type":"price_change","market_id":"3790397","outcome_index":0,"market_type":"set2","local_side":"home","local_uid":"2026-08-23_hugo_grenier_mees_rottgering","bid":0.31,"ask":0.42,"mid":0.365,"spread":0.11,"price":0.31,"size":150.0,"side":"BUY"}
{"ts":"2026-08-23T17:53:20.344Z","event_type":"price_change","market_id":"3790397","outcome_index":1,"market_type":"set2","local_side":"away","local_uid":"2026-08-23_hugo_grenier_mees_rottgering","bid":0.58,"ask":0.69,"mid":0.635,"spread":0.11,"price":0.69,"size":150.0,"side":"SELL"}
{"ts":"2026-08-23T17:53:20.367Z","event_type":"price_change","market_id":"3780832","outcome_index":0,"market_type":"match","local_side":"home","local_uid":"2026-08-23_francisco_comesana_yibing_wu","bid":0.38,"ask":0.39,"mid":0.385,"spread":0.01,"price":0.13,"size":5.0,"side":"BUY"}
{"ts":"2026-08-23T17:53:20.367Z","event_type":"price_change","market_id":"3780832","outcome_index":1,"market_type":"match","local_side":"away","local_uid":"2026-08-23_francisco_comesana_yibing_wu","bid":0.61,"ask":0.62,"mid":0.615,"spread":0.01,"price":0.87,"size":5.0,"side":"SELL"}
{"ts":"2026-08-23T17:53:20.400Z","event_type":"best_bid_ask","market_id":"3790394","outcome_index":0,"market_type":"set1","local_side":"home","local_uid":"2026-08-23_hugo_grenier_mees_rottgering","bid":0.3,"ask":0.41,"mid":0.355,"spread":0.11,"bid_size":null,"ask_size":null}
{"ts":"2026-08-23T17:53:20.400Z","event_type":"best_bid_ask","market_id":"3790394","outcome_index":1,"market_type":"set1","local_side":"away","local_uid":"2026-08-23_hugo_grenier_mees_rottgering","bid":0.59,"ask":0.7,"mid":0.645,"spread":0.11,"bid_size":null,"ask_size":null}
{"ts":"2026-08-23T17:53:20.400Z","event_type":"price_change","market_id":"3790394","outcome_index":1,"market_type":"set1","local_side":"away","local_uid":"2026-08-23_hugo_grenier_mees_rottgering","bid":0.59,"ask":0.7,"mid":0.645,"spread":0.11,"price":0.6,"size":0.0,"side":"BUY"}
{"ts":"2026-08-23T17:53:20.400Z","event_type":"price_change","market_id":"3790394","outcome_index":0,"market_type":"set1","local_side":"home","local_uid":"2026-08-23_hugo_grenier_mees_rottgering","bid":0.3,"ask":0.41,"mid":0.355,"spread":0.11,"price":0.4,"size":0.0,"side":"SELL"}
{"ts":"2026-08-23T17:53:20.446Z","event_type":"best_bid_ask","market_id":"3789927","outcome_index":0,"market_type":"match","local_side":"home","local_uid":"2026-08-23_hugo_grenier_mees_rottgering","bid":0.29,"ask":0.3,"mid":0.295,"spread":0.01,"bid_size":null,"ask_size":null}
{"ts":"2026-08-23T17:53:20.446Z","event_type":"best_bid_ask","market_id":"3789927","outcome_index":1,"market_type":"match","local_side":"away","local_uid":"2026-08-23_hugo_grenier_mees_rottgering","bid":0.7,"ask":0.71,"mid":0.705,"spread":0.01,"bid_size":null,"ask_size":null}
{"ts":"2026-08-23T17:53:20.446Z","event_type":"price_change","market_id":"3789927","outcome_index":0,"market_type":"match","local_side":"home","local_uid":"2026-08-23_hugo_grenier_mees_rottgering","bid":0.29,"ask":0.3,"mid":0.295,"spread":0.01,"price":0.29,"size":675.97,"side":"BUY"}
{"ts":"2026-08-23T17:53:20.446Z","event_type":"price_change","market_id":"3789927","outcome_index":1,"market_type":"match","local_side":"away","local_uid":"2026-08-23_hugo_grenier_mees_rottgering","bid":0.7,"ask":0.71,"mid":0.705,"spread":0.01,"price":0.71,"size":675.97,"side":"SELL"}
{"ts":"2026-08-23T17:53:20.584Z","event_type":"best_bid_ask","market_id":"3790334","outcome_index":0,"market_type":"set2","local_side":"home","local_uid":"2026-08-23_abdullah_shelbayh_dhakshineswar_suresh","bid":0.48,"ask":0.55,"mid":0.515,"spread":0.07,"bid_size":null,"ask_size":null}
{"ts":"2026-08-23T17:53:20.584Z","event_type":"best_bid_ask","market_id":"3790334","outcome_index":1,"market_type":"set2","local_side":"away","local_uid":"2026-08-23_abdullah_shelbayh_dhakshineswar_suresh","bid":0.45,"ask":0.52,"mid":0.485,"spread":0.07,"bid_size":null,"ask_size":null}
{"ts":"2026-08-23T17:53:20.585Z","event_type":"price_change","market_id":"3790334","outcome_index":1,"market_type":"set2","local_side":"away","local_uid":"2026-08-23_abdullah_shelbayh_dhakshineswar_suresh","bid":0.45,"ask":0.52,"mid":0.485,"spread":0.07,"price":0.48,"size":0.0,"side":"BUY"}
{"ts":"2026-08-23T17:53:20.585Z","event_type":"price_change","market_id":"3790334","outcome_index":0,"market_type":"set2","local_side":"home","local_uid":"2026-08-23_abdullah_shelbayh_dhakshineswar_suresh","bid":0.48,"ask":0.55,"mid":0.515,"spread":0.07,"price":0.52,"size":0.0,"side":"SELL"}
{"ts":"2026-08-23T17:53:20.589Z","event_type":"best_bid_ask","market_id":"3790334","outcome_index":0,"market_type":"set2","local_side":"home","local_uid":"2026-08-23_abdullah_shelbayh_dhakshineswar_suresh","bid":0.48,"ask":0.54,"mid":0.51,"spread":0.06,"bid_size":null,"ask_size":null}
{"ts":"2026-08-23T17:53:20.589Z","event_type":"best_bid_ask","market_id":"3790334","outcome_index":1,"market_type":"set2","local_side":"away","local_uid":"2026-08-23_abdullah_shelbayh_dhakshineswar_suresh","bid":0.46,"ask":0.52,"mid":0.49,"spread":0.06,"bid_size":null,"ask_size":null}
{"ts":"2026-08-23T17:53:20.589Z","event_type":"price_change","market_id":"3790334","outcome_index":1,"market_type":"set2","local_side":"away","local_uid":"2026-08-23_abdullah_shelbayh_dhakshineswar_suresh","bid":0.46,"ask":0.52,"mid":0.49,"spread":0.06,"price":0.46,"size":88.0,"side":"BUY"}
{"ts":"2026-08-23T17:53:20.589Z","event_type":"price_change","market_id":"3790334","outcome_index":0,"market_type":"set2","local_side":"home","local_uid":"2026-08-23_abdullah_shelbayh_dhakshineswar_suresh","bid":0.48,"ask":0.54,"mid":0.51,"spread":0.06,"price":0.54,"size":88.0,"side":"SELL"}
{"ts":"2026-08-23T17:53:20.615Z","event_type":"best_bid_ask","market_id":"3790334","outcome_index":0,"market_type":"set2","local_side":"home","local_uid":"2026-08-23_abdullah_shelbayh_dhakshineswar_suresh","bid":0.48,"ask":0.55,"mid":0.515,"spread":0.07,"bid_size":null,"ask_size":null}
{"ts":"2026-08-23T17:53:20.615Z","event_type":"best_bid_ask","market_id":"3790334","outcome_index":1,"market_type":"set2","local_side":"away","local_uid":"2026-08-23_abdullah_shelbayh_dhakshineswar_suresh","bid":0.45,"ask":0.52,"mid":0.485,"spread":0.07,"bid_size":null,"ask_size":null}
{"ts":"2026-08-23T17:53:20.616Z","event_type":"price_change","market_id":"3790334","outcome_index":1,"market_type":"set2","local_side":"away","local_uid":"2026-08-23_abdullah_shelbayh_dhakshineswar_suresh","bid":0.45,"ask":0.52,"mid":0.485,"spread":0.07,"price":0.46,"size":0.0,"side":"BUY"}
{"ts":"2026-08-23T17:53:20.616Z","event_type":"price_change","market_id":"3790334","outcome_index":0,"market_type":"set2","local_side":"home","local_uid":"2026-08-23_abdullah_shelbayh_dhakshineswar_suresh","bid":0.48,"ask":0.55,"mid":0.515,"spread":0.07,"price":0.54,"size":0.0,"side":"SELL"}
{"ts":"2026-08-23T17:53:21.893Z","event_type":"best_bid_ask","market_id":"3789931","outcome_index":0,"market_type":"match","local_side":"home","local_uid":"2026-08-23_stefanos_sakellaridis_luca_van_assche","bid":0.05,"ask":0.06,"mid":0.055,"spread":0.01,"bid_size":null,"ask_size":null}
{"ts":"2026-08-23T17:53:21.894Z","event_type":"best_bid_ask","market_id":"3789931","outcome_index":1,"market_type":"match","local_side":"away","local_uid":"2026-08-23_stefanos_sakellaridis_luca_van_assche","bid":0.94,"ask":0.95,"mid":0.945,"spread":0.01,"bid_size":null,"ask_size":null}
{"ts":"2026-08-23T17:53:21.894Z","event_type":"price_change","market_id":"3789931","outcome_index":1,"market_type":"match","local_side":"away","local_uid":"2026-08-23_stefanos_sakellaridis_luca_van_assche","bid":0.94,"ask":0.95,"mid":0.945,"spread":0.01,"price":0.94,"size":6000.0,"side":"BUY"}
{"ts":"2026-08-23T17:53:21.894Z","event_type":"price_change","market_id":"3789931","outcome_index":0,"market_type":"match","local_side":"home","local_uid":"2026-08-23_stefanos_sakellaridis_luca_van_assche","bid":0.05,"ask":0.06,"mid":0.055,"spread":0.01,"price":0.06,"size":6000.0,"side":"SELL"}
{"ts":"2026-08-23T17:53:21.919Z","event_type":"best_bid_ask","market_id":"3790334","outcome_index":0,"market_type":"set2","local_side":"home","local_uid":"2026-08-23_abdullah_shelbayh_dhakshineswar_suresh","bid":0.48,"ask":1.0,"mid":0.74,"spread":0.52,"bid_size":null,"ask_size":null}
{"ts":"2026-08-23T17:53:21.920Z","event_type":"best_bid_ask","market_id":"3790334","outcome_index":1,"market_type":"set2","local_side":"away","local_uid":"2026-08-23_abdullah_shelbayh_dhakshineswar_suresh","bid":0.0,"ask":0.52,"mid":0.26,"spread":0.52,"bid_size":null,"ask_size":null}
{"ts":"2026-08-23T17:53:21.920Z","event_type":"price_change","market_id":"3790334","outcome_index":1,"market_type":"set2","local_side":"away","local_uid":"2026-08-23_abdullah_shelbayh_dhakshineswar_suresh","bid":0.0,"ask":0.52,"mid":0.26,"spread":0.52,"price":0.45,"size":0.0,"side":"BUY"}
{"ts":"2026-08-23T17:53:21.920Z","event_type":"price_change","market_id":"3790334","outcome_index":0,"market_type":"set2","local_side":"home","local_uid":"2026-08-23_abdullah_shelbayh_dhakshineswar_suresh","bid":0.48,"ask":1.0,"mid":0.74,"spread":0.52,"price":0.55,"size":0.0,"side":"SELL"}
{"ts":"2026-08-23T17:53:22.138Z","event_type":"last_trade_price","market_id":"3789997","outcome_index":1,"market_type":"match","local_side":"away","local_uid":"2026-08-23_oscar_weightman_alec_deckers","last_trade":0.95,"trade_size":60.0,"trade_side":"BUY","trade_notional":57.0}
{"ts":"2026-08-23T17:53:22.160Z","event_type":"best_bid_ask","market_id":"3790334","outcome_index":0,"market_type":"set2","local_side":"home","local_uid":"2026-08-23_abdullah_shelbayh_dhakshineswar_suresh","bid":0.48,"ask":0.53,"mid":0.505,"spread":0.05,"bid_size":null,"ask_size":null}
{"ts":"2026-08-23T17:53:22.160Z","event_type":"best_bid_ask","market_id":"3790334","outcome_index":1,"market_type":"set2","local_side":"away","local_uid":"2026-08-23_abdullah_shelbayh_dhakshineswar_suresh","bid":0.47,"ask":0.52,"mid":0.495,"spread":0.05,"bid_size":null,"ask_size":null}
{"ts":"2026-08-23T17:53:22.160Z","event_type":"price_change","market_id":"3790334","outcome_index":1,"market_type":"set2","local_side":"away","local_uid":"2026-08-23_abdullah_shelbayh_dhakshineswar_suresh","bid":0.47,"ask":0.52,"mid":0.495,"spread":0.05,"price":0.47,"size":150.0,"side":"BUY"}
{"ts":"2026-08-23T17:53:22.160Z","event_type":"price_change","market_id":"3790334","outcome_index":0,"market_type":"set2","local_side":"home","local_uid":"2026-08-23_abdullah_shelbayh_dhakshineswar_suresh","bid":0.48,"ask":0.53,"mid":0.505,"spread":0.05,"price":0.53,"size":150.0,"side":"SELL"}
{"ts":"2026-08-23T17:53:22.184Z","event_type":"best_bid_ask","market_id":"3789931","outcome_index":0,"market_type":"match","local_side":"home","local_uid":"2026-08-23_stefanos_sakellaridis_luca_van_assche","bid":0.04,"ask":0.06,"mid":0.05,"spread":0.02,"bid_size":null,"ask_size":null}
{"ts":"2026-08-23T17:53:22.184Z","event_type":"best_bid_ask","market_id":"3789931","outcome_index":1,"market_type":"match","local_side":"away","local_uid":"2026-08-23_stefanos_sakellaridis_luca_van_assche","bid":0.94,"ask":0.96,"mid":0.95,"spread":0.02,"bid_size":null,"ask_size":null}
{"ts":"2026-08-23T17:53:22.184Z","event_type":"price_change","market_id":"3789931","outcome_index":0,"market_type":"match","local_side":"home","local_uid":"2026-08-23_stefanos_sakellaridis_luca_van_assche","bid":0.04,"ask":0.06,"mid":0.05,"spread":0.02,"price":0.05,"size":0.0,"side":"BUY"}
{"ts":"2026-08-23T17:53:22.184Z","event_type":"price_change","market_id":"3789931","outcome_index":1,"market_type":"match","local_side":"away","local_uid":"2026-08-23_stefanos_sakellaridis_luca_van_assche","bid":0.94,"ask":0.96,"mid":0.95,"spread":0.02,"price":0.95,"size":0.0,"side":"SELL"}
{"ts":"2026-08-23T17:53:22.198Z","event_type":"price_change","market_id":"3795960","outcome_index":1,"market_type":"match","local_side":"away","local_uid":"2026-08-23_enmanuel_munoz_thomas_fancutt","bid":0.992,"ask":0.999,"mid":0.9955,"spread":0.007,"price":0.983,"size":5183.0,"side":"BUY"}
{"ts":"2026-08-23T17:53:22.198Z","event_type":"price_change","market_id":"3795960","outcome_index":0,"market_type":"match","local_side":"home","local_uid":"2026-08-23_enmanuel_munoz_thomas_fancutt","bid":0.001,"ask":0.008,"mid":0.0045,"spread":0.007,"price":0.017,"size":5183.0,"side":"SELL"}
{"ts":"2026-08-23T17:53:22.213Z","event_type":"best_bid_ask","market_id":"3789931","outcome_index":0,"market_type":"match","local_side":"home","local_uid":"2026-08-23_stefanos_sakellaridis_luca_van_assche","bid":0.05,"ask":0.06,"mid":0.055,"spread":0.01,"bid_size":null,"ask_size":null}
{"ts":"2026-08-23T17:53:22.213Z","event_type":"best_bid_ask","market_id":"3789931","outcome_index":1,"market_type":"match","local_side":"away","local_uid":"2026-08-23_stefanos_sakellaridis_luca_van_assche","bid":0.94,"ask":0.95,"mid":0.945,"spread":0.01,"bid_size":null,"ask_size":null}
{"ts":"2026-08-23T17:53:22.214Z","event_type":"price_change","market_id":"3789931","outcome_index":0,"market_type":"match","local_side":"home","local_uid":"2026-08-23_stefanos_sakellaridis_luca_van_assche","bid":0.05,"ask":0.06,"mid":0.055,"spread":0.01,"price":0.05,"size":47.7,"side":"BUY"}
{"ts":"2026-08-23T17:53:22.214Z","event_type":"price_change","market_id":"3789931","outcome_index":1,"market_type":"match","local_side":"away","local_uid":"2026-08-23_stefanos_sakellaridis_luca_van_assche","bid":0.94,"ask":0.95,"mid":0.945,"spread":0.01,"price":0.95,"size":47.7,"side":"SELL"}
{"ts":"2026-08-23T17:53:22.214Z","event_type":"best_bid_ask","market_id":"3790394","outcome_index":0,"market_type":"set1","local_side":"home","local_uid":"2026-08-23_hugo_grenier_mees_rottgering","bid":0.31,"ask":0.41,"mid":0.36,"spread":0.1,"bid_size":null,"ask_size":null}
{"ts":"2026-08-23T17:53:22.214Z","event_type":"best_bid_ask","market_id":"3790394","outcome_index":1,"market_type":"set1","local_side":"away","local_uid":"2026-08-23_hugo_grenier_mees_rottgering","bid":0.59,"ask":0.69,"mid":0.64,"spread":0.1,"bid_size":null,"ask_size":null}
{"ts":"2026-08-23T17:53:22.214Z","event_type":"price_change","market_id":"3790394","outcome_index":0,"market_type":"set1","local_side":"home","local_uid":"2026-08-23_hugo_grenier_mees_rottgering","bid":0.31,"ask":0.41,"mid":0.36,"spread":0.1,"price":0.31,"size":106.76,"side":"BUY"}
{"ts":"2026-08-23T17:53:22.214Z","event_type":"price_change","market_id":"3790394","outcome_index":1,"market_type":"set1","local_side":"away","local_uid":"2026-08-23_hugo_grenier_mees_rottgering","bid":0.59,"ask":0.69,"mid":0.64,"spread":0.1,"price":0.69,"size":106.76,"side":"SELL"}
{"ts":"2026-08-23T17:53:22.382Z","event_type":"best_bid_ask","market_id":"3789931","outcome_index":0,"market_type":"match","local_side":"home","local_uid":"2026-08-23_stefanos_sakellaridis_luca_van_assche","bid":0.04,"ask":0.06,"mid":0.05,"spread":0.02,"bid_size":null,"ask_size":null}
{"ts":"2026-08-23T17:53:22.382Z","event_type":"best_bid_ask","market_id":"3789931","outcome_index":1,"market_type":"match","local_side":"away","local_uid":"2026-08-23_stefanos_sakellaridis_luca_van_assche","bid":0.94,"ask":0.96,"mid":0.95,"spread":0.02,"bid_size":null,"ask_size":null}
{"ts":"2026-08-23T17:53:22.382Z","event_type":"price_change","market_id":"3789931","outcome_index":0,"market_type":"match","local_side":"home","local_uid":"2026-08-23_stefanos_sakellaridis_luca_van_assche","bid":0.04,"ask":0.06,"mid":0.05,"spread":0.02,"price":0.05,"size":0.0,"side":"BUY"}
{"ts":"2026-08-23T17:53:22.382Z","event_type":"price_change","market_id":"3789931","outcome_index":1,"market_type":"match","local_side":"away","local_uid":"2026-08-23_stefanos_sakellaridis_luca_van_assche","bid":0.94,"ask":0.96,"mid":0.95,"spread":0.02,"price":0.95,"size":0.0,"side":"SELL"}
{"ts":"2026-08-23T17:53:22.382Z","event_type":"best_bid_ask","market_id":"3789931","outcome_index":0,"market_type":"match","local_side":"home","local_uid":"2026-08-23_stefanos_sakellaridis_luca_van_assche","bid":0.04,"ask":0.05,"mid":0.045,"spread":0.01,"bid_size":null,"ask_size":null}
{"ts":"2026-08-23T17:53:22.383Z","event_type":"best_bid_ask","market_id":"3789931","outcome_index":1,"market_type":"match","local_side":"away","local_uid":"2026-08-23_stefanos_sakellaridis_luca_van_assche","bid":0.95,"ask":0.96,"mid":0.955,"spread":0.01,"bid_size":null,"ask_size":null}
{"ts":"2026-08-23T17:53:22.383Z","event_type":"price_change","market_id":"3789931","outcome_index":1,"market_type":"match","local_side":"away","local_uid":"2026-08-23_stefanos_sakellaridis_luca_van_assche","bid":0.95,"ask":0.96,"mid":0.955,"spread":0.01,"price":0.95,"size":6474.74,"side":"BUY"}
{"ts":"2026-08-23T17:53:22.383Z","event_type":"price_change","market_id":"3789931","outcome_index":0,"market_type":"match","local_side":"home","local_uid":"2026-08-23_stefanos_sakellaridis_luca_van_assche","bid":0.04,"ask":0.05,"mid":0.045,"spread":0.01,"price":0.05,"size":6474.74,"side":"SELL"}
{"ts":"2026-08-23T17:53:22.385Z","event_type":"best_bid_ask","market_id":"3790394","outcome_index":0,"market_type":"set1","local_side":"home","local_uid":"2026-08-23_hugo_grenier_mees_rottgering","bid":0.33,"ask":0.41,"mid":0.37,"spread":0.08,"bid_size":null,"ask_size":null}
{"ts":"2026-08-23T17:53:22.385Z","event_type":"best_bid_ask","market_id":"3790394","outcome_index":1,"market_type":"set1","local_side":"away","local_uid":"2026-08-23_hugo_grenier_mees_rottgering","bid":0.59,"ask":0.67,"mid":0.63,"spread":0.08,"bid_size":null,"ask_size":null}
{"ts":"2026-08-23T17:53:22.386Z","event_type":"price_change","market_id":"3790394","outcome_index":0,"market_type":"set1","local_side":"home","local_uid":"2026-08-23_hugo_grenier_mees_rottgering","bid":0.33,"ask":0.41,"mid":0.37,"spread":0.08,"price":0.33,"size":400.0,"side":"BUY"}
{"ts":"2026-08-23T17:53:22.386Z","event_type":"price_change","market_id":"3790394","outcome_index":1,"market_type":"set1","local_side":"away","local_uid":"2026-08-23_hugo_grenier_mees_rottgering","bid":0.59,"ask":0.67,"mid":0.63,"spread":0.08,"price":0.67,"size":400.0,"side":"SELL"}
{"ts":"2026-08-23T17:53:22.386Z","event_type":"best_bid_ask","market_id":"3790394","outcome_index":0,"market_type":"set1","local_side":"home","local_uid":"2026-08-23_hugo_grenier_mees_rottgering","bid":0.33,"ask":0.4,"mid":0.365,"spread":0.07,"bid_size":null,"ask_size":null}
{"ts":"2026-08-23T17:53:22.386Z","event_type":"best_bid_ask","market_id":"3790394","outcome_index":1,"market_type":"set1","local_side":"away","local_uid":"2026-08-23_hugo_grenier_mees_rottgering","bid":0.6,"ask":0.67,"mid":0.635,"spread":0.07,"bid_size":null,"ask_size":null}
{"ts":"2026-08-23T17:53:22.386Z","event_type":"price_change","market_id":"3790394","outcome_index":1,"market_type":"set1","local_side":"away","local_uid":"2026-08-23_hugo_grenier_mees_rottgering","bid":0.6,"ask":0.67,"mid":0.635,"spread":0.07,"price":0.6,"size":150.0,"side":"BUY"}
{"ts":"2026-08-23T17:53:22.386Z","event_type":"price_change","market_id":"3790394","outcome_index":0,"market_type":"set1","local_side":"home","local_uid":"2026-08-23_hugo_grenier_mees_rottgering","bid":0.33,"ask":0.4,"mid":0.365,"spread":0.07,"price":0.4,"size":150.0,"side":"SELL"}
{"ts":"2026-08-23T17:53:22.402Z","event_type":"best_bid_ask","market_id":"3790397","outcome_index":0,"market_type":"set2","local_side":"home","local_uid":"2026-08-23_hugo_grenier_mees_rottgering","bid":0.32,"ask":0.42,"mid":0.37,"spread":0.1,"bid_size":null,"ask_size":null}
{"ts":"2026-08-23T17:53:22.402Z","event_type":"best_bid_ask","market_id":"3790397","outcome_index":1,"market_type":"set2","local_side":"away","local_uid":"2026-08-23_hugo_grenier_mees_rottgering","bid":0.58,"ask":0.68,"mid":0.63,"spread":0.1,"bid_size":null,"ask_size":null}
{"ts":"2026-08-23T17:53:22.402Z","event_type":"price_change","market_id":"3790397","outcome_index":0,"market_type":"set2","local_side":"home","local_uid":"2026-08-23_hugo_grenier_mees_rottgering","bid":0.32,"ask":0.42,"mid":0.37,"spread":0.1,"price":0.32,"size":150.0,"side":"BUY"}
{"ts":"2026-08-23T17:53:22.402Z","event_type":"price_change","market_id":"3790397","outcome_index":1,"market_type":"set2","local_side":"away","local_uid":"2026-08-23_hugo_grenier_mees_rottgering","bid":0.58,"ask":0.68,"mid":0.63,"spread":0.1,"price":0.68,"size":150.0,"side":"SELL"}
{"ts":"2026-08-23T17:53:22.958Z","event_type":"best_bid_ask","market_id":"3790334","outcome_index":0,"market_type":"set2","local_side":"home","local_uid":"2026-08-23_abdullah_shelbayh_dhakshineswar_suresh","bid":0.48,"ask":0.58,"mid":0.53,"spread":0.1,"bid_size":null,"ask_size":null}
{"ts":"2026-08-23T17:53:22.958Z","event_type":"best_bid_ask","market_id":"3790334","outcome_index":1,"market_type":"set2","local_side":"away","local_uid":"2026-08-23_abdullah_shelbayh_dhakshineswar_suresh","bid":0.42,"ask":0.52,"mid":0.47,"spread":0.1,"bid_size":null,"ask_size":null}
{"ts":"2026-08-23T17:53:22.958Z","event_type":"price_change","market_id":"3790334","outcome_index":1,"market_type":"set2","local_side":"away","local_uid":"2026-08-23_abdullah_shelbayh_dhakshineswar_suresh","bid":0.42,"ask":0.52,"mid":0.47,"spread":0.1,"price":0.47,"size":0.0,"side":"BUY"}
{"ts":"2026-08-23T17:53:22.958Z","event_type":"price_change","market_id":"3790334","outcome_index":0,"market_type":"set2","local_side":"home","local_uid":"2026-08-23_abdullah_shelbayh_dhakshineswar_suresh","bid":0.48,"ask":0.58,"mid":0.53,"spread":0.1,"price":0.53,"size":0.0,"side":"SELL"}
{"ts":"2026-08-23T17:53:23.046Z","event_type":"best_bid_ask","market_id":"3790334","outcome_index":0,"market_type":"set2","local_side":"home","local_uid":"2026-08-23_abdullah_shelbayh_dhakshineswar_suresh","bid":0.48,"ask":0.55,"mid":0.515,"spread":0.07,"bid_size":null,"ask_size":null}
{"ts":"2026-08-23T17:53:23.046Z","event_type":"best_bid_ask","market_id":"3790334","outcome_index":1,"market_type":"set2","local_side":"away","local_uid":"2026-08-23_abdullah_shelbayh_dhakshineswar_suresh","bid":0.45,"ask":0.52,"mid":0.485,"spread":0.07,"bid_size":null,"ask_size":null}
{"ts":"2026-08-23T17:53:23.046Z","event_type":"price_change","market_id":"3790334","outcome_index":1,"market_type":"set2","local_side":"away","local_uid":"2026-08-23_abdullah_shelbayh_dhakshineswar_suresh","bid":0.45,"ask":0.52,"mid":0.485,"spread":0.07,"price":0.45,"size":211.0,"side":"BUY"}
{"ts":"2026-08-23T17:53:23.046Z","event_type":"price_change","market_id":"3790334","outcome_index":0,"market_type":"set2","local_side":"home","local_uid":"2026-08-23_abdullah_shelbayh_dhakshineswar_suresh","bid":0.48,"ask":0.55,"mid":0.515,"spread":0.07,"price":0.55,"size":211.0,"side":"SELL"}
{"ts":"2026-08-23T17:53:23.046Z","event_type":"best_bid_ask","market_id":"3790334","outcome_index":0,"market_type":"set2","local_side":"home","local_uid":"2026-08-23_abdullah_shelbayh_dhakshineswar_suresh","bid":0.48,"ask":0.54,"mid":0.51,"spread":0.06,"bid_size":null,"ask_size":null}
{"ts":"2026-08-23T17:53:23.046Z","event_type":"best_bid_ask","market_id":"3790334","outcome_index":1,"market_type":"set2","local_side":"away","local_uid":"2026-08-23_abdullah_shelbayh_dhakshineswar_suresh","bid":0.46,"ask":0.52,"mid":0.49,"spread":0.06,"bid_size":null,"ask_size":null}
{"ts":"2026-08-23T17:53:23.046Z","event_type":"price_change","market_id":"3790334","outcome_index":1,"market_type":"set2","local_side":"away","local_uid":"2026-08-23_abdullah_shelbayh_dhakshineswar_suresh","bid":0.46,"ask":0.52,"mid":0.49,"spread":0.06,"price":0.46,"size":88.0,"side":"BUY"}
{"ts":"2026-08-23T17:53:23.046Z","event_type":"price_change","market_id":"3790334","outcome_index":0,"market_type":"set2","local_side":"home","local_uid":"2026-08-23_abdullah_shelbayh_dhakshineswar_suresh","bid":0.48,"ask":0.54,"mid":0.51,"spread":0.06,"price":0.54,"size":88.0,"side":"SELL"}
{"ts":"2026-08-23T17:53:23.085Z","event_type":"book","market_id":"3789927","outcome_index":0,"market_type":"match","local_side":"home","local_uid":"2026-08-23_hugo_grenier_mees_rottgering","bid":0.29,"ask":0.3,"mid":0.295,"spread":0.01,"bid_size":17585.37,"ask_size":61.19}
{"ts":"2026-08-23T17:53:23.086Z","event_type":"book","market_id":"3789927","outcome_index":1,"market_type":"match","local_side":"away","local_uid":"2026-08-23_hugo_grenier_mees_rottgering","bid":0.7,"ask":0.71,"mid":0.705,"spread":0.01,"bid_size":61.19,"ask_size":17585.37}
{"ts":"2026-08-23T17:53:23.160Z","event_type":"last_trade_price","market_id":"3789927","outcome_index":0,"market_type":"match","local_side":"home","local_uid":"2026-08-23_hugo_grenier_mees_rottgering","last_trade":0.3,"trade_size":10.0,"trade_side":"BUY","trade_notional":3.0}
{"ts":"2026-08-23T17:53:23.854Z","event_type":"new_market","market_id":"0xafa17f40743fab4195103fcc1132b86627042898a91e78d883fe20d79e7527ab"}
{"ts":"2026-08-23T17:53:23.854Z","event_type":"new_market","market_id":"0x236efc1c85110eb48e1d973bb6385f1d3100b74595fd620bfb631c6d3018a4bf"}
{"ts":"2026-08-23T17:53:23.871Z","event_type":"new_market","market_id":"0x40f100a232ff6fbf0c7e7f046a6ee2e01edbd78c8cda9b8d22ae8d49cb609648"}
{"ts":"2026-08-23T17:53:23.880Z","event_type":"new_market","market_id":"0x525c70ca07a46b8486e947d506bd8e8e77e954719f1b0dda9cc691f802592b27"}
{"ts":"2026-08-23T17:53:23.881Z","event_type":"price_change","market_id":"3789999","outcome_index":1,"market_type":"match","local_side":"away","local_uid":"2026-08-23_tiago_cacao_fabrizio_andaloro","bid":0.999,"ask":1.0,"mid":0.9995,"spread":0.001,"price":0.013,"size":44000.0,"side":"BUY"}
{"ts":"2026-08-23T17:53:23.881Z","event_type":"price_change","market_id":"3789999","outcome_index":0,"market_type":"match","local_side":"home","local_uid":"2026-08-23_tiago_cacao_fabrizio_andaloro","bid":0.0,"ask":0.001,"mid":0.0005,"spread":0.001,"price":0.987,"size":44000.0,"side":"SELL"}
{"ts":"2026-08-23T17:53:24.092Z","event_type":"last_trade_price","market_id":"3789927","outcome_index":0,"market_type":"match","local_side":"home","local_uid":"2026-08-23_hugo_grenier_mees_rottgering","last_trade":0.29,"trade_size":150.0,"trade_side":"SELL","trade_notional":43.5}
{"ts":"2026-08-23T17:53:24.235Z","event_type":"last_trade_price","market_id":"3789927","outcome_index":0,"market_type":"match","local_side":"home","local_uid":"2026-08-23_hugo_grenier_mees_rottgering","last_trade":0.29,"trade_size":150.0,"trade_side":"SELL","trade_notional":43.5}
{"ts":"2026-08-23T17:53:24.480Z","event_type":"price_change","market_id":"3793888","outcome_index":0,"market_type":"set1","local_side":"home","local_uid":"2026-08-23_anna_bondar_en_shuo_liang","bid":0.69,"ask":0.72,"mid":0.705,"spread":0.03,"price":0.64,"size":0.0,"side":"BUY"}
{"ts":"2026-08-23T17:53:24.480Z","event_type":"price_change","market_id":"3793888","outcome_index":1,"market_type":"set1","local_side":"away","local_uid":"2026-08-23_anna_bondar_en_shuo_liang","bid":0.28,"ask":0.31,"mid":0.295,"spread":0.03,"price":0.36,"size":0.0,"side":"SELL"}
{"ts":"2026-08-23T17:53:24.839Z","event_type":"best_bid_ask","market_id":"3790394","outcome_index":0,"market_type":"set1","local_side":"home","local_uid":"2026-08-23_hugo_grenier_mees_rottgering","bid":0.31,"ask":0.4,"mid":0.355,"spread":0.09,"bid_size":null,"ask_size":null}
{"ts":"2026-08-23T17:53:24.839Z","event_type":"best_bid_ask","market_id":"3790394","outcome_index":1,"market_type":"set1","local_side":"away","local_uid":"2026-08-23_hugo_grenier_mees_rottgering","bid":0.6,"ask":0.69,"mid":0.645,"spread":0.09,"bid_size":null,"ask_size":null}
{"ts":"2026-08-23T17:53:24.839Z","event_type":"price_change","market_id":"3790394","outcome_index":0,"market_type":"set1","local_side":"home","local_uid":"2026-08-23_hugo_grenier_mees_rottgering","bid":0.31,"ask":0.4,"mid":0.355,"spread":0.09,"price":0.33,"size":0.0,"side":"BUY"}
{"ts":"2026-08-23T17:53:24.840Z","event_type":"price_change","market_id":"3790394","outcome_index":1,"market_type":"set1","local_side":"away","local_uid":"2026-08-23_hugo_grenier_mees_rottgering","bid":0.6,"ask":0.69,"mid":0.645,"spread":0.09,"price":0.67,"size":0.0,"side":"SELL"}
{"ts":"2026-08-23T17:53:25.092Z","event_type":"last_trade_price","market_id":"3789927","outcome_index":0,"market_type":"match","local_side":"home","local_uid":"2026-08-23_hugo_grenier_mees_rottgering","last_trade":0.29,"trade_size":105.0,"trade_side":"SELL","trade_notional":30.45}
{"ts":"2026-08-23T17:53:25.237Z","event_type":"best_bid_ask","market_id":"3790415","outcome_index":0,"market_type":"set2","local_side":"home","local_uid":"2026-08-23_pierre_hugues_herbert_quinn_vandecasteele","bid":0.63,"ask":0.71,"mid":0.67,"spread":0.08,"bid_size":null,"ask_size":null}
{"ts":"2026-08-23T17:53:25.237Z","event_type":"best_bid_ask","market_id":"3790415","outcome_index":1,"market_type":"set2","local_side":"away","local_uid":"2026-08-23_pierre_hugues_herbert_quinn_vandecasteele","bid":0.29,"ask":0.37,"mid":0.33,"spread":0.08,"bid_size":null,"ask_size":null}
{"ts":"2026-08-23T17:53:25.238Z","event_type":"price_change","market_id":"3790415","outcome_index":1,"market_type":"set2","local_side":"away","local_uid":"2026-08-23_pierre_hugues_herbert_quinn_vandecasteele","bid":0.29,"ask":0.37,"mid":0.33,"spread":0.08,"price":0.3,"size":0.0,"side":"BUY"}
{"ts":"2026-08-23T17:53:25.238Z","event_type":"price_change","market_id":"3790415","outcome_index":0,"market_type":"set2","local_side":"home","local_uid":"2026-08-23_pierre_hugues_herbert_quinn_vandecasteele","bid":0.63,"ask":0.71,"mid":0.67,"spread":0.08,"price":0.7,"size":0.0,"side":"SELL"}
{"ts":"2026-08-23T17:53:25.251Z","event_type":"best_bid_ask","market_id":"3790415","outcome_index":0,"market_type":"set2","local_side":"home","local_uid":"2026-08-23_pierre_hugues_herbert_quinn_vandecasteele","bid":0.63,"ask":0.72,"mid":0.675,"spread":0.09,"bid_size":null,"ask_size":null}
{"ts":"2026-08-23T17:53:25.254Z","event_type":"best_bid_ask","market_id":"3790415","outcome_index":1,"market_type":"set2","local_side":"away","local_uid":"2026-08-23_pierre_hugues_herbert_quinn_vandecasteele","bid":0.28,"ask":0.37,"mid":0.325,"spread":0.09,"bid_size":null,"ask_size":null}
{"ts":"2026-08-23T17:53:25.254Z","event_type":"price_change","market_id":"3790415","outcome_index":1,"market_type":"set2","local_side":"away","local_uid":"2026-08-23_pierre_hugues_herbert_quinn_vandecasteele","bid":0.28,"ask":0.37,"mid":0.325,"spread":0.09,"price":0.29,"size":0.0,"side":"BUY"}
{"ts":"2026-08-23T17:53:25.254Z","event_type":"price_change","market_id":"3790415","outcome_index":0,"market_type":"set2","local_side":"home","local_uid":"2026-08-23_pierre_hugues_herbert_quinn_vandecasteele","bid":0.63,"ask":0.72,"mid":0.675,"spread":0.09,"price":0.71,"size":0.0,"side":"SELL"}
{"ts":"2026-08-23T17:53:25.256Z","event_type":"best_bid_ask","market_id":"3790415","outcome_index":0,"market_type":"set2","local_side":"home","local_uid":"2026-08-23_pierre_hugues_herbert_quinn_vandecasteele","bid":0.63,"ask":0.73,"mid":0.68,"spread":0.1,"bid_size":null,"ask_size":null}
{"ts":"2026-08-23T17:53:25.256Z","event_type":"best_bid_ask","market_id":"3790415","outcome_index":1,"market_type":"set2","local_side":"away","local_uid":"2026-08-23_pierre_hugues_herbert_quinn_vandecasteele","bid":0.27,"ask":0.37,"mid":0.32,"spread":0.1,"bid_size":null,"ask_size":null}
{"ts":"2026-08-23T17:53:25.256Z","event_type":"price_change","market_id":"3790415","outcome_index":1,"market_type":"set2","local_side":"away","local_uid":"2026-08-23_pierre_hugues_herbert_quinn_vandecasteele","bid":0.27,"ask":0.37,"mid":0.32,"spread":0.1,"price":0.28,"size":0.0,"side":"BUY"}
{"ts":"2026-08-23T17:53:25.256Z","event_type":"price_change","market_id":"3790415","outcome_index":0,"market_type":"set2","local_side":"home","local_uid":"2026-08-23_pierre_hugues_herbert_quinn_vandecasteele","bid":0.63,"ask":0.73,"mid":0.68,"spread":0.1,"price":0.72,"size":0.0,"side":"SELL"}
{"ts":"2026-08-23T17:53:25.282Z","event_type":"best_bid_ask","market_id":"3790415","outcome_index":0,"market_type":"set2","local_side":"home","local_uid":"2026-08-23_pierre_hugues_herbert_quinn_vandecasteele","bid":0.63,"ask":0.76,"mid":0.695,"spread":0.13,"bid_size":null,"ask_size":null}
{"ts":"2026-08-23T17:53:25.293Z","event_type":"best_bid_ask","market_id":"3790415","outcome_index":1,"market_type":"set2","local_side":"away","local_uid":"2026-08-23_pierre_hugues_herbert_quinn_vandecasteele","bid":0.24,"ask":0.37,"mid":0.305,"spread":0.13,"bid_size":null,"ask_size":null}
{"ts":"2026-08-23T17:53:25.293Z","event_type":"price_change","market_id":"3790415","outcome_index":1,"market_type":"set2","local_side":"away","local_uid":"2026-08-23_pierre_hugues_herbert_quinn_vandecasteele","bid":0.24,"ask":0.37,"mid":0.305,"spread":0.13,"price":0.27,"size":0.0,"side":"BUY"}
{"ts":"2026-08-23T17:53:25.293Z","event_type":"price_change","market_id":"3790415","outcome_index":0,"market_type":"set2","local_side":"home","local_uid":"2026-08-23_pierre_hugues_herbert_quinn_vandecasteele","bid":0.63,"ask":0.76,"mid":0.695,"spread":0.13,"price":0.73,"size":0.0,"side":"SELL"}
{"ts":"2026-08-23T17:53:25.296Z","event_type":"best_bid_ask","market_id":"3790415","outcome_index":0,"market_type":"set2","local_side":"home","local_uid":"2026-08-23_pierre_hugues_herbert_quinn_vandecasteele","bid":0.63,"ask":0.75,"mid":0.69,"spread":0.12,"bid_size":null,"ask_size":null}
{"ts":"2026-08-23T17:53:25.304Z","event_type":"best_bid_ask","market_id":"3790415","outcome_index":1,"market_type":"set2","local_side":"away","local_uid":"2026-08-23_pierre_hugues_herbert_quinn_vandecasteele","bid":0.25,"ask":0.37,"mid":0.31,"spread":0.12,"bid_size":null,"ask_size":null}
{"ts":"2026-08-23T17:53:25.304Z","event_type":"price_change","market_id":"3790415","outcome_index":1,"market_type":"set2","local_side":"away","local_uid":"2026-08-23_pierre_hugues_herbert_quinn_vandecasteele","bid":0.25,"ask":0.37,"mid":0.31,"spread":0.12,"price":0.25,"size":150.0,"side":"BUY"}
{"ts":"2026-08-23T17:53:25.304Z","event_type":"price_change","market_id":"3790415","outcome_index":0,"market_type":"set2","local_side":"home","local_uid":"2026-08-23_pierre_hugues_herbert_quinn_vandecasteele","bid":0.63,"ask":0.75,"mid":0.69,"spread":0.12,"price":0.75,"size":150.0,"side":"SELL"}
{"ts":"2026-08-23T17:53:25.328Z","event_type":"best_bid_ask","market_id":"3790415","outcome_index":0,"market_type":"set2","local_side":"home","local_uid":"2026-08-23_pierre_hugues_herbert_quinn_vandecasteele","bid":0.59,"ask":0.75,"mid":0.67,"spread":0.16,"bid_size":null,"ask_size":null}
{"ts":"2026-08-23T17:53:25.328Z","event_type":"best_bid_ask","market_id":"3790415","outcome_index":1,"market_type":"set2","local_side":"away","local_uid":"2026-08-23_pierre_hugues_herbert_quinn_vandecasteele","bid":0.25,"ask":0.41,"mid":0.33,"spread":0.16,"bid_size":null,"ask_size":null}
{"ts":"2026-08-23T17:53:25.328Z","event_type":"price_change","market_id":"3790415","outcome_index":0,"market_type":"set2","local_side":"home","local_uid":"2026-08-23_pierre_hugues_herbert_quinn_vandecasteele","bid":0.59,"ask":0.75,"mid":0.67,"spread":0.16,"price":0.63,"size":0.0,"side":"BUY"}
{"ts":"2026-08-23T17:53:25.328Z","event_type":"price_change","market_id":"3790415","outcome_index":1,"market_type":"set2","local_side":"away","local_uid":"2026-08-23_pierre_hugues_herbert_quinn_vandecasteele","bid":0.25,"ask":0.41,"mid":0.33,"spread":0.16,"price":0.37,"size":0.0,"side":"SELL"}
{"ts":"2026-08-23T17:53:25.337Z","event_type":"best_bid_ask","market_id":"3790394","outcome_index":0,"market_type":"set1","local_side":"home","local_uid":"2026-08-23_hugo_grenier_mees_rottgering","bid":0.3,"ask":0.4,"mid":0.35,"spread":0.1,"bid_size":null,"ask_size":null}
{"ts":"2026-08-23T17:53:25.337Z","event_type":"best_bid_ask","market_id":"3790394","outcome_index":1,"market_type":"set1","local_side":"away","local_uid":"2026-08-23_hugo_grenier_mees_rottgering","bid":0.6,"ask":0.7,"mid":0.65,"spread":0.1,"bid_size":null,"ask_size":null}
{"ts":"2026-08-23T17:53:25.337Z","event_type":"price_change","market_id":"3790394","outcome_index":0,"market_type":"set1","local_side":"home","local_uid":"2026-08-23_hugo_grenier_mees_rottgering","bid":0.3,"ask":0.4,"mid":0.35,"spread":0.1,"price":0.31,"size":0.0,"side":"BUY"}
{"ts":"2026-08-23T17:53:25.337Z","event_type":"price_change","market_id":"3790394","outcome_index":1,"market_type":"set1","local_side":"away","local_uid":"2026-08-23_hugo_grenier_mees_rottgering","bid":0.6,"ask":0.7,"mid":0.65,"spread":0.1,"price":0.69,"size":0.0,"side":"SELL"}
{"ts":"2026-08-23T17:53:25.343Z","event_type":"best_bid_ask","market_id":"3790415","outcome_index":0,"market_type":"set2","local_side":"home","local_uid":"2026-08-23_pierre_hugues_herbert_quinn_vandecasteele","bid":0.59,"ask":1.0,"mid":0.795,"spread":0.41,"bid_size":null,"ask_size":null}
{"ts":"2026-08-23T17:53:25.345Z","event_type":"best_bid_ask","market_id":"3790415","outcome_index":1,"market_type":"set2","local_side":"away","local_uid":"2026-08-23_pierre_hugues_herbert_quinn_vandecasteele","bid":0.0,"ask":0.41,"mid":0.205,"spread":0.41,"bid_size":null,"ask_size":null}
{"ts":"2026-08-23T17:53:25.346Z","event_type":"price_change","market_id":"3790415","outcome_index":1,"market_type":"set2","local_side":"away","local_uid":"2026-08-23_pierre_hugues_herbert_quinn_vandecasteele","bid":0.0,"ask":0.41,"mid":0.205,"spread":0.41,"price":0.25,"size":0.0,"side":"BUY"}
{"ts":"2026-08-23T17:53:25.346Z","event_type":"price_change","market_id":"3790415","outcome_index":0,"market_type":"set2","local_side":"home","local_uid":"2026-08-23_pierre_hugues_herbert_quinn_vandecasteele","bid":0.59,"ask":1.0,"mid":0.795,"spread":0.41,"price":0.75,"size":0.0,"side":"SELL"}
{"ts":"2026-08-23T17:53:25.358Z","event_type":"best_bid_ask","market_id":"3790334","outcome_index":0,"market_type":"set2","local_side":"home","local_uid":"2026-08-23_abdullah_shelbayh_dhakshineswar_suresh","bid":0.48,"ask":0.53,"mid":0.505,"spread":0.05,"bid_size":null,"ask_size":null}
{"ts":"2026-08-23T17:53:25.359Z","event_type":"best_bid_ask","market_id":"3790334","outcome_index":1,"market_type":"set2","local_side":"away","local_uid":"2026-08-23_abdullah_shelbayh_dhakshineswar_suresh","bid":0.47,"ask":0.52,"mid":0.495,"spread":0.05,"bid_size":null,"ask_size":null}
{"ts":"2026-08-23T17:53:25.359Z","event_type":"price_change","market_id":"3790334","outcome_index":1,"market_type":"set2","local_side":"away","local_uid":"2026-08-23_abdullah_shelbayh_dhakshineswar_suresh","bid":0.47,"ask":0.52,"mid":0.495,"spread":0.05,"price":0.47,"size":104.35,"side":"BUY"}
{"ts":"2026-08-23T17:53:25.359Z","event_type":"price_change","market_id":"3790334","outcome_index":0,"market_type":"set2","local_side":"home","local_uid":"2026-08-23_abdullah_shelbayh_dhakshineswar_suresh","bid":0.48,"ask":0.53,"mid":0.505,"spread":0.05,"price":0.53,"size":104.35,"side":"SELL"}
{"ts":"2026-08-23T17:53:25.360Z","event_type":"best_bid_ask","market_id":"3790415","outcome_index":0,"market_type":"set2","local_side":"home","local_uid":"2026-08-23_pierre_hugues_herbert_quinn_vandecasteele","bid":0.58,"ask":1.0,"mid":0.79,"spread":0.42,"bid_size":null,"ask_size":null}
{"ts":"2026-08-23T17:53:25.360Z","event_type":"best_bid_ask","market_id":"3790415","outcome_index":1,"market_type":"set2","local_side":"away","local_uid":"2026-08-23_pierre_hugues_herbert_quinn_vandecasteele","bid":0.0,"ask":0.42,"mid":0.21,"spread":0.42,"bid_size":null,"ask_size":null}
{"ts":"2026-08-23T17:53:25.360Z","event_type":"price_change","market_id":"3790415","outcome_index":0,"market_type":"set2","local_side":"home","local_uid":"2026-08-23_pierre_hugues_herbert_quinn_vandecasteele","bid":0.58,"ask":1.0,"mid":0.79,"spread":0.42,"price":0.59,"size":0.0,"side":"BUY"}
{"ts":"2026-08-23T17:53:25.361Z","event_type":"price_change","market_id":"3790415","outcome_index":1,"market_type":"set2","local_side":"away","local_uid":"2026-08-23_pierre_hugues_herbert_quinn_vandecasteele","bid":0.0,"ask":0.42,"mid":0.21,"spread":0.42,"price":0.41,"size":0.0,"side":"SELL"}
{"ts":"2026-08-23T17:53:25.382Z","event_type":"best_bid_ask","market_id":"3790415","outcome_index":0,"market_type":"set2","local_side":"home","local_uid":"2026-08-23_pierre_hugues_herbert_quinn_vandecasteele","bid":0.59,"ask":1.0,"mid":0.795,"spread":0.41,"bid_size":null,"ask_size":null}
{"ts":"2026-08-23T17:53:25.383Z","event_type":"best_bid_ask","market_id":"3790415","outcome_index":1,"market_type":"set2","local_side":"away","local_uid":"2026-08-23_pierre_hugues_herbert_quinn_vandecasteele","bid":0.0,"ask":0.41,"mid":0.205,"spread":0.41,"bid_size":null,"ask_size":null}
{"ts":"2026-08-23T17:53:25.383Z","event_type":"price_change","market_id":"3790415","outcome_index":0,"market_type":"set2","local_side":"home","local_uid":"2026-08-23_pierre_hugues_herbert_quinn_vandecasteele","bid":0.59,"ask":1.0,"mid":0.795,"spread":0.41,"price":0.59,"size":37.39,"side":"BUY"}
{"ts":"2026-08-23T17:53:25.383Z","event_type":"price_change","market_id":"3790415","outcome_index":1,"market_type":"set2","local_side":"away","local_uid":"2026-08-23_pierre_hugues_herbert_quinn_vandecasteele","bid":0.0,"ask":0.41,"mid":0.205,"spread":0.41,"price":0.41,"size":37.39,"side":"SELL"}
{"ts":"2026-08-23T17:53:25.400Z","event_type":"best_bid_ask","market_id":"3790415","outcome_index":0,"market_type":"set2","local_side":"home","local_uid":"2026-08-23_pierre_hugues_herbert_quinn_vandecasteele","bid":0.59,"ask":0.76,"mid":0.675,"spread":0.17,"bid_size":null,"ask_size":null}
{"ts":"2026-08-23T17:53:25.401Z","event_type":"best_bid_ask","market_id":"3790415","outcome_index":1,"market_type":"set2","local_side":"away","local_uid":"2026-08-23_pierre_hugues_herbert_quinn_vandecasteele","bid":0.24,"ask":0.41,"mid":0.325,"spread":0.17,"bid_size":null,"ask_size":null}
{"ts":"2026-08-23T17:53:25.401Z","event_type":"price_change","market_id":"3790415","outcome_index":1,"market_type":"set2","local_side":"away","local_uid":"2026-08-23_pierre_hugues_herbert_quinn_vandecasteele","bid":0.24,"ask":0.41,"mid":0.325,"spread":0.17,"price":0.24,"size":150.0,"side":"BUY"}
{"ts":"2026-08-23T17:53:25.401Z","event_type":"price_change","market_id":"3790415","outcome_index":0,"market_type":"set2","local_side":"home","local_uid":"2026-08-23_pierre_hugues_herbert_quinn_vandecasteele","bid":0.59,"ask":0.76,"mid":0.675,"spread":0.17,"price":0.76,"size":150.0,"side":"SELL"}
{"ts":"2026-08-23T17:53:25.402Z","event_type":"best_bid_ask","market_id":"3790394","outcome_index":0,"market_type":"set1","local_side":"home","local_uid":"2026-08-23_hugo_grenier_mees_rottgering","bid":0.31,"ask":0.4,"mid":0.355,"spread":0.09,"bid_size":null,"ask_size":null}
{"ts":"2026-08-23T17:53:25.402Z","event_type":"best_bid_ask","market_id":"3790394","outcome_index":1,"market_type":"set1","local_side":"away","local_uid":"2026-08-23_hugo_grenier_mees_rottgering","bid":0.6,"ask":0.69,"mid":0.645,"spread":0.09,"bid_size":null,"ask_size":null}
{"ts":"2026-08-23T17:53:25.402Z","event_type":"price_change","market_id":"3790394","outcome_index":0,"market_type":"set1","local_side":"home","local_uid":"2026-08-23_hugo_grenier_mees_rottgering","bid":0.31,"ask":0.4,"mid":0.355,"spread":0.09,"price":0.31,"size":150.0,"side":"BUY"}
{"ts":"2026-08-23T17:53:25.403Z","event_type":"price_change","market_id":"3790394","outcome_index":1,"market_type":"set1","local_side":"away","local_uid":"2026-08-23_hugo_grenier_mees_rottgering","bid":0.6,"ask":0.69,"mid":0.645,"spread":0.09,"price":0.69,"size":150.0,"side":"SELL"}
