{"ts":"2026-08-23T17:52:43.682Z","event_type":"price_change","market_id":"3790334","outcome_index":0,"market_type":"set2","local_side":"home","local_uid":"2026-08-23_abdullah_shelbayh_dhakshineswar_suresh","bid":0.48,"ask":1.0,"mid":0.74,"spread":0.52,"price":0.6,"size":0.0,"side":"SELL"}
{"ts":"2026-08-23T17:52:43.682Z","event_type":"best_bid_ask","market_id":"3790334","outcome_index":0,"market_type":"set2","local_side":"home","local_uid":"2026-08-23_abdullah_shelbayh_dhakshineswar_suresh","bid":0.48,"ask":0.63,"mid":0.555,"spread":0.15,"bid_size":null,"ask_size":null}
{"ts":"2026-08-23T17:52:43.682Z","event_type":"best_bid_ask","market_id":"3790334","outcome_index":1,"market_type":"set2","local_side":"away","local_uid":"2026-08-23_abdullah_shelbayh_dhakshineswar_suresh","bid":0.37,"ask":0.52,"mid":0.445,"spread":0.15,"bid_size":null,"ask_size":null}
{"ts":"2026-08-23T17:52:43.682Z","event_type":"price_change","market_id":"3790334","outcome_index":1,"market_type":"set2","local_side":"away","local_uid":"2026-08-23_abdullah_shelbayh_dhakshineswar_suresh","bid":0.37,"ask":0.52,"mid":0.445,"spread":0.15,"price":0.37,"size":88.0,"side":"BUY"}
{"ts":"2026-08-23T17:52:43.682Z","event_type":"price_change","market_id":"3790334","outcome_index":0,"market_type":"set2","local_side":"home","local_uid":"2026-08-23_abdullah_shelbayh_dhakshineswar_suresh","bid":0.48,"ask":0.63,"mid":0.555,"spread":0.15,"price":0.63,"size":88.0,"side":"SELL"}
{"ts":"2026-08-23T17:52:43.683Z","event_type":"best_bid_ask","market_id":"3790334","outcome_index":0,"market_type":"set2","local_side":"home","local_uid":"2026-08-23_abdullah_shelbayh_dhakshineswar_suresh","bid":0.48,"ask":0.64,"mid":0.56,"spread":0.16,"bid_size":null,"ask_size":null}
{"ts":"2026-08-23T17:52:43.683Z","event_type":"best_bid_ask","market_id":"3790334","outcome_index":1,"market_type":"set2","local_side":"away","local_uid":"2026-08-23_abdullah_shelbayh_dhakshineswar_suresh","bid":0.36,"ask":0.52,"mid":0.44,"spread":0.16,"bid_size":null,"ask_size":null}
{"ts":"2026-08-23T17:52:43.684Z","event_type":"price_change","market_id":"3790334","outcome_index":1,"market_type":"set2","local_side":"away","local_uid":"2026-08-23_abdullah_shelbayh_dhakshineswar_suresh","bid":0.36,"ask":0.52,"mid":0.44,"spread":0.16,"price":0.37,"size":0.0,"side":"BUY"}
{"ts":"2026-08-23T17:52:43.684Z","event_type":"price_change","market_id":"3790334","outcome_index":0,"market_type":"set2","local_side":"home","local_uid":"2026-08-23_abdullah_shelbayh_dhakshineswar_suresh","bid":0.48,"ask":0.64,"mid":0.56,"spread":0.16,"price":0.63,"size":0.0,"side":"SELL"}
{"ts":"2026-08-23T17:52:43.743Z","event_type":"best_bid_ask","market_id":"3790334","outcome_index":0,"market_type":"set2","local_side":"home","local_uid":"2026-08-23_abdullah_shelbayh_dhakshineswar_suresh","bid":0.48,"ask":0.63,"mid":0.555,"spread":0.15,"bid_size":null,"ask_size":null}
{"ts":"2026-08-23T17:52:43.743Z","event_type":"best_bid_ask","market_id":"3790334","outcome_index":1,"market_type":"set2","local_side":"away","local_uid":"2026-08-23_abdullah_shelbayh_dhakshineswar_suresh","bid":0.37,"ask":0.52,"mid":0.445,"spread":0.15,"bid_size":null,"ask_size":null}
{"ts":"2026-08-23T17:52:43.743Z","event_type":"price_change","market_id":"3790334","outcome_index":1,"market_type":"set2","local_side":"away","local_uid":"2026-08-23_abdullah_shelbayh_dhakshineswar_suresh","bid":0.37,"ask":0.52,"mid":0.445,"spread":0.15,"price":0.37,"size":88.0,"side":"BUY"}
{"ts":"2026-08-23T17:52:43.743Z","event_type":"price_change","market_id":"3790334","outcome_index":0,"market_type":"set2","local_side":"home","local_uid":"2026-08-23_abdullah_shelbayh_dhakshineswar_suresh","bid":0.48,"ask":0.63,"mid":0.555,"spread":0.15,"price":0.63,"size":88.0,"side":"SELL"}
{"ts":"2026-08-23T17:52:43.788Z","event_type":"best_bid_ask","market_id":"3790334","outcome_index":0,"market_type":"set2","local_side":"home","local_uid":"2026-08-23_abdullah_shelbayh_dhakshineswar_suresh","bid":0.48,"ask":0.66,"mid":0.57,"spread":0.18,"bid_size":null,"ask_size":null}
{"ts":"2026-08-23T17:52:43.788Z","event_type":"best_bid_ask","market_id":"3790334","outcome_index":1,"market_type":"set2","local_side":"away","local_uid":"2026-08-23_abdullah_shelbayh_dhakshineswar_suresh","bid":0.34,"ask":0.52,"mid":0.43,"spread":0.18,"bid_size":null,"ask_size":null}
{"ts":"2026-08-23T17:52:43.788Z","event_type":"price_change","market_id":"3790334","outcome_index":1,"market_type":"set2","local_side":"away","local_uid":"2026-08-23_abdullah_shelbayh_dhakshineswar_suresh","bid":0.34,"ask":0.52,"mid":0.43,"spread":0.18,"price":0.37,"size":0.0,"side":"BUY"}
{"ts":"2026-08-23T17:52:43.788Z","event_type":"price_change","market_id":"3790334","outcome_index":0,"market_type":"set2","local_side":"home","local_uid":"2026-08-23_abdullah_shelbayh_dhakshineswar_suresh","bid":0.48,"ask":0.66,"mid":0.57,"spread":0.18,"price":0.63,"size":0.0,"side":"SELL"}
{"ts":"2026-08-23T17:52:43.788Z","event_type":"best_bid_ask","market_id":"3790334","outcome_index":0,"market_type":"set2","local_side":"home","local_uid":"2026-08-23_abdullah_shelbayh_dhakshineswar_suresh","bid":0.48,"ask":0.65,"mid":0.565,"spread":0.17,"bid_size":null,"ask_size":null}
{"ts":"2026-08-23T17:52:43.788Z","event_type":"best_bid_ask","market_id":"3790334","outcome_index":1,"market_type":"set2","local_side":"away","local_uid":"2026-08-23_abdullah_shelbayh_dhakshineswar_suresh","bid":0.35,"ask":0.52,"mid":0.435,"spread":0.17,"bid_size":null,"ask_size":null}
{"ts":"2026-08-23T17:52:43.789Z","event_type":"price_change","market_id":"3790334","outcome_index":1,"market_type":"set2","local_side":"away","local_uid":"2026-08-23_abdullah_shelbayh_dhakshineswar_suresh","bid":0.35,"ask":0.52,"mid":0.435,"spread":0.17,"price":0.35,"size":88.0,"side":"BUY"}
{"ts":"2026-08-23T17:52:43.789Z","event_type":"price_change","market_id":"3790334","outcome_index":0,"market_type":"set2","local_side":"home","local_uid":"2026-08-23_abdullah_shelbayh_dhakshineswar_suresh","bid":0.48,"ask":0.65,"mid":0.565,"spread":0.17,"price":0.65,"size":88.0,"side":"SELL"}
{"ts":"2026-08-23T17:52:43.789Z","event_type":"new_market","market_id":"0x41518da3330476664a54f6391cc8cc0c4634fbc0dc08caec7e4cf5ffca82a4e3"}
{"ts":"2026-08-23T17:52:43.789Z","event_type":"new_market","market_id":"0x746334944b5e3425db9759ca20010384209d1125bc07997f6565a88d7d6dc50a"}
{"ts":"2026-08-23T17:52:43.790Z","event_type":"new_market","market_id":"0xff7cc9270e038ca5ac5d1bd11c87df8db90498a14a067daf15f74e782c4e9501"}
{"ts":"2026-08-23T17:52:43.790Z","event_type":"new_market","market_id":"0x7b211a62bbd8dd43097c272616d33fad4bf859fc7be6420c42f14aa520552620"}
{"ts":"2026-08-23T17:52:43.849Z","event_type":"new_market","market_id":"0x67f6ef6cf3fd91c36c7960fc9d007ba4464e095678c1f4fbcf43d1d0a6e9956e"}
{"ts":"2026-08-23T17:52:43.851Z","event_type":"new_market","market_id":"0xf37d7004d410dfad16e30d58c1511fe4934764054031e566019f5474ca8ea753"}
{"ts":"2026-08-23T17:52:43.891Z","event_type":"new_market","market_id":"0x7e6680687a29c1d01cd802727534ee1142dafccead6281e62317c76c7cb93cec"}
{"ts":"2026-08-23T17:52:43.893Z","event_type":"new_market","market_id":"0x65cf761a1678aae41e758fd816c04515ca7ab5df5944c95d5d2239b72989b6d5"}
{"ts":"2026-08-23T17:52:43.894Z","event_type":"new_market","market_id":"0x10ebc1192553c5bbb31ac758d38ebb269595ac869f4f5ddaf8c6f73ca36b3d36"}
{"ts":"2026-08-23T17:52:43.894Z","event_type":"best_bid_ask","market_id":"3790334","outcome_index":0,"market_type":"set2","local_side":"home","local_uid":"2026-08-23_abdullah_shelbayh_dhakshineswar_suresh","bid":0.48,"ask":0.64,"mid":0.56,"spread":0.16,"bid_size":null,"ask_size":null}
{"ts":"2026-08-23T17:52:43.894Z","event_type":"best_bid_ask","market_id":"3790334","outcome_index":1,"market_type":"set2","local_side":"away","local_uid":"2026-08-23_abdullah_shelbayh_dhakshineswar_suresh","bid":0.36,"ask":0.52,"mid":0.44,"spread":0.16,"bid_size":null,"ask_size":null}
{"ts":"2026-08-23T17:52:43.894Z","event_type":"price_change","market_id":"3790334","outcome_index":1,"market_type":"set2","local_side":"away","local_uid":"2026-08-23_abdullah_shelbayh_dhakshineswar_suresh","bid":0.36,"ask":0.52,"mid":0.44,"spread":0.16,"price":0.36,"size":423.0,"side":"BUY"}
{"ts":"2026-08-23T17:52:43.894Z","event_type":"price_change","market_id":"3790334","outcome_index":0,"market_type":"set2","local_side":"home","local_uid":"2026-08-23_abdullah_shelbayh_dhakshineswar_suresh","bid":0.48,"ask":0.64,"mid":0.56,"spread":0.16,"price":0.64,"size":423.0,"side":"SELL"}
{"ts":"2026-08-23T17:52:43.894Z","event_type":"best_bid_ask","market_id":"3790334","outcome_index":0,"market_type":"set2","local_side":"home","local_uid":"2026-08-23_abdullah_shelbayh_dhakshineswar_suresh","bid":0.48,"ask":0.62,"mid":0.55,"spread":0.14,"bid_size":null,"ask_size":null}
{"ts":"2026-08-23T17:52:43.894Z","event_type":"best_bid_ask","market_id":"3790334","outcome_index":1,"market_type":"set2","local_side":"away","local_uid":"2026-08-23_abdullah_shelbayh_dhakshineswar_suresh","bid":0.38,"ask":0.52,"mid":0.45,"spread":0.14,"bid_size":null,"ask_size":null}
{"ts":"2026-08-23T17:52:43.895Z","event_type":"price_change","market_id":"3790334","outcome_index":1,"market_type":"set2","local_side":"away","local_uid":"2026-08-23_abdullah_shelbayh_dhakshineswar_suresh","bid":0.38,"ask":0.52,"mid":0.45,"spread":0.14,"price":0.38,"size":44.0,"side":"BUY"}
{"ts":"2026-08-23T17:52:43.895Z","event_type":"price_change","market_id":"3790334","outcome_index":0,"market_type":"set2","local_side":"home","local_uid":"2026-08-23_abdullah_shelbayh_dhakshineswar_suresh","bid":0.48,"ask":0.62,"mid":0.55,"spread":0.14,"price":0.62,"size":44.0,"side":"SELL"}
{"ts":"2026-08-23T17:52:43.896Z","event_type":"price_change","market_id":"3790345","outcome_index":1,"market_type":"set1","local_side":"away","local_uid":"2026-08-23_stefanos_sakellaridis_luca_van_assche","bid":0.999,"ask":1.0,"mid":0.9995,"spread":0.001,"price":0.013,"size":10560.0,"side":"BUY"}
{"ts":"2026-08-23T17:52:43.896Z","event_type":"price_change","market_id":"3790345","outcome_index":0,"market_type":"set1","local_side":"home","local_uid":"2026-08-23_stefanos_sakellaridis_luca_van_assche","bid":0.0,"ask":0.001,"mid":0.0005,"spread":0.001,"price":0.987,"size":10560.0,"side":"SELL"}
{"ts":"2026-08-23T17:52:43.957Z","event_type":"best_bid_ask","market_id":"3790334","outcome_index":0,"market_type":"set2","local_side":"home","local_uid":"2026-08-23_abdullah_shelbayh_dhakshineswar_suresh","bid":0.48,"ask":1.0,"mid":0.74,"spread":0.52,"bid_size":null,"ask_size":null}
{"ts":"2026-08-23T17:52:43.957Z","event_type":"best_bid_ask","market_id":"3790334","outcome_index":1,"market_type":"set2","local_side":"away","local_uid":"2026-08-23_abdullah_shelbayh_dhakshineswar_suresh","bid":0.0,"ask":0.52,"mid":0.26,"spread":0.52,"bid_size":null,"ask_size":null}
{"ts":"2026-08-23T17:52:43.957Z","event_type":"price_change","market_id":"3790334","outcome_index":1,"market_type":"set2","local_side":"away","local_uid":"2026-08-23_abdullah_shelbayh_dhakshineswar_suresh","bid":0.0,"ask":0.52,"mid":0.26,"spread":0.52,"price":0.38,"size":0.0,"side":"BUY"}
{"ts":"2026-08-23T17:52:43.957Z","event_type":"price_change","market_id":"3790334","outcome_index":0,"market_type":"set2","local_side":"home","local_uid":"2026-08-23_abdullah_shelbayh_dhakshineswar_suresh","bid":0.48,"ask":1.0,"mid":0.74,"spread":0.52,"price":0.62,"size":0.0,"side":"SELL"}
{"ts":"2026-08-23T17:52:44.000Z","event_type":"best_bid_ask","market_id":"3790334","outcome_index":0,"market_type":"set2","local_side":"home","local_uid":"2026-08-23_abdullah_shelbayh_dhakshineswar_suresh","bid":0.48,"ask":0.62,"mid":0.55,"spread":0.14,"bid_size":null,"ask_size":null}
{"ts":"2026-08-23T17:52:44.000Z","event_type":"best_bid_ask","market_id":"3790334","outcome_index":1,"market_type":"set2","local_side":"away","local_uid":"2026-08-23_abdullah_shelbayh_dhakshineswar_suresh","bid":0.38,"ask":0.52,"mid":0.45,"spread":0.14,"bid_size":null,"ask_size":null}
{"ts":"2026-08-23T17:52:44.001Z","event_type":"price_change","market_id":"3790334","outcome_index":1,"market_type":"set2","local_side":"away","local_uid":"2026-08-23_abdullah_shelbayh_dhakshineswar_suresh","bid":0.38,"ask":0.52,"mid":0.45,"spread":0.14,"price":0.38,"size":44.0,"side":"BUY"}
{"ts":"2026-08-23T17:52:44.001Z","event_type":"price_change","market_id":"3790334","outcome_index":0,"market_type":"set2","local_side":"home","local_uid":"2026-08-23_abdullah_shelbayh_dhakshineswar_suresh","bid":0.48,"ask":0.62,"mid":0.55,"spread":0.14,"price":0.62,"size":44.0,"side":"SELL"}
{"ts":"2026-08-23T17:52:44.002Z","event_type":"best_bid_ask","market_id":"3790334","outcome_index":0,"market_type":"set2","local_side":"home","local_uid":"2026-08-23_abdullah_shelbayh_dhakshineswar_suresh","bid":0.48,"ask":1.0,"mid":0.74,"spread":0.52,"bid_size":null,"ask_size":null}
{"ts":"2026-08-23T17:52:44.002Z","event_type":"best_bid_ask","market_id":"3790334","outcome_index":1,"market_type":"set2","local_side":"away","local_uid":"2026-08-23_abdullah_shelbayh_dhakshineswar_suresh","bid":0.0,"ask":0.52,"mid":0.26,"spread":0.52,"bid_size":null,"ask_size":null}
{"ts":"2026-08-23T17:52:44.002Z","event_type":"price_change","market_id":"3790334","outcome_index":1,"market_type":"set2","local_side":"away","local_uid":"2026-08-23_abdullah_shelbayh_dhakshineswar_suresh","bid":0.0,"ask":0.52,"mid":0.26,"spread":0.52,"price":0.38,"size":0.0,"side":"BUY"}
{"ts":"2026-08-23T17:52:44.002Z","event_type":"price_change","market_id":"3790334","outcome_index":0,"market_type":"set2","local_side":"home","local_uid":"2026-08-23_abdullah_shelbayh_dhakshineswar_suresh","bid":0.48,"ask":1.0,"mid":0.74,"spread":0.52,"price":0.62,"size":0.0,"side":"SELL"}
{"ts":"2026-08-23T17:52:44.002Z","event_type":"best_bid_ask","market_id":"3790334","outcome_index":0,"market_type":"set2","local_side":"home","local_uid":"2026-08-23_abdullah_shelbayh_dhakshineswar_suresh","bid":0.48,"ask":0.65,"mid":0.565,"spread":0.17,"bid_size":null,"ask_size":null}
{"ts":"2026-08-23T17:52:44.002Z","event_type":"best_bid_ask","market_id":"3790334","outcome_index":1,"market_type":"set2","local_side":"away","local_uid":"2026-08-23_abdullah_shelbayh_dhakshineswar_suresh","bid":0.35,"ask":0.52,"mid":0.435,"spread":0.17,"bid_size":null,"ask_size":null}
{"ts":"2026-08-23T17:52:44.002Z","event_type":"price_change","market_id":"3790334","outcome_index":1,"market_type":"set2","local_side":"away","local_uid":"2026-08-23_abdullah_shelbayh_dhakshineswar_suresh","bid":0.35,"ask":0.52,"mid":0.435,"spread":0.17,"price":0.35,"size":88.0,"side":"BUY"}
{"ts":"2026-08-23T17:52:44.002Z","event_type":"price_change","market_id":"3790334","outcome_index":0,"market_type":"set2","local_side":"home","local_uid":"2026-08-23_abdullah_shelbayh_dhakshineswar_suresh","bid":0.48,"ask":0.65,"mid":0.565,"spread":0.17,"price":0.65,"size":88.0,"side":"SELL"}
{"ts":"2026-08-23T17:52:44.062Z","event_type":"best_bid_ask","market_id":"3790334","outcome_index":0,"market_type":"set2","local_side":"home","local_uid":"2026-08-23_abdullah_shelbayh_dhakshineswar_suresh","bid":0.48,"ask":1.0,"mid":0.74,"spread":0.52,"bid_size":null,"ask_size":null}
{"ts":"2026-08-23T17:52:44.062Z","event_type":"best_bid_ask","market_id":"3790334","outcome_index":1,"market_type":"set2","local_side":"away","local_uid":"2026-08-23_abdullah_shelbayh_dhakshineswar_suresh","bid":0.0,"ask":0.52,"mid":0.26,"spread":0.52,"bid_size":null,"ask_size":null}
{"ts":"2026-08-23T17:52:44.062Z","event_type":"price_change","market_id":"3790334","outcome_index":1,"market_type":"set2","local_side":"away","local_uid":"2026-08-23_abdullah_shelbayh_dhakshineswar_suresh","bid":0.0,"ask":0.52,"mid":0.26,"spread":0.52,"price":0.35,"size":0.0,"side":"BUY"}
{"ts":"2026-08-23T17:52:44.063Z","event_type":"price_change","market_id":"3790334","outcome_index":0,"market_type":"set2","local_side":"home","local_uid":"2026-08-23_abdullah_shelbayh_dhakshineswar_suresh","bid":0.48,"ask":1.0,"mid":0.74,"spread":0.52,"price":0.65,"size":0.0,"side":"SELL"}
{"ts":"2026-08-23T17:52:44.063Z","event_type":"best_bid_ask","market_id":"3790334","outcome_index":0,"market_type":"set2","local_side":"home","local_uid":"2026-08-23_abdullah_shelbayh_dhakshineswar_suresh","bid":0.48,"ask":0.63,"mid":0.555,"spread":0.15,"bid_size":null,"ask_size":null}
{"ts":"2026-08-23T17:52:44.063Z","event_type":"best_bid_ask","market_id":"3790334","outcome_index":1,"market_type":"set2","local_side":"away","local_uid":"2026-08-23_abdullah_shelbayh_dhakshineswar_suresh","bid":0.37,"ask":0.52,"mid":0.445,"spread":0.15,"bid_size":null,"ask_size":null}
{"ts":"2026-08-23T17:52:44.063Z","event_type":"price_change","market_id":"3790334","outcome_index":1,"market_type":"set2","local_side":"away","local_uid":"2026-08-23_abdullah_shelbayh_dhakshineswar_suresh","bid":0.37,"ask":0.52,"mid":0.445,"spread":0.15,"price":0.37,"size":88.0,"side":"BUY"}
{"ts":"2026-08-23T17:52:44.063Z","event_type":"price_change","market_id":"3790334","outcome_index":0,"market_type":"set2","local_side":"home","local_uid":"2026-08-23_abdullah_shelbayh_dhakshineswar_suresh","bid":0.48,"ask":0.63,"mid":0.555,"spread":0.15,"price":0.63,"size":88.0,"side":"SELL"}
{"ts":"2026-08-23T17:52:44.215Z","event_type":"best_bid_ask","market_id":"3790334","outcome_index":0,"market_type":"set2","local_side":"home","local_uid":"2026-08-23_abdullah_shelbayh_dhakshineswar_suresh","bid":0.48,"ask":1.0,"mid":0.74,"spread":0.52,"bid_size":null,"ask_size":null}
{"ts":"2026-08-23T17:52:44.216Z","event_type":"best_bid_ask","market_id":"3790334","outcome_index":1,"market_type":"set2","local_side":"away","local_uid":"2026-08-23_abdullah_shelbayh_dhakshineswar_suresh","bid":0.0,"ask":0.52,"mid":0.26,"spread":0.52,"bid_size":null,"ask_size":null}
{"ts":"2026-08-23T17:52:44.216Z","event_type":"price_change","market_id":"3790334","outcome_index":1,"market_type":"set2","local_side":"away","local_uid":"2026-08-23_abdullah_shelbayh_dhakshineswar_suresh","bid":0.0,"ask":0.52,"mid":0.26,"spread":0.52,"price":0.37,"size":0.0,"side":"BUY"}
{"ts":"2026-08-23T17:52:44.216Z","event_type":"price_change","market_id":"3790334","outcome_index":0,"market_type":"set2","local_side":"home","local_uid":"2026-08-23_abdullah_shelbayh_dhakshineswar_suresh","bid":0.48,"ask":1.0,"mid":0.74,"spread":0.52,"price":0.63,"size":0.0,"side":"SELL"}
{"ts":"2026-08-23T17:52:44.216Z","event_type":"best_bid_ask","market_id":"3790334","outcome_index":0,"market_type":"set2","local_side":"home","local_uid":"2026-08-23_abdullah_shelbayh_dhakshineswar_suresh","bid":0.48,"ask":0.62,"mid":0.55,"spread":0.14,"bid_size":null,"ask_size":null}
{"ts":"2026-08-23T17:52:44.216Z","event_type":"best_bid_ask","market_id":"3790334","outcome_index":1,"market_type":"set2","local_side":"away","local_uid":"2026-08-23_abdullah_shelbayh_dhakshineswar_suresh","bid":0.38,"ask":0.52,"mid":0.45,"spread":0.14,"bid_size":null,"ask_size":null}
{"ts":"2026-08-23T17:52:44.216Z","event_type":"price_change","market_id":"3790334","outcome_index":1,"market_type":"set2","local_side":"away","local_uid":"2026-08-23_abdullah_shelbayh_dhakshineswar_suresh","bid":0.38,"ask":0.52,"mid":0.45,"spread":0.14,"price":0.38,"size":44.0,"side":"BUY"}
{"ts":"2026-08-23T17:52:44.216Z","event_type":"price_change","market_id":"3790334","outcome_index":0,"market_type":"set2","local_side":"home","local_uid":"2026-08-23_abdullah_shelbayh_dhakshineswar_suresh","bid":0.48,"ask":0.62,"mid":0.55,"spread":0.14,"price":0.62,"size":44.0,"side":"SELL"}
{"ts":"2026-08-23T17:52:44.275Z","event_type":"best_bid_ask","market_id":"3789997","outcome_index":0,"market_type":"match","local_side":"home","local_uid":"2026-08-23_oscar_weightman_alec_deckers","bid":0.09,"ask":0.1,"mid":0.095,"spread":0.01,"bid_size":null,"ask_size":null}
{"ts":"2026-08-23T17:52:44.275Z","event_type":"best_bid_ask","market_id":"3789997","outcome_index":1,"market_type":"match","local_side":"away","local_uid":"2026-08-23_oscar_weightman_alec_deckers","bid":0.9,"ask":0.91,"mid":0.905,"spread":0.01,"bid_size":null,"ask_size":null}
{"ts":"2026-08-23T17:52:44.315Z","event_type":"price_change","market_id":"3789997","outcome_index":1,"market_type":"match","local_side":"away","local_uid":"2026-08-23_oscar_weightman_alec_deckers","bid":0.9,"ask":0.91,"mid":0.905,"spread":0.01,"price":0.9,"size":100.0,"side":"BUY"}
{"ts":"2026-08-23T17:52:44.315Z","event_type":"price_change","market_id":"3789997","outcome_index":0,"market_type":"match","local_side":"home","local_uid":"2026-08-23_oscar_weightman_alec_deckers","bid":0.09,"ask":0.1,"mid":0.095,"spread":0.01,"price":0.1,"size":100.0,"side":"SELL"}
{"ts":"2026-08-23T17:52:44.322Z","event_type":"best_bid_ask","market_id":"3790334","outcome_index":0,"market_type":"set2","local_side":"home","local_uid":"2026-08-23_abdullah_shelbayh_dhakshineswar_suresh","bid":0.48,"ask":0.66,"mid":0.57,"spread":0.18,"bid_size":null,"ask_size":null}
{"ts":"2026-08-23T17:52:44.322Z","event_type":"best_bid_ask","market_id":"3790334","outcome_index":1,"market_type":"set2","local_side":"away","local_uid":"2026-08-23_abdullah_shelbayh_dhakshineswar_suresh","bid":0.34,"ask":0.52,"mid":0.43,"spread":0.18,"bid_size":null,"ask_size":null}
{"ts":"2026-08-23T17:52:44.322Z","event_type":"price_change","market_id":"3790334","outcome_index":1,"market_type":"set2","local_side":"away","local_uid":"2026-08-23_abdullah_shelbayh_dhakshineswar_suresh","bid":0.34,"ask":0.52,"mid":0.43,"spread":0.18,"price":0.38,"size":0.0,"side":"BUY"}
{"ts":"2026-08-23T17:52:44.322Z","event_type":"price_change","market_id":"3790334","outcome_index":0,"market_type":"set2","local_side":"home","local_uid":"2026-08-23_abdullah_shelbayh_dhakshineswar_suresh","bid":0.48,"ask":0.66,"mid":0.57,"spread":0.18,"price":0.62,"size":0.0,"side":"SELL"}
{"ts":"2026-08-23T17:52:44.322Z","event_type":"best_bid_ask","market_id":"3790334","outcome_index":0,"market_type":"set2","local_side":"home","local_uid":"2026-08-23_abdullah_shelbayh_dhakshineswar_suresh","bid":0.48,"ask":0.65,"mid":0.565,"spread":0.17,"bid_size":null,"ask_size":null}
{"ts":"2026-08-23T17:52:44.322Z","event_type":"best_bid_ask","market_id":"3790334","outcome_index":1,"market_type":"set2","local_side":"away","local_uid":"2026-08-23_abdullah_shelbayh_dhakshineswar_suresh","bid":0.35,"ask":0.52,"mid":0.435,"spread":0.17,"bid_size":null,"ask_size":null}
{"ts":"2026-08-23T17:52:44.322Z","event_type":"price_change","market_id":"3790334","outcome_index":1,"market_type":"set2","local_side":"away","local_uid":"2026-08-23_abdullah_shelbayh_dhakshineswar_suresh","bid":0.35,"ask":0.52,"mid":0.435,"spread":0.17,"price":0.35,"size":88.0,"side":"BUY"}
{"ts":"2026-08-23T17:52:44.322Z","event_type":"price_change","market_id":"3790334","outcome_index":0,"market_type":"set2","local_side":"home","local_uid":"2026-08-23_abdullah_shelbayh_dhakshineswar_suresh","bid":0.48,"ask":0.65,"mid":0.565,"spread":0.17,"price":0.65,"size":88.0,"side":"SELL"}
{"ts":"2026-08-23T17:52:44.425Z","event_type":"price_change","market_id":"3792975","outcome_index":1,"market_type":"match","local_side":"away","local_uid":"2026-08-23_coco_gauff_jessica_pegula","bid":0.41,"ask":0.42,"mid":0.415,"spread":0.01,"price":0.36,"size":2489.8,"side":"BUY"}
{"ts":"2026-08-23T17:52:44.425Z","event_type":"price_change","market_id":"3792975","outcome_index":0,"market_type":"match","local_side":"home","local_uid":"2026-08-23_coco_gauff_jessica_pegula","bid":0.58,"ask":0.59,"mid":0.585,"spread":0.01,"price":0.64,"size":2489.8,"side":"SELL"}
{"ts":"2026-08-23T17:52:44.425Z","event_type":"best_bid_ask","market_id":"3790334","outcome_index":0,"market_type":"set2","local_side":"home","local_uid":"2026-08-23_abdullah_shelbayh_dhakshineswar_suresh","bid":0.48,"ask":0.63,"mid":0.555,"spread":0.15,"bid_size":null,"ask_size":null}
{"ts":"2026-08-23T17:52:44.425Z","event_type":"best_bid_ask","market_id":"3790334","outcome_index":1,"market_type":"set2","local_side":"away","local_uid":"2026-08-23_abdullah_shelbayh_dhakshineswar_suresh","bid":0.37,"ask":0.52,"mid":0.445,"spread":0.15,"bid_size":null,"ask_size":null}
{"ts":"2026-08-23T17:52:44.425Z","event_type":"price_change","market_id":"3790334","outcome_index":1,"market_type":"set2","local_side":"away","local_uid":"2026-08-23_abdullah_shelbayh_dhakshineswar_suresh","bid":0.37,"ask":0.52,"mid":0.445,"spread":0.15,"price":0.37,"size":88.0,"side":"BUY"}
{"ts":"2026-08-23T17:52:44.425Z","event_type":"price_change","market_id":"3790334","outcome_index":0,"market_type":"set2","local_side":"home","local_uid":"2026-08-23_abdullah_shelbayh_dhakshineswar_suresh","bid":0.48,"ask":0.63,"mid":0.555,"spread":0.15,"price":0.63,"size":88.0,"side":"SELL"}
{"ts":"2026-08-23T17:52:44.427Z","event_type":"best_bid_ask","market_id":"3790334","outcome_index":0,"market_type":"set2","local_side":"home","local_uid":"2026-08-23_abdullah_shelbayh_dhakshineswar_suresh","bid":0.48,"ask":1.0,"mid":0.74,"spread":0.52,"bid_size":null,"ask_size":null}
{"ts":"2026-08-23T17:52:44.427Z","event_type":"best_bid_ask","market_id":"3790334","outcome_index":1,"market_type":"set2","local_side":"away","local_uid":"2026-08-23_abdullah_shelbayh_dhakshineswar_suresh","bid":0.0,"ask":0.52,"mid":0.26,"spread":0.52,"bid_size":null,"ask_size":null}
{"ts":"2026-08-23T17:52:44.427Z","event_type":"price_change","market_id":"3790334","outcome_index":1,"market_type":"set2","local_side":"away","local_uid":"2026-08-23_abdullah_shelbayh_dhakshineswar_suresh","bid":0.0,"ask":0.52,"mid":0.26,"spread":0.52,"price":0.37,"size":0.0,"side":"BUY"}
{"ts":"2026-08-23T17:52:44.427Z","event_type":"price_change","market_id":"3790334","outcome_index":0,"market_type":"set2","local_side":"home","local_uid":"2026-08-23_abdullah_shelbayh_dhakshineswar_suresh","bid":0.48,"ask":1.0,"mid":0.74,"spread":0.52,"price":0.63,"size":0.0,"side":"SELL"}
{"ts":"2026-08-23T17:52:44.427Z","event_type":"best_bid_ask","market_id":"3790334","outcome_index":0,"market_type":"set2","local_side":"home","local_uid":"2026-08-23_abdullah_shelbayh_dhakshineswar_suresh","bid":0.48,"ask":0.62,"mid":0.55,"spread":0.14,"bid_size":null,"ask_size":null}
{"ts":"2026-08-23T17:52:44.427Z","event_type":"best_bid_ask","market_id":"3790334","outcome_index":1,"market_type":"set2","local_side":"away","local_uid":"2026-08-23_abdullah_shelbayh_dhakshineswar_suresh","bid":0.38,"ask":0.52,"mid":0.45,"spread":0.14,"bid_size":null,"ask_size":null}
{"ts":"2026-08-23T17:52:44.427Z","event_type":"price_change","market_id":"3790334","outcome_index":1,"market_type":"set2","local_side":"away","local_uid":"2026-08-23_abdullah_shelbayh_dhakshineswar_suresh","bid":0.38,"ask":0.52,"mid":0.45,"spread":0.14,"price":0.38,"size":44.0,"side":"BUY"}
{"ts":"2026-08-23T17:52:44.427Z","event_type":"price_change","market_id":"3790334","outcome_index":0,"market_type":"set2","local_side":"home","local_uid":"2026-08-23_abdullah_shelbayh_dhakshineswar_suresh","bid":0.48,"ask":0.62,"mid":0.55,"spread":0.14,"price":0.62,"size":44.0,"side":"SELL"}
{"ts":"2026-08-23T17:52:44.428Z","event_type":"best_bid_ask","market_id":"3790334","outcome_index":0,"market_type":"set2","local_side":"home","local_uid":"2026-08-23_abdullah_shelbayh_dhakshineswar_suresh","bid":0.48,"ask":0.66,"mid":0.57,"spread":0.18,"bid_size":null,"ask_size":null}
{"ts":"2026-08-23T17:52:44.428Z","event_type":"best_bid_ask","market_id":"3790334","outcome_index":1,"market_type":"set2","local_side":"away","local_uid":"2026-08-23_abdullah_shelbayh_dhakshineswar_suresh","bid":0.34,"ask":0.52,"mid":0.43,"spread":0.18,"bid_size":null,"ask_size":null}
{"ts":"2026-08-23T17:52:44.428Z","event_type":"price_change","market_id":"3790334","outcome_index":1,"market_type":"set2","local_side":"away","local_uid":"2026-08-23_abdullah_shelbayh_dhakshineswar_suresh","bid":0.34,"ask":0.52,"mid":0.43,"spread":0.18,"price":0.38,"size":0.0,"side":"BUY"}
{"ts":"2026-08-23T17:52:44.428Z","event_type":"price_change","market_id":"3790334","outcome_index":0,"market_type":"set2","local_side":"home","local_uid":"2026-08-23_abdullah_shelbayh_dhakshineswar_suresh","bid":0.48,"ask":0.66,"mid":0.57,"spread":0.18,"price":0.62,"size":0.0,"side":"SELL"}
{"ts":"2026-08-23T17:52:44.429Z","event_type":"best_bid_ask","market_id":"3790334","outcome_index":0,"market_type":"set2","local_side":"home","local_uid":"2026-08-23_abdullah_shelbayh_dhakshineswar_suresh","bid":0.48,"ask":0.65,"mid":0.565,"spread":0.17,"bid_size":null,"ask_size":null}
{"ts":"2026-08-23T17:52:44.429Z","event_type":"best_bid_ask","market_id":"3790334","outcome_index":1,"market_type":"set2","local_side":"away","local_uid":"2026-08-23_abdullah_shelbayh_dhakshineswar_suresh","bid":0.35,"ask":0.52,"mid":0.435,"spread":0.17,"bid_size":null,"ask_size":null}
{"ts":"2026-08-23T17:52:44.486Z","event_type":"price_change","market_id":"3790334","outcome_index":1,"market_type":"set2","local_side":"away","local_uid":"2026-08-23_abdullah_shelbayh_dhakshineswar_suresh","bid":0.35,"ask":0.52,"mid":0.435,"spread":0.17,"price":0.35,"size":88.0,"side":"BUY"}
{"ts":"2026-08-23T17:52:44.487Z","event_type":"price_change","market_id":"3790334","outcome_index":0,"market_type":"set2","local_side":"home","local_uid":"2026-08-23_abdullah_shelbayh_dhakshineswar_suresh","bid":0.48,"ask":0.65,"mid":0.565,"spread":0.17,"price":0.65,"size":88.0,"side":"SELL"}
{"ts":"2026-08-23T17:52:44.488Z","event_type":"best_bid_ask","market_id":"3790334","outcome_index":0,"market_type":"set2","local_side":"home","local_uid":"2026-08-23_abdullah_shelbayh_dhakshineswar_suresh","bid":0.48,"ask":0.63,"mid":0.555,"spread":0.15,"bid_size":null,"ask_size":null}
{"ts":"2026-08-23T17:52:44.488Z","event_type":"best_bid_ask","market_id":"3790334","outcome_index":1,"market_type":"set2","local_side":"away","local_uid":"2026-08-23_abdullah_shelbayh_dhakshineswar_suresh","bid":0.37,"ask":0.52,"mid":0.445,"spread":0.15,"bid_size":null,"ask_size":null}
{"ts":"2026-08-23T17:52:44.488Z","event_type":"price_change","market_id":"3790334","outcome_index":1,"market_type":"set2","local_side":"away","local_uid":"2026-08-23_abdullah_shelbayh_dhakshineswar_suresh","bid":0.37,"ask":0.52,"mid":0.445,"spread":0.15,"price":0.37,"size":44.0,"side":"BUY"}
{"ts":"2026-08-23T17:52:44.488Z","event_type":"price_change","market_id":"3790334","outcome_index":0,"market_type":"set2","local_side":"home","local_uid":"2026-08-23_abdullah_shelbayh_dhakshineswar_suresh","bid":0.48,"ask":0.63,"mid":0.555,"spread":0.15,"price":0.63,"size":44.0,"side":"SELL"}
{"ts":"2026-08-23T17:52:44.488Z","event_type":"best_bid_ask","market_id":"3789925","outcome_index":0,"market_type":"match","local_side":"home","local_uid":"2026-08-23_pierre_hugues_herbert_quinn_vandecasteele","bid":0.83,"ask":0.85,"mid":0.84,"spread":0.02,"bid_size":null,"ask_size":null}
{"ts":"2026-08-23T17:52:44.488Z","event_type":"best_bid_ask","market_id":"3789925","outcome_index":1,"market_type":"match","local_side":"away","local_uid":"2026-08-23_pierre_hugues_herbert_quinn_vandecasteele","bid":0.15,"ask":0.17,"mid":0.16,"spread":0.02,"bid_size":null,"ask_size":null}
{"ts":"2026-08-23T17:52:44.488Z","event_type":"price_change","market_id":"3789925","outcome_index":0,"market_type":"match","local_side":"home","local_uid":"2026-08-23_pierre_hugues_herbert_quinn_vandecasteele","bid":0.83,"ask":0.85,"mid":0.84,"spread":0.02,"price":0.84,"size":0.0,"side":"SELL"}
{"ts":"2026-08-23T17:52:44.488Z","event_type":"price_change","market_id":"3789925","outcome_index":1,"market_type":"match","local_side":"away","local_uid":"2026-08-23_pierre_hugues_herbert_quinn_vandecasteele","bid":0.15,"ask":0.17,"mid":0.16,"spread":0.02,"price":0.16,"size":0.0,"side":"BUY"}
{"ts":"2026-08-23T17:52:44.530Z","event_type":"best_bid_ask","market_id":"3789925","outcome_index":0,"market_type":"match","local_side":"home","local_uid":"2026-08-23_pierre_hugues_herbert_quinn_vandecasteele","bid":0.84,"ask":0.85,"mid":0.845,"spread":0.01,"bid_size":null,"ask_size":null}
{"ts":"2026-08-23T17:52:44.531Z","event_type":"best_bid_ask","market_id":"3789925","outcome_index":1,"market_type":"match","local_side":"away","local_uid":"2026-08-23_pierre_hugues_herbert_quinn_vandecasteele","bid":0.15,"ask":0.16,"mid":0.155,"spread":0.01,"bid_size":null,"ask_size":null}
{"ts":"2026-08-23T17:52:44.531Z","event_type":"price_change","market_id":"3789925","outcome_index":0,"market_type":"match","local_side":"home","local_uid":"2026-08-23_pierre_hugues_herbert_quinn_vandecasteele","bid":0.84,"ask":0.85,"mid":0.845,"spread":0.01,"price":0.84,"size":4807.0,"side":"BUY"}
{"ts":"2026-08-23T17:52:44.531Z","event_type":"price_change","market_id":"3789925","outcome_index":1,"market_type":"match","local_side":"away","local_uid":"2026-08-23_pierre_hugues_herbert_quinn_vandecasteele","bid":0.15,"ask":0.16,"mid":0.155,"spread":0.01,"price":0.16,"size":4807.0,"side":"SELL"}
{"ts":"2026-08-23T17:52:44.532Z","event_type":"best_bid_ask","market_id":"3790334","outcome_index":0,"market_type":"set2","local_side":"home","local_uid":"2026-08-23_abdullah_shelbayh_dhakshineswar_suresh","bid":0.48,"ask":0.65,"mid":0.565,"spread":0.17,"bid_size":null,"ask_size":null}
{"ts":"2026-08-23T17:52:44.532Z","event_type":"best_bid_ask","market_id":"3790334","outcome_index":1,"market_type":"set2","local_side":"away","local_uid":"2026-08-23_abdullah_shelbayh_dhakshineswar_suresh","bid":0.35,"ask":0.52,"mid":0.435,"spread":0.17,"bid_size":null,"ask_size":null}
{"ts":"2026-08-23T17:52:44.533Z","event_type":"price_change","market_id":"3790334","outcome_index":1,"market_type":"set2","local_side":"away","local_uid":"2026-08-23_abdullah_shelbayh_dhakshineswar_suresh","bid":0.35,"ask":0.52,"mid":0.435,"spread":0.17,"price":0.37,"size":0.0,"side":"BUY"}
{"ts":"2026-08-23T17:52:44.533Z","event_type":"price_change","market_id":"3790334","outcome_index":0,"market_type":"set2","local_side":"home","local_uid":"2026-08-23_abdullah_shelbayh_dhakshineswar_suresh","bid":0.48,"ask":0.65,"mid":0.565,"spread":0.17,"price":0.63,"size":0.0,"side":"SELL"}
{"ts":"2026-08-23T17:52:44.533Z","event_type":"best_bid_ask","market_id":"3790334","outcome_index":0,"market_type":"set2","local_side":"home","local_uid":"2026-08-23_abdullah_shelbayh_dhakshineswar_suresh","bid":0.48,"ask":0.62,"mid":0.55,"spread":0.14,"bid_size":null,"ask_size":null}
{"ts":"2026-08-23T17:52:44.533Z","event_type":"best_bid_ask","market_id":"3790334","outcome_index":1,"market_type":"set2","local_side":"away","local_uid":"2026-08-23_abdullah_shelbayh_dhakshineswar_suresh","bid":0.38,"ask":0.52,"mid":0.45,"spread":0.14,"bid_size":null,"ask_size":null}
{"ts":"2026-08-23T17:52:44.533Z","event_type":"price_change","market_id":"3790334","outcome_index":1,"market_type":"set2","local_side":"away","local_uid":"2026-08-23_abdullah_shelbayh_dhakshineswar_suresh","bid":0.38,"ask":0.52,"mid":0.45,"spread":0.14,"price":0.38,"size":44.0,"side":"BUY"}
{"ts":"2026-08-23T17:52:44.533Z","event_type":"price_change","market_id":"3790334","outcome_index":0,"market_type":"set2","local_side":"home","local_uid":"2026-08-23_abdullah_shelbayh_dhakshineswar_suresh","bid":0.48,"ask":0.62,"mid":0.55,"spread":0.14,"price":0.62,"size":44.0,"side":"SELL"}
{"ts":"2026-08-23T17:52:44.594Z","event_type":"best_bid_ask","market_id":"3790334","outcome_index":0,"market_type":"set2","local_side":"home","local_uid":"2026-08-23_abdullah_shelbayh_dhakshineswar_suresh","bid":0.48,"ask":0.63,"mid":0.555,"spread":0.15,"bid_size":null,"ask_size":null}
{"ts":"2026-08-23T17:52:44.594Z","event_type":"best_bid_ask","market_id":"3790334","outcome_index":1,"market_type":"set2","local_side":"away","local_uid":"2026-08-23_abdullah_shelbayh_dhakshineswar_suresh","bid":0.37,"ask":0.52,"mid":0.445,"spread":0.15,"bid_size":null,"ask_size":null}
{"ts":"2026-08-23T17:52:44.595Z","event_type":"price_change","market_id":"3790334","outcome_index":1,"market_type":"set2","local_side":"away","local_uid":"2026-08-23_abdullah_shelbayh_dhakshineswar_suresh","bid":0.37,"ask":0.52,"mid":0.445,"spread":0.15,"price":0.38,"size":0.0,"side":"BUY"}
{"ts":"2026-08-23T17:52:44.595Z","event_type":"price_change","market_id":"3790334","outcome_index":0,"market_type":"set2","local_side":"home","local_uid":"2026-08-23_abdullah_shelbayh_dhakshineswar_suresh","bid":0.48,"ask":0.63,"mid":0.555,"spread":0.15,"price":0.62,"size":0.0,"side":"SELL"}
{"ts":"2026-08-23T17:52:44.595Z","event_type":"best_bid_ask","market_id":"3790334","outcome_index":0,"market_type":"set2","local_side":"home","local_uid":"2026-08-23_abdullah_shelbayh_dhakshineswar_suresh","bid":0.48,"ask":0.64,"mid":0.56,"spread":0.16,"bid_size":null,"ask_size":null}
{"ts":"2026-08-23T17:52:44.595Z","event_type":"best_bid_ask","market_id":"3790334","outcome_index":1,"market_type":"set2","local_side":"away","local_uid":"2026-08-23_abdullah_shelbayh_dhakshineswar_suresh","bid":0.36,"ask":0.52,"mid":0.44,"spread":0.16,"bid_size":null,"ask_size":null}
{"ts":"2026-08-23T17:52:44.595Z","event_type":"price_change","market_id":"3790334","outcome_index":1,"market_type":"set2","local_side":"away","local_uid":"2026-08-23_abdullah_shelbayh_dhakshineswar_suresh","bid":0.36,"ask":0.52,"mid":0.44,"spread":0.16,"price":0.37,"size":0.0,"side":"BUY"}
{"ts":"2026-08-23T17:52:44.595Z","event_type":"price_change","market_id":"3790334","outcome_index":0,"market_type":"set2","local_side":"home","local_uid":"2026-08-23_abdullah_shelbayh_dhakshineswar_suresh","bid":0.48,"ask":0.64,"mid":0.56,"spread":0.16,"price":0.63,"size":0.0,"side":"SELL"}
{"ts":"2026-08-23T17:52:44.595Z","event_type":"best_bid_ask","market_id":"3790334","outcome_index":0,"market_type":"set2","local_side":"home","local_uid":"2026-08-23_abdullah_shelbayh_dhakshineswar_suresh","bid":0.48,"ask":0.63,"mid":0.555,"spread":0.15,"bid_size":null,"ask_size":null}
{"ts":"2026-08-23T17:52:44.595Z","event_type":"best_bid_ask","market_id":"3790334","outcome_index":1,"market_type":"set2","local_side":"away","local_uid":"2026-08-23_abdullah_shelbayh_dhakshineswar_suresh","bid":0.37,"ask":0.52,"mid":0.445,"spread":0.15,"bid_size":null,"ask_size":null}
{"ts":"2026-08-23T17:52:44.595Z","event_type":"price_change","market_id":"3790334","outcome_index":1,"market_type":"set2","local_side":"away","local_uid":"2026-08-23_abdullah_shelbayh_dhakshineswar_suresh","bid":0.37,"ask":0.52,"mid":0.445,"spread":0.15,"price":0.37,"size":88.0,"side":"BUY"}
{"ts":"2026-08-23T17:52:44.595Z","event_type":"price_change","market_id":"3790334","outcome_index":0,"market_type":"set2","local_side":"home","local_uid":"2026-08-23_abdullah_shelbayh_dhakshineswar_suresh","bid":0.48,"ask":0.63,"mid":0.555,"spread":0.15,"price":0.63,"size":88.0,"side":"SELL"}
{"ts":"2026-08-23T17:52:44.596Z","event_type":"best_bid_ask","market_id":"3790334","outcome_index":0,"market_type":"set2","local_side":"home","local_uid":"2026-08-23_abdullah_shelbayh_dhakshineswar_suresh","bid":0.48,"ask":1.0,"mid":0.74,"spread":0.52,"bid_size":null,"ask_size":null}
{"ts":"2026-08-23T17:52:44.596Z","event_type":"best_bid_ask","market_id":"3790334","outcome_index":1,"market_type":"set2","local_side":"away","local_uid":"2026-08-23_abdullah_shelbayh_dhakshineswar_suresh","bid":0.0,"ask":0.52,"mid":0.26,"spread":0.52,"bid_size":null,"ask_size":null}
{"ts":"2026-08-23T17:52:44.634Z","event_type":"price_change","market_id":"3790334","outcome_index":1,"market_type":"set2","local_side":"away","local_uid":"2026-08-23_abdullah_shelbayh_dhakshineswar_suresh","bid":0.0,"ask":0.52,"mid":0.26,"spread":0.52,"price":0.37,"size":0.0,"side":"BUY"}
{"ts":"2026-08-23T17:52:44.634Z","event_type":"price_change","market_id":"3790334","outcome_index":0,"market_type":"set2","local_side":"home","local_uid":"2026-08-23_abdullah_shelbayh_dhakshineswar_suresh","bid":0.48,"ask":1.0,"mid":0.74,"spread":0.52,"price":0.63,"size":0.0,"side":"SELL"}
{"ts":"2026-08-23T17:52:44.638Z","event_type":"best_bid_ask","market_id":"3790334","outcome_index":0,"market_type":"set2","local_side":"home","local_uid":"2026-08-23_abdullah_shelbayh_dhakshineswar_suresh","bid":0.48,"ask":0.63,"mid":0.555,"spread":0.15,"bid_size":null,"ask_size":null}
{"ts":"2026-08-23T17:52:44.638Z","event_type":"best_bid_ask","market_id":"3790334","outcome_index":1,"market_type":"set2","local_side":"away","local_uid":"2026-08-23_abdullah_shelbayh_dhakshineswar_suresh","bid":0.37,"ask":0.52,"mid":0.445,"spread":0.15,"bid_size":null,"ask_size":null}
{"ts":"2026-08-23T17:52:44.638Z","event_type":"price_change","market_id":"3790334","outcome_index":1,"market_type":"set2","local_side":"away","local_uid":"2026-08-23_abdullah_shelbayh_dhakshineswar_suresh","bid":0.37,"ask":0.52,"mid":0.445,"spread":0.15,"price":0.37,"size":88.0,"side":"BUY"}
{"ts":"2026-08-23T17:52:44.638Z","event_type":"price_change","market_id":"3790334","outcome_index":0,"market_type":"set2","local_side":"home","local_uid":"2026-08-23_abdullah_shelbayh_dhakshineswar_suresh","bid":0.48,"ask":0.63,"mid":0.555,"spread":0.15,"price":0.63,"size":88.0,"side":"SELL"}
{"ts":"2026-08-23T17:52:44.640Z","event_type":"best_bid_ask","market_id":"3790334","outcome_index":0,"market_type":"set2","local_side":"home","local_uid":"2026-08-23_abdullah_shelbayh_dhakshineswar_suresh","bid":0.48,"ask":0.64,"mid":0.56,"spread":0.16,"bid_size":null,"ask_size":null}
{"ts":"2026-08-23T17:52:44.640Z","event_type":"best_bid_ask","market_id":"3790334","outcome_index":1,"market_type":"set2","local_side":"away","local_uid":"2026-08-23_abdullah_shelbayh_dhakshineswar_suresh","bid":0.36,"ask":0.52,"mid":0.44,"spread":0.16,"bid_size":null,"ask_size":null}
{"ts":"2026-08-23T17:52:44.641Z","event_type":"price_change","market_id":"3790334","outcome_index":1,"market_type":"set2","local_side":"away","local_uid":"2026-08-23_abdullah_shelbayh_dhakshineswar_suresh","bid":0.36,"ask":0.52,"mid":0.44,"spread":0.16,"price":0.37,"size":0.0,"side":"BUY"}
{"ts":"2026-08-23T17:52:44.641Z","event_type":"price_change","market_id":"3790334","outcome_index":0,"market_type":"set2","local_side":"home","local_uid":"2026-08-23_abdullah_shelbayh_dhakshineswar_suresh","bid":0.48,"ask":0.64,"mid":0.56,"spread":0.16,"price":0.63,"size":0.0,"side":"SELL"}
{"ts":"2026-08-23T17:52:44.641Z","event_type":"best_bid_ask","market_id":"3790334","outcome_index":0,"market_type":"set2","local_side":"home","local_uid":"2026-08-23_abdullah_shelbayh_dhakshineswar_suresh","bid":0.48,"ask":0.6,"mid":0.54,"spread":0.12,"bid_size":null,"ask_size":null}
{"ts":"2026-08-23T17:52:44.641Z","event_type":"best_bid_ask","market_id":"3790334","outcome_index":1,"market_type":"set2","local_side":"away","local_uid":"2026-08-23_abdullah_shelbayh_dhakshineswar_suresh","bid":0.4,"ask":0.52,"mid":0.46,"spread":0.12,"bid_size":null,"ask_size":null}
{"ts":"2026-08-23T17:52:44.641Z","event_type":"price_change","market_id":"3790334","outcome_index":1,"market_type":"set2","local_side":"away","local_uid":"2026-08-23_abdullah_shelbayh_dhakshineswar_suresh","bid":0.4,"ask":0.52,"mid":0.46,"spread":0.12,"price":0.4,"size":26.0,"side":"BUY"}
{"ts":"2026-08-23T17:52:44.641Z","event_type":"price_change","market_id":"3790334","outcome_index":0,"market_type":"set2","local_side":"home","local_uid":"2026-08-23_abdullah_shelbayh_dhakshineswar_suresh","bid":0.48,"ask":0.6,"mid":0.54,"spread":0.12,"price":0.6,"size":26.0,"side":"SELL"}
{"ts":"2026-08-23T17:52:44.701Z","event_type":"best_bid_ask","market_id":"3790334","outcome_index":0,"market_type":"set2","local_side":"home","local_uid":"2026-08-23_abdullah_shelbayh_dhakshineswar_suresh","bid":0.48,"ask":0.59,"mid":0.535,"spread":0.11,"bid_size":null,"ask_size":null}
{"ts":"2026-08-23T17:52:44.701Z","event_type":"best_bid_ask","market_id":"3790334","outcome_index":1,"market_type":"set2","local_side":"away","local_uid":"2026-08-23_abdullah_shelbayh_dhakshineswar_suresh","bid":0.41,"ask":0.52,"mid":0.465,"spread":0.11,"bid_size":null,"ask_size":null}
{"ts":"2026-08-23T17:52:44.701Z","event_type":"price_change","market_id":"3790334","outcome_index":1,"market_type":"set2","local_side":"away","local_uid":"2026-08-23_abdullah_shelbayh_dhakshineswar_suresh","bid":0.41,"ask":0.52,"mid":0.465,"spread":0.11,"price":0.41,"size":44.0,"side":"BUY"}
{"ts":"2026-08-23T17:52:44.701Z","event_type":"price_change","market_id":"3790334","outcome_index":0,"market_type":"set2","local_side":"home","local_uid":"2026-08-23_abdullah_shelbayh_dhakshineswar_suresh","bid":0.48,"ask":0.59,"mid":0.535,"spread":0.11,"price":0.59,"size":44.0,"side":"SELL"}
{"ts":"2026-08-23T17:52:44.905Z","event_type":"price_change","market_id":"3792969","outcome_index":0,"market_type":"match","local_side":"home","local_uid":"2026-08-23_maya_joint_yulia_putintseva","bid":0.44,"ask":0.45,"mid":0.445,"spread":0.01,"price":0.43,"size":10767.37,"side":"BUY"}
{"ts":"2026-08-23T17:52:44.905Z","event_type":"price_change","market_id":"3792969","outcome_index":1,"market_type":"match","local_side":"away","local_uid":"2026-08-23_maya_joint_yulia_putintseva","bid":0.55,"ask":0.56,"mid":0.555,"spread":0.01,"price":0.57,"size":10767.37,"side":"SELL"}
{"ts":"2026-08-23T17:52:45.176Z","event_type":"best_bid_ask","market_id":"3790334","outcome_index":0,"market_type":"set2","local_side":"home","local_uid":"2026-08-23_abdullah_shelbayh_dhakshineswar_suresh","bid":0.48,"ask":0.58,"mid":0.53,"spread":0.1,"bid_size":null,"ask_size":null}
{"ts":"2026-08-23T17:52:45.176Z","event_type":"best_bid_ask","market_id":"3790334","outcome_index":1,"market_type":"set2","local_side":"away","local_uid":"2026-08-23_abdullah_shelbayh_dhakshineswar_suresh","bid":0.42,"ask":0.52,"mid":0.47,"spread":0.1,"bid_size":null,"ask_size":null}
{"ts":"2026-08-23T17:52:45.176Z","event_type":"price_change","market_id":"3790334","outcome_index":1,"market_type":"set2","local_side":"away","local_uid":"2026-08-23_abdullah_shelbayh_dhakshineswar_suresh","bid":0.42,"ask":0.52,"mid":0.47,"spread":0.1,"price":0.42,"size":150.0,"side":"BUY"}
{"ts":"2026-08-23T17:52:45.176Z","event_type":"price_change","market_id":"3790334","outcome_index":0,"market_type":"set2","local_side":"home","local_uid":"2026-08-23_abdullah_shelbayh_dhakshineswar_suresh","bid":0.48,"ask":0.58,"mid":0.53,"spread":0.1,"price":0.58,"size":150.0,"side":"SELL"}
{"ts":"2026-08-23T17:52:46.207Z","event_type":"last_trade_price","market_id":"3789931","outcome_index":1,"market_type":"match","local_side":"away","local_uid":"2026-08-23_stefanos_sakellaridis_luca_van_assche","last_trade":0.94,"trade_size":5.0,"trade_side":"BUY","trade_notional":4.7}
{"ts":"2026-08-23T17:52:46.224Z","event_type":"price_change","market_id":"3780832","outcome_index":0,"market_type":"match","local_side":"home","local_uid":"2026-08-23_francisco_comesana_yibing_wu","bid":0.38,"ask":0.39,"mid":0.385,"spread":0.01,"price":0.36,"size":23144.58,"side":"BUY"}
{"ts":"2026-08-23T17:52:46.224Z","event_type":"price_change","market_id":"3780832","outcome_index":1,"market_type":"match","local_side":"away","local_uid":"2026-08-23_francisco_comesana_yibing_wu","bid":0.61,"ask":0.62,"mid":0.615,"spread":0.01,"price":0.64,"size":23144.58,"side":"SELL"}
{"ts":"2026-08-23T17:52:47.589Z","event_type":"price_change","market_id":"3780846","outcome_index":1,"market_type":"match","local_side":"away","local_uid":"2026-08-23_martin_landaluce_mattia_bellucci","bid":0.46,"ask":0.47,"mid":0.465,"spread":0.01,"price":0.45,"size":20780.18,"side":"BUY"}
{"ts":"2026-08-23T17:52:47.589Z","event_type":"price_change","market_id":"3780846","outcome_index":0,"market_type":"match","local_side":"home","local_uid":"2026-08-23_martin_landaluce_mattia_bellucci","bid":0.53,"ask":0.54,"mid":0.535,"spread":0.01,"price":0.55,"size":20780.18,"side":"SELL"}
{"ts":"2026-08-23T17:52:49.190Z","event_type":"best_bid_ask","market_id":"3790323","outcome_index":0,"market_type":"set2","local_side":"home","local_uid":"2026-08-23_felix_balshaw_sebastian_gorzny","bid":0.5,"ask":0.6,"mid":0.55,"spread":0.1,"bid_size":null,"ask_size":null}
{"ts":"2026-08-23T17:52:49.191Z","event_type":"best_bid_ask","market_id":"3790323","outcome_index":1,"market_type":"set2","local_side":"away","local_uid":"2026-08-23_felix_balshaw_sebastian_gorzny","bid":0.4,"ask":0.5,"mid":0.45,"spread":0.1,"bid_size":null,"ask_size":null}
{"ts":"2026-08-23T17:52:49.191Z","event_type":"price_change","market_id":"3790323","outcome_index":1,"market_type":"set2","local_side":"away","local_uid":"2026-08-23_felix_balshaw_sebastian_gorzny","bid":0.4,"ask":0.5,"mid":0.45,"spread":0.1,"price":0.43,"size":0.0,"side":"BUY"}
{"ts":"2026-08-23T17:52:49.191Z","event_type":"price_change","market_id":"3790323","outcome_index":0,"market_type":"set2","local_side":"home","local_uid":"2026-08-23_felix_balshaw_sebastian_gorzny","bid":0.5,"ask":0.6,"mid":0.55,"spread":0.1,"price":0.57,"size":0.0,"side":"SELL"}
{"ts":"2026-08-23T17:52:49.252Z","event_type":"best_bid_ask","market_id":"3790323","outcome_index":0,"market_type":"set2","local_side":"home","local_uid":"2026-08-23_felix_balshaw_sebastian_gorzny","bid":0.5,"ask":0.59,"mid":0.545,"spread":0.09,"bid_size":null,"ask_size":null}
{"ts":"2026-08-23T17:52:49.254Z","event_type":"best_bid_ask","market_id":"3790323","outcome_index":1,"market_type":"set2","local_side":"away","local_uid":"2026-08-23_felix_balshaw_sebastian_gorzny","bid":0.41,"ask":0.5,"mid":0.455,"spread":0.09,"bid_size":null,"ask_size":null}
{"ts":"2026-08-23T17:52:49.254Z","event_type":"price_change","market_id":"3790323","outcome_index":1,"market_type":"set2","local_side":"away","local_uid":"2026-08-23_felix_balshaw_sebastian_gorzny","bid":0.41,"ask":0.5,"mid":0.455,"spread":0.09,"price":0.41,"size":22.0,"side":"BUY"}
{"ts":"2026-08-23T17:52:49.254Z","event_type":"price_change","market_id":"3790323","outcome_index":0,"market_type":"set2","local_side":"home","local_uid":"2026-08-23_felix_balshaw_sebastian_gorzny","bid":0.5,"ask":0.59,"mid":0.545,"spread":0.09,"price":0.59,"size":22.0,"side":"SELL"}
{"ts":"2026-08-23T17:52:49.285Z","event_type":"best_bid_ask","market_id":"3790323","outcome_index":0,"market_type":"set2","local_side":"home","local_uid":"2026-08-23_felix_balshaw_sebastian_gorzny","bid":0.5,"ask":0.63,"mid":0.565,"spread":0.13,"bid_size":null,"ask_size":null}
{"ts":"2026-08-23T17:52:49.285Z","event_type":"best_bid_ask","market_id":"3790323","outcome_index":1,"market_type":"set2","local_side":"away","local_uid":"2026-08-23_felix_balshaw_sebastian_gorzny","bid":0.37,"ask":0.5,"mid":0.435,"spread":0.13,"bid_size":null,"ask_size":null}
{"ts":"2026-08-23T17:52:49.285Z","event_type":"price_change","market_id":"3790323","outcome_index":1,"market_type":"set2","local_side":"away","local_uid":"2026-08-23_felix_balshaw_sebastian_gorzny","bid":0.37,"ask":0.5,"mid":0.435,"spread":0.13,"price":0.41,"size":0.0,"side":"BUY"}
{"ts":"2026-08-23T17:52:49.285Z","event_type":"price_change","market_id":"3790323","outcome_index":0,"market_type":"set2","local_side":"home","local_uid":"2026-08-23_felix_balshaw_sebastian_gorzny","bid":0.5,"ask":0.63,"mid":0.565,"spread":0.13,"price":0.59,"size":0.0,"side":"SELL"}
{"ts":"2026-08-23T17:52:49.314Z","event_type":"best_bid_ask","market_id":"3790323","outcome_index":0,"market_type":"set2","local_side":"home","local_uid":"2026-08-23_felix_balshaw_sebastian_gorzny","bid":0.5,"ask":0.62,"mid":0.56,"spread":0.12,"bid_size":null,"ask_size":null}
{"ts":"2026-08-23T17:52:49.314Z","event_type":"best_bid_ask","market_id":"3790323","outcome_index":1,"market_type":"set2","local_side":"away","local_uid":"2026-08-23_felix_balshaw_sebastian_gorzny","bid":0.38,"ask":0.5,"mid":0.44,"spread":0.12,"bid_size":null,"ask_size":null}
{"ts":"2026-08-23T17:52:49.314Z","event_type":"price_change","market_id":"3790323","outcome_index":1,"market_type":"set2","local_side":"away","local_uid":"2026-08-23_felix_balshaw_sebastian_gorzny","bid":0.38,"ask":0.5,"mid":0.44,"spread":0.12,"price":0.38,"size":150.0,"side":"BUY"}
{"ts":"2026-08-23T17:52:49.314Z","event_type":"price_change","market_id":"3790323","outcome_index":0,"market_type":"set2","local_side":"home","local_uid":"2026-08-23_felix_balshaw_sebastian_gorzny","bid":0.5,"ask":0.62,"mid":0.56,"spread":0.12,"price":0.62,"size":150.0,"side":"SELL"}
{"ts":"2026-08-23T17:52:49.392Z","event_type":"best_bid_ask","market_id":"3790323","outcome_index":0,"market_type":"set2","local_side":"home","local_uid":"2026-08-23_felix_balshaw_sebastian_gorzny","bid":0.5,"ask":0.63,"mid":0.565,"spread":0.13,"bid_size":null,"ask_size":null}
{"ts":"2026-08-23T17:52:49.392Z","event_type":"best_bid_ask","market_id":"3790323","outcome_index":1,"market_type":"set2","local_side":"away","local_uid":"2026-08-23_felix_balshaw_sebastian_gorzny","bid":0.37,"ask":0.5,"mid":0.435,"spread":0.13,"bid_size":null,"ask_size":null}
{"ts":"2026-08-23T17:52:49.393Z","event_type":"price_change","market_id":"3790323","outcome_index":1,"market_type":"set2","local_side":"away","local_uid":"2026-08-23_felix_balshaw_sebastian_gorzny","bid":0.37,"ask":0.5,"mid":0.435,"spread":0.13,"price":0.38,"size":0.0,"side":"BUY"}
{"ts":"2026-08-23T17:52:49.393Z","event_type":"price_change","market_id":"3790323","outcome_index":0,"market_type":"set2","local_side":"home","local_uid":"2026-08-23_felix_balshaw_sebastian_gorzny","bid":0.5,"ask":0.63,"mid":0.565,"spread":0.13,"price":0.62,"size":0.0,"side":"SELL"}
{"ts":"2026-08-23T17:52:49.429Z","event_type":"best_bid_ask","market_id":"3790323","outcome_index":0,"market_type":"set2","local_side":"home","local_uid":"2026-08-23_felix_balshaw_sebastian_gorzny","bid":0.5,"ask":0.58,"mid":0.54,"spread":0.08,"bid_size":null,"ask_size":null}
{"ts":"2026-08-23T17:52:49.429Z","event_type":"best_bid_ask","market_id":"3790323","outcome_index":1,"market_type":"set2","local_side":"away","local_uid":"2026-08-23_felix_balshaw_sebastian_gorzny","bid":0.42,"ask":0.5,"mid":0.46,"spread":0.08,"bid_size":null,"ask_size":null}
{"ts":"2026-08-23T17:52:49.429Z","event_type":"price_change","market_id":"3790323","outcome_index":1,"market_type":"set2","local_side":"away","local_uid":"2026-08-23_felix_balshaw_sebastian_gorzny","bid":0.42,"ask":0.5,"mid":0.46,"spread":0.08,"price":0.42,"size":150.0,"side":"BUY"}
{"ts":"2026-08-23T17:52:49.429Z","event_type":"price_change","market_id":"3790323","outcome_index":0,"market_type":"set2","local_side":"home","local_uid":"2026-08-23_felix_balshaw_sebastian_gorzny","bid":0.5,"ask":0.58,"mid":0.54,"spread":0.08,"price":0.58,"size":150.0,"side":"SELL"}
{"ts":"2026-08-23T17:52:49.545Z","event_type":"best_bid_ask","market_id":"3790323","outcome_index":0,"market_type":"set2","local_side":"home","local_uid":"2026-08-23_felix_balshaw_sebastian_gorzny","bid":0.5,"ask":0.61,"mid":0.555,"spread":0.11,"bid_size":null,"ask_size":null}
{"ts":"2026-08-23T17:52:49.546Z","event_type":"best_bid_ask","market_id":"3790323","outcome_index":1,"market_type":"set2","local_side":"away","local_uid":"2026-08-23_felix_balshaw_sebastian_gorzny","bid":0.39,"ask":0.5,"mid":0.445,"spread":0.11,"bid_size":null,"ask_size":null}
{"ts":"2026-08-23T17:52:49.546Z","event_type":"price_change","market_id":"3790323","outcome_index":1,"market_type":"set2","local_side":"away","local_uid":"2026-08-23_felix_balshaw_sebastian_gorzny","bid":0.39,"ask":0.5,"mid":0.445,"spread":0.11,"price":0.42,"size":0.0,"side":"BUY"}
{"ts":"2026-08-23T17:52:49.546Z","event_type":"price_change","market_id":"3790323","outcome_index":0,"market_type":"set2","local_side":"home","local_uid":"2026-08-23_felix_balshaw_sebastian_gorzny","bid":0.5,"ask":0.61,"mid":0.555,"spread":0.11,"price":0.58,"size":0.0,"side":"SELL"}
{"ts":"2026-08-23T17:52:49.561Z","event_type":"best_bid_ask","market_id":"3790323","outcome_index":0,"market_type":"set2","local_side":"home","local_uid":"2026-08-23_felix_balshaw_sebastian_gorzny","bid":0.5,"ask":0.63,"mid":0.565,"spread":0.13,"bid_size":null,"ask_size":null}
{"ts":"2026-08-23T17:52:49.561Z","event_type":"best_bid_ask","market_id":"3790323","outcome_index":1,"market_type":"set2","local_side":"away","local_uid":"2026-08-23_felix_balshaw_sebastian_gorzny","bid":0.37,"ask":0.5,"mid":0.435,"spread":0.13,"bid_size":null,"ask_size":null}
{"ts":"2026-08-23T17:52:49.561Z","event_type":"price_change","market_id":"3790323","outcome_index":1,"market_type":"set2","local_side":"away","local_uid":"2026-08-23_felix_balshaw_sebastian_gorzny","bid":0.37,"ask":0.5,"mid":0.435,"spread":0.13,"price":0.39,"size":0.0,"side":"BUY"}
{"ts":"2026-08-23T17:52:49.561Z","event_type":"price_change","market_id":"3790323","outcome_index":0,"market_type":"set2","local_side":"home","local_uid":"2026-08-23_felix_balshaw_sebastian_gorzny","bid":0.5,"ask":0.63,"mid":0.565,"spread":0.13,"price":0.61,"size":0.0,"side":"SELL"}
{"ts":"2026-08-23T17:52:49.588Z","event_type":"best_bid_ask","market_id":"3790323","outcome_index":0,"market_type":"set2","local_side":"home","local_uid":"2026-08-23_felix_balshaw_sebastian_gorzny","bid":0.5,"ask":0.61,"mid":0.555,"spread":0.11,"bid_size":null,"ask_size":null}
{"ts":"2026-08-23T17:52:49.589Z","event_type":"best_bid_ask","market_id":"3790323","outcome_index":1,"market_type":"set2","local_side":"away","local_uid":"2026-08-23_felix_balshaw_sebastian_gorzny","bid":0.39,"ask":0.5,"mid":0.445,"spread":0.11,"bid_size":null,"ask_size":null}
{"ts":"2026-08-23T17:52:49.589Z","event_type":"price_change","market_id":"3790323","outcome_index":1,"market_type":"set2","local_side":"away","local_uid":"2026-08-23_felix_balshaw_sebastian_gorzny","bid":0.39,"ask":0.5,"mid":0.445,"spread":0.11,"price":0.39,"size":150.0,"side":"BUY"}
{"ts":"2026-08-23T17:52:49.589Z","event_type":"price_change","market_id":"3790323","outcome_index":0,"market_type":"set2","local_side":"home","local_uid":"2026-08-23_felix_balshaw_sebastian_gorzny","bid":0.5,"ask":0.61,"mid":0.555,"spread":0.11,"price":0.61,"size":150.0,"side":"SELL"}
{"ts":"2026-08-23T17:52:49.731Z","event_type":"best_bid_ask","market_id":"3790334","outcome_index":0,"market_type":"set2","local_side":"home","local_uid":"2026-08-23_abdullah_shelbayh_dhakshineswar_suresh","bid":0.48,"ask":0.59,"mid":0.535,"spread":0.11,"bid_size":null,"ask_size":null}
{"ts":"2026-08-23T17:52:49.732Z","event_type":"best_bid_ask","market_id":"3790334","outcome_index":1,"market_type":"set2","local_side":"away","local_uid":"2026-08-23_abdullah_shelbayh_dhakshineswar_suresh","bid":0.41,"ask":0.52,"mid":0.465,"spread":0.11,"bid_size":null,"ask_size":null}
{"ts":"2026-08-23T17:52:49.732Z","event_type":"price_change","market_id":"3790334","outcome_index":1,"market_type":"set2","local_side":"away","local_uid":"2026-08-23_abdullah_shelbayh_dhakshineswar_suresh","bid":0.41,"ask":0.52,"mid":0.465,"spread":0.11,"price":0.42,"size":0.0,"side":"BUY"}
{"ts":"2026-08-23T17:52:49.732Z","event_type":"price_change","market_id":"3790334","outcome_index":0,"market_type":"set2","local_side":"home","local_uid":"2026-08-23_abdullah_shelbayh_dhakshineswar_suresh","bid":0.48,"ask":0.59,"mid":0.535,"spread":0.11,"price":0.58,"size":0.0,"side":"SELL"}
{"ts":"2026-08-23T17:52:49.737Z","event_type":"best_bid_ask","market_id":"3790334","outcome_index":0,"market_type":"set2","local_side":"home","local_uid":"2026-08-23_abdullah_shelbayh_dhakshineswar_suresh","bid":0.48,"ask":0.58,"mid":0.53,"spread":0.1,"bid_size":null,"ask_size":null}
{"ts":"2026-08-23T17:52:49.737Z","event_type":"best_bid_ask","market_id":"3790334","outcome_index":1,"market_type":"set2","local_side":"away","local_uid":"2026-08-23_abdullah_shelbayh_dhakshineswar_suresh","bid":0.42,"ask":0.52,"mid":0.47,"spread":0.1,"bid_size":null,"ask_size":null}
{"ts":"2026-08-23T17:52:49.737Z","event_type":"price_change","market_id":"3790334","outcome_index":1,"market_type":"set2","local_side":"away","local_uid":"2026-08-23_abdullah_shelbayh_dhakshineswar_suresh","bid":0.42,"ask":0.52,"mid":0.47,"spread":0.1,"price":0.42,"size":96.0,"side":"BUY"}
{"ts":"2026-08-23T17:52:49.737Z","event_type":"price_change","market_id":"3790334","outcome_index":0,"market_type":"set2","local_side":"home","local_uid":"2026-08-23_abdullah_shelbayh_dhakshineswar_suresh","bid":0.48,"ask":0.58,"mid":0.53,"spread":0.1,"price":0.58,"size":96.0,"side":"SELL"}
{"ts":"2026-08-23T17:52:49.766Z","event_type":"best_bid_ask","market_id":"3790334","outcome_index":0,"market_type":"set2","local_side":"home","local_uid":"2026-08-23_abdullah_shelbayh_dhakshineswar_suresh","bid":0.48,"ask":0.57,"mid":0.525,"spread":0.09,"bid_size":null,"ask_size":null}
{"ts":"2026-08-23T17:52:49.766Z","event_type":"best_bid_ask","market_id":"3790334","outcome_index":1,"market_type":"set2","local_side":"away","local_uid":"2026-08-23_abdullah_shelbayh_dhakshineswar_suresh","bid":0.43,"ask":0.52,"mid":0.475,"spread":0.09,"bid_size":null,"ask_size":null}
{"ts":"2026-08-23T17:52:49.766Z","event_type":"price_change","market_id":"3790334","outcome_index":1,"market_type":"set2","local_side":"away","local_uid":"2026-08-23_abdullah_shelbayh_dhakshineswar_suresh","bid":0.43,"ask":0.52,"mid":0.475,"spread":0.09,"price":0.43,"size":29.82,"side":"BUY"}
{"ts":"2026-08-23T17:52:49.766Z","event_type":"price_change","market_id":"3790334","outcome_index":0,"market_type":"set2","local_side":"home","local_uid":"2026-08-23_abdullah_shelbayh_dhakshineswar_suresh","bid":0.48,"ask":0.57,"mid":0.525,"spread":0.09,"price":0.57,"size":29.82,"side":"SELL"}
{"ts":"2026-08-23T17:52:49.802Z","event_type":"best_bid_ask","market_id":"3790334","outcome_index":0,"market_type":"set2","local_side":"home","local_uid":"2026-08-23_abdullah_shelbayh_dhakshineswar_suresh","bid":0.48,"ask":0.64,"mid":0.56,"spread":0.16,"bid_size":null,"ask_size":null}
{"ts":"2026-08-23T17:52:49.802Z","event_type":"best_bid_ask","market_id":"3790334","outcome_index":1,"market_type":"set2","local_side":"away","local_uid":"2026-08-23_abdullah_shelbayh_dhakshineswar_suresh","bid":0.36,"ask":0.52,"mid":0.44,"spread":0.16,"bid_size":null,"ask_size":null}
{"ts":"2026-08-23T17:52:49.802Z","event_type":"price_change","market_id":"3790334","outcome_index":1,"market_type":"set2","local_side":"away","local_uid":"2026-08-23_abdullah_shelbayh_dhakshineswar_suresh","bid":0.36,"ask":0.52,"mid":0.44,"spread":0.16,"price":0.43,"size":0.0,"side":"BUY"}
{"ts":"2026-08-23T17:52:49.802Z","event_type":"price_change","market_id":"3790334","outcome_index":0,"market_type":"set2","local_side":"home","local_uid":"2026-08-23_abdullah_shelbayh_dhakshineswar_suresh","bid":0.48,"ask":0.64,"mid":0.56,"spread":0.16,"price":0.57,"size":0.0,"side":"SELL"}
{"ts":"2026-08-23T17:52:49.954Z","event_type":"best_bid_ask","market_id":"3790334","outcome_index":0,"market_type":"set2","local_side":"home","local_uid":"2026-08-23_abdullah_shelbayh_dhakshineswar_suresh","bid":0.48,"ask":0.62,"mid":0.55,"spread":0.14,"bid_size":null,"ask_size":null}
{"ts":"2026-08-23T17:52:49.954Z","event_type":"best_bid_ask","market_id":"3790334","outcome_index":1,"market_type":"set2","local_side":"away","local_uid":"2026-08-23_abdullah_shelbayh_dhakshineswar_suresh","bid":0.38,"ask":0.52,"mid":0.45,"spread":0.14,"bid_size":null,"ask_size":null}
{"ts":"2026-08-23T17:52:49.954Z","event_type":"price_change","market_id":"3790334","outcome_index":1,"market_type":"set2","local_side":"away","local_uid":"2026-08-23_abdullah_shelbayh_dhakshineswar_suresh","bid":0.38,"ask":0.52,"mid":0.45,"spread":0.14,"price":0.38,"size":88.0,"side":"BUY"}
{"ts":"2026-08-23T17:52:49.954Z","event_type":"price_change","market_id":"3790334","outcome_index":0,"market_type":"set2","local_side":"home","local_uid":"2026-08-23_abdullah_shelbayh_dhakshineswar_suresh","bid":0.48,"ask":0.62,"mid":0.55,"spread":0.14,"price":0.62,"size":88.0,"side":"SELL"}
{"ts":"2026-08-23T17:52:49.988Z","event_type":"best_bid_ask","market_id":"3790334","outcome_index":0,"market_type":"set2","local_side":"home","local_uid":"2026-08-23_abdullah_shelbayh_dhakshineswar_suresh","bid":0.48,"ask":0.63,"mid":0.555,"spread":0.15,"bid_size":null,"ask_size":null}
{"ts":"2026-08-23T17:52:49.989Z","event_type":"best_bid_ask","market_id":"3790334","outcome_index":1,"market_type":"set2","local_side":"away","local_uid":"2026-08-23_abdullah_shelbayh_dhakshineswar_suresh","bid":0.37,"ask":0.52,"mid":0.445,"spread":0.15,"bid_size":null,"ask_size":null}
{"ts":"2026-08-23T17:52:49.989Z","event_type":"price_change","market_id":"3790334","outcome_index":1,"market_type":"set2","local_side":"away","local_uid":"2026-08-23_abdullah_shelbayh_dhakshineswar_suresh","bid":0.37,"ask":0.52,"mid":0.445,"spread":0.15,"price":0.38,"size":0.0,"side":"BUY"}
{"ts":"2026-08-23T17:52:49.989Z","event_type":"price_change","market_id":"3790334","outcome_index":0,"market_type":"set2","local_side":"home","local_uid":"2026-08-23_abdullah_shelbayh_dhakshineswar_suresh","bid":0.48,"ask":0.63,"mid":0.555,"spread":0.15,"price":0.62,"size":0.0,"side":"SELL"}
{"ts":"2026-08-23T17:52:49.989Z","event_type":"best_bid_ask","market_id":"3790334","outcome_index":0,"market_type":"set2","local_side":"home","local_uid":"2026-08-23_abdullah_shelbayh_dhakshineswar_suresh","bid":0.48,"ask":1.0,"mid":0.74,"spread":0.52,"bid_size":null,"ask_size":null}
{"ts":"2026-08-23T17:52:49.989Z","event_type":"best_bid_ask","market_id":"3790334","outcome_index":1,"market_type":"set2","local_side":"away","local_uid":"2026-08-23_abdullah_shelbayh_dhakshineswar_suresh","bid":0.0,"ask":0.52,"mid":0.26,"spread":0.52,"bid_size":null,"ask_size":null}
{"ts":"2026-08-23T17:52:49.989Z","event_type":"price_change","market_id":"3790334","outcome_index":1,"market_type":"set2","local_side":"away","local_uid":"2026-08-23_abdullah_shelbayh_dhakshineswar_suresh","bid":0.0,"ask":0.52,"mid":0.26,"spread":0.52,"price":0.37,"size":0.0,"side":"BUY"}
{"ts":"2026-08-23T17:52:49.989Z","event_type":"price_change","market_id":"3790334","outcome_index":0,"market_type":"set2","local_side":"home","local_uid":"2026-08-23_abdullah_shelbayh_dhakshineswar_suresh","bid":0.48,"ask":1.0,"mid":0.74,"spread":0.52,"price":0.63,"size":0.0,"side":"SELL"}
{"ts":"2026-08-23T17:52:49.990Z","event_type":"best_bid_ask","market_id":"3790334","outcome_index":0,"market_type":"set2","local_side":"home","local_uid":"2026-08-23_abdullah_shelbayh_dhakshineswar_suresh","bid":0.48,"ask":0.63,"mid":0.555,"spread":0.15,"bid_size":null,"ask_size":null}
{"ts":"2026-08-23T17:52:49.990Z","event_type":"best_bid_ask","market_id":"3790334","outcome_index":1,"market_type":"set2","local_side":"away","local_uid":"2026-08-23_abdullah_shelbayh_dhakshineswar_suresh","bid":0.37,"ask":0.52,"mid":0.445,"spread":0.15,"bid_size":null,"ask_size":null}
{"ts":"2026-08-23T17:52:49.990Z","event_type":"price_change","market_id":"3790334","outcome_index":1,"market_type":"set2","local_side":"away","local_uid":"2026-08-23_abdullah_shelbayh_dhakshineswar_suresh","bid":0.37,"ask":0.52,"mid":0.445,"spread":0.15,"price":0.37,"size":22.0,"side":"BUY"}
{"ts":"2026-08-23T17:52:49.990Z","event_type":"price_change","market_id":"3790334","outcome_index":0,"market_type":"set2","local_side":"home","local_uid":"2026-08-23_abdullah_shelbayh_dhakshineswar_suresh","bid":0.48,"ask":0.63,"mid":0.555,"spread":0.15,"price":0.63,"size":22.0,"side":"SELL"}
{"ts":"2026-08-23T17:52:50.031Z","event_type":"best_bid_ask","market_id":"3790334","outcome_index":0,"market_type":"set2","local_side":"home","local_uid":"2026-08-23_abdullah_shelbayh_dhakshineswar_suresh","bid":0.48,"ask":0.64,"mid":0.56,"spread":0.16,"bid_size":null,"ask_size":null}
{"ts":"2026-08-23T17:52:50.032Z","event_type":"best_bid_ask","market_id":"3790334","outcome_index":1,"market_type":"set2","local_side":"away","local_uid":"2026-08-23_abdullah_shelbayh_dhakshineswar_suresh","bid":0.36,"ask":0.52,"mid":0.44,"spread":0.16,"bid_size":null,"ask_size":null}
{"ts":"2026-08-23T17:52:50.032Z","event_type":"price_change","market_id":"3790334","outcome_index":1,"market_type":"set2","local_side":"away","local_uid":"2026-08-23_abdullah_shelbayh_dhakshineswar_suresh","bid":0.36,"ask":0.52,"mid":0.44,"spread":0.16,"price":0.37,"size":0.0,"side":"BUY"}
{"ts":"2026-08-23T17:52:50.032Z","event_type":"price_change","market_id":"3790334","outcome_index":0,"market_type":"set2","local_side":"home","local_uid":"2026-08-23_abdullah_shelbayh_dhakshineswar_suresh","bid":0.48,"ask":0.64,"mid":0.56,"spread":0.16,"price":0.63,"size":0.0,"side":"SELL"}
{"ts":"2026-08-23T17:52:50.101Z","event_type":"best_bid_ask","market_id":"3790334","outcome_index":0,"market_type":"set2","local_side":"home","local_uid":"2026-08-23_abdullah_shelbayh_dhakshineswar_suresh","bid":0.48,"ask":0.65,"mid":0.565,"spread":0.17,"bid_size":null,"ask_size":null}
{"ts":"2026-08-23T17:52:50.101Z","event_type":"best_bid_ask","market_id":"3790334","outcome_index":1,"market_type":"set2","local_side":"away","local_uid":"2026-08-23_abdullah_shelbayh_dhakshineswar_suresh","bid":0.35,"ask":0.52,"mid":0.435,"spread":0.17,"bid_size":null,"ask_size":null}
{"ts":"2026-08-23T17:52:50.101Z","event_type":"price_change","market_id":"3790334","outcome_index":1,"market_type":"set2","local_side":"away","local_uid":"2026-08-23_abdullah_shelbayh_dhakshineswar_suresh","bid":0.35,"ask":0.52,"mid":0.435,"spread":0.17,"price":0.36,"size":0.0,"side":"BUY"}
{"ts":"2026-08-23T17:52:50.102Z","event_type":"price_change","market_id":"3790334","outcome_index":0,"market_type":"set2","local_side":"home","local_uid":"2026-08-23_abdullah_shelbayh_dhakshineswar_suresh","bid":0.48,"ask":0.65,"mid":0.565,"spread":0.17,"price":0.64,"size":0.0,"side":"SELL"}
{"ts":"2026-08-23T17:52:50.102Z","event_type":"best_bid_ask","market_id":"3790334","outcome_index":0,"market_type":"set2","local_side":"home","local_uid":"2026-08-23_abdullah_shelbayh_dhakshineswar_suresh","bid":0.48,"ask":1.0,"mid":0.74,"spread":0.52,"bid_size":null,"ask_size":null}
{"ts":"2026-08-23T17:52:50.102Z","event_type":"best_bid_ask","market_id":"3790334","outcome_index":1,"market_type":"set2","local_side":"away","local_uid":"2026-08-23_abdullah_shelbayh_dhakshineswar_suresh","bid":0.0,"ask":0.52,"mid":0.26,"spread":0.52,"bid_size":null,"ask_size":null}
{"ts":"2026-08-23T17:52:50.102Z","event_type":"price_change","market_id":"3790334","outcome_index":1,"market_type":"set2","local_side":"away","local_uid":"2026-08-23_abdullah_shelbayh_dhakshineswar_suresh","bid":0.0,"ask":0.52,"mid":0.26,"spread":0.52,"price":0.35,"size":0.0,"side":"BUY"}
{"ts":"2026-08-23T17:52:50.102Z","event_type":"price_change","market_id":"3790334","outcome_index":0,"market_type":"set2","local_side":"home","local_uid":"2026-08-23_abdullah_shelbayh_dhakshineswar_suresh","bid":0.48,"ask":1.0,"mid":0.74,"spread":0.52,"price":0.65,"size":0.0,"side":"SELL"}
{"ts":"2026-08-23T17:52:50.102Z","event_type":"best_bid_ask","market_id":"3790334","outcome_index":0,"market_type":"set2","local_side":"home","local_uid":"2026-08-23_abdullah_shelbayh_dhakshineswar_suresh","bid":0.48,"ask":0.64,"mid":0.56,"spread":0.16,"bid_size":null,"ask_size":null}
{"ts":"2026-08-23T17:52:50.102Z","event_type":"best_bid_ask","market_id":"3790334","outcome_index":1,"market_type":"set2","local_side":"away","local_uid":"2026-08-23_abdullah_shelbayh_dhakshineswar_suresh","bid":0.36,"ask":0.52,"mid":0.44,"spread":0.16,"bid_size":null,"ask_size":null}
{"ts":"2026-08-23T17:52:50.102Z","event_type":"price_change","market_id":"3790334","outcome_index":1,"market_type":"set2","local_side":"away","local_uid":"2026-08-23_abdullah_shelbayh_dhakshineswar_suresh","bid":0.36,"ask":0.52,"mid":0.44,"spread":0.16,"price":0.36,"size":423.0,"side":"BUY"}
{"ts":"2026-08-23T17:52:50.102Z","event_type":"price_change","market_id":"3790334","outcome_index":0,"market_type":"set2","local_side":"home","local_uid":"2026-08-23_abdullah_shelbayh_dhakshineswar_suresh","bid":0.48,"ask":0.64,"mid":0.56,"spread":0.16,"price":0.64,"size":423.0,"side":"SELL"}
{"ts":"2026-08-23T17:52:50.103Z","event_type":"best_bid_ask","market_id":"3790334","outcome_index":0,"market_type":"set2","local_side":"home","local_uid":"2026-08-23_abdullah_shelbayh_dhakshineswar_suresh","bid":0.48,"ask":0.63,"mid":0.555,"spread":0.15,"bid_size":null,"ask_size":null}
{"ts":"2026-08-23T17:52:50.103Z","event_type":"best_bid_ask","market_id":"3790334","outcome_index":1,"market_type":"set2","local_side":"away","local_uid":"2026-08-23_abdullah_shelbayh_dhakshineswar_suresh","bid":0.37,"ask":0.52,"mid":0.445,"spread":0.15,"bid_size":null,"ask_size":null}
{"ts":"2026-08-23T17:52:50.103Z","event_type":"price_change","market_id":"3790334","outcome_index":1,"market_type":"set2","local_side":"away","local_uid":"2026-08-23_abdullah_shelbayh_dhakshineswar_suresh","bid":0.37,"ask":0.52,"mid":0.445,"spread":0.15,"price":0.37,"size":88.0,"side":"BUY"}
{"ts":"2026-08-23T17:52:50.103Z","event_type":"price_change","market_id":"3790334","outcome_index":0,"market_type":"set2","local_side":"home","local_uid":"2026-08-23_abdullah_shelbayh_dhakshineswar_suresh","bid":0.48,"ask":0.63,"mid":0.555,"spread":0.15,"price":0.63,"size":88.0,"side":"SELL"}
{"ts":"2026-08-23T17:52:50.140Z","event_type":"last_trade_price","market_id":"3789927","outcome_index":0,"market_type":"match","local_side":"home","local_uid":"2026-08-23_hugo_grenier_mees_rottgering","last_trade":0.24,"trade_size":30.0,"trade_side":"BUY","trade_notional":7.2}
{"ts":"2026-08-23T17:52:50.244Z","event_type":"best_bid_ask","market_id":"3790334","outcome_index":0,"market_type":"set2","local_side":"home","local_uid":"2026-08-23_abdullah_shelbayh_dhakshineswar_suresh","bid":0.48,"ask":0.62,"mid":0.55,"spread":0.14,"bid_size":null,"ask_size":null}
{"ts":"2026-08-23T17:52:50.244Z","event_type":"best_bid_ask","market_id":"3790334","outcome_index":1,"market_type":"set2","local_side":"away","local_uid":"2026-08-23_abdullah_shelbayh_dhakshineswar_suresh","bid":0.38,"ask":0.52,"mid":0.45,"spread":0.14,"bid_size":null,"ask_size":null}
{"ts":"2026-08-23T17:52:50.244Z","event_type":"price_change","market_id":"3790334","outcome_index":1,"market_type":"set2","local_side":"away","local_uid":"2026-08-23_abdullah_shelbayh_dhakshineswar_suresh","bid":0.38,"ask":0.52,"mid":0.45,"spread":0.14,"price":0.38,"size":44.0,"side":"BUY"}
{"ts":"2026-08-23T17:52:50.244Z","event_type":"price_change","market_id":"3790334","outcome_index":0,"market_type":"set2","local_side":"home","local_uid":"2026-08-23_abdullah_shelbayh_dhakshineswar_suresh","bid":0.48,"ask":0.62,"mid":0.55,"spread":0.14,"price":0.62,"size":44.0,"side":"SELL"}
{"ts":"2026-08-23T17:52:50.310Z","event_type":"best_bid_ask","market_id":"3790334","outcome_index":0,"market_type":"set2","local_side":"home","local_uid":"2026-08-23_abdullah_shelbayh_dhakshineswar_suresh","bid":0.48,"ask":0.61,"mid":0.545,"spread":0.13,"bid_size":null,"ask_size":null}
{"ts":"2026-08-23T17:52:50.311Z","event_type":"best_bid_ask","market_id":"3790334","outcome_index":1,"market_type":"set2","local_side":"away","local_uid":"2026-08-23_abdullah_shelbayh_dhakshineswar_suresh","bid":0.39,"ask":0.52,"mid":0.455,"spread":0.13,"bid_size":null,"ask_size":null}
{"ts":"2026-08-23T17:52:50.311Z","event_type":"price_change","market_id":"3790334","outcome_index":1,"market_type":"set2","local_side":"away","local_uid":"2026-08-23_abdullah_shelbayh_dhakshineswar_suresh","bid":0.39,"ask":0.52,"mid":0.455,"spread":0.13,"price":0.39,"size":44.0,"side":"BUY"}
{"ts":"2026-08-23T17:52:50.311Z","event_type":"price_change","market_id":"3790334","outcome_index":0,"market_type":"set2","local_side":"home","local_uid":"2026-08-23_abdullah_shelbayh_dhakshineswar_suresh","bid":0.48,"ask":0.61,"mid":0.545,"spread":0.13,"price":0.61,"size":44.0,"side":"SELL"}
{"ts":"2026-08-23T17:52:50.389Z","event_type":"price_change","market_id":"3795960","outcome_index":0,"market_type":"match","local_side":"home","local_uid":"2026-08-23_enmanuel_munoz_thomas_fancutt","bid":0.003,"ask":0.008,"mid":0.0055,"spread":0.005,"price":0.002,"size":5203.0,"side":"BUY"}
{"ts":"2026-08-23T17:52:50.389Z","event_type":"price_change","market_id":"3795960","outcome_index":1,"market_type":"match","local_side":"away","local_uid":"2026-08-23_enmanuel_munoz_thomas_fancutt","bid":0.992,"ask":0.997,"mid":0.9945,"spread":0.005,"price":0.998,"size":5203.0,"side":"SELL"}
{"ts":"2026-08-23T17:52:50.401Z","event_type":"price_change","market_id":"3789271","outcome_index":1,"market_type":"match","local_side":"away","local_uid":"2026-08-23_panna_udvardy_darja_vidmanova","bid":0.66,"ask":0.67,"mid":0.665,"spread":0.01,"price":0.37,"size":165.54,"side":"BUY"}
{"ts":"2026-08-23T17:52:50.401Z","event_type":"price_change","market_id":"3789271","outcome_index":0,"market_type":"match","local_side":"home","local_uid":"2026-08-23_panna_udvardy_darja_vidmanova","bid":0.33,"ask":0.34,"mid":0.335,"spread":0.01,"price":0.63,"size":165.54,"side":"SELL"}
{"ts":"2026-08-23T17:52:51.146Z","event_type":"last_trade_price","market_id":"3789927","outcome_index":0,"market_type":"match","local_side":"home","local_uid":"2026-08-23_hugo_grenier_mees_rottgering","last_trade":0.24,"trade_size":30.0,"trade_side":"BUY","trade_notional":7.2}
{"ts":"2026-08-23T17:52:51.785Z","event_type":"best_bid_ask","market_id":"3790334","outcome_index":0,"market_type":"set2","local_side":"home","local_uid":"2026-08-23_abdullah_shelbayh_dhakshineswar_suresh","bid":0.48,"ask":0.6,"mid":0.54,"spread":0.12,"bid_size":null,"ask_size":null}
{"ts":"2026-08-23T17:52:51.786Z","event_type":"best_bid_ask","market_id":"3790334","outcome_index":1,"market_type":"set2","local_side":"away","local_uid":"2026-08-23_abdullah_shelbayh_dhakshineswar_suresh","bid":0.4,"ask":0.52,"mid":0.46,"spread":0.12,"bid_size":null,"ask_size":null}
{"ts":"2026-08-23T17:52:51.786Z","event_type":"price_change","market_id":"3790334","outcome_index":1,"market_type":"set2","local_side":"away","local_uid":"2026-08-23_abdullah_shelbayh_dhakshineswar_suresh","bid":0.4,"ask":0.52,"mid":0.46,"spread":0.12,"price":0.4,"size":16.95,"side":"BUY"}
{"ts":"2026-08-23T17:52:51.786Z","event_type":"price_change","market_id":"3790334","outcome_index":0,"market_type":"set2","local_side":"home","local_uid":"2026-08-23_abdullah_shelbayh_dhakshineswar_suresh","bid":0.48,"ask":0.6,"mid":0.54,"spread":0.12,"price":0.6,"size":16.95,"side":"SELL"}
{"ts":"2026-08-23T17:52:51.786Z","event_type":"best_bid_ask","market_id":"3790334","outcome_index":0,"market_type":"set2","local_side":"home","local_uid":"2026-08-23_abdullah_shelbayh_dhakshineswar_suresh","bid":0.48,"ask":0.59,"mid":0.535,"spread":0.11,"bid_size":null,"ask_size":null}
{"ts":"2026-08-23T17:52:51.786Z","event_type":"best_bid_ask","market_id":"3790334","outcome_index":1,"market_type":"set2","local_side":"away","local_uid":"2026-08-23_abdullah_shelbayh_dhakshineswar_suresh","bid":0.41,"ask":0.52,"mid":0.465,"spread":0.11,"bid_size":null,"ask_size":null}
{"ts":"2026-08-23T17:52:51.786Z","event_type":"price_change","market_id":"3790334","outcome_index":1,"market_type":"set2","local_side":"away","local_uid":"2026-08-23_abdullah_shelbayh_dhakshineswar_suresh","bid":0.41,"ask":0.52,"mid":0.465,"spread":0.11,"price":0.41,"size":129.47,"side":"BUY"}
{"ts":"2026-08-23T17:52:51.786Z","event_type":"price_change","market_id":"3790334","outcome_index":0,"market_type":"set2","local_side":"home","local_uid":"2026-08-23_abdullah_shelbayh_dhakshineswar_suresh","bid":0.48,"ask":0.59,"mid":0.535,"spread":0.11,"price":0.59,"size":129.47,"side":"SELL"}
{"ts":"2026-08-23T17:52:51.831Z","event_type":"best_bid_ask","market_id":"3790334","outcome_index":0,"market_type":"set2","local_side":"home","local_uid":"2026-08-23_abdullah_shelbayh_dhakshineswar_suresh","bid":0.48,"ask":0.6,"mid":0.54,"spread":0.12,"bid_size":null,"ask_size":null}
{"ts":"2026-08-23T17:52:51.832Z","event_type":"best_bid_ask","market_id":"3790334","outcome_index":1,"market_type":"set2","local_side":"away","local_uid":"2026-08-23_abdullah_shelbayh_dhakshineswar_suresh","bid":0.4,"ask":0.52,"mid":0.46,"spread":0.12,"bid_size":null,"ask_size":null}
{"ts":"2026-08-23T17:52:51.832Z","event_type":"price_change","market_id":"3790334","outcome_index":1,"market_type":"set2","local_side":"away","local_uid":"2026-08-23_abdullah_shelbayh_dhakshineswar_suresh","bid":0.4,"ask":0.52,"mid":0.46,"spread":0.12,"price":0.41,"size":0.0,"side":"BUY"}
{"ts":"2026-08-23T17:52:51.832Z","event_type":"price_change","market_id":"3790334","outcome_index":0,"market_type":"set2","local_side":"home","local_uid":"2026-08-23_abdullah_shelbayh_dhakshineswar_suresh","bid":0.48,"ask":0.6,"mid":0.54,"spread":0.12,"price":0.59,"size":0.0,"side":"SELL"}
{"ts":"2026-08-23T17:52:51.867Z","event_type":"best_bid_ask","market_id":"3790334","outcome_index":0,"market_type":"set2","local_side":"home","local_uid":"2026-08-23_abdullah_shelbayh_dhakshineswar_suresh","bid":0.48,"ask":0.59,"mid":0.535,"spread":0.11,"bid_size":null,"ask_size":null}
{"ts":"2026-08-23T17:52:51.867Z","event_type":"best_bid_ask","market_id":"3790334","outcome_index":1,"market_type":"set2","local_side":"away","local_uid":"2026-08-23_abdullah_shelbayh_dhakshineswar_suresh","bid":0.41,"ask":0.52,"mid":0.465,"spread":0.11,"bid_size":null,"ask_size":null}
{"ts":"2026-08-23T17:52:51.868Z","event_type":"price_change","market_id":"3790334","outcome_index":1,"market_type":"set2","local_side":"away","local_uid":"2026-08-23_abdullah_shelbayh_dhakshineswar_suresh","bid":0.41,"ask":0.52,"mid":0.465,"spread":0.11,"price":0.41,"size":97.04,"side":"BUY"}
{"ts":"2026-08-23T17:52:51.868Z","event_type":"price_change","market_id":"3790334","outcome_index":0,"market_type":"set2","local_side":"home","local_uid":"2026-08-23_abdullah_shelbayh_dhakshineswar_suresh","bid":0.48,"ask":0.59,"mid":0.535,"spread":0.11,"price":0.59,"size":97.04,"side":"SELL"}
{"ts":"2026-08-23T17:52:51.897Z","event_type":"best_bid_ask","market_id":"3790334","outcome_index":0,"market_type":"set2","local_side":"home","local_uid":"2026-08-23_abdullah_shelbayh_dhakshineswar_suresh","bid":0.48,"ask":0.6,"mid":0.54,"spread":0.12,"bid_size":null,"ask_size":null}
{"ts":"2026-08-23T17:52:51.897Z","event_type":"best_bid_ask","market_id":"3790334","outcome_index":1,"market_type":"set2","local_side":"away","local_uid":"2026-08-23_abdullah_shelbayh_dhakshineswar_suresh","bid":0.4,"ask":0.52,"mid":0.46,"spread":0.12,"bid_size":null,"ask_size":null}
{"ts":"2026-08-23T17:52:51.897Z","event_type":"price_change","market_id":"3790334","outcome_index":1,"market_type":"set2","local_side":"away","local_uid":"2026-08-23_abdullah_shelbayh_dhakshineswar_suresh","bid":0.4,"ask":0.52,"mid":0.46,"spread":0.12,"price":0.41,"size":0.0,"side":"BUY"}
{"ts":"2026-08-23T17:52:51.897Z","event_type":"price_change","market_id":"3790334","outcome_index":0,"market_type":"set2","local_side":"home","local_uid":"2026-08-23_abdullah_shelbayh_dhakshineswar_suresh","bid":0.48,"ask":0.6,"mid":0.54,"spread":0.12,"price":0.59,"size":0.0,"side":"SELL"}
{"ts":"2026-08-23T17:52:51.947Z","event_type":"price_change","market_id":"3780844","outcome_index":0,"market_type":"match","local_side":"home","local_uid":"2026-08-23_pablo_carreno_busta_adolfo_daniel_vallejo","bid":0.56,"ask":0.57,"mid":0.565,"spread":0.01,"price":0.37,"size":30.0,"side":"BUY"}
{"ts":"2026-08-23T17:52:51.947Z","event_type":"price_change","market_id":"3780844","outcome_index":1,"market_type":"match","local_side":"away","local_uid":"2026-08-23_pablo_carreno_busta_adolfo_daniel_vallejo","bid":0.43,"ask":0.44,"mid":0.435,"spread":0.01,"price":0.63,"size":30.0,"side":"SELL"}
{"ts":"2026-08-23T17:52:53.259Z","event_type":"best_bid_ask","market_id":"3790394","outcome_index":0,"market_type":"set1","local_side":"home","local_uid":"2026-08-23_hugo_grenier_mees_rottgering","bid":0.18,"ask":0.26,"mid":0.22,"spread":0.08,"bid_size":null,"ask_size":null}
{"ts":"2026-08-23T17:52:53.259Z","event_type":"best_bid_ask","market_id":"3790394","outcome_index":1,"market_type":"set1","local_side":"away","local_uid":"2026-08-23_hugo_grenier_mees_rottgering","bid":0.74,"ask":0.82,"mid":0.78,"spread":0.08,"bid_size":null,"ask_size":null}
{"ts":"2026-08-23T17:52:53.259Z","event_type":"price_change","market_id":"3790394","outcome_index":1,"market_type":"set1","local_side":"away","local_uid":"2026-08-23_hugo_grenier_mees_rottgering","bid":0.74,"ask":0.82,"mid":0.78,"spread":0.08,"price":0.75,"size":0.0,"side":"BUY"}
{"ts":"2026-08-23T17:52:53.259Z","event_type":"price_change","market_id":"3790394","outcome_index":0,"market_type":"set1","local_side":"home","local_uid":"2026-08-23_hugo_grenier_mees_rottgering","bid":0.18,"ask":0.26,"mid":0.22,"spread":0.08,"price":0.25,"size":0.0,"side":"SELL"}
{"ts":"2026-08-23T17:52:53.260Z","event_type":"best_bid_ask","market_id":"3790394","outcome_index":0,"market_type":"set1","local_side":"home","local_uid":"2026-08-23_hugo_grenier_mees_rottgering","bid":0.17,"ask":0.26,"mid":0.215,"spread":0.09,"bid_size":null,"ask_size":null}
{"ts":"2026-08-23T17:52:53.260Z","event_type":"best_bid_ask","market_id":"3790394","outcome_index":1,"market_type":"set1","local_side":"away","local_uid":"2026-08-23_hugo_grenier_mees_rottgering","bid":0.74,"ask":0.83,"mid":0.785,"spread":0.09,"bid_size":null,"ask_size":null}
{"ts":"2026-08-23T17:52:53.263Z","event_type":"price_change","market_id":"3790394","outcome_index":0,"market_type":"set1","local_side":"home","local_uid":"2026-08-23_hugo_grenier_mees_rottgering","bid":0.17,"ask":0.26,"mid":0.215,"spread":0.09,"price":0.18,"size":0.0,"side":"BUY"}
{"ts":"2026-08-23T17:52:53.263Z","event_type":"price_change","market_id":"3790394","outcome_index":1,"market_type":"set1","local_side":"away","local_uid":"2026-08-23_hugo_grenier_mees_rottgering","bid":0.74,"ask":0.83,"mid":0.785,"spread":0.09,"price":0.82,"size":0.0,"side":"SELL"}
{"ts":"2026-08-23T17:52:53.289Z","event_type":"best_bid_ask","market_id":"3790397","outcome_index":0,"market_type":"set2","local_side":"home","local_uid":"2026-08-23_hugo_grenier_mees_rottgering","bid":0.27,"ask":0.39,"mid":0.33,"spread":0.12,"bid_size":null,"ask_size":null}
{"ts":"2026-08-23T17:52:53.290Z","event_type":"best_bid_ask","market_id":"3790397","outcome_index":1,"market_type":"set2","local_side":"away","local_uid":"2026-08-23_hugo_grenier_mees_rottgering","bid":0.61,"ask":0.73,"mid":0.67,"spread":0.12,"bid_size":null,"ask_size":null}
{"ts":"2026-08-23T17:52:53.290Z","event_type":"price_change","market_id":"3790397","outcome_index":1,"market_type":"set2","local_side":"away","local_uid":"2026-08-23_hugo_grenier_mees_rottgering","bid":0.61,"ask":0.73,"mid":0.67,"spread":0.12,"price":0.6,"size":0.0,"side":"BUY"}
{"ts":"2026-08-23T17:52:53.290Z","event_type":"price_change","market_id":"3790397","outcome_index":0,"market_type":"set2","local_side":"home","local_uid":"2026-08-23_hugo_grenier_mees_rottgering","bid":0.27,"ask":0.39,"mid":0.33,"spread":0.12,"price":0.4,"size":0.0,"side":"SELL"}
{"ts":"2026-08-23T17:52:53.323Z","event_type":"price_change","market_id":"3793888","outcome_index":0,"market_type":"set1","local_side":"home","local_uid":"2026-08-23_anna_bondar_en_shuo_liang","bid":0.69,"ask":0.72,"mid":0.705,"spread":0.03,"price":0.65,"size":181.0,"side":"BUY"}
{"ts":"2026-08-23T17:52:53.323Z","event_type":"price_change","market_id":"3793888","outcome_index":1,"market_type":"set1","local_side":"away","local_uid":"2026-08-23_anna_bondar_en_shuo_liang","bid":0.28,"ask":0.31,"mid":0.295,"spread":0.03,"price":0.35,"size":181.0,"side":"SELL"}
{"ts":"2026-08-23T17:52:53.337Z","event_type":"best_bid_ask","market_id":"3790397","outcome_index":0,"market_type":"set2","local_side":"home","local_uid":"2026-08-23_hugo_grenier_mees_rottgering","bid":0.28,"ask":0.39,"mid":0.335,"spread":0.11,"bid_size":null,"ask_size":null}
{"ts":"2026-08-23T17:52:53.337Z","event_type":"best_bid_ask","market_id":"3790397","outcome_index":1,"market_type":"set2","local_side":"away","local_uid":"2026-08-23_hugo_grenier_mees_rottgering","bid":0.61,"ask":0.72,"mid":0.665,"spread":0.11,"bid_size":null,"ask_size":null}
{"ts":"2026-08-23T17:52:53.337Z","event_type":"price_change","market_id":"3790397","outcome_index":0,"market_type":"set2","local_side":"home","local_uid":"2026-08-23_hugo_grenier_mees_rottgering","bid":0.28,"ask":0.39,"mid":0.335,"spread":0.11,"price":0.28,"size":125.46,"side":"BUY"}
{"ts":"2026-08-23T17:52:53.337Z","event_type":"price_change","market_id":"3790397","outcome_index":1,"market_type":"set2","local_side":"away","local_uid":"2026-08-23_hugo_grenier_mees_rottgering","bid":0.61,"ask":0.72,"mid":0.665,"spread":0.11,"price":0.72,"size":125.46,"side":"SELL"}
{"ts":"2026-08-23T17:52:53.346Z","event_type":"best_bid_ask","market_id":"3790397","outcome_index":0,"market_type":"set2","local_side":"home","local_uid":"2026-08-23_hugo_grenier_mees_rottgering","bid":0.28,"ask":0.42,"mid":0.35,"spread":0.14,"bid_size":null,"ask_size":null}
{"ts":"2026-08-23T17:52:53.346Z","event_type":"best_bid_ask","market_id":"3790397","outcome_index":1,"market_type":"set2","local_side":"away","local_uid":"2026-08-23_hugo_grenier_mees_rottgering","bid":0.58,"ask":0.72,"mid":0.65,"spread":0.14,"bid_size":null,"ask_size":null}
{"ts":"2026-08-23T17:52:53.346Z","event_type":"price_change","market_id":"3790397","outcome_index":1,"market_type":"set2","local_side":"away","local_uid":"2026-08-23_hugo_grenier_mees_rottgering","bid":0.58,"ask":0.72,"mid":0.65,"spread":0.14,"price":0.61,"size":0.0,"side":"BUY"}
{"ts":"2026-08-23T17:52:53.346Z","event_type":"price_change","market_id":"3790397","outcome_index":0,"market_type":"set2","local_side":"home","local_uid":"2026-08-23_hugo_grenier_mees_rottgering","bid":0.28,"ask":0.42,"mid":0.35,"spread":0.14,"price":0.39,"size":0.0,"side":"SELL"}
{"ts":"2026-08-23T17:52:53.347Z","event_type":"best_bid_ask","market_id":"3790394","outcome_index":0,"market_type":"set1","local_side":"home","local_uid":"2026-08-23_hugo_grenier_mees_rottgering","bid":0.17,"ask":1.0,"mid":0.585,"spread":0.83,"bid_size":null,"ask_size":null}
{"ts":"2026-08-23T17:52:53.347Z","event_type":"best_bid_ask","market_id":"3790394","outcome_index":1,"market_type":"set1","local_side":"away","local_uid":"2026-08-23_hugo_grenier_mees_rottgering","bid":0.0,"ask":0.83,"mid":0.415,"spread":0.83,"bid_size":null,"ask_size":null}
{"ts":"2026-08-23T17:52:53.347Z","event_type":"price_change","market_id":"3790394","outcome_index":1,"market_type":"set1","local_side":"away","local_uid":"2026-08-23_hugo_grenier_mees_rottgering","bid":0.0,"ask":0.83,"mid":0.415,"spread":0.83,"price":0.74,"size":0.0,"side":"BUY"}
{"ts":"2026-08-23T17:52:53.347Z","event_type":"price_change","market_id":"3790394","outcome_index":0,"market_type":"set1","local_side":"home","local_uid":"2026-08-23_hugo_grenier_mees_rottgering","bid":0.17,"ask":1.0,"mid":0.585,"spread":0.83,"price":0.26,"size":0.0,"side":"SELL"}
{"ts":"2026-08-23T17:52:53.386Z","event_type":"best_bid_ask","market_id":"3790397","outcome_index":0,"market_type":"set2","local_side":"home","local_uid":"2026-08-23_hugo_grenier_mees_rottgering","bid":0.28,"ask":0.4,"mid":0.34,"spread":0.12,"bid_size":null,"ask_size":null}
{"ts":"2026-08-23T17:52:53.387Z","event_type":"best_bid_ask","market_id":"3790397","outcome_index":1,"market_type":"set2","local_side":"away","local_uid":"2026-08-23_hugo_grenier_mees_rottgering","bid":0.6,"ask":0.72,"mid":0.66,"spread":0.12,"bid_size":null,"ask_size":null}
{"ts":"2026-08-23T17:52:53.387Z","event_type":"price_change","market_id":"3790397","outcome_index":1,"market_type":"set2","local_side":"away","local_uid":"2026-08-23_hugo_grenier_mees_rottgering","bid":0.6,"ask":0.72,"mid":0.66,"spread":0.12,"price":0.6,"size":31.98,"side":"BUY"}
{"ts":"2026-08-23T17:52:53.387Z","event_type":"price_change","market_id":"3790397","outcome_index":0,"market_type":"set2","local_side":"home","local_uid":"2026-08-23_hugo_grenier_mees_rottgering","bid":0.28,"ask":0.4,"mid":0.34,"spread":0.12,"price":0.4,"size":31.98,"side":"SELL"}
{"ts":"2026-08-23T17:52:53.400Z","event_type":"best_bid_ask","market_id":"3790394","outcome_index":0,"market_type":"set1","local_side":"home","local_uid":"2026-08-23_hugo_grenier_mees_rottgering","bid":0.16,"ask":1.0,"mid":0.58,"spread":0.84,"bid_size":null,"ask_size":null}
{"ts":"2026-08-23T17:52:53.400Z","event_type":"best_bid_ask","market_id":"3790394","outcome_index":1,"market_type":"set1","local_side":"away","local_uid":"2026-08-23_hugo_grenier_mees_rottgering","bid":0.0,"ask":0.84,"mid":0.42,"spread":0.84,"bid_size":null,"ask_size":null}
{"ts":"2026-08-23T17:52:53.400Z","event_type":"price_change","market_id":"3790394","outcome_index":0,"market_type":"set1","local_side":"home","local_uid":"2026-08-23_hugo_grenier_mees_rottgering","bid":0.16,"ask":1.0,"mid":0.58,"spread":0.84,"price":0.17,"size":0.0,"side":"BUY"}
{"ts":"2026-08-23T17:52:53.400Z","event_type":"price_change","market_id":"3790394","outcome_index":1,"market_type":"set1","local_side":"away","local_uid":"2026-08-23_hugo_grenier_mees_rottgering","bid":0.0,"ask":0.84,"mid":0.42,"spread":0.84,"price":0.83,"size":0.0,"side":"SELL"}
{"ts":"2026-08-23T17:52:53.495Z","event_type":"best_bid_ask","market_id":"3790394","outcome_index":0,"market_type":"set1","local_side":"home","local_uid":"2026-08-23_hugo_grenier_mees_rottgering","bid":0.16,"ask":0.36,"mid":0.26,"spread":0.2,"bid_size":null,"ask_size":null}
{"ts":"2026-08-23T17:52:53.495Z","event_type":"best_bid_ask","market_id":"3790394","outcome_index":1,"market_type":"set1","local_side":"away","local_uid":"2026-08-23_hugo_grenier_mees_rottgering","bid":0.64,"ask":0.84,"mid":0.74,"spread":0.2,"bid_size":null,"ask_size":null}
{"ts":"2026-08-23T17:52:53.495Z","event_type":"price_change","market_id":"3790394","outcome_index":1,"market_type":"set1","local_side":"away","local_uid":"2026-08-23_hugo_grenier_mees_rottgering","bid":0.64,"ask":0.84,"mid":0.74,"spread":0.2,"price":0.64,"size":6.0,"side":"BUY"}
{"ts":"2026-08-23T17:52:53.495Z","event_type":"price_change","market_id":"3790394","outcome_index":0,"market_type":"set1","local_side":"home","local_uid":"2026-08-23_hugo_grenier_mees_rottgering","bid":0.16,"ask":0.36,"mid":0.26,"spread":0.2,"price":0.36,"size":6.0,"side":"SELL"}
{"ts":"2026-08-23T17:52:53.498Z","event_type":"best_bid_ask","market_id":"3790394","outcome_index":0,"market_type":"set1","local_side":"home","local_uid":"2026-08-23_hugo_grenier_mees_rottgering","bid":0.16,"ask":0.35,"mid":0.255,"spread":0.19,"bid_size":null,"ask_size":null}
{"ts":"2026-08-23T17:52:53.498Z","event_type":"best_bid_ask","market_id":"3790394","outcome_index":1,"market_type":"set1","local_side":"away","local_uid":"2026-08-23_hugo_grenier_mees_rottgering","bid":0.65,"ask":0.84,"mid":0.745,"spread":0.19,"bid_size":null,"ask_size":null}
{"ts":"2026-08-23T17:52:53.498Z","event_type":"price_change","market_id":"3790394","outcome_index":1,"market_type":"set1","local_side":"away","local_uid":"2026-08-23_hugo_grenier_mees_rottgering","bid":0.65,"ask":0.84,"mid":0.745,"spread":0.19,"price":0.65,"size":5.0,"side":"BUY"}
{"ts":"2026-08-23T17:52:53.498Z","event_type":"price_change","market_id":"3790394","outcome_index":0,"market_type":"set1","local_side":"home","local_uid":"2026-08-23_hugo_grenier_mees_rottgering","bid":0.16,"ask":0.35,"mid":0.255,"spread":0.19,"price":0.35,"size":5.0,"side":"SELL"}
{"ts":"2026-08-23T17:52:53.512Z","event_type":"best_bid_ask","market_id":"3790394","outcome_index":0,"market_type":"set1","local_side":"home","local_uid":"2026-08-23_hugo_grenier_mees_rottgering","bid":0.15,"ask":0.35,"mid":0.25,"spread":0.2,"bid_size":null,"ask_size":null}
{"ts":"2026-08-23T17:52:53.512Z","event_type":"best_bid_ask","market_id":"3790394","outcome_index":1,"market_type":"set1","local_side":"away","local_uid":"2026-08-23_hugo_grenier_mees_rottgering","bid":0.65,"ask":0.85,"mid":0.75,"spread":0.2,"bid_size":null,"ask_size":null}
{"ts":"2026-08-23T17:52:53.512Z","event_type":"price_change","market_id":"3790394","outcome_index":0,"market_type":"set1","local_side":"home","local_uid":"2026-08-23_hugo_grenier_mees_rottgering","bid":0.15,"ask":0.35,"mid":0.25,"spread":0.2,"price":0.16,"size":0.0,"side":"BUY"}
{"ts":"2026-08-23T17:52:53.512Z","event_type":"price_change","market_id":"3790394","outcome_index":1,"market_type":"set1","local_side":"away","local_uid":"2026-08-23_hugo_grenier_mees_rottgering","bid":0.65,"ask":0.85,"mid":0.75,"spread":0.2,"price":0.84,"size":0.0,"side":"SELL"}
{"ts":"2026-08-23T17:52:53.513Z","event_type":"best_bid_ask","market_id":"3790394","outcome_index":0,"market_type":"set1","local_side":"home","local_uid":"2026-08-23_hugo_grenier_mees_rottgering","bid":0.13,"ask":0.35,"mid":0.24,"spread":0.22,"bid_size":null,"ask_size":null}
{"ts":"2026-08-23T17:52:53.514Z","event_type":"best_bid_ask","market_id":"3790394","outcome_index":1,"market_type":"set1","local_side":"away","local_uid":"2026-08-23_hugo_grenier_mees_rottgering","bid":0.65,"ask":0.87,"mid":0.76,"spread":0.22,"bid_size":null,"ask_size":null}
{"ts":"2026-08-23T17:52:53.514Z","event_type":"price_change","market_id":"3790394","outcome_index":0,"market_type":"set1","local_side":"home","local_uid":"2026-08-23_hugo_grenier_mees_rottgering","bid":0.13,"ask":0.35,"mid":0.24,"spread":0.22,"price":0.15,"size":0.0,"side":"BUY"}
{"ts":"2026-08-23T17:52:53.514Z","event_type":"price_change","market_id":"3790394","outcome_index":1,"market_type":"set1","local_side":"away","local_uid":"2026-08-23_hugo_grenier_mees_rottgering","bid":0.65,"ask":0.87,"mid":0.76,"spread":0.22,"price":0.85,"size":0.0,"side":"SELL"}
{"ts":"2026-08-23T17:52:53.542Z","event_type":"best_bid_ask","market_id":"3790394","outcome_index":0,"market_type":"set1","local_side":"home","local_uid":"2026-08-23_hugo_grenier_mees_rottgering","bid":0.07,"ask":0.35,"mid":0.21,"spread":0.28,"bid_size":null,"ask_size":null}
{"ts":"2026-08-23T17:52:53.542Z","event_type":"best_bid_ask","market_id":"3790394","outcome_index":1,"market_type":"set1","local_side":"away","local_uid":"2026-08-23_hugo_grenier_mees_rottgering","bid":0.65,"ask":0.93,"mid":0.79,"spread":0.28,"bid_size":null,"ask_size":null}
{"ts":"2026-08-23T17:52:53.542Z","event_type":"price_change","market_id":"3790394","outcome_index":0,"market_type":"set1","local_side":"home","local_uid":"2026-08-23_hugo_grenier_mees_rottgering","bid":0.07,"ask":0.35,"mid":0.21,"spread":0.28,"price":0.13,"size":0.0,"side":"BUY"}
{"ts":"2026-08-23T17:52:53.542Z","event_type":"price_change","market_id":"3790394","outcome_index":1,"market_type":"set1","local_side":"away","local_uid":"2026-08-23_hugo_grenier_mees_rottgering","bid":0.65,"ask":0.93,"mid":0.79,"spread":0.28,"price":0.87,"size":0.0,"side":"SELL"}
{"ts":"2026-08-23T17:52:53.690Z","event_type":"best_bid_ask","market_id":"3790394","outcome_index":0,"market_type":"set1","local_side":"home","local_uid":"2026-08-23_hugo_grenier_mees_rottgering","bid":0.0,"ask":0.35,"mid":0.175,"spread":0.35,"bid_size":null,"ask_size":null}
{"ts":"2026-08-23T17:52:53.690Z","event_type":"best_bid_ask","market_id":"3790394","outcome_index":1,"market_type":"set1","local_side":"away","local_uid":"2026-08-23_hugo_grenier_mees_rottgering","bid":0.65,"ask":1.0,"mid":0.825,"spread":0.35,"bid_size":null,"ask_size":null}
{"ts":"2026-08-23T17:52:53.690Z","event_type":"price_change","market_id":"3790394","outcome_index":0,"market_type":"set1","local_side":"home","local_uid":"2026-08-23_hugo_grenier_mees_rottgering","bid":0.0,"ask":0.35,"mid":0.175,"spread":0.35,"price":0.07,"size":0.0,"side":"BUY"}
{"ts":"2026-08-23T17:52:53.690Z","event_type":"price_change","market_id":"3790394","outcome_index":1,"market_type":"set1","local_side":"away","local_uid":"2026-08-23_hugo_grenier_mees_rottgering","bid":0.65,"ask":1.0,"mid":0.825,"spread":0.35,"price":0.93,"size":0.0,"side":"SELL"}
{"ts":"2026-08-23T17:52:53.732Z","event_type":"best_bid_ask","market_id":"3789927","outcome_index":0,"market_type":"match","local_side":"home","local_uid":"2026-08-23_hugo_grenier_mees_rottgering","bid":0.23,"ask":0.26,"mid":0.245,"spread":0.03,"bid_size":null,"ask_size":null}
{"ts":"2026-08-23T17:52:53.732Z","event_type":"best_bid_ask","market_id":"3789927","outcome_index":1,"market_type":"match","local_side":"away","local_uid":"2026-08-23_hugo_grenier_mees_rottgering","bid":0.74,"ask":0.77,"mid":0.755,"spread":0.03,"bid_size":null,"ask_size":null}
{"ts":"2026-08-23T17:52:53.732Z","event_type":"price_change","market_id":"3789927","outcome_index":1,"market_type":"match","local_side":"away","local_uid":"2026-08-23_hugo_grenier_mees_rottgering","bid":0.74,"ask":0.77,"mid":0.755,"spread":0.03,"price":0.75,"size":0.0,"side":"BUY"}
{"ts":"2026-08-23T17:52:53.732Z","event_type":"price_change","market_id":"3789927","outcome_index":0,"market_type":"match","local_side":"home","local_uid":"2026-08-23_hugo_grenier_mees_rottgering","bid":0.23,"ask":0.26,"mid":0.245,"spread":0.03,"price":0.25,"size":0.0,"side":"SELL"}
{"ts":"2026-08-23T17:52:54.190Z","event_type":"last_trade_price","market_id":"3789931","outcome_index":1,"market_type":"match","local_side":"away","local_uid":"2026-08-23_stefanos_sakellaridis_luca_van_assche","last_trade":0.94,"trade_size":9.99,"trade_side":"BUY","trade_notional":9.3906}
{"ts":"2026-08-23T17:52:54.303Z","event_type":"best_bid_ask","market_id":"3789927","outcome_index":0,"market_type":"match","local_side":"home","local_uid":"2026-08-23_hugo_grenier_mees_rottgering","bid":0.22,"ask":0.26,"mid":0.24,"spread":0.04,"bid_size":null,"ask_size":null}
{"ts":"2026-08-23T17:52:54.304Z","event_type":"best_bid_ask","market_id":"3789927","outcome_index":1,"market_type":"match","local_side":"away","local_uid":"2026-08-23_hugo_grenier_mees_rottgering","bid":0.74,"ask":0.78,"mid":0.76,"spread":0.04,"bid_size":null,"ask_size":null}
{"ts":"2026-08-23T17:52:54.304Z","event_type":"price_change","market_id":"3789927","outcome_index":0,"market_type":"match","local_side":"home","local_uid":"2026-08-23_hugo_grenier_mees_rottgering","bid":0.22,"ask":0.26,"mid":0.24,"spread":0.04,"price":0.23,"size":0.0,"side":"BUY"}
{"ts":"2026-08-23T17:52:54.304Z","event_type":"price_change","market_id":"3789927","outcome_index":1,"market_type":"match","local_side":"away","local_uid":"2026-08-23_hugo_grenier_mees_rottgering","bid":0.74,"ask":0.78,"mid":0.76,"spread":0.04,"price":0.77,"size":0.0,"side":"SELL"}
{"ts":"2026-08-23T17:52:54.668Z","event_type":"best_bid_ask","market_id":"3789997","outcome_index":0,"market_type":"match","local_side":"home","local_uid":"2026-08-23_oscar_weightman_alec_deckers","bid":0.06,"ask":0.1,"mid":0.08,"spread":0.04,"bid_size":null,"ask_size":null}
{"ts":"2026-08-23T17:52:54.668Z","event_type":"best_bid_ask","market_id":"3789997","outcome_index":1,"market_type":"match","local_side":"away","local_uid":"2026-08-23_oscar_weightman_alec_deckers","bid":0.9,"ask":0.94,"mid":0.92,"spread":0.04,"bid_size":null,"ask_size":null}
{"ts":"2026-08-23T17:52:54.668Z","event_type":"price_change","market_id":"3789997","outcome_index":1,"market_type":"match","local_side":"away","local_uid":"2026-08-23_oscar_weightman_alec_deckers","bid":0.9,"ask":0.94,"mid":0.92,"spread":0.04,"price":0.91,"size":0.0,"side":"SELL"}
{"ts":"2026-08-23T17:52:54.668Z","event_type":"price_change","market_id":"3789997","outcome_index":0,"market_type":"match","local_side":"home","local_uid":"2026-08-23_oscar_weightman_alec_deckers","bid":0.06,"ask":0.1,"mid":0.08,"spread":0.04,"price":0.09,"size":0.0,"side":"BUY"}
{"ts":"2026-08-23T17:52:54.720Z","event_type":"best_bid_ask","market_id":"3789997","outcome_index":0,"market_type":"match","local_side":"home","local_uid":"2026-08-23_oscar_weightman_alec_deckers","bid":0.06,"ask":0.09,"mid":0.075,"spread":0.03,"bid_size":null,"ask_size":null}
{"ts":"2026-08-23T17:52:54.721Z","event_type":"best_bid_ask","market_id":"3789997","outcome_index":1,"market_type":"match","local_side":"away","local_uid":"2026-08-23_oscar_weightman_alec_deckers","bid":0.91,"ask":0.94,"mid":0.925,"spread":0.03,"bid_size":null,"ask_size":null}
{"ts":"2026-08-23T17:52:54.721Z","event_type":"price_change","market_id":"3789997","outcome_index":1,"market_type":"match","local_side":"away","local_uid":"2026-08-23_oscar_weightman_alec_deckers","bid":0.91,"ask":0.94,"mid":0.925,"spread":0.03,"price":0.91,"size":67.0,"side":"BUY"}
{"ts":"2026-08-23T17:52:54.721Z","event_type":"price_change","market_id":"3789997","outcome_index":0,"market_type":"match","local_side":"home","local_uid":"2026-08-23_oscar_weightman_alec_deckers","bid":0.06,"ask":0.09,"mid":0.075,"spread":0.03,"price":0.09,"size":67.0,"side":"SELL"}
{"ts":"2026-08-23T17:52:54.751Z","event_type":"best_bid_ask","market_id":"3789997","outcome_index":0,"market_type":"match","local_side":"home","local_uid":"2026-08-23_oscar_weightman_alec_deckers","bid":0.06,"ask":0.1,"mid":0.08,"spread":0.04,"bid_size":null,"ask_size":null}
{"ts":"2026-08-23T17:52:54.751Z","event_type":"best_bid_ask","market_id":"3789997","outcome_index":1,"market_type":"match","local_side":"away","local_uid":"2026-08-23_oscar_weightman_alec_deckers","bid":0.9,"ask":0.94,"mid":0.92,"spread":0.04,"bid_size":null,"ask_size":null}
{"ts":"2026-08-23T17:52:54.751Z","event_type":"price_change","market_id":"3789997","outcome_index":0,"market_type":"match","local_side":"home","local_uid":"2026-08-23_oscar_weightman_alec_deckers","bid":0.06,"ask":0.1,"mid":0.08,"spread":0.04,"price":0.03,"size":1146.8,"side":"BUY"}
{"ts":"2026-08-23T17:52:54.751Z","event_type":"price_change","market_id":"3789997","outcome_index":1,"market_type":"match","local_side":"away","local_uid":"2026-08-23_oscar_weightman_alec_deckers","bid":0.9,"ask":0.94,"mid":0.92,"spread":0.04,"price":0.97,"size":1146.8,"side":"SELL"}
{"ts":"2026-08-23T17:52:54.840Z","event_type":"best_bid_ask","market_id":"3789997","outcome_index":0,"market_type":"match","local_side":"home","local_uid":"2026-08-23_oscar_weightman_alec_deckers","bid":0.06,"ask":0.09,"mid":0.075,"spread":0.03,"bid_size":null,"ask_size":null}
{"ts":"2026-08-23T17:52:54.840Z","event_type":"best_bid_ask","market_id":"3789997","outcome_index":1,"market_type":"match","local_side":"away","local_uid":"2026-08-23_oscar_weightman_alec_deckers","bid":0.91,"ask":0.94,"mid":0.925,"spread":0.03,"bid_size":null,"ask_size":null}
{"ts":"2026-08-23T17:52:54.841Z","event_type":"price_change","market_id":"3789997","outcome_index":1,"market_type":"match","local_side":"away","local_uid":"2026-08-23_oscar_weightman_alec_deckers","bid":0.91,"ask":0.94,"mid":0.925,"spread":0.03,"price":0.91,"size":66.0,"side":"BUY"}
{"ts":"2026-08-23T17:52:54.841Z","event_type":"price_change","market_id":"3789997","outcome_index":0,"market_type":"match","local_side":"home","local_uid":"2026-08-23_oscar_weightman_alec_deckers","bid":0.06,"ask":0.09,"mid":0.075,"spread":0.03,"price":0.09,"size":66.0,"side":"SELL"}
{"ts":"2026-08-23T17:52:54.868Z","event_type":"best_bid_ask","market_id":"3789997","outcome_index":0,"market_type":"match","local_side":"home","local_uid":"2026-08-23_oscar_weightman_alec_deckers","bid":0.06,"ask":0.1,"mid":0.08,"spread":0.04,"bid_size":null,"ask_size":null}
{"ts":"2026-08-23T17:52:54.868Z","event_type":"best_bid_ask","market_id":"3789997","outcome_index":1,"market_type":"match","local_side":"away","local_uid":"2026-08-23_oscar_weightman_alec_deckers","bid":0.9,"ask":0.94,"mid":0.92,"spread":0.04,"bid_size":null,"ask_size":null}
{"ts":"2026-08-23T17:52:54.868Z","event_type":"price_change","market_id":"3789997","outcome_index":0,"market_type":"match","local_side":"home","local_uid":"2026-08-23_oscar_weightman_alec_deckers","bid":0.06,"ask":0.1,"mid":0.08,"spread":0.04,"price":0.03,"size":1146.8,"side":"BUY"}
{"ts":"2026-08-23T17:52:54.868Z","event_type":"price_change","market_id":"3789997","outcome_index":1,"market_type":"match","local_side":"away","local_uid":"2026-08-23_oscar_weightman_alec_deckers","bid":0.9,"ask":0.94,"mid":0.92,"spread":0.04,"price":0.97,"size":1146.8,"side":"SELL"}
{"ts":"2026-08-23T17:52:55.070Z","event_type":"book","market_id":"3789925","outcome_index":0,"market_type":"match","local_side":"home","local_uid":"2026-08-23_pierre_hugues_herbert_quinn_vandecasteele","bid":0.84,"ask":0.85,"mid":0.845,"spread":0.01,"bid_size":24241.74,"ask_size":22538.39}
{"ts":"2026-08-23T17:52:55.070Z","event_type":"book","market_id":"3789925","outcome_index":1,"market_type":"match","local_side":"away","local_uid":"2026-08-23_pierre_hugues_herbert_quinn_vandecasteele","bid":0.15,"ask":0.16,"mid":0.155,"spread":0.01,"bid_size":22538.39,"ask_size":24241.74}
{"ts":"2026-08-23T17:52:55.122Z","event_type":"last_trade_price","market_id":"3789925","outcome_index":0,"market_type":"match","local_side":"home","local_uid":"2026-08-23_pierre_hugues_herbert_quinn_vandecasteele","last_trade":0.84,"trade_size":47.15,"trade_side":"SELL","trade_notional":39.606}
{"ts":"2026-08-23T17:52:55.162Z","event_type":"price_change","market_id":"3790322","outcome_index":1,"market_type":"set1","local_side":"away","local_uid":"2026-08-23_felix_balshaw_sebastian_gorzny","bid":0.999,"ask":1.0,"mid":0.9995,"spread":0.001,"price":0.01,"size":14111.0,"side":"BUY"}
{"ts":"2026-08-23T17:52:55.163Z","event_type":"price_change","market_id":"3790322","outcome_index":0,"market_type":"set1","local_side":"home","local_uid":"2026-08-23_felix_balshaw_sebastian_gorzny","bid":0.0,"ask":0.001,"mid":0.0005,"spread":0.001,"price":0.99,"size":14111.0,"side":"SELL"}
{"ts":"2026-08-23T17:52:55.314Z","event_type":"best_bid_ask","market_id":"3789927","outcome_index":0,"market_type":"match","local_side":"home","local_uid":"2026-08-23_hugo_grenier_mees_rottgering","bid":0.21,"ask":0.26,"mid":0.235,"spread":0.05,"bid_size":null,"ask_size":null}
{"ts":"2026-08-23T17:52:55.314Z","event_type":"best_bid_ask","market_id":"3789927","outcome_index":1,"market_type":"match","local_side":"away","local_uid":"2026-08-23_hugo_grenier_mees_rottgering","bid":0.74,"ask":0.79,"mid":0.765,"spread":0.05,"bid_size":null,"ask_size":null}
{"ts":"2026-08-23T17:52:55.315Z","event_type":"price_change","market_id":"3789927","outcome_index":0,"market_type":"match","local_side":"home","local_uid":"2026-08-23_hugo_grenier_mees_rottgering","bid":0.21,"ask":0.26,"mid":0.235,"spread":0.05,"price":0.22,"size":0.0,"side":"BUY"}
{"ts":"2026-08-23T17:52:55.315Z","event_type":"price_change","market_id":"3789927","outcome_index":1,"market_type":"match","local_side":"away","local_uid":"2026-08-23_hugo_grenier_mees_rottgering","bid":0.74,"ask":0.79,"mid":0.765,"spread":0.05,"price":0.78,"size":0.0,"side":"SELL"}
{"ts":"2026-08-23T17:52:55.319Z","event_type":"best_bid_ask","market_id":"3789927","outcome_index":0,"market_type":"match","local_side":"home","local_uid":"2026-08-23_hugo_grenier_mees_rottgering","bid":0.2,"ask":0.26,"mid":0.23,"spread":0.06,"bid_size":null,"ask_size":null}
{"ts":"2026-08-23T17:52:55.319Z","event_type":"best_bid_ask","market_id":"3789927","outcome_index":1,"market_type":"match","local_side":"away","local_uid":"2026-08-23_hugo_grenier_mees_rottgering","bid":0.74,"ask":0.8,"mid":0.77,"spread":0.06,"bid_size":null,"ask_size":null}
{"ts":"2026-08-23T17:52:55.320Z","event_type":"price_change","market_id":"3789927","outcome_index":0,"market_type":"match","local_side":"home","local_uid":"2026-08-23_hugo_grenier_mees_rottgering","bid":0.2,"ask":0.26,"mid":0.23,"spread":0.06,"price":0.21,"size":0.0,"side":"BUY"}
{"ts":"2026-08-23T17:52:55.320Z","event_type":"price_change","market_id":"3789927","outcome_index":1,"market_type":"match","local_side":"away","local_uid":"2026-08-23_hugo_grenier_mees_rottgering","bid":0.74,"ask":0.8,"mid":0.77,"spread":0.06,"price":0.79,"size":0.0,"side":"SELL"}
{"ts":"2026-08-23T17:52:55.694Z","event_type":"best_bid_ask","market_id":"3790394","outcome_index":0,"market_type":"set1","local_side":"home","local_uid":"2026-08-23_hugo_grenier_mees_rottgering","bid":0.08,"ask":0.35,"mid":0.215,"spread":0.27,"bid_size":null,"ask_size":null}
{"ts":"2026-08-23T17:52:55.694Z","event_type":"best_bid_ask","market_id":"3790394","outcome_index":1,"market_type":"set1","local_side":"away","local_uid":"2026-08-23_hugo_grenier_mees_rottgering","bid":0.65,"ask":0.92,"mid":0.785,"spread":0.27,"bid_size":null,"ask_size":null}
{"ts":"2026-08-23T17:52:55.695Z","event_type":"price_change","market_id":"3790394","outcome_index":0,"market_type":"set1","local_side":"home","local_uid":"2026-08-23_hugo_grenier_mees_rottgering","bid":0.08,"ask":0.35,"mid":0.215,"spread":0.27,"price":0.08,"size":21.16,"side":"BUY"}
{"ts":"2026-08-23T17:52:55.695Z","event_type":"price_change","market_id":"3790394","outcome_index":1,"market_type":"set1","local_side":"away","local_uid":"2026-08-23_hugo_grenier_mees_rottgering","bid":0.65,"ask":0.92,"mid":0.785,"spread":0.27,"price":0.92,"size":21.16,"side":"SELL"}
{"ts":"2026-08-23T17:52:55.726Z","event_type":"best_bid_ask","market_id":"3790334","outcome_index":0,"market_type":"set2","local_side":"home","local_uid":"2026-08-23_abdullah_shelbayh_dhakshineswar_suresh","bid":0.48,"ask":0.57,"mid":0.525,"spread":0.09,"bid_size":null,"ask_size":null}
{"ts":"2026-08-23T17:52:55.726Z","event_type":"best_bid_ask","market_id":"3790334","outcome_index":1,"market_type":"set2","local_side":"away","local_uid":"2026-08-23_abdullah_shelbayh_dhakshineswar_suresh","bid":0.43,"ask":0.52,"mid":0.475,"spread":0.09,"bid_size":null,"ask_size":null}
{"ts":"2026-08-23T17:52:55.726Z","event_type":"price_change","market_id":"3790334","outcome_index":1,"market_type":"set2","local_side":"away","local_uid":"2026-08-23_abdullah_shelbayh_dhakshineswar_suresh","bid":0.43,"ask":0.52,"mid":0.475,"spread":0.09,"price":0.43,"size":423.0,"side":"BUY"}
{"ts":"2026-08-23T17:52:55.726Z","event_type":"price_change","market_id":"3790334","outcome_index":0,"market_type":"set2","local_side":"home","local_uid":"2026-08-23_abdullah_shelbayh_dhakshineswar_suresh","bid":0.48,"ask":0.57,"mid":0.525,"spread":0.09,"price":0.57,"size":423.0,"side":"SELL"}
{"ts":"2026-08-23T17:52:55.733Z","event_type":"best_bid_ask","market_id":"3790334","outcome_index":0,"market_type":"set2","local_side":"home","local_uid":"2026-08-23_abdullah_shelbayh_dhakshineswar_suresh","bid":0.48,"ask":0.56,"mid":0.52,"spread":0.08,"bid_size":null,"ask_size":null}
{"ts":"2026-08-23T17:52:55.733Z","event_type":"best_bid_ask","market_id":"3790334","outcome_index":1,"market_type":"set2","local_side":"away","local_uid":"2026-08-23_abdullah_shelbayh_dhakshineswar_suresh","bid":0.44,"ask":0.52,"mid":0.48,"spread":0.08,"bid_size":null,"ask_size":null}
{"ts":"2026-08-23T17:52:55.733Z","event_type":"price_change","market_id":"3790334","outcome_index":1,"market_type":"set2","local_side":"away","local_uid":"2026-08-23_abdullah_shelbayh_dhakshineswar_suresh","bid":0.44,"ask":0.52,"mid":0.48,"spread":0.08,"price":0.44,"size":88.0,"side":"BUY"}
{"ts":"2026-08-23T17:52:55.733Z","event_type":"price_change","market_id":"3790334","outcome_index":0,"market_type":"set2","local_side":"home","local_uid":"2026-08-23_abdullah_shelbayh_dhakshineswar_suresh","bid":0.48,"ask":0.56,"mid":0.52,"spread":0.08,"price":0.56,"size":88.0,"side":"SELL"}
{"ts":"2026-08-23T17:52:55.896Z","event_type":"best_bid_ask","market_id":"3790334","outcome_index":0,"market_type":"set2","local_side":"home","local_uid":"2026-08-23_abdullah_shelbayh_dhakshineswar_suresh","bid":0.48,"ask":0.55,"mid":0.515,"spread":0.07,"bid_size":null,"ask_size":null}
{"ts":"2026-08-23T17:52:55.896Z","event_type":"best_bid_ask","market_id":"3790334","outcome_index":1,"market_type":"set2","local_side":"away","local_uid":"2026-08-23_abdullah_shelbayh_dhakshineswar_suresh","bid":0.45,"ask":0.52,"mid":0.485,"spread":0.07,"bid_size":null,"ask_size":null}
{"ts":"2026-08-23T17:52:55.896Z","event_type":"price_change","market_id":"3790334","outcome_index":1,"market_type":"set2","local_side":"away","local_uid":"2026-08-23_abdullah_shelbayh_dhakshineswar_suresh","bid":0.45,"ask":0.52,"mid":0.485,"spread":0.07,"price":0.45,"size":150.0,"side":"BUY"}
{"ts":"2026-08-23T17:52:55.896Z","event_type":"price_change","market_id":"3790334","outcome_index":0,"market_type":"set2","local_side":"home","local_uid":"2026-08-23_abdullah_shelbayh_dhakshineswar_suresh","bid":0.48,"ask":0.55,"mid":0.515,"spread":0.07,"price":0.55,"size":150.0,"side":"SELL"}
{"ts":"2026-08-23T17:52:55.913Z","event_type":"best_bid_ask","market_id":"3789927","outcome_index":0,"market_type":"match","local_side":"home","local_uid":"2026-08-23_hugo_grenier_mees_rottgering","bid":0.19,"ask":0.26,"mid":0.225,"spread":0.07,"bid_size":null,"ask_size":null}
{"ts":"2026-08-23T17:52:55.913Z","event_type":"best_bid_ask","market_id":"3789927","outcome_index":1,"market_type":"match","local_side":"away","local_uid":"2026-08-23_hugo_grenier_mees_rottgering","bid":0.74,"ask":0.81,"mid":0.775,"spread":0.07,"bid_size":null,"ask_size":null}
{"ts":"2026-08-23T17:52:55.913Z","event_type":"price_change","market_id":"3789927","outcome_index":0,"market_type":"match","local_side":"home","local_uid":"2026-08-23_hugo_grenier_mees_rottgering","bid":0.19,"ask":0.26,"mid":0.225,"spread":0.07,"price":0.2,"size":0.0,"side":"BUY"}
{"ts":"2026-08-23T17:52:55.913Z","event_type":"price_change","market_id":"3789927","outcome_index":1,"market_type":"match","local_side":"away","local_uid":"2026-08-23_hugo_grenier_mees_rottgering","bid":0.74,"ask":0.81,"mid":0.775,"spread":0.07,"price":0.8,"size":0.0,"side":"SELL"}
{"ts":"2026-08-23T17:52:56.220Z","event_type":"best_bid_ask","market_id":"3790415","outcome_index":0,"market_type":"set2","local_side":"home","local_uid":"2026-08-23_pierre_hugues_herbert_quinn_vandecasteele","bid":0.65,"ask":0.74,"mid":0.695,"spread":0.09,"bid_size":null,"ask_size":null}
{"ts":"2026-08-23T17:52:56.221Z","event_type":"best_bid_ask","market_id":"3790415","outcome_index":1,"market_type":"set2","local_side":"away","local_uid":"2026-08-23_pierre_hugues_herbert_quinn_vandecasteele","bid":0.26,"ask":0.35,"mid":0.305,"spread":0.09,"bid_size":null,"ask_size":null}
{"ts":"2026-08-23T17:52:56.221Z","event_type":"price_change","market_id":"3790415","outcome_index":0,"market_type":"set2","local_side":"home","local_uid":"2026-08-23_pierre_hugues_herbert_quinn_vandecasteele","bid":0.65,"ask":0.74,"mid":0.695,"spread":0.09,"price":0.66,"size":0.0,"side":"BUY"}
{"ts":"2026-08-23T17:52:56.221Z","event_type":"price_change","market_id":"3790415","outcome_index":1,"market_type":"set2","local_side":"away","local_uid":"2026-08-23_pierre_hugues_herbert_quinn_vandecasteele","bid":0.26,"ask":0.35,"mid":0.305,"spread":0.09,"price":0.34,"size":0.0,"side":"SELL"}
{"ts":"2026-08-23T17:52:56.229Z","event_type":"best_bid_ask","market_id":"3790415","outcome_index":0,"market_type":"set2","local_side":"home","local_uid":"2026-08-23_pierre_hugues_herbert_quinn_vandecasteele","bid":0.65,"ask":0.76,"mid":0.705,"spread":0.11,"bid_size":null,"ask_size":null}
{"ts":"2026-08-23T17:52:56.229Z","event_type":"best_bid_ask","market_id":"3790415","outcome_index":1,"market_type":"set2","local_side":"away","local_uid":"2026-08-23_pierre_hugues_herbert_quinn_vandecasteele","bid":0.24,"ask":0.35,"mid":0.295,"spread":0.11,"bid_size":null,"ask_size":null}
{"ts":"2026-08-23T17:52:56.230Z","event_type":"price_change","market_id":"3790415","outcome_index":1,"market_type":"set2","local_side":"away","local_uid":"2026-08-23_pierre_hugues_herbert_quinn_vandecasteele","bid":0.24,"ask":0.35,"mid":0.295,"spread":0.11,"price":0.26,"size":0.0,"side":"BUY"}
{"ts":"2026-08-23T17:52:56.230Z","event_type":"price_change","market_id":"3790415","outcome_index":0,"market_type":"set2","local_side":"home","local_uid":"2026-08-23_pierre_hugues_herbert_quinn_vandecasteele","bid":0.65,"ask":0.76,"mid":0.705,"spread":0.11,"price":0.74,"size":0.0,"side":"SELL"}
{"ts":"2026-08-23T17:52:56.250Z","event_type":"best_bid_ask","market_id":"3790415","outcome_index":0,"market_type":"set2","local_side":"home","local_uid":"2026-08-23_pierre_hugues_herbert_quinn_vandecasteele","bid":0.64,"ask":0.76,"mid":0.7,"spread":0.12,"bid_size":null,"ask_size":null}
{"ts":"2026-08-23T17:52:56.250Z","event_type":"best_bid_ask","market_id":"3790415","outcome_index":1,"market_type":"set2","local_side":"away","local_uid":"2026-08-23_pierre_hugues_herbert_quinn_vandecasteele","bid":0.24,"ask":0.36,"mid":0.3,"spread":0.12,"bid_size":null,"ask_size":null}
{"ts":"2026-08-23T17:52:56.250Z","event_type":"price_change","market_id":"3790415","outcome_index":0,"market_type":"set2","local_side":"home","local_uid":"2026-08-23_pierre_hugues_herbert_quinn_vandecasteele","bid":0.64,"ask":0.76,"mid":0.7,"spread":0.12,"price":0.65,"size":0.0,"side":"BUY"}
{"ts":"2026-08-23T17:52:56.250Z","event_type":"price_change","market_id":"3790415","outcome_index":1,"market_type":"set2","local_side":"away","local_uid":"2026-08-23_pierre_hugues_herbert_quinn_vandecasteele","bid":0.24,"ask":0.36,"mid":0.3,"spread":0.12,"price":0.35,"size":0.0,"side":"SELL"}
{"ts":"2026-08-23T17:52:56.254Z","event_type":"best_bid_ask","market_id":"3790415","outcome_index":0,"market_type":"set2","local_side":"home","local_uid":"2026-08-23_pierre_hugues_herbert_quinn_vandecasteele","bid":0.0,"ask":0.76,"mid":0.38,"spread":0.76,"bid_size":null,"ask_size":null}
{"ts":"2026-08-23T17:52:56.254Z","event_type":"best_bid_ask","market_id":"3790415","outcome_index":1,"market_type":"set2","local_side":"away","local_uid":"2026-08-23_pierre_hugues_herbert_quinn_vandecasteele","bid":0.24,"ask":1.0,"mid":0.62,"spread":0.76,"bid_size":null,"ask_size":null}
{"ts":"2026-08-23T17:52:56.254Z","event_type":"price_change","market_id":"3790415","outcome_index":0,"market_type":"set2","local_side":"home","local_uid":"2026-08-23_pierre_hugues_herbert_quinn_vandecasteele","bid":0.0,"ask":0.76,"mid":0.38,"spread":0.76,"price":0.64,"size":0.0,"side":"BUY"}
{"ts":"2026-08-23T17:52:56.255Z","event_type":"price_change","market_id":"3790415","outcome_index":1,"market_type":"set2","local_side":"away","local_uid":"2026-08-23_pierre_hugues_herbert_quinn_vandecasteele","bid":0.24,"ask":1.0,"mid":0.62,"spread":0.76,"price":0.36,"size":0.0,"side":"SELL"}
{"ts":"2026-08-23T17:52:56.262Z","event_type":"best_bid_ask","market_id":"3790415","outcome_index":0,"market_type":"set2","local_side":"home","local_uid":"2026-08-23_pierre_hugues_herbert_quinn_vandecasteele","bid":0.63,"ask":0.76,"mid":0.695,"spread":0.13,"bid_size":null,"ask_size":null}
{"ts":"2026-08-23T17:52:56.262Z","event_type":"best_bid_ask","market_id":"3790415","outcome_index":1,"market_type":"set2","local_side":"away","local_uid":"2026-08-23_pierre_hugues_herbert_quinn_vandecasteele","bid":0.24,"ask":0.37,"mid":0.305,"spread":0.13,"bid_size":null,"ask_size":null}
{"ts":"2026-08-23T17:52:56.262Z","event_type":"price_change","market_id":"3790415","outcome_index":0,"market_type":"set2","local_side":"home","local_uid":"2026-08-23_pierre_hugues_herbert_quinn_vandecasteele","bid":0.63,"ask":0.76,"mid":0.695,"spread":0.13,"price":0.63,"size":150.0,"side":"BUY"}
{"ts":"2026-08-23T17:52:56.262Z","event_type":"price_change","market_id":"3790415","outcome_index":1,"market_type":"set2","local_side":"away","local_uid":"2026-08-23_pierre_hugues_herbert_quinn_vandecasteele","bid":0.24,"ask":0.37,"mid":0.305,"spread":0.13,"price":0.37,"size":150.0,"side":"SELL"}
{"ts":"2026-08-23T17:52:56.263Z","event_type":"best_bid_ask","market_id":"3790415","outcome_index":0,"market_type":"set2","local_side":"home","local_uid":"2026-08-23_pierre_hugues_herbert_quinn_vandecasteele","bid":0.63,"ask":0.75,"mid":0.69,"spread":0.12,"bid_size":null,"ask_size":null}
{"ts":"2026-08-23T17:52:56.263Z","event_type":"best_bid_ask","market_id":"3790415","outcome_index":1,"market_type":"set2","local_side":"away","local_uid":"2026-08-23_pierre_hugues_herbert_quinn_vandecasteele","bid":0.25,"ask":0.37,"mid":0.31,"spread":0.12,"bid_size":null,"ask_size":null}
{"ts":"2026-08-23T17:52:56.263Z","event_type":"price_change","market_id":"3790415","outcome_index":1,"market_type":"set2","local_side":"away","local_uid":"2026-08-23_pierre_hugues_herbert_quinn_vandecasteele","bid":0.25,"ask":0.37,"mid":0.31,"spread":0.12,"price":0.25,"size":35.92,"side":"BUY"}
{"ts":"2026-08-23T17:52:56.263Z","event_type":"price_change","market_id":"3790415","outcome_index":0,"market_type":"set2","local_side":"home","local_uid":"2026-08-23_pierre_hugues_herbert_quinn_vandecasteele","bid":0.63,"ask":0.75,"mid":0.69,"spread":0.12,"price":0.75,"size":35.92,"side":"SELL"}
{"ts":"2026-08-23T17:52:56.278Z","event_type":"best_bid_ask","market_id":"3790394","outcome_index":0,"market_type":"set1","local_side":"home","local_uid":"2026-08-23_hugo_grenier_mees_rottgering","bid":0.08,"ask":0.34,"mid":0.21,"spread":0.26,"bid_size":null,"ask_size":null}
{"ts":"2026-08-23T17:52:56.278Z","event_type":"best_bid_ask","market_id":"3790394","outcome_index":1,"market_type":"set1","local_side":"away","local_uid":"2026-08-23_hugo_grenier_mees_rottgering","bid":0.66,"ask":0.92,"mid":0.79,"spread":0.26,"bid_size":null,"ask_size":null}
{"ts":"2026-08-23T17:52:56.279Z","event_type":"price_change","market_id":"3790394","outcome_index":1,"market_type":"set1","local_side":"away","local_uid":"2026-08-23_hugo_grenier_mees_rottgering","bid":0.66,"ask":0.92,"mid":0.79,"spread":0.26,"price":0.66,"size":119.33,"side":"BUY"}
{"ts":"2026-08-23T17:52:56.279Z","event_type":"price_change","market_id":"3790394","outcome_index":0,"market_type":"set1","local_side":"home","local_uid":"2026-08-23_hugo_grenier_mees_rottgering","bid":0.08,"ask":0.34,"mid":0.21,"spread":0.26,"price":0.34,"size":119.33,"side":"SELL"}
{"ts":"2026-08-23T17:52:56.382Z","event_type":"best_bid_ask","market_id":"3790415","outcome_index":0,"market_type":"set2","local_side":"home","local_uid":"2026-08-23_pierre_hugues_herbert_quinn_vandecasteele","bid":0.63,"ask":0.76,"mid":0.695,"spread":0.13,"bid_size":null,"ask_size":null}
{"ts":"2026-08-23T17:52:56.382Z","event_type":"best_bid_ask","market_id":"3790415","outcome_index":1,"market_type":"set2","local_side":"away","local_uid":"2026-08-23_pierre_hugues_herbert_quinn_vandecasteele","bid":0.24,"ask":0.37,"mid":0.305,"spread":0.13,"bid_size":null,"ask_size":null}
{"ts":"2026-08-23T17:52:56.382Z","event_type":"price_change","market_id":"3790415","outcome_index":1,"market_type":"set2","local_side":"away","local_uid":"2026-08-23_pierre_hugues_herbert_quinn_vandecasteele","bid":0.24,"ask":0.37,"mid":0.305,"spread":0.13,"price":0.25,"size":0.0,"side":"BUY"}
{"ts":"2026-08-23T17:52:56.382Z","event_type":"price_change","market_id":"3790415","outcome_index":0,"market_type":"set2","local_side":"home","local_uid":"2026-08-23_pierre_hugues_herbert_quinn_vandecasteele","bid":0.63,"ask":0.76,"mid":0.695,"spread":0.13,"price":0.75,"size":0.0,"side":"SELL"}
{"ts":"2026-08-23T17:52:56.398Z","event_type":"price_change","market_id":"3789987","outcome_index":1,"market_type":"match","local_side":"away","local_uid":"2026-08-23_mika_petkovic_federico_iannaccone","bid":0.999,"ask":1.0,"mid":0.9995,"spread":0.001,"price":0.013,"size":44000.0,"side":"BUY"}
{"ts":"2026-08-23T17:52:56.398Z","event_type":"price_change","market_id":"3789987","outcome_index":0,"market_type":"match","local_side":"home","local_uid":"2026-08-23_mika_petkovic_federico_iannaccone","bid":0.0,"ask":0.001,"mid":0.0005,"spread":0.001,"price":0.987,"size":44000.0,"side":"SELL"}
{"ts":"2026-08-23T17:52:56.400Z","event_type":"best_bid_ask","market_id":"3790415","outcome_index":0,"market_type":"set2","local_side":"home","local_uid":"2026-08-23_pierre_hugues_herbert_quinn_vandecasteele","bid":0.63,"ask":1.0,"mid":0.815,"spread":0.37,"bid_size":null,"ask_size":null}
{"ts":"2026-08-23T17:52:56.400Z","event_type":"best_bid_ask","market_id":"3790415","outcome_index":1,"market_type":"set2","local_side":"away","local_uid":"2026-08-23_pierre_hugues_herbert_quinn_vandecasteele","bid":0.0,"ask":0.37,"mid":0.185,"spread":0.37,"bid_size":null,"ask_size":null}
{"ts":"2026-08-23T17:52:56.400Z","event_type":"price_change","market_id":"3790415","outcome_index":1,"market_type":"set2","local_side":"away","local_uid":"2026-08-23_pierre_hugues_herbert_quinn_vandecasteele","bid":0.0,"ask":0.37,"mid":0.185,"spread":0.37,"price":0.24,"size":0.0,"side":"BUY"}
{"ts":"2026-08-23T17:52:56.400Z","event_type":"price_change","market_id":"3790415","outcome_index":0,"market_type":"set2","local_side":"home","local_uid":"2026-08-23_pierre_hugues_herbert_quinn_vandecasteele","bid":0.63,"ask":1.0,"mid":0.815,"spread":0.37,"price":0.76,"size":0.0,"side":"SELL"}
{"ts":"2026-08-23T17:52:56.412Z","event_type":"best_bid_ask","market_id":"3790415","outcome_index":0,"market_type":"set2","local_side":"home","local_uid":"2026-08-23_pierre_hugues_herbert_quinn_vandecasteele","bid":0.63,"ask":0.75,"mid":0.69,"spread":0.12,"bid_size":null,"ask_size":null}
{"ts":"2026-08-23T17:52:56.413Z","event_type":"best_bid_ask","market_id":"3790415","outcome_index":1,"market_type":"set2","local_side":"away","local_uid":"2026-08-23_pierre_hugues_herbert_quinn_vandecasteele","bid":0.25,"ask":0.37,"mid":0.31,"spread":0.12,"bid_size":null,"ask_size":null}
{"ts":"2026-08-23T17:52:56.413Z","event_type":"price_change","market_id":"3790415","outcome_index":1,"market_type":"set2","local_side":"away","local_uid":"2026-08-23_pierre_hugues_herbert_quinn_vandecasteele","bid":0.25,"ask":0.37,"mid":0.31,"spread":0.12,"price":0.25,"size":26.28,"side":"BUY"}
{"ts":"2026-08-23T17:52:56.413Z","event_type":"price_change","market_id":"3790415","outcome_index":0,"market_type":"set2","local_side":"home","local_uid":"2026-08-23_pierre_hugues_herbert_quinn_vandecasteele","bid":0.63,"ask":0.75,"mid":0.69,"spread":0.12,"price":0.75,"size":26.28,"side":"SELL"}
{"ts":"2026-08-23T17:52:56.426Z","event_type":"best_bid_ask","market_id":"3790415","outcome_index":0,"market_type":"set2","local_side":"home","local_uid":"2026-08-23_pierre_hugues_herbert_quinn_vandecasteele","bid":0.64,"ask":0.75,"mid":0.695,"spread":0.11,"bid_size":null,"ask_size":null}
{"ts":"2026-08-23T17:52:56.426Z","event_type":"best_bid_ask","market_id":"3790415","outcome_index":1,"market_type":"set2","local_side":"away","local_uid":"2026-08-23_pierre_hugues_herbert_quinn_vandecasteele","bid":0.25,"ask":0.36,"mid":0.305,"spread":0.11,"bid_size":null,"ask_size":null}
{"ts":"2026-08-23T17:52:56.426Z","event_type":"price_change","market_id":"3790415","outcome_index":0,"market_type":"set2","local_side":"home","local_uid":"2026-08-23_pierre_hugues_herbert_quinn_vandecasteele","bid":0.64,"ask":0.75,"mid":0.695,"spread":0.11,"price":0.64,"size":31.49,"side":"BUY"}
{"ts":"2026-08-23T17:52:56.426Z","event_type":"price_change","market_id":"3790415","outcome_index":1,"market_type":"set2","local_side":"away","local_uid":"2026-08-23_pierre_hugues_herbert_quinn_vandecasteele","bid":0.25,"ask":0.36,"mid":0.305,"spread":0.11,"price":0.36,"size":31.49,"side":"SELL"}
{"ts":"2026-08-23T17:52:56.648Z","event_type":"best_bid_ask","market_id":"3790334","outcome_index":0,"market_type":"set2","local_side":"home","local_uid":"2026-08-23_abdullah_shelbayh_dhakshineswar_suresh","bid":0.48,"ask":0.54,"mid":0.51,"spread":0.06,"bid_size":null,"ask_size":null}
{"ts":"2026-08-23T17:52:56.648Z","event_type":"best_bid_ask","market_id":"3790334","outcome_index":1,"market_type":"set2","local_side":"away","local_uid":"2026-08-23_abdullah_shelbayh_dhakshineswar_suresh","bid":0.46,"ask":0.52,"mid":0.49,"spread":0.06,"bid_size":null,"ask_size":null}
{"ts":"2026-08-23T17:52:56.648Z","event_type":"price_change","market_id":"3790334","outcome_index":1,"market_type":"set2","local_side":"away","local_uid":"2026-08-23_abdullah_shelbayh_dhakshineswar_suresh","bid":0.46,"ask":0.52,"mid":0.49,"spread":0.06,"price":0.46,"size":150.0,"side":"BUY"}
{"ts":"2026-08-23T17:52:56.648Z","event_type":"price_change","market_id":"3790334","outcome_index":0,"market_type":"set2","local_side":"home","local_uid":"2026-08-23_abdullah_shelbayh_dhakshineswar_suresh","bid":0.48,"ask":0.54,"mid":0.51,"spread":0.06,"price":0.54,"size":150.0,"side":"SELL"}
{"ts":"2026-08-23T17:52:56.938Z","event_type":"best_bid_ask","market_id":"3790334","outcome_index":0,"market_type":"set2","local_side":"home","local_uid":"2026-08-23_abdullah_shelbayh_dhakshineswar_suresh","bid":0.48,"ask":0.53,"mid":0.505,"spread":0.05,"bid_size":null,"ask_size":null}
{"ts":"2026-08-23T17:52:56.938Z","event_type":"best_bid_ask","market_id":"3790334","outcome_index":1,"market_type":"set2","local_side":"away","local_uid":"2026-08-23_abdullah_shelbayh_dhakshineswar_suresh","bid":0.47,"ask":0.52,"mid":0.495,"spread":0.05,"bid_size":null,"ask_size":null}
{"ts":"2026-08-23T17:52:56.938Z","event_type":"price_change","market_id":"3790334","outcome_index":1,"market_type":"set2","local_side":"away","local_uid":"2026-08-23_abdullah_shelbayh_dhakshineswar_suresh","bid":0.47,"ask":0.52,"mid":0.495,"spread":0.05,"price":0.47,"size":150.0,"side":"BUY"}
{"ts":"2026-08-23T17:52:56.938Z","event_type":"price_change","market_id":"3790334","outcome_index":0,"market_type":"set2","local_side":"home","local_uid":"2026-08-23_abdullah_shelbayh_dhakshineswar_suresh","bid":0.48,"ask":0.53,"mid":0.505,"spread":0.05,"price":0.53,"size":150.0,"side":"SELL"}
{"ts":"2026-08-23T17:52:56.954Z","event_type":"best_bid_ask","market_id":"3789997","outcome_index":0,"market_type":"match","local_side":"home","local_uid":"2026-08-23_oscar_weightman_alec_deckers","bid":0.05,"ask":0.1,"mid":0.075,"spread":0.05,"bid_size":null,"ask_size":null}
{"ts":"2026-08-23T17:52:56.954Z","event_type":"best_bid_ask","market_id":"3789997","outcome_index":1,"market_type":"match","local_side":"away","local_uid":"2026-08-23_oscar_weightman_alec_deckers","bid":0.9,"ask":0.95,"mid":0.925,"spread":0.05,"bid_size":null,"ask_size":null}
{"ts":"2026-08-23T17:52:56.954Z","event_type":"price_change","market_id":"3789997","outcome_index":0,"market_type":"match","local_side":"home","local_uid":"2026-08-23_oscar_weightman_alec_deckers","bid":0.05,"ask":0.1,"mid":0.075,"spread":0.05,"price":0.06,"size":0.0,"side":"BUY"}
{"ts":"2026-08-23T17:52:56.954Z","event_type":"price_change","market_id":"3789997","outcome_index":1,"market_type":"match","local_side":"away","local_uid":"2026-08-23_oscar_weightman_alec_deckers","bid":0.9,"ask":0.95,"mid":0.925,"spread":0.05,"price":0.94,"size":0.0,"side":"SELL"}
{"ts":"2026-08-23T17:52:56.974Z","event_type":"best_bid_ask","market_id":"3789997","outcome_index":0,"market_type":"match","local_side":"home","local_uid":"2026-08-23_oscar_weightman_alec_deckers","bid":0.06,"ask":0.1,"mid":0.08,"spread":0.04,"bid_size":null,"ask_size":null}
{"ts":"2026-08-23T17:52:56.975Z","event_type":"best_bid_ask","market_id":"3789997","outcome_index":1,"market_type":"match","local_side":"away","local_uid":"2026-08-23_oscar_weightman_alec_deckers","bid":0.9,"ask":0.94,"mid":0.92,"spread":0.04,"bid_size":null,"ask_size":null}
{"ts":"2026-08-23T17:52:56.975Z","event_type":"price_change","market_id":"3789997","outcome_index":0,"market_type":"match","local_side":"home","local_uid":"2026-08-23_oscar_weightman_alec_deckers","bid":0.06,"ask":0.1,"mid":0.08,"spread":0.04,"price":0.06,"size":10.0,"side":"BUY"}
{"ts":"2026-08-23T17:52:56.975Z","event_type":"price_change","market_id":"3789997","outcome_index":1,"market_type":"match","local_side":"away","local_uid":"2026-08-23_oscar_weightman_alec_deckers","bid":0.9,"ask":0.94,"mid":0.92,"spread":0.04,"price":0.94,"size":10.0,"side":"SELL"}
{"ts":"2026-08-23T17:52:56.975Z","event_type":"best_bid_ask","market_id":"3790334","outcome_index":0,"market_type":"set2","local_side":"home","local_uid":"2026-08-23_abdullah_shelbayh_dhakshineswar_suresh","bid":0.48,"ask":0.54,"mid":0.51,"spread":0.06,"bid_size":null,"ask_size":null}
{"ts":"2026-08-23T17:52:56.975Z","event_type":"best_bid_ask","market_id":"3790334","outcome_index":1,"market_type":"set2","local_side":"away","local_uid":"2026-08-23_abdullah_shelbayh_dhakshineswar_suresh","bid":0.46,"ask":0.52,"mid":0.49,"spread":0.06,"bid_size":null,"ask_size":null}
{"ts":"2026-08-23T17:52:56.975Z","event_type":"price_change","market_id":"3790334","outcome_index":1,"market_type":"set2","local_side":"away","local_uid":"2026-08-23_abdullah_shelbayh_dhakshineswar_suresh","bid":0.46,"ask":0.52,"mid":0.49,"spread":0.06,"price":0.47,"size":0.0,"side":"BUY"}
{"ts":"2026-08-23T17:52:56.975Z","event_type":"price_change","market_id":"3790334","outcome_index":0,"market_type":"set2","local_side":"home","local_uid":"2026-08-23_abdullah_shelbayh_dhakshineswar_suresh","bid":0.48,"ask":0.54,"mid":0.51,"spread":0.06,"price":0.53,"size":0.0,"side":"SELL"}
{"ts":"2026-08-23T17:52:56.987Z","event_type":"best_bid_ask","market_id":"3789927","outcome_index":0,"market_type":"match","local_side":"home","local_uid":"2026-08-23_hugo_grenier_mees_rottgering","bid":0.24,"ask":0.26,"mid":0.25,"spread":0.02,"bid_size":null,"ask_size":null}
{"ts":"2026-08-23T17:52:56.987Z","event_type":"best_bid_ask","market_id":"3789927","outcome_index":1,"market_type":"match","local_side":"away","local_uid":"2026-08-23_hugo_grenier_mees_rottgering","bid":0.74,"ask":0.76,"mid":0.75,"spread":0.02,"bid_size":null,"ask_size":null}
{"ts":"2026-08-23T17:52:56.987Z","event_type":"price_change","market_id":"3789927","outcome_index":0,"market_type":"match","local_side":"home","local_uid":"2026-08-23_hugo_grenier_mees_rottgering","bid":0.24,"ask":0.26,"mid":0.25,"spread":0.02,"price":0.24,"size":6000.0,"side":"BUY"}
{"ts":"2026-08-23T17:52:56.987Z","event_type":"price_change","market_id":"3789927","outcome_index":1,"market_type":"match","local_side":"away","local_uid":"2026-08-23_hugo_grenier_mees_rottgering","bid":0.74,"ask":0.76,"mid":0.75,"spread":0.02,"price":0.76,"size":6000.0,"side":"SELL"}
{"ts":"2026-08-23T17:52:57.010Z","event_type":"best_bid_ask","market_id":"3790334","outcome_index":0,"market_type":"set2","local_side":"home","local_uid":"2026-08-23_abdullah_shelbayh_dhakshineswar_suresh","bid":0.48,"ask":0.53,"mid":0.505,"spread":0.05,"bid_size":null,"ask_size":null}
{"ts":"2026-08-23T17:52:57.010Z","event_type":"best_bid_ask","market_id":"3790334","outcome_index":1,"market_type":"set2","local_side":"away","local_uid":"2026-08-23_abdullah_shelbayh_dhakshineswar_suresh","bid":0.47,"ask":0.52,"mid":0.495,"spread":0.05,"bid_size":null,"ask_size":null}
{"ts":"2026-08-23T17:52:57.010Z","event_type":"price_change","market_id":"3790334","outcome_index":1,"market_type":"set2","local_side":"away","local_uid":"2026-08-23_abdullah_shelbayh_dhakshineswar_suresh","bid":0.47,"ask":0.52,"mid":0.495,"spread":0.05,"price":0.47,"size":150.0,"side":"BUY"}
{"ts":"2026-08-23T17:52:57.010Z","event_type":"price_change","market_id":"3790334","outcome_index":0,"market_type":"set2","local_side":"home","local_uid":"2026-08-23_abdullah_shelbayh_dhakshineswar_suresh","bid":0.48,"ask":0.53,"mid":0.505,"spread":0.05,"price":0.53,"size":150.0,"side":"SELL"}
{"ts":"2026-08-23T17:52:57.016Z","event_type":"best_bid_ask","market_id":"3789927","outcome_index":0,"market_type":"match","local_side":"home","local_uid":"2026-08-23_hugo_grenier_mees_rottgering","bid":0.19,"ask":0.26,"mid":0.225,"spread":0.07,"bid_size":null,"ask_size":null}
{"ts":"2026-08-23T17:52:57.016Z","event_type":"best_bid_ask","market_id":"3789927","outcome_index":1,"market_type":"match","local_side":"away","local_uid":"2026-08-23_hugo_grenier_mees_rottgering","bid":0.74,"ask":0.81,"mid":0.775,"spread":0.07,"bid_size":null,"ask_size":null}
{"ts":"2026-08-23T17:52:57.016Z","event_type":"price_change","market_id":"3789927","outcome_index":0,"market_type":"match","local_side":"home","local_uid":"2026-08-23_hugo_grenier_mees_rottgering","bid":0.19,"ask":0.26,"mid":0.225,"spread":0.07,"price":0.24,"size":0.0,"side":"BUY"}
{"ts":"2026-08-23T17:52:57.017Z","event_type":"price_change","market_id":"3789927","outcome_index":1,"market_type":"match","local_side":"away","local_uid":"2026-08-23_hugo_grenier_mees_rottgering","bid":0.74,"ask":0.81,"mid":0.775,"spread":0.07,"price":0.76,"size":0.0,"side":"SELL"}
{"ts":"2026-08-23T17:52:57.070Z","event_type":"best_bid_ask","market_id":"3789927","outcome_index":0,"market_type":"match","local_side":"home","local_uid":"2026-08-23_hugo_grenier_mees_rottgering","bid":0.19,"ask":0.27,"mid":0.23,"spread":0.08,"bid_size":null,"ask_size":null}
{"ts":"2026-08-23T17:52:57.070Z","event_type":"best_bid_ask","market_id":"3789927","outcome_index":1,"market_type":"match","local_side":"away","local_uid":"2026-08-23_hugo_grenier_mees_rottgering","bid":0.73,"ask":0.81,"mid":0.77,"spread":0.08,"bid_size":null,"ask_size":null}
{"ts":"2026-08-23T17:52:57.070Z","event_type":"price_change","market_id":"3789927","outcome_index":1,"market_type":"match","local_side":"away","local_uid":"2026-08-23_hugo_grenier_mees_rottgering","bid":0.73,"ask":0.81,"mid":0.77,"spread":0.08,"price":0.74,"size":0.0,"side":"BUY"}
{"ts":"2026-08-23T17:52:57.070Z","event_type":"price_change","market_id":"3789927","outcome_index":0,"market_type":"match","local_side":"home","local_uid":"2026-08-23_hugo_grenier_mees_rottgering","bid":0.19,"ask":0.27,"mid":0.23,"spread":0.08,"price":0.26,"size":0.0,"side":"SELL"}
{"ts":"2026-08-23T17:52:57.071Z","event_type":"book","market_id":"3789927","outcome_index":0,"market_type":"match","local_side":"home","local_uid":"2026-08-23_hugo_grenier_mees_rottgering","bid":0.19,"ask":0.27,"mid":0.23,"spread":0.08,"bid_size":115.0,"ask_size":925.0}
{"ts":"2026-08-23T17:52:57.071Z","event_type":"book","market_id":"3789927","outcome_index":1,"market_type":"match","local_side":"away","local_uid":"2026-08-23_hugo_grenier_mees_rottgering","bid":0.73,"ask":0.81,"mid":0.77,"spread":0.08,"bid_size":925.0,"ask_size":115.0}
{"ts":"2026-08-23T17:52:57.071Z","event_type":"best_bid_ask","market_id":"3789927","outcome_index":0,"market_type":"match","local_side":"home","local_uid":"2026-08-23_hugo_grenier_mees_rottgering","bid":0.25,"ask":0.27,"mid":0.26,"spread":0.02,"bid_size":null,"ask_size":null}
{"ts":"2026-08-23T17:52:57.071Z","event_type":"best_bid_ask","market_id":"3789927","outcome_index":1,"market_type":"match","local_side":"away","local_uid":"2026-08-23_hugo_grenier_mees_rottgering","bid":0.73,"ask":0.75,"mid":0.74,"spread":0.02,"bid_size":null,"ask_size":null}
{"ts":"2026-08-23T17:52:57.072Z","event_type":"price_change","market_id":"3789927","outcome_index":0,"market_type":"match","local_side":"home","local_uid":"2026-08-23_hugo_grenier_mees_rottgering","bid":0.25,"ask":0.27,"mid":0.26,"spread":0.02,"price":0.25,"size":191.0,"side":"BUY"}
{"ts":"2026-08-23T17:52:57.072Z","event_type":"price_change","market_id":"3789927","outcome_index":1,"market_type":"match","local_side":"away","local_uid":"2026-08-23_hugo_grenier_mees_rottgering","bid":0.73,"ask":0.75,"mid":0.74,"spread":0.02,"price":0.75,"size":191.0,"side":"SELL"}
{"ts":"2026-08-23T17:52:57.096Z","event_type":"best_bid_ask","market_id":"3789927","outcome_index":0,"market_type":"match","local_side":"home","local_uid":"2026-08-23_hugo_grenier_mees_rottgering","bid":0.2,"ask":0.27,"mid":0.235,"spread":0.07,"bid_size":null,"ask_size":null}
{"ts":"2026-08-23T17:52:57.096Z","event_type":"best_bid_ask","market_id":"3789927","outcome_index":1,"market_type":"match","local_side":"away","local_uid":"2026-08-23_hugo_grenier_mees_rottgering","bid":0.73,"ask":0.8,"mid":0.765,"spread":0.07,"bid_size":null,"ask_size":null}
{"ts":"2026-08-23T17:52:57.096Z","event_type":"price_change","market_id":"3789927","outcome_index":0,"market_type":"match","local_side":"home","local_uid":"2026-08-23_hugo_grenier_mees_rottgering","bid":0.2,"ask":0.27,"mid":0.235,"spread":0.07,"price":0.25,"size":0.0,"side":"BUY"}
{"ts":"2026-08-23T17:52:57.096Z","event_type":"price_change","market_id":"3789927","outcome_index":1,"market_type":"match","local_side":"away","local_uid":"2026-08-23_hugo_grenier_mees_rottgering","bid":0.73,"ask":0.8,"mid":0.765,"spread":0.07,"price":0.75,"size":0.0,"side":"SELL"}
{"ts":"2026-08-23T17:52:57.114Z","event_type":"best_bid_ask","market_id":"3789927","outcome_index":0,"market_type":"match","local_side":"home","local_uid":"2026-08-23_hugo_grenier_mees_rottgering","bid":0.22,"ask":0.27,"mid":0.245,"spread":0.05,"bid_size":null,"ask_size":null}
{"ts":"2026-08-23T17:52:57.114Z","event_type":"best_bid_ask","market_id":"3789927","outcome_index":1,"market_type":"match","local_side":"away","local_uid":"2026-08-23_hugo_grenier_mees_rottgering","bid":0.73,"ask":0.78,"mid":0.755,"spread":0.05,"bid_size":null,"ask_size":null}
{"ts":"2026-08-23T17:52:57.114Z","event_type":"price_change","market_id":"3789927","outcome_index":0,"market_type":"match","local_side":"home","local_uid":"2026-08-23_hugo_grenier_mees_rottgering","bid":0.22,"ask":0.27,"mid":0.245,"spread":0.05,"price":0.22,"size":100.0,"side":"BUY"}
{"ts":"2026-08-23T17:52:57.114Z","event_type":"price_change","market_id":"3789927","outcome_index":1,"market_type":"match","local_side":"away","local_uid":"2026-08-23_hugo_grenier_mees_rottgering","bid":0.73,"ask":0.78,"mid":0.755,"spread":0.05,"price":0.78,"size":100.0,"side":"SELL"}
{"ts":"2026-08-23T17:52:57.118Z","event_type":"best_bid_ask","market_id":"3789997","outcome_index":0,"market_type":"match","local_side":"home","local_uid":"2026-08-23_oscar_weightman_alec_deckers","bid":0.06,"ask":0.09,"mid":0.075,"spread":0.03,"bid_size":null,"ask_size":null}
{"ts":"2026-08-23T17:52:57.118Z","event_type":"best_bid_ask","market_id":"3789997","outcome_index":1,"market_type":"match","local_side":"away","local_uid":"2026-08-23_oscar_weightman_alec_deckers","bid":0.91,"ask":0.94,"mid":0.925,"spread":0.03,"bid_size":null,"ask_size":null}
{"ts":"2026-08-23T17:52:57.118Z","event_type":"price_change","market_id":"3789997","outcome_index":1,"market_type":"match","local_side":"away","local_uid":"2026-08-23_oscar_weightman_alec_deckers","bid":0.91,"ask":0.94,"mid":0.925,"spread":0.03,"price":0.91,"size":70.0,"side":"BUY"}
{"ts":"2026-08-23T17:52:57.118Z","event_type":"price_change","market_id":"3789997","outcome_index":0,"market_type":"match","local_side":"home","local_uid":"2026-08-23_oscar_weightman_alec_deckers","bid":0.06,"ask":0.09,"mid":0.075,"spread":0.03,"price":0.09,"size":70.0,"side":"SELL"}
{"ts":"2026-08-23T17:52:57.123Z","event_type":"best_bid_ask","market_id":"3789927","outcome_index":0,"market_type":"match","local_side":"home","local_uid":"2026-08-23_hugo_grenier_mees_rottgering","bid":0.23,"ask":0.27,"mid":0.25,"spread":0.04,"bid_size":null,"ask_size":null}
{"ts":"2026-08-23T17:52:57.123Z","event_type":"best_bid_ask","market_id":"3789927","outcome_index":1,"market_type":"match","local_side":"away","local_uid":"2026-08-23_hugo_grenier_mees_rottgering","bid":0.73,"ask":0.77,"mid":0.75,"spread":0.04,"bid_size":null,"ask_size":null}
{"ts":"2026-08-23T17:52:57.124Z","event_type":"price_change","market_id":"3789927","outcome_index":0,"market_type":"match","local_side":"home","local_uid":"2026-08-23_hugo_grenier_mees_rottgering","bid":0.23,"ask":0.27,"mid":0.25,"spread":0.04,"price":0.23,"size":5.0,"side":"BUY"}
{"ts":"2026-08-23T17:52:57.124Z","event_type":"price_change","market_id":"3789927","outcome_index":1,"market_type":"match","local_side":"away","local_uid":"2026-08-23_hugo_grenier_mees_rottgering","bid":0.73,"ask":0.77,"mid":0.75,"spread":0.04,"price":0.77,"size":5.0,"side":"SELL"}
{"ts":"2026-08-23T17:52:57.214Z","event_type":"last_trade_price","market_id":"3789925","outcome_index":0,"market_type":"match","local_side":"home","local_uid":"2026-08-23_pierre_hugues_herbert_quinn_vandecasteele","last_trade":0.85,"trade_size":1.1765,"trade_side":"BUY","trade_notional":1.0}
{"ts":"2026-08-23T17:52:57.232Z","event_type":"last_trade_price","market_id":"3789927","outcome_index":0,"market_type":"match","local_side":"home","local_uid":"2026-08-23_hugo_grenier_mees_rottgering","last_trade":0.26,"trade_size":109.9,"trade_side":"BUY","trade_notional":28.574}
{"ts":"2026-08-23T17:52:57.238Z","event_type":"best_bid_ask","market_id":"3790394","outcome_index":0,"market_type":"set1","local_side":"home","local_uid":"2026-08-23_hugo_grenier_mees_rottgering","bid":0.21,"ask":0.34,"mid":0.275,"spread":0.13,"bid_size":null,"ask_size":null}
{"ts":"2026-08-23T17:52:57.238Z","event_type":"best_bid_ask","market_id":"3790394","outcome_index":1,"market_type":"set1","local_side":"away","local_uid":"2026-08-23_hugo_grenier_mees_rottgering","bid":0.66,"ask":0.79,"mid":0.725,"spread":0.13,"bid_size":null,"ask_size":null}
{"ts":"2026-08-23T17:52:57.238Z","event_type":"price_change","market_id":"3790394","outcome_index":0,"market_type":"set1","local_side":"home","local_uid":"2026-08-23_hugo_grenier_mees_rottgering","bid":0.21,"ask":0.34,"mid":0.275,"spread":0.13,"price":0.21,"size":423.0,"side":"BUY"}
{"ts":"2026-08-23T17:52:57.238Z","event_type":"price_change","market_id":"3790394","outcome_index":1,"market_type":"set1","local_side":"away","local_uid":"2026-08-23_hugo_grenier_mees_rottgering","bid":0.66,"ask":0.79,"mid":0.725,"spread":0.13,"price":0.79,"size":423.0,"side":"SELL"}
{"ts":"2026-08-23T17:52:57.247Z","event_type":"best_bid_ask","market_id":"3790394","outcome_index":0,"market_type":"set1","local_side":"home","local_uid":"2026-08-23_hugo_grenier_mees_rottgering","bid":0.22,"ask":0.34,"mid":0.28,"spread":0.12,"bid_size":null,"ask_size":null}
{"ts":"2026-08-23T17:52:57.251Z","event_type":"best_bid_ask","market_id":"3790394","outcome_index":1,"market_type":"set1","local_side":"away","local_uid":"2026-08-23_hugo_grenier_mees_rottgering","bid":0.66,"ask":0.78,"mid":0.72,"spread":0.12,"bid_size":null,"ask_size":null}
{"ts":"2026-08-23T17:52:57.251Z","event_type":"price_change","market_id":"3790394","outcome_index":0,"market_type":"set1","local_side":"home","local_uid":"2026-08-23_hugo_grenier_mees_rottgering","bid":0.22,"ask":0.34,"mid":0.28,"spread":0.12,"price":0.22,"size":150.0,"side":"BUY"}
{"ts":"2026-08-23T17:52:57.251Z","event_type":"price_change","market_id":"3790394","outcome_index":1,"market_type":"set1","local_side":"away","local_uid":"2026-08-23_hugo_grenier_mees_rottgering","bid":0.66,"ask":0.78,"mid":0.72,"spread":0.12,"price":0.78,"size":150.0,"side":"SELL"}
{"ts":"2026-08-23T17:52:57.253Z","event_type":"best_bid_ask","market_id":"3790397","outcome_index":0,"market_type":"set2","local_side":"home","local_uid":"2026-08-23_hugo_grenier_mees_rottgering","bid":0.29,"ask":0.4,"mid":0.345,"spread":0.11,"bid_size":null,"ask_size":null}
{"ts":"2026-08-23T17:52:57.253Z","event_type":"best_bid_ask","market_id":"3790397","outcome_index":1,"market_type":"set2","local_side":"away","local_uid":"2026-08-23_hugo_grenier_mees_rottgering","bid":0.6,"ask":0.71,"mid":0.655,"spread":0.11,"bid_size":null,"ask_size":null}
{"ts":"2026-08-23T17:52:57.254Z","event_type":"price_change","market_id":"3790397","outcome_index":0,"market_type":"set2","local_side":"home","local_uid":"2026-08-23_hugo_grenier_mees_rottgering","bid":0.29,"ask":0.4,"mid":0.345,"spread":0.11,"price":0.29,"size":88.0,"side":"BUY"}
{"ts":"2026-08-23T17:52:57.254Z","event_type":"price_change","market_id":"3790397","outcome_index":1,"market_type":"set2","local_side":"away","local_uid":"2026-08-23_hugo_grenier_mees_rottgering","bid":0.6,"ask":0.71,"mid":0.655,"spread":0.11,"price":0.71,"size":88.0,"side":"SELL"}
{"ts":"2026-08-23T17:52:57.282Z","event_type":"best_bid_ask","market_id":"3789927","outcome_index":0,"market_type":"match","local_side":"home","local_uid":"2026-08-23_hugo_grenier_mees_rottgering","bid":0.24,"ask":0.27,"mid":0.255,"spread":0.03,"bid_size":null,"ask_size":null}
{"ts":"2026-08-23T17:52:57.282Z","event_type":"best_bid_ask","market_id":"3789927","outcome_index":1,"market_type":"match","local_side":"away","local_uid":"2026-08-23_hugo_grenier_mees_rottgering","bid":0.73,"ask":0.76,"mid":0.745,"spread":0.03,"bid_size":null,"ask_size":null}
{"ts":"2026-08-23T17:52:57.282Z","event_type":"price_change","market_id":"3789927","outcome_index":0,"market_type":"match","local_side":"home","local_uid":"2026-08-23_hugo_grenier_mees_rottgering","bid":0.24,"ask":0.27,"mid":0.255,"spread":0.03,"price":0.24,"size":100.0,"side":"BUY"}
{"ts":"2026-08-23T17:52:57.282Z","event_type":"price_change","market_id":"3789927","outcome_index":1,"market_type":"match","local_side":"away","local_uid":"2026-08-23_hugo_grenier_mees_rottgering","bid":0.73,"ask":0.76,"mid":0.745,"spread":0.03,"price":0.76,"size":100.0,"side":"SELL"}
{"ts":"2026-08-23T17:52:57.283Z","event_type":"best_bid_ask","market_id":"3790397","outcome_index":0,"market_type":"set2","local_side":"home","local_uid":"2026-08-23_hugo_grenier_mees_rottgering","bid":0.29,"ask":0.42,"mid":0.355,"spread":0.13,"bid_size":null,"ask_size":null}
{"ts":"2026-08-23T17:52:57.283Z","event_type":"best_bid_ask","market_id":"3790397","outcome_index":1,"market_type":"set2","local_side":"away","local_uid":"2026-08-23_hugo_grenier_mees_rottgering","bid":0.58,"ask":0.71,"mid":0.645,"spread":0.13,"bid_size":null,"ask_size":null}
{"ts":"2026-08-23T17:52:57.283Z","event_type":"price_change","market_id":"3790397","outcome_index":1,"market_type":"set2","local_side":"away","local_uid":"2026-08-23_hugo_grenier_mees_rottgering","bid":0.58,"ask":0.71,"mid":0.645,"spread":0.13,"price":0.6,"size":0.0,"side":"BUY"}
{"ts":"2026-08-23T17:52:57.283Z","event_type":"price_change","market_id":"3790397","outcome_index":0,"market_type":"set2","local_side":"home","local_uid":"2026-08-23_hugo_grenier_mees_rottgering","bid":0.29,"ask":0.42,"mid":0.355,"spread":0.13,"price":0.4,"size":0.0,"side":"SELL"}
{"ts":"2026-08-23T17:52:57.285Z","event_type":"price_change","market_id":"3795968","outcome_index":0,"market_type":"match","local_side":"home","local_uid":"2026-08-23_mario_gonzalez_fernandez_richard_mallory","bid":0.5,"ask":0.51,"mid":0.505,"spread":0.01,"price":0.27,"size":0.0,"side":"BUY"}
{"ts":"2026-08-23T17:52:57.285Z","event_type":"price_change","market_id":"3795968","outcome_index":1,"market_type":"match","local_side":"away","local_uid":"2026-08-23_mario_gonzalez_fernandez_richard_mallory","bid":0.49,"ask":0.5,"mid":0.495,"spread":0.01,"price":0.73,"size":0.0,"side":"SELL"}
{"ts":"2026-08-23T17:52:57.287Z","event_type":"best_bid_ask","market_id":"3790397","outcome_index":0,"market_type":"set2","local_side":"home","local_uid":"2026-08-23_hugo_grenier_mees_rottgering","bid":0.3,"ask":0.42,"mid":0.36,"spread":0.12,"bid_size":null,"ask_size":null}
{"ts":"2026-08-23T17:52:57.287Z","event_type":"best_bid_ask","market_id":"3790397","outcome_index":1,"market_type":"set2","local_side":"away","local_uid":"2026-08-23_hugo_grenier_mees_rottgering","bid":0.58,"ask":0.7,"mid":0.64,"spread":0.12,"bid_size":null,"ask_size":null}
{"ts":"2026-08-23T17:52:57.287Z","event_type":"price_change","market_id":"3790397","outcome_index":0,"market_type":"set2","local_side":"home","local_uid":"2026-08-23_hugo_grenier_mees_rottgering","bid":0.3,"ask":0.42,"mid":0.36,"spread":0.12,"price":0.3,"size":150.0,"side":"BUY"}
{"ts":"2026-08-23T17:52:57.287Z","event_type":"price_change","market_id":"3790397","outcome_index":1,"market_type":"set2","local_side":"away","local_uid":"2026-08-23_hugo_grenier_mees_rottgering","bid":0.58,"ask":0.7,"mid":0.64,"spread":0.12,"price":0.7,"size":150.0,"side":"SELL"}
{"ts":"2026-08-23T17:52:57.287Z","event_type":"best_bid_ask","market_id":"3790394","outcome_index":0,"market_type":"set1","local_side":"home","local_uid":"2026-08-23_hugo_grenier_mees_rottgering","bid":0.23,"ask":0.34,"mid":0.285,"spread":0.11,"bid_size":null,"ask_size":null}
{"ts":"2026-08-23T17:52:57.288Z","event_type":"best_bid_ask","market_id":"3790394","outcome_index":1,"market_type":"set1","local_side":"away","local_uid":"2026-08-23_hugo_grenier_mees_rottgering","bid":0.66,"ask":0.77,"mid":0.715,"spread":0.11,"bid_size":null,"ask_size":null}
{"ts":"2026-08-23T17:52:57.288Z","event_type":"price_change","market_id":"3790394","outcome_index":0,"market_type":"set1","local_side":"home","local_uid":"2026-08-23_hugo_grenier_mees_rottgering","bid":0.23,"ask":0.34,"mid":0.285,"spread":0.11,"price":0.23,"size":150.0,"side":"BUY"}
{"ts":"2026-08-23T17:52:57.289Z","event_type":"price_change","market_id":"3790394","outcome_index":1,"market_type":"set1","local_side":"away","local_uid":"2026-08-23_hugo_grenier_mees_rottgering","bid":0.66,"ask":0.77,"mid":0.715,"spread":0.11,"price":0.77,"size":150.0,"side":"SELL"}
{"ts":"2026-08-23T17:52:57.336Z","event_type":"best_bid_ask","market_id":"3789927","outcome_index":0,"market_type":"match","local_side":"home","local_uid":"2026-08-23_hugo_grenier_mees_rottgering","bid":0.25,"ask":0.27,"mid":0.26,"spread":0.02,"bid_size":null,"ask_size":null}
{"ts":"2026-08-23T17:52:57.336Z","event_type":"best_bid_ask","market_id":"3789927","outcome_index":1,"market_type":"match","local_side":"away","local_uid":"2026-08-23_hugo_grenier_mees_rottgering","bid":0.73,"ask":0.75,"mid":0.74,"spread":0.02,"bid_size":null,"ask_size":null}
{"ts":"2026-08-23T17:52:57.336Z","event_type":"price_change","market_id":"3789927","outcome_index":0,"market_type":"match","local_side":"home","local_uid":"2026-08-23_hugo_grenier_mees_rottgering","bid":0.25,"ask":0.27,"mid":0.26,"spread":0.02,"price":0.25,"size":112.0,"side":"BUY"}
{"ts":"2026-08-23T17:52:57.336Z","event_type":"price_change","market_id":"3789927","outcome_index":1,"market_type":"match","local_side":"away","local_uid":"2026-08-23_hugo_grenier_mees_rottgering","bid":0.73,"ask":0.75,"mid":0.74,"spread":0.02,"price":0.75,"size":112.0,"side":"SELL"}
{"ts":"2026-08-23T17:52:57.422Z","event_type":"best_bid_ask","market_id":"3790415","outcome_index":0,"market_type":"set2","local_side":"home","local_uid":"2026-08-23_pierre_hugues_herbert_quinn_vandecasteele","bid":0.64,"ask":0.77,"mid":0.705,"spread":0.13,"bid_size":null,"ask_size":null}
{"ts":"2026-08-23T17:52:57.422Z","event_type":"best_bid_ask","market_id":"3790415","outcome_index":1,"market_type":"set2","local_side":"away","local_uid":"2026-08-23_pierre_hugues_herbert_quinn_vandecasteele","bid":0.23,"ask":0.36,"mid":0.295,"spread":0.13,"bid_size":null,"ask_size":null}
{"ts":"2026-08-23T17:52:57.422Z","event_type":"price_change","market_id":"3790415","outcome_index":1,"market_type":"set2","local_side":"away","local_uid":"2026-08-23_pierre_hugues_herbert_quinn_vandecasteele","bid":0.23,"ask":0.36,"mid":0.295,"spread":0.13,"price":0.25,"size":0.0,"side":"BUY"}
{"ts":"2026-08-23T17:52:57.422Z","event_type":"price_change","market_id":"3790415","outcome_index":0,"market_type":"set2","local_side":"home","local_uid":"2026-08-23_pierre_hugues_herbert_quinn_vandecasteele","bid":0.64,"ask":0.77,"mid":0.705,"spread":0.13,"price":0.75,"size":0.0,"side":"SELL"}
{"ts":"2026-08-23T17:52:57.460Z","event_type":"best_bid_ask","market_id":"3790415","outcome_index":0,"market_type":"set2","local_side":"home","local_uid":"2026-08-23_pierre_hugues_herbert_quinn_vandecasteele","bid":0.64,"ask":0.75,"mid":0.695,"spread":0.11,"bid_size":null,"ask_size":null}
{"ts":"2026-08-23T17:52:57.460Z","event_type":"best_bid_ask","market_id":"3790415","outcome_index":1,"market_type":"set2","local_side":"away","local_uid":"2026-08-23_pierre_hugues_herbert_quinn_vandecasteele","bid":0.25,"ask":0.36,"mid":0.305,"spread":0.11,"bid_size":null,"ask_size":null}
{"ts":"2026-08-23T17:52:57.461Z","event_type":"price_change","market_id":"3790415","outcome_index":1,"market_type":"set2","local_side":"away","local_uid":"2026-08-23_pierre_hugues_herbert_quinn_vandecasteele","bid":0.25,"ask":0.36,"mid":0.305,"spread":0.11,"price":0.25,"size":98.28,"side":"BUY"}
{"ts":"2026-08-23T17:52:57.461Z","event_type":"price_change","market_id":"3790415","outcome_index":0,"market_type":"set2","local_side":"home","local_uid":"2026-08-23_pierre_hugues_herbert_quinn_vandecasteele","bid":0.64,"ask":0.75,"mid":0.695,"spread":0.11,"price":0.75,"size":98.28,"side":"SELL"}
{"ts":"2026-08-23T17:52:57.520Z","event_type":"best_bid_ask","market_id":"3789927","outcome_index":0,"market_type":"match","local_side":"home","local_uid":"2026-08-23_hugo_grenier_mees_rottgering","bid":0.26,"ask":0.27,"mid":0.265,"spread":0.01,"bid_size":null,"ask_size":null}
{"ts":"2026-08-23T17:52:57.521Z","event_type":"best_bid_ask","market_id":"3789927","outcome_index":1,"market_type":"match","local_side":"away","local_uid":"2026-08-23_hugo_grenier_mees_rottgering","bid":0.73,"ask":0.74,"mid":0.735,"spread":0.01,"bid_size":null,"ask_size":null}
{"ts":"2026-08-23T17:52:57.521Z","event_type":"price_change","market_id":"3789927","outcome_index":0,"market_type":"match","local_side":"home","local_uid":"2026-08-23_hugo_grenier_mees_rottgering","bid":0.26,"ask":0.27,"mid":0.265,"spread":0.01,"price":0.26,"size":479.99,"side":"BUY"}
{"ts":"2026-08-23T17:52:57.521Z","event_type":"price_change","market_id":"3789927","outcome_index":1,"market_type":"match","local_side":"away","local_uid":"2026-08-23_hugo_grenier_mees_rottgering","bid":0.73,"ask":0.74,"mid":0.735,"spread":0.01,"price":0.74,"size":479.99,"side":"SELL"}
{"ts":"2026-08-23T17:52:57.570Z","event_type":"best_bid_ask","market_id":"3790394","outcome_index":0,"market_type":"set1","local_side":"home","local_uid":"2026-08-23_hugo_grenier_mees_rottgering","bid":0.24,"ask":0.34,"mid":0.29,"spread":0.1,"bid_size":null,"ask_size":null}
{"ts":"2026-08-23T17:52:57.570Z","event_type":"best_bid_ask","market_id":"3790394","outcome_index":1,"market_type":"set1","local_side":"away","local_uid":"2026-08-23_hugo_grenier_mees_rottgering","bid":0.66,"ask":0.76,"mid":0.71,"spread":0.1,"bid_size":null,"ask_size":null}
{"ts":"2026-08-23T17:52:57.570Z","event_type":"price_change","market_id":"3790394","outcome_index":0,"market_type":"set1","local_side":"home","local_uid":"2026-08-23_hugo_grenier_mees_rottgering","bid":0.24,"ask":0.34,"mid":0.29,"spread":0.1,"price":0.24,"size":100.92,"side":"BUY"}
{"ts":"2026-08-23T17:52:57.571Z","event_type":"price_change","market_id":"3790394","outcome_index":1,"market_type":"set1","local_side":"away","local_uid":"2026-08-23_hugo_grenier_mees_rottgering","bid":0.66,"ask":0.76,"mid":0.71,"spread":0.1,"price":0.76,"size":100.92,"side":"SELL"}
{"ts":"2026-08-23T17:52:57.709Z","event_type":"best_bid_ask","market_id":"3790415","outcome_index":0,"market_type":"set2","local_side":"home","local_uid":"2026-08-23_pierre_hugues_herbert_quinn_vandecasteele","bid":0.64,"ask":0.77,"mid":0.705,"spread":0.13,"bid_size":null,"ask_size":null}
{"ts":"2026-08-23T17:52:57.709Z","event_type":"best_bid_ask","market_id":"3790415","outcome_index":1,"market_type":"set2","local_side":"away","local_uid":"2026-08-23_pierre_hugues_herbert_quinn_vandecasteele","bid":0.23,"ask":0.36,"mid":0.295,"spread":0.13,"bid_size":null,"ask_size":null}
{"ts":"2026-08-23T17:52:57.709Z","event_type":"price_change","market_id":"3790415","outcome_index":1,"market_type":"set2","local_side":"away","local_uid":"2026-08-23_pierre_hugues_herbert_quinn_vandecasteele","bid":0.23,"ask":0.36,"mid":0.295,"spread":0.13,"price":0.25,"size":0.0,"side":"BUY"}
{"ts":"2026-08-23T17:52:57.709Z","event_type":"price_change","market_id":"3790415","outcome_index":0,"market_type":"set2","local_side":"home","local_uid":"2026-08-23_pierre_hugues_herbert_quinn_vandecasteele","bid":0.64,"ask":0.77,"mid":0.705,"spread":0.13,"price":0.75,"size":0.0,"side":"SELL"}
{"ts":"2026-08-23T17:52:57.721Z","event_type":"best_bid_ask","market_id":"3789931","outcome_index":0,"market_type":"match","local_side":"home","local_uid":"2026-08-23_stefanos_sakellaridis_luca_van_assche","bid":0.05,"ask":0.07,"mid":0.06,"spread":0.02,"bid_size":null,"ask_size":null}
{"ts":"2026-08-23T17:52:57.721Z","event_type":"best_bid_ask","market_id":"3789931","outcome_index":1,"market_type":"match","local_side":"away","local_uid":"2026-08-23_stefanos_sakellaridis_luca_van_assche","bid":0.93,"ask":0.95,"mid":0.94,"spread":0.02,"bid_size":null,"ask_size":null}
{"ts":"2026-08-23T17:52:57.721Z","event_type":"price_change","market_id":"3789931","outcome_index":1,"market_type":"match","local_side":"away","local_uid":"2026-08-23_stefanos_sakellaridis_luca_van_assche","bid":0.93,"ask":0.95,"mid":0.94,"spread":0.02,"price":0.94,"size":0.0,"side":"SELL"}
{"ts":"2026-08-23T17:52:57.721Z","event_type":"price_change","market_id":"3789931","outcome_index":0,"market_type":"match","local_side":"home","local_uid":"2026-08-23_stefanos_sakellaridis_luca_van_assche","bid":0.05,"ask":0.07,"mid":0.06,"spread":0.02,"price":0.06,"size":0.0,"side":"BUY"}
{"ts":"2026-08-23T17:52:57.740Z","event_type":"best_bid_ask","market_id":"3789931","outcome_index":0,"market_type":"match","local_side":"home","local_uid":"2026-08-23_stefanos_sakellaridis_luca_van_assche","bid":0.06,"ask":0.07,"mid":0.065,"spread":0.01,"bid_size":null,"ask_size":null}
{"ts":"2026-08-23T17:52:57.740Z","event_type":"best_bid_ask","market_id":"3789931","outcome_index":1,"market_type":"match","local_side":"away","local_uid":"2026-08-23_stefanos_sakellaridis_luca_van_assche","bid":0.93,"ask":0.94,"mid":0.935,"spread":0.01,"bid_size":null,"ask_size":null}
{"ts":"2026-08-23T17:52:57.740Z","event_type":"price_change","market_id":"3789931","outcome_index":0,"market_type":"match","local_side":"home","local_uid":"2026-08-23_stefanos_sakellaridis_luca_van_assche","bid":0.06,"ask":0.07,"mid":0.065,"spread":0.01,"price":0.06,"size":5.0,"side":"BUY"}
{"ts":"2026-08-23T17:52:57.740Z","event_type":"price_change","market_id":"3789931","outcome_index":1,"market_type":"match","local_side":"away","local_uid":"2026-08-23_stefanos_sakellaridis_luca_van_assche","bid":0.93,"ask":0.94,"mid":0.935,"spread":0.01,"price":0.94,"size":5.0,"side":"SELL"}
{"ts":"2026-08-23T17:52:57.749Z","event_type":"best_bid_ask","market_id":"3790415","outcome_index":0,"market_type":"set2","local_side":"home","local_uid":"2026-08-23_pierre_hugues_herbert_quinn_vandecasteele","bid":0.64,"ask":0.75,"mid":0.695,"spread":0.11,"bid_size":null,"ask_size":null}
{"ts":"2026-08-23T17:52:57.749Z","event_type":"best_bid_ask","market_id":"3790415","outcome_index":1,"market_type":"set2","local_side":"away","local_uid":"2026-08-23_pierre_hugues_herbert_quinn_vandecasteele","bid":0.25,"ask":0.36,"mid":0.305,"spread":0.11,"bid_size":null,"ask_size":null}
{"ts":"2026-08-23T17:52:57.749Z","event_type":"price_change","market_id":"3790415","outcome_index":1,"market_type":"set2","local_side":"away","local_uid":"2026-08-23_pierre_hugues_herbert_quinn_vandecasteele","bid":0.25,"ask":0.36,"mid":0.305,"spread":0.11,"price":0.25,"size":44.31,"side":"BUY"}
{"ts":"2026-08-23T17:52:57.749Z","event_type":"price_change","market_id":"3790415","outcome_index":0,"market_type":"set2","local_side":"home","local_uid":"2026-08-23_pierre_hugues_herbert_quinn_vandecasteele","bid":0.64,"ask":0.75,"mid":0.695,"spread":0.11,"price":0.75,"size":44.31,"side":"SELL"}
{"ts":"2026-08-23T17:52:57.793Z","event_type":"best_bid_ask","market_id":"3789931","outcome_index":0,"market_type":"match","local_side":"home","local_uid":"2026-08-23_stefanos_sakellaridis_luca_van_assche","bid":0.05,"ask":0.07,"mid":0.06,"spread":0.02,"bid_size":null,"ask_size":null}
{"ts":"2026-08-23T17:52:57.793Z","event_type":"best_bid_ask","market_id":"3789931","outcome_index":1,"market_type":"match","local_side":"away","local_uid":"2026-08-23_stefanos_sakellaridis_luca_van_assche","bid":0.93,"ask":0.95,"mid":0.94,"spread":0.02,"bid_size":null,"ask_size":null}
{"ts":"2026-08-23T17:52:57.793Z","event_type":"price_change","market_id":"3789931","outcome_index":0,"market_type":"match","local_side":"home","local_uid":"2026-08-23_stefanos_sakellaridis_luca_van_assche","bid":0.05,"ask":0.07,"mid":0.06,"spread":0.02,"price":0.06,"size":0.0,"side":"BUY"}
{"ts":"2026-08-23T17:52:57.793Z","event_type":"price_change","market_id":"3789931","outcome_index":1,"market_type":"match","local_side":"away","local_uid":"2026-08-23_stefanos_sakellaridis_luca_van_assche","bid":0.93,"ask":0.95,"mid":0.94,"spread":0.02,"price":0.94,"size":0.0,"side":"SELL"}
{"ts":"2026-08-23T17:52:58.062Z","event_type":"book","market_id":"3789927","outcome_index":0,"market_type":"match","local_side":"home","local_uid":"2026-08-23_hugo_grenier_mees_rottgering","bid":0.26,"ask":0.27,"mid":0.265,"spread":0.01,"bid_size":13422.62,"ask_size":20.0}
{"ts":"2026-08-23T17:52:58.062Z","event_type":"book","market_id":"3789927","outcome_index":1,"market_type":"match","local_side":"away","local_uid":"2026-08-23_hugo_grenier_mees_rottgering","bid":0.73,"ask":0.74,"mid":0.735,"spread":0.01,"bid_size":20.0,"ask_size":13422.62}
{"ts":"2026-08-23T17:52:58.132Z","event_type":"best_bid_ask","market_id":"3790394","outcome_index":0,"market_type":"set1","local_side":"home","local_uid":"2026-08-23_hugo_grenier_mees_rottgering","bid":0.27,"ask":0.34,"mid":0.305,"spread":0.07,"bid_size":null,"ask_size":null}
{"ts":"2026-08-23T17:52:58.132Z","event_type":"best_bid_ask","market_id":"3790394","outcome_index":1,"market_type":"set1","local_side":"away","local_uid":"2026-08-23_hugo_grenier_mees_rottgering","bid":0.66,"ask":0.73,"mid":0.695,"spread":0.07,"bid_size":null,"ask_size":null}
{"ts":"2026-08-23T17:52:58.132Z","event_type":"price_change","market_id":"3790394","outcome_index":0,"market_type":"set1","local_side":"home","local_uid":"2026-08-23_hugo_grenier_mees_rottgering","bid":0.27,"ask":0.34,"mid":0.305,"spread":0.07,"price":0.27,"size":400.0,"side":"BUY"}
{"ts":"2026-08-23T17:52:58.132Z","event_type":"price_change","market_id":"3790394","outcome_index":1,"market_type":"set1","local_side":"away","local_uid":"2026-08-23_hugo_grenier_mees_rottgering","bid":0.66,"ask":0.73,"mid":0.695,"spread":0.07,"price":0.73,"size":400.0,"side":"SELL"}
{"ts":"2026-08-23T17:52:58.140Z","event_type":"last_trade_price","market_id":"3789927","outcome_index":1,"market_type":"match","local_side":"away","local_uid":"2026-08-23_hugo_grenier_mees_rottgering","last_trade":0.74,"trade_size":35.473,"trade_side":"BUY","trade_notional":26.25}
{"ts":"2026-08-23T17:52:59.060Z","event_type":"book","market_id":"3789997","outcome_index":0,"market_type":"match","local_side":"home","local_uid":"2026-08-23_oscar_weightman_alec_deckers","bid":0.06,"ask":0.09,"mid":0.075,"spread":0.03,"bid_size":510.85,"ask_size":870.0}
{"ts":"2026-08-23T17:52:59.061Z","event_type":"price_change","market_id":"3792995","outcome_index":0,"market_type":"match","local_side":"home","local_uid":"2026-08-24_alycia_parks_petra_marcinko","bid":0.44,"ask":0.45,"mid":0.445,"spread":0.01,"price":0.41,"size":700.26,"side":"BUY"}
{"ts":"2026-08-23T17:52:59.061Z","event_type":"price_change","market_id":"3792995","outcome_index":1,"market_type":"match","local_side":"away","local_uid":"2026-08-24_alycia_parks_petra_marcinko","bid":0.55,"ask":0.56,"mid":0.555,"spread":0.01,"price":0.59,"size":700.26,"side":"SELL"}
{"ts":"2026-08-23T17:52:59.062Z","event_type":"book","market_id":"3789997","outcome_index":1,"market_type":"match","local_side":"away","local_uid":"2026-08-23_oscar_weightman_alec_deckers","bid":0.91,"ask":0.94,"mid":0.925,"spread":0.03,"bid_size":870.0,"ask_size":510.85}
{"ts":"2026-08-23T17:52:59.119Z","event_type":"last_trade_price","market_id":"3789997","outcome_index":1,"market_type":"match","local_side":"away","local_uid":"2026-08-23_oscar_weightman_alec_deckers","last_trade":0.94,"trade_size":319.1489,"trade_side":"BUY","trade_notional":300.0}
{"ts":"2026-08-23T17:52:59.138Z","event_type":"last_trade_price","market_id":"3789927","outcome_index":0,"market_type":"match","local_side":"home","local_uid":"2026-08-23_hugo_grenier_mees_rottgering","last_trade":0.27,"trade_size":5.8889,"trade_side":"BUY","trade_notional":1.59}
{"ts":"2026-08-23T17:52:59.164Z","event_type":"best_bid_ask","market_id":"3789997","outcome_index":0,"market_type":"match","local_side":"home","local_uid":"2026-08-23_oscar_weightman_alec_deckers","bid":0.06,"ask":0.08,"mid":0.07,"spread":0.02,"bid_size":null,"ask_size":null}
{"ts":"2026-08-23T17:52:59.164Z","event_type":"best_bid_ask","market_id":"3789997","outcome_index":1,"market_type":"match","local_side":"away","local_uid":"2026-08-23_oscar_weightman_alec_deckers","bid":0.92,"ask":0.94,"mid":0.93,"spread":0.02,"bid_size":null,"ask_size":null}
{"ts":"2026-08-23T17:52:59.164Z","event_type":"price_change","market_id":"3789997","outcome_index":1,"market_type":"match","local_side":"away","local_uid":"2026-08-23_oscar_weightman_alec_deckers","bid":0.92,"ask":0.94,"mid":0.93,"spread":0.02,"price":0.92,"size":100.0,"side":"BUY"}
{"ts":"2026-08-23T17:52:59.164Z","event_type":"price_change","market_id":"3789997","outcome_index":0,"market_type":"match","local_side":"home","local_uid":"2026-08-23_oscar_weightman_alec_deckers","bid":0.06,"ask":0.08,"mid":0.07,"spread":0.02,"price":0.08,"size":100.0,"side":"SELL"}
{"ts":"2026-08-23T17:52:59.184Z","event_type":"last_trade_price","market_id":"3789927","outcome_index":1,"market_type":"match","local_side":"away","local_uid":"2026-08-23_hugo_grenier_mees_rottgering","last_trade":0.74,"trade_size":35.473,"trade_side":"BUY","trade_notional":26.25}
{"ts":"2026-08-23T17:52:59.230Z","event_type":"best_bid_ask","market_id":"3789997","outcome_index":0,"market_type":"match","local_side":"home","local_uid":"2026-08-23_oscar_weightman_alec_deckers","bid":0.06,"ask":0.07,"mid":0.065,"spread":0.01,"bid_size":null,"ask_size":null}
{"ts":"2026-08-23T17:52:59.230Z","event_type":"best_bid_ask","market_id":"3789997","outcome_index":1,"market_type":"match","local_side":"away","local_uid":"2026-08-23_oscar_weightman_alec_deckers","bid":0.93,"ask":0.94,"mid":0.935,"spread":0.01,"bid_size":null,"ask_size":null}
{"ts":"2026-08-23T17:52:59.230Z","event_type":"price_change","market_id":"3789997","outcome_index":1,"market_type":"match","local_side":"away","local_uid":"2026-08-23_oscar_weightman_alec_deckers","bid":0.93,"ask":0.94,"mid":0.935,"spread":0.01,"price":0.93,"size":61.0,"side":"BUY"}
{"ts":"2026-08-23T17:52:59.230Z","event_type":"price_change","market_id":"3789997","outcome_index":0,"market_type":"match","local_side":"home","local_uid":"2026-08-23_oscar_weightman_alec_deckers","bid":0.06,"ask":0.07,"mid":0.065,"spread":0.01,"price":0.07,"size":61.0,"side":"SELL"}
{"ts":"2026-08-23T17:52:59.266Z","event_type":"best_bid_ask","market_id":"3790397","outcome_index":0,"market_type":"set2","local_side":"home","local_uid":"2026-08-23_hugo_grenier_mees_rottgering","bid":0.31,"ask":0.42,"mid":0.365,"spread":0.11,"bid_size":null,"ask_size":null}
{"ts":"2026-08-23T17:52:59.267Z","event_type":"best_bid_ask","market_id":"3790397","outcome_index":1,"market_type":"set2","local_side":"away","local_uid":"2026-08-23_hugo_grenier_mees_rottgering","bid":0.58,"ask":0.69,"mid":0.635,"spread":0.11,"bid_size":null,"ask_size":null}
{"ts":"2026-08-23T17:52:59.267Z","event_type":"price_change","market_id":"3790397","outcome_index":0,"market_type":"set2","local_side":"home","local_uid":"2026-08-23_hugo_grenier_mees_rottgering","bid":0.31,"ask":0.42,"mid":0.365,"spread":0.11,"price":0.31,"size":150.0,"side":"BUY"}
{"ts":"2026-08-23T17:52:59.267Z","event_type":"price_change","market_id":"3790397","outcome_index":1,"market_type":"set2","local_side":"away","local_uid":"2026-08-23_hugo_grenier_mees_rottgering","bid":0.58,"ask":0.69,"mid":0.635,"spread":0.11,"price":0.69,"size":150.0,"side":"SELL"}
{"ts":"2026-08-23T17:52:59.269Z","event_type":"best_bid_ask","market_id":"3790397","outcome_index":0,"market_type":"set2","local_side":"home","local_uid":"2026-08-23_hugo_grenier_mees_rottgering","bid":0.31,"ask":0.41,"mid":0.36,"spread":0.1,"bid_size":null,"ask_size":null}
{"ts":"2026-08-23T17:52:59.269Z","event_type":"best_bid_ask","market_id":"3790397","outcome_index":1,"market_type":"set2","local_side":"away","local_uid":"2026-08-23_hugo_grenier_mees_rottgering","bid":0.59,"ask":0.69,"mid":0.64,"spread":0.1,"bid_size":null,"ask_size":null}
{"ts":"2026-08-23T17:52:59.269Z","event_type":"price_change","market_id":"3790397","outcome_index":1,"market_type":"set2","local_side":"away","local_uid":"2026-08-23_hugo_grenier_mees_rottgering","bid":0.59,"ask":0.69,"mid":0.64,"spread":0.1,"price":0.59,"size":98.89,"side":"BUY"}
{"ts":"2026-08-23T17:52:59.269Z","event_type":"price_change","market_id":"3790397","outcome_index":0,"market_type":"set2","local_side":"home","local_uid":"2026-08-23_hugo_grenier_mees_rottgering","bid":0.31,"ask":0.41,"mid":0.36,"spread":0.1,"price":0.41,"size":98.89,"side":"SELL"}
{"ts":"2026-08-23T17:52:59.655Z","event_type":"best_bid_ask","market_id":"3790415","outcome_index":0,"market_type":"set2","local_side":"home","local_uid":"2026-08-23_pierre_hugues_herbert_quinn_vandecasteele","bid":0.63,"ask":0.75,"mid":0.69,"spread":0.12,"bid_size":null,"ask_size":null}
{"ts":"2026-08-23T17:52:59.655Z","event_type":"best_bid_ask","market_id":"3790415","outcome_index":1,"market_type":"set2","local_side":"away","local_uid":"2026-08-23_pierre_hugues_herbert_quinn_vandecasteele","bid":0.25,"ask":0.37,"mid":0.31,"spread":0.12,"bid_size":null,"ask_size":null}
{"ts":"2026-08-23T17:52:59.655Z","event_type":"price_change","market_id":"3790415","outcome_index":0,"market_type":"set2","local_side":"home","local_uid":"2026-08-23_pierre_hugues_herbert_quinn_vandecasteele","bid":0.63,"ask":0.75,"mid":0.69,"spread":0.12,"price":0.64,"size":0.0,"side":"BUY"}
{"ts":"2026-08-23T17:52:59.655Z","event_type":"price_change","market_id":"3790415","outcome_index":1,"market_type":"set2","local_side":"away","local_uid":"2026-08-23_pierre_hugues_herbert_quinn_vandecasteele","bid":0.25,"ask":0.37,"mid":0.31,"spread":0.12,"price":0.36,"size":0.0,"side":"SELL"}
{"ts":"2026-08-23T17:52:59.678Z","event_type":"best_bid_ask","market_id":"3790415","outcome_index":0,"market_type":"set2","local_side":"home","local_uid":"2026-08-23_pierre_hugues_herbert_quinn_vandecasteele","bid":0.63,"ask":0.77,"mid":0.7,"spread":0.14,"bid_size":null,"ask_size":null}
{"ts":"2026-08-23T17:52:59.678Z","event_type":"best_bid_ask","market_id":"3790415","outcome_index":1,"market_type":"set2","local_side":"away","local_uid":"2026-08-23_pierre_hugues_herbert_quinn_vandecasteele","bid":0.23,"ask":0.37,"mid":0.3,"spread":0.14,"bid_size":null,"ask_size":null}
{"ts":"2026-08-23T17:52:59.678Z","event_type":"price_change","market_id":"3790415","outcome_index":1,"market_type":"set2","local_side":"away","local_uid":"2026-08-23_pierre_hugues_herbert_quinn_vandecasteele","bid":0.23,"ask":0.37,"mid":0.3,"spread":0.14,"price":0.25,"size":0.0,"side":"BUY"}
{"ts":"2026-08-23T17:52:59.679Z","event_type":"price_change","market_id":"3790415","outcome_index":0,"market_type":"set2","local_side":"home","local_uid":"2026-08-23_pierre_hugues_herbert_quinn_vandecasteele","bid":0.63,"ask":0.77,"mid":0.7,"spread":0.14,"price":0.75,"size":0.0,"side":"SELL"}
{"ts":"2026-08-23T17:52:59.719Z","event_type":"best_bid_ask","market_id":"3790415","outcome_index":0,"market_type":"set2","local_side":"home","local_uid":"2026-08-23_pierre_hugues_herbert_quinn_vandecasteele","bid":0.63,"ask":0.75,"mid":0.69,"spread":0.12,"bid_size":null,"ask_size":null}
{"ts":"2026-08-23T17:52:59.719Z","event_type":"best_bid_ask","market_id":"3790415","outcome_index":1,"market_type":"set2","local_side":"away","local_uid":"2026-08-23_pierre_hugues_herbert_quinn_vandecasteele","bid":0.25,"ask":0.37,"mid":0.31,"spread":0.12,"bid_size":null,"ask_size":null}
{"ts":"2026-08-23T17:52:59.719Z","event_type":"price_change","market_id":"3790415","outcome_index":1,"market_type":"set2","local_side":"away","local_uid":"2026-08-23_pierre_hugues_herbert_quinn_vandecasteele","bid":0.25,"ask":0.37,"mid":0.31,"spread":0.12,"price":0.25,"size":18.39,"side":"BUY"}
{"ts":"2026-08-23T17:52:59.719Z","event_type":"price_change","market_id":"3790415","outcome_index":0,"market_type":"set2","local_side":"home","local_uid":"2026-08-23_pierre_hugues_herbert_quinn_vandecasteele","bid":0.63,"ask":0.75,"mid":0.69,"spread":0.12,"price":0.75,"size":18.39,"side":"SELL"}
{"ts":"2026-08-23T17:53:00.323Z","event_type":"best_bid_ask","market_id":"3789997","outcome_index":0,"market_type":"match","local_side":"home","local_uid":"2026-08-23_oscar_weightman_alec_deckers","bid":0.05,"ask":0.07,"mid":0.06,"spread":0.02,"bid_size":null,"ask_size":null}
{"ts":"2026-08-23T17:53:00.323Z","event_type":"best_bid_ask","market_id":"3789997","outcome_index":1,"market_type":"match","local_side":"away","local_uid":"2026-08-23_oscar_weightman_alec_deckers","bid":0.93,"ask":0.95,"mid":0.94,"spread":0.02,"bid_size":null,"ask_size":null}
{"ts":"2026-08-23T17:53:00.324Z","event_type":"price_change","market_id":"3789997","outcome_index":0,"market_type":"match","local_side":"home","local_uid":"2026-08-23_oscar_weightman_alec_deckers","bid":0.05,"ask":0.07,"mid":0.06,"spread":0.02,"price":0.06,"size":0.0,"side":"BUY"}
{"ts":"2026-08-23T17:53:00.324Z","event_type":"price_change","market_id":"3789997","outcome_index":1,"market_type":"match","local_side":"away","local_uid":"2026-08-23_oscar_weightman_alec_deckers","bid":0.93,"ask":0.95,"mid":0.94,"spread":0.02,"price":0.94,"size":0.0,"side":"SELL"}
{"ts":"2026-08-23T17:53:00.324Z","event_type":"book","market_id":"3789997","outcome_index":0,"market_type":"match","local_side":"home","local_uid":"2026-08-23_oscar_weightman_alec_deckers","bid":0.05,"ask":0.07,"mid":0.06,"spread":0.02,"bid_size":795.0,"ask_size":186.7}
{"ts":"2026-08-23T17:53:00.324Z","event_type":"book","market_id":"3789997","outcome_index":1,"market_type":"match","local_side":"away","local_uid":"2026-08-23_oscar_weightman_alec_deckers","bid":0.93,"ask":0.95,"mid":0.94,"spread":0.02,"bid_size":186.7,"ask_size":795.0}
{"ts":"2026-08-23T17:53:00.369Z","event_type":"last_trade_price","market_id":"3789997","outcome_index":1,"market_type":"match","local_side":"away","local_uid":"2026-08-23_oscar_weightman_alec_deckers","last_trade":0.94,"trade_size":510.8404,"trade_side":"BUY","trade_notional":480.19}
{"ts":"2026-08-23T17:53:00.697Z","event_type":"price_change","market_id":"3795974","outcome_index":0,"market_type":"match","local_side":"home","local_uid":"2026-08-23_juan_jose_bianchi_keshav_chopra","bid":0.15,"ask":0.19,"mid":0.17,"spread":0.04,"price":0.13,"size":1599.62,"side":"BUY"}
{"ts":"2026-08-23T17:53:00.697Z","event_type":"price_change","market_id":"3795974","outcome_index":1,"market_type":"match","local_side":"away","local_uid":"2026-08-23_juan_jose_bianchi_keshav_chopra","bid":0.81,"ask":0.85,"mid":0.83,"spread":0.04,"price":0.87,"size":1599.62,"side":"SELL"}
{"ts":"2026-08-23T17:53:00.769Z","event_type":"best_bid_ask","market_id":"3789931","outcome_index":0,"market_type":"match","local_side":"home","local_uid":"2026-08-23_stefanos_sakellaridis_luca_van_assche","bid":0.06,"ask":0.07,"mid":0.065,"spread":0.01,"bid_size":null,"ask_size":null}
{"ts":"2026-08-23T17:53:00.770Z","event_type":"best_bid_ask","market_id":"3789931","outcome_index":1,"market_type":"match","local_side":"away","local_uid":"2026-08-23_stefanos_sakellaridis_luca_van_assche","bid":0.93,"ask":0.94,"mid":0.935,"spread":0.01,"bid_size":null,"ask_size":null}
{"ts":"2026-08-23T17:53:00.770Z","event_type":"price_change","market_id":"3789931","outcome_index":0,"market_type":"match","local_side":"home","local_uid":"2026-08-23_stefanos_sakellaridis_luca_van_assche","bid":0.06,"ask":0.07,"mid":0.065,"spread":0.01,"price":0.06,"size":6633.33,"side":"BUY"}
{"ts":"2026-08-23T17:53:00.770Z","event_type":"price_change","market_id":"3789931","outcome_index":1,"market_type":"match","local_side":"away","local_uid":"2026-08-23_stefanos_sakellaridis_luca_van_assche","bid":0.93,"ask":0.94,"mid":0.935,"spread":0.01,"price":0.94,"size":6633.33,"side":"SELL"}
{"ts":"2026-08-23T17:53:00.897Z","event_type":"best_bid_ask","market_id":"3789997","outcome_index":0,"market_type":"match","local_side":"home","local_uid":"2026-08-23_oscar_weightman_alec_deckers","bid":0.05,"ask":0.06,"mid":0.055,"spread":0.01,"bid_size":null,"ask_size":null}
{"ts":"2026-08-23T17:53:00.897Z","event_type":"best_bid_ask","market_id":"3789997","outcome_index":1,"market_type":"match","local_side":"away","local_uid":"2026-08-23_oscar_weightman_alec_deckers","bid":0.94,"ask":0.95,"mid":0.945,"spread":0.01,"bid_size":null,"ask_size":null}
{"ts":"2026-08-23T17:53:00.897Z","event_type":"price_change","market_id":"3789997","outcome_index":1,"market_type":"match","local_side":"away","local_uid":"2026-08-23_oscar_weightman_alec_deckers","bid":0.94,"ask":0.95,"mid":0.945,"spread":0.01,"price":0.94,"size":5.1,"side":"BUY"}
{"ts":"2026-08-23T17:53:00.897Z","event_type":"price_change","market_id":"3789997","outcome_index":0,"market_type":"match","local_side":"home","local_uid":"2026-08-23_oscar_weightman_alec_deckers","bid":0.05,"ask":0.06,"mid":0.055,"spread":0.01,"price":0.06,"size":5.1,"side":"SELL"}
{"ts":"2026-08-23T17:53:01.067Z","event_type":"book","market_id":"3789997","outcome_index":0,"market_type":"match","local_side":"home","local_uid":"2026-08-23_oscar_weightman_alec_deckers","bid":0.05,"ask":0.06,"mid":0.055,"spread":0.01,"bid_size":782.23,"ask_size":5.1}
{"ts":"2026-08-23T17:53:01.067Z","event_type":"book","market_id":"3789997","outcome_index":1,"market_type":"match","local_side":"away","local_uid":"2026-08-23_oscar_weightman_alec_deckers","bid":0.94,"ask":0.95,"mid":0.945,"spread":0.01,"bid_size":5.1,"ask_size":782.23}
{"ts":"2026-08-23T17:53:01.143Z","event_type":"last_trade_price","market_id":"3789997","outcome_index":1,"market_type":"match","local_side":"away","local_uid":"2026-08-23_oscar_weightman_alec_deckers","last_trade":0.95,"trade_size":12.77,"trade_side":"BUY","trade_notional":12.1315}
{"ts":"2026-08-23T17:53:01.209Z","event_type":"best_bid_ask","market_id":"3790415","outcome_index":0,"market_type":"set2","local_side":"home","local_uid":"2026-08-23_pierre_hugues_herbert_quinn_vandecasteele","bid":0.63,"ask":0.74,"mid":0.685,"spread":0.11,"bid_size":null,"ask_size":null}
{"ts":"2026-08-23T17:53:01.209Z","event_type":"best_bid_ask","market_id":"3790415","outcome_index":1,"market_type":"set2","local_side":"away","local_uid":"2026-08-23_pierre_hugues_herbert_quinn_vandecasteele","bid":0.26,"ask":0.37,"mid":0.315,"spread":0.11,"bid_size":null,"ask_size":null}
{"ts":"2026-08-23T17:53:01.209Z","event_type":"price_change","market_id":"3790415","outcome_index":1,"market_type":"set2","local_side":"away","local_uid":"2026-08-23_pierre_hugues_herbert_quinn_vandecasteele","bid":0.26,"ask":0.37,"mid":0.315,"spread":0.11,"price":0.26,"size":88.0,"side":"BUY"}
{"ts":"2026-08-23T17:53:01.209Z","event_type":"price_change","market_id":"3790415","outcome_index":0,"market_type":"set2","local_side":"home","local_uid":"2026-08-23_pierre_hugues_herbert_quinn_vandecasteele","bid":0.63,"ask":0.74,"mid":0.685,"spread":0.11,"price":0.74,"size":88.0,"side":"SELL"}
{"ts":"2026-08-23T17:53:01.230Z","event_type":"last_trade_price","market_id":"3789997","outcome_index":1,"market_type":"match","local_side":"away","local_uid":"2026-08-23_oscar_weightman_alec_deckers","last_trade":0.95,"trade_size":12.77,"trade_side":"BUY","trade_notional":12.1315}
{"ts":"2026-08-23T17:53:01.249Z","event_type":"best_bid_ask","market_id":"3790415","outcome_index":0,"market_type":"set2","local_side":"home","local_uid":"2026-08-23_pierre_hugues_herbert_quinn_vandecasteele","bid":0.61,"ask":0.74,"mid":0.675,"spread":0.13,"bid_size":null,"ask_size":null}
{"ts":"2026-08-23T17:53:01.250Z","event_type":"best_bid_ask","market_id":"3790415","outcome_index":1,"market_type":"set2","local_side":"away","local_uid":"2026-08-23_pierre_hugues_herbert_quinn_vandecasteele","bid":0.26,"ask":0.39,"mid":0.325,"spread":0.13,"bid_size":null,"ask_size":null}
{"ts":"2026-08-23T17:53:01.250Z","event_type":"price_change","market_id":"3790415","outcome_index":0,"market_type":"set2","local_side":"home","local_uid":"2026-08-23_pierre_hugues_herbert_quinn_vandecasteele","bid":0.61,"ask":0.74,"mid":0.675,"spread":0.13,"price":0.63,"size":0.0,"side":"BUY"}
{"ts":"2026-08-23T17:53:01.250Z","event_type":"price_change","market_id":"3790415","outcome_index":1,"market_type":"set2","local_side":"away","local_uid":"2026-08-23_pierre_hugues_herbert_quinn_vandecasteele","bid":0.26,"ask":0.39,"mid":0.325,"spread":0.13,"price":0.37,"size":0.0,"side":"SELL"}
{"ts":"2026-08-23T17:53:01.261Z","event_type":"best_bid_ask","market_id":"3790415","outcome_index":0,"market_type":"set2","local_side":"home","local_uid":"2026-08-23_pierre_hugues_herbert_quinn_vandecasteele","bid":0.6,"ask":0.74,"mid":0.67,"spread":0.14,"bid_size":null,"ask_size":null}
{"ts":"2026-08-23T17:53:01.261Z","event_type":"best_bid_ask","market_id":"3790415","outcome_index":1,"market_type":"set2","local_side":"away","local_uid":"2026-08-23_pierre_hugues_herbert_quinn_vandecasteele","bid":0.26,"ask":0.4,"mid":0.33,"spread":0.14,"bid_size":null,"ask_size":null}
{"ts":"2026-08-23T17:53:01.261Z","event_type":"price_change","market_id":"3790415","outcome_index":0,"market_type":"set2","local_side":"home","local_uid":"2026-08-23_pierre_hugues_herbert_quinn_vandecasteele","bid":0.6,"ask":0.74,"mid":0.67,"spread":0.14,"price":0.61,"size":0.0,"side":"BUY"}
{"ts":"2026-08-23T17:53:01.261Z","event_type":"price_change","market_id":"3790415","outcome_index":1,"market_type":"set2","local_side":"away","local_uid":"2026-08-23_pierre_hugues_herbert_quinn_vandecasteele","bid":0.26,"ask":0.4,"mid":0.33,"spread":0.14,"price":0.39,"size":0.0,"side":"SELL"}
{"ts":"2026-08-23T17:53:01.264Z","event_type":"best_bid_ask","market_id":"3790415","outcome_index":0,"market_type":"set2","local_side":"home","local_uid":"2026-08-23_pierre_hugues_herbert_quinn_vandecasteele","bid":0.6,"ask":0.73,"mid":0.665,"spread":0.13,"bid_size":null,"ask_size":null}
{"ts":"2026-08-23T17:53:01.264Z","event_type":"best_bid_ask","market_id":"3790415","outcome_index":1,"market_type":"set2","local_side":"away","local_uid":"2026-08-23_pierre_hugues_herbert_quinn_vandecasteele","bid":0.27,"ask":0.4,"mid":0.335,"spread":0.13,"bid_size":null,"ask_size":null}
{"ts":"2026-08-23T17:53:01.264Z","event_type":"price_change","market_id":"3790415","outcome_index":1,"market_type":"set2","local_side":"away","local_uid":"2026-08-23_pierre_hugues_herbert_quinn_vandecasteele","bid":0.27,"ask":0.4,"mid":0.335,"spread":0.13,"price":0.27,"size":150.0,"side":"BUY"}
{"ts":"2026-08-23T17:53:01.265Z","event_type":"price_change","market_id":"3790415","outcome_index":0,"market_type":"set2","local_side":"home","local_uid":"2026-08-23_pierre_hugues_herbert_quinn_vandecasteele","bid":0.6,"ask":0.73,"mid":0.665,"spread":0.13,"price":0.73,"size":150.0,"side":"SELL"}
{"ts":"2026-08-23T17:53:01.265Z","event_type":"best_bid_ask","market_id":"3790415","outcome_index":0,"market_type":"set2","local_side":"home","local_uid":"2026-08-23_pierre_hugues_herbert_quinn_vandecasteele","bid":0.61,"ask":0.73,"mid":0.67,"spread":0.12,"bid_size":null,"ask_size":null}
{"ts":"2026-08-23T17:53:01.265Z","event_type":"best_bid_ask","market_id":"3790415","outcome_index":1,"market_type":"set2","local_side":"away","local_uid":"2026-08-23_pierre_hugues_herbert_quinn_vandecasteele","bid":0.27,"ask":0.39,"mid":0.33,"spread":0.12,"bid_size":null,"ask_size":null}
{"ts":"2026-08-23T17:53:01.265Z","event_type":"price_change","market_id":"3790415","outcome_index":0,"market_type":"set2","local_side":"home","local_uid":"2026-08-23_pierre_hugues_herbert_quinn_vandecasteele","bid":0.61,"ask":0.73,"mid":0.67,"spread":0.12,"price":0.61,"size":150.0,"side":"BUY"}
{"ts":"2026-08-23T17:53:01.265Z","event_type":"price_change","market_id":"3790415","outcome_index":1,"market_type":"set2","local_side":"away","local_uid":"2026-08-23_pierre_hugues_herbert_quinn_vandecasteele","bid":0.27,"ask":0.39,"mid":0.33,"spread":0.12,"price":0.39,"size":150.0,"side":"SELL"}
{"ts":"2026-08-23T17:53:01.813Z","event_type":"best_bid_ask","market_id":"3790323","outcome_index":0,"market_type":"set2","local_side":"home","local_uid":"2026-08-23_felix_balshaw_sebastian_gorzny","bid":0.49,"ask":0.61,"mid":0.55,"spread":0.12,"bid_size":null,"ask_size":null}
{"ts":"2026-08-23T17:53:01.813Z","event_type":"best_bid_ask","market_id":"3790323","outcome_index":1,"market_type":"set2","local_side":"away","local_uid":"2026-08-23_felix_balshaw_sebastian_gorzny","bid":0.39,"ask":0.51,"mid":0.45,"spread":0.12,"bid_size":null,"ask_size":null}
{"ts":"2026-08-23T17:53:01.814Z","event_type":"price_change","market_id":"3790323","outcome_index":0,"market_type":"set2","local_side":"home","local_uid":"2026-08-23_felix_balshaw_sebastian_gorzny","bid":0.49,"ask":0.61,"mid":0.55,"spread":0.12,"price":0.5,"size":0.0,"side":"BUY"}
{"ts":"2026-08-23T17:53:01.814Z","event_type":"price_change","market_id":"3790323","outcome_index":1,"market_type":"set2","local_side":"away","local_uid":"2026-08-23_felix_balshaw_sebastian_gorzny","bid":0.39,"ask":0.51,"mid":0.45,"spread":0.12,"price":0.5,"size":0.0,"side":"SELL"}
{"ts":"2026-08-23T17:53:01.825Z","event_type":"best_bid_ask","market_id":"3790323","outcome_index":0,"market_type":"set2","local_side":"home","local_uid":"2026-08-23_felix_balshaw_sebastian_gorzny","bid":0.49,"ask":0.62,"mid":0.555,"spread":0.13,"bid_size":null,"ask_size":null}
{"ts":"2026-08-23T17:53:01.825Z","event_type":"best_bid_ask","market_id":"3790323","outcome_index":1,"market_type":"set2","local_side":"away","local_uid":"2026-08-23_felix_balshaw_sebastian_gorzny","bid":0.38,"ask":0.51,"mid":0.445,"spread":0.13,"bid_size":null,"ask_size":null}
{"ts":"2026-08-23T17:53:01.825Z","event_type":"price_change","market_id":"3790323","outcome_index":1,"market_type":"set2","local_side":"away","local_uid":"2026-08-23_felix_balshaw_sebastian_gorzny","bid":0.38,"ask":0.51,"mid":0.445,"spread":0.13,"price":0.39,"size":0.0,"side":"BUY"}
{"ts":"2026-08-23T17:53:01.825Z","event_type":"price_change","market_id":"3790323","outcome_index":0,"market_type":"set2","local_side":"home","local_uid":"2026-08-23_felix_balshaw_sebastian_gorzny","bid":0.49,"ask":0.62,"mid":0.555,"spread":0.13,"price":0.61,"size":0.0,"side":"SELL"}
{"ts":"2026-08-23T17:53:01.849Z","event_type":"best_bid_ask","market_id":"3790323","outcome_index":0,"market_type":"set2","local_side":"home","local_uid":"2026-08-23_felix_balshaw_sebastian_gorzny","bid":0.49,"ask":0.63,"mid":0.56,"spread":0.14,"bid_size":null,"ask_size":null}
{"ts":"2026-08-23T17:53:01.849Z","event_type":"best_bid_ask","market_id":"3790323","outcome_index":1,"market_type":"set2","local_side":"away","local_uid":"2026-08-23_felix_balshaw_sebastian_gorzny","bid":0.37,"ask":0.51,"mid":0.44,"spread":0.14,"bid_size":null,"ask_size":null}
{"ts":"2026-08-23T17:53:01.849Z","event_type":"price_change","market_id":"3790323","outcome_index":1,"market_type":"set2","local_side":"away","local_uid":"2026-08-23_felix_balshaw_sebastian_gorzny","bid":0.37,"ask":0.51,"mid":0.44,"spread":0.14,"price":0.38,"size":0.0,"side":"BUY"}
{"ts":"2026-08-23T17:53:01.849Z","event_type":"price_change","market_id":"3790323","outcome_index":0,"market_type":"set2","local_side":"home","local_uid":"2026-08-23_felix_balshaw_sebastian_gorzny","bid":0.49,"ask":0.63,"mid":0.56,"spread":0.14,"price":0.62,"size":0.0,"side":"SELL"}
{"ts":"2026-08-23T17:53:01.849Z","event_type":"best_bid_ask","market_id":"3790323","outcome_index":0,"market_type":"set2","local_side":"home","local_uid":"2026-08-23_felix_balshaw_sebastian_gorzny","bid":0.0,"ask":0.63,"mid":0.315,"spread":0.63,"bid_size":null,"ask_size":null}
{"ts":"2026-08-23T17:53:01.849Z","event_type":"best_bid_ask","market_id":"3790323","outcome_index":1,"market_type":"set2","local_side":"away","local_uid":"2026-08-23_felix_balshaw_sebastian_gorzny","bid":0.37,"ask":1.0,"mid":0.685,"spread":0.63,"bid_size":null,"ask_size":null}
{"ts":"2026-08-23T17:53:01.854Z","event_type":"price_change","market_id":"3790323","outcome_index":0,"market_type":"set2","local_side":"home","local_uid":"2026-08-23_felix_balshaw_sebastian_gorzny","bid":0.0,"ask":0.63,"mid":0.315,"spread":0.63,"price":0.49,"size":0.0,"side":"BUY"}
{"ts":"2026-08-23T17:53:01.854Z","event_type":"price_change","market_id":"3790323","outcome_index":1,"market_type":"set2","local_side":"away","local_uid":"2026-08-23_felix_balshaw_sebastian_gorzny","bid":0.37,"ask":1.0,"mid":0.685,"spread":0.63,"price":0.51,"size":0.0,"side":"SELL"}
{"ts":"2026-08-23T17:53:01.864Z","event_type":"best_bid_ask","market_id":"3790323","outcome_index":0,"market_type":"set2","local_side":"home","local_uid":"2026-08-23_felix_balshaw_sebastian_gorzny","bid":0.5,"ask":0.63,"mid":0.565,"spread":0.13,"bid_size":null,"ask_size":null}
{"ts":"2026-08-23T17:53:01.864Z","event_type":"best_bid_ask","market_id":"3790323","outcome_index":1,"market_type":"set2","local_side":"away","local_uid":"2026-08-23_felix_balshaw_sebastian_gorzny","bid":0.37,"ask":0.5,"mid":0.435,"spread":0.13,"bid_size":null,"ask_size":null}
{"ts":"2026-08-23T17:53:01.864Z","event_type":"price_change","market_id":"3790323","outcome_index":0,"market_type":"set2","local_side":"home","local_uid":"2026-08-23_felix_balshaw_sebastian_gorzny","bid":0.5,"ask":0.63,"mid":0.565,"spread":0.13,"price":0.5,"size":30.24,"side":"BUY"}
{"ts":"2026-08-23T17:53:01.864Z","event_type":"price_change","market_id":"3790323","outcome_index":1,"market_type":"set2","local_side":"away","local_uid":"2026-08-23_felix_balshaw_sebastian_gorzny","bid":0.37,"ask":0.5,"mid":0.435,"spread":0.13,"price":0.5,"size":30.24,"side":"SELL"}
{"ts":"2026-08-23T17:53:01.907Z","event_type":"best_bid_ask","market_id":"3790323","outcome_index":0,"market_type":"set2","local_side":"home","local_uid":"2026-08-23_felix_balshaw_sebastian_gorzny","bid":0.46,"ask":0.63,"mid":0.545,"spread":0.17,"bid_size":null,"ask_size":null}
{"ts":"2026-08-23T17:53:01.907Z","event_type":"best_bid_ask","market_id":"3790323","outcome_index":1,"market_type":"set2","local_side":"away","local_uid":"2026-08-23_felix_balshaw_sebastian_gorzny","bid":0.37,"ask":0.54,"mid":0.455,"spread":0.17,"bid_size":null,"ask_size":null}
{"ts":"2026-08-23T17:53:01.907Z","event_type":"price_change","market_id":"3790323","outcome_index":0,"market_type":"set2","local_side":"home","local_uid":"2026-08-23_felix_balshaw_sebastian_gorzny","bid":0.46,"ask":0.63,"mid":0.545,"spread":0.17,"price":0.5,"size":0.0,"side":"BUY"}
{"ts":"2026-08-23T17:53:01.907Z","event_type":"price_change","market_id":"3790323","outcome_index":1,"market_type":"set2","local_side":"away","local_uid":"2026-08-23_felix_balshaw_sebastian_gorzny","bid":0.37,"ask":0.54,"mid":0.455,"spread":0.17,"price":0.5,"size":0.0,"side":"SELL"}
{"ts":"2026-08-23T17:53:01.947Z","event_type":"best_bid_ask","market_id":"3790323","outcome_index":0,"market_type":"set2","local_side":"home","local_uid":"2026-08-23_felix_balshaw_sebastian_gorzny","bid":0.5,"ask":0.63,"mid":0.565,"spread":0.13,"bid_size":null,"ask_size":null}
{"ts":"2026-08-23T17:53:01.948Z","event_type":"best_bid_ask","market_id":"3790323","outcome_index":1,"market_type":"set2","local_side":"away","local_uid":"2026-08-23_felix_balshaw_sebastian_gorzny","bid":0.37,"ask":0.5,"mid":0.435,"spread":0.13,"bid_size":null,"ask_size":null}
{"ts":"2026-08-23T17:53:01.948Z","event_type":"price_change","market_id":"3790323","outcome_index":0,"market_type":"set2","local_side":"home","local_uid":"2026-08-23_felix_balshaw_sebastian_gorzny","bid":0.5,"ask":0.63,"mid":0.565,"spread":0.13,"price":0.5,"size":22.2,"side":"BUY"}
{"ts":"2026-08-23T17:53:01.948Z","event_type":"price_change","market_id":"3790323","outcome_index":1,"market_type":"set2","local_side":"away","local_uid":"2026-08-23_felix_balshaw_sebastian_gorzny","bid":0.37,"ask":0.5,"mid":0.435,"spread":0.13,"price":0.5,"size":22.2,"side":"SELL"}
{"ts":"2026-08-23T17:53:02.110Z","event_type":"last_trade_price","market_id":"3789927","outcome_index":1,"market_type":"match","local_side":"away","local_uid":"2026-08-23_hugo_grenier_mees_rottgering","last_trade":0.73,"trade_size":13.86,"trade_side":"SELL","trade_notional":10.1178}
{"ts":"2026-08-23T17:53:02.201Z","event_type":"best_bid_ask","market_id":"3790323","outcome_index":0,"market_type":"set2","local_side":"home","local_uid":"2026-08-23_felix_balshaw_sebastian_gorzny","bid":0.5,"ask":0.64,"mid":0.57,"spread":0.14,"bid_size":null,"ask_size":null}
{"ts":"2026-08-23T17:53:02.201Z","event_type":"best_bid_ask","market_id":"3790323","outcome_index":1,"market_type":"set2","local_side":"away","local_uid":"2026-08-23_felix_balshaw_sebastian_gorzny","bid":0.36,"ask":0.5,"mid":0.43,"spread":0.14,"bid_size":null,"ask_size":null}
{"ts":"2026-08-23T17:53:02.201Z","event_type":"price_change","market_id":"3790323","outcome_index":1,"market_type":"set2","local_side":"away","local_uid":"2026-08-23_felix_balshaw_sebastian_gorzny","bid":0.36,"ask":0.5,"mid":0.43,"spread":0.14,"price":0.37,"size":0.0,"side":"BUY"}
