{"ts":"2026-08-23T17:53:25.403Z","event_type":"best_bid_ask","market_id":"3790397","outcome_index":0,"market_type":"set2","local_side":"home","local_uid":"2026-08-23_hugo_grenier_mees_rottgering","bid":0.32,"ask":0.41,"mid":0.365,"spread":0.09,"bid_size":null,"ask_size":null}
{"ts":"2026-08-23T17:53:25.403Z","event_type":"best_bid_ask","market_id":"3790397","outcome_index":1,"market_type":"set2","local_side":"away","local_uid":"2026-08-23_hugo_grenier_mees_rottgering","bid":0.59,"ask":0.68,"mid":0.635,"spread":0.09,"bid_size":null,"ask_size":null}
{"ts":"2026-08-23T17:53:25.409Z","event_type":"price_change","market_id":"3790397","outcome_index":1,"market_type":"set2","local_side":"away","local_uid":"2026-08-23_hugo_grenier_mees_rottgering","bid":0.59,"ask":0.68,"mid":0.635,"spread":0.09,"price":0.59,"size":150.0,"side":"BUY"}
{"ts":"2026-08-23T17:53:25.409Z","event_type":"price_change","market_id":"3790397","outcome_index":0,"market_type":"set2","local_side":"home","local_uid":"2026-08-23_hugo_grenier_mees_rottgering","bid":0.32,"ask":0.41,"mid":0.365,"spread":0.09,"price":0.41,"size":150.0,"side":"SELL"}
{"ts":"2026-08-23T17:53:25.409Z","event_type":"best_bid_ask","market_id":"3790415","outcome_index":0,"market_type":"set2","local_side":"home","local_uid":"2026-08-23_pierre_hugues_herbert_quinn_vandecasteele","bid":0.59,"ask":0.74,"mid":0.665,"spread":0.15,"bid_size":null,"ask_size":null}
{"ts":"2026-08-23T17:53:25.410Z","event_type":"best_bid_ask","market_id":"3790415","outcome_index":1,"market_type":"set2","local_side":"away","local_uid":"2026-08-23_pierre_hugues_herbert_quinn_vandecasteele","bid":0.26,"ask":0.41,"mid":0.335,"spread":0.15,"bid_size":null,"ask_size":null}
{"ts":"2026-08-23T17:53:25.415Z","event_type":"price_change","market_id":"3790415","outcome_index":1,"market_type":"set2","local_side":"away","local_uid":"2026-08-23_pierre_hugues_herbert_quinn_vandecasteele","bid":0.26,"ask":0.41,"mid":0.335,"spread":0.15,"price":0.26,"size":34.44,"side":"BUY"}
{"ts":"2026-08-23T17:53:25.415Z","event_type":"price_change","market_id":"3790415","outcome_index":0,"market_type":"set2","local_side":"home","local_uid":"2026-08-23_pierre_hugues_herbert_quinn_vandecasteele","bid":0.59,"ask":0.74,"mid":0.665,"spread":0.15,"price":0.74,"size":34.44,"side":"SELL"}
{"ts":"2026-08-23T17:53:25.550Z","event_type":"best_bid_ask","market_id":"3790394","outcome_index":0,"market_type":"set1","local_side":"home","local_uid":"2026-08-23_hugo_grenier_mees_rottgering","bid":0.32,"ask":0.4,"mid":0.36,"spread":0.08,"bid_size":null,"ask_size":null}
{"ts":"2026-08-23T17:53:25.550Z","event_type":"best_bid_ask","market_id":"3790394","outcome_index":1,"market_type":"set1","local_side":"away","local_uid":"2026-08-23_hugo_grenier_mees_rottgering","bid":0.6,"ask":0.68,"mid":0.64,"spread":0.08,"bid_size":null,"ask_size":null}
{"ts":"2026-08-23T17:53:25.550Z","event_type":"price_change","market_id":"3790394","outcome_index":0,"market_type":"set1","local_side":"home","local_uid":"2026-08-23_hugo_grenier_mees_rottgering","bid":0.32,"ask":0.4,"mid":0.36,"spread":0.08,"price":0.32,"size":150.0,"side":"BUY"}
{"ts":"2026-08-23T17:53:25.550Z","event_type":"price_change","market_id":"3790394","outcome_index":1,"market_type":"set1","local_side":"away","local_uid":"2026-08-23_hugo_grenier_mees_rottgering","bid":0.6,"ask":0.68,"mid":0.64,"spread":0.08,"price":0.68,"size":150.0,"side":"SELL"}
{"ts":"2026-08-23T17:53:25.642Z","event_type":"new_market","market_id":"0xe836d5001348312ff0967b757a1cf075e8482a288009939e874f5bbcb7f30cff"}
{"ts":"2026-08-23T17:53:25.646Z","event_type":"new_market","market_id":"0xfce4e5c7a13c504e7abcc2229c5b836ff238578a1645bce7684fcbfc10ef56b1"}
{"ts":"2026-08-23T17:53:25.788Z","event_type":"new_market","market_id":"0x54d0847e3ccc21d70fdf15515a9964f13cdfafbbd95a705e78b73513e50003af"}
{"ts":"2026-08-23T17:53:25.788Z","event_type":"new_market","market_id":"0x1c780102f78c0c28bb8bcfb303f55042548449aa0c53a5b8e98d1fea4824da19"}
{"ts":"2026-08-23T17:53:25.907Z","event_type":"new_market","market_id":"0xa63f748e3c8e22e211c4aba0b8338067e1d8c1ce6b8ea12535b2635d78ff805b"}
{"ts":"2026-08-23T17:53:26.475Z","event_type":"best_bid_ask","market_id":"3790415","outcome_index":0,"market_type":"set2","local_side":"home","local_uid":"2026-08-23_pierre_hugues_herbert_quinn_vandecasteele","bid":0.59,"ask":0.76,"mid":0.675,"spread":0.17,"bid_size":null,"ask_size":null}
{"ts":"2026-08-23T17:53:26.476Z","event_type":"best_bid_ask","market_id":"3790415","outcome_index":1,"market_type":"set2","local_side":"away","local_uid":"2026-08-23_pierre_hugues_herbert_quinn_vandecasteele","bid":0.24,"ask":0.41,"mid":0.325,"spread":0.17,"bid_size":null,"ask_size":null}
{"ts":"2026-08-23T17:53:26.476Z","event_type":"price_change","market_id":"3790415","outcome_index":1,"market_type":"set2","local_side":"away","local_uid":"2026-08-23_pierre_hugues_herbert_quinn_vandecasteele","bid":0.24,"ask":0.41,"mid":0.325,"spread":0.17,"price":0.26,"size":0.0,"side":"BUY"}
{"ts":"2026-08-23T17:53:26.476Z","event_type":"price_change","market_id":"3790415","outcome_index":0,"market_type":"set2","local_side":"home","local_uid":"2026-08-23_pierre_hugues_herbert_quinn_vandecasteele","bid":0.59,"ask":0.76,"mid":0.675,"spread":0.17,"price":0.74,"size":0.0,"side":"SELL"}
{"ts":"2026-08-23T17:53:26.534Z","event_type":"best_bid_ask","market_id":"3790415","outcome_index":0,"market_type":"set2","local_side":"home","local_uid":"2026-08-23_pierre_hugues_herbert_quinn_vandecasteele","bid":0.59,"ask":0.72,"mid":0.655,"spread":0.13,"bid_size":null,"ask_size":null}
{"ts":"2026-08-23T17:53:26.534Z","event_type":"best_bid_ask","market_id":"3790415","outcome_index":1,"market_type":"set2","local_side":"away","local_uid":"2026-08-23_pierre_hugues_herbert_quinn_vandecasteele","bid":0.28,"ask":0.41,"mid":0.345,"spread":0.13,"bid_size":null,"ask_size":null}
{"ts":"2026-08-23T17:53:26.534Z","event_type":"price_change","market_id":"3790415","outcome_index":1,"market_type":"set2","local_side":"away","local_uid":"2026-08-23_pierre_hugues_herbert_quinn_vandecasteele","bid":0.28,"ask":0.41,"mid":0.345,"spread":0.13,"price":0.28,"size":45.54,"side":"BUY"}
{"ts":"2026-08-23T17:53:26.534Z","event_type":"price_change","market_id":"3790415","outcome_index":0,"market_type":"set2","local_side":"home","local_uid":"2026-08-23_pierre_hugues_herbert_quinn_vandecasteele","bid":0.59,"ask":0.72,"mid":0.655,"spread":0.13,"price":0.72,"size":45.54,"side":"SELL"}
{"ts":"2026-08-23T17:53:27.063Z","event_type":"best_bid_ask","market_id":"3789927","outcome_index":0,"market_type":"match","local_side":"home","local_uid":"2026-08-23_hugo_grenier_mees_rottgering","bid":0.29,"ask":0.31,"mid":0.3,"spread":0.02,"bid_size":null,"ask_size":null}
{"ts":"2026-08-23T17:53:27.063Z","event_type":"best_bid_ask","market_id":"3789927","outcome_index":1,"market_type":"match","local_side":"away","local_uid":"2026-08-23_hugo_grenier_mees_rottgering","bid":0.69,"ask":0.71,"mid":0.7,"spread":0.02,"bid_size":null,"ask_size":null}
{"ts":"2026-08-23T17:53:27.063Z","event_type":"price_change","market_id":"3789927","outcome_index":1,"market_type":"match","local_side":"away","local_uid":"2026-08-23_hugo_grenier_mees_rottgering","bid":0.69,"ask":0.71,"mid":0.7,"spread":0.02,"price":0.7,"size":0.0,"side":"BUY"}
{"ts":"2026-08-23T17:53:27.063Z","event_type":"price_change","market_id":"3789927","outcome_index":0,"market_type":"match","local_side":"home","local_uid":"2026-08-23_hugo_grenier_mees_rottgering","bid":0.29,"ask":0.31,"mid":0.3,"spread":0.02,"price":0.3,"size":0.0,"side":"SELL"}
{"ts":"2026-08-23T17:53:27.064Z","event_type":"book","market_id":"3789927","outcome_index":0,"market_type":"match","local_side":"home","local_uid":"2026-08-23_hugo_grenier_mees_rottgering","bid":0.29,"ask":0.31,"mid":0.3,"spread":0.02,"bid_size":34069.97,"ask_size":22534.52}
{"ts":"2026-08-23T17:53:27.064Z","event_type":"book","market_id":"3789927","outcome_index":1,"market_type":"match","local_side":"away","local_uid":"2026-08-23_hugo_grenier_mees_rottgering","bid":0.69,"ask":0.71,"mid":0.7,"spread":0.02,"bid_size":22534.52,"ask_size":34069.97}
{"ts":"2026-08-23T17:53:27.125Z","event_type":"last_trade_price","market_id":"3789927","outcome_index":0,"market_type":"match","local_side":"home","local_uid":"2026-08-23_hugo_grenier_mees_rottgering","last_trade":0.3,"trade_size":5.0,"trade_side":"BUY","trade_notional":1.5}
{"ts":"2026-08-23T17:53:27.290Z","event_type":"best_bid_ask","market_id":"3789927","outcome_index":0,"market_type":"match","local_side":"home","local_uid":"2026-08-23_hugo_grenier_mees_rottgering","bid":0.3,"ask":0.31,"mid":0.305,"spread":0.01,"bid_size":null,"ask_size":null}
{"ts":"2026-08-23T17:53:27.290Z","event_type":"best_bid_ask","market_id":"3789927","outcome_index":1,"market_type":"match","local_side":"away","local_uid":"2026-08-23_hugo_grenier_mees_rottgering","bid":0.69,"ask":0.7,"mid":0.695,"spread":0.01,"bid_size":null,"ask_size":null}
{"ts":"2026-08-23T17:53:27.291Z","event_type":"price_change","market_id":"3789927","outcome_index":0,"market_type":"match","local_side":"home","local_uid":"2026-08-23_hugo_grenier_mees_rottgering","bid":0.3,"ask":0.31,"mid":0.305,"spread":0.01,"price":0.3,"size":4822.0,"side":"BUY"}
{"ts":"2026-08-23T17:53:27.291Z","event_type":"price_change","market_id":"3789927","outcome_index":1,"market_type":"match","local_side":"away","local_uid":"2026-08-23_hugo_grenier_mees_rottgering","bid":0.69,"ask":0.7,"mid":0.695,"spread":0.01,"price":0.7,"size":4822.0,"side":"SELL"}
{"ts":"2026-08-23T17:53:27.464Z","event_type":"best_bid_ask","market_id":"3789925","outcome_index":0,"market_type":"match","local_side":"home","local_uid":"2026-08-23_pierre_hugues_herbert_quinn_vandecasteele","bid":0.82,"ask":0.84,"mid":0.83,"spread":0.02,"bid_size":null,"ask_size":null}
{"ts":"2026-08-23T17:53:27.464Z","event_type":"best_bid_ask","market_id":"3789925","outcome_index":1,"market_type":"match","local_side":"away","local_uid":"2026-08-23_pierre_hugues_herbert_quinn_vandecasteele","bid":0.16,"ask":0.18,"mid":0.17,"spread":0.02,"bid_size":null,"ask_size":null}
{"ts":"2026-08-23T17:53:27.464Z","event_type":"price_change","market_id":"3789925","outcome_index":0,"market_type":"match","local_side":"home","local_uid":"2026-08-23_pierre_hugues_herbert_quinn_vandecasteele","bid":0.82,"ask":0.84,"mid":0.83,"spread":0.02,"price":0.83,"size":0.0,"side":"BUY"}
{"ts":"2026-08-23T17:53:27.464Z","event_type":"price_change","market_id":"3789925","outcome_index":1,"market_type":"match","local_side":"away","local_uid":"2026-08-23_pierre_hugues_herbert_quinn_vandecasteele","bid":0.16,"ask":0.18,"mid":0.17,"spread":0.02,"price":0.17,"size":0.0,"side":"SELL"}
{"ts":"2026-08-23T17:53:28.023Z","event_type":"new_market","market_id":"0xf3eba74099b4ad326b6e984fa6aefdf80bdd3a25445cd4490b584c534cdc545c"}
{"ts":"2026-08-23T17:53:28.023Z","event_type":"new_market","market_id":"0xdf7d719e41ccf9b6e5ea79b5ab09ae7463d3fae86fb4112d79698c16b869efae"}
{"ts":"2026-08-23T17:53:28.024Z","event_type":"new_market","market_id":"0x2a2f3c00d227757f43d6d07ea93d729d1eb26b13302170b2719e7ebb55ca9ef6"}
{"ts":"2026-08-23T17:53:28.481Z","event_type":"price_change","market_id":"3792969","outcome_index":0,"market_type":"match","local_side":"home","local_uid":"2026-08-23_maya_joint_yulia_putintseva","bid":0.44,"ask":0.45,"mid":0.445,"spread":0.01,"price":0.3,"size":92.66,"side":"BUY"}
{"ts":"2026-08-23T17:53:28.482Z","event_type":"price_change","market_id":"3792969","outcome_index":1,"market_type":"match","local_side":"away","local_uid":"2026-08-23_maya_joint_yulia_putintseva","bid":0.55,"ask":0.56,"mid":0.555,"spread":0.01,"price":0.7,"size":92.66,"side":"SELL"}
{"ts":"2026-08-23T17:53:29.063Z","event_type":"best_bid_ask","market_id":"3789997","outcome_index":0,"market_type":"match","local_side":"home","local_uid":"2026-08-23_oscar_weightman_alec_deckers","bid":0.03,"ask":0.06,"mid":0.045,"spread":0.03,"bid_size":null,"ask_size":null}
{"ts":"2026-08-23T17:53:29.064Z","event_type":"best_bid_ask","market_id":"3789997","outcome_index":1,"market_type":"match","local_side":"away","local_uid":"2026-08-23_oscar_weightman_alec_deckers","bid":0.94,"ask":0.97,"mid":0.955,"spread":0.03,"bid_size":null,"ask_size":null}
{"ts":"2026-08-23T17:53:29.064Z","event_type":"price_change","market_id":"3789997","outcome_index":1,"market_type":"match","local_side":"away","local_uid":"2026-08-23_oscar_weightman_alec_deckers","bid":0.94,"ask":0.97,"mid":0.955,"spread":0.03,"price":0.95,"size":0.0,"side":"SELL"}
{"ts":"2026-08-23T17:53:29.064Z","event_type":"price_change","market_id":"3789997","outcome_index":0,"market_type":"match","local_side":"home","local_uid":"2026-08-23_oscar_weightman_alec_deckers","bid":0.03,"ask":0.06,"mid":0.045,"spread":0.03,"price":0.05,"size":0.0,"side":"BUY"}
{"ts":"2026-08-23T17:53:29.296Z","event_type":"best_bid_ask","market_id":"3790323","outcome_index":0,"market_type":"set2","local_side":"home","local_uid":"2026-08-23_felix_balshaw_sebastian_gorzny","bid":0.55,"ask":0.65,"mid":0.6,"spread":0.1,"bid_size":null,"ask_size":null}
{"ts":"2026-08-23T17:53:29.301Z","event_type":"best_bid_ask","market_id":"3790323","outcome_index":1,"market_type":"set2","local_side":"away","local_uid":"2026-08-23_felix_balshaw_sebastian_gorzny","bid":0.35,"ask":0.45,"mid":0.4,"spread":0.1,"bid_size":null,"ask_size":null}
{"ts":"2026-08-23T17:53:29.301Z","event_type":"price_change","market_id":"3790323","outcome_index":1,"market_type":"set2","local_side":"away","local_uid":"2026-08-23_felix_balshaw_sebastian_gorzny","bid":0.35,"ask":0.45,"mid":0.4,"spread":0.1,"price":0.37,"size":0.0,"side":"BUY"}
{"ts":"2026-08-23T17:53:29.301Z","event_type":"price_change","market_id":"3790323","outcome_index":0,"market_type":"set2","local_side":"home","local_uid":"2026-08-23_felix_balshaw_sebastian_gorzny","bid":0.55,"ask":0.65,"mid":0.6,"spread":0.1,"price":0.63,"size":0.0,"side":"SELL"}
{"ts":"2026-08-23T17:53:29.311Z","event_type":"best_bid_ask","market_id":"3790323","outcome_index":0,"market_type":"set2","local_side":"home","local_uid":"2026-08-23_felix_balshaw_sebastian_gorzny","bid":0.54,"ask":0.65,"mid":0.595,"spread":0.11,"bid_size":null,"ask_size":null}
{"ts":"2026-08-23T17:53:29.311Z","event_type":"best_bid_ask","market_id":"3790323","outcome_index":1,"market_type":"set2","local_side":"away","local_uid":"2026-08-23_felix_balshaw_sebastian_gorzny","bid":0.35,"ask":0.46,"mid":0.405,"spread":0.11,"bid_size":null,"ask_size":null}
{"ts":"2026-08-23T17:53:29.311Z","event_type":"price_change","market_id":"3790323","outcome_index":0,"market_type":"set2","local_side":"home","local_uid":"2026-08-23_felix_balshaw_sebastian_gorzny","bid":0.54,"ask":0.65,"mid":0.595,"spread":0.11,"price":0.55,"size":0.0,"side":"BUY"}
{"ts":"2026-08-23T17:53:29.311Z","event_type":"price_change","market_id":"3790323","outcome_index":1,"market_type":"set2","local_side":"away","local_uid":"2026-08-23_felix_balshaw_sebastian_gorzny","bid":0.35,"ask":0.46,"mid":0.405,"spread":0.11,"price":0.45,"size":0.0,"side":"SELL"}
{"ts":"2026-08-23T17:53:29.318Z","event_type":"best_bid_ask","market_id":"3790415","outcome_index":0,"market_type":"set2","local_side":"home","local_uid":"2026-08-23_pierre_hugues_herbert_quinn_vandecasteele","bid":0.59,"ask":0.73,"mid":0.66,"spread":0.14,"bid_size":null,"ask_size":null}
{"ts":"2026-08-23T17:53:29.319Z","event_type":"best_bid_ask","market_id":"3790415","outcome_index":1,"market_type":"set2","local_side":"away","local_uid":"2026-08-23_pierre_hugues_herbert_quinn_vandecasteele","bid":0.27,"ask":0.41,"mid":0.34,"spread":0.14,"bid_size":null,"ask_size":null}
{"ts":"2026-08-23T17:53:29.319Z","event_type":"price_change","market_id":"3790415","outcome_index":1,"market_type":"set2","local_side":"away","local_uid":"2026-08-23_pierre_hugues_herbert_quinn_vandecasteele","bid":0.27,"ask":0.41,"mid":0.34,"spread":0.14,"price":0.25,"size":0.0,"side":"BUY"}
{"ts":"2026-08-23T17:53:29.319Z","event_type":"price_change","market_id":"3790415","outcome_index":0,"market_type":"set2","local_side":"home","local_uid":"2026-08-23_pierre_hugues_herbert_quinn_vandecasteele","bid":0.59,"ask":0.73,"mid":0.66,"spread":0.14,"price":0.75,"size":0.0,"side":"SELL"}
{"ts":"2026-08-23T17:53:29.377Z","event_type":"best_bid_ask","market_id":"3790323","outcome_index":0,"market_type":"set2","local_side":"home","local_uid":"2026-08-23_felix_balshaw_sebastian_gorzny","bid":0.54,"ask":0.64,"mid":0.59,"spread":0.1,"bid_size":null,"ask_size":null}
{"ts":"2026-08-23T17:53:29.377Z","event_type":"best_bid_ask","market_id":"3790323","outcome_index":1,"market_type":"set2","local_side":"away","local_uid":"2026-08-23_felix_balshaw_sebastian_gorzny","bid":0.36,"ask":0.46,"mid":0.41,"spread":0.1,"bid_size":null,"ask_size":null}
{"ts":"2026-08-23T17:53:29.377Z","event_type":"price_change","market_id":"3790323","outcome_index":1,"market_type":"set2","local_side":"away","local_uid":"2026-08-23_felix_balshaw_sebastian_gorzny","bid":0.36,"ask":0.46,"mid":0.41,"spread":0.1,"price":0.36,"size":150.0,"side":"BUY"}
{"ts":"2026-08-23T17:53:29.377Z","event_type":"price_change","market_id":"3790323","outcome_index":0,"market_type":"set2","local_side":"home","local_uid":"2026-08-23_felix_balshaw_sebastian_gorzny","bid":0.54,"ask":0.64,"mid":0.59,"spread":0.1,"price":0.64,"size":150.0,"side":"SELL"}
{"ts":"2026-08-23T17:53:29.402Z","event_type":"best_bid_ask","market_id":"3790415","outcome_index":0,"market_type":"set2","local_side":"home","local_uid":"2026-08-23_pierre_hugues_herbert_quinn_vandecasteele","bid":0.59,"ask":0.72,"mid":0.655,"spread":0.13,"bid_size":null,"ask_size":null}
{"ts":"2026-08-23T17:53:29.402Z","event_type":"best_bid_ask","market_id":"3790415","outcome_index":1,"market_type":"set2","local_side":"away","local_uid":"2026-08-23_pierre_hugues_herbert_quinn_vandecasteele","bid":0.28,"ask":0.41,"mid":0.345,"spread":0.13,"bid_size":null,"ask_size":null}
{"ts":"2026-08-23T17:53:29.402Z","event_type":"price_change","market_id":"3790415","outcome_index":1,"market_type":"set2","local_side":"away","local_uid":"2026-08-23_pierre_hugues_herbert_quinn_vandecasteele","bid":0.28,"ask":0.41,"mid":0.345,"spread":0.13,"price":0.28,"size":34.93,"side":"BUY"}
{"ts":"2026-08-23T17:53:29.402Z","event_type":"price_change","market_id":"3790415","outcome_index":0,"market_type":"set2","local_side":"home","local_uid":"2026-08-23_pierre_hugues_herbert_quinn_vandecasteele","bid":0.59,"ask":0.72,"mid":0.655,"spread":0.13,"price":0.72,"size":34.93,"side":"SELL"}
{"ts":"2026-08-23T17:53:29.412Z","event_type":"best_bid_ask","market_id":"3790415","outcome_index":0,"market_type":"set2","local_side":"home","local_uid":"2026-08-23_pierre_hugues_herbert_quinn_vandecasteele","bid":0.62,"ask":0.72,"mid":0.67,"spread":0.1,"bid_size":null,"ask_size":null}
{"ts":"2026-08-23T17:53:29.412Z","event_type":"best_bid_ask","market_id":"3790415","outcome_index":1,"market_type":"set2","local_side":"away","local_uid":"2026-08-23_pierre_hugues_herbert_quinn_vandecasteele","bid":0.28,"ask":0.38,"mid":0.33,"spread":0.1,"bid_size":null,"ask_size":null}
{"ts":"2026-08-23T17:53:29.412Z","event_type":"price_change","market_id":"3790415","outcome_index":0,"market_type":"set2","local_side":"home","local_uid":"2026-08-23_pierre_hugues_herbert_quinn_vandecasteele","bid":0.62,"ask":0.72,"mid":0.67,"spread":0.1,"price":0.62,"size":33.95,"side":"BUY"}
{"ts":"2026-08-23T17:53:29.412Z","event_type":"price_change","market_id":"3790415","outcome_index":1,"market_type":"set2","local_side":"away","local_uid":"2026-08-23_pierre_hugues_herbert_quinn_vandecasteele","bid":0.28,"ask":0.38,"mid":0.33,"spread":0.1,"price":0.38,"size":33.95,"side":"SELL"}
{"ts":"2026-08-23T17:53:29.443Z","event_type":"best_bid_ask","market_id":"3790323","outcome_index":0,"market_type":"set2","local_side":"home","local_uid":"2026-08-23_felix_balshaw_sebastian_gorzny","bid":0.54,"ask":0.66,"mid":0.6,"spread":0.12,"bid_size":null,"ask_size":null}
{"ts":"2026-08-23T17:53:29.443Z","event_type":"best_bid_ask","market_id":"3790323","outcome_index":1,"market_type":"set2","local_side":"away","local_uid":"2026-08-23_felix_balshaw_sebastian_gorzny","bid":0.34,"ask":0.46,"mid":0.4,"spread":0.12,"bid_size":null,"ask_size":null}
{"ts":"2026-08-23T17:53:29.444Z","event_type":"price_change","market_id":"3790323","outcome_index":1,"market_type":"set2","local_side":"away","local_uid":"2026-08-23_felix_balshaw_sebastian_gorzny","bid":0.34,"ask":0.46,"mid":0.4,"spread":0.12,"price":0.36,"size":0.0,"side":"BUY"}
{"ts":"2026-08-23T17:53:29.444Z","event_type":"price_change","market_id":"3790323","outcome_index":0,"market_type":"set2","local_side":"home","local_uid":"2026-08-23_felix_balshaw_sebastian_gorzny","bid":0.54,"ask":0.66,"mid":0.6,"spread":0.12,"price":0.64,"size":0.0,"side":"SELL"}
{"ts":"2026-08-23T17:53:29.523Z","event_type":"best_bid_ask","market_id":"3790323","outcome_index":0,"market_type":"set2","local_side":"home","local_uid":"2026-08-23_felix_balshaw_sebastian_gorzny","bid":0.54,"ask":0.71,"mid":0.625,"spread":0.17,"bid_size":null,"ask_size":null}
{"ts":"2026-08-23T17:53:29.523Z","event_type":"best_bid_ask","market_id":"3790323","outcome_index":1,"market_type":"set2","local_side":"away","local_uid":"2026-08-23_felix_balshaw_sebastian_gorzny","bid":0.29,"ask":0.46,"mid":0.375,"spread":0.17,"bid_size":null,"ask_size":null}
{"ts":"2026-08-23T17:53:29.524Z","event_type":"price_change","market_id":"3790323","outcome_index":1,"market_type":"set2","local_side":"away","local_uid":"2026-08-23_felix_balshaw_sebastian_gorzny","bid":0.29,"ask":0.46,"mid":0.375,"spread":0.17,"price":0.34,"size":0.0,"side":"BUY"}
{"ts":"2026-08-23T17:53:29.524Z","event_type":"price_change","market_id":"3790323","outcome_index":0,"market_type":"set2","local_side":"home","local_uid":"2026-08-23_felix_balshaw_sebastian_gorzny","bid":0.54,"ask":0.71,"mid":0.625,"spread":0.17,"price":0.66,"size":0.0,"side":"SELL"}
{"ts":"2026-08-23T17:53:29.525Z","event_type":"best_bid_ask","market_id":"3790323","outcome_index":0,"market_type":"set2","local_side":"home","local_uid":"2026-08-23_felix_balshaw_sebastian_gorzny","bid":0.54,"ask":0.7,"mid":0.62,"spread":0.16,"bid_size":null,"ask_size":null}
{"ts":"2026-08-23T17:53:29.525Z","event_type":"best_bid_ask","market_id":"3790323","outcome_index":1,"market_type":"set2","local_side":"away","local_uid":"2026-08-23_felix_balshaw_sebastian_gorzny","bid":0.3,"ask":0.46,"mid":0.38,"spread":0.16,"bid_size":null,"ask_size":null}
{"ts":"2026-08-23T17:53:29.526Z","event_type":"price_change","market_id":"3790323","outcome_index":1,"market_type":"set2","local_side":"away","local_uid":"2026-08-23_felix_balshaw_sebastian_gorzny","bid":0.3,"ask":0.46,"mid":0.38,"spread":0.16,"price":0.3,"size":31.87,"side":"BUY"}
{"ts":"2026-08-23T17:53:29.526Z","event_type":"price_change","market_id":"3790323","outcome_index":0,"market_type":"set2","local_side":"home","local_uid":"2026-08-23_felix_balshaw_sebastian_gorzny","bid":0.54,"ask":0.7,"mid":0.62,"spread":0.16,"price":0.7,"size":31.87,"side":"SELL"}
{"ts":"2026-08-23T17:53:29.526Z","event_type":"best_bid_ask","market_id":"3790323","outcome_index":0,"market_type":"set2","local_side":"home","local_uid":"2026-08-23_felix_balshaw_sebastian_gorzny","bid":0.53,"ask":0.7,"mid":0.615,"spread":0.17,"bid_size":null,"ask_size":null}
{"ts":"2026-08-23T17:53:29.526Z","event_type":"best_bid_ask","market_id":"3790323","outcome_index":1,"market_type":"set2","local_side":"away","local_uid":"2026-08-23_felix_balshaw_sebastian_gorzny","bid":0.3,"ask":0.47,"mid":0.385,"spread":0.17,"bid_size":null,"ask_size":null}
{"ts":"2026-08-23T17:53:29.526Z","event_type":"price_change","market_id":"3790323","outcome_index":0,"market_type":"set2","local_side":"home","local_uid":"2026-08-23_felix_balshaw_sebastian_gorzny","bid":0.53,"ask":0.7,"mid":0.615,"spread":0.17,"price":0.54,"size":0.0,"side":"BUY"}
{"ts":"2026-08-23T17:53:29.526Z","event_type":"price_change","market_id":"3790323","outcome_index":1,"market_type":"set2","local_side":"away","local_uid":"2026-08-23_felix_balshaw_sebastian_gorzny","bid":0.3,"ask":0.47,"mid":0.385,"spread":0.17,"price":0.46,"size":0.0,"side":"SELL"}
{"ts":"2026-08-23T17:53:29.531Z","event_type":"best_bid_ask","market_id":"3790323","outcome_index":0,"market_type":"set2","local_side":"home","local_uid":"2026-08-23_felix_balshaw_sebastian_gorzny","bid":0.51,"ask":0.7,"mid":0.605,"spread":0.19,"bid_size":null,"ask_size":null}
{"ts":"2026-08-23T17:53:29.531Z","event_type":"best_bid_ask","market_id":"3790323","outcome_index":1,"market_type":"set2","local_side":"away","local_uid":"2026-08-23_felix_balshaw_sebastian_gorzny","bid":0.3,"ask":0.49,"mid":0.395,"spread":0.19,"bid_size":null,"ask_size":null}
{"ts":"2026-08-23T17:53:29.531Z","event_type":"price_change","market_id":"3790323","outcome_index":0,"market_type":"set2","local_side":"home","local_uid":"2026-08-23_felix_balshaw_sebastian_gorzny","bid":0.51,"ask":0.7,"mid":0.605,"spread":0.19,"price":0.53,"size":0.0,"side":"BUY"}
{"ts":"2026-08-23T17:53:29.531Z","event_type":"price_change","market_id":"3790323","outcome_index":1,"market_type":"set2","local_side":"away","local_uid":"2026-08-23_felix_balshaw_sebastian_gorzny","bid":0.3,"ask":0.49,"mid":0.395,"spread":0.19,"price":0.47,"size":0.0,"side":"SELL"}
{"ts":"2026-08-23T17:53:29.545Z","event_type":"best_bid_ask","market_id":"3790323","outcome_index":0,"market_type":"set2","local_side":"home","local_uid":"2026-08-23_felix_balshaw_sebastian_gorzny","bid":0.51,"ask":0.72,"mid":0.615,"spread":0.21,"bid_size":null,"ask_size":null}
{"ts":"2026-08-23T17:53:29.546Z","event_type":"best_bid_ask","market_id":"3790323","outcome_index":1,"market_type":"set2","local_side":"away","local_uid":"2026-08-23_felix_balshaw_sebastian_gorzny","bid":0.28,"ask":0.49,"mid":0.385,"spread":0.21,"bid_size":null,"ask_size":null}
{"ts":"2026-08-23T17:53:29.546Z","event_type":"price_change","market_id":"3790323","outcome_index":1,"market_type":"set2","local_side":"away","local_uid":"2026-08-23_felix_balshaw_sebastian_gorzny","bid":0.28,"ask":0.49,"mid":0.385,"spread":0.21,"price":0.3,"size":0.0,"side":"BUY"}
{"ts":"2026-08-23T17:53:29.546Z","event_type":"price_change","market_id":"3790323","outcome_index":0,"market_type":"set2","local_side":"home","local_uid":"2026-08-23_felix_balshaw_sebastian_gorzny","bid":0.51,"ask":0.72,"mid":0.615,"spread":0.21,"price":0.7,"size":0.0,"side":"SELL"}
{"ts":"2026-08-23T17:53:29.587Z","event_type":"best_bid_ask","market_id":"3790323","outcome_index":0,"market_type":"set2","local_side":"home","local_uid":"2026-08-23_felix_balshaw_sebastian_gorzny","bid":0.51,"ask":0.71,"mid":0.61,"spread":0.2,"bid_size":null,"ask_size":null}
{"ts":"2026-08-23T17:53:29.587Z","event_type":"best_bid_ask","market_id":"3790323","outcome_index":1,"market_type":"set2","local_side":"away","local_uid":"2026-08-23_felix_balshaw_sebastian_gorzny","bid":0.29,"ask":0.49,"mid":0.39,"spread":0.2,"bid_size":null,"ask_size":null}
{"ts":"2026-08-23T17:53:29.597Z","event_type":"price_change","market_id":"3790323","outcome_index":1,"market_type":"set2","local_side":"away","local_uid":"2026-08-23_felix_balshaw_sebastian_gorzny","bid":0.29,"ask":0.49,"mid":0.39,"spread":0.2,"price":0.29,"size":34.49,"side":"BUY"}
{"ts":"2026-08-23T17:53:29.597Z","event_type":"price_change","market_id":"3790323","outcome_index":0,"market_type":"set2","local_side":"home","local_uid":"2026-08-23_felix_balshaw_sebastian_gorzny","bid":0.51,"ask":0.71,"mid":0.61,"spread":0.2,"price":0.71,"size":34.49,"side":"SELL"}
{"ts":"2026-08-23T17:53:29.651Z","event_type":"best_bid_ask","market_id":"3790323","outcome_index":0,"market_type":"set2","local_side":"home","local_uid":"2026-08-23_felix_balshaw_sebastian_gorzny","bid":0.51,"ask":0.72,"mid":0.615,"spread":0.21,"bid_size":null,"ask_size":null}
{"ts":"2026-08-23T17:53:29.651Z","event_type":"best_bid_ask","market_id":"3790323","outcome_index":1,"market_type":"set2","local_side":"away","local_uid":"2026-08-23_felix_balshaw_sebastian_gorzny","bid":0.28,"ask":0.49,"mid":0.385,"spread":0.21,"bid_size":null,"ask_size":null}
{"ts":"2026-08-23T17:53:29.652Z","event_type":"price_change","market_id":"3790323","outcome_index":1,"market_type":"set2","local_side":"away","local_uid":"2026-08-23_felix_balshaw_sebastian_gorzny","bid":0.28,"ask":0.49,"mid":0.385,"spread":0.21,"price":0.29,"size":0.0,"side":"BUY"}
{"ts":"2026-08-23T17:53:29.652Z","event_type":"price_change","market_id":"3790323","outcome_index":0,"market_type":"set2","local_side":"home","local_uid":"2026-08-23_felix_balshaw_sebastian_gorzny","bid":0.51,"ask":0.72,"mid":0.615,"spread":0.21,"price":0.71,"size":0.0,"side":"SELL"}
{"ts":"2026-08-23T17:53:29.667Z","event_type":"best_bid_ask","market_id":"3790323","outcome_index":0,"market_type":"set2","local_side":"home","local_uid":"2026-08-23_felix_balshaw_sebastian_gorzny","bid":0.5,"ask":0.72,"mid":0.61,"spread":0.22,"bid_size":null,"ask_size":null}
{"ts":"2026-08-23T17:53:29.667Z","event_type":"best_bid_ask","market_id":"3790323","outcome_index":1,"market_type":"set2","local_side":"away","local_uid":"2026-08-23_felix_balshaw_sebastian_gorzny","bid":0.28,"ask":0.5,"mid":0.39,"spread":0.22,"bid_size":null,"ask_size":null}
{"ts":"2026-08-23T17:53:29.667Z","event_type":"price_change","market_id":"3790323","outcome_index":0,"market_type":"set2","local_side":"home","local_uid":"2026-08-23_felix_balshaw_sebastian_gorzny","bid":0.5,"ask":0.72,"mid":0.61,"spread":0.22,"price":0.51,"size":0.0,"side":"BUY"}
{"ts":"2026-08-23T17:53:29.667Z","event_type":"price_change","market_id":"3790323","outcome_index":1,"market_type":"set2","local_side":"away","local_uid":"2026-08-23_felix_balshaw_sebastian_gorzny","bid":0.28,"ask":0.5,"mid":0.39,"spread":0.22,"price":0.49,"size":0.0,"side":"SELL"}
{"ts":"2026-08-23T17:53:30.247Z","event_type":"best_bid_ask","market_id":"3789925","outcome_index":0,"market_type":"match","local_side":"home","local_uid":"2026-08-23_pierre_hugues_herbert_quinn_vandecasteele","bid":0.82,"ask":0.83,"mid":0.825,"spread":0.01,"bid_size":null,"ask_size":null}
{"ts":"2026-08-23T17:53:30.247Z","event_type":"best_bid_ask","market_id":"3789925","outcome_index":1,"market_type":"match","local_side":"away","local_uid":"2026-08-23_pierre_hugues_herbert_quinn_vandecasteele","bid":0.17,"ask":0.18,"mid":0.175,"spread":0.01,"bid_size":null,"ask_size":null}
{"ts":"2026-08-23T17:53:30.248Z","event_type":"price_change","market_id":"3789925","outcome_index":1,"market_type":"match","local_side":"away","local_uid":"2026-08-23_pierre_hugues_herbert_quinn_vandecasteele","bid":0.17,"ask":0.18,"mid":0.175,"spread":0.01,"price":0.17,"size":3282.35,"side":"BUY"}
{"ts":"2026-08-23T17:53:30.248Z","event_type":"price_change","market_id":"3789925","outcome_index":0,"market_type":"match","local_side":"home","local_uid":"2026-08-23_pierre_hugues_herbert_quinn_vandecasteele","bid":0.82,"ask":0.83,"mid":0.825,"spread":0.01,"price":0.83,"size":3282.35,"side":"SELL"}
{"ts":"2026-08-23T17:53:30.463Z","event_type":"best_bid_ask","market_id":"3790415","outcome_index":0,"market_type":"set2","local_side":"home","local_uid":"2026-08-23_pierre_hugues_herbert_quinn_vandecasteele","bid":0.62,"ask":0.71,"mid":0.665,"spread":0.09,"bid_size":null,"ask_size":null}
{"ts":"2026-08-23T17:53:30.464Z","event_type":"best_bid_ask","market_id":"3790415","outcome_index":1,"market_type":"set2","local_side":"away","local_uid":"2026-08-23_pierre_hugues_herbert_quinn_vandecasteele","bid":0.29,"ask":0.38,"mid":0.335,"spread":0.09,"bid_size":null,"ask_size":null}
{"ts":"2026-08-23T17:53:30.471Z","event_type":"price_change","market_id":"3790415","outcome_index":1,"market_type":"set2","local_side":"away","local_uid":"2026-08-23_pierre_hugues_herbert_quinn_vandecasteele","bid":0.29,"ask":0.38,"mid":0.335,"spread":0.09,"price":0.29,"size":50.6,"side":"BUY"}
{"ts":"2026-08-23T17:53:30.471Z","event_type":"price_change","market_id":"3790415","outcome_index":0,"market_type":"set2","local_side":"home","local_uid":"2026-08-23_pierre_hugues_herbert_quinn_vandecasteele","bid":0.62,"ask":0.71,"mid":0.665,"spread":0.09,"price":0.71,"size":50.6,"side":"SELL"}
{"ts":"2026-08-23T17:53:30.476Z","event_type":"best_bid_ask","market_id":"3789997","outcome_index":0,"market_type":"match","local_side":"home","local_uid":"2026-08-23_oscar_weightman_alec_deckers","bid":0.03,"ask":0.05,"mid":0.04,"spread":0.02,"bid_size":null,"ask_size":null}
{"ts":"2026-08-23T17:53:30.476Z","event_type":"best_bid_ask","market_id":"3789997","outcome_index":1,"market_type":"match","local_side":"away","local_uid":"2026-08-23_oscar_weightman_alec_deckers","bid":0.95,"ask":0.97,"mid":0.96,"spread":0.02,"bid_size":null,"ask_size":null}
{"ts":"2026-08-23T17:53:30.478Z","event_type":"price_change","market_id":"3789997","outcome_index":0,"market_type":"match","local_side":"home","local_uid":"2026-08-23_oscar_weightman_alec_deckers","bid":0.03,"ask":0.05,"mid":0.04,"spread":0.02,"price":0.05,"size":10.0,"side":"SELL"}
{"ts":"2026-08-23T17:53:30.478Z","event_type":"price_change","market_id":"3789997","outcome_index":1,"market_type":"match","local_side":"away","local_uid":"2026-08-23_oscar_weightman_alec_deckers","bid":0.95,"ask":0.97,"mid":0.96,"spread":0.02,"price":0.95,"size":10.0,"side":"BUY"}
{"ts":"2026-08-23T17:53:30.490Z","event_type":"best_bid_ask","market_id":"3789929","outcome_index":0,"market_type":"match","local_side":"home","local_uid":"2026-08-23_felix_balshaw_sebastian_gorzny","bid":0.34,"ask":0.36,"mid":0.35,"spread":0.02,"bid_size":null,"ask_size":null}
{"ts":"2026-08-23T17:53:30.490Z","event_type":"best_bid_ask","market_id":"3789929","outcome_index":1,"market_type":"match","local_side":"away","local_uid":"2026-08-23_felix_balshaw_sebastian_gorzny","bid":0.64,"ask":0.66,"mid":0.65,"spread":0.02,"bid_size":null,"ask_size":null}
{"ts":"2026-08-23T17:53:30.490Z","event_type":"price_change","market_id":"3789929","outcome_index":1,"market_type":"match","local_side":"away","local_uid":"2026-08-23_felix_balshaw_sebastian_gorzny","bid":0.64,"ask":0.66,"mid":0.65,"spread":0.02,"price":0.65,"size":0.0,"side":"BUY"}
{"ts":"2026-08-23T17:53:30.490Z","event_type":"price_change","market_id":"3789929","outcome_index":0,"market_type":"match","local_side":"home","local_uid":"2026-08-23_felix_balshaw_sebastian_gorzny","bid":0.34,"ask":0.36,"mid":0.35,"spread":0.02,"price":0.35,"size":0.0,"side":"SELL"}
{"ts":"2026-08-23T17:53:31.061Z","event_type":"book","market_id":"3789997","outcome_index":0,"market_type":"match","local_side":"home","local_uid":"2026-08-23_oscar_weightman_alec_deckers","bid":0.03,"ask":0.05,"mid":0.04,"spread":0.02,"bid_size":1463.8,"ask_size":474.26}
{"ts":"2026-08-23T17:53:31.062Z","event_type":"book","market_id":"3789997","outcome_index":1,"market_type":"match","local_side":"away","local_uid":"2026-08-23_oscar_weightman_alec_deckers","bid":0.95,"ask":0.97,"mid":0.96,"spread":0.02,"bid_size":474.26,"ask_size":1463.8}
{"ts":"2026-08-23T17:53:31.292Z","event_type":"last_trade_price","market_id":"3789997","outcome_index":1,"market_type":"match","local_side":"away","local_uid":"2026-08-23_oscar_weightman_alec_deckers","last_trade":0.95,"trade_size":259.14,"trade_side":"SELL","trade_notional":246.183}
{"ts":"2026-08-23T17:53:31.507Z","event_type":"best_bid_ask","market_id":"3789997","outcome_index":0,"market_type":"match","local_side":"home","local_uid":"2026-08-23_oscar_weightman_alec_deckers","bid":0.03,"ask":0.06,"mid":0.045,"spread":0.03,"bid_size":null,"ask_size":null}
{"ts":"2026-08-23T17:53:31.508Z","event_type":"best_bid_ask","market_id":"3789997","outcome_index":1,"market_type":"match","local_side":"away","local_uid":"2026-08-23_oscar_weightman_alec_deckers","bid":0.94,"ask":0.97,"mid":0.955,"spread":0.03,"bid_size":null,"ask_size":null}
{"ts":"2026-08-23T17:53:31.518Z","event_type":"price_change","market_id":"3789997","outcome_index":0,"market_type":"match","local_side":"home","local_uid":"2026-08-23_oscar_weightman_alec_deckers","bid":0.03,"ask":0.06,"mid":0.045,"spread":0.03,"price":0.05,"size":0.0,"side":"SELL"}
{"ts":"2026-08-23T17:53:31.518Z","event_type":"price_change","market_id":"3789997","outcome_index":1,"market_type":"match","local_side":"away","local_uid":"2026-08-23_oscar_weightman_alec_deckers","bid":0.94,"ask":0.97,"mid":0.955,"spread":0.03,"price":0.95,"size":0.0,"side":"BUY"}
{"ts":"2026-08-23T17:53:31.747Z","event_type":"best_bid_ask","market_id":"3790323","outcome_index":0,"market_type":"set2","local_side":"home","local_uid":"2026-08-23_felix_balshaw_sebastian_gorzny","bid":0.5,"ask":0.73,"mid":0.615,"spread":0.23,"bid_size":null,"ask_size":null}
{"ts":"2026-08-23T17:53:31.750Z","event_type":"best_bid_ask","market_id":"3790323","outcome_index":1,"market_type":"set2","local_side":"away","local_uid":"2026-08-23_felix_balshaw_sebastian_gorzny","bid":0.27,"ask":0.5,"mid":0.385,"spread":0.23,"bid_size":null,"ask_size":null}
{"ts":"2026-08-23T17:53:31.750Z","event_type":"price_change","market_id":"3790323","outcome_index":1,"market_type":"set2","local_side":"away","local_uid":"2026-08-23_felix_balshaw_sebastian_gorzny","bid":0.27,"ask":0.5,"mid":0.385,"spread":0.23,"price":0.28,"size":0.0,"side":"BUY"}
{"ts":"2026-08-23T17:53:31.750Z","event_type":"price_change","market_id":"3790323","outcome_index":0,"market_type":"set2","local_side":"home","local_uid":"2026-08-23_felix_balshaw_sebastian_gorzny","bid":0.5,"ask":0.73,"mid":0.615,"spread":0.23,"price":0.72,"size":0.0,"side":"SELL"}
{"ts":"2026-08-23T17:53:31.791Z","event_type":"price_change","market_id":"3795974","outcome_index":0,"market_type":"match","local_side":"home","local_uid":"2026-08-23_juan_jose_bianchi_keshav_chopra","bid":0.15,"ask":0.19,"mid":0.17,"spread":0.04,"price":0.13,"size":1599.62,"side":"BUY"}
{"ts":"2026-08-23T17:53:31.791Z","event_type":"price_change","market_id":"3795974","outcome_index":1,"market_type":"match","local_side":"away","local_uid":"2026-08-23_juan_jose_bianchi_keshav_chopra","bid":0.81,"ask":0.85,"mid":0.83,"spread":0.04,"price":0.87,"size":1599.62,"side":"SELL"}
{"ts":"2026-08-23T17:53:31.871Z","event_type":"best_bid_ask","market_id":"3790323","outcome_index":0,"market_type":"set2","local_side":"home","local_uid":"2026-08-23_felix_balshaw_sebastian_gorzny","bid":0.5,"ask":0.71,"mid":0.605,"spread":0.21,"bid_size":null,"ask_size":null}
{"ts":"2026-08-23T17:53:31.871Z","event_type":"best_bid_ask","market_id":"3790323","outcome_index":1,"market_type":"set2","local_side":"away","local_uid":"2026-08-23_felix_balshaw_sebastian_gorzny","bid":0.29,"ask":0.5,"mid":0.395,"spread":0.21,"bid_size":null,"ask_size":null}
{"ts":"2026-08-23T17:53:31.871Z","event_type":"price_change","market_id":"3790323","outcome_index":1,"market_type":"set2","local_side":"away","local_uid":"2026-08-23_felix_balshaw_sebastian_gorzny","bid":0.29,"ask":0.5,"mid":0.395,"spread":0.21,"price":0.29,"size":74.29,"side":"BUY"}
{"ts":"2026-08-23T17:53:31.871Z","event_type":"price_change","market_id":"3790323","outcome_index":0,"market_type":"set2","local_side":"home","local_uid":"2026-08-23_felix_balshaw_sebastian_gorzny","bid":0.5,"ask":0.71,"mid":0.605,"spread":0.21,"price":0.71,"size":74.29,"side":"SELL"}
{"ts":"2026-08-23T17:53:32.043Z","event_type":"best_bid_ask","market_id":"3790323","outcome_index":0,"market_type":"set2","local_side":"home","local_uid":"2026-08-23_felix_balshaw_sebastian_gorzny","bid":0.51,"ask":0.71,"mid":0.61,"spread":0.2,"bid_size":null,"ask_size":null}
{"ts":"2026-08-23T17:53:32.044Z","event_type":"best_bid_ask","market_id":"3790323","outcome_index":1,"market_type":"set2","local_side":"away","local_uid":"2026-08-23_felix_balshaw_sebastian_gorzny","bid":0.29,"ask":0.49,"mid":0.39,"spread":0.2,"bid_size":null,"ask_size":null}
{"ts":"2026-08-23T17:53:32.044Z","event_type":"price_change","market_id":"3790323","outcome_index":0,"market_type":"set2","local_side":"home","local_uid":"2026-08-23_felix_balshaw_sebastian_gorzny","bid":0.51,"ask":0.71,"mid":0.61,"spread":0.2,"price":0.51,"size":29.03,"side":"BUY"}
{"ts":"2026-08-23T17:53:32.044Z","event_type":"price_change","market_id":"3790323","outcome_index":1,"market_type":"set2","local_side":"away","local_uid":"2026-08-23_felix_balshaw_sebastian_gorzny","bid":0.29,"ask":0.49,"mid":0.39,"spread":0.2,"price":0.49,"size":29.03,"side":"SELL"}
{"ts":"2026-08-23T17:53:32.725Z","event_type":"best_bid_ask","market_id":"3790323","outcome_index":0,"market_type":"set2","local_side":"home","local_uid":"2026-08-23_felix_balshaw_sebastian_gorzny","bid":0.53,"ask":0.71,"mid":0.62,"spread":0.18,"bid_size":null,"ask_size":null}
{"ts":"2026-08-23T17:53:32.726Z","event_type":"best_bid_ask","market_id":"3790323","outcome_index":1,"market_type":"set2","local_side":"away","local_uid":"2026-08-23_felix_balshaw_sebastian_gorzny","bid":0.29,"ask":0.47,"mid":0.38,"spread":0.18,"bid_size":null,"ask_size":null}
{"ts":"2026-08-23T17:53:32.726Z","event_type":"price_change","market_id":"3790323","outcome_index":0,"market_type":"set2","local_side":"home","local_uid":"2026-08-23_felix_balshaw_sebastian_gorzny","bid":0.53,"ask":0.71,"mid":0.62,"spread":0.18,"price":0.53,"size":423.0,"side":"BUY"}
{"ts":"2026-08-23T17:53:32.726Z","event_type":"price_change","market_id":"3790323","outcome_index":1,"market_type":"set2","local_side":"away","local_uid":"2026-08-23_felix_balshaw_sebastian_gorzny","bid":0.29,"ask":0.47,"mid":0.38,"spread":0.18,"price":0.47,"size":423.0,"side":"SELL"}
{"ts":"2026-08-23T17:53:32.726Z","event_type":"best_bid_ask","market_id":"3790323","outcome_index":0,"market_type":"set2","local_side":"home","local_uid":"2026-08-23_felix_balshaw_sebastian_gorzny","bid":0.54,"ask":0.71,"mid":0.625,"spread":0.17,"bid_size":null,"ask_size":null}
{"ts":"2026-08-23T17:53:32.726Z","event_type":"best_bid_ask","market_id":"3790323","outcome_index":1,"market_type":"set2","local_side":"away","local_uid":"2026-08-23_felix_balshaw_sebastian_gorzny","bid":0.29,"ask":0.46,"mid":0.375,"spread":0.17,"bid_size":null,"ask_size":null}
{"ts":"2026-08-23T17:53:32.726Z","event_type":"price_change","market_id":"3790323","outcome_index":0,"market_type":"set2","local_side":"home","local_uid":"2026-08-23_felix_balshaw_sebastian_gorzny","bid":0.54,"ask":0.71,"mid":0.625,"spread":0.17,"price":0.54,"size":88.0,"side":"BUY"}
{"ts":"2026-08-23T17:53:32.726Z","event_type":"price_change","market_id":"3790323","outcome_index":1,"market_type":"set2","local_side":"away","local_uid":"2026-08-23_felix_balshaw_sebastian_gorzny","bid":0.29,"ask":0.46,"mid":0.375,"spread":0.17,"price":0.46,"size":88.0,"side":"SELL"}
{"ts":"2026-08-23T17:53:32.736Z","event_type":"best_bid_ask","market_id":"3790323","outcome_index":0,"market_type":"set2","local_side":"home","local_uid":"2026-08-23_felix_balshaw_sebastian_gorzny","bid":0.54,"ask":0.7,"mid":0.62,"spread":0.16,"bid_size":null,"ask_size":null}
{"ts":"2026-08-23T17:53:32.736Z","event_type":"best_bid_ask","market_id":"3790323","outcome_index":1,"market_type":"set2","local_side":"away","local_uid":"2026-08-23_felix_balshaw_sebastian_gorzny","bid":0.3,"ask":0.46,"mid":0.38,"spread":0.16,"bid_size":null,"ask_size":null}
{"ts":"2026-08-23T17:53:32.882Z","event_type":"price_change","market_id":"3790323","outcome_index":1,"market_type":"set2","local_side":"away","local_uid":"2026-08-23_felix_balshaw_sebastian_gorzny","bid":0.3,"ask":0.46,"mid":0.38,"spread":0.16,"price":0.3,"size":423.0,"side":"BUY"}
{"ts":"2026-08-23T17:53:32.882Z","event_type":"price_change","market_id":"3790323","outcome_index":0,"market_type":"set2","local_side":"home","local_uid":"2026-08-23_felix_balshaw_sebastian_gorzny","bid":0.54,"ask":0.7,"mid":0.62,"spread":0.16,"price":0.7,"size":423.0,"side":"SELL"}
{"ts":"2026-08-23T17:53:32.889Z","event_type":"best_bid_ask","market_id":"3789929","outcome_index":0,"market_type":"match","local_side":"home","local_uid":"2026-08-23_felix_balshaw_sebastian_gorzny","bid":0.35,"ask":0.36,"mid":0.355,"spread":0.01,"bid_size":null,"ask_size":null}
{"ts":"2026-08-23T17:53:32.889Z","event_type":"best_bid_ask","market_id":"3789929","outcome_index":1,"market_type":"match","local_side":"away","local_uid":"2026-08-23_felix_balshaw_sebastian_gorzny","bid":0.64,"ask":0.65,"mid":0.645,"spread":0.01,"bid_size":null,"ask_size":null}
{"ts":"2026-08-23T17:53:32.890Z","event_type":"price_change","market_id":"3789929","outcome_index":0,"market_type":"match","local_side":"home","local_uid":"2026-08-23_felix_balshaw_sebastian_gorzny","bid":0.35,"ask":0.36,"mid":0.355,"spread":0.01,"price":0.35,"size":38.0,"side":"BUY"}
{"ts":"2026-08-23T17:53:32.890Z","event_type":"price_change","market_id":"3789929","outcome_index":1,"market_type":"match","local_side":"away","local_uid":"2026-08-23_felix_balshaw_sebastian_gorzny","bid":0.64,"ask":0.65,"mid":0.645,"spread":0.01,"price":0.65,"size":38.0,"side":"SELL"}
{"ts":"2026-08-23T17:53:32.890Z","event_type":"best_bid_ask","market_id":"3790323","outcome_index":0,"market_type":"set2","local_side":"home","local_uid":"2026-08-23_felix_balshaw_sebastian_gorzny","bid":0.54,"ask":0.69,"mid":0.615,"spread":0.15,"bid_size":null,"ask_size":null}
{"ts":"2026-08-23T17:53:32.890Z","event_type":"best_bid_ask","market_id":"3790323","outcome_index":1,"market_type":"set2","local_side":"away","local_uid":"2026-08-23_felix_balshaw_sebastian_gorzny","bid":0.31,"ask":0.46,"mid":0.385,"spread":0.15,"bid_size":null,"ask_size":null}
{"ts":"2026-08-23T17:53:32.890Z","event_type":"price_change","market_id":"3790323","outcome_index":1,"market_type":"set2","local_side":"away","local_uid":"2026-08-23_felix_balshaw_sebastian_gorzny","bid":0.31,"ask":0.46,"mid":0.385,"spread":0.15,"price":0.31,"size":88.0,"side":"BUY"}
{"ts":"2026-08-23T17:53:32.890Z","event_type":"price_change","market_id":"3790323","outcome_index":0,"market_type":"set2","local_side":"home","local_uid":"2026-08-23_felix_balshaw_sebastian_gorzny","bid":0.54,"ask":0.69,"mid":0.615,"spread":0.15,"price":0.69,"size":88.0,"side":"SELL"}
{"ts":"2026-08-23T17:53:32.894Z","event_type":"best_bid_ask","market_id":"3790323","outcome_index":0,"market_type":"set2","local_side":"home","local_uid":"2026-08-23_felix_balshaw_sebastian_gorzny","bid":0.55,"ask":0.69,"mid":0.62,"spread":0.14,"bid_size":null,"ask_size":null}
{"ts":"2026-08-23T17:53:32.894Z","event_type":"best_bid_ask","market_id":"3790323","outcome_index":1,"market_type":"set2","local_side":"away","local_uid":"2026-08-23_felix_balshaw_sebastian_gorzny","bid":0.31,"ask":0.45,"mid":0.38,"spread":0.14,"bid_size":null,"ask_size":null}
{"ts":"2026-08-23T17:53:32.894Z","event_type":"price_change","market_id":"3790323","outcome_index":0,"market_type":"set2","local_side":"home","local_uid":"2026-08-23_felix_balshaw_sebastian_gorzny","bid":0.55,"ask":0.69,"mid":0.62,"spread":0.14,"price":0.55,"size":150.0,"side":"BUY"}
{"ts":"2026-08-23T17:53:32.894Z","event_type":"price_change","market_id":"3790323","outcome_index":1,"market_type":"set2","local_side":"away","local_uid":"2026-08-23_felix_balshaw_sebastian_gorzny","bid":0.31,"ask":0.45,"mid":0.38,"spread":0.14,"price":0.45,"size":150.0,"side":"SELL"}
{"ts":"2026-08-23T17:53:32.894Z","event_type":"best_bid_ask","market_id":"3790323","outcome_index":0,"market_type":"set2","local_side":"home","local_uid":"2026-08-23_felix_balshaw_sebastian_gorzny","bid":0.55,"ask":0.67,"mid":0.61,"spread":0.12,"bid_size":null,"ask_size":null}
{"ts":"2026-08-23T17:53:32.895Z","event_type":"best_bid_ask","market_id":"3790323","outcome_index":1,"market_type":"set2","local_side":"away","local_uid":"2026-08-23_felix_balshaw_sebastian_gorzny","bid":0.33,"ask":0.45,"mid":0.39,"spread":0.12,"bid_size":null,"ask_size":null}
{"ts":"2026-08-23T17:53:32.895Z","event_type":"price_change","market_id":"3790323","outcome_index":1,"market_type":"set2","local_side":"away","local_uid":"2026-08-23_felix_balshaw_sebastian_gorzny","bid":0.33,"ask":0.45,"mid":0.39,"spread":0.12,"price":0.33,"size":150.0,"side":"BUY"}
{"ts":"2026-08-23T17:53:32.895Z","event_type":"price_change","market_id":"3790323","outcome_index":0,"market_type":"set2","local_side":"home","local_uid":"2026-08-23_felix_balshaw_sebastian_gorzny","bid":0.55,"ask":0.67,"mid":0.61,"spread":0.12,"price":0.67,"size":150.0,"side":"SELL"}
{"ts":"2026-08-23T17:53:33.063Z","event_type":"book","market_id":"3789927","outcome_index":0,"market_type":"match","local_side":"home","local_uid":"2026-08-23_hugo_grenier_mees_rottgering","bid":0.3,"ask":0.31,"mid":0.305,"spread":0.01,"bid_size":5360.7,"ask_size":22595.94}
{"ts":"2026-08-23T17:53:33.063Z","event_type":"book","market_id":"3789927","outcome_index":1,"market_type":"match","local_side":"away","local_uid":"2026-08-23_hugo_grenier_mees_rottgering","bid":0.69,"ask":0.7,"mid":0.695,"spread":0.01,"bid_size":22595.94,"ask_size":5360.7}
{"ts":"2026-08-23T17:53:33.170Z","event_type":"last_trade_price","market_id":"3789927","outcome_index":0,"market_type":"match","local_side":"home","local_uid":"2026-08-23_hugo_grenier_mees_rottgering","last_trade":0.31,"trade_size":7.0,"trade_side":"BUY","trade_notional":2.17}
{"ts":"2026-08-23T17:53:33.741Z","event_type":"new_market","market_id":"0x5592cc4b303e941229823cfab1a0d3b73f9fff25076dbd4613ebf8ffb20a69ed"}
{"ts":"2026-08-23T17:53:34.298Z","event_type":"new_market","market_id":"0xfce4e6c131f4b9c975d949183d58d7c1f8ba15b99f50bd69d74d96e9dc8d9059"}
{"ts":"2026-08-23T17:53:34.548Z","event_type":"best_bid_ask","market_id":"3790415","outcome_index":0,"market_type":"set2","local_side":"home","local_uid":"2026-08-23_pierre_hugues_herbert_quinn_vandecasteele","bid":0.62,"ask":0.72,"mid":0.67,"spread":0.1,"bid_size":null,"ask_size":null}
{"ts":"2026-08-23T17:53:34.548Z","event_type":"best_bid_ask","market_id":"3790415","outcome_index":1,"market_type":"set2","local_side":"away","local_uid":"2026-08-23_pierre_hugues_herbert_quinn_vandecasteele","bid":0.28,"ask":0.38,"mid":0.33,"spread":0.1,"bid_size":null,"ask_size":null}
{"ts":"2026-08-23T17:53:34.548Z","event_type":"price_change","market_id":"3790415","outcome_index":1,"market_type":"set2","local_side":"away","local_uid":"2026-08-23_pierre_hugues_herbert_quinn_vandecasteele","bid":0.28,"ask":0.38,"mid":0.33,"spread":0.1,"price":0.29,"size":0.0,"side":"BUY"}
{"ts":"2026-08-23T17:53:34.548Z","event_type":"price_change","market_id":"3790415","outcome_index":0,"market_type":"set2","local_side":"home","local_uid":"2026-08-23_pierre_hugues_herbert_quinn_vandecasteele","bid":0.62,"ask":0.72,"mid":0.67,"spread":0.1,"price":0.71,"size":0.0,"side":"SELL"}
{"ts":"2026-08-23T17:53:34.625Z","event_type":"best_bid_ask","market_id":"3790415","outcome_index":0,"market_type":"set2","local_side":"home","local_uid":"2026-08-23_pierre_hugues_herbert_quinn_vandecasteele","bid":0.62,"ask":0.71,"mid":0.665,"spread":0.09,"bid_size":null,"ask_size":null}
{"ts":"2026-08-23T17:53:34.625Z","event_type":"best_bid_ask","market_id":"3790415","outcome_index":1,"market_type":"set2","local_side":"away","local_uid":"2026-08-23_pierre_hugues_herbert_quinn_vandecasteele","bid":0.29,"ask":0.38,"mid":0.335,"spread":0.09,"bid_size":null,"ask_size":null}
{"ts":"2026-08-23T17:53:34.625Z","event_type":"price_change","market_id":"3790415","outcome_index":1,"market_type":"set2","local_side":"away","local_uid":"2026-08-23_pierre_hugues_herbert_quinn_vandecasteele","bid":0.29,"ask":0.38,"mid":0.335,"spread":0.09,"price":0.29,"size":40.25,"side":"BUY"}
{"ts":"2026-08-23T17:53:34.625Z","event_type":"price_change","market_id":"3790415","outcome_index":0,"market_type":"set2","local_side":"home","local_uid":"2026-08-23_pierre_hugues_herbert_quinn_vandecasteele","bid":0.62,"ask":0.71,"mid":0.665,"spread":0.09,"price":0.71,"size":40.25,"side":"SELL"}
{"ts":"2026-08-23T17:53:34.906Z","event_type":"price_change","market_id":"3790345","outcome_index":1,"market_type":"set1","local_side":"away","local_uid":"2026-08-23_stefanos_sakellaridis_luca_van_assche","bid":0.999,"ask":1.0,"mid":0.9995,"spread":0.001,"price":0.013,"size":10560.0,"side":"BUY"}
{"ts":"2026-08-23T17:53:34.906Z","event_type":"price_change","market_id":"3790345","outcome_index":0,"market_type":"set1","local_side":"home","local_uid":"2026-08-23_stefanos_sakellaridis_luca_van_assche","bid":0.0,"ask":0.001,"mid":0.0005,"spread":0.001,"price":0.987,"size":10560.0,"side":"SELL"}
{"ts":"2026-08-23T17:53:35.326Z","event_type":"best_bid_ask","market_id":"3789927","outcome_index":0,"market_type":"match","local_side":"home","local_uid":"2026-08-23_hugo_grenier_mees_rottgering","bid":0.29,"ask":0.31,"mid":0.3,"spread":0.02,"bid_size":null,"ask_size":null}
{"ts":"2026-08-23T17:53:35.326Z","event_type":"best_bid_ask","market_id":"3789927","outcome_index":1,"market_type":"match","local_side":"away","local_uid":"2026-08-23_hugo_grenier_mees_rottgering","bid":0.69,"ask":0.71,"mid":0.7,"spread":0.02,"bid_size":null,"ask_size":null}
{"ts":"2026-08-23T17:53:35.326Z","event_type":"price_change","market_id":"3789927","outcome_index":0,"market_type":"match","local_side":"home","local_uid":"2026-08-23_hugo_grenier_mees_rottgering","bid":0.29,"ask":0.31,"mid":0.3,"spread":0.02,"price":0.3,"size":0.0,"side":"BUY"}
{"ts":"2026-08-23T17:53:35.326Z","event_type":"price_change","market_id":"3789927","outcome_index":1,"market_type":"match","local_side":"away","local_uid":"2026-08-23_hugo_grenier_mees_rottgering","bid":0.69,"ask":0.71,"mid":0.7,"spread":0.02,"price":0.7,"size":0.0,"side":"SELL"}
{"ts":"2026-08-23T17:53:35.622Z","event_type":"best_bid_ask","market_id":"3789927","outcome_index":0,"market_type":"match","local_side":"home","local_uid":"2026-08-23_hugo_grenier_mees_rottgering","bid":0.3,"ask":0.31,"mid":0.305,"spread":0.01,"bid_size":null,"ask_size":null}
{"ts":"2026-08-23T17:53:35.623Z","event_type":"best_bid_ask","market_id":"3789927","outcome_index":1,"market_type":"match","local_side":"away","local_uid":"2026-08-23_hugo_grenier_mees_rottgering","bid":0.69,"ask":0.7,"mid":0.695,"spread":0.01,"bid_size":null,"ask_size":null}
{"ts":"2026-08-23T17:53:35.623Z","event_type":"price_change","market_id":"3789927","outcome_index":0,"market_type":"match","local_side":"home","local_uid":"2026-08-23_hugo_grenier_mees_rottgering","bid":0.3,"ask":0.31,"mid":0.305,"spread":0.01,"price":0.3,"size":4822.0,"side":"BUY"}
{"ts":"2026-08-23T17:53:35.623Z","event_type":"price_change","market_id":"3789927","outcome_index":1,"market_type":"match","local_side":"away","local_uid":"2026-08-23_hugo_grenier_mees_rottgering","bid":0.69,"ask":0.7,"mid":0.695,"spread":0.01,"price":0.7,"size":4822.0,"side":"SELL"}
{"ts":"2026-08-23T17:53:35.726Z","event_type":"price_change","market_id":"3780820","outcome_index":0,"market_type":"match","local_side":"home","local_uid":"2026-08-23_sho_shimabukuro_miomir_kecmanovic","bid":0.31,"ask":0.32,"mid":0.315,"spread":0.01,"price":0.15,"size":41.0,"side":"BUY"}
{"ts":"2026-08-23T17:53:35.726Z","event_type":"price_change","market_id":"3780820","outcome_index":1,"market_type":"match","local_side":"away","local_uid":"2026-08-23_sho_shimabukuro_miomir_kecmanovic","bid":0.68,"ask":0.69,"mid":0.685,"spread":0.01,"price":0.85,"size":41.0,"side":"SELL"}
{"ts":"2026-08-23T17:53:36.010Z","event_type":"price_change","market_id":"3790419","outcome_index":0,"market_type":"set1","local_side":"home","local_uid":"2026-08-23_pierre_hugues_herbert_quinn_vandecasteele","bid":0.999,"ask":1.0,"mid":0.9995,"spread":0.001,"price":0.013,"size":10560.0,"side":"BUY"}
{"ts":"2026-08-23T17:53:36.010Z","event_type":"price_change","market_id":"3790419","outcome_index":1,"market_type":"set1","local_side":"away","local_uid":"2026-08-23_pierre_hugues_herbert_quinn_vandecasteele","bid":0.0,"ask":0.001,"mid":0.0005,"spread":0.001,"price":0.987,"size":10560.0,"side":"SELL"}
{"ts":"2026-08-23T17:53:36.249Z","event_type":"best_bid_ask","market_id":"3795958","outcome_index":0,"market_type":"match","local_side":"home","local_uid":"2026-08-23_bruno_kuzuhara_kody_pearson","bid":0.95,"ask":0.96,"mid":0.955,"spread":0.01,"bid_size":null,"ask_size":null}
{"ts":"2026-08-23T17:53:36.249Z","event_type":"best_bid_ask","market_id":"3795958","outcome_index":1,"market_type":"match","local_side":"away","local_uid":"2026-08-23_bruno_kuzuhara_kody_pearson","bid":0.04,"ask":0.05,"mid":0.045,"spread":0.01,"bid_size":null,"ask_size":null}
{"ts":"2026-08-23T17:53:36.249Z","event_type":"price_change","market_id":"3795958","outcome_index":0,"market_type":"match","local_side":"home","local_uid":"2026-08-23_bruno_kuzuhara_kody_pearson","bid":0.95,"ask":0.96,"mid":0.955,"spread":0.01,"price":0.952,"size":0.0,"side":"BUY"}
{"ts":"2026-08-23T17:53:36.250Z","event_type":"price_change","market_id":"3795958","outcome_index":1,"market_type":"match","local_side":"away","local_uid":"2026-08-23_bruno_kuzuhara_kody_pearson","bid":0.04,"ask":0.05,"mid":0.045,"spread":0.01,"price":0.048,"size":0.0,"side":"SELL"}
{"ts":"2026-08-23T17:53:36.278Z","event_type":"best_bid_ask","market_id":"3795958","outcome_index":0,"market_type":"match","local_side":"home","local_uid":"2026-08-23_bruno_kuzuhara_kody_pearson","bid":0.942,"ask":0.96,"mid":0.951,"spread":0.018,"bid_size":null,"ask_size":null}
{"ts":"2026-08-23T17:53:36.278Z","event_type":"best_bid_ask","market_id":"3795958","outcome_index":1,"market_type":"match","local_side":"away","local_uid":"2026-08-23_bruno_kuzuhara_kody_pearson","bid":0.04,"ask":0.058,"mid":0.049,"spread":0.018,"bid_size":null,"ask_size":null}
{"ts":"2026-08-23T17:53:36.278Z","event_type":"price_change","market_id":"3795958","outcome_index":1,"market_type":"match","local_side":"away","local_uid":"2026-08-23_bruno_kuzuhara_kody_pearson","bid":0.04,"ask":0.058,"mid":0.049,"spread":0.018,"price":0.05,"size":0.0,"side":"SELL"}
{"ts":"2026-08-23T17:53:36.278Z","event_type":"price_change","market_id":"3795958","outcome_index":0,"market_type":"match","local_side":"home","local_uid":"2026-08-23_bruno_kuzuhara_kody_pearson","bid":0.942,"ask":0.96,"mid":0.951,"spread":0.018,"price":0.95,"size":0.0,"side":"BUY"}
{"ts":"2026-08-23T17:53:36.442Z","event_type":"new_market","market_id":"0x1a2a06ae58d0d1c02c7f5475c975a2606bc335bf2d9060cb677161dbabafe5d5"}
{"ts":"2026-08-23T17:53:36.837Z","event_type":"best_bid_ask","market_id":"3790415","outcome_index":0,"market_type":"set2","local_side":"home","local_uid":"2026-08-23_pierre_hugues_herbert_quinn_vandecasteele","bid":0.59,"ask":0.73,"mid":0.66,"spread":0.14,"bid_size":null,"ask_size":null}
{"ts":"2026-08-23T17:53:36.837Z","event_type":"best_bid_ask","market_id":"3790415","outcome_index":1,"market_type":"set2","local_side":"away","local_uid":"2026-08-23_pierre_hugues_herbert_quinn_vandecasteele","bid":0.27,"ask":0.41,"mid":0.34,"spread":0.14,"bid_size":null,"ask_size":null}
{"ts":"2026-08-23T17:53:36.838Z","event_type":"price_change","market_id":"3790415","outcome_index":0,"market_type":"set2","local_side":"home","local_uid":"2026-08-23_pierre_hugues_herbert_quinn_vandecasteele","bid":0.59,"ask":0.73,"mid":0.66,"spread":0.14,"price":0.62,"size":0.0,"side":"BUY"}
{"ts":"2026-08-23T17:53:36.838Z","event_type":"price_change","market_id":"3790415","outcome_index":1,"market_type":"set2","local_side":"away","local_uid":"2026-08-23_pierre_hugues_herbert_quinn_vandecasteele","bid":0.27,"ask":0.41,"mid":0.34,"spread":0.14,"price":0.38,"size":0.0,"side":"SELL"}
{"ts":"2026-08-23T17:53:36.844Z","event_type":"best_bid_ask","market_id":"3790415","outcome_index":0,"market_type":"set2","local_side":"home","local_uid":"2026-08-23_pierre_hugues_herbert_quinn_vandecasteele","bid":0.59,"ask":0.74,"mid":0.665,"spread":0.15,"bid_size":null,"ask_size":null}
{"ts":"2026-08-23T17:53:36.844Z","event_type":"best_bid_ask","market_id":"3790415","outcome_index":1,"market_type":"set2","local_side":"away","local_uid":"2026-08-23_pierre_hugues_herbert_quinn_vandecasteele","bid":0.26,"ask":0.41,"mid":0.335,"spread":0.15,"bid_size":null,"ask_size":null}
{"ts":"2026-08-23T17:53:36.864Z","event_type":"price_change","market_id":"3790415","outcome_index":1,"market_type":"set2","local_side":"away","local_uid":"2026-08-23_pierre_hugues_herbert_quinn_vandecasteele","bid":0.26,"ask":0.41,"mid":0.335,"spread":0.15,"price":0.27,"size":0.0,"side":"BUY"}
{"ts":"2026-08-23T17:53:36.864Z","event_type":"price_change","market_id":"3790415","outcome_index":0,"market_type":"set2","local_side":"home","local_uid":"2026-08-23_pierre_hugues_herbert_quinn_vandecasteele","bid":0.59,"ask":0.74,"mid":0.665,"spread":0.15,"price":0.73,"size":0.0,"side":"SELL"}
{"ts":"2026-08-23T17:53:36.864Z","event_type":"best_bid_ask","market_id":"3790415","outcome_index":0,"market_type":"set2","local_side":"home","local_uid":"2026-08-23_pierre_hugues_herbert_quinn_vandecasteele","bid":0.59,"ask":0.73,"mid":0.66,"spread":0.14,"bid_size":null,"ask_size":null}
{"ts":"2026-08-23T17:53:36.864Z","event_type":"best_bid_ask","market_id":"3790415","outcome_index":1,"market_type":"set2","local_side":"away","local_uid":"2026-08-23_pierre_hugues_herbert_quinn_vandecasteele","bid":0.27,"ask":0.41,"mid":0.34,"spread":0.14,"bid_size":null,"ask_size":null}
{"ts":"2026-08-23T17:53:36.866Z","event_type":"price_change","market_id":"3790415","outcome_index":1,"market_type":"set2","local_side":"away","local_uid":"2026-08-23_pierre_hugues_herbert_quinn_vandecasteele","bid":0.27,"ask":0.41,"mid":0.34,"spread":0.14,"price":0.27,"size":88.0,"side":"BUY"}
{"ts":"2026-08-23T17:53:36.866Z","event_type":"price_change","market_id":"3790415","outcome_index":0,"market_type":"set2","local_side":"home","local_uid":"2026-08-23_pierre_hugues_herbert_quinn_vandecasteele","bid":0.59,"ask":0.73,"mid":0.66,"spread":0.14,"price":0.73,"size":88.0,"side":"SELL"}
{"ts":"2026-08-23T17:53:36.904Z","event_type":"best_bid_ask","market_id":"3790415","outcome_index":0,"market_type":"set2","local_side":"home","local_uid":"2026-08-23_pierre_hugues_herbert_quinn_vandecasteele","bid":0.59,"ask":0.76,"mid":0.675,"spread":0.17,"bid_size":null,"ask_size":null}
{"ts":"2026-08-23T17:53:36.904Z","event_type":"best_bid_ask","market_id":"3790415","outcome_index":1,"market_type":"set2","local_side":"away","local_uid":"2026-08-23_pierre_hugues_herbert_quinn_vandecasteele","bid":0.24,"ask":0.41,"mid":0.325,"spread":0.17,"bid_size":null,"ask_size":null}
{"ts":"2026-08-23T17:53:36.904Z","event_type":"price_change","market_id":"3790415","outcome_index":1,"market_type":"set2","local_side":"away","local_uid":"2026-08-23_pierre_hugues_herbert_quinn_vandecasteele","bid":0.24,"ask":0.41,"mid":0.325,"spread":0.17,"price":0.27,"size":0.0,"side":"BUY"}
{"ts":"2026-08-23T17:53:36.904Z","event_type":"price_change","market_id":"3790415","outcome_index":0,"market_type":"set2","local_side":"home","local_uid":"2026-08-23_pierre_hugues_herbert_quinn_vandecasteele","bid":0.59,"ask":0.76,"mid":0.675,"spread":0.17,"price":0.73,"size":0.0,"side":"SELL"}
{"ts":"2026-08-23T17:53:36.924Z","event_type":"best_bid_ask","market_id":"3790415","outcome_index":0,"market_type":"set2","local_side":"home","local_uid":"2026-08-23_pierre_hugues_herbert_quinn_vandecasteele","bid":0.59,"ask":0.74,"mid":0.665,"spread":0.15,"bid_size":null,"ask_size":null}
{"ts":"2026-08-23T17:53:36.927Z","event_type":"best_bid_ask","market_id":"3790415","outcome_index":1,"market_type":"set2","local_side":"away","local_uid":"2026-08-23_pierre_hugues_herbert_quinn_vandecasteele","bid":0.26,"ask":0.41,"mid":0.335,"spread":0.15,"bid_size":null,"ask_size":null}
{"ts":"2026-08-23T17:53:36.927Z","event_type":"price_change","market_id":"3790415","outcome_index":1,"market_type":"set2","local_side":"away","local_uid":"2026-08-23_pierre_hugues_herbert_quinn_vandecasteele","bid":0.26,"ask":0.41,"mid":0.335,"spread":0.15,"price":0.26,"size":49.2,"side":"BUY"}
{"ts":"2026-08-23T17:53:36.927Z","event_type":"price_change","market_id":"3790415","outcome_index":0,"market_type":"set2","local_side":"home","local_uid":"2026-08-23_pierre_hugues_herbert_quinn_vandecasteele","bid":0.59,"ask":0.74,"mid":0.665,"spread":0.15,"price":0.74,"size":49.2,"side":"SELL"}
{"ts":"2026-08-23T17:53:36.942Z","event_type":"best_bid_ask","market_id":"3789997","outcome_index":0,"market_type":"match","local_side":"home","local_uid":"2026-08-23_oscar_weightman_alec_deckers","bid":0.03,"ask":0.05,"mid":0.04,"spread":0.02,"bid_size":null,"ask_size":null}
{"ts":"2026-08-23T17:53:36.942Z","event_type":"best_bid_ask","market_id":"3789997","outcome_index":1,"market_type":"match","local_side":"away","local_uid":"2026-08-23_oscar_weightman_alec_deckers","bid":0.95,"ask":0.97,"mid":0.96,"spread":0.02,"bid_size":null,"ask_size":null}
{"ts":"2026-08-23T17:53:36.942Z","event_type":"price_change","market_id":"3789997","outcome_index":0,"market_type":"match","local_side":"home","local_uid":"2026-08-23_oscar_weightman_alec_deckers","bid":0.03,"ask":0.05,"mid":0.04,"spread":0.02,"price":0.05,"size":10.0,"side":"SELL"}
{"ts":"2026-08-23T17:53:36.942Z","event_type":"price_change","market_id":"3789997","outcome_index":1,"market_type":"match","local_side":"away","local_uid":"2026-08-23_oscar_weightman_alec_deckers","bid":0.95,"ask":0.97,"mid":0.96,"spread":0.02,"price":0.95,"size":10.0,"side":"BUY"}
{"ts":"2026-08-23T17:53:36.951Z","event_type":"best_bid_ask","market_id":"3790415","outcome_index":0,"market_type":"set2","local_side":"home","local_uid":"2026-08-23_pierre_hugues_herbert_quinn_vandecasteele","bid":0.58,"ask":0.74,"mid":0.66,"spread":0.16,"bid_size":null,"ask_size":null}
{"ts":"2026-08-23T17:53:36.951Z","event_type":"best_bid_ask","market_id":"3790415","outcome_index":1,"market_type":"set2","local_side":"away","local_uid":"2026-08-23_pierre_hugues_herbert_quinn_vandecasteele","bid":0.26,"ask":0.42,"mid":0.34,"spread":0.16,"bid_size":null,"ask_size":null}
{"ts":"2026-08-23T17:53:36.951Z","event_type":"price_change","market_id":"3790415","outcome_index":0,"market_type":"set2","local_side":"home","local_uid":"2026-08-23_pierre_hugues_herbert_quinn_vandecasteele","bid":0.58,"ask":0.74,"mid":0.66,"spread":0.16,"price":0.59,"size":0.0,"side":"BUY"}
{"ts":"2026-08-23T17:53:36.951Z","event_type":"price_change","market_id":"3790415","outcome_index":1,"market_type":"set2","local_side":"away","local_uid":"2026-08-23_pierre_hugues_herbert_quinn_vandecasteele","bid":0.26,"ask":0.42,"mid":0.34,"spread":0.16,"price":0.41,"size":0.0,"side":"SELL"}
{"ts":"2026-08-23T17:53:36.994Z","event_type":"price_change","market_id":"3789271","outcome_index":0,"market_type":"match","local_side":"home","local_uid":"2026-08-23_panna_udvardy_darja_vidmanova","bid":0.33,"ask":0.34,"mid":0.335,"spread":0.01,"price":0.31,"size":25723.86,"side":"BUY"}
{"ts":"2026-08-23T17:53:36.994Z","event_type":"price_change","market_id":"3789271","outcome_index":1,"market_type":"match","local_side":"away","local_uid":"2026-08-23_panna_udvardy_darja_vidmanova","bid":0.66,"ask":0.67,"mid":0.665,"spread":0.01,"price":0.69,"size":25723.86,"side":"SELL"}
{"ts":"2026-08-23T17:53:36.995Z","event_type":"best_bid_ask","market_id":"3790397","outcome_index":0,"market_type":"set2","local_side":"home","local_uid":"2026-08-23_hugo_grenier_mees_rottgering","bid":0.31,"ask":0.41,"mid":0.36,"spread":0.1,"bid_size":null,"ask_size":null}
{"ts":"2026-08-23T17:53:36.995Z","event_type":"best_bid_ask","market_id":"3790397","outcome_index":1,"market_type":"set2","local_side":"away","local_uid":"2026-08-23_hugo_grenier_mees_rottgering","bid":0.59,"ask":0.69,"mid":0.64,"spread":0.1,"bid_size":null,"ask_size":null}
{"ts":"2026-08-23T17:53:36.995Z","event_type":"price_change","market_id":"3790397","outcome_index":0,"market_type":"set2","local_side":"home","local_uid":"2026-08-23_hugo_grenier_mees_rottgering","bid":0.31,"ask":0.41,"mid":0.36,"spread":0.1,"price":0.32,"size":0.0,"side":"BUY"}
{"ts":"2026-08-23T17:53:36.995Z","event_type":"price_change","market_id":"3790397","outcome_index":1,"market_type":"set2","local_side":"away","local_uid":"2026-08-23_hugo_grenier_mees_rottgering","bid":0.59,"ask":0.69,"mid":0.64,"spread":0.1,"price":0.68,"size":0.0,"side":"SELL"}
{"ts":"2026-08-23T17:53:37.011Z","event_type":"best_bid_ask","market_id":"3790415","outcome_index":0,"market_type":"set2","local_side":"home","local_uid":"2026-08-23_pierre_hugues_herbert_quinn_vandecasteele","bid":0.57,"ask":0.74,"mid":0.655,"spread":0.17,"bid_size":null,"ask_size":null}
{"ts":"2026-08-23T17:53:37.011Z","event_type":"best_bid_ask","market_id":"3790415","outcome_index":1,"market_type":"set2","local_side":"away","local_uid":"2026-08-23_pierre_hugues_herbert_quinn_vandecasteele","bid":0.26,"ask":0.43,"mid":0.345,"spread":0.17,"bid_size":null,"ask_size":null}
{"ts":"2026-08-23T17:53:37.011Z","event_type":"price_change","market_id":"3790415","outcome_index":0,"market_type":"set2","local_side":"home","local_uid":"2026-08-23_pierre_hugues_herbert_quinn_vandecasteele","bid":0.57,"ask":0.74,"mid":0.655,"spread":0.17,"price":0.58,"size":0.0,"side":"BUY"}
{"ts":"2026-08-23T17:53:37.011Z","event_type":"price_change","market_id":"3790415","outcome_index":1,"market_type":"set2","local_side":"away","local_uid":"2026-08-23_pierre_hugues_herbert_quinn_vandecasteele","bid":0.26,"ask":0.43,"mid":0.345,"spread":0.17,"price":0.42,"size":0.0,"side":"SELL"}
{"ts":"2026-08-23T17:53:37.020Z","event_type":"best_bid_ask","market_id":"3789925","outcome_index":0,"market_type":"match","local_side":"home","local_uid":"2026-08-23_pierre_hugues_herbert_quinn_vandecasteele","bid":0.81,"ask":0.83,"mid":0.82,"spread":0.02,"bid_size":null,"ask_size":null}
{"ts":"2026-08-23T17:53:37.020Z","event_type":"best_bid_ask","market_id":"3789925","outcome_index":1,"market_type":"match","local_side":"away","local_uid":"2026-08-23_pierre_hugues_herbert_quinn_vandecasteele","bid":0.17,"ask":0.19,"mid":0.18,"spread":0.02,"bid_size":null,"ask_size":null}
{"ts":"2026-08-23T17:53:37.020Z","event_type":"price_change","market_id":"3789925","outcome_index":0,"market_type":"match","local_side":"home","local_uid":"2026-08-23_pierre_hugues_herbert_quinn_vandecasteele","bid":0.81,"ask":0.83,"mid":0.82,"spread":0.02,"price":0.82,"size":0.0,"side":"BUY"}
{"ts":"2026-08-23T17:53:37.020Z","event_type":"price_change","market_id":"3789925","outcome_index":1,"market_type":"match","local_side":"away","local_uid":"2026-08-23_pierre_hugues_herbert_quinn_vandecasteele","bid":0.17,"ask":0.19,"mid":0.18,"spread":0.02,"price":0.18,"size":0.0,"side":"SELL"}
{"ts":"2026-08-23T17:53:37.029Z","event_type":"best_bid_ask","market_id":"3790397","outcome_index":0,"market_type":"set2","local_side":"home","local_uid":"2026-08-23_hugo_grenier_mees_rottgering","bid":0.32,"ask":0.41,"mid":0.365,"spread":0.09,"bid_size":null,"ask_size":null}
{"ts":"2026-08-23T17:53:37.029Z","event_type":"best_bid_ask","market_id":"3790397","outcome_index":1,"market_type":"set2","local_side":"away","local_uid":"2026-08-23_hugo_grenier_mees_rottgering","bid":0.59,"ask":0.68,"mid":0.635,"spread":0.09,"bid_size":null,"ask_size":null}
{"ts":"2026-08-23T17:53:37.032Z","event_type":"price_change","market_id":"3790397","outcome_index":0,"market_type":"set2","local_side":"home","local_uid":"2026-08-23_hugo_grenier_mees_rottgering","bid":0.32,"ask":0.41,"mid":0.365,"spread":0.09,"price":0.32,"size":98.89,"side":"BUY"}
{"ts":"2026-08-23T17:53:37.032Z","event_type":"price_change","market_id":"3790397","outcome_index":1,"market_type":"set2","local_side":"away","local_uid":"2026-08-23_hugo_grenier_mees_rottgering","bid":0.59,"ask":0.68,"mid":0.635,"spread":0.09,"price":0.68,"size":98.89,"side":"SELL"}
{"ts":"2026-08-23T17:53:37.139Z","event_type":"best_bid_ask","market_id":"3790415","outcome_index":0,"market_type":"set2","local_side":"home","local_uid":"2026-08-23_pierre_hugues_herbert_quinn_vandecasteele","bid":0.57,"ask":0.75,"mid":0.66,"spread":0.18,"bid_size":null,"ask_size":null}
{"ts":"2026-08-23T17:53:37.144Z","event_type":"best_bid_ask","market_id":"3790415","outcome_index":1,"market_type":"set2","local_side":"away","local_uid":"2026-08-23_pierre_hugues_herbert_quinn_vandecasteele","bid":0.25,"ask":0.43,"mid":0.34,"spread":0.18,"bid_size":null,"ask_size":null}
{"ts":"2026-08-23T17:53:37.144Z","event_type":"price_change","market_id":"3790415","outcome_index":1,"market_type":"set2","local_side":"away","local_uid":"2026-08-23_pierre_hugues_herbert_quinn_vandecasteele","bid":0.25,"ask":0.43,"mid":0.34,"spread":0.18,"price":0.26,"size":0.0,"side":"BUY"}
{"ts":"2026-08-23T17:53:37.144Z","event_type":"price_change","market_id":"3790415","outcome_index":0,"market_type":"set2","local_side":"home","local_uid":"2026-08-23_pierre_hugues_herbert_quinn_vandecasteele","bid":0.57,"ask":0.75,"mid":0.66,"spread":0.18,"price":0.74,"size":0.0,"side":"SELL"}
{"ts":"2026-08-23T17:53:37.186Z","event_type":"best_bid_ask","market_id":"3790415","outcome_index":0,"market_type":"set2","local_side":"home","local_uid":"2026-08-23_pierre_hugues_herbert_quinn_vandecasteele","bid":0.57,"ask":0.76,"mid":0.665,"spread":0.19,"bid_size":null,"ask_size":null}
{"ts":"2026-08-23T17:53:37.186Z","event_type":"best_bid_ask","market_id":"3790415","outcome_index":1,"market_type":"set2","local_side":"away","local_uid":"2026-08-23_pierre_hugues_herbert_quinn_vandecasteele","bid":0.24,"ask":0.43,"mid":0.335,"spread":0.19,"bid_size":null,"ask_size":null}
{"ts":"2026-08-23T17:53:37.186Z","event_type":"price_change","market_id":"3790415","outcome_index":1,"market_type":"set2","local_side":"away","local_uid":"2026-08-23_pierre_hugues_herbert_quinn_vandecasteele","bid":0.24,"ask":0.43,"mid":0.335,"spread":0.19,"price":0.25,"size":0.0,"side":"BUY"}
{"ts":"2026-08-23T17:53:37.186Z","event_type":"price_change","market_id":"3790415","outcome_index":0,"market_type":"set2","local_side":"home","local_uid":"2026-08-23_pierre_hugues_herbert_quinn_vandecasteele","bid":0.57,"ask":0.76,"mid":0.665,"spread":0.19,"price":0.75,"size":0.0,"side":"SELL"}
{"ts":"2026-08-23T17:53:37.186Z","event_type":"best_bid_ask","market_id":"3790415","outcome_index":0,"market_type":"set2","local_side":"home","local_uid":"2026-08-23_pierre_hugues_herbert_quinn_vandecasteele","bid":0.0,"ask":0.76,"mid":0.38,"spread":0.76,"bid_size":null,"ask_size":null}
{"ts":"2026-08-23T17:53:37.207Z","event_type":"best_bid_ask","market_id":"3790415","outcome_index":1,"market_type":"set2","local_side":"away","local_uid":"2026-08-23_pierre_hugues_herbert_quinn_vandecasteele","bid":0.24,"ask":1.0,"mid":0.62,"spread":0.76,"bid_size":null,"ask_size":null}
{"ts":"2026-08-23T17:53:37.207Z","event_type":"price_change","market_id":"3790415","outcome_index":0,"market_type":"set2","local_side":"home","local_uid":"2026-08-23_pierre_hugues_herbert_quinn_vandecasteele","bid":0.0,"ask":0.76,"mid":0.38,"spread":0.76,"price":0.57,"size":0.0,"side":"BUY"}
{"ts":"2026-08-23T17:53:37.207Z","event_type":"price_change","market_id":"3790415","outcome_index":1,"market_type":"set2","local_side":"away","local_uid":"2026-08-23_pierre_hugues_herbert_quinn_vandecasteele","bid":0.24,"ask":1.0,"mid":0.62,"spread":0.76,"price":0.43,"size":0.0,"side":"SELL"}
{"ts":"2026-08-23T17:53:37.207Z","event_type":"best_bid_ask","market_id":"3790415","outcome_index":0,"market_type":"set2","local_side":"home","local_uid":"2026-08-23_pierre_hugues_herbert_quinn_vandecasteele","bid":0.55,"ask":0.76,"mid":0.655,"spread":0.21,"bid_size":null,"ask_size":null}
{"ts":"2026-08-23T17:53:37.208Z","event_type":"best_bid_ask","market_id":"3790415","outcome_index":1,"market_type":"set2","local_side":"away","local_uid":"2026-08-23_pierre_hugues_herbert_quinn_vandecasteele","bid":0.24,"ask":0.45,"mid":0.345,"spread":0.21,"bid_size":null,"ask_size":null}
{"ts":"2026-08-23T17:53:37.216Z","event_type":"price_change","market_id":"3790415","outcome_index":0,"market_type":"set2","local_side":"home","local_uid":"2026-08-23_pierre_hugues_herbert_quinn_vandecasteele","bid":0.55,"ask":0.76,"mid":0.655,"spread":0.21,"price":0.55,"size":423.0,"side":"BUY"}
{"ts":"2026-08-23T17:53:37.216Z","event_type":"price_change","market_id":"3790415","outcome_index":1,"market_type":"set2","local_side":"away","local_uid":"2026-08-23_pierre_hugues_herbert_quinn_vandecasteele","bid":0.24,"ask":0.45,"mid":0.345,"spread":0.21,"price":0.45,"size":423.0,"side":"SELL"}
{"ts":"2026-08-23T17:53:37.216Z","event_type":"best_bid_ask","market_id":"3790394","outcome_index":0,"market_type":"set1","local_side":"home","local_uid":"2026-08-23_hugo_grenier_mees_rottgering","bid":0.32,"ask":0.41,"mid":0.365,"spread":0.09,"bid_size":null,"ask_size":null}
{"ts":"2026-08-23T17:53:37.216Z","event_type":"best_bid_ask","market_id":"3790394","outcome_index":1,"market_type":"set1","local_side":"away","local_uid":"2026-08-23_hugo_grenier_mees_rottgering","bid":0.59,"ask":0.68,"mid":0.635,"spread":0.09,"bid_size":null,"ask_size":null}
{"ts":"2026-08-23T17:53:37.216Z","event_type":"price_change","market_id":"3790394","outcome_index":0,"market_type":"set1","local_side":"home","local_uid":"2026-08-23_hugo_grenier_mees_rottgering","bid":0.32,"ask":0.41,"mid":0.365,"spread":0.09,"price":0.32,"size":150.0,"side":"BUY"}
{"ts":"2026-08-23T17:53:37.216Z","event_type":"price_change","market_id":"3790394","outcome_index":1,"market_type":"set1","local_side":"away","local_uid":"2026-08-23_hugo_grenier_mees_rottgering","bid":0.59,"ask":0.68,"mid":0.635,"spread":0.09,"price":0.68,"size":150.0,"side":"SELL"}
{"ts":"2026-08-23T17:53:37.229Z","event_type":"best_bid_ask","market_id":"3790415","outcome_index":0,"market_type":"set2","local_side":"home","local_uid":"2026-08-23_pierre_hugues_herbert_quinn_vandecasteele","bid":0.56,"ask":0.76,"mid":0.66,"spread":0.2,"bid_size":null,"ask_size":null}
{"ts":"2026-08-23T17:53:37.229Z","event_type":"best_bid_ask","market_id":"3790415","outcome_index":1,"market_type":"set2","local_side":"away","local_uid":"2026-08-23_pierre_hugues_herbert_quinn_vandecasteele","bid":0.24,"ask":0.44,"mid":0.34,"spread":0.2,"bid_size":null,"ask_size":null}
{"ts":"2026-08-23T17:53:37.229Z","event_type":"price_change","market_id":"3790415","outcome_index":0,"market_type":"set2","local_side":"home","local_uid":"2026-08-23_pierre_hugues_herbert_quinn_vandecasteele","bid":0.56,"ask":0.76,"mid":0.66,"spread":0.2,"price":0.56,"size":88.0,"side":"BUY"}
{"ts":"2026-08-23T17:53:37.230Z","event_type":"price_change","market_id":"3790415","outcome_index":1,"market_type":"set2","local_side":"away","local_uid":"2026-08-23_pierre_hugues_herbert_quinn_vandecasteele","bid":0.24,"ask":0.44,"mid":0.34,"spread":0.2,"price":0.44,"size":88.0,"side":"SELL"}
{"ts":"2026-08-23T17:53:37.264Z","event_type":"best_bid_ask","market_id":"3790415","outcome_index":0,"market_type":"set2","local_side":"home","local_uid":"2026-08-23_pierre_hugues_herbert_quinn_vandecasteele","bid":0.57,"ask":0.76,"mid":0.665,"spread":0.19,"bid_size":null,"ask_size":null}
{"ts":"2026-08-23T17:53:37.264Z","event_type":"best_bid_ask","market_id":"3790415","outcome_index":1,"market_type":"set2","local_side":"away","local_uid":"2026-08-23_pierre_hugues_herbert_quinn_vandecasteele","bid":0.24,"ask":0.43,"mid":0.335,"spread":0.19,"bid_size":null,"ask_size":null}
{"ts":"2026-08-23T17:53:37.270Z","event_type":"price_change","market_id":"3790415","outcome_index":0,"market_type":"set2","local_side":"home","local_uid":"2026-08-23_pierre_hugues_herbert_quinn_vandecasteele","bid":0.57,"ask":0.76,"mid":0.665,"spread":0.19,"price":0.57,"size":150.0,"side":"BUY"}
{"ts":"2026-08-23T17:53:37.270Z","event_type":"price_change","market_id":"3790415","outcome_index":1,"market_type":"set2","local_side":"away","local_uid":"2026-08-23_pierre_hugues_herbert_quinn_vandecasteele","bid":0.24,"ask":0.43,"mid":0.335,"spread":0.19,"price":0.43,"size":150.0,"side":"SELL"}
{"ts":"2026-08-23T17:53:37.289Z","event_type":"best_bid_ask","market_id":"3790415","outcome_index":0,"market_type":"set2","local_side":"home","local_uid":"2026-08-23_pierre_hugues_herbert_quinn_vandecasteele","bid":0.57,"ask":0.74,"mid":0.655,"spread":0.17,"bid_size":null,"ask_size":null}
{"ts":"2026-08-23T17:53:37.289Z","event_type":"best_bid_ask","market_id":"3790415","outcome_index":1,"market_type":"set2","local_side":"away","local_uid":"2026-08-23_pierre_hugues_herbert_quinn_vandecasteele","bid":0.26,"ask":0.43,"mid":0.345,"spread":0.17,"bid_size":null,"ask_size":null}
{"ts":"2026-08-23T17:53:37.289Z","event_type":"price_change","market_id":"3790415","outcome_index":1,"market_type":"set2","local_side":"away","local_uid":"2026-08-23_pierre_hugues_herbert_quinn_vandecasteele","bid":0.26,"ask":0.43,"mid":0.345,"spread":0.17,"price":0.26,"size":33.95,"side":"BUY"}
{"ts":"2026-08-23T17:53:37.289Z","event_type":"price_change","market_id":"3790415","outcome_index":0,"market_type":"set2","local_side":"home","local_uid":"2026-08-23_pierre_hugues_herbert_quinn_vandecasteele","bid":0.57,"ask":0.74,"mid":0.655,"spread":0.17,"price":0.74,"size":33.95,"side":"SELL"}
{"ts":"2026-08-23T17:53:37.292Z","event_type":"best_bid_ask","market_id":"3790397","outcome_index":0,"market_type":"set2","local_side":"home","local_uid":"2026-08-23_hugo_grenier_mees_rottgering","bid":0.31,"ask":0.41,"mid":0.36,"spread":0.1,"bid_size":null,"ask_size":null}
{"ts":"2026-08-23T17:53:37.292Z","event_type":"best_bid_ask","market_id":"3790397","outcome_index":1,"market_type":"set2","local_side":"away","local_uid":"2026-08-23_hugo_grenier_mees_rottgering","bid":0.59,"ask":0.69,"mid":0.64,"spread":0.1,"bid_size":null,"ask_size":null}
{"ts":"2026-08-23T17:53:37.292Z","event_type":"price_change","market_id":"3790397","outcome_index":0,"market_type":"set2","local_side":"home","local_uid":"2026-08-23_hugo_grenier_mees_rottgering","bid":0.31,"ask":0.41,"mid":0.36,"spread":0.1,"price":0.32,"size":0.0,"side":"BUY"}
{"ts":"2026-08-23T17:53:37.292Z","event_type":"price_change","market_id":"3790397","outcome_index":1,"market_type":"set2","local_side":"away","local_uid":"2026-08-23_hugo_grenier_mees_rottgering","bid":0.59,"ask":0.69,"mid":0.64,"spread":0.1,"price":0.68,"size":0.0,"side":"SELL"}
{"ts":"2026-08-23T17:53:37.315Z","event_type":"best_bid_ask","market_id":"3790394","outcome_index":0,"market_type":"set1","local_side":"home","local_uid":"2026-08-23_hugo_grenier_mees_rottgering","bid":0.31,"ask":0.41,"mid":0.36,"spread":0.1,"bid_size":null,"ask_size":null}
{"ts":"2026-08-23T17:53:37.315Z","event_type":"best_bid_ask","market_id":"3790394","outcome_index":1,"market_type":"set1","local_side":"away","local_uid":"2026-08-23_hugo_grenier_mees_rottgering","bid":0.59,"ask":0.69,"mid":0.64,"spread":0.1,"bid_size":null,"ask_size":null}
{"ts":"2026-08-23T17:53:37.321Z","event_type":"price_change","market_id":"3790394","outcome_index":0,"market_type":"set1","local_side":"home","local_uid":"2026-08-23_hugo_grenier_mees_rottgering","bid":0.31,"ask":0.41,"mid":0.36,"spread":0.1,"price":0.32,"size":0.0,"side":"BUY"}
{"ts":"2026-08-23T17:53:37.321Z","event_type":"price_change","market_id":"3790394","outcome_index":1,"market_type":"set1","local_side":"away","local_uid":"2026-08-23_hugo_grenier_mees_rottgering","bid":0.59,"ask":0.69,"mid":0.64,"spread":0.1,"price":0.68,"size":0.0,"side":"SELL"}
{"ts":"2026-08-23T17:53:37.321Z","event_type":"best_bid_ask","market_id":"3790397","outcome_index":0,"market_type":"set2","local_side":"home","local_uid":"2026-08-23_hugo_grenier_mees_rottgering","bid":0.29,"ask":0.41,"mid":0.35,"spread":0.12,"bid_size":null,"ask_size":null}
{"ts":"2026-08-23T17:53:37.321Z","event_type":"best_bid_ask","market_id":"3790397","outcome_index":1,"market_type":"set2","local_side":"away","local_uid":"2026-08-23_hugo_grenier_mees_rottgering","bid":0.59,"ask":0.71,"mid":0.65,"spread":0.12,"bid_size":null,"ask_size":null}
{"ts":"2026-08-23T17:53:37.322Z","event_type":"price_change","market_id":"3790397","outcome_index":0,"market_type":"set2","local_side":"home","local_uid":"2026-08-23_hugo_grenier_mees_rottgering","bid":0.29,"ask":0.41,"mid":0.35,"spread":0.12,"price":0.31,"size":0.0,"side":"BUY"}
{"ts":"2026-08-23T17:53:37.322Z","event_type":"price_change","market_id":"3790397","outcome_index":1,"market_type":"set2","local_side":"away","local_uid":"2026-08-23_hugo_grenier_mees_rottgering","bid":0.59,"ask":0.71,"mid":0.65,"spread":0.12,"price":0.69,"size":0.0,"side":"SELL"}
{"ts":"2026-08-23T17:53:37.322Z","event_type":"best_bid_ask","market_id":"3790397","outcome_index":0,"market_type":"set2","local_side":"home","local_uid":"2026-08-23_hugo_grenier_mees_rottgering","bid":0.29,"ask":0.43,"mid":0.36,"spread":0.14,"bid_size":null,"ask_size":null}
{"ts":"2026-08-23T17:53:37.322Z","event_type":"best_bid_ask","market_id":"3790397","outcome_index":1,"market_type":"set2","local_side":"away","local_uid":"2026-08-23_hugo_grenier_mees_rottgering","bid":0.57,"ask":0.71,"mid":0.64,"spread":0.14,"bid_size":null,"ask_size":null}
{"ts":"2026-08-23T17:53:37.322Z","event_type":"price_change","market_id":"3790397","outcome_index":1,"market_type":"set2","local_side":"away","local_uid":"2026-08-23_hugo_grenier_mees_rottgering","bid":0.57,"ask":0.71,"mid":0.64,"spread":0.14,"price":0.59,"size":0.0,"side":"BUY"}
{"ts":"2026-08-23T17:53:37.322Z","event_type":"price_change","market_id":"3790397","outcome_index":0,"market_type":"set2","local_side":"home","local_uid":"2026-08-23_hugo_grenier_mees_rottgering","bid":0.29,"ask":0.43,"mid":0.36,"spread":0.14,"price":0.41,"size":0.0,"side":"SELL"}
{"ts":"2026-08-23T17:53:37.349Z","event_type":"best_bid_ask","market_id":"3790397","outcome_index":0,"market_type":"set2","local_side":"home","local_uid":"2026-08-23_hugo_grenier_mees_rottgering","bid":0.29,"ask":0.44,"mid":0.365,"spread":0.15,"bid_size":null,"ask_size":null}
{"ts":"2026-08-23T17:53:37.350Z","event_type":"best_bid_ask","market_id":"3790397","outcome_index":1,"market_type":"set2","local_side":"away","local_uid":"2026-08-23_hugo_grenier_mees_rottgering","bid":0.56,"ask":0.71,"mid":0.635,"spread":0.15,"bid_size":null,"ask_size":null}
{"ts":"2026-08-23T17:53:37.353Z","event_type":"price_change","market_id":"3790397","outcome_index":1,"market_type":"set2","local_side":"away","local_uid":"2026-08-23_hugo_grenier_mees_rottgering","bid":0.56,"ask":0.71,"mid":0.635,"spread":0.15,"price":0.57,"size":0.0,"side":"BUY"}
{"ts":"2026-08-23T17:53:37.353Z","event_type":"price_change","market_id":"3790397","outcome_index":0,"market_type":"set2","local_side":"home","local_uid":"2026-08-23_hugo_grenier_mees_rottgering","bid":0.29,"ask":0.44,"mid":0.365,"spread":0.15,"price":0.43,"size":0.0,"side":"SELL"}
{"ts":"2026-08-23T17:53:37.362Z","event_type":"best_bid_ask","market_id":"3790415","outcome_index":0,"market_type":"set2","local_side":"home","local_uid":"2026-08-23_pierre_hugues_herbert_quinn_vandecasteele","bid":0.57,"ask":0.75,"mid":0.66,"spread":0.18,"bid_size":null,"ask_size":null}
{"ts":"2026-08-23T17:53:37.362Z","event_type":"best_bid_ask","market_id":"3790415","outcome_index":1,"market_type":"set2","local_side":"away","local_uid":"2026-08-23_pierre_hugues_herbert_quinn_vandecasteele","bid":0.25,"ask":0.43,"mid":0.34,"spread":0.18,"bid_size":null,"ask_size":null}
{"ts":"2026-08-23T17:53:37.362Z","event_type":"price_change","market_id":"3790415","outcome_index":1,"market_type":"set2","local_side":"away","local_uid":"2026-08-23_pierre_hugues_herbert_quinn_vandecasteele","bid":0.25,"ask":0.43,"mid":0.34,"spread":0.18,"price":0.26,"size":0.0,"side":"BUY"}
{"ts":"2026-08-23T17:53:37.362Z","event_type":"price_change","market_id":"3790415","outcome_index":0,"market_type":"set2","local_side":"home","local_uid":"2026-08-23_pierre_hugues_herbert_quinn_vandecasteele","bid":0.57,"ask":0.75,"mid":0.66,"spread":0.18,"price":0.74,"size":0.0,"side":"SELL"}
{"ts":"2026-08-23T17:53:37.395Z","event_type":"best_bid_ask","market_id":"3790397","outcome_index":0,"market_type":"set2","local_side":"home","local_uid":"2026-08-23_hugo_grenier_mees_rottgering","bid":0.31,"ask":0.44,"mid":0.375,"spread":0.13,"bid_size":null,"ask_size":null}
{"ts":"2026-08-23T17:53:37.395Z","event_type":"best_bid_ask","market_id":"3790397","outcome_index":1,"market_type":"set2","local_side":"away","local_uid":"2026-08-23_hugo_grenier_mees_rottgering","bid":0.56,"ask":0.69,"mid":0.625,"spread":0.13,"bid_size":null,"ask_size":null}
{"ts":"2026-08-23T17:53:37.395Z","event_type":"price_change","market_id":"3790397","outcome_index":0,"market_type":"set2","local_side":"home","local_uid":"2026-08-23_hugo_grenier_mees_rottgering","bid":0.31,"ask":0.44,"mid":0.375,"spread":0.13,"price":0.31,"size":30.01,"side":"BUY"}
{"ts":"2026-08-23T17:53:37.395Z","event_type":"price_change","market_id":"3790397","outcome_index":1,"market_type":"set2","local_side":"away","local_uid":"2026-08-23_hugo_grenier_mees_rottgering","bid":0.56,"ask":0.69,"mid":0.625,"spread":0.13,"price":0.69,"size":30.01,"side":"SELL"}
{"ts":"2026-08-23T17:53:37.429Z","event_type":"best_bid_ask","market_id":"3790394","outcome_index":0,"market_type":"set1","local_side":"home","local_uid":"2026-08-23_hugo_grenier_mees_rottgering","bid":0.31,"ask":0.47,"mid":0.39,"spread":0.16,"bid_size":null,"ask_size":null}
{"ts":"2026-08-23T17:53:37.429Z","event_type":"best_bid_ask","market_id":"3790394","outcome_index":1,"market_type":"set1","local_side":"away","local_uid":"2026-08-23_hugo_grenier_mees_rottgering","bid":0.53,"ask":0.69,"mid":0.61,"spread":0.16,"bid_size":null,"ask_size":null}
{"ts":"2026-08-23T17:53:37.430Z","event_type":"price_change","market_id":"3790394","outcome_index":1,"market_type":"set1","local_side":"away","local_uid":"2026-08-23_hugo_grenier_mees_rottgering","bid":0.53,"ask":0.69,"mid":0.61,"spread":0.16,"price":0.59,"size":0.0,"side":"BUY"}
{"ts":"2026-08-23T17:53:37.430Z","event_type":"price_change","market_id":"3790394","outcome_index":0,"market_type":"set1","local_side":"home","local_uid":"2026-08-23_hugo_grenier_mees_rottgering","bid":0.31,"ask":0.47,"mid":0.39,"spread":0.16,"price":0.41,"size":0.0,"side":"SELL"}
{"ts":"2026-08-23T17:53:37.475Z","event_type":"best_bid_ask","market_id":"3790394","outcome_index":0,"market_type":"set1","local_side":"home","local_uid":"2026-08-23_hugo_grenier_mees_rottgering","bid":0.31,"ask":0.46,"mid":0.385,"spread":0.15,"bid_size":null,"ask_size":null}
{"ts":"2026-08-23T17:53:37.475Z","event_type":"best_bid_ask","market_id":"3790394","outcome_index":1,"market_type":"set1","local_side":"away","local_uid":"2026-08-23_hugo_grenier_mees_rottgering","bid":0.54,"ask":0.69,"mid":0.615,"spread":0.15,"bid_size":null,"ask_size":null}
{"ts":"2026-08-23T17:53:37.475Z","event_type":"price_change","market_id":"3790394","outcome_index":1,"market_type":"set1","local_side":"away","local_uid":"2026-08-23_hugo_grenier_mees_rottgering","bid":0.54,"ask":0.69,"mid":0.615,"spread":0.15,"price":0.54,"size":18.52,"side":"BUY"}
{"ts":"2026-08-23T17:53:37.475Z","event_type":"price_change","market_id":"3790394","outcome_index":0,"market_type":"set1","local_side":"home","local_uid":"2026-08-23_hugo_grenier_mees_rottgering","bid":0.31,"ask":0.46,"mid":0.385,"spread":0.15,"price":0.46,"size":18.52,"side":"SELL"}
{"ts":"2026-08-23T17:53:37.490Z","event_type":"best_bid_ask","market_id":"3790394","outcome_index":0,"market_type":"set1","local_side":"home","local_uid":"2026-08-23_hugo_grenier_mees_rottgering","bid":0.31,"ask":0.41,"mid":0.36,"spread":0.1,"bid_size":null,"ask_size":null}
{"ts":"2026-08-23T17:53:37.490Z","event_type":"best_bid_ask","market_id":"3790394","outcome_index":1,"market_type":"set1","local_side":"away","local_uid":"2026-08-23_hugo_grenier_mees_rottgering","bid":0.59,"ask":0.69,"mid":0.64,"spread":0.1,"bid_size":null,"ask_size":null}
{"ts":"2026-08-23T17:53:37.491Z","event_type":"price_change","market_id":"3790394","outcome_index":1,"market_type":"set1","local_side":"away","local_uid":"2026-08-23_hugo_grenier_mees_rottgering","bid":0.59,"ask":0.69,"mid":0.64,"spread":0.1,"price":0.59,"size":11.0,"side":"BUY"}
{"ts":"2026-08-23T17:53:37.491Z","event_type":"price_change","market_id":"3790394","outcome_index":0,"market_type":"set1","local_side":"home","local_uid":"2026-08-23_hugo_grenier_mees_rottgering","bid":0.31,"ask":0.41,"mid":0.36,"spread":0.1,"price":0.41,"size":11.0,"side":"SELL"}
{"ts":"2026-08-23T17:53:37.565Z","event_type":"best_bid_ask","market_id":"3790394","outcome_index":0,"market_type":"set1","local_side":"home","local_uid":"2026-08-23_hugo_grenier_mees_rottgering","bid":0.3,"ask":0.41,"mid":0.355,"spread":0.11,"bid_size":null,"ask_size":null}
{"ts":"2026-08-23T17:53:37.565Z","event_type":"best_bid_ask","market_id":"3790394","outcome_index":1,"market_type":"set1","local_side":"away","local_uid":"2026-08-23_hugo_grenier_mees_rottgering","bid":0.59,"ask":0.7,"mid":0.645,"spread":0.11,"bid_size":null,"ask_size":null}
{"ts":"2026-08-23T17:53:37.565Z","event_type":"price_change","market_id":"3790394","outcome_index":0,"market_type":"set1","local_side":"home","local_uid":"2026-08-23_hugo_grenier_mees_rottgering","bid":0.3,"ask":0.41,"mid":0.355,"spread":0.11,"price":0.31,"size":0.0,"side":"BUY"}
{"ts":"2026-08-23T17:53:37.565Z","event_type":"price_change","market_id":"3790394","outcome_index":1,"market_type":"set1","local_side":"away","local_uid":"2026-08-23_hugo_grenier_mees_rottgering","bid":0.59,"ask":0.7,"mid":0.645,"spread":0.11,"price":0.69,"size":0.0,"side":"SELL"}
{"ts":"2026-08-23T17:53:37.584Z","event_type":"best_bid_ask","market_id":"3790394","outcome_index":0,"market_type":"set1","local_side":"home","local_uid":"2026-08-23_hugo_grenier_mees_rottgering","bid":0.3,"ask":0.46,"mid":0.38,"spread":0.16,"bid_size":null,"ask_size":null}
{"ts":"2026-08-23T17:53:37.584Z","event_type":"best_bid_ask","market_id":"3790394","outcome_index":1,"market_type":"set1","local_side":"away","local_uid":"2026-08-23_hugo_grenier_mees_rottgering","bid":0.54,"ask":0.7,"mid":0.62,"spread":0.16,"bid_size":null,"ask_size":null}
{"ts":"2026-08-23T17:53:37.584Z","event_type":"price_change","market_id":"3790394","outcome_index":1,"market_type":"set1","local_side":"away","local_uid":"2026-08-23_hugo_grenier_mees_rottgering","bid":0.54,"ask":0.7,"mid":0.62,"spread":0.16,"price":0.59,"size":0.0,"side":"BUY"}
{"ts":"2026-08-23T17:53:37.584Z","event_type":"price_change","market_id":"3790394","outcome_index":0,"market_type":"set1","local_side":"home","local_uid":"2026-08-23_hugo_grenier_mees_rottgering","bid":0.3,"ask":0.46,"mid":0.38,"spread":0.16,"price":0.41,"size":0.0,"side":"SELL"}
{"ts":"2026-08-23T17:53:37.642Z","event_type":"best_bid_ask","market_id":"3790394","outcome_index":0,"market_type":"set1","local_side":"home","local_uid":"2026-08-23_hugo_grenier_mees_rottgering","bid":0.3,"ask":0.47,"mid":0.385,"spread":0.17,"bid_size":null,"ask_size":null}
{"ts":"2026-08-23T17:53:37.642Z","event_type":"best_bid_ask","market_id":"3790394","outcome_index":1,"market_type":"set1","local_side":"away","local_uid":"2026-08-23_hugo_grenier_mees_rottgering","bid":0.53,"ask":0.7,"mid":0.615,"spread":0.17,"bid_size":null,"ask_size":null}
{"ts":"2026-08-23T17:53:37.642Z","event_type":"price_change","market_id":"3790394","outcome_index":1,"market_type":"set1","local_side":"away","local_uid":"2026-08-23_hugo_grenier_mees_rottgering","bid":0.53,"ask":0.7,"mid":0.615,"spread":0.17,"price":0.54,"size":0.0,"side":"BUY"}
{"ts":"2026-08-23T17:53:37.643Z","event_type":"price_change","market_id":"3790394","outcome_index":0,"market_type":"set1","local_side":"home","local_uid":"2026-08-23_hugo_grenier_mees_rottgering","bid":0.3,"ask":0.47,"mid":0.385,"spread":0.17,"price":0.46,"size":0.0,"side":"SELL"}
{"ts":"2026-08-23T17:53:37.671Z","event_type":"best_bid_ask","market_id":"3790394","outcome_index":0,"market_type":"set1","local_side":"home","local_uid":"2026-08-23_hugo_grenier_mees_rottgering","bid":0.3,"ask":0.46,"mid":0.38,"spread":0.16,"bid_size":null,"ask_size":null}
{"ts":"2026-08-23T17:53:37.672Z","event_type":"best_bid_ask","market_id":"3790394","outcome_index":1,"market_type":"set1","local_side":"away","local_uid":"2026-08-23_hugo_grenier_mees_rottgering","bid":0.54,"ask":0.7,"mid":0.62,"spread":0.16,"bid_size":null,"ask_size":null}
{"ts":"2026-08-23T17:53:37.672Z","event_type":"price_change","market_id":"3790394","outcome_index":1,"market_type":"set1","local_side":"away","local_uid":"2026-08-23_hugo_grenier_mees_rottgering","bid":0.54,"ask":0.7,"mid":0.62,"spread":0.16,"price":0.54,"size":11.0,"side":"BUY"}
{"ts":"2026-08-23T17:53:37.672Z","event_type":"price_change","market_id":"3790394","outcome_index":0,"market_type":"set1","local_side":"home","local_uid":"2026-08-23_hugo_grenier_mees_rottgering","bid":0.3,"ask":0.46,"mid":0.38,"spread":0.16,"price":0.46,"size":11.0,"side":"SELL"}
{"ts":"2026-08-23T17:53:37.825Z","event_type":"new_market","market_id":"0x9e1ddd66e4299dfd2a12144db8b947e5f8f8218808cd3fdad460555f33ad63d4"}
{"ts":"2026-08-23T17:53:37.886Z","event_type":"best_bid_ask","market_id":"3790394","outcome_index":0,"market_type":"set1","local_side":"home","local_uid":"2026-08-23_hugo_grenier_mees_rottgering","bid":0.25,"ask":0.46,"mid":0.355,"spread":0.21,"bid_size":null,"ask_size":null}
{"ts":"2026-08-23T17:53:37.886Z","event_type":"best_bid_ask","market_id":"3790394","outcome_index":1,"market_type":"set1","local_side":"away","local_uid":"2026-08-23_hugo_grenier_mees_rottgering","bid":0.54,"ask":0.75,"mid":0.645,"spread":0.21,"bid_size":null,"ask_size":null}
{"ts":"2026-08-23T17:53:37.886Z","event_type":"price_change","market_id":"3790394","outcome_index":0,"market_type":"set1","local_side":"home","local_uid":"2026-08-23_hugo_grenier_mees_rottgering","bid":0.25,"ask":0.46,"mid":0.355,"spread":0.21,"price":0.3,"size":0.0,"side":"BUY"}
{"ts":"2026-08-23T17:53:37.886Z","event_type":"price_change","market_id":"3790394","outcome_index":1,"market_type":"set1","local_side":"away","local_uid":"2026-08-23_hugo_grenier_mees_rottgering","bid":0.54,"ask":0.75,"mid":0.645,"spread":0.21,"price":0.7,"size":0.0,"side":"SELL"}
{"ts":"2026-08-23T17:53:38.087Z","event_type":"best_bid_ask","market_id":"3789997","outcome_index":0,"market_type":"match","local_side":"home","local_uid":"2026-08-23_oscar_weightman_alec_deckers","bid":0.04,"ask":0.05,"mid":0.045,"spread":0.01,"bid_size":null,"ask_size":null}
{"ts":"2026-08-23T17:53:38.092Z","event_type":"best_bid_ask","market_id":"3789997","outcome_index":1,"market_type":"match","local_side":"away","local_uid":"2026-08-23_oscar_weightman_alec_deckers","bid":0.95,"ask":0.96,"mid":0.955,"spread":0.01,"bid_size":null,"ask_size":null}
{"ts":"2026-08-23T17:53:38.092Z","event_type":"price_change","market_id":"3789997","outcome_index":0,"market_type":"match","local_side":"home","local_uid":"2026-08-23_oscar_weightman_alec_deckers","bid":0.04,"ask":0.05,"mid":0.045,"spread":0.01,"price":0.04,"size":100.0,"side":"BUY"}
{"ts":"2026-08-23T17:53:38.092Z","event_type":"price_change","market_id":"3789997","outcome_index":1,"market_type":"match","local_side":"away","local_uid":"2026-08-23_oscar_weightman_alec_deckers","bid":0.95,"ask":0.96,"mid":0.955,"spread":0.01,"price":0.96,"size":100.0,"side":"SELL"}
{"ts":"2026-08-23T17:53:38.092Z","event_type":"best_bid_ask","market_id":"3789997","outcome_index":0,"market_type":"match","local_side":"home","local_uid":"2026-08-23_oscar_weightman_alec_deckers","bid":0.04,"ask":0.06,"mid":0.05,"spread":0.02,"bid_size":null,"ask_size":null}
{"ts":"2026-08-23T17:53:38.092Z","event_type":"best_bid_ask","market_id":"3789997","outcome_index":1,"market_type":"match","local_side":"away","local_uid":"2026-08-23_oscar_weightman_alec_deckers","bid":0.94,"ask":0.96,"mid":0.95,"spread":0.02,"bid_size":null,"ask_size":null}
{"ts":"2026-08-23T17:53:38.096Z","event_type":"price_change","market_id":"3789997","outcome_index":0,"market_type":"match","local_side":"home","local_uid":"2026-08-23_oscar_weightman_alec_deckers","bid":0.04,"ask":0.06,"mid":0.05,"spread":0.02,"price":0.05,"size":0.0,"side":"SELL"}
{"ts":"2026-08-23T17:53:38.096Z","event_type":"price_change","market_id":"3789997","outcome_index":1,"market_type":"match","local_side":"away","local_uid":"2026-08-23_oscar_weightman_alec_deckers","bid":0.94,"ask":0.96,"mid":0.95,"spread":0.02,"price":0.95,"size":0.0,"side":"BUY"}
{"ts":"2026-08-23T17:53:38.140Z","event_type":"best_bid_ask","market_id":"3790394","outcome_index":0,"market_type":"set1","local_side":"home","local_uid":"2026-08-23_hugo_grenier_mees_rottgering","bid":0.24,"ask":0.46,"mid":0.35,"spread":0.22,"bid_size":null,"ask_size":null}
{"ts":"2026-08-23T17:53:38.140Z","event_type":"best_bid_ask","market_id":"3790394","outcome_index":1,"market_type":"set1","local_side":"away","local_uid":"2026-08-23_hugo_grenier_mees_rottgering","bid":0.54,"ask":0.76,"mid":0.65,"spread":0.22,"bid_size":null,"ask_size":null}
{"ts":"2026-08-23T17:53:38.148Z","event_type":"price_change","market_id":"3790394","outcome_index":0,"market_type":"set1","local_side":"home","local_uid":"2026-08-23_hugo_grenier_mees_rottgering","bid":0.24,"ask":0.46,"mid":0.35,"spread":0.22,"price":0.25,"size":0.0,"side":"BUY"}
{"ts":"2026-08-23T17:53:38.148Z","event_type":"price_change","market_id":"3790394","outcome_index":1,"market_type":"set1","local_side":"away","local_uid":"2026-08-23_hugo_grenier_mees_rottgering","bid":0.54,"ask":0.76,"mid":0.65,"spread":0.22,"price":0.75,"size":0.0,"side":"SELL"}
{"ts":"2026-08-23T17:53:38.164Z","event_type":"best_bid_ask","market_id":"3790323","outcome_index":0,"market_type":"set2","local_side":"home","local_uid":"2026-08-23_felix_balshaw_sebastian_gorzny","bid":0.54,"ask":0.7,"mid":0.62,"spread":0.16,"bid_size":null,"ask_size":null}
{"ts":"2026-08-23T17:53:38.164Z","event_type":"best_bid_ask","market_id":"3790323","outcome_index":1,"market_type":"set2","local_side":"away","local_uid":"2026-08-23_felix_balshaw_sebastian_gorzny","bid":0.3,"ask":0.46,"mid":0.38,"spread":0.16,"bid_size":null,"ask_size":null}
{"ts":"2026-08-23T17:53:38.174Z","event_type":"price_change","market_id":"3790323","outcome_index":1,"market_type":"set2","local_side":"away","local_uid":"2026-08-23_felix_balshaw_sebastian_gorzny","bid":0.3,"ask":0.46,"mid":0.38,"spread":0.16,"price":0.32,"size":0.0,"side":"BUY"}
{"ts":"2026-08-23T17:53:38.174Z","event_type":"price_change","market_id":"3790323","outcome_index":0,"market_type":"set2","local_side":"home","local_uid":"2026-08-23_felix_balshaw_sebastian_gorzny","bid":0.54,"ask":0.7,"mid":0.62,"spread":0.16,"price":0.68,"size":0.0,"side":"SELL"}
{"ts":"2026-08-23T17:53:38.181Z","event_type":"best_bid_ask","market_id":"3790323","outcome_index":0,"market_type":"set2","local_side":"home","local_uid":"2026-08-23_felix_balshaw_sebastian_gorzny","bid":0.0,"ask":0.7,"mid":0.35,"spread":0.7,"bid_size":null,"ask_size":null}
{"ts":"2026-08-23T17:53:38.181Z","event_type":"best_bid_ask","market_id":"3790323","outcome_index":1,"market_type":"set2","local_side":"away","local_uid":"2026-08-23_felix_balshaw_sebastian_gorzny","bid":0.3,"ask":1.0,"mid":0.65,"spread":0.7,"bid_size":null,"ask_size":null}
{"ts":"2026-08-23T17:53:38.181Z","event_type":"price_change","market_id":"3790323","outcome_index":0,"market_type":"set2","local_side":"home","local_uid":"2026-08-23_felix_balshaw_sebastian_gorzny","bid":0.0,"ask":0.7,"mid":0.35,"spread":0.7,"price":0.54,"size":0.0,"side":"BUY"}
{"ts":"2026-08-23T17:53:38.181Z","event_type":"price_change","market_id":"3790323","outcome_index":1,"market_type":"set2","local_side":"away","local_uid":"2026-08-23_felix_balshaw_sebastian_gorzny","bid":0.3,"ask":1.0,"mid":0.65,"spread":0.7,"price":0.46,"size":0.0,"side":"SELL"}
{"ts":"2026-08-23T17:53:38.188Z","event_type":"best_bid_ask","market_id":"3790323","outcome_index":0,"market_type":"set2","local_side":"home","local_uid":"2026-08-23_felix_balshaw_sebastian_gorzny","bid":0.48,"ask":0.7,"mid":0.59,"spread":0.22,"bid_size":null,"ask_size":null}
{"ts":"2026-08-23T17:53:38.188Z","event_type":"best_bid_ask","market_id":"3790323","outcome_index":1,"market_type":"set2","local_side":"away","local_uid":"2026-08-23_felix_balshaw_sebastian_gorzny","bid":0.3,"ask":0.52,"mid":0.41,"spread":0.22,"bid_size":null,"ask_size":null}
{"ts":"2026-08-23T17:53:38.188Z","event_type":"price_change","market_id":"3790323","outcome_index":0,"market_type":"set2","local_side":"home","local_uid":"2026-08-23_felix_balshaw_sebastian_gorzny","bid":0.48,"ask":0.7,"mid":0.59,"spread":0.22,"price":0.48,"size":423.0,"side":"BUY"}
{"ts":"2026-08-23T17:53:38.188Z","event_type":"price_change","market_id":"3790323","outcome_index":1,"market_type":"set2","local_side":"away","local_uid":"2026-08-23_felix_balshaw_sebastian_gorzny","bid":0.3,"ask":0.52,"mid":0.41,"spread":0.22,"price":0.52,"size":423.0,"side":"SELL"}
{"ts":"2026-08-23T17:53:38.191Z","event_type":"best_bid_ask","market_id":"3790323","outcome_index":0,"market_type":"set2","local_side":"home","local_uid":"2026-08-23_felix_balshaw_sebastian_gorzny","bid":0.48,"ask":0.74,"mid":0.61,"spread":0.26,"bid_size":null,"ask_size":null}
{"ts":"2026-08-23T17:53:38.191Z","event_type":"best_bid_ask","market_id":"3790323","outcome_index":1,"market_type":"set2","local_side":"away","local_uid":"2026-08-23_felix_balshaw_sebastian_gorzny","bid":0.26,"ask":0.52,"mid":0.39,"spread":0.26,"bid_size":null,"ask_size":null}
{"ts":"2026-08-23T17:53:38.192Z","event_type":"price_change","market_id":"3790323","outcome_index":1,"market_type":"set2","local_side":"away","local_uid":"2026-08-23_felix_balshaw_sebastian_gorzny","bid":0.26,"ask":0.52,"mid":0.39,"spread":0.26,"price":0.3,"size":0.0,"side":"BUY"}
{"ts":"2026-08-23T17:53:38.192Z","event_type":"price_change","market_id":"3790323","outcome_index":0,"market_type":"set2","local_side":"home","local_uid":"2026-08-23_felix_balshaw_sebastian_gorzny","bid":0.48,"ask":0.74,"mid":0.61,"spread":0.26,"price":0.7,"size":0.0,"side":"SELL"}
{"ts":"2026-08-23T17:53:38.224Z","event_type":"best_bid_ask","market_id":"3789997","outcome_index":0,"market_type":"match","local_side":"home","local_uid":"2026-08-23_oscar_weightman_alec_deckers","bid":0.05,"ask":0.06,"mid":0.055,"spread":0.01,"bid_size":null,"ask_size":null}
{"ts":"2026-08-23T17:53:38.224Z","event_type":"best_bid_ask","market_id":"3789997","outcome_index":1,"market_type":"match","local_side":"away","local_uid":"2026-08-23_oscar_weightman_alec_deckers","bid":0.94,"ask":0.95,"mid":0.945,"spread":0.01,"bid_size":null,"ask_size":null}
{"ts":"2026-08-23T17:53:38.224Z","event_type":"price_change","market_id":"3789997","outcome_index":0,"market_type":"match","local_side":"home","local_uid":"2026-08-23_oscar_weightman_alec_deckers","bid":0.05,"ask":0.06,"mid":0.055,"spread":0.01,"price":0.05,"size":63.0,"side":"BUY"}
{"ts":"2026-08-23T17:53:38.224Z","event_type":"price_change","market_id":"3789997","outcome_index":1,"market_type":"match","local_side":"away","local_uid":"2026-08-23_oscar_weightman_alec_deckers","bid":0.94,"ask":0.95,"mid":0.945,"spread":0.01,"price":0.95,"size":63.0,"side":"SELL"}
{"ts":"2026-08-23T17:53:38.395Z","event_type":"best_bid_ask","market_id":"3790415","outcome_index":0,"market_type":"set2","local_side":"home","local_uid":"2026-08-23_pierre_hugues_herbert_quinn_vandecasteele","bid":0.59,"ask":0.75,"mid":0.67,"spread":0.16,"bid_size":null,"ask_size":null}
{"ts":"2026-08-23T17:53:38.395Z","event_type":"best_bid_ask","market_id":"3790415","outcome_index":1,"market_type":"set2","local_side":"away","local_uid":"2026-08-23_pierre_hugues_herbert_quinn_vandecasteele","bid":0.25,"ask":0.41,"mid":0.33,"spread":0.16,"bid_size":null,"ask_size":null}
{"ts":"2026-08-23T17:53:38.396Z","event_type":"price_change","market_id":"3790415","outcome_index":0,"market_type":"set2","local_side":"home","local_uid":"2026-08-23_pierre_hugues_herbert_quinn_vandecasteele","bid":0.59,"ask":0.75,"mid":0.67,"spread":0.16,"price":0.59,"size":72.36,"side":"BUY"}
{"ts":"2026-08-23T17:53:38.396Z","event_type":"price_change","market_id":"3790415","outcome_index":1,"market_type":"set2","local_side":"away","local_uid":"2026-08-23_pierre_hugues_herbert_quinn_vandecasteele","bid":0.25,"ask":0.41,"mid":0.33,"spread":0.16,"price":0.41,"size":72.36,"side":"SELL"}
{"ts":"2026-08-23T17:53:38.438Z","event_type":"best_bid_ask","market_id":"3789997","outcome_index":0,"market_type":"match","local_side":"home","local_uid":"2026-08-23_oscar_weightman_alec_deckers","bid":0.05,"ask":0.07,"mid":0.06,"spread":0.02,"bid_size":null,"ask_size":null}
{"ts":"2026-08-23T17:53:38.438Z","event_type":"best_bid_ask","market_id":"3789997","outcome_index":1,"market_type":"match","local_side":"away","local_uid":"2026-08-23_oscar_weightman_alec_deckers","bid":0.93,"ask":0.95,"mid":0.94,"spread":0.02,"bid_size":null,"ask_size":null}
{"ts":"2026-08-23T17:53:38.438Z","event_type":"price_change","market_id":"3789997","outcome_index":1,"market_type":"match","local_side":"away","local_uid":"2026-08-23_oscar_weightman_alec_deckers","bid":0.93,"ask":0.95,"mid":0.94,"spread":0.02,"price":0.94,"size":0.0,"side":"BUY"}
{"ts":"2026-08-23T17:53:38.438Z","event_type":"price_change","market_id":"3789997","outcome_index":0,"market_type":"match","local_side":"home","local_uid":"2026-08-23_oscar_weightman_alec_deckers","bid":0.05,"ask":0.07,"mid":0.06,"spread":0.02,"price":0.06,"size":0.0,"side":"SELL"}
{"ts":"2026-08-23T17:53:38.438Z","event_type":"book","market_id":"3789997","outcome_index":0,"market_type":"match","local_side":"home","local_uid":"2026-08-23_oscar_weightman_alec_deckers","bid":0.05,"ask":0.07,"mid":0.06,"spread":0.02,"bid_size":165.2,"ask_size":26.0}
{"ts":"2026-08-23T17:53:38.451Z","event_type":"book","market_id":"3789997","outcome_index":1,"market_type":"match","local_side":"away","local_uid":"2026-08-23_oscar_weightman_alec_deckers","bid":0.93,"ask":0.95,"mid":0.94,"spread":0.02,"bid_size":26.0,"ask_size":165.2}
{"ts":"2026-08-23T17:53:38.452Z","event_type":"best_bid_ask","market_id":"3789997","outcome_index":0,"market_type":"match","local_side":"home","local_uid":"2026-08-23_oscar_weightman_alec_deckers","bid":0.05,"ask":0.08,"mid":0.065,"spread":0.03,"bid_size":null,"ask_size":null}
{"ts":"2026-08-23T17:53:38.452Z","event_type":"best_bid_ask","market_id":"3789997","outcome_index":1,"market_type":"match","local_side":"away","local_uid":"2026-08-23_oscar_weightman_alec_deckers","bid":0.92,"ask":0.95,"mid":0.935,"spread":0.03,"bid_size":null,"ask_size":null}
{"ts":"2026-08-23T17:53:38.460Z","event_type":"price_change","market_id":"3789997","outcome_index":1,"market_type":"match","local_side":"away","local_uid":"2026-08-23_oscar_weightman_alec_deckers","bid":0.92,"ask":0.95,"mid":0.935,"spread":0.03,"price":0.93,"size":0.0,"side":"BUY"}
{"ts":"2026-08-23T17:53:38.460Z","event_type":"price_change","market_id":"3789997","outcome_index":0,"market_type":"match","local_side":"home","local_uid":"2026-08-23_oscar_weightman_alec_deckers","bid":0.05,"ask":0.08,"mid":0.065,"spread":0.03,"price":0.07,"size":0.0,"side":"SELL"}
{"ts":"2026-08-23T17:53:38.461Z","event_type":"book","market_id":"3789997","outcome_index":0,"market_type":"match","local_side":"home","local_uid":"2026-08-23_oscar_weightman_alec_deckers","bid":0.05,"ask":0.08,"mid":0.065,"spread":0.03,"bid_size":165.2,"ask_size":447.09}
{"ts":"2026-08-23T17:53:38.465Z","event_type":"book","market_id":"3789997","outcome_index":1,"market_type":"match","local_side":"away","local_uid":"2026-08-23_oscar_weightman_alec_deckers","bid":0.92,"ask":0.95,"mid":0.935,"spread":0.03,"bid_size":447.09,"ask_size":165.2}
{"ts":"2026-08-23T17:53:38.495Z","event_type":"last_trade_price","market_id":"3789997","outcome_index":0,"market_type":"match","local_side":"home","local_uid":"2026-08-23_oscar_weightman_alec_deckers","last_trade":0.06,"trade_size":5.1,"trade_side":"BUY","trade_notional":0.306}
{"ts":"2026-08-23T17:53:38.514Z","event_type":"last_trade_price","market_id":"3789997","outcome_index":0,"market_type":"match","local_side":"home","local_uid":"2026-08-23_oscar_weightman_alec_deckers","last_trade":0.07,"trade_size":26.0,"trade_side":"BUY","trade_notional":1.82}
{"ts":"2026-08-23T17:53:38.629Z","event_type":"price_change","market_id":"3792975","outcome_index":1,"market_type":"match","local_side":"away","local_uid":"2026-08-23_coco_gauff_jessica_pegula","bid":0.41,"ask":0.42,"mid":0.415,"spread":0.01,"price":0.4,"size":64091.58,"side":"BUY"}
{"ts":"2026-08-23T17:53:38.629Z","event_type":"price_change","market_id":"3792975","outcome_index":0,"market_type":"match","local_side":"home","local_uid":"2026-08-23_coco_gauff_jessica_pegula","bid":0.58,"ask":0.59,"mid":0.585,"spread":0.01,"price":0.6,"size":64091.58,"side":"SELL"}
{"ts":"2026-08-23T17:53:38.672Z","event_type":"best_bid_ask","market_id":"3790415","outcome_index":0,"market_type":"set2","local_side":"home","local_uid":"2026-08-23_pierre_hugues_herbert_quinn_vandecasteele","bid":0.59,"ask":0.74,"mid":0.665,"spread":0.15,"bid_size":null,"ask_size":null}
{"ts":"2026-08-23T17:53:38.673Z","event_type":"best_bid_ask","market_id":"3790415","outcome_index":1,"market_type":"set2","local_side":"away","local_uid":"2026-08-23_pierre_hugues_herbert_quinn_vandecasteele","bid":0.26,"ask":0.41,"mid":0.335,"spread":0.15,"bid_size":null,"ask_size":null}
{"ts":"2026-08-23T17:53:38.673Z","event_type":"price_change","market_id":"3790415","outcome_index":1,"market_type":"set2","local_side":"away","local_uid":"2026-08-23_pierre_hugues_herbert_quinn_vandecasteele","bid":0.26,"ask":0.41,"mid":0.335,"spread":0.15,"price":0.26,"size":132.35,"side":"BUY"}
{"ts":"2026-08-23T17:53:38.673Z","event_type":"price_change","market_id":"3790415","outcome_index":0,"market_type":"set2","local_side":"home","local_uid":"2026-08-23_pierre_hugues_herbert_quinn_vandecasteele","bid":0.59,"ask":0.74,"mid":0.665,"spread":0.15,"price":0.74,"size":132.35,"side":"SELL"}
{"ts":"2026-08-23T17:53:38.897Z","event_type":"price_change","market_id":"3795964","outcome_index":1,"market_type":"match","local_side":"away","local_uid":"2026-08-23_nicholas_gore_dan_martin","bid":0.991,"ask":0.997,"mid":0.994,"spread":0.006,"price":0.493,"size":200.56,"side":"BUY"}
{"ts":"2026-08-23T17:53:38.897Z","event_type":"price_change","market_id":"3795964","outcome_index":0,"market_type":"match","local_side":"home","local_uid":"2026-08-23_nicholas_gore_dan_martin","bid":0.003,"ask":0.009,"mid":0.006,"spread":0.006,"price":0.507,"size":200.56,"side":"SELL"}
{"ts":"2026-08-23T17:53:39.010Z","event_type":"best_bid_ask","market_id":"3790323","outcome_index":0,"market_type":"set2","local_side":"home","local_uid":"2026-08-23_felix_balshaw_sebastian_gorzny","bid":0.48,"ask":0.72,"mid":0.6,"spread":0.24,"bid_size":null,"ask_size":null}
{"ts":"2026-08-23T17:53:39.011Z","event_type":"best_bid_ask","market_id":"3790323","outcome_index":1,"market_type":"set2","local_side":"away","local_uid":"2026-08-23_felix_balshaw_sebastian_gorzny","bid":0.28,"ask":0.52,"mid":0.4,"spread":0.24,"bid_size":null,"ask_size":null}
{"ts":"2026-08-23T17:53:39.011Z","event_type":"price_change","market_id":"3790323","outcome_index":1,"market_type":"set2","local_side":"away","local_uid":"2026-08-23_felix_balshaw_sebastian_gorzny","bid":0.28,"ask":0.52,"mid":0.4,"spread":0.24,"price":0.28,"size":88.0,"side":"BUY"}
{"ts":"2026-08-23T17:53:39.011Z","event_type":"price_change","market_id":"3790323","outcome_index":0,"market_type":"set2","local_side":"home","local_uid":"2026-08-23_felix_balshaw_sebastian_gorzny","bid":0.48,"ask":0.72,"mid":0.6,"spread":0.24,"price":0.72,"size":88.0,"side":"SELL"}
{"ts":"2026-08-23T17:53:39.135Z","event_type":"best_bid_ask","market_id":"3789927","outcome_index":0,"market_type":"match","local_side":"home","local_uid":"2026-08-23_hugo_grenier_mees_rottgering","bid":0.29,"ask":0.31,"mid":0.3,"spread":0.02,"bid_size":null,"ask_size":null}
{"ts":"2026-08-23T17:53:39.136Z","event_type":"best_bid_ask","market_id":"3789927","outcome_index":1,"market_type":"match","local_side":"away","local_uid":"2026-08-23_hugo_grenier_mees_rottgering","bid":0.69,"ask":0.71,"mid":0.7,"spread":0.02,"bid_size":null,"ask_size":null}
{"ts":"2026-08-23T17:53:39.136Z","event_type":"price_change","market_id":"3789927","outcome_index":0,"market_type":"match","local_side":"home","local_uid":"2026-08-23_hugo_grenier_mees_rottgering","bid":0.29,"ask":0.31,"mid":0.3,"spread":0.02,"price":0.3,"size":0.0,"side":"BUY"}
{"ts":"2026-08-23T17:53:39.136Z","event_type":"price_change","market_id":"3789927","outcome_index":1,"market_type":"match","local_side":"away","local_uid":"2026-08-23_hugo_grenier_mees_rottgering","bid":0.69,"ask":0.71,"mid":0.7,"spread":0.02,"price":0.7,"size":0.0,"side":"SELL"}
{"ts":"2026-08-23T17:53:39.351Z","event_type":"new_market","market_id":"0x44a36cfacc8d9f4232bccc7a0b1414ecd68811f40d6972543ba5d6cb8604d1c5"}
{"ts":"2026-08-23T17:53:39.420Z","event_type":"price_change","market_id":"3780844","outcome_index":0,"market_type":"match","local_side":"home","local_uid":"2026-08-23_pablo_carreno_busta_adolfo_daniel_vallejo","bid":0.56,"ask":0.57,"mid":0.565,"spread":0.01,"price":0.37,"size":0.0,"side":"BUY"}
{"ts":"2026-08-23T17:53:39.420Z","event_type":"price_change","market_id":"3780844","outcome_index":1,"market_type":"match","local_side":"away","local_uid":"2026-08-23_pablo_carreno_busta_adolfo_daniel_vallejo","bid":0.43,"ask":0.44,"mid":0.435,"spread":0.01,"price":0.63,"size":0.0,"side":"SELL"}
{"ts":"2026-08-23T17:53:39.477Z","event_type":"best_bid_ask","market_id":"3789927","outcome_index":0,"market_type":"match","local_side":"home","local_uid":"2026-08-23_hugo_grenier_mees_rottgering","bid":0.28,"ask":0.31,"mid":0.295,"spread":0.03,"bid_size":null,"ask_size":null}
{"ts":"2026-08-23T17:53:39.477Z","event_type":"best_bid_ask","market_id":"3789927","outcome_index":1,"market_type":"match","local_side":"away","local_uid":"2026-08-23_hugo_grenier_mees_rottgering","bid":0.69,"ask":0.72,"mid":0.705,"spread":0.03,"bid_size":null,"ask_size":null}
{"ts":"2026-08-23T17:53:39.477Z","event_type":"price_change","market_id":"3789927","outcome_index":0,"market_type":"match","local_side":"home","local_uid":"2026-08-23_hugo_grenier_mees_rottgering","bid":0.28,"ask":0.31,"mid":0.295,"spread":0.03,"price":0.29,"size":0.0,"side":"BUY"}
{"ts":"2026-08-23T17:53:39.477Z","event_type":"price_change","market_id":"3789927","outcome_index":1,"market_type":"match","local_side":"away","local_uid":"2026-08-23_hugo_grenier_mees_rottgering","bid":0.69,"ask":0.72,"mid":0.705,"spread":0.03,"price":0.71,"size":0.0,"side":"SELL"}
{"ts":"2026-08-23T17:53:39.595Z","event_type":"price_change","market_id":"3795968","outcome_index":1,"market_type":"match","local_side":"away","local_uid":"2026-08-23_mario_gonzalez_fernandez_richard_mallory","bid":0.49,"ask":0.5,"mid":0.495,"spread":0.01,"price":0.34,"size":0.0,"side":"BUY"}
{"ts":"2026-08-23T17:53:39.595Z","event_type":"price_change","market_id":"3795968","outcome_index":0,"market_type":"match","local_side":"home","local_uid":"2026-08-23_mario_gonzalez_fernandez_richard_mallory","bid":0.5,"ask":0.51,"mid":0.505,"spread":0.01,"price":0.66,"size":0.0,"side":"SELL"}
{"ts":"2026-08-23T17:53:39.648Z","event_type":"best_bid_ask","market_id":"3790394","outcome_index":0,"market_type":"set1","local_side":"home","local_uid":"2026-08-23_hugo_grenier_mees_rottgering","bid":0.0,"ask":0.46,"mid":0.23,"spread":0.46,"bid_size":null,"ask_size":null}
{"ts":"2026-08-23T17:53:39.648Z","event_type":"best_bid_ask","market_id":"3790394","outcome_index":1,"market_type":"set1","local_side":"away","local_uid":"2026-08-23_hugo_grenier_mees_rottgering","bid":0.54,"ask":1.0,"mid":0.77,"spread":0.46,"bid_size":null,"ask_size":null}
{"ts":"2026-08-23T17:53:39.648Z","event_type":"price_change","market_id":"3790394","outcome_index":0,"market_type":"set1","local_side":"home","local_uid":"2026-08-23_hugo_grenier_mees_rottgering","bid":0.0,"ask":0.46,"mid":0.23,"spread":0.46,"price":0.24,"size":0.0,"side":"BUY"}
{"ts":"2026-08-23T17:53:39.648Z","event_type":"price_change","market_id":"3790394","outcome_index":1,"market_type":"set1","local_side":"away","local_uid":"2026-08-23_hugo_grenier_mees_rottgering","bid":0.54,"ask":1.0,"mid":0.77,"spread":0.46,"price":0.76,"size":0.0,"side":"SELL"}
{"ts":"2026-08-23T17:53:39.718Z","event_type":"best_bid_ask","market_id":"3790394","outcome_index":0,"market_type":"set1","local_side":"home","local_uid":"2026-08-23_hugo_grenier_mees_rottgering","bid":0.0,"ask":0.44,"mid":0.22,"spread":0.44,"bid_size":null,"ask_size":null}
{"ts":"2026-08-23T17:53:39.718Z","event_type":"best_bid_ask","market_id":"3790394","outcome_index":1,"market_type":"set1","local_side":"away","local_uid":"2026-08-23_hugo_grenier_mees_rottgering","bid":0.56,"ask":1.0,"mid":0.78,"spread":0.44,"bid_size":null,"ask_size":null}
{"ts":"2026-08-23T17:53:39.718Z","event_type":"price_change","market_id":"3790394","outcome_index":1,"market_type":"set1","local_side":"away","local_uid":"2026-08-23_hugo_grenier_mees_rottgering","bid":0.56,"ask":1.0,"mid":0.78,"spread":0.44,"price":0.56,"size":36.0,"side":"BUY"}
{"ts":"2026-08-23T17:53:39.718Z","event_type":"price_change","market_id":"3790394","outcome_index":0,"market_type":"set1","local_side":"home","local_uid":"2026-08-23_hugo_grenier_mees_rottgering","bid":0.0,"ask":0.44,"mid":0.22,"spread":0.44,"price":0.44,"size":36.0,"side":"SELL"}
{"ts":"2026-08-23T17:53:39.747Z","event_type":"best_bid_ask","market_id":"3790394","outcome_index":0,"market_type":"set1","local_side":"home","local_uid":"2026-08-23_hugo_grenier_mees_rottgering","bid":0.26,"ask":0.44,"mid":0.35,"spread":0.18,"bid_size":null,"ask_size":null}
{"ts":"2026-08-23T17:53:39.747Z","event_type":"best_bid_ask","market_id":"3790394","outcome_index":1,"market_type":"set1","local_side":"away","local_uid":"2026-08-23_hugo_grenier_mees_rottgering","bid":0.56,"ask":0.74,"mid":0.65,"spread":0.18,"bid_size":null,"ask_size":null}
{"ts":"2026-08-23T17:53:39.747Z","event_type":"price_change","market_id":"3790394","outcome_index":0,"market_type":"set1","local_side":"home","local_uid":"2026-08-23_hugo_grenier_mees_rottgering","bid":0.26,"ask":0.44,"mid":0.35,"spread":0.18,"price":0.26,"size":28.04,"side":"BUY"}
{"ts":"2026-08-23T17:53:39.747Z","event_type":"price_change","market_id":"3790394","outcome_index":1,"market_type":"set1","local_side":"away","local_uid":"2026-08-23_hugo_grenier_mees_rottgering","bid":0.56,"ask":0.74,"mid":0.65,"spread":0.18,"price":0.74,"size":28.04,"side":"SELL"}
{"ts":"2026-08-23T17:53:40.357Z","event_type":"best_bid_ask","market_id":"3790323","outcome_index":0,"market_type":"set2","local_side":"home","local_uid":"2026-08-23_felix_balshaw_sebastian_gorzny","bid":0.5,"ask":0.72,"mid":0.61,"spread":0.22,"bid_size":null,"ask_size":null}
{"ts":"2026-08-23T17:53:40.357Z","event_type":"best_bid_ask","market_id":"3790323","outcome_index":1,"market_type":"set2","local_side":"away","local_uid":"2026-08-23_felix_balshaw_sebastian_gorzny","bid":0.28,"ask":0.5,"mid":0.39,"spread":0.22,"bid_size":null,"ask_size":null}
{"ts":"2026-08-23T17:53:40.357Z","event_type":"price_change","market_id":"3790323","outcome_index":0,"market_type":"set2","local_side":"home","local_uid":"2026-08-23_felix_balshaw_sebastian_gorzny","bid":0.5,"ask":0.72,"mid":0.61,"spread":0.22,"price":0.5,"size":150.0,"side":"BUY"}
{"ts":"2026-08-23T17:53:40.357Z","event_type":"price_change","market_id":"3790323","outcome_index":1,"market_type":"set2","local_side":"away","local_uid":"2026-08-23_felix_balshaw_sebastian_gorzny","bid":0.28,"ask":0.5,"mid":0.39,"spread":0.22,"price":0.5,"size":150.0,"side":"SELL"}
{"ts":"2026-08-23T17:53:40.359Z","event_type":"best_bid_ask","market_id":"3790323","outcome_index":0,"market_type":"set2","local_side":"home","local_uid":"2026-08-23_felix_balshaw_sebastian_gorzny","bid":0.51,"ask":0.72,"mid":0.615,"spread":0.21,"bid_size":null,"ask_size":null}
{"ts":"2026-08-23T17:53:40.359Z","event_type":"best_bid_ask","market_id":"3790323","outcome_index":1,"market_type":"set2","local_side":"away","local_uid":"2026-08-23_felix_balshaw_sebastian_gorzny","bid":0.28,"ask":0.49,"mid":0.385,"spread":0.21,"bid_size":null,"ask_size":null}
{"ts":"2026-08-23T17:53:40.360Z","event_type":"price_change","market_id":"3790323","outcome_index":0,"market_type":"set2","local_side":"home","local_uid":"2026-08-23_felix_balshaw_sebastian_gorzny","bid":0.51,"ask":0.72,"mid":0.615,"spread":0.21,"price":0.51,"size":29.03,"side":"BUY"}
{"ts":"2026-08-23T17:53:40.360Z","event_type":"price_change","market_id":"3790323","outcome_index":1,"market_type":"set2","local_side":"away","local_uid":"2026-08-23_felix_balshaw_sebastian_gorzny","bid":0.28,"ask":0.49,"mid":0.385,"spread":0.21,"price":0.49,"size":29.03,"side":"SELL"}
{"ts":"2026-08-23T17:53:40.466Z","event_type":"best_bid_ask","market_id":"3790323","outcome_index":0,"market_type":"set2","local_side":"home","local_uid":"2026-08-23_felix_balshaw_sebastian_gorzny","bid":0.51,"ask":0.71,"mid":0.61,"spread":0.2,"bid_size":null,"ask_size":null}
{"ts":"2026-08-23T17:53:40.466Z","event_type":"best_bid_ask","market_id":"3790323","outcome_index":1,"market_type":"set2","local_side":"away","local_uid":"2026-08-23_felix_balshaw_sebastian_gorzny","bid":0.29,"ask":0.49,"mid":0.39,"spread":0.2,"bid_size":null,"ask_size":null}
{"ts":"2026-08-23T17:53:40.466Z","event_type":"price_change","market_id":"3790323","outcome_index":1,"market_type":"set2","local_side":"away","local_uid":"2026-08-23_felix_balshaw_sebastian_gorzny","bid":0.29,"ask":0.49,"mid":0.39,"spread":0.2,"price":0.29,"size":61.13,"side":"BUY"}
{"ts":"2026-08-23T17:53:40.466Z","event_type":"price_change","market_id":"3790323","outcome_index":0,"market_type":"set2","local_side":"home","local_uid":"2026-08-23_felix_balshaw_sebastian_gorzny","bid":0.51,"ask":0.71,"mid":0.61,"spread":0.2,"price":0.71,"size":61.13,"side":"SELL"}
{"ts":"2026-08-23T17:53:40.696Z","event_type":"new_market","market_id":"0x482983def090d61b33e260aa9d34390db3602b1d32bd484140447a35fea22f71"}
{"ts":"2026-08-23T17:53:41.003Z","event_type":"new_market","market_id":"0xfc0ddaf9967c986b45d4ccfef045346fff0803a9993efbd5bd2cd9c6e8fedc7c"}
{"ts":"2026-08-23T17:53:41.007Z","event_type":"best_bid_ask","market_id":"3789997","outcome_index":0,"market_type":"match","local_side":"home","local_uid":"2026-08-23_oscar_weightman_alec_deckers","bid":0.06,"ask":0.08,"mid":0.07,"spread":0.02,"bid_size":null,"ask_size":null}
{"ts":"2026-08-23T17:53:41.007Z","event_type":"best_bid_ask","market_id":"3789997","outcome_index":1,"market_type":"match","local_side":"away","local_uid":"2026-08-23_oscar_weightman_alec_deckers","bid":0.92,"ask":0.94,"mid":0.93,"spread":0.02,"bid_size":null,"ask_size":null}
{"ts":"2026-08-23T17:53:41.007Z","event_type":"price_change","market_id":"3789997","outcome_index":0,"market_type":"match","local_side":"home","local_uid":"2026-08-23_oscar_weightman_alec_deckers","bid":0.06,"ask":0.08,"mid":0.07,"spread":0.02,"price":0.06,"size":21.0,"side":"BUY"}
{"ts":"2026-08-23T17:53:41.007Z","event_type":"price_change","market_id":"3789997","outcome_index":1,"market_type":"match","local_side":"away","local_uid":"2026-08-23_oscar_weightman_alec_deckers","bid":0.92,"ask":0.94,"mid":0.93,"spread":0.02,"price":0.94,"size":21.0,"side":"SELL"}
{"ts":"2026-08-23T17:53:41.247Z","event_type":"best_bid_ask","market_id":"3795958","outcome_index":0,"market_type":"match","local_side":"home","local_uid":"2026-08-23_bruno_kuzuhara_kody_pearson","bid":0.953,"ask":0.959,"mid":0.956,"spread":0.006,"bid_size":null,"ask_size":null}
{"ts":"2026-08-23T17:53:41.247Z","event_type":"best_bid_ask","market_id":"3795958","outcome_index":1,"market_type":"match","local_side":"away","local_uid":"2026-08-23_bruno_kuzuhara_kody_pearson","bid":0.041,"ask":0.047,"mid":0.044,"spread":0.006,"bid_size":null,"ask_size":null}
{"ts":"2026-08-23T17:53:41.247Z","event_type":"price_change","market_id":"3795958","outcome_index":0,"market_type":"match","local_side":"home","local_uid":"2026-08-23_bruno_kuzuhara_kody_pearson","bid":0.953,"ask":0.959,"mid":0.956,"spread":0.006,"price":0.953,"size":329.49,"side":"BUY"}
{"ts":"2026-08-23T17:53:41.247Z","event_type":"price_change","market_id":"3795958","outcome_index":1,"market_type":"match","local_side":"away","local_uid":"2026-08-23_bruno_kuzuhara_kody_pearson","bid":0.041,"ask":0.047,"mid":0.044,"spread":0.006,"price":0.047,"size":329.49,"side":"SELL"}
{"ts":"2026-08-23T17:53:41.348Z","event_type":"price_change","market_id":"3780836","outcome_index":1,"market_type":"match","local_side":"away","local_uid":"2026-08-23_rinky_hijikata_darwin_blanch","bid":0.33,"ask":0.34,"mid":0.335,"spread":0.01,"price":0.31,"size":23893.99,"side":"BUY"}
{"ts":"2026-08-23T17:53:41.349Z","event_type":"price_change","market_id":"3780836","outcome_index":0,"market_type":"match","local_side":"home","local_uid":"2026-08-23_rinky_hijikata_darwin_blanch","bid":0.66,"ask":0.67,"mid":0.665,"spread":0.01,"price":0.69,"size":23893.99,"side":"SELL"}
{"ts":"2026-08-23T17:53:41.771Z","event_type":"best_bid_ask","market_id":"3790323","outcome_index":0,"market_type":"set2","local_side":"home","local_uid":"2026-08-23_felix_balshaw_sebastian_gorzny","bid":0.59,"ask":0.71,"mid":0.65,"spread":0.12,"bid_size":null,"ask_size":null}
{"ts":"2026-08-23T17:53:41.771Z","event_type":"best_bid_ask","market_id":"3790323","outcome_index":1,"market_type":"set2","local_side":"away","local_uid":"2026-08-23_felix_balshaw_sebastian_gorzny","bid":0.29,"ask":0.41,"mid":0.35,"spread":0.12,"bid_size":null,"ask_size":null}
{"ts":"2026-08-23T17:53:41.772Z","event_type":"price_change","market_id":"3790323","outcome_index":0,"market_type":"set2","local_side":"home","local_uid":"2026-08-23_felix_balshaw_sebastian_gorzny","bid":0.59,"ask":0.71,"mid":0.65,"spread":0.12,"price":0.59,"size":423.0,"side":"BUY"}
{"ts":"2026-08-23T17:53:41.772Z","event_type":"price_change","market_id":"3790323","outcome_index":1,"market_type":"set2","local_side":"away","local_uid":"2026-08-23_felix_balshaw_sebastian_gorzny","bid":0.29,"ask":0.41,"mid":0.35,"spread":0.12,"price":0.41,"size":423.0,"side":"SELL"}
{"ts":"2026-08-23T17:53:41.786Z","event_type":"best_bid_ask","market_id":"3790323","outcome_index":0,"market_type":"set2","local_side":"home","local_uid":"2026-08-23_felix_balshaw_sebastian_gorzny","bid":0.6,"ask":0.71,"mid":0.655,"spread":0.11,"bid_size":null,"ask_size":null}
{"ts":"2026-08-23T17:53:41.786Z","event_type":"best_bid_ask","market_id":"3790323","outcome_index":1,"market_type":"set2","local_side":"away","local_uid":"2026-08-23_felix_balshaw_sebastian_gorzny","bid":0.29,"ask":0.4,"mid":0.345,"spread":0.11,"bid_size":null,"ask_size":null}
{"ts":"2026-08-23T17:53:41.786Z","event_type":"price_change","market_id":"3790323","outcome_index":0,"market_type":"set2","local_side":"home","local_uid":"2026-08-23_felix_balshaw_sebastian_gorzny","bid":0.6,"ask":0.71,"mid":0.655,"spread":0.11,"price":0.6,"size":88.0,"side":"BUY"}
{"ts":"2026-08-23T17:53:41.786Z","event_type":"price_change","market_id":"3790323","outcome_index":1,"market_type":"set2","local_side":"away","local_uid":"2026-08-23_felix_balshaw_sebastian_gorzny","bid":0.29,"ask":0.4,"mid":0.345,"spread":0.11,"price":0.4,"size":88.0,"side":"SELL"}
{"ts":"2026-08-23T17:53:41.875Z","event_type":"best_bid_ask","market_id":"3790323","outcome_index":0,"market_type":"set2","local_side":"home","local_uid":"2026-08-23_felix_balshaw_sebastian_gorzny","bid":0.6,"ask":0.72,"mid":0.66,"spread":0.12,"bid_size":null,"ask_size":null}
{"ts":"2026-08-23T17:53:41.876Z","event_type":"best_bid_ask","market_id":"3790323","outcome_index":1,"market_type":"set2","local_side":"away","local_uid":"2026-08-23_felix_balshaw_sebastian_gorzny","bid":0.28,"ask":0.4,"mid":0.34,"spread":0.12,"bid_size":null,"ask_size":null}
{"ts":"2026-08-23T17:53:41.876Z","event_type":"price_change","market_id":"3790323","outcome_index":1,"market_type":"set2","local_side":"away","local_uid":"2026-08-23_felix_balshaw_sebastian_gorzny","bid":0.28,"ask":0.4,"mid":0.34,"spread":0.12,"price":0.29,"size":0.0,"side":"BUY"}
{"ts":"2026-08-23T17:53:41.876Z","event_type":"price_change","market_id":"3790323","outcome_index":0,"market_type":"set2","local_side":"home","local_uid":"2026-08-23_felix_balshaw_sebastian_gorzny","bid":0.6,"ask":0.72,"mid":0.66,"spread":0.12,"price":0.71,"size":0.0,"side":"SELL"}
{"ts":"2026-08-23T17:53:41.878Z","event_type":"best_bid_ask","market_id":"3790323","outcome_index":0,"market_type":"set2","local_side":"home","local_uid":"2026-08-23_felix_balshaw_sebastian_gorzny","bid":0.62,"ask":0.72,"mid":0.67,"spread":0.1,"bid_size":null,"ask_size":null}
{"ts":"2026-08-23T17:53:41.878Z","event_type":"best_bid_ask","market_id":"3790323","outcome_index":1,"market_type":"set2","local_side":"away","local_uid":"2026-08-23_felix_balshaw_sebastian_gorzny","bid":0.28,"ask":0.38,"mid":0.33,"spread":0.1,"bid_size":null,"ask_size":null}
{"ts":"2026-08-23T17:53:41.878Z","event_type":"price_change","market_id":"3790323","outcome_index":0,"market_type":"set2","local_side":"home","local_uid":"2026-08-23_felix_balshaw_sebastian_gorzny","bid":0.62,"ask":0.72,"mid":0.67,"spread":0.1,"price":0.62,"size":150.0,"side":"BUY"}
{"ts":"2026-08-23T17:53:41.878Z","event_type":"price_change","market_id":"3790323","outcome_index":1,"market_type":"set2","local_side":"away","local_uid":"2026-08-23_felix_balshaw_sebastian_gorzny","bid":0.28,"ask":0.38,"mid":0.33,"spread":0.1,"price":0.38,"size":150.0,"side":"SELL"}
{"ts":"2026-08-23T17:53:41.907Z","event_type":"best_bid_ask","market_id":"3790323","outcome_index":0,"market_type":"set2","local_side":"home","local_uid":"2026-08-23_felix_balshaw_sebastian_gorzny","bid":0.62,"ask":0.71,"mid":0.665,"spread":0.09,"bid_size":null,"ask_size":null}
{"ts":"2026-08-23T17:53:41.907Z","event_type":"best_bid_ask","market_id":"3790323","outcome_index":1,"market_type":"set2","local_side":"away","local_uid":"2026-08-23_felix_balshaw_sebastian_gorzny","bid":0.29,"ask":0.38,"mid":0.335,"spread":0.09,"bid_size":null,"ask_size":null}
{"ts":"2026-08-23T17:53:41.907Z","event_type":"price_change","market_id":"3790323","outcome_index":1,"market_type":"set2","local_side":"away","local_uid":"2026-08-23_felix_balshaw_sebastian_gorzny","bid":0.29,"ask":0.38,"mid":0.335,"spread":0.09,"price":0.29,"size":54.0,"side":"BUY"}
{"ts":"2026-08-23T17:53:41.907Z","event_type":"price_change","market_id":"3790323","outcome_index":0,"market_type":"set2","local_side":"home","local_uid":"2026-08-23_felix_balshaw_sebastian_gorzny","bid":0.62,"ask":0.71,"mid":0.665,"spread":0.09,"price":0.71,"size":54.0,"side":"SELL"}
{"ts":"2026-08-23T17:53:42.059Z","event_type":"best_bid_ask","market_id":"3789929","outcome_index":0,"market_type":"match","local_side":"home","local_uid":"2026-08-23_felix_balshaw_sebastian_gorzny","bid":0.37,"ask":0.39,"mid":0.38,"spread":0.02,"bid_size":null,"ask_size":null}
{"ts":"2026-08-23T17:53:42.060Z","event_type":"best_bid_ask","market_id":"3789929","outcome_index":1,"market_type":"match","local_side":"away","local_uid":"2026-08-23_felix_balshaw_sebastian_gorzny","bid":0.61,"ask":0.63,"mid":0.62,"spread":0.02,"bid_size":null,"ask_size":null}
{"ts":"2026-08-23T17:53:42.069Z","event_type":"price_change","market_id":"3789929","outcome_index":0,"market_type":"match","local_side":"home","local_uid":"2026-08-23_felix_balshaw_sebastian_gorzny","bid":0.37,"ask":0.39,"mid":0.38,"spread":0.02,"price":0.37,"size":30.0,"side":"BUY"}
{"ts":"2026-08-23T17:53:42.069Z","event_type":"price_change","market_id":"3789929","outcome_index":1,"market_type":"match","local_side":"away","local_uid":"2026-08-23_felix_balshaw_sebastian_gorzny","bid":0.61,"ask":0.63,"mid":0.62,"spread":0.02,"price":0.63,"size":30.0,"side":"SELL"}
{"ts":"2026-08-23T17:53:42.073Z","event_type":"book","market_id":"3789929","outcome_index":0,"market_type":"match","local_side":"home","local_uid":"2026-08-23_felix_balshaw_sebastian_gorzny","bid":0.37,"ask":0.39,"mid":0.38,"spread":0.02,"bid_size":30.0,"ask_size":56.0}
{"ts":"2026-08-23T17:53:42.081Z","event_type":"book","market_id":"3789929","outcome_index":1,"market_type":"match","local_side":"away","local_uid":"2026-08-23_felix_balshaw_sebastian_gorzny","bid":0.61,"ask":0.63,"mid":0.62,"spread":0.02,"bid_size":56.0,"ask_size":30.0}
{"ts":"2026-08-23T17:53:42.126Z","event_type":"last_trade_price","market_id":"3789929","outcome_index":0,"market_type":"match","local_side":"home","local_uid":"2026-08-23_felix_balshaw_sebastian_gorzny","last_trade":0.37,"trade_size":70.0,"trade_side":"BUY","trade_notional":25.9}
{"ts":"2026-08-23T17:53:42.194Z","event_type":"best_bid_ask","market_id":"3789929","outcome_index":0,"market_type":"match","local_side":"home","local_uid":"2026-08-23_felix_balshaw_sebastian_gorzny","bid":0.38,"ask":0.39,"mid":0.385,"spread":0.01,"bid_size":null,"ask_size":null}
{"ts":"2026-08-23T17:53:42.194Z","event_type":"best_bid_ask","market_id":"3789929","outcome_index":1,"market_type":"match","local_side":"away","local_uid":"2026-08-23_felix_balshaw_sebastian_gorzny","bid":0.61,"ask":0.62,"mid":0.615,"spread":0.01,"bid_size":null,"ask_size":null}
{"ts":"2026-08-23T17:53:42.195Z","event_type":"price_change","market_id":"3789929","outcome_index":0,"market_type":"match","local_side":"home","local_uid":"2026-08-23_felix_balshaw_sebastian_gorzny","bid":0.38,"ask":0.39,"mid":0.385,"spread":0.01,"price":0.38,"size":60000.0,"side":"BUY"}
{"ts":"2026-08-23T17:53:42.195Z","event_type":"price_change","market_id":"3789929","outcome_index":1,"market_type":"match","local_side":"away","local_uid":"2026-08-23_felix_balshaw_sebastian_gorzny","bid":0.61,"ask":0.62,"mid":0.615,"spread":0.01,"price":0.62,"size":60000.0,"side":"SELL"}
{"ts":"2026-08-23T17:53:42.294Z","event_type":"price_change","market_id":"3790322","outcome_index":1,"market_type":"set1","local_side":"away","local_uid":"2026-08-23_felix_balshaw_sebastian_gorzny","bid":0.999,"ask":1.0,"mid":0.9995,"spread":0.001,"price":0.01,"size":14111.0,"side":"BUY"}
{"ts":"2026-08-23T17:53:42.294Z","event_type":"price_change","market_id":"3790322","outcome_index":0,"market_type":"set1","local_side":"home","local_uid":"2026-08-23_felix_balshaw_sebastian_gorzny","bid":0.0,"ask":0.001,"mid":0.0005,"spread":0.001,"price":0.99,"size":14111.0,"side":"SELL"}
{"ts":"2026-08-23T17:53:42.412Z","event_type":"price_change","market_id":"3780824","outcome_index":0,"market_type":"match","local_side":"home","local_uid":"2026-08-23_dino_prizmic_cruz_hewitt","bid":0.5,"ask":0.51,"mid":0.505,"spread":0.01,"price":0.5,"size":45847.62,"side":"BUY"}
{"ts":"2026-08-23T17:53:42.412Z","event_type":"price_change","market_id":"3780824","outcome_index":1,"market_type":"match","local_side":"away","local_uid":"2026-08-23_dino_prizmic_cruz_hewitt","bid":0.49,"ask":0.5,"mid":0.495,"spread":0.01,"price":0.5,"size":45847.62,"side":"SELL"}
{"ts":"2026-08-23T17:53:42.518Z","event_type":"best_bid_ask","market_id":"3789929","outcome_index":0,"market_type":"match","local_side":"home","local_uid":"2026-08-23_felix_balshaw_sebastian_gorzny","bid":0.38,"ask":0.4,"mid":0.39,"spread":0.02,"bid_size":null,"ask_size":null}
{"ts":"2026-08-23T17:53:42.518Z","event_type":"best_bid_ask","market_id":"3789929","outcome_index":1,"market_type":"match","local_side":"away","local_uid":"2026-08-23_felix_balshaw_sebastian_gorzny","bid":0.6,"ask":0.62,"mid":0.61,"spread":0.02,"bid_size":null,"ask_size":null}
{"ts":"2026-08-23T17:53:42.519Z","event_type":"price_change","market_id":"3789929","outcome_index":1,"market_type":"match","local_side":"away","local_uid":"2026-08-23_felix_balshaw_sebastian_gorzny","bid":0.6,"ask":0.62,"mid":0.61,"spread":0.02,"price":0.61,"size":0.0,"side":"BUY"}
{"ts":"2026-08-23T17:53:42.519Z","event_type":"price_change","market_id":"3789929","outcome_index":0,"market_type":"match","local_side":"home","local_uid":"2026-08-23_felix_balshaw_sebastian_gorzny","bid":0.38,"ask":0.4,"mid":0.39,"spread":0.02,"price":0.39,"size":0.0,"side":"SELL"}
{"ts":"2026-08-23T17:53:42.596Z","event_type":"best_bid_ask","market_id":"3789929","outcome_index":0,"market_type":"match","local_side":"home","local_uid":"2026-08-23_felix_balshaw_sebastian_gorzny","bid":0.39,"ask":0.4,"mid":0.395,"spread":0.01,"bid_size":null,"ask_size":null}
{"ts":"2026-08-23T17:53:42.596Z","event_type":"best_bid_ask","market_id":"3789929","outcome_index":1,"market_type":"match","local_side":"away","local_uid":"2026-08-23_felix_balshaw_sebastian_gorzny","bid":0.6,"ask":0.61,"mid":0.605,"spread":0.01,"bid_size":null,"ask_size":null}
{"ts":"2026-08-23T17:53:42.597Z","event_type":"price_change","market_id":"3789929","outcome_index":0,"market_type":"match","local_side":"home","local_uid":"2026-08-23_felix_balshaw_sebastian_gorzny","bid":0.39,"ask":0.4,"mid":0.395,"spread":0.01,"price":0.39,"size":530.87,"side":"BUY"}
{"ts":"2026-08-23T17:53:42.597Z","event_type":"price_change","market_id":"3789929","outcome_index":1,"market_type":"match","local_side":"away","local_uid":"2026-08-23_felix_balshaw_sebastian_gorzny","bid":0.6,"ask":0.61,"mid":0.605,"spread":0.01,"price":0.61,"size":530.87,"side":"SELL"}
{"ts":"2026-08-23T17:53:42.777Z","event_type":"price_change","market_id":"3795946","outcome_index":0,"market_type":"match","local_side":"home","local_uid":"2026-08-23_arthur_fils_frances_tiafoe","bid":0.66,"ask":0.67,"mid":0.665,"spread":0.01,"price":0.64,"size":9246.95,"side":"BUY"}
{"ts":"2026-08-23T17:53:42.777Z","event_type":"price_change","market_id":"3795946","outcome_index":1,"market_type":"match","local_side":"away","local_uid":"2026-08-23_arthur_fils_frances_tiafoe","bid":0.33,"ask":0.34,"mid":0.335,"spread":0.01,"price":0.36,"size":9246.95,"side":"SELL"}
{"ts":"2026-08-23T17:53:43.557Z","event_type":"new_market","market_id":"0xf04971097a1389ef6915c176b4e73ed9cba39d39c44842dbef959321750e2939"}
{"ts":"2026-08-23T17:53:43.566Z","event_type":"best_bid_ask","market_id":"3790323","outcome_index":0,"market_type":"set2","local_side":"home","local_uid":"2026-08-23_felix_balshaw_sebastian_gorzny","bid":0.62,"ask":0.73,"mid":0.675,"spread":0.11,"bid_size":null,"ask_size":null}
{"ts":"2026-08-23T17:53:43.567Z","event_type":"best_bid_ask","market_id":"3790323","outcome_index":1,"market_type":"set2","local_side":"away","local_uid":"2026-08-23_felix_balshaw_sebastian_gorzny","bid":0.27,"ask":0.38,"mid":0.325,"spread":0.11,"bid_size":null,"ask_size":null}
{"ts":"2026-08-23T17:53:43.567Z","event_type":"price_change","market_id":"3790323","outcome_index":1,"market_type":"set2","local_side":"away","local_uid":"2026-08-23_felix_balshaw_sebastian_gorzny","bid":0.27,"ask":0.38,"mid":0.325,"spread":0.11,"price":0.29,"size":0.0,"side":"BUY"}
{"ts":"2026-08-23T17:53:43.567Z","event_type":"price_change","market_id":"3790323","outcome_index":0,"market_type":"set2","local_side":"home","local_uid":"2026-08-23_felix_balshaw_sebastian_gorzny","bid":0.62,"ask":0.73,"mid":0.675,"spread":0.11,"price":0.71,"size":0.0,"side":"SELL"}
{"ts":"2026-08-23T17:53:43.592Z","event_type":"best_bid_ask","market_id":"3790323","outcome_index":0,"market_type":"set2","local_side":"home","local_uid":"2026-08-23_felix_balshaw_sebastian_gorzny","bid":0.62,"ask":0.72,"mid":0.67,"spread":0.1,"bid_size":null,"ask_size":null}
{"ts":"2026-08-23T17:53:43.604Z","event_type":"best_bid_ask","market_id":"3790323","outcome_index":1,"market_type":"set2","local_side":"away","local_uid":"2026-08-23_felix_balshaw_sebastian_gorzny","bid":0.28,"ask":0.38,"mid":0.33,"spread":0.1,"bid_size":null,"ask_size":null}
{"ts":"2026-08-23T17:53:43.604Z","event_type":"price_change","market_id":"3790323","outcome_index":1,"market_type":"set2","local_side":"away","local_uid":"2026-08-23_felix_balshaw_sebastian_gorzny","bid":0.28,"ask":0.38,"mid":0.33,"spread":0.1,"price":0.28,"size":100.37,"side":"BUY"}
{"ts":"2026-08-23T17:53:43.604Z","event_type":"price_change","market_id":"3790323","outcome_index":0,"market_type":"set2","local_side":"home","local_uid":"2026-08-23_felix_balshaw_sebastian_gorzny","bid":0.62,"ask":0.72,"mid":0.67,"spread":0.1,"price":0.72,"size":100.37,"side":"SELL"}
{"ts":"2026-08-23T17:53:43.671Z","event_type":"best_bid_ask","market_id":"3790334","outcome_index":0,"market_type":"set2","local_side":"home","local_uid":"2026-08-23_abdullah_shelbayh_dhakshineswar_suresh","bid":0.48,"ask":0.52,"mid":0.5,"spread":0.04,"bid_size":null,"ask_size":null}
{"ts":"2026-08-23T17:53:43.671Z","event_type":"best_bid_ask","market_id":"3790334","outcome_index":1,"market_type":"set2","local_side":"away","local_uid":"2026-08-23_abdullah_shelbayh_dhakshineswar_suresh","bid":0.48,"ask":0.52,"mid":0.5,"spread":0.04,"bid_size":null,"ask_size":null}
{"ts":"2026-08-23T17:53:43.694Z","event_type":"price_change","market_id":"3790334","outcome_index":1,"market_type":"set2","local_side":"away","local_uid":"2026-08-23_abdullah_shelbayh_dhakshineswar_suresh","bid":0.48,"ask":0.52,"mid":0.5,"spread":0.04,"price":0.48,"size":150.0,"side":"BUY"}
{"ts":"2026-08-23T17:53:43.694Z","event_type":"price_change","market_id":"3790334","outcome_index":0,"market_type":"set2","local_side":"home","local_uid":"2026-08-23_abdullah_shelbayh_dhakshineswar_suresh","bid":0.48,"ask":0.52,"mid":0.5,"spread":0.04,"price":0.52,"size":150.0,"side":"SELL"}
{"ts":"2026-08-23T17:53:43.885Z","event_type":"new_market","market_id":"0xb8e72d84530c7b616c4c7473789f0a2606b06600405546712ae5d4d5b22f3efc"}
{"ts":"2026-08-23T17:53:44.262Z","event_type":"best_bid_ask","market_id":"3790334","outcome_index":0,"market_type":"set2","local_side":"home","local_uid":"2026-08-23_abdullah_shelbayh_dhakshineswar_suresh","bid":0.48,"ask":0.51,"mid":0.495,"spread":0.03,"bid_size":null,"ask_size":null}
{"ts":"2026-08-23T17:53:44.263Z","event_type":"best_bid_ask","market_id":"3790334","outcome_index":1,"market_type":"set2","local_side":"away","local_uid":"2026-08-23_abdullah_shelbayh_dhakshineswar_suresh","bid":0.49,"ask":0.52,"mid":0.505,"spread":0.03,"bid_size":null,"ask_size":null}
{"ts":"2026-08-23T17:53:44.263Z","event_type":"price_change","market_id":"3790334","outcome_index":1,"market_type":"set2","local_side":"away","local_uid":"2026-08-23_abdullah_shelbayh_dhakshineswar_suresh","bid":0.49,"ask":0.52,"mid":0.505,"spread":0.03,"price":0.49,"size":150.0,"side":"BUY"}
{"ts":"2026-08-23T17:53:44.263Z","event_type":"price_change","market_id":"3790334","outcome_index":0,"market_type":"set2","local_side":"home","local_uid":"2026-08-23_abdullah_shelbayh_dhakshineswar_suresh","bid":0.48,"ask":0.51,"mid":0.495,"spread":0.03,"price":0.51,"size":150.0,"side":"SELL"}
{"ts":"2026-08-23T17:53:44.263Z","event_type":"best_bid_ask","market_id":"3790323","outcome_index":0,"market_type":"set2","local_side":"home","local_uid":"2026-08-23_felix_balshaw_sebastian_gorzny","bid":0.63,"ask":0.72,"mid":0.675,"spread":0.09,"bid_size":null,"ask_size":null}
{"ts":"2026-08-23T17:53:44.263Z","event_type":"best_bid_ask","market_id":"3790323","outcome_index":1,"market_type":"set2","local_side":"away","local_uid":"2026-08-23_felix_balshaw_sebastian_gorzny","bid":0.28,"ask":0.37,"mid":0.325,"spread":0.09,"bid_size":null,"ask_size":null}
{"ts":"2026-08-23T17:53:44.267Z","event_type":"price_change","market_id":"3790323","outcome_index":0,"market_type":"set2","local_side":"home","local_uid":"2026-08-23_felix_balshaw_sebastian_gorzny","bid":0.63,"ask":0.72,"mid":0.675,"spread":0.09,"price":0.63,"size":150.0,"side":"BUY"}
{"ts":"2026-08-23T17:53:44.267Z","event_type":"price_change","market_id":"3790323","outcome_index":1,"market_type":"set2","local_side":"away","local_uid":"2026-08-23_felix_balshaw_sebastian_gorzny","bid":0.28,"ask":0.37,"mid":0.325,"spread":0.09,"price":0.37,"size":150.0,"side":"SELL"}
{"ts":"2026-08-23T17:53:44.439Z","event_type":"best_bid_ask","market_id":"3790334","outcome_index":0,"market_type":"set2","local_side":"home","local_uid":"2026-08-23_abdullah_shelbayh_dhakshineswar_suresh","bid":0.48,"ask":0.5,"mid":0.49,"spread":0.02,"bid_size":null,"ask_size":null}
{"ts":"2026-08-23T17:53:44.440Z","event_type":"best_bid_ask","market_id":"3790334","outcome_index":1,"market_type":"set2","local_side":"away","local_uid":"2026-08-23_abdullah_shelbayh_dhakshineswar_suresh","bid":0.5,"ask":0.52,"mid":0.51,"spread":0.02,"bid_size":null,"ask_size":null}
{"ts":"2026-08-23T17:53:44.440Z","event_type":"price_change","market_id":"3790334","outcome_index":1,"market_type":"set2","local_side":"away","local_uid":"2026-08-23_abdullah_shelbayh_dhakshineswar_suresh","bid":0.5,"ask":0.52,"mid":0.51,"spread":0.02,"price":0.5,"size":59.53,"side":"BUY"}
{"ts":"2026-08-23T17:53:44.440Z","event_type":"price_change","market_id":"3790334","outcome_index":0,"market_type":"set2","local_side":"home","local_uid":"2026-08-23_abdullah_shelbayh_dhakshineswar_suresh","bid":0.48,"ask":0.5,"mid":0.49,"spread":0.02,"price":0.5,"size":59.53,"side":"SELL"}
{"ts":"2026-08-23T17:53:44.484Z","event_type":"best_bid_ask","market_id":"3790334","outcome_index":0,"market_type":"set2","local_side":"home","local_uid":"2026-08-23_abdullah_shelbayh_dhakshineswar_suresh","bid":0.48,"ask":0.51,"mid":0.495,"spread":0.03,"bid_size":null,"ask_size":null}
{"ts":"2026-08-23T17:53:44.484Z","event_type":"best_bid_ask","market_id":"3790334","outcome_index":1,"market_type":"set2","local_side":"away","local_uid":"2026-08-23_abdullah_shelbayh_dhakshineswar_suresh","bid":0.49,"ask":0.52,"mid":0.505,"spread":0.03,"bid_size":null,"ask_size":null}
{"ts":"2026-08-23T17:53:44.484Z","event_type":"price_change","market_id":"3790334","outcome_index":1,"market_type":"set2","local_side":"away","local_uid":"2026-08-23_abdullah_shelbayh_dhakshineswar_suresh","bid":0.49,"ask":0.52,"mid":0.505,"spread":0.03,"price":0.5,"size":0.0,"side":"BUY"}
{"ts":"2026-08-23T17:53:44.485Z","event_type":"price_change","market_id":"3790334","outcome_index":0,"market_type":"set2","local_side":"home","local_uid":"2026-08-23_abdullah_shelbayh_dhakshineswar_suresh","bid":0.48,"ask":0.51,"mid":0.495,"spread":0.03,"price":0.5,"size":0.0,"side":"SELL"}
{"ts":"2026-08-23T17:53:44.522Z","event_type":"price_change","market_id":"3781424","outcome_index":1,"market_type":"set2","local_side":"away","local_uid":"2026-08-23_sho_shimabukuro_miomir_kecmanovic","bid":0.61,"ask":0.69,"mid":0.65,"spread":0.08,"price":0.59,"size":0.0,"side":"BUY"}
{"ts":"2026-08-23T17:53:44.522Z","event_type":"price_change","market_id":"3781424","outcome_index":0,"market_type":"set2","local_side":"home","local_uid":"2026-08-23_sho_shimabukuro_miomir_kecmanovic","bid":0.31,"ask":0.39,"mid":0.35,"spread":0.08,"price":0.41,"size":0.0,"side":"SELL"}
{"ts":"2026-08-23T17:53:44.545Z","event_type":"best_bid_ask","market_id":"3790334","outcome_index":0,"market_type":"set2","local_side":"home","local_uid":"2026-08-23_abdullah_shelbayh_dhakshineswar_suresh","bid":0.48,"ask":0.5,"mid":0.49,"spread":0.02,"bid_size":null,"ask_size":null}
{"ts":"2026-08-23T17:53:44.546Z","event_type":"best_bid_ask","market_id":"3790334","outcome_index":1,"market_type":"set2","local_side":"away","local_uid":"2026-08-23_abdullah_shelbayh_dhakshineswar_suresh","bid":0.5,"ask":0.52,"mid":0.51,"spread":0.02,"bid_size":null,"ask_size":null}
{"ts":"2026-08-23T17:53:44.546Z","event_type":"price_change","market_id":"3790334","outcome_index":1,"market_type":"set2","local_side":"away","local_uid":"2026-08-23_abdullah_shelbayh_dhakshineswar_suresh","bid":0.5,"ask":0.52,"mid":0.51,"spread":0.02,"price":0.5,"size":20.58,"side":"BUY"}
{"ts":"2026-08-23T17:53:44.546Z","event_type":"price_change","market_id":"3790334","outcome_index":0,"market_type":"set2","local_side":"home","local_uid":"2026-08-23_abdullah_shelbayh_dhakshineswar_suresh","bid":0.48,"ask":0.5,"mid":0.49,"spread":0.02,"price":0.5,"size":20.58,"side":"SELL"}
{"ts":"2026-08-23T17:53:44.717Z","event_type":"price_change","market_id":"3789987","outcome_index":1,"market_type":"match","local_side":"away","local_uid":"2026-08-23_mika_petkovic_federico_iannaccone","bid":0.999,"ask":1.0,"mid":0.9995,"spread":0.001,"price":0.013,"size":44000.0,"side":"BUY"}
{"ts":"2026-08-23T17:53:44.717Z","event_type":"price_change","market_id":"3789987","outcome_index":0,"market_type":"match","local_side":"home","local_uid":"2026-08-23_mika_petkovic_federico_iannaccone","bid":0.0,"ask":0.001,"mid":0.0005,"spread":0.001,"price":0.987,"size":44000.0,"side":"SELL"}
{"ts":"2026-08-23T17:53:44.861Z","event_type":"price_change","market_id":"3802004","outcome_index":1,"market_type":"match","local_side":"away","local_uid":"2026-08-24_luis_guto_miguel_tyler_zink","bid":0.62,"ask":0.63,"mid":0.625,"spread":0.01,"price":0.75,"size":9.0,"side":"SELL"}
{"ts":"2026-08-23T17:53:44.861Z","event_type":"price_change","market_id":"3802004","outcome_index":0,"market_type":"match","local_side":"home","local_uid":"2026-08-24_luis_guto_miguel_tyler_zink","bid":0.37,"ask":0.38,"mid":0.375,"spread":0.01,"price":0.25,"size":9.0,"side":"BUY"}
{"ts":"2026-08-23T17:53:45.344Z","event_type":"new_market","market_id":"0x48da80643121e494f23b7d48454f4f5a737b09f33cb2723f0eca4fe481117b5c"}
{"ts":"2026-08-23T17:53:46.011Z","event_type":"price_change","market_id":"3790338","outcome_index":0,"market_type":"set1","local_side":"home","local_uid":"2026-08-23_abdullah_shelbayh_dhakshineswar_suresh","bid":0.999,"ask":1.0,"mid":0.9995,"spread":0.001,"price":0.99,"size":5267.0,"side":"BUY"}
{"ts":"2026-08-23T17:53:46.012Z","event_type":"price_change","market_id":"3790338","outcome_index":1,"market_type":"set1","local_side":"away","local_uid":"2026-08-23_abdullah_shelbayh_dhakshineswar_suresh","bid":0.0,"ask":0.001,"mid":0.0005,"spread":0.001,"price":0.01,"size":5267.0,"side":"SELL"}
{"ts":"2026-08-23T17:53:46.951Z","event_type":"best_bid_ask","market_id":"3790334","outcome_index":0,"market_type":"set2","local_side":"home","local_uid":"2026-08-23_abdullah_shelbayh_dhakshineswar_suresh","bid":0.48,"ask":0.52,"mid":0.5,"spread":0.04,"bid_size":null,"ask_size":null}
{"ts":"2026-08-23T17:53:46.951Z","event_type":"best_bid_ask","market_id":"3790334","outcome_index":1,"market_type":"set2","local_side":"away","local_uid":"2026-08-23_abdullah_shelbayh_dhakshineswar_suresh","bid":0.48,"ask":0.52,"mid":0.5,"spread":0.04,"bid_size":null,"ask_size":null}
{"ts":"2026-08-23T17:53:46.954Z","event_type":"price_change","market_id":"3790334","outcome_index":1,"market_type":"set2","local_side":"away","local_uid":"2026-08-23_abdullah_shelbayh_dhakshineswar_suresh","bid":0.48,"ask":0.52,"mid":0.5,"spread":0.04,"price":0.5,"size":0.0,"side":"BUY"}
{"ts":"2026-08-23T17:53:46.954Z","event_type":"price_change","market_id":"3790334","outcome_index":0,"market_type":"set2","local_side":"home","local_uid":"2026-08-23_abdullah_shelbayh_dhakshineswar_suresh","bid":0.48,"ask":0.52,"mid":0.5,"spread":0.04,"price":0.5,"size":0.0,"side":"SELL"}
{"ts":"2026-08-23T17:53:46.976Z","event_type":"best_bid_ask","market_id":"3790334","outcome_index":0,"market_type":"set2","local_side":"home","local_uid":"2026-08-23_abdullah_shelbayh_dhakshineswar_suresh","bid":0.48,"ask":0.51,"mid":0.495,"spread":0.03,"bid_size":null,"ask_size":null}
{"ts":"2026-08-23T17:53:46.977Z","event_type":"best_bid_ask","market_id":"3790334","outcome_index":1,"market_type":"set2","local_side":"away","local_uid":"2026-08-23_abdullah_shelbayh_dhakshineswar_suresh","bid":0.49,"ask":0.52,"mid":0.505,"spread":0.03,"bid_size":null,"ask_size":null}
{"ts":"2026-08-23T17:53:46.977Z","event_type":"price_change","market_id":"3790334","outcome_index":1,"market_type":"set2","local_side":"away","local_uid":"2026-08-23_abdullah_shelbayh_dhakshineswar_suresh","bid":0.49,"ask":0.52,"mid":0.505,"spread":0.03,"price":0.49,"size":150.0,"side":"BUY"}
{"ts":"2026-08-23T17:53:46.977Z","event_type":"price_change","market_id":"3790334","outcome_index":0,"market_type":"set2","local_side":"home","local_uid":"2026-08-23_abdullah_shelbayh_dhakshineswar_suresh","bid":0.48,"ask":0.51,"mid":0.495,"spread":0.03,"price":0.51,"size":150.0,"side":"SELL"}
{"ts":"2026-08-23T17:53:47.120Z","event_type":"best_bid_ask","market_id":"3789927","outcome_index":0,"market_type":"match","local_side":"home","local_uid":"2026-08-23_hugo_grenier_mees_rottgering","bid":0.28,"ask":0.3,"mid":0.29,"spread":0.02,"bid_size":null,"ask_size":null}
{"ts":"2026-08-23T17:53:47.120Z","event_type":"best_bid_ask","market_id":"3789927","outcome_index":1,"market_type":"match","local_side":"away","local_uid":"2026-08-23_hugo_grenier_mees_rottgering","bid":0.7,"ask":0.72,"mid":0.71,"spread":0.02,"bid_size":null,"ask_size":null}
{"ts":"2026-08-23T17:53:47.120Z","event_type":"price_change","market_id":"3789927","outcome_index":1,"market_type":"match","local_side":"away","local_uid":"2026-08-23_hugo_grenier_mees_rottgering","bid":0.7,"ask":0.72,"mid":0.71,"spread":0.02,"price":0.7,"size":6000.0,"side":"BUY"}
{"ts":"2026-08-23T17:53:47.120Z","event_type":"price_change","market_id":"3789927","outcome_index":0,"market_type":"match","local_side":"home","local_uid":"2026-08-23_hugo_grenier_mees_rottgering","bid":0.28,"ask":0.3,"mid":0.29,"spread":0.02,"price":0.3,"size":6000.0,"side":"SELL"}
{"ts":"2026-08-23T17:53:47.136Z","event_type":"new_market","market_id":"0x088245b7156a7e94f0c92b735c285e89723f6452eeca0e3040f965d0e16b9400"}
{"ts":"2026-08-23T17:53:47.159Z","event_type":"best_bid_ask","market_id":"3789927","outcome_index":0,"market_type":"match","local_side":"home","local_uid":"2026-08-23_hugo_grenier_mees_rottgering","bid":0.28,"ask":0.31,"mid":0.295,"spread":0.03,"bid_size":null,"ask_size":null}
{"ts":"2026-08-23T17:53:47.159Z","event_type":"best_bid_ask","market_id":"3789927","outcome_index":1,"market_type":"match","local_side":"away","local_uid":"2026-08-23_hugo_grenier_mees_rottgering","bid":0.69,"ask":0.72,"mid":0.705,"spread":0.03,"bid_size":null,"ask_size":null}
{"ts":"2026-08-23T17:53:47.159Z","event_type":"price_change","market_id":"3789927","outcome_index":1,"market_type":"match","local_side":"away","local_uid":"2026-08-23_hugo_grenier_mees_rottgering","bid":0.69,"ask":0.72,"mid":0.705,"spread":0.03,"price":0.7,"size":0.0,"side":"BUY"}
{"ts":"2026-08-23T17:53:47.160Z","event_type":"price_change","market_id":"3789927","outcome_index":0,"market_type":"match","local_side":"home","local_uid":"2026-08-23_hugo_grenier_mees_rottgering","bid":0.28,"ask":0.31,"mid":0.295,"spread":0.03,"price":0.3,"size":0.0,"side":"SELL"}
{"ts":"2026-08-23T17:53:47.445Z","event_type":"best_bid_ask","market_id":"3790394","outcome_index":0,"market_type":"set1","local_side":"home","local_uid":"2026-08-23_hugo_grenier_mees_rottgering","bid":0.26,"ask":0.36,"mid":0.31,"spread":0.1,"bid_size":null,"ask_size":null}
{"ts":"2026-08-23T17:53:47.451Z","event_type":"best_bid_ask","market_id":"3790394","outcome_index":1,"market_type":"set1","local_side":"away","local_uid":"2026-08-23_hugo_grenier_mees_rottgering","bid":0.64,"ask":0.74,"mid":0.69,"spread":0.1,"bid_size":null,"ask_size":null}
{"ts":"2026-08-23T17:53:47.451Z","event_type":"price_change","market_id":"3790394","outcome_index":1,"market_type":"set1","local_side":"away","local_uid":"2026-08-23_hugo_grenier_mees_rottgering","bid":0.64,"ask":0.74,"mid":0.69,"spread":0.1,"price":0.64,"size":88.0,"side":"BUY"}
{"ts":"2026-08-23T17:53:47.451Z","event_type":"price_change","market_id":"3790394","outcome_index":0,"market_type":"set1","local_side":"home","local_uid":"2026-08-23_hugo_grenier_mees_rottgering","bid":0.26,"ask":0.36,"mid":0.31,"spread":0.1,"price":0.36,"size":88.0,"side":"SELL"}
{"ts":"2026-08-23T17:53:47.451Z","event_type":"best_bid_ask","market_id":"3790397","outcome_index":0,"market_type":"set2","local_side":"home","local_uid":"2026-08-23_hugo_grenier_mees_rottgering","bid":0.31,"ask":0.42,"mid":0.365,"spread":0.11,"bid_size":null,"ask_size":null}
{"ts":"2026-08-23T17:53:47.452Z","event_type":"best_bid_ask","market_id":"3790397","outcome_index":1,"market_type":"set2","local_side":"away","local_uid":"2026-08-23_hugo_grenier_mees_rottgering","bid":0.58,"ask":0.69,"mid":0.635,"spread":0.11,"bid_size":null,"ask_size":null}
{"ts":"2026-08-23T17:53:47.452Z","event_type":"price_change","market_id":"3790397","outcome_index":1,"market_type":"set2","local_side":"away","local_uid":"2026-08-23_hugo_grenier_mees_rottgering","bid":0.58,"ask":0.69,"mid":0.635,"spread":0.11,"price":0.58,"size":88.0,"side":"BUY"}
{"ts":"2026-08-23T17:53:47.452Z","event_type":"price_change","market_id":"3790397","outcome_index":0,"market_type":"set2","local_side":"home","local_uid":"2026-08-23_hugo_grenier_mees_rottgering","bid":0.31,"ask":0.42,"mid":0.365,"spread":0.11,"price":0.42,"size":88.0,"side":"SELL"}
{"ts":"2026-08-23T17:53:47.478Z","event_type":"best_bid_ask","market_id":"3789927","outcome_index":0,"market_type":"match","local_side":"home","local_uid":"2026-08-23_hugo_grenier_mees_rottgering","bid":0.28,"ask":0.3,"mid":0.29,"spread":0.02,"bid_size":null,"ask_size":null}
{"ts":"2026-08-23T17:53:47.478Z","event_type":"best_bid_ask","market_id":"3789927","outcome_index":1,"market_type":"match","local_side":"away","local_uid":"2026-08-23_hugo_grenier_mees_rottgering","bid":0.7,"ask":0.72,"mid":0.71,"spread":0.02,"bid_size":null,"ask_size":null}
{"ts":"2026-08-23T17:53:47.478Z","event_type":"price_change","market_id":"3789927","outcome_index":1,"market_type":"match","local_side":"away","local_uid":"2026-08-23_hugo_grenier_mees_rottgering","bid":0.7,"ask":0.72,"mid":0.71,"spread":0.02,"price":0.7,"size":30.0,"side":"BUY"}
{"ts":"2026-08-23T17:53:47.478Z","event_type":"price_change","market_id":"3789927","outcome_index":0,"market_type":"match","local_side":"home","local_uid":"2026-08-23_hugo_grenier_mees_rottgering","bid":0.28,"ask":0.3,"mid":0.29,"spread":0.02,"price":0.3,"size":30.0,"side":"SELL"}
{"ts":"2026-08-23T17:53:47.478Z","event_type":"best_bid_ask","market_id":"3790394","outcome_index":0,"market_type":"set1","local_side":"home","local_uid":"2026-08-23_hugo_grenier_mees_rottgering","bid":0.25,"ask":0.36,"mid":0.305,"spread":0.11,"bid_size":null,"ask_size":null}
{"ts":"2026-08-23T17:53:47.478Z","event_type":"best_bid_ask","market_id":"3790394","outcome_index":1,"market_type":"set1","local_side":"away","local_uid":"2026-08-23_hugo_grenier_mees_rottgering","bid":0.64,"ask":0.75,"mid":0.695,"spread":0.11,"bid_size":null,"ask_size":null}
{"ts":"2026-08-23T17:53:47.478Z","event_type":"price_change","market_id":"3790394","outcome_index":0,"market_type":"set1","local_side":"home","local_uid":"2026-08-23_hugo_grenier_mees_rottgering","bid":0.25,"ask":0.36,"mid":0.305,"spread":0.11,"price":0.26,"size":0.0,"side":"BUY"}
{"ts":"2026-08-23T17:53:47.479Z","event_type":"price_change","market_id":"3790394","outcome_index":1,"market_type":"set1","local_side":"away","local_uid":"2026-08-23_hugo_grenier_mees_rottgering","bid":0.64,"ask":0.75,"mid":0.695,"spread":0.11,"price":0.74,"size":0.0,"side":"SELL"}
{"ts":"2026-08-23T17:53:47.482Z","event_type":"best_bid_ask","market_id":"3789927","outcome_index":0,"market_type":"match","local_side":"home","local_uid":"2026-08-23_hugo_grenier_mees_rottgering","bid":0.28,"ask":0.29,"mid":0.285,"spread":0.01,"bid_size":null,"ask_size":null}
{"ts":"2026-08-23T17:53:47.482Z","event_type":"best_bid_ask","market_id":"3789927","outcome_index":1,"market_type":"match","local_side":"away","local_uid":"2026-08-23_hugo_grenier_mees_rottgering","bid":0.71,"ask":0.72,"mid":0.715,"spread":0.01,"bid_size":null,"ask_size":null}
{"ts":"2026-08-23T17:53:47.482Z","event_type":"price_change","market_id":"3789927","outcome_index":1,"market_type":"match","local_side":"away","local_uid":"2026-08-23_hugo_grenier_mees_rottgering","bid":0.71,"ask":0.72,"mid":0.715,"spread":0.01,"price":0.71,"size":15.0,"side":"BUY"}
{"ts":"2026-08-23T17:53:47.482Z","event_type":"price_change","market_id":"3789927","outcome_index":0,"market_type":"match","local_side":"home","local_uid":"2026-08-23_hugo_grenier_mees_rottgering","bid":0.28,"ask":0.29,"mid":0.285,"spread":0.01,"price":0.29,"size":15.0,"side":"SELL"}
{"ts":"2026-08-23T17:53:47.553Z","event_type":"best_bid_ask","market_id":"3790394","outcome_index":0,"market_type":"set1","local_side":"home","local_uid":"2026-08-23_hugo_grenier_mees_rottgering","bid":0.25,"ask":0.34,"mid":0.295,"spread":0.09,"bid_size":null,"ask_size":null}
{"ts":"2026-08-23T17:53:47.553Z","event_type":"best_bid_ask","market_id":"3790394","outcome_index":1,"market_type":"set1","local_side":"away","local_uid":"2026-08-23_hugo_grenier_mees_rottgering","bid":0.66,"ask":0.75,"mid":0.705,"spread":0.09,"bid_size":null,"ask_size":null}
{"ts":"2026-08-23T17:53:47.553Z","event_type":"price_change","market_id":"3790394","outcome_index":1,"market_type":"set1","local_side":"away","local_uid":"2026-08-23_hugo_grenier_mees_rottgering","bid":0.66,"ask":0.75,"mid":0.705,"spread":0.09,"price":0.66,"size":150.0,"side":"BUY"}
{"ts":"2026-08-23T17:53:47.553Z","event_type":"price_change","market_id":"3790394","outcome_index":0,"market_type":"set1","local_side":"home","local_uid":"2026-08-23_hugo_grenier_mees_rottgering","bid":0.25,"ask":0.34,"mid":0.295,"spread":0.09,"price":0.34,"size":150.0,"side":"SELL"}
{"ts":"2026-08-23T17:53:47.553Z","event_type":"best_bid_ask","market_id":"3790397","outcome_index":0,"market_type":"set2","local_side":"home","local_uid":"2026-08-23_hugo_grenier_mees_rottgering","bid":0.31,"ask":0.41,"mid":0.36,"spread":0.1,"bid_size":null,"ask_size":null}
{"ts":"2026-08-23T17:53:47.553Z","event_type":"best_bid_ask","market_id":"3790397","outcome_index":1,"market_type":"set2","local_side":"away","local_uid":"2026-08-23_hugo_grenier_mees_rottgering","bid":0.59,"ask":0.69,"mid":0.64,"spread":0.1,"bid_size":null,"ask_size":null}
{"ts":"2026-08-23T17:53:47.553Z","event_type":"price_change","market_id":"3790397","outcome_index":1,"market_type":"set2","local_side":"away","local_uid":"2026-08-23_hugo_grenier_mees_rottgering","bid":0.59,"ask":0.69,"mid":0.64,"spread":0.1,"price":0.59,"size":150.0,"side":"BUY"}
{"ts":"2026-08-23T17:53:47.554Z","event_type":"price_change","market_id":"3790397","outcome_index":0,"market_type":"set2","local_side":"home","local_uid":"2026-08-23_hugo_grenier_mees_rottgering","bid":0.31,"ask":0.41,"mid":0.36,"spread":0.1,"price":0.41,"size":150.0,"side":"SELL"}
{"ts":"2026-08-23T17:53:47.718Z","event_type":"best_bid_ask","market_id":"3790397","outcome_index":0,"market_type":"set2","local_side":"home","local_uid":"2026-08-23_hugo_grenier_mees_rottgering","bid":0.31,"ask":0.4,"mid":0.355,"spread":0.09,"bid_size":null,"ask_size":null}
{"ts":"2026-08-23T17:53:47.719Z","event_type":"best_bid_ask","market_id":"3790397","outcome_index":1,"market_type":"set2","local_side":"away","local_uid":"2026-08-23_hugo_grenier_mees_rottgering","bid":0.6,"ask":0.69,"mid":0.645,"spread":0.09,"bid_size":null,"ask_size":null}
{"ts":"2026-08-23T17:53:47.719Z","event_type":"price_change","market_id":"3790397","outcome_index":1,"market_type":"set2","local_side":"away","local_uid":"2026-08-23_hugo_grenier_mees_rottgering","bid":0.6,"ask":0.69,"mid":0.645,"spread":0.09,"price":0.6,"size":31.98,"side":"BUY"}
{"ts":"2026-08-23T17:53:47.719Z","event_type":"price_change","market_id":"3790397","outcome_index":0,"market_type":"set2","local_side":"home","local_uid":"2026-08-23_hugo_grenier_mees_rottgering","bid":0.31,"ask":0.4,"mid":0.355,"spread":0.09,"price":0.4,"size":31.98,"side":"SELL"}
{"ts":"2026-08-23T17:53:47.977Z","event_type":"best_bid_ask","market_id":"3789927","outcome_index":0,"market_type":"match","local_side":"home","local_uid":"2026-08-23_hugo_grenier_mees_rottgering","bid":0.27,"ask":0.29,"mid":0.28,"spread":0.02,"bid_size":null,"ask_size":null}
{"ts":"2026-08-23T17:53:47.977Z","event_type":"best_bid_ask","market_id":"3789927","outcome_index":1,"market_type":"match","local_side":"away","local_uid":"2026-08-23_hugo_grenier_mees_rottgering","bid":0.71,"ask":0.73,"mid":0.72,"spread":0.02,"bid_size":null,"ask_size":null}
{"ts":"2026-08-23T17:53:47.977Z","event_type":"price_change","market_id":"3789927","outcome_index":0,"market_type":"match","local_side":"home","local_uid":"2026-08-23_hugo_grenier_mees_rottgering","bid":0.27,"ask":0.29,"mid":0.28,"spread":0.02,"price":0.28,"size":0.0,"side":"BUY"}
{"ts":"2026-08-23T17:53:47.977Z","event_type":"price_change","market_id":"3789927","outcome_index":1,"market_type":"match","local_side":"away","local_uid":"2026-08-23_hugo_grenier_mees_rottgering","bid":0.71,"ask":0.73,"mid":0.72,"spread":0.02,"price":0.72,"size":0.0,"side":"SELL"}
{"ts":"2026-08-23T17:53:48.009Z","event_type":"best_bid_ask","market_id":"3789927","outcome_index":0,"market_type":"match","local_side":"home","local_uid":"2026-08-23_hugo_grenier_mees_rottgering","bid":0.27,"ask":0.28,"mid":0.275,"spread":0.01,"bid_size":null,"ask_size":null}
{"ts":"2026-08-23T17:53:48.009Z","event_type":"best_bid_ask","market_id":"3789927","outcome_index":1,"market_type":"match","local_side":"away","local_uid":"2026-08-23_hugo_grenier_mees_rottgering","bid":0.72,"ask":0.73,"mid":0.725,"spread":0.01,"bid_size":null,"ask_size":null}
{"ts":"2026-08-23T17:53:48.009Z","event_type":"price_change","market_id":"3789927","outcome_index":1,"market_type":"match","local_side":"away","local_uid":"2026-08-23_hugo_grenier_mees_rottgering","bid":0.72,"ask":0.73,"mid":0.725,"spread":0.01,"price":0.72,"size":544.09,"side":"BUY"}
{"ts":"2026-08-23T17:53:48.009Z","event_type":"price_change","market_id":"3789927","outcome_index":0,"market_type":"match","local_side":"home","local_uid":"2026-08-23_hugo_grenier_mees_rottgering","bid":0.27,"ask":0.28,"mid":0.275,"spread":0.01,"price":0.28,"size":544.09,"side":"SELL"}
{"ts":"2026-08-23T17:53:48.070Z","event_type":"price_change","market_id":"3792971","outcome_index":1,"market_type":"match","local_side":"away","local_uid":"2026-08-23_maria_timofeeva_kamilla_rakhimova","bid":0.6,"ask":0.61,"mid":0.605,"spread":0.01,"price":0.49,"size":4460.09,"side":"BUY"}
{"ts":"2026-08-23T17:53:48.071Z","event_type":"price_change","market_id":"3792971","outcome_index":0,"market_type":"match","local_side":"home","local_uid":"2026-08-23_maria_timofeeva_kamilla_rakhimova","bid":0.39,"ask":0.4,"mid":0.395,"spread":0.01,"price":0.51,"size":4460.09,"side":"SELL"}
{"ts":"2026-08-23T17:53:48.171Z","event_type":"price_change","market_id":"3792999","outcome_index":0,"market_type":"match","local_side":"home","local_uid":"2026-08-24_antonia_ruzic_nikola_bartunkova","bid":0.3,"ask":0.31,"mid":0.305,"spread":0.01,"price":0.26,"size":277.98,"side":"BUY"}
{"ts":"2026-08-23T17:53:48.171Z","event_type":"price_change","market_id":"3792999","outcome_index":1,"market_type":"match","local_side":"away","local_uid":"2026-08-24_antonia_ruzic_nikola_bartunkova","bid":0.69,"ask":0.7,"mid":0.695,"spread":0.01,"price":0.74,"size":277.98,"side":"SELL"}
{"ts":"2026-08-23T17:53:48.225Z","event_type":"price_change","market_id":"3795950","outcome_index":1,"market_type":"match","local_side":"away","local_uid":"2026-08-24_sebastian_baez_hubert_hurkacz","bid":0.68,"ask":0.69,"mid":0.685,"spread":0.01,"price":0.34,"size":336.16,"side":"BUY"}
{"ts":"2026-08-23T17:53:48.225Z","event_type":"price_change","market_id":"3795950","outcome_index":0,"market_type":"match","local_side":"home","local_uid":"2026-08-24_sebastian_baez_hubert_hurkacz","bid":0.31,"ask":0.32,"mid":0.315,"spread":0.01,"price":0.66,"size":336.16,"side":"SELL"}
{"ts":"2026-08-23T17:53:48.275Z","event_type":"best_bid_ask","market_id":"3790415","outcome_index":0,"market_type":"set2","local_side":"home","local_uid":"2026-08-23_pierre_hugues_herbert_quinn_vandecasteele","bid":0.59,"ask":0.71,"mid":0.65,"spread":0.12,"bid_size":null,"ask_size":null}
{"ts":"2026-08-23T17:53:48.275Z","event_type":"best_bid_ask","market_id":"3790415","outcome_index":1,"market_type":"set2","local_side":"away","local_uid":"2026-08-23_pierre_hugues_herbert_quinn_vandecasteele","bid":0.29,"ask":0.41,"mid":0.35,"spread":0.12,"bid_size":null,"ask_size":null}
{"ts":"2026-08-23T17:53:48.276Z","event_type":"price_change","market_id":"3790415","outcome_index":1,"market_type":"set2","local_side":"away","local_uid":"2026-08-23_pierre_hugues_herbert_quinn_vandecasteele","bid":0.29,"ask":0.41,"mid":0.35,"spread":0.12,"price":0.29,"size":423.0,"side":"BUY"}
{"ts":"2026-08-23T17:53:48.276Z","event_type":"price_change","market_id":"3790415","outcome_index":0,"market_type":"set2","local_side":"home","local_uid":"2026-08-23_pierre_hugues_herbert_quinn_vandecasteele","bid":0.59,"ask":0.71,"mid":0.65,"spread":0.12,"price":0.71,"size":423.0,"side":"SELL"}
{"ts":"2026-08-23T17:53:48.283Z","event_type":"best_bid_ask","market_id":"3790415","outcome_index":0,"market_type":"set2","local_side":"home","local_uid":"2026-08-23_pierre_hugues_herbert_quinn_vandecasteele","bid":0.59,"ask":0.7,"mid":0.645,"spread":0.11,"bid_size":null,"ask_size":null}
{"ts":"2026-08-23T17:53:48.288Z","event_type":"best_bid_ask","market_id":"3790415","outcome_index":1,"market_type":"set2","local_side":"away","local_uid":"2026-08-23_pierre_hugues_herbert_quinn_vandecasteele","bid":0.3,"ask":0.41,"mid":0.355,"spread":0.11,"bid_size":null,"ask_size":null}
{"ts":"2026-08-23T17:53:48.288Z","event_type":"price_change","market_id":"3790415","outcome_index":1,"market_type":"set2","local_side":"away","local_uid":"2026-08-23_pierre_hugues_herbert_quinn_vandecasteele","bid":0.3,"ask":0.41,"mid":0.355,"spread":0.11,"price":0.3,"size":88.0,"side":"BUY"}
{"ts":"2026-08-23T17:53:48.289Z","event_type":"price_change","market_id":"3790415","outcome_index":0,"market_type":"set2","local_side":"home","local_uid":"2026-08-23_pierre_hugues_herbert_quinn_vandecasteele","bid":0.59,"ask":0.7,"mid":0.645,"spread":0.11,"price":0.7,"size":88.0,"side":"SELL"}
{"ts":"2026-08-23T17:53:48.300Z","event_type":"best_bid_ask","market_id":"3789925","outcome_index":0,"market_type":"match","local_side":"home","local_uid":"2026-08-23_pierre_hugues_herbert_quinn_vandecasteele","bid":0.81,"ask":0.82,"mid":0.815,"spread":0.01,"bid_size":null,"ask_size":null}
{"ts":"2026-08-23T17:53:48.300Z","event_type":"best_bid_ask","market_id":"3789925","outcome_index":1,"market_type":"match","local_side":"away","local_uid":"2026-08-23_pierre_hugues_herbert_quinn_vandecasteele","bid":0.18,"ask":0.19,"mid":0.185,"spread":0.01,"bid_size":null,"ask_size":null}
{"ts":"2026-08-23T17:53:48.300Z","event_type":"price_change","market_id":"3789925","outcome_index":1,"market_type":"match","local_side":"away","local_uid":"2026-08-23_pierre_hugues_herbert_quinn_vandecasteele","bid":0.18,"ask":0.19,"mid":0.185,"spread":0.01,"price":0.18,"size":11687.69,"side":"BUY"}
{"ts":"2026-08-23T17:53:48.300Z","event_type":"price_change","market_id":"3789925","outcome_index":0,"market_type":"match","local_side":"home","local_uid":"2026-08-23_pierre_hugues_herbert_quinn_vandecasteele","bid":0.81,"ask":0.82,"mid":0.815,"spread":0.01,"price":0.82,"size":11687.69,"side":"SELL"}
{"ts":"2026-08-23T17:53:48.302Z","event_type":"best_bid_ask","market_id":"3790415","outcome_index":0,"market_type":"set2","local_side":"home","local_uid":"2026-08-23_pierre_hugues_herbert_quinn_vandecasteele","bid":0.58,"ask":0.7,"mid":0.64,"spread":0.12,"bid_size":null,"ask_size":null}
{"ts":"2026-08-23T17:53:48.302Z","event_type":"best_bid_ask","market_id":"3790415","outcome_index":1,"market_type":"set2","local_side":"away","local_uid":"2026-08-23_pierre_hugues_herbert_quinn_vandecasteele","bid":0.3,"ask":0.42,"mid":0.36,"spread":0.12,"bid_size":null,"ask_size":null}
{"ts":"2026-08-23T17:53:48.302Z","event_type":"price_change","market_id":"3790415","outcome_index":0,"market_type":"set2","local_side":"home","local_uid":"2026-08-23_pierre_hugues_herbert_quinn_vandecasteele","bid":0.58,"ask":0.7,"mid":0.64,"spread":0.12,"price":0.59,"size":0.0,"side":"BUY"}
{"ts":"2026-08-23T17:53:48.302Z","event_type":"price_change","market_id":"3790415","outcome_index":1,"market_type":"set2","local_side":"away","local_uid":"2026-08-23_pierre_hugues_herbert_quinn_vandecasteele","bid":0.3,"ask":0.42,"mid":0.36,"spread":0.12,"price":0.41,"size":0.0,"side":"SELL"}
{"ts":"2026-08-23T17:53:48.306Z","event_type":"best_bid_ask","market_id":"3790415","outcome_index":0,"market_type":"set2","local_side":"home","local_uid":"2026-08-23_pierre_hugues_herbert_quinn_vandecasteele","bid":0.56,"ask":0.7,"mid":0.63,"spread":0.14,"bid_size":null,"ask_size":null}
{"ts":"2026-08-23T17:53:48.306Z","event_type":"best_bid_ask","market_id":"3790415","outcome_index":1,"market_type":"set2","local_side":"away","local_uid":"2026-08-23_pierre_hugues_herbert_quinn_vandecasteele","bid":0.3,"ask":0.44,"mid":0.37,"spread":0.14,"bid_size":null,"ask_size":null}
{"ts":"2026-08-23T17:53:48.306Z","event_type":"price_change","market_id":"3790415","outcome_index":0,"market_type":"set2","local_side":"home","local_uid":"2026-08-23_pierre_hugues_herbert_quinn_vandecasteele","bid":0.56,"ask":0.7,"mid":0.63,"spread":0.14,"price":0.58,"size":0.0,"side":"BUY"}
{"ts":"2026-08-23T17:53:48.306Z","event_type":"price_change","market_id":"3790415","outcome_index":1,"market_type":"set2","local_side":"away","local_uid":"2026-08-23_pierre_hugues_herbert_quinn_vandecasteele","bid":0.3,"ask":0.44,"mid":0.37,"spread":0.14,"price":0.42,"size":0.0,"side":"SELL"}
{"ts":"2026-08-23T17:53:48.369Z","event_type":"best_bid_ask","market_id":"3790415","outcome_index":0,"market_type":"set2","local_side":"home","local_uid":"2026-08-23_pierre_hugues_herbert_quinn_vandecasteele","bid":0.56,"ask":0.68,"mid":0.62,"spread":0.12,"bid_size":null,"ask_size":null}
{"ts":"2026-08-23T17:53:48.370Z","event_type":"best_bid_ask","market_id":"3790415","outcome_index":1,"market_type":"set2","local_side":"away","local_uid":"2026-08-23_pierre_hugues_herbert_quinn_vandecasteele","bid":0.32,"ask":0.44,"mid":0.38,"spread":0.12,"bid_size":null,"ask_size":null}
{"ts":"2026-08-23T17:53:48.370Z","event_type":"price_change","market_id":"3790415","outcome_index":1,"market_type":"set2","local_side":"away","local_uid":"2026-08-23_pierre_hugues_herbert_quinn_vandecasteele","bid":0.32,"ask":0.44,"mid":0.38,"spread":0.12,"price":0.32,"size":150.0,"side":"BUY"}
{"ts":"2026-08-23T17:53:48.370Z","event_type":"price_change","market_id":"3790415","outcome_index":0,"market_type":"set2","local_side":"home","local_uid":"2026-08-23_pierre_hugues_herbert_quinn_vandecasteele","bid":0.56,"ask":0.68,"mid":0.62,"spread":0.12,"price":0.68,"size":150.0,"side":"SELL"}
{"ts":"2026-08-23T17:53:48.835Z","event_type":"best_bid_ask","market_id":"3790394","outcome_index":0,"market_type":"set1","local_side":"home","local_uid":"2026-08-23_hugo_grenier_mees_rottgering","bid":0.27,"ask":0.34,"mid":0.305,"spread":0.07,"bid_size":null,"ask_size":null}
{"ts":"2026-08-23T17:53:48.835Z","event_type":"best_bid_ask","market_id":"3790394","outcome_index":1,"market_type":"set1","local_side":"away","local_uid":"2026-08-23_hugo_grenier_mees_rottgering","bid":0.66,"ask":0.73,"mid":0.695,"spread":0.07,"bid_size":null,"ask_size":null}
{"ts":"2026-08-23T17:53:48.836Z","event_type":"price_change","market_id":"3790394","outcome_index":0,"market_type":"set1","local_side":"home","local_uid":"2026-08-23_hugo_grenier_mees_rottgering","bid":0.27,"ask":0.34,"mid":0.305,"spread":0.07,"price":0.27,"size":201.79,"side":"BUY"}
{"ts":"2026-08-23T17:53:48.836Z","event_type":"price_change","market_id":"3790394","outcome_index":1,"market_type":"set1","local_side":"away","local_uid":"2026-08-23_hugo_grenier_mees_rottgering","bid":0.66,"ask":0.73,"mid":0.695,"spread":0.07,"price":0.73,"size":201.79,"side":"SELL"}
{"ts":"2026-08-23T17:53:49.047Z","event_type":"best_bid_ask","market_id":"3795958","outcome_index":0,"market_type":"match","local_side":"home","local_uid":"2026-08-23_bruno_kuzuhara_kody_pearson","bid":0.944,"ask":0.96,"mid":0.952,"spread":0.016,"bid_size":null,"ask_size":null}
{"ts":"2026-08-23T17:53:49.048Z","event_type":"best_bid_ask","market_id":"3795958","outcome_index":1,"market_type":"match","local_side":"away","local_uid":"2026-08-23_bruno_kuzuhara_kody_pearson","bid":0.04,"ask":0.056,"mid":0.048,"spread":0.016,"bid_size":null,"ask_size":null}
{"ts":"2026-08-23T17:53:49.048Z","event_type":"price_change","market_id":"3795958","outcome_index":1,"market_type":"match","local_side":"away","local_uid":"2026-08-23_bruno_kuzuhara_kody_pearson","bid":0.04,"ask":0.056,"mid":0.048,"spread":0.016,"price":0.04,"size":32.54,"side":"BUY"}
{"ts":"2026-08-23T17:53:49.048Z","event_type":"price_change","market_id":"3795958","outcome_index":0,"market_type":"match","local_side":"home","local_uid":"2026-08-23_bruno_kuzuhara_kody_pearson","bid":0.944,"ask":0.96,"mid":0.952,"spread":0.016,"price":0.96,"size":32.54,"side":"SELL"}
{"ts":"2026-08-23T17:53:49.222Z","event_type":"best_bid_ask","market_id":"3790397","outcome_index":0,"market_type":"set2","local_side":"home","local_uid":"2026-08-23_hugo_grenier_mees_rottgering","bid":0.29,"ask":0.4,"mid":0.345,"spread":0.11,"bid_size":null,"ask_size":null}
{"ts":"2026-08-23T17:53:49.226Z","event_type":"best_bid_ask","market_id":"3790397","outcome_index":1,"market_type":"set2","local_side":"away","local_uid":"2026-08-23_hugo_grenier_mees_rottgering","bid":0.6,"ask":0.71,"mid":0.655,"spread":0.11,"bid_size":null,"ask_size":null}
{"ts":"2026-08-23T17:53:49.226Z","event_type":"price_change","market_id":"3790397","outcome_index":0,"market_type":"set2","local_side":"home","local_uid":"2026-08-23_hugo_grenier_mees_rottgering","bid":0.29,"ask":0.4,"mid":0.345,"spread":0.11,"price":0.31,"size":0.0,"side":"BUY"}
{"ts":"2026-08-23T17:53:49.226Z","event_type":"price_change","market_id":"3790397","outcome_index":1,"market_type":"set2","local_side":"away","local_uid":"2026-08-23_hugo_grenier_mees_rottgering","bid":0.6,"ask":0.71,"mid":0.655,"spread":0.11,"price":0.69,"size":0.0,"side":"SELL"}
{"ts":"2026-08-23T17:53:49.251Z","event_type":"best_bid_ask","market_id":"3790397","outcome_index":0,"market_type":"set2","local_side":"home","local_uid":"2026-08-23_hugo_grenier_mees_rottgering","bid":0.31,"ask":0.4,"mid":0.355,"spread":0.09,"bid_size":null,"ask_size":null}
{"ts":"2026-08-23T17:53:49.251Z","event_type":"best_bid_ask","market_id":"3790397","outcome_index":1,"market_type":"set2","local_side":"away","local_uid":"2026-08-23_hugo_grenier_mees_rottgering","bid":0.6,"ask":0.69,"mid":0.645,"spread":0.09,"bid_size":null,"ask_size":null}
{"ts":"2026-08-23T17:53:49.251Z","event_type":"price_change","market_id":"3790397","outcome_index":0,"market_type":"set2","local_side":"home","local_uid":"2026-08-23_hugo_grenier_mees_rottgering","bid":0.31,"ask":0.4,"mid":0.355,"spread":0.09,"price":0.31,"size":150.0,"side":"BUY"}
{"ts":"2026-08-23T17:53:49.251Z","event_type":"price_change","market_id":"3790397","outcome_index":1,"market_type":"set2","local_side":"away","local_uid":"2026-08-23_hugo_grenier_mees_rottgering","bid":0.6,"ask":0.69,"mid":0.645,"spread":0.09,"price":0.69,"size":150.0,"side":"SELL"}
{"ts":"2026-08-23T17:53:50.168Z","event_type":"new_market","market_id":"0x9c543a85ae718e058fe4e2516a61283695f956e357596be430aa4e03c4ce9645"}
{"ts":"2026-08-23T17:53:50.352Z","event_type":"best_bid_ask","market_id":"3790415","outcome_index":0,"market_type":"set2","local_side":"home","local_uid":"2026-08-23_pierre_hugues_herbert_quinn_vandecasteele","bid":0.56,"ask":0.67,"mid":0.615,"spread":0.11,"bid_size":null,"ask_size":null}
{"ts":"2026-08-23T17:53:50.352Z","event_type":"best_bid_ask","market_id":"3790415","outcome_index":1,"market_type":"set2","local_side":"away","local_uid":"2026-08-23_pierre_hugues_herbert_quinn_vandecasteele","bid":0.33,"ask":0.44,"mid":0.385,"spread":0.11,"bid_size":null,"ask_size":null}
{"ts":"2026-08-23T17:53:50.353Z","event_type":"price_change","market_id":"3790415","outcome_index":1,"market_type":"set2","local_side":"away","local_uid":"2026-08-23_pierre_hugues_herbert_quinn_vandecasteele","bid":0.33,"ask":0.44,"mid":0.385,"spread":0.11,"price":0.33,"size":150.0,"side":"BUY"}
{"ts":"2026-08-23T17:53:50.353Z","event_type":"price_change","market_id":"3790415","outcome_index":0,"market_type":"set2","local_side":"home","local_uid":"2026-08-23_pierre_hugues_herbert_quinn_vandecasteele","bid":0.56,"ask":0.67,"mid":0.615,"spread":0.11,"price":0.67,"size":150.0,"side":"SELL"}
{"ts":"2026-08-23T17:53:50.374Z","event_type":"best_bid_ask","market_id":"3790394","outcome_index":0,"market_type":"set1","local_side":"home","local_uid":"2026-08-23_hugo_grenier_mees_rottgering","bid":0.27,"ask":0.33,"mid":0.3,"spread":0.06,"bid_size":null,"ask_size":null}
{"ts":"2026-08-23T17:53:50.374Z","event_type":"best_bid_ask","market_id":"3790394","outcome_index":1,"market_type":"set1","local_side":"away","local_uid":"2026-08-23_hugo_grenier_mees_rottgering","bid":0.67,"ask":0.73,"mid":0.7,"spread":0.06,"bid_size":null,"ask_size":null}
{"ts":"2026-08-23T17:53:50.374Z","event_type":"price_change","market_id":"3790394","outcome_index":1,"market_type":"set1","local_side":"away","local_uid":"2026-08-23_hugo_grenier_mees_rottgering","bid":0.67,"ask":0.73,"mid":0.7,"spread":0.06,"price":0.67,"size":150.0,"side":"BUY"}
{"ts":"2026-08-23T17:53:50.374Z","event_type":"price_change","market_id":"3790394","outcome_index":0,"market_type":"set1","local_side":"home","local_uid":"2026-08-23_hugo_grenier_mees_rottgering","bid":0.27,"ask":0.33,"mid":0.3,"spread":0.06,"price":0.33,"size":150.0,"side":"SELL"}
{"ts":"2026-08-23T17:53:51.444Z","event_type":"best_bid_ask","market_id":"3790394","outcome_index":0,"market_type":"set1","local_side":"home","local_uid":"2026-08-23_hugo_grenier_mees_rottgering","bid":0.24,"ask":0.33,"mid":0.285,"spread":0.09,"bid_size":null,"ask_size":null}
{"ts":"2026-08-23T17:53:51.444Z","event_type":"best_bid_ask","market_id":"3790394","outcome_index":1,"market_type":"set1","local_side":"away","local_uid":"2026-08-23_hugo_grenier_mees_rottgering","bid":0.67,"ask":0.76,"mid":0.715,"spread":0.09,"bid_size":null,"ask_size":null}
{"ts":"2026-08-23T17:53:51.444Z","event_type":"price_change","market_id":"3790394","outcome_index":0,"market_type":"set1","local_side":"home","local_uid":"2026-08-23_hugo_grenier_mees_rottgering","bid":0.24,"ask":0.33,"mid":0.285,"spread":0.09,"price":0.27,"size":0.0,"side":"BUY"}
{"ts":"2026-08-23T17:53:51.444Z","event_type":"price_change","market_id":"3790394","outcome_index":1,"market_type":"set1","local_side":"away","local_uid":"2026-08-23_hugo_grenier_mees_rottgering","bid":0.67,"ask":0.76,"mid":0.715,"spread":0.09,"price":0.73,"size":0.0,"side":"SELL"}
{"ts":"2026-08-23T17:53:52.712Z","event_type":"best_bid_ask","market_id":"3790394","outcome_index":0,"market_type":"set1","local_side":"home","local_uid":"2026-08-23_hugo_grenier_mees_rottgering","bid":0.25,"ask":0.33,"mid":0.29,"spread":0.08,"bid_size":null,"ask_size":null}
{"ts":"2026-08-23T17:53:52.712Z","event_type":"best_bid_ask","market_id":"3790394","outcome_index":1,"market_type":"set1","local_side":"away","local_uid":"2026-08-23_hugo_grenier_mees_rottgering","bid":0.67,"ask":0.75,"mid":0.71,"spread":0.08,"bid_size":null,"ask_size":null}
{"ts":"2026-08-23T17:53:52.712Z","event_type":"price_change","market_id":"3790394","outcome_index":0,"market_type":"set1","local_side":"home","local_uid":"2026-08-23_hugo_grenier_mees_rottgering","bid":0.25,"ask":0.33,"mid":0.29,"spread":0.08,"price":0.25,"size":150.0,"side":"BUY"}
{"ts":"2026-08-23T17:53:52.712Z","event_type":"price_change","market_id":"3790394","outcome_index":1,"market_type":"set1","local_side":"away","local_uid":"2026-08-23_hugo_grenier_mees_rottgering","bid":0.67,"ask":0.75,"mid":0.71,"spread":0.08,"price":0.75,"size":150.0,"side":"SELL"}
{"ts":"2026-08-23T17:53:52.981Z","event_type":"best_bid_ask","market_id":"3790394","outcome_index":0,"market_type":"set1","local_side":"home","local_uid":"2026-08-23_hugo_grenier_mees_rottgering","bid":0.26,"ask":0.33,"mid":0.295,"spread":0.07,"bid_size":null,"ask_size":null}
{"ts":"2026-08-23T17:53:52.981Z","event_type":"best_bid_ask","market_id":"3790394","outcome_index":1,"market_type":"set1","local_side":"away","local_uid":"2026-08-23_hugo_grenier_mees_rottgering","bid":0.67,"ask":0.74,"mid":0.705,"spread":0.07,"bid_size":null,"ask_size":null}
{"ts":"2026-08-23T17:53:52.981Z","event_type":"price_change","market_id":"3790394","outcome_index":0,"market_type":"set1","local_side":"home","local_uid":"2026-08-23_hugo_grenier_mees_rottgering","bid":0.26,"ask":0.33,"mid":0.295,"spread":0.07,"price":0.26,"size":150.0,"side":"BUY"}
{"ts":"2026-08-23T17:53:52.981Z","event_type":"price_change","market_id":"3790394","outcome_index":1,"market_type":"set1","local_side":"away","local_uid":"2026-08-23_hugo_grenier_mees_rottgering","bid":0.67,"ask":0.74,"mid":0.705,"spread":0.07,"price":0.74,"size":150.0,"side":"SELL"}
{"ts":"2026-08-23T17:53:53.007Z","event_type":"best_bid_ask","market_id":"3790397","outcome_index":0,"market_type":"set2","local_side":"home","local_uid":"2026-08-23_hugo_grenier_mees_rottgering","bid":0.31,"ask":0.41,"mid":0.36,"spread":0.1,"bid_size":null,"ask_size":null}
{"ts":"2026-08-23T17:53:53.007Z","event_type":"best_bid_ask","market_id":"3790397","outcome_index":1,"market_type":"set2","local_side":"away","local_uid":"2026-08-23_hugo_grenier_mees_rottgering","bid":0.59,"ask":0.69,"mid":0.64,"spread":0.1,"bid_size":null,"ask_size":null}
{"ts":"2026-08-23T17:53:53.007Z","event_type":"price_change","market_id":"3790397","outcome_index":1,"market_type":"set2","local_side":"away","local_uid":"2026-08-23_hugo_grenier_mees_rottgering","bid":0.59,"ask":0.69,"mid":0.64,"spread":0.1,"price":0.6,"size":0.0,"side":"BUY"}
{"ts":"2026-08-23T17:53:53.008Z","event_type":"price_change","market_id":"3790397","outcome_index":0,"market_type":"set2","local_side":"home","local_uid":"2026-08-23_hugo_grenier_mees_rottgering","bid":0.31,"ask":0.41,"mid":0.36,"spread":0.1,"price":0.4,"size":0.0,"side":"SELL"}
{"ts":"2026-08-23T17:53:53.049Z","event_type":"best_bid_ask","market_id":"3790397","outcome_index":0,"market_type":"set2","local_side":"home","local_uid":"2026-08-23_hugo_grenier_mees_rottgering","bid":0.31,"ask":0.4,"mid":0.355,"spread":0.09,"bid_size":null,"ask_size":null}
{"ts":"2026-08-23T17:53:53.049Z","event_type":"best_bid_ask","market_id":"3790397","outcome_index":1,"market_type":"set2","local_side":"away","local_uid":"2026-08-23_hugo_grenier_mees_rottgering","bid":0.6,"ask":0.69,"mid":0.645,"spread":0.09,"bid_size":null,"ask_size":null}
{"ts":"2026-08-23T17:53:53.050Z","event_type":"price_change","market_id":"3790397","outcome_index":1,"market_type":"set2","local_side":"away","local_uid":"2026-08-23_hugo_grenier_mees_rottgering","bid":0.6,"ask":0.69,"mid":0.645,"spread":0.09,"price":0.6,"size":150.0,"side":"BUY"}
{"ts":"2026-08-23T17:53:53.050Z","event_type":"price_change","market_id":"3790397","outcome_index":0,"market_type":"set2","local_side":"home","local_uid":"2026-08-23_hugo_grenier_mees_rottgering","bid":0.31,"ask":0.4,"mid":0.355,"spread":0.09,"price":0.4,"size":150.0,"side":"SELL"}
{"ts":"2026-08-23T17:53:53.209Z","event_type":"best_bid_ask","market_id":"3790397","outcome_index":0,"market_type":"set2","local_side":"home","local_uid":"2026-08-23_hugo_grenier_mees_rottgering","bid":0.31,"ask":0.39,"mid":0.35,"spread":0.08,"bid_size":null,"ask_size":null}
{"ts":"2026-08-23T17:53:53.210Z","event_type":"best_bid_ask","market_id":"3790397","outcome_index":1,"market_type":"set2","local_side":"away","local_uid":"2026-08-23_hugo_grenier_mees_rottgering","bid":0.61,"ask":0.69,"mid":0.65,"spread":0.08,"bid_size":null,"ask_size":null}
{"ts":"2026-08-23T17:53:53.210Z","event_type":"price_change","market_id":"3790397","outcome_index":1,"market_type":"set2","local_side":"away","local_uid":"2026-08-23_hugo_grenier_mees_rottgering","bid":0.61,"ask":0.69,"mid":0.65,"spread":0.08,"price":0.61,"size":150.0,"side":"BUY"}
{"ts":"2026-08-23T17:53:53.210Z","event_type":"price_change","market_id":"3790397","outcome_index":0,"market_type":"set2","local_side":"home","local_uid":"2026-08-23_hugo_grenier_mees_rottgering","bid":0.31,"ask":0.39,"mid":0.35,"spread":0.08,"price":0.39,"size":150.0,"side":"SELL"}
{"ts":"2026-08-23T17:53:54.310Z","event_type":"price_change","market_id":"3789931","outcome_index":0,"market_type":"match","local_side":"home","local_uid":"2026-08-23_stefanos_sakellaridis_luca_van_assche","bid":0.04,"ask":0.05,"mid":0.045,"spread":0.01,"price":0.03,"size":23392.14,"side":"BUY"}
{"ts":"2026-08-23T17:53:54.311Z","event_type":"price_change","market_id":"3789931","outcome_index":1,"market_type":"match","local_side":"away","local_uid":"2026-08-23_stefanos_sakellaridis_luca_van_assche","bid":0.95,"ask":0.96,"mid":0.955,"spread":0.01,"price":0.97,"size":23392.14,"side":"SELL"}
{"ts":"2026-08-23T17:53:54.630Z","event_type":"price_change","market_id":"3793888","outcome_index":0,"market_type":"set1","local_side":"home","local_uid":"2026-08-23_anna_bondar_en_shuo_liang","bid":0.69,"ask":0.72,"mid":0.705,"spread":0.03,"price":0.65,"size":181.0,"side":"BUY"}
{"ts":"2026-08-23T17:53:54.631Z","event_type":"price_change","market_id":"3793888","outcome_index":1,"market_type":"set1","local_side":"away","local_uid":"2026-08-23_anna_bondar_en_shuo_liang","bid":0.28,"ask":0.31,"mid":0.295,"spread":0.03,"price":0.35,"size":181.0,"side":"SELL"}
{"ts":"2026-08-23T17:53:54.631Z","event_type":"best_bid_ask","market_id":"3790415","outcome_index":0,"market_type":"set2","local_side":"home","local_uid":"2026-08-23_pierre_hugues_herbert_quinn_vandecasteele","bid":0.57,"ask":0.67,"mid":0.62,"spread":0.1,"bid_size":null,"ask_size":null}
{"ts":"2026-08-23T17:53:54.631Z","event_type":"best_bid_ask","market_id":"3790415","outcome_index":1,"market_type":"set2","local_side":"away","local_uid":"2026-08-23_pierre_hugues_herbert_quinn_vandecasteele","bid":0.33,"ask":0.43,"mid":0.38,"spread":0.1,"bid_size":null,"ask_size":null}
{"ts":"2026-08-23T17:53:54.631Z","event_type":"price_change","market_id":"3790415","outcome_index":0,"market_type":"set2","local_side":"home","local_uid":"2026-08-23_pierre_hugues_herbert_quinn_vandecasteele","bid":0.57,"ask":0.67,"mid":0.62,"spread":0.1,"price":0.57,"size":150.0,"side":"BUY"}
{"ts":"2026-08-23T17:53:54.631Z","event_type":"price_change","market_id":"3790415","outcome_index":1,"market_type":"set2","local_side":"away","local_uid":"2026-08-23_pierre_hugues_herbert_quinn_vandecasteele","bid":0.33,"ask":0.43,"mid":0.38,"spread":0.1,"price":0.43,"size":150.0,"side":"SELL"}
{"ts":"2026-08-23T17:53:54.631Z","event_type":"best_bid_ask","market_id":"3790415","outcome_index":0,"market_type":"set2","local_side":"home","local_uid":"2026-08-23_pierre_hugues_herbert_quinn_vandecasteele","bid":0.57,"ask":0.66,"mid":0.615,"spread":0.09,"bid_size":null,"ask_size":null}
{"ts":"2026-08-23T17:53:54.631Z","event_type":"best_bid_ask","market_id":"3790415","outcome_index":1,"market_type":"set2","local_side":"away","local_uid":"2026-08-23_pierre_hugues_herbert_quinn_vandecasteele","bid":0.34,"ask":0.43,"mid":0.385,"spread":0.09,"bid_size":null,"ask_size":null}
{"ts":"2026-08-23T17:53:54.631Z","event_type":"price_change","market_id":"3790415","outcome_index":1,"market_type":"set2","local_side":"away","local_uid":"2026-08-23_pierre_hugues_herbert_quinn_vandecasteele","bid":0.34,"ask":0.43,"mid":0.385,"spread":0.09,"price":0.34,"size":150.0,"side":"BUY"}
{"ts":"2026-08-23T17:53:54.631Z","event_type":"price_change","market_id":"3790415","outcome_index":0,"market_type":"set2","local_side":"home","local_uid":"2026-08-23_pierre_hugues_herbert_quinn_vandecasteele","bid":0.57,"ask":0.66,"mid":0.615,"spread":0.09,"price":0.66,"size":150.0,"side":"SELL"}
{"ts":"2026-08-23T17:53:54.691Z","event_type":"price_change","market_id":"3795960","outcome_index":1,"market_type":"match","local_side":"away","local_uid":"2026-08-23_enmanuel_munoz_thomas_fancutt","bid":0.992,"ask":0.999,"mid":0.9955,"spread":0.007,"price":0.99,"size":2366.0,"side":"BUY"}
{"ts":"2026-08-23T17:53:54.691Z","event_type":"price_change","market_id":"3795960","outcome_index":0,"market_type":"match","local_side":"home","local_uid":"2026-08-23_enmanuel_munoz_thomas_fancutt","bid":0.001,"ask":0.008,"mid":0.0045,"spread":0.007,"price":0.01,"size":2366.0,"side":"SELL"}
{"ts":"2026-08-23T17:53:54.782Z","event_type":"best_bid_ask","market_id":"3790415","outcome_index":0,"market_type":"set2","local_side":"home","local_uid":"2026-08-23_pierre_hugues_herbert_quinn_vandecasteele","bid":0.58,"ask":0.66,"mid":0.62,"spread":0.08,"bid_size":null,"ask_size":null}
{"ts":"2026-08-23T17:53:54.783Z","event_type":"best_bid_ask","market_id":"3790415","outcome_index":1,"market_type":"set2","local_side":"away","local_uid":"2026-08-23_pierre_hugues_herbert_quinn_vandecasteele","bid":0.34,"ask":0.42,"mid":0.38,"spread":0.08,"bid_size":null,"ask_size":null}
{"ts":"2026-08-23T17:53:54.783Z","event_type":"price_change","market_id":"3790415","outcome_index":0,"market_type":"set2","local_side":"home","local_uid":"2026-08-23_pierre_hugues_herbert_quinn_vandecasteele","bid":0.58,"ask":0.66,"mid":0.62,"spread":0.08,"price":0.58,"size":150.0,"side":"BUY"}
{"ts":"2026-08-23T17:53:54.783Z","event_type":"price_change","market_id":"3790415","outcome_index":1,"market_type":"set2","local_side":"away","local_uid":"2026-08-23_pierre_hugues_herbert_quinn_vandecasteele","bid":0.34,"ask":0.42,"mid":0.38,"spread":0.08,"price":0.42,"size":150.0,"side":"SELL"}
{"ts":"2026-08-23T17:53:56.120Z","event_type":"best_bid_ask","market_id":"3790415","outcome_index":0,"market_type":"set2","local_side":"home","local_uid":"2026-08-23_pierre_hugues_herbert_quinn_vandecasteele","bid":0.57,"ask":0.66,"mid":0.615,"spread":0.09,"bid_size":null,"ask_size":null}
{"ts":"2026-08-23T17:53:56.120Z","event_type":"best_bid_ask","market_id":"3790415","outcome_index":1,"market_type":"set2","local_side":"away","local_uid":"2026-08-23_pierre_hugues_herbert_quinn_vandecasteele","bid":0.34,"ask":0.43,"mid":0.385,"spread":0.09,"bid_size":null,"ask_size":null}
{"ts":"2026-08-23T17:53:56.120Z","event_type":"price_change","market_id":"3790415","outcome_index":0,"market_type":"set2","local_side":"home","local_uid":"2026-08-23_pierre_hugues_herbert_quinn_vandecasteele","bid":0.57,"ask":0.66,"mid":0.615,"spread":0.09,"price":0.58,"size":0.0,"side":"BUY"}
{"ts":"2026-08-23T17:53:56.120Z","event_type":"price_change","market_id":"3790415","outcome_index":1,"market_type":"set2","local_side":"away","local_uid":"2026-08-23_pierre_hugues_herbert_quinn_vandecasteele","bid":0.34,"ask":0.43,"mid":0.385,"spread":0.09,"price":0.42,"size":0.0,"side":"SELL"}
{"ts":"2026-08-23T17:53:56.179Z","event_type":"new_market","market_id":"0xb69000dbfdba9414e16d1ca12cb35f2304c6402ef3dbee250c288b18d8bd26ed"}
{"ts":"2026-08-23T17:53:56.584Z","event_type":"best_bid_ask","market_id":"3790415","outcome_index":0,"market_type":"set2","local_side":"home","local_uid":"2026-08-23_pierre_hugues_herbert_quinn_vandecasteele","bid":0.56,"ask":0.66,"mid":0.61,"spread":0.1,"bid_size":null,"ask_size":null}
{"ts":"2026-08-23T17:53:56.584Z","event_type":"best_bid_ask","market_id":"3790415","outcome_index":1,"market_type":"set2","local_side":"away","local_uid":"2026-08-23_pierre_hugues_herbert_quinn_vandecasteele","bid":0.34,"ask":0.44,"mid":0.39,"spread":0.1,"bid_size":null,"ask_size":null}
{"ts":"2026-08-23T17:53:56.585Z","event_type":"price_change","market_id":"3790415","outcome_index":0,"market_type":"set2","local_side":"home","local_uid":"2026-08-23_pierre_hugues_herbert_quinn_vandecasteele","bid":0.56,"ask":0.66,"mid":0.61,"spread":0.1,"price":0.57,"size":0.0,"side":"BUY"}
{"ts":"2026-08-23T17:53:56.585Z","event_type":"price_change","market_id":"3790415","outcome_index":1,"market_type":"set2","local_side":"away","local_uid":"2026-08-23_pierre_hugues_herbert_quinn_vandecasteele","bid":0.34,"ask":0.44,"mid":0.39,"spread":0.1,"price":0.43,"size":0.0,"side":"SELL"}
{"ts":"2026-08-23T17:53:56.691Z","event_type":"best_bid_ask","market_id":"3790415","outcome_index":0,"market_type":"set2","local_side":"home","local_uid":"2026-08-23_pierre_hugues_herbert_quinn_vandecasteele","bid":0.57,"ask":0.66,"mid":0.615,"spread":0.09,"bid_size":null,"ask_size":null}
{"ts":"2026-08-23T17:53:56.691Z","event_type":"best_bid_ask","market_id":"3790415","outcome_index":1,"market_type":"set2","local_side":"away","local_uid":"2026-08-23_pierre_hugues_herbert_quinn_vandecasteele","bid":0.34,"ask":0.43,"mid":0.385,"spread":0.09,"bid_size":null,"ask_size":null}
{"ts":"2026-08-23T17:53:56.691Z","event_type":"price_change","market_id":"3790415","outcome_index":0,"market_type":"set2","local_side":"home","local_uid":"2026-08-23_pierre_hugues_herbert_quinn_vandecasteele","bid":0.57,"ask":0.66,"mid":0.615,"spread":0.09,"price":0.57,"size":150.0,"side":"BUY"}
