{"ts":"2026-08-24T20:48:14.146Z","event_type":"best_bid_ask","market_id":"3825070","outcome_index":0,"market_type":"set2","local_side":"home","local_uid":"2026-08-24_polina_kudermetova_linda_fruhvirtova","bid":0.5,"ask":0.61,"mid":0.555,"spread":0.11,"bid_size":null,"ask_size":null}
{"ts":"2026-08-24T20:48:14.146Z","event_type":"best_bid_ask","market_id":"3825070","outcome_index":1,"market_type":"set2","local_side":"away","local_uid":"2026-08-24_polina_kudermetova_linda_fruhvirtova","bid":0.39,"ask":0.5,"mid":0.445,"spread":0.11,"bid_size":null,"ask_size":null}
{"ts":"2026-08-24T20:48:14.146Z","event_type":"price_change","market_id":"3825070","outcome_index":1,"market_type":"set2","local_side":"away","local_uid":"2026-08-24_polina_kudermetova_linda_fruhvirtova","bid":0.39,"ask":0.5,"mid":0.445,"spread":0.11,"price":0.41,"size":0.0,"side":"BUY"}
{"ts":"2026-08-24T20:48:14.146Z","event_type":"price_change","market_id":"3825070","outcome_index":0,"market_type":"set2","local_side":"home","local_uid":"2026-08-24_polina_kudermetova_linda_fruhvirtova","bid":0.5,"ask":0.61,"mid":0.555,"spread":0.11,"price":0.59,"size":0.0,"side":"SELL"}
{"ts":"2026-08-24T20:48:14.148Z","event_type":"best_bid_ask","market_id":"3826738","outcome_index":0,"market_type":"set2","local_side":"home","local_uid":"2026-08-24_harry_wendelken_stefano_travaglia","bid":0.49,"ask":0.59,"mid":0.54,"spread":0.1,"bid_size":null,"ask_size":null}
{"ts":"2026-08-24T20:48:14.149Z","event_type":"best_bid_ask","market_id":"3826738","outcome_index":1,"market_type":"set2","local_side":"away","local_uid":"2026-08-24_harry_wendelken_stefano_travaglia","bid":0.41,"ask":0.51,"mid":0.46,"spread":0.1,"bid_size":null,"ask_size":null}
{"ts":"2026-08-24T20:48:14.149Z","event_type":"price_change","market_id":"3826738","outcome_index":0,"market_type":"set2","local_side":"home","local_uid":"2026-08-24_harry_wendelken_stefano_travaglia","bid":0.49,"ask":0.59,"mid":0.54,"spread":0.1,"price":0.5,"size":0.0,"side":"BUY"}
{"ts":"2026-08-24T20:48:14.149Z","event_type":"price_change","market_id":"3826738","outcome_index":1,"market_type":"set2","local_side":"away","local_uid":"2026-08-24_harry_wendelken_stefano_travaglia","bid":0.41,"ask":0.51,"mid":0.46,"spread":0.1,"price":0.5,"size":0.0,"side":"SELL"}
{"ts":"2026-08-24T20:48:14.162Z","event_type":"best_bid_ask","market_id":"3825070","outcome_index":0,"market_type":"set2","local_side":"home","local_uid":"2026-08-24_polina_kudermetova_linda_fruhvirtova","bid":0.48,"ask":0.61,"mid":0.545,"spread":0.13,"bid_size":null,"ask_size":null}
{"ts":"2026-08-24T20:48:14.163Z","event_type":"best_bid_ask","market_id":"3825070","outcome_index":1,"market_type":"set2","local_side":"away","local_uid":"2026-08-24_polina_kudermetova_linda_fruhvirtova","bid":0.39,"ask":0.52,"mid":0.455,"spread":0.13,"bid_size":null,"ask_size":null}
{"ts":"2026-08-24T20:48:14.163Z","event_type":"price_change","market_id":"3825070","outcome_index":0,"market_type":"set2","local_side":"home","local_uid":"2026-08-24_polina_kudermetova_linda_fruhvirtova","bid":0.48,"ask":0.61,"mid":0.545,"spread":0.13,"price":0.5,"size":0.0,"side":"BUY"}
{"ts":"2026-08-24T20:48:14.163Z","event_type":"price_change","market_id":"3825070","outcome_index":1,"market_type":"set2","local_side":"away","local_uid":"2026-08-24_polina_kudermetova_linda_fruhvirtova","bid":0.39,"ask":0.52,"mid":0.455,"spread":0.13,"price":0.5,"size":0.0,"side":"SELL"}
{"ts":"2026-08-24T20:48:14.168Z","event_type":"best_bid_ask","market_id":"3825070","outcome_index":0,"market_type":"set2","local_side":"home","local_uid":"2026-08-24_polina_kudermetova_linda_fruhvirtova","bid":0.49,"ask":0.61,"mid":0.55,"spread":0.12,"bid_size":null,"ask_size":null}
{"ts":"2026-08-24T20:48:14.168Z","event_type":"best_bid_ask","market_id":"3825070","outcome_index":1,"market_type":"set2","local_side":"away","local_uid":"2026-08-24_polina_kudermetova_linda_fruhvirtova","bid":0.39,"ask":0.51,"mid":0.45,"spread":0.12,"bid_size":null,"ask_size":null}
{"ts":"2026-08-24T20:48:14.169Z","event_type":"price_change","market_id":"3825070","outcome_index":0,"market_type":"set2","local_side":"home","local_uid":"2026-08-24_polina_kudermetova_linda_fruhvirtova","bid":0.49,"ask":0.61,"mid":0.55,"spread":0.12,"price":0.49,"size":2891.0,"side":"BUY"}
{"ts":"2026-08-24T20:48:14.169Z","event_type":"price_change","market_id":"3825070","outcome_index":1,"market_type":"set2","local_side":"away","local_uid":"2026-08-24_polina_kudermetova_linda_fruhvirtova","bid":0.39,"ask":0.51,"mid":0.45,"spread":0.12,"price":0.51,"size":2891.0,"side":"SELL"}
{"ts":"2026-08-24T20:48:14.236Z","event_type":"best_bid_ask","market_id":"3826738","outcome_index":0,"market_type":"set2","local_side":"home","local_uid":"2026-08-24_harry_wendelken_stefano_travaglia","bid":0.5,"ask":0.59,"mid":0.545,"spread":0.09,"bid_size":null,"ask_size":null}
{"ts":"2026-08-24T20:48:14.237Z","event_type":"best_bid_ask","market_id":"3826738","outcome_index":1,"market_type":"set2","local_side":"away","local_uid":"2026-08-24_harry_wendelken_stefano_travaglia","bid":0.41,"ask":0.5,"mid":0.455,"spread":0.09,"bid_size":null,"ask_size":null}
{"ts":"2026-08-24T20:48:14.237Z","event_type":"price_change","market_id":"3826738","outcome_index":0,"market_type":"set2","local_side":"home","local_uid":"2026-08-24_harry_wendelken_stefano_travaglia","bid":0.5,"ask":0.59,"mid":0.545,"spread":0.09,"price":0.5,"size":18.0,"side":"BUY"}
{"ts":"2026-08-24T20:48:14.237Z","event_type":"price_change","market_id":"3826738","outcome_index":1,"market_type":"set2","local_side":"away","local_uid":"2026-08-24_harry_wendelken_stefano_travaglia","bid":0.41,"ask":0.5,"mid":0.455,"spread":0.09,"price":0.5,"size":18.0,"side":"SELL"}
{"ts":"2026-08-24T20:48:14.315Z","event_type":"best_bid_ask","market_id":"3824761","outcome_index":0,"market_type":"set1","local_side":"home","local_uid":"2026-08-24_jazmin_ortenzi_himeno_sakatsume","bid":0.17,"ask":0.25,"mid":0.21,"spread":0.08,"bid_size":null,"ask_size":null}
{"ts":"2026-08-24T20:48:14.324Z","event_type":"best_bid_ask","market_id":"3824761","outcome_index":1,"market_type":"set1","local_side":"away","local_uid":"2026-08-24_jazmin_ortenzi_himeno_sakatsume","bid":0.75,"ask":0.83,"mid":0.79,"spread":0.08,"bid_size":null,"ask_size":null}
{"ts":"2026-08-24T20:48:14.331Z","event_type":"price_change","market_id":"3824761","outcome_index":0,"market_type":"set1","local_side":"home","local_uid":"2026-08-24_jazmin_ortenzi_himeno_sakatsume","bid":0.17,"ask":0.25,"mid":0.21,"spread":0.08,"price":0.18,"size":0.0,"side":"BUY"}
{"ts":"2026-08-24T20:48:14.331Z","event_type":"price_change","market_id":"3824761","outcome_index":1,"market_type":"set1","local_side":"away","local_uid":"2026-08-24_jazmin_ortenzi_himeno_sakatsume","bid":0.75,"ask":0.83,"mid":0.79,"spread":0.08,"price":0.82,"size":0.0,"side":"SELL"}
{"ts":"2026-08-24T20:48:14.395Z","event_type":"price_change","market_id":"3825612","outcome_index":0,"market_type":"match","local_side":"home","local_uid":"2026-08-24_otto_virtanen_ugo_blanchet","bid":0.67,"ask":0.68,"mid":0.675,"spread":0.01,"price":0.67,"size":19526.16,"side":"BUY"}
{"ts":"2026-08-24T20:48:14.395Z","event_type":"price_change","market_id":"3825612","outcome_index":1,"market_type":"match","local_side":"away","local_uid":"2026-08-24_otto_virtanen_ugo_blanchet","bid":0.32,"ask":0.33,"mid":0.325,"spread":0.01,"price":0.33,"size":19526.16,"side":"SELL"}
{"ts":"2026-08-24T20:48:14.428Z","event_type":"best_bid_ask","market_id":"3826733","outcome_index":0,"market_type":"set1","local_side":"home","local_uid":"2026-08-24_harry_wendelken_stefano_travaglia","bid":0.85,"ask":0.91,"mid":0.88,"spread":0.06,"bid_size":null,"ask_size":null}
{"ts":"2026-08-24T20:48:14.428Z","event_type":"best_bid_ask","market_id":"3826733","outcome_index":1,"market_type":"set1","local_side":"away","local_uid":"2026-08-24_harry_wendelken_stefano_travaglia","bid":0.09,"ask":0.15,"mid":0.12,"spread":0.06,"bid_size":null,"ask_size":null}
{"ts":"2026-08-24T20:48:14.436Z","event_type":"price_change","market_id":"3826733","outcome_index":0,"market_type":"set1","local_side":"home","local_uid":"2026-08-24_harry_wendelken_stefano_travaglia","bid":0.85,"ask":0.91,"mid":0.88,"spread":0.06,"price":0.86,"size":0.0,"side":"BUY"}
{"ts":"2026-08-24T20:48:14.436Z","event_type":"price_change","market_id":"3826733","outcome_index":1,"market_type":"set1","local_side":"away","local_uid":"2026-08-24_harry_wendelken_stefano_travaglia","bid":0.09,"ask":0.15,"mid":0.12,"spread":0.06,"price":0.14,"size":0.0,"side":"SELL"}
{"ts":"2026-08-24T20:48:14.460Z","event_type":"best_bid_ask","market_id":"3826738","outcome_index":0,"market_type":"set2","local_side":"home","local_uid":"2026-08-24_harry_wendelken_stefano_travaglia","bid":0.48,"ask":0.59,"mid":0.535,"spread":0.11,"bid_size":null,"ask_size":null}
{"ts":"2026-08-24T20:48:14.460Z","event_type":"best_bid_ask","market_id":"3826738","outcome_index":1,"market_type":"set2","local_side":"away","local_uid":"2026-08-24_harry_wendelken_stefano_travaglia","bid":0.41,"ask":0.52,"mid":0.465,"spread":0.11,"bid_size":null,"ask_size":null}
{"ts":"2026-08-24T20:48:14.460Z","event_type":"price_change","market_id":"3826738","outcome_index":0,"market_type":"set2","local_side":"home","local_uid":"2026-08-24_harry_wendelken_stefano_travaglia","bid":0.48,"ask":0.59,"mid":0.535,"spread":0.11,"price":0.5,"size":0.0,"side":"BUY"}
{"ts":"2026-08-24T20:48:14.461Z","event_type":"price_change","market_id":"3826738","outcome_index":1,"market_type":"set2","local_side":"away","local_uid":"2026-08-24_harry_wendelken_stefano_travaglia","bid":0.41,"ask":0.52,"mid":0.465,"spread":0.11,"price":0.5,"size":0.0,"side":"SELL"}
{"ts":"2026-08-24T20:48:14.508Z","event_type":"best_bid_ask","market_id":"3825077","outcome_index":0,"market_type":"set1","local_side":"home","local_uid":"2026-08-24_polina_kudermetova_linda_fruhvirtova","bid":0.45,"ask":0.52,"mid":0.485,"spread":0.07,"bid_size":null,"ask_size":null}
{"ts":"2026-08-24T20:48:14.508Z","event_type":"best_bid_ask","market_id":"3825077","outcome_index":1,"market_type":"set1","local_side":"away","local_uid":"2026-08-24_polina_kudermetova_linda_fruhvirtova","bid":0.48,"ask":0.55,"mid":0.515,"spread":0.07,"bid_size":null,"ask_size":null}
{"ts":"2026-08-24T20:48:14.508Z","event_type":"price_change","market_id":"3825077","outcome_index":1,"market_type":"set1","local_side":"away","local_uid":"2026-08-24_polina_kudermetova_linda_fruhvirtova","bid":0.48,"ask":0.55,"mid":0.515,"spread":0.07,"price":0.53,"size":0.0,"side":"BUY"}
{"ts":"2026-08-24T20:48:14.509Z","event_type":"price_change","market_id":"3825077","outcome_index":0,"market_type":"set1","local_side":"home","local_uid":"2026-08-24_polina_kudermetova_linda_fruhvirtova","bid":0.45,"ask":0.52,"mid":0.485,"spread":0.07,"price":0.47,"size":0.0,"side":"SELL"}
{"ts":"2026-08-24T20:48:14.530Z","event_type":"best_bid_ask","market_id":"3823619","outcome_index":0,"market_type":"match","local_side":"home","local_uid":"2026-08-24_polina_kudermetova_linda_fruhvirtova","bid":0.53,"ask":0.55,"mid":0.54,"spread":0.02,"bid_size":null,"ask_size":null}
{"ts":"2026-08-24T20:48:14.530Z","event_type":"best_bid_ask","market_id":"3823619","outcome_index":1,"market_type":"match","local_side":"away","local_uid":"2026-08-24_polina_kudermetova_linda_fruhvirtova","bid":0.45,"ask":0.47,"mid":0.46,"spread":0.02,"bid_size":null,"ask_size":null}
{"ts":"2026-08-24T20:48:14.531Z","event_type":"price_change","market_id":"3823619","outcome_index":0,"market_type":"match","local_side":"home","local_uid":"2026-08-24_polina_kudermetova_linda_fruhvirtova","bid":0.53,"ask":0.55,"mid":0.54,"spread":0.02,"price":0.54,"size":0.0,"side":"SELL"}
{"ts":"2026-08-24T20:48:14.531Z","event_type":"price_change","market_id":"3823619","outcome_index":1,"market_type":"match","local_side":"away","local_uid":"2026-08-24_polina_kudermetova_linda_fruhvirtova","bid":0.45,"ask":0.47,"mid":0.46,"spread":0.02,"price":0.46,"size":0.0,"side":"BUY"}
{"ts":"2026-08-24T20:48:14.533Z","event_type":"best_bid_ask","market_id":"3825077","outcome_index":0,"market_type":"set1","local_side":"home","local_uid":"2026-08-24_polina_kudermetova_linda_fruhvirtova","bid":0.45,"ask":0.51,"mid":0.48,"spread":0.06,"bid_size":null,"ask_size":null}
{"ts":"2026-08-24T20:48:14.534Z","event_type":"best_bid_ask","market_id":"3825077","outcome_index":1,"market_type":"set1","local_side":"away","local_uid":"2026-08-24_polina_kudermetova_linda_fruhvirtova","bid":0.49,"ask":0.55,"mid":0.52,"spread":0.06,"bid_size":null,"ask_size":null}
{"ts":"2026-08-24T20:48:14.534Z","event_type":"price_change","market_id":"3825077","outcome_index":1,"market_type":"set1","local_side":"away","local_uid":"2026-08-24_polina_kudermetova_linda_fruhvirtova","bid":0.49,"ask":0.55,"mid":0.52,"spread":0.06,"price":0.49,"size":250.0,"side":"BUY"}
{"ts":"2026-08-24T20:48:14.534Z","event_type":"price_change","market_id":"3825077","outcome_index":0,"market_type":"set1","local_side":"home","local_uid":"2026-08-24_polina_kudermetova_linda_fruhvirtova","bid":0.45,"ask":0.51,"mid":0.48,"spread":0.06,"price":0.51,"size":250.0,"side":"SELL"}
{"ts":"2026-08-24T20:48:14.721Z","event_type":"price_change","market_id":"3824997","outcome_index":1,"market_type":"set2","local_side":"away","local_uid":"2026-08-24_claire_liu_heather_watson","bid":0.999,"ask":1.0,"mid":0.9995,"spread":0.001,"price":0.013,"size":10560.0,"side":"BUY"}
{"ts":"2026-08-24T20:48:14.722Z","event_type":"price_change","market_id":"3824997","outcome_index":0,"market_type":"set2","local_side":"home","local_uid":"2026-08-24_claire_liu_heather_watson","bid":0.0,"ask":0.001,"mid":0.0005,"spread":0.001,"price":0.987,"size":10560.0,"side":"SELL"}
{"ts":"2026-08-24T20:48:14.766Z","event_type":"best_bid_ask","market_id":"3825077","outcome_index":0,"market_type":"set1","local_side":"home","local_uid":"2026-08-24_polina_kudermetova_linda_fruhvirtova","bid":0.45,"ask":0.5,"mid":0.475,"spread":0.05,"bid_size":null,"ask_size":null}
{"ts":"2026-08-24T20:48:14.766Z","event_type":"best_bid_ask","market_id":"3825077","outcome_index":1,"market_type":"set1","local_side":"away","local_uid":"2026-08-24_polina_kudermetova_linda_fruhvirtova","bid":0.5,"ask":0.55,"mid":0.525,"spread":0.05,"bid_size":null,"ask_size":null}
{"ts":"2026-08-24T20:48:14.767Z","event_type":"price_change","market_id":"3825077","outcome_index":1,"market_type":"set1","local_side":"away","local_uid":"2026-08-24_polina_kudermetova_linda_fruhvirtova","bid":0.5,"ask":0.55,"mid":0.525,"spread":0.05,"price":0.5,"size":5.0,"side":"BUY"}
{"ts":"2026-08-24T20:48:14.767Z","event_type":"price_change","market_id":"3825077","outcome_index":0,"market_type":"set1","local_side":"home","local_uid":"2026-08-24_polina_kudermetova_linda_fruhvirtova","bid":0.45,"ask":0.5,"mid":0.475,"spread":0.05,"price":0.5,"size":5.0,"side":"SELL"}
{"ts":"2026-08-24T20:48:14.787Z","event_type":"price_change","market_id":"3825645","outcome_index":1,"market_type":"match","local_side":"away","local_uid":"2026-08-24_felix_balshaw_aleksandar_kovacevic","bid":0.66,"ask":0.67,"mid":0.665,"spread":0.01,"price":0.66,"size":890.71,"side":"BUY"}
{"ts":"2026-08-24T20:48:14.787Z","event_type":"price_change","market_id":"3825645","outcome_index":0,"market_type":"match","local_side":"home","local_uid":"2026-08-24_felix_balshaw_aleksandar_kovacevic","bid":0.33,"ask":0.34,"mid":0.335,"spread":0.01,"price":0.34,"size":890.71,"side":"SELL"}
{"ts":"2026-08-24T20:48:14.788Z","event_type":"best_bid_ask","market_id":"3826733","outcome_index":0,"market_type":"set1","local_side":"home","local_uid":"2026-08-24_harry_wendelken_stefano_travaglia","bid":0.85,"ask":0.93,"mid":0.89,"spread":0.08,"bid_size":null,"ask_size":null}
{"ts":"2026-08-24T20:48:14.788Z","event_type":"best_bid_ask","market_id":"3826733","outcome_index":1,"market_type":"set1","local_side":"away","local_uid":"2026-08-24_harry_wendelken_stefano_travaglia","bid":0.07,"ask":0.15,"mid":0.11,"spread":0.08,"bid_size":null,"ask_size":null}
{"ts":"2026-08-24T20:48:14.789Z","event_type":"price_change","market_id":"3826733","outcome_index":1,"market_type":"set1","local_side":"away","local_uid":"2026-08-24_harry_wendelken_stefano_travaglia","bid":0.07,"ask":0.15,"mid":0.11,"spread":0.08,"price":0.09,"size":0.0,"side":"BUY"}
{"ts":"2026-08-24T20:48:14.789Z","event_type":"price_change","market_id":"3826733","outcome_index":0,"market_type":"set1","local_side":"home","local_uid":"2026-08-24_harry_wendelken_stefano_travaglia","bid":0.85,"ask":0.93,"mid":0.89,"spread":0.08,"price":0.91,"size":0.0,"side":"SELL"}
{"ts":"2026-08-24T20:48:14.800Z","event_type":"best_bid_ask","market_id":"3826738","outcome_index":0,"market_type":"set2","local_side":"home","local_uid":"2026-08-24_harry_wendelken_stefano_travaglia","bid":0.48,"ask":0.6,"mid":0.54,"spread":0.12,"bid_size":null,"ask_size":null}
{"ts":"2026-08-24T20:48:14.800Z","event_type":"best_bid_ask","market_id":"3826738","outcome_index":1,"market_type":"set2","local_side":"away","local_uid":"2026-08-24_harry_wendelken_stefano_travaglia","bid":0.4,"ask":0.52,"mid":0.46,"spread":0.12,"bid_size":null,"ask_size":null}
{"ts":"2026-08-24T20:48:14.800Z","event_type":"price_change","market_id":"3826738","outcome_index":1,"market_type":"set2","local_side":"away","local_uid":"2026-08-24_harry_wendelken_stefano_travaglia","bid":0.4,"ask":0.52,"mid":0.46,"spread":0.12,"price":0.41,"size":0.0,"side":"BUY"}
{"ts":"2026-08-24T20:48:14.800Z","event_type":"price_change","market_id":"3826738","outcome_index":0,"market_type":"set2","local_side":"home","local_uid":"2026-08-24_harry_wendelken_stefano_travaglia","bid":0.48,"ask":0.6,"mid":0.54,"spread":0.12,"price":0.59,"size":0.0,"side":"SELL"}
{"ts":"2026-08-24T20:48:14.826Z","event_type":"best_bid_ask","market_id":"3825077","outcome_index":0,"market_type":"set1","local_side":"home","local_uid":"2026-08-24_polina_kudermetova_linda_fruhvirtova","bid":0.45,"ask":0.51,"mid":0.48,"spread":0.06,"bid_size":null,"ask_size":null}
{"ts":"2026-08-24T20:48:14.826Z","event_type":"best_bid_ask","market_id":"3825077","outcome_index":1,"market_type":"set1","local_side":"away","local_uid":"2026-08-24_polina_kudermetova_linda_fruhvirtova","bid":0.49,"ask":0.55,"mid":0.52,"spread":0.06,"bid_size":null,"ask_size":null}
{"ts":"2026-08-24T20:48:14.827Z","event_type":"price_change","market_id":"3825077","outcome_index":1,"market_type":"set1","local_side":"away","local_uid":"2026-08-24_polina_kudermetova_linda_fruhvirtova","bid":0.49,"ask":0.55,"mid":0.52,"spread":0.06,"price":0.5,"size":0.0,"side":"BUY"}
{"ts":"2026-08-24T20:48:14.827Z","event_type":"price_change","market_id":"3825077","outcome_index":0,"market_type":"set1","local_side":"home","local_uid":"2026-08-24_polina_kudermetova_linda_fruhvirtova","bid":0.45,"ask":0.51,"mid":0.48,"spread":0.06,"price":0.5,"size":0.0,"side":"SELL"}
{"ts":"2026-08-24T20:48:15.041Z","event_type":"price_change","market_id":"3827170","outcome_index":0,"market_type":"set1","local_side":"home","local_uid":"2026-08-24_jenson_brooksby_stefanos_tsitsipas","bid":0.42,"ask":0.43,"mid":0.425,"spread":0.01,"price":0.34,"size":39.61,"side":"BUY"}
{"ts":"2026-08-24T20:48:15.041Z","event_type":"price_change","market_id":"3827170","outcome_index":1,"market_type":"set1","local_side":"away","local_uid":"2026-08-24_jenson_brooksby_stefanos_tsitsipas","bid":0.57,"ask":0.58,"mid":0.575,"spread":0.01,"price":0.66,"size":39.61,"side":"SELL"}
{"ts":"2026-08-24T20:48:15.071Z","event_type":"best_bid_ask","market_id":"3826738","outcome_index":0,"market_type":"set2","local_side":"home","local_uid":"2026-08-24_harry_wendelken_stefano_travaglia","bid":0.49,"ask":0.6,"mid":0.545,"spread":0.11,"bid_size":null,"ask_size":null}
{"ts":"2026-08-24T20:48:15.072Z","event_type":"best_bid_ask","market_id":"3826738","outcome_index":1,"market_type":"set2","local_side":"away","local_uid":"2026-08-24_harry_wendelken_stefano_travaglia","bid":0.4,"ask":0.51,"mid":0.455,"spread":0.11,"bid_size":null,"ask_size":null}
{"ts":"2026-08-24T20:48:15.072Z","event_type":"price_change","market_id":"3826738","outcome_index":0,"market_type":"set2","local_side":"home","local_uid":"2026-08-24_harry_wendelken_stefano_travaglia","bid":0.49,"ask":0.6,"mid":0.545,"spread":0.11,"price":0.49,"size":42.8,"side":"BUY"}
{"ts":"2026-08-24T20:48:15.072Z","event_type":"price_change","market_id":"3826738","outcome_index":1,"market_type":"set2","local_side":"away","local_uid":"2026-08-24_harry_wendelken_stefano_travaglia","bid":0.4,"ask":0.51,"mid":0.455,"spread":0.11,"price":0.51,"size":42.8,"side":"SELL"}
{"ts":"2026-08-24T20:48:15.128Z","event_type":"best_bid_ask","market_id":"3826738","outcome_index":0,"market_type":"set2","local_side":"home","local_uid":"2026-08-24_harry_wendelken_stefano_travaglia","bid":0.48,"ask":0.6,"mid":0.54,"spread":0.12,"bid_size":null,"ask_size":null}
{"ts":"2026-08-24T20:48:15.128Z","event_type":"best_bid_ask","market_id":"3826738","outcome_index":1,"market_type":"set2","local_side":"away","local_uid":"2026-08-24_harry_wendelken_stefano_travaglia","bid":0.4,"ask":0.52,"mid":0.46,"spread":0.12,"bid_size":null,"ask_size":null}
{"ts":"2026-08-24T20:48:15.129Z","event_type":"price_change","market_id":"3826738","outcome_index":0,"market_type":"set2","local_side":"home","local_uid":"2026-08-24_harry_wendelken_stefano_travaglia","bid":0.48,"ask":0.6,"mid":0.54,"spread":0.12,"price":0.49,"size":0.0,"side":"BUY"}
{"ts":"2026-08-24T20:48:15.129Z","event_type":"price_change","market_id":"3826738","outcome_index":1,"market_type":"set2","local_side":"away","local_uid":"2026-08-24_harry_wendelken_stefano_travaglia","bid":0.4,"ask":0.52,"mid":0.46,"spread":0.12,"price":0.51,"size":0.0,"side":"SELL"}
{"ts":"2026-08-24T20:48:15.201Z","event_type":"best_bid_ask","market_id":"3823665","outcome_index":0,"market_type":"match","local_side":"home","local_uid":"2026-08-24_jazmin_ortenzi_himeno_sakatsume","bid":0.15,"ask":0.17,"mid":0.16,"spread":0.02,"bid_size":null,"ask_size":null}
{"ts":"2026-08-24T20:48:15.201Z","event_type":"best_bid_ask","market_id":"3823665","outcome_index":1,"market_type":"match","local_side":"away","local_uid":"2026-08-24_jazmin_ortenzi_himeno_sakatsume","bid":0.83,"ask":0.85,"mid":0.84,"spread":0.02,"bid_size":null,"ask_size":null}
{"ts":"2026-08-24T20:48:15.201Z","event_type":"price_change","market_id":"3823665","outcome_index":0,"market_type":"match","local_side":"home","local_uid":"2026-08-24_jazmin_ortenzi_himeno_sakatsume","bid":0.15,"ask":0.17,"mid":0.16,"spread":0.02,"price":0.14,"size":4808.0,"side":"BUY"}
{"ts":"2026-08-24T20:48:15.202Z","event_type":"price_change","market_id":"3823665","outcome_index":1,"market_type":"match","local_side":"away","local_uid":"2026-08-24_jazmin_ortenzi_himeno_sakatsume","bid":0.83,"ask":0.85,"mid":0.84,"spread":0.02,"price":0.86,"size":4808.0,"side":"SELL"}
{"ts":"2026-08-24T20:48:15.219Z","event_type":"book","market_id":"3825604","outcome_index":0,"market_type":"match","local_side":"home","local_uid":"2026-08-24_dalibor_svrcina_felipe_meligeni_alves","bid":0.78,"ask":0.84,"mid":0.81,"spread":0.06,"bid_size":29.45,"ask_size":10.0}
{"ts":"2026-08-24T20:48:15.224Z","event_type":"book","market_id":"3825604","outcome_index":1,"market_type":"match","local_side":"away","local_uid":"2026-08-24_dalibor_svrcina_felipe_meligeni_alves","bid":0.16,"ask":0.22,"mid":0.19,"spread":0.06,"bid_size":10.0,"ask_size":29.45}
{"ts":"2026-08-24T20:48:15.340Z","event_type":"last_trade_price","market_id":"3825604","outcome_index":1,"market_type":"match","local_side":"away","local_uid":"2026-08-24_dalibor_svrcina_felipe_meligeni_alves","last_trade":0.22,"trade_size":4.5455,"trade_side":"BUY","trade_notional":1.0}
{"ts":"2026-08-24T20:48:15.342Z","event_type":"last_trade_price","market_id":"3825604","outcome_index":1,"market_type":"match","local_side":"away","local_uid":"2026-08-24_dalibor_svrcina_felipe_meligeni_alves","last_trade":0.22,"trade_size":4.5455,"trade_side":"BUY","trade_notional":1.0}
{"ts":"2026-08-24T20:48:15.422Z","event_type":"best_bid_ask","market_id":"3824760","outcome_index":0,"market_type":"set2","local_side":"home","local_uid":"2026-08-24_jazmin_ortenzi_himeno_sakatsume","bid":0.2,"ask":0.3,"mid":0.25,"spread":0.1,"bid_size":null,"ask_size":null}
{"ts":"2026-08-24T20:48:15.422Z","event_type":"best_bid_ask","market_id":"3824760","outcome_index":1,"market_type":"set2","local_side":"away","local_uid":"2026-08-24_jazmin_ortenzi_himeno_sakatsume","bid":0.7,"ask":0.8,"mid":0.75,"spread":0.1,"bid_size":null,"ask_size":null}
{"ts":"2026-08-24T20:48:15.423Z","event_type":"price_change","market_id":"3824760","outcome_index":0,"market_type":"set2","local_side":"home","local_uid":"2026-08-24_jazmin_ortenzi_himeno_sakatsume","bid":0.2,"ask":0.3,"mid":0.25,"spread":0.1,"price":0.21,"size":0.0,"side":"BUY"}
{"ts":"2026-08-24T20:48:15.423Z","event_type":"price_change","market_id":"3824760","outcome_index":1,"market_type":"set2","local_side":"away","local_uid":"2026-08-24_jazmin_ortenzi_himeno_sakatsume","bid":0.7,"ask":0.8,"mid":0.75,"spread":0.1,"price":0.79,"size":0.0,"side":"SELL"}
{"ts":"2026-08-24T20:48:15.447Z","event_type":"best_bid_ask","market_id":"3824760","outcome_index":0,"market_type":"set2","local_side":"home","local_uid":"2026-08-24_jazmin_ortenzi_himeno_sakatsume","bid":0.18,"ask":0.3,"mid":0.24,"spread":0.12,"bid_size":null,"ask_size":null}
{"ts":"2026-08-24T20:48:15.448Z","event_type":"best_bid_ask","market_id":"3824760","outcome_index":1,"market_type":"set2","local_side":"away","local_uid":"2026-08-24_jazmin_ortenzi_himeno_sakatsume","bid":0.7,"ask":0.82,"mid":0.76,"spread":0.12,"bid_size":null,"ask_size":null}
{"ts":"2026-08-24T20:48:15.448Z","event_type":"price_change","market_id":"3824760","outcome_index":0,"market_type":"set2","local_side":"home","local_uid":"2026-08-24_jazmin_ortenzi_himeno_sakatsume","bid":0.18,"ask":0.3,"mid":0.24,"spread":0.12,"price":0.2,"size":0.0,"side":"BUY"}
{"ts":"2026-08-24T20:48:15.448Z","event_type":"price_change","market_id":"3824760","outcome_index":1,"market_type":"set2","local_side":"away","local_uid":"2026-08-24_jazmin_ortenzi_himeno_sakatsume","bid":0.7,"ask":0.82,"mid":0.76,"spread":0.12,"price":0.8,"size":0.0,"side":"SELL"}
{"ts":"2026-08-24T20:48:15.450Z","event_type":"best_bid_ask","market_id":"3824760","outcome_index":0,"market_type":"set2","local_side":"home","local_uid":"2026-08-24_jazmin_ortenzi_himeno_sakatsume","bid":0.2,"ask":0.3,"mid":0.25,"spread":0.1,"bid_size":null,"ask_size":null}
{"ts":"2026-08-24T20:48:15.450Z","event_type":"best_bid_ask","market_id":"3824760","outcome_index":1,"market_type":"set2","local_side":"away","local_uid":"2026-08-24_jazmin_ortenzi_himeno_sakatsume","bid":0.7,"ask":0.8,"mid":0.75,"spread":0.1,"bid_size":null,"ask_size":null}
{"ts":"2026-08-24T20:48:15.450Z","event_type":"price_change","market_id":"3824760","outcome_index":0,"market_type":"set2","local_side":"home","local_uid":"2026-08-24_jazmin_ortenzi_himeno_sakatsume","bid":0.2,"ask":0.3,"mid":0.25,"spread":0.1,"price":0.2,"size":968.0,"side":"BUY"}
{"ts":"2026-08-24T20:48:15.451Z","event_type":"price_change","market_id":"3824760","outcome_index":1,"market_type":"set2","local_side":"away","local_uid":"2026-08-24_jazmin_ortenzi_himeno_sakatsume","bid":0.7,"ask":0.8,"mid":0.75,"spread":0.1,"price":0.8,"size":968.0,"side":"SELL"}
{"ts":"2026-08-24T20:48:15.451Z","event_type":"best_bid_ask","market_id":"3824761","outcome_index":0,"market_type":"set1","local_side":"home","local_uid":"2026-08-24_jazmin_ortenzi_himeno_sakatsume","bid":0.16,"ask":0.25,"mid":0.205,"spread":0.09,"bid_size":null,"ask_size":null}
{"ts":"2026-08-24T20:48:15.451Z","event_type":"best_bid_ask","market_id":"3824761","outcome_index":1,"market_type":"set1","local_side":"away","local_uid":"2026-08-24_jazmin_ortenzi_himeno_sakatsume","bid":0.75,"ask":0.84,"mid":0.795,"spread":0.09,"bid_size":null,"ask_size":null}
{"ts":"2026-08-24T20:48:15.452Z","event_type":"price_change","market_id":"3824761","outcome_index":0,"market_type":"set1","local_side":"home","local_uid":"2026-08-24_jazmin_ortenzi_himeno_sakatsume","bid":0.16,"ask":0.25,"mid":0.205,"spread":0.09,"price":0.17,"size":0.0,"side":"BUY"}
{"ts":"2026-08-24T20:48:15.452Z","event_type":"price_change","market_id":"3824761","outcome_index":1,"market_type":"set1","local_side":"away","local_uid":"2026-08-24_jazmin_ortenzi_himeno_sakatsume","bid":0.75,"ask":0.84,"mid":0.795,"spread":0.09,"price":0.83,"size":0.0,"side":"SELL"}
{"ts":"2026-08-24T20:48:15.466Z","event_type":"best_bid_ask","market_id":"3824761","outcome_index":0,"market_type":"set1","local_side":"home","local_uid":"2026-08-24_jazmin_ortenzi_himeno_sakatsume","bid":0.17,"ask":0.25,"mid":0.21,"spread":0.08,"bid_size":null,"ask_size":null}
{"ts":"2026-08-24T20:48:15.466Z","event_type":"best_bid_ask","market_id":"3824761","outcome_index":1,"market_type":"set1","local_side":"away","local_uid":"2026-08-24_jazmin_ortenzi_himeno_sakatsume","bid":0.75,"ask":0.83,"mid":0.79,"spread":0.08,"bid_size":null,"ask_size":null}
{"ts":"2026-08-24T20:48:15.467Z","event_type":"price_change","market_id":"3824761","outcome_index":0,"market_type":"set1","local_side":"home","local_uid":"2026-08-24_jazmin_ortenzi_himeno_sakatsume","bid":0.17,"ask":0.25,"mid":0.21,"spread":0.08,"price":0.17,"size":787.0,"side":"BUY"}
{"ts":"2026-08-24T20:48:15.467Z","event_type":"price_change","market_id":"3824761","outcome_index":1,"market_type":"set1","local_side":"away","local_uid":"2026-08-24_jazmin_ortenzi_himeno_sakatsume","bid":0.75,"ask":0.83,"mid":0.79,"spread":0.08,"price":0.83,"size":787.0,"side":"SELL"}
{"ts":"2026-08-24T20:48:15.477Z","event_type":"price_change","market_id":"3824845","outcome_index":0,"market_type":"set1","local_side":"home","local_uid":"2026-08-24_gabriela_knutson_varvara_lepchenko","bid":0.54,"ask":0.57,"mid":0.555,"spread":0.03,"price":0.43,"size":0.0,"side":"BUY"}
{"ts":"2026-08-24T20:48:15.477Z","event_type":"price_change","market_id":"3824845","outcome_index":1,"market_type":"set1","local_side":"away","local_uid":"2026-08-24_gabriela_knutson_varvara_lepchenko","bid":0.43,"ask":0.46,"mid":0.445,"spread":0.03,"price":0.57,"size":0.0,"side":"SELL"}
{"ts":"2026-08-24T20:48:15.478Z","event_type":"best_bid_ask","market_id":"3824760","outcome_index":0,"market_type":"set2","local_side":"home","local_uid":"2026-08-24_jazmin_ortenzi_himeno_sakatsume","bid":0.19,"ask":0.3,"mid":0.245,"spread":0.11,"bid_size":null,"ask_size":null}
{"ts":"2026-08-24T20:48:15.478Z","event_type":"best_bid_ask","market_id":"3824760","outcome_index":1,"market_type":"set2","local_side":"away","local_uid":"2026-08-24_jazmin_ortenzi_himeno_sakatsume","bid":0.7,"ask":0.81,"mid":0.755,"spread":0.11,"bid_size":null,"ask_size":null}
{"ts":"2026-08-24T20:48:15.478Z","event_type":"price_change","market_id":"3824760","outcome_index":0,"market_type":"set2","local_side":"home","local_uid":"2026-08-24_jazmin_ortenzi_himeno_sakatsume","bid":0.19,"ask":0.3,"mid":0.245,"spread":0.11,"price":0.2,"size":0.0,"side":"BUY"}
{"ts":"2026-08-24T20:48:15.479Z","event_type":"price_change","market_id":"3824760","outcome_index":1,"market_type":"set2","local_side":"away","local_uid":"2026-08-24_jazmin_ortenzi_himeno_sakatsume","bid":0.7,"ask":0.81,"mid":0.755,"spread":0.11,"price":0.8,"size":0.0,"side":"SELL"}
{"ts":"2026-08-24T20:48:15.479Z","event_type":"best_bid_ask","market_id":"3824760","outcome_index":0,"market_type":"set2","local_side":"home","local_uid":"2026-08-24_jazmin_ortenzi_himeno_sakatsume","bid":0.2,"ask":0.3,"mid":0.25,"spread":0.1,"bid_size":null,"ask_size":null}
{"ts":"2026-08-24T20:48:15.479Z","event_type":"best_bid_ask","market_id":"3824760","outcome_index":1,"market_type":"set2","local_side":"away","local_uid":"2026-08-24_jazmin_ortenzi_himeno_sakatsume","bid":0.7,"ask":0.8,"mid":0.75,"spread":0.1,"bid_size":null,"ask_size":null}
{"ts":"2026-08-24T20:48:15.480Z","event_type":"price_change","market_id":"3824760","outcome_index":0,"market_type":"set2","local_side":"home","local_uid":"2026-08-24_jazmin_ortenzi_himeno_sakatsume","bid":0.2,"ask":0.3,"mid":0.25,"spread":0.1,"price":0.2,"size":25.0,"side":"BUY"}
{"ts":"2026-08-24T20:48:15.480Z","event_type":"price_change","market_id":"3824760","outcome_index":1,"market_type":"set2","local_side":"away","local_uid":"2026-08-24_jazmin_ortenzi_himeno_sakatsume","bid":0.7,"ask":0.8,"mid":0.75,"spread":0.1,"price":0.8,"size":25.0,"side":"SELL"}
{"ts":"2026-08-24T20:48:15.482Z","event_type":"best_bid_ask","market_id":"3824761","outcome_index":0,"market_type":"set1","local_side":"home","local_uid":"2026-08-24_jazmin_ortenzi_himeno_sakatsume","bid":0.16,"ask":0.25,"mid":0.205,"spread":0.09,"bid_size":null,"ask_size":null}
{"ts":"2026-08-24T20:48:15.482Z","event_type":"best_bid_ask","market_id":"3824761","outcome_index":1,"market_type":"set1","local_side":"away","local_uid":"2026-08-24_jazmin_ortenzi_himeno_sakatsume","bid":0.75,"ask":0.84,"mid":0.795,"spread":0.09,"bid_size":null,"ask_size":null}
{"ts":"2026-08-24T20:48:15.482Z","event_type":"price_change","market_id":"3824761","outcome_index":0,"market_type":"set1","local_side":"home","local_uid":"2026-08-24_jazmin_ortenzi_himeno_sakatsume","bid":0.16,"ask":0.25,"mid":0.205,"spread":0.09,"price":0.17,"size":0.0,"side":"BUY"}
{"ts":"2026-08-24T20:48:15.483Z","event_type":"price_change","market_id":"3824761","outcome_index":1,"market_type":"set1","local_side":"away","local_uid":"2026-08-24_jazmin_ortenzi_himeno_sakatsume","bid":0.75,"ask":0.84,"mid":0.795,"spread":0.09,"price":0.83,"size":0.0,"side":"SELL"}
{"ts":"2026-08-24T20:48:15.643Z","event_type":"best_bid_ask","market_id":"3823659","outcome_index":0,"market_type":"match","local_side":"home","local_uid":"2026-08-24_victoria_jimenez_kasintseva_francisca_jorge","bid":0.36,"ask":0.38,"mid":0.37,"spread":0.02,"bid_size":null,"ask_size":null}
{"ts":"2026-08-24T20:48:15.644Z","event_type":"best_bid_ask","market_id":"3823659","outcome_index":1,"market_type":"match","local_side":"away","local_uid":"2026-08-24_victoria_jimenez_kasintseva_francisca_jorge","bid":0.62,"ask":0.64,"mid":0.63,"spread":0.02,"bid_size":null,"ask_size":null}
{"ts":"2026-08-24T20:48:15.644Z","event_type":"price_change","market_id":"3823659","outcome_index":0,"market_type":"match","local_side":"home","local_uid":"2026-08-24_victoria_jimenez_kasintseva_francisca_jorge","bid":0.36,"ask":0.38,"mid":0.37,"spread":0.02,"price":0.37,"size":0.0,"side":"BUY"}
{"ts":"2026-08-24T20:48:15.644Z","event_type":"price_change","market_id":"3823659","outcome_index":1,"market_type":"match","local_side":"away","local_uid":"2026-08-24_victoria_jimenez_kasintseva_francisca_jorge","bid":0.62,"ask":0.64,"mid":0.63,"spread":0.02,"price":0.63,"size":0.0,"side":"SELL"}
{"ts":"2026-08-24T20:48:15.747Z","event_type":"best_bid_ask","market_id":"3824796","outcome_index":0,"market_type":"set2","local_side":"home","local_uid":"2026-08-24_victoria_jimenez_kasintseva_francisca_jorge","bid":0.46,"ask":0.6,"mid":0.53,"spread":0.14,"bid_size":null,"ask_size":null}
{"ts":"2026-08-24T20:48:15.748Z","event_type":"best_bid_ask","market_id":"3824796","outcome_index":1,"market_type":"set2","local_side":"away","local_uid":"2026-08-24_victoria_jimenez_kasintseva_francisca_jorge","bid":0.4,"ask":0.54,"mid":0.47,"spread":0.14,"bid_size":null,"ask_size":null}
{"ts":"2026-08-24T20:48:15.748Z","event_type":"price_change","market_id":"3824796","outcome_index":1,"market_type":"set2","local_side":"away","local_uid":"2026-08-24_victoria_jimenez_kasintseva_francisca_jorge","bid":0.4,"ask":0.54,"mid":0.47,"spread":0.14,"price":0.4,"size":423.0,"side":"BUY"}
{"ts":"2026-08-24T20:48:15.748Z","event_type":"price_change","market_id":"3824796","outcome_index":0,"market_type":"set2","local_side":"home","local_uid":"2026-08-24_victoria_jimenez_kasintseva_francisca_jorge","bid":0.46,"ask":0.6,"mid":0.53,"spread":0.14,"price":0.6,"size":423.0,"side":"SELL"}
{"ts":"2026-08-24T20:48:15.749Z","event_type":"best_bid_ask","market_id":"3824796","outcome_index":0,"market_type":"set2","local_side":"home","local_uid":"2026-08-24_victoria_jimenez_kasintseva_francisca_jorge","bid":0.46,"ask":0.59,"mid":0.525,"spread":0.13,"bid_size":null,"ask_size":null}
{"ts":"2026-08-24T20:48:15.749Z","event_type":"best_bid_ask","market_id":"3824796","outcome_index":1,"market_type":"set2","local_side":"away","local_uid":"2026-08-24_victoria_jimenez_kasintseva_francisca_jorge","bid":0.41,"ask":0.54,"mid":0.475,"spread":0.13,"bid_size":null,"ask_size":null}
{"ts":"2026-08-24T20:48:15.749Z","event_type":"price_change","market_id":"3824796","outcome_index":1,"market_type":"set2","local_side":"away","local_uid":"2026-08-24_victoria_jimenez_kasintseva_francisca_jorge","bid":0.41,"ask":0.54,"mid":0.475,"spread":0.13,"price":0.41,"size":88.0,"side":"BUY"}
{"ts":"2026-08-24T20:48:15.749Z","event_type":"price_change","market_id":"3824796","outcome_index":0,"market_type":"set2","local_side":"home","local_uid":"2026-08-24_victoria_jimenez_kasintseva_francisca_jorge","bid":0.46,"ask":0.59,"mid":0.525,"spread":0.13,"price":0.59,"size":88.0,"side":"SELL"}
{"ts":"2026-08-24T20:48:15.753Z","event_type":"best_bid_ask","market_id":"3823659","outcome_index":0,"market_type":"match","local_side":"home","local_uid":"2026-08-24_victoria_jimenez_kasintseva_francisca_jorge","bid":0.36,"ask":0.37,"mid":0.365,"spread":0.01,"bid_size":null,"ask_size":null}
{"ts":"2026-08-24T20:48:15.754Z","event_type":"best_bid_ask","market_id":"3823659","outcome_index":1,"market_type":"match","local_side":"away","local_uid":"2026-08-24_victoria_jimenez_kasintseva_francisca_jorge","bid":0.63,"ask":0.64,"mid":0.635,"spread":0.01,"bid_size":null,"ask_size":null}
{"ts":"2026-08-24T20:48:15.754Z","event_type":"price_change","market_id":"3823659","outcome_index":1,"market_type":"match","local_side":"away","local_uid":"2026-08-24_victoria_jimenez_kasintseva_francisca_jorge","bid":0.63,"ask":0.64,"mid":0.635,"spread":0.01,"price":0.63,"size":148.0,"side":"BUY"}
{"ts":"2026-08-24T20:48:15.754Z","event_type":"price_change","market_id":"3823659","outcome_index":0,"market_type":"match","local_side":"home","local_uid":"2026-08-24_victoria_jimenez_kasintseva_francisca_jorge","bid":0.36,"ask":0.37,"mid":0.365,"spread":0.01,"price":0.37,"size":148.0,"side":"SELL"}
{"ts":"2026-08-24T20:48:15.806Z","event_type":"best_bid_ask","market_id":"3824796","outcome_index":0,"market_type":"set2","local_side":"home","local_uid":"2026-08-24_victoria_jimenez_kasintseva_francisca_jorge","bid":0.46,"ask":0.58,"mid":0.52,"spread":0.12,"bid_size":null,"ask_size":null}
{"ts":"2026-08-24T20:48:15.806Z","event_type":"best_bid_ask","market_id":"3824796","outcome_index":1,"market_type":"set2","local_side":"away","local_uid":"2026-08-24_victoria_jimenez_kasintseva_francisca_jorge","bid":0.42,"ask":0.54,"mid":0.48,"spread":0.12,"bid_size":null,"ask_size":null}
{"ts":"2026-08-24T20:48:15.807Z","event_type":"price_change","market_id":"3824796","outcome_index":1,"market_type":"set2","local_side":"away","local_uid":"2026-08-24_victoria_jimenez_kasintseva_francisca_jorge","bid":0.42,"ask":0.54,"mid":0.48,"spread":0.12,"price":0.42,"size":150.0,"side":"BUY"}
{"ts":"2026-08-24T20:48:15.807Z","event_type":"price_change","market_id":"3824796","outcome_index":0,"market_type":"set2","local_side":"home","local_uid":"2026-08-24_victoria_jimenez_kasintseva_francisca_jorge","bid":0.46,"ask":0.58,"mid":0.52,"spread":0.12,"price":0.58,"size":150.0,"side":"SELL"}
{"ts":"2026-08-24T20:48:15.855Z","event_type":"best_bid_ask","market_id":"3826738","outcome_index":0,"market_type":"set2","local_side":"home","local_uid":"2026-08-24_harry_wendelken_stefano_travaglia","bid":0.49,"ask":0.6,"mid":0.545,"spread":0.11,"bid_size":null,"ask_size":null}
{"ts":"2026-08-24T20:48:15.856Z","event_type":"best_bid_ask","market_id":"3826738","outcome_index":1,"market_type":"set2","local_side":"away","local_uid":"2026-08-24_harry_wendelken_stefano_travaglia","bid":0.4,"ask":0.51,"mid":0.455,"spread":0.11,"bid_size":null,"ask_size":null}
{"ts":"2026-08-24T20:48:15.856Z","event_type":"price_change","market_id":"3826738","outcome_index":0,"market_type":"set2","local_side":"home","local_uid":"2026-08-24_harry_wendelken_stefano_travaglia","bid":0.49,"ask":0.6,"mid":0.545,"spread":0.11,"price":0.49,"size":42.8,"side":"BUY"}
{"ts":"2026-08-24T20:48:15.856Z","event_type":"price_change","market_id":"3826738","outcome_index":1,"market_type":"set2","local_side":"away","local_uid":"2026-08-24_harry_wendelken_stefano_travaglia","bid":0.4,"ask":0.51,"mid":0.455,"spread":0.11,"price":0.51,"size":42.8,"side":"SELL"}
{"ts":"2026-08-24T20:48:15.889Z","event_type":"best_bid_ask","market_id":"3826738","outcome_index":0,"market_type":"set2","local_side":"home","local_uid":"2026-08-24_harry_wendelken_stefano_travaglia","bid":0.48,"ask":0.6,"mid":0.54,"spread":0.12,"bid_size":null,"ask_size":null}
{"ts":"2026-08-24T20:48:15.890Z","event_type":"best_bid_ask","market_id":"3826738","outcome_index":1,"market_type":"set2","local_side":"away","local_uid":"2026-08-24_harry_wendelken_stefano_travaglia","bid":0.4,"ask":0.52,"mid":0.46,"spread":0.12,"bid_size":null,"ask_size":null}
{"ts":"2026-08-24T20:48:15.890Z","event_type":"price_change","market_id":"3826738","outcome_index":0,"market_type":"set2","local_side":"home","local_uid":"2026-08-24_harry_wendelken_stefano_travaglia","bid":0.48,"ask":0.6,"mid":0.54,"spread":0.12,"price":0.49,"size":0.0,"side":"BUY"}
{"ts":"2026-08-24T20:48:15.890Z","event_type":"price_change","market_id":"3826738","outcome_index":1,"market_type":"set2","local_side":"away","local_uid":"2026-08-24_harry_wendelken_stefano_travaglia","bid":0.4,"ask":0.52,"mid":0.46,"spread":0.12,"price":0.51,"size":0.0,"side":"SELL"}
{"ts":"2026-08-24T20:48:15.895Z","event_type":"best_bid_ask","market_id":"3823659","outcome_index":0,"market_type":"match","local_side":"home","local_uid":"2026-08-24_victoria_jimenez_kasintseva_francisca_jorge","bid":0.34,"ask":0.37,"mid":0.355,"spread":0.03,"bid_size":null,"ask_size":null}
{"ts":"2026-08-24T20:48:15.895Z","event_type":"best_bid_ask","market_id":"3823659","outcome_index":1,"market_type":"match","local_side":"away","local_uid":"2026-08-24_victoria_jimenez_kasintseva_francisca_jorge","bid":0.63,"ask":0.66,"mid":0.645,"spread":0.03,"bid_size":null,"ask_size":null}
{"ts":"2026-08-24T20:48:15.896Z","event_type":"price_change","market_id":"3823659","outcome_index":0,"market_type":"match","local_side":"home","local_uid":"2026-08-24_victoria_jimenez_kasintseva_francisca_jorge","bid":0.34,"ask":0.37,"mid":0.355,"spread":0.03,"price":0.36,"size":0.0,"side":"BUY"}
{"ts":"2026-08-24T20:48:15.896Z","event_type":"price_change","market_id":"3823659","outcome_index":1,"market_type":"match","local_side":"away","local_uid":"2026-08-24_victoria_jimenez_kasintseva_francisca_jorge","bid":0.63,"ask":0.66,"mid":0.645,"spread":0.03,"price":0.64,"size":0.0,"side":"SELL"}
{"ts":"2026-08-24T20:48:15.896Z","event_type":"best_bid_ask","market_id":"3823659","outcome_index":0,"market_type":"match","local_side":"home","local_uid":"2026-08-24_victoria_jimenez_kasintseva_francisca_jorge","bid":0.33,"ask":0.37,"mid":0.35,"spread":0.04,"bid_size":null,"ask_size":null}
{"ts":"2026-08-24T20:48:15.896Z","event_type":"best_bid_ask","market_id":"3823659","outcome_index":1,"market_type":"match","local_side":"away","local_uid":"2026-08-24_victoria_jimenez_kasintseva_francisca_jorge","bid":0.63,"ask":0.67,"mid":0.65,"spread":0.04,"bid_size":null,"ask_size":null}
{"ts":"2026-08-24T20:48:15.897Z","event_type":"price_change","market_id":"3823659","outcome_index":0,"market_type":"match","local_side":"home","local_uid":"2026-08-24_victoria_jimenez_kasintseva_francisca_jorge","bid":0.33,"ask":0.37,"mid":0.35,"spread":0.04,"price":0.34,"size":0.0,"side":"BUY"}
{"ts":"2026-08-24T20:48:15.897Z","event_type":"price_change","market_id":"3823659","outcome_index":1,"market_type":"match","local_side":"away","local_uid":"2026-08-24_victoria_jimenez_kasintseva_francisca_jorge","bid":0.63,"ask":0.67,"mid":0.65,"spread":0.04,"price":0.66,"size":0.0,"side":"SELL"}
{"ts":"2026-08-24T20:48:15.897Z","event_type":"best_bid_ask","market_id":"3823659","outcome_index":0,"market_type":"match","local_side":"home","local_uid":"2026-08-24_victoria_jimenez_kasintseva_francisca_jorge","bid":0.35,"ask":0.37,"mid":0.36,"spread":0.02,"bid_size":null,"ask_size":null}
{"ts":"2026-08-24T20:48:15.898Z","event_type":"best_bid_ask","market_id":"3823659","outcome_index":1,"market_type":"match","local_side":"away","local_uid":"2026-08-24_victoria_jimenez_kasintseva_francisca_jorge","bid":0.63,"ask":0.65,"mid":0.64,"spread":0.02,"bid_size":null,"ask_size":null}
{"ts":"2026-08-24T20:48:15.898Z","event_type":"price_change","market_id":"3823659","outcome_index":0,"market_type":"match","local_side":"home","local_uid":"2026-08-24_victoria_jimenez_kasintseva_francisca_jorge","bid":0.35,"ask":0.37,"mid":0.36,"spread":0.02,"price":0.35,"size":20.0,"side":"BUY"}
{"ts":"2026-08-24T20:48:15.898Z","event_type":"price_change","market_id":"3823659","outcome_index":1,"market_type":"match","local_side":"away","local_uid":"2026-08-24_victoria_jimenez_kasintseva_francisca_jorge","bid":0.63,"ask":0.65,"mid":0.64,"spread":0.02,"price":0.65,"size":20.0,"side":"SELL"}
{"ts":"2026-08-24T20:48:15.910Z","event_type":"best_bid_ask","market_id":"3823659","outcome_index":0,"market_type":"match","local_side":"home","local_uid":"2026-08-24_victoria_jimenez_kasintseva_francisca_jorge","bid":0.35,"ask":0.36,"mid":0.355,"spread":0.01,"bid_size":null,"ask_size":null}
{"ts":"2026-08-24T20:48:15.911Z","event_type":"best_bid_ask","market_id":"3823659","outcome_index":1,"market_type":"match","local_side":"away","local_uid":"2026-08-24_victoria_jimenez_kasintseva_francisca_jorge","bid":0.64,"ask":0.65,"mid":0.645,"spread":0.01,"bid_size":null,"ask_size":null}
{"ts":"2026-08-24T20:48:15.911Z","event_type":"price_change","market_id":"3823659","outcome_index":1,"market_type":"match","local_side":"away","local_uid":"2026-08-24_victoria_jimenez_kasintseva_francisca_jorge","bid":0.64,"ask":0.65,"mid":0.645,"spread":0.01,"price":0.64,"size":100.0,"side":"BUY"}
{"ts":"2026-08-24T20:48:15.911Z","event_type":"price_change","market_id":"3823659","outcome_index":0,"market_type":"match","local_side":"home","local_uid":"2026-08-24_victoria_jimenez_kasintseva_francisca_jorge","bid":0.35,"ask":0.36,"mid":0.355,"spread":0.01,"price":0.36,"size":100.0,"side":"SELL"}
{"ts":"2026-08-24T20:48:15.989Z","event_type":"best_bid_ask","market_id":"3823659","outcome_index":0,"market_type":"match","local_side":"home","local_uid":"2026-08-24_victoria_jimenez_kasintseva_francisca_jorge","bid":0.34,"ask":0.36,"mid":0.35,"spread":0.02,"bid_size":null,"ask_size":null}
{"ts":"2026-08-24T20:48:15.989Z","event_type":"best_bid_ask","market_id":"3823659","outcome_index":1,"market_type":"match","local_side":"away","local_uid":"2026-08-24_victoria_jimenez_kasintseva_francisca_jorge","bid":0.64,"ask":0.66,"mid":0.65,"spread":0.02,"bid_size":null,"ask_size":null}
{"ts":"2026-08-24T20:48:15.990Z","event_type":"price_change","market_id":"3823659","outcome_index":0,"market_type":"match","local_side":"home","local_uid":"2026-08-24_victoria_jimenez_kasintseva_francisca_jorge","bid":0.34,"ask":0.36,"mid":0.35,"spread":0.02,"price":0.35,"size":0.0,"side":"BUY"}
{"ts":"2026-08-24T20:48:15.990Z","event_type":"price_change","market_id":"3823659","outcome_index":1,"market_type":"match","local_side":"away","local_uid":"2026-08-24_victoria_jimenez_kasintseva_francisca_jorge","bid":0.64,"ask":0.66,"mid":0.65,"spread":0.02,"price":0.65,"size":0.0,"side":"SELL"}
{"ts":"2026-08-24T20:48:16.031Z","event_type":"best_bid_ask","market_id":"3823659","outcome_index":0,"market_type":"match","local_side":"home","local_uid":"2026-08-24_victoria_jimenez_kasintseva_francisca_jorge","bid":0.34,"ask":0.35,"mid":0.345,"spread":0.01,"bid_size":null,"ask_size":null}
{"ts":"2026-08-24T20:48:16.032Z","event_type":"best_bid_ask","market_id":"3823659","outcome_index":1,"market_type":"match","local_side":"away","local_uid":"2026-08-24_victoria_jimenez_kasintseva_francisca_jorge","bid":0.65,"ask":0.66,"mid":0.655,"spread":0.01,"bid_size":null,"ask_size":null}
{"ts":"2026-08-24T20:48:16.032Z","event_type":"price_change","market_id":"3823659","outcome_index":1,"market_type":"match","local_side":"away","local_uid":"2026-08-24_victoria_jimenez_kasintseva_francisca_jorge","bid":0.65,"ask":0.66,"mid":0.655,"spread":0.01,"price":0.65,"size":175.0,"side":"BUY"}
{"ts":"2026-08-24T20:48:16.032Z","event_type":"price_change","market_id":"3823659","outcome_index":0,"market_type":"match","local_side":"home","local_uid":"2026-08-24_victoria_jimenez_kasintseva_francisca_jorge","bid":0.34,"ask":0.35,"mid":0.345,"spread":0.01,"price":0.35,"size":175.0,"side":"SELL"}
{"ts":"2026-08-24T20:48:16.214Z","event_type":"price_change","market_id":"3826636","outcome_index":1,"market_type":"set1","local_side":"away","local_uid":"2026-08-24_felix_balshaw_aleksandar_kovacevic","bid":0.6,"ask":0.63,"mid":0.615,"spread":0.03,"price":0.49,"size":2000.0,"side":"BUY"}
{"ts":"2026-08-24T20:48:16.215Z","event_type":"price_change","market_id":"3826636","outcome_index":0,"market_type":"set1","local_side":"home","local_uid":"2026-08-24_felix_balshaw_aleksandar_kovacevic","bid":0.37,"ask":0.4,"mid":0.385,"spread":0.03,"price":0.51,"size":2000.0,"side":"SELL"}
{"ts":"2026-08-24T20:48:16.290Z","event_type":"best_bid_ask","market_id":"3823659","outcome_index":0,"market_type":"match","local_side":"home","local_uid":"2026-08-24_victoria_jimenez_kasintseva_francisca_jorge","bid":0.33,"ask":0.35,"mid":0.34,"spread":0.02,"bid_size":null,"ask_size":null}
{"ts":"2026-08-24T20:48:16.291Z","event_type":"best_bid_ask","market_id":"3823659","outcome_index":1,"market_type":"match","local_side":"away","local_uid":"2026-08-24_victoria_jimenez_kasintseva_francisca_jorge","bid":0.65,"ask":0.67,"mid":0.66,"spread":0.02,"bid_size":null,"ask_size":null}
{"ts":"2026-08-24T20:48:16.291Z","event_type":"price_change","market_id":"3823659","outcome_index":0,"market_type":"match","local_side":"home","local_uid":"2026-08-24_victoria_jimenez_kasintseva_francisca_jorge","bid":0.33,"ask":0.35,"mid":0.34,"spread":0.02,"price":0.34,"size":0.0,"side":"BUY"}
{"ts":"2026-08-24T20:48:16.291Z","event_type":"price_change","market_id":"3823659","outcome_index":1,"market_type":"match","local_side":"away","local_uid":"2026-08-24_victoria_jimenez_kasintseva_francisca_jorge","bid":0.65,"ask":0.67,"mid":0.66,"spread":0.02,"price":0.66,"size":0.0,"side":"SELL"}
{"ts":"2026-08-24T20:48:16.292Z","event_type":"book","market_id":"3823659","outcome_index":0,"market_type":"match","local_side":"home","local_uid":"2026-08-24_victoria_jimenez_kasintseva_francisca_jorge","bid":0.33,"ask":0.35,"mid":0.34,"spread":0.02,"bid_size":130.0,"ask_size":16744.32}
{"ts":"2026-08-24T20:48:16.293Z","event_type":"book","market_id":"3823659","outcome_index":1,"market_type":"match","local_side":"away","local_uid":"2026-08-24_victoria_jimenez_kasintseva_francisca_jorge","bid":0.65,"ask":0.67,"mid":0.66,"spread":0.02,"bid_size":16744.32,"ask_size":130.0}
{"ts":"2026-08-24T20:48:16.302Z","event_type":"last_trade_price","market_id":"3823659","outcome_index":1,"market_type":"match","local_side":"away","local_uid":"2026-08-24_victoria_jimenez_kasintseva_francisca_jorge","last_trade":0.66,"trade_size":20.0,"trade_side":"BUY","trade_notional":13.2}
{"ts":"2026-08-24T20:48:16.303Z","event_type":"best_bid_ask","market_id":"3823659","outcome_index":0,"market_type":"match","local_side":"home","local_uid":"2026-08-24_victoria_jimenez_kasintseva_francisca_jorge","bid":0.32,"ask":0.35,"mid":0.335,"spread":0.03,"bid_size":null,"ask_size":null}
{"ts":"2026-08-24T20:48:16.304Z","event_type":"best_bid_ask","market_id":"3823659","outcome_index":1,"market_type":"match","local_side":"away","local_uid":"2026-08-24_victoria_jimenez_kasintseva_francisca_jorge","bid":0.65,"ask":0.68,"mid":0.665,"spread":0.03,"bid_size":null,"ask_size":null}
{"ts":"2026-08-24T20:48:16.304Z","event_type":"price_change","market_id":"3823659","outcome_index":0,"market_type":"match","local_side":"home","local_uid":"2026-08-24_victoria_jimenez_kasintseva_francisca_jorge","bid":0.32,"ask":0.35,"mid":0.335,"spread":0.03,"price":0.33,"size":0.0,"side":"BUY"}
{"ts":"2026-08-24T20:48:16.304Z","event_type":"price_change","market_id":"3823659","outcome_index":1,"market_type":"match","local_side":"away","local_uid":"2026-08-24_victoria_jimenez_kasintseva_francisca_jorge","bid":0.65,"ask":0.68,"mid":0.665,"spread":0.03,"price":0.67,"size":0.0,"side":"SELL"}
{"ts":"2026-08-24T20:48:16.322Z","event_type":"best_bid_ask","market_id":"3823659","outcome_index":0,"market_type":"match","local_side":"home","local_uid":"2026-08-24_victoria_jimenez_kasintseva_francisca_jorge","bid":0.32,"ask":0.34,"mid":0.33,"spread":0.02,"bid_size":null,"ask_size":null}
{"ts":"2026-08-24T20:48:16.322Z","event_type":"best_bid_ask","market_id":"3823659","outcome_index":1,"market_type":"match","local_side":"away","local_uid":"2026-08-24_victoria_jimenez_kasintseva_francisca_jorge","bid":0.66,"ask":0.68,"mid":0.67,"spread":0.02,"bid_size":null,"ask_size":null}
{"ts":"2026-08-24T20:48:16.325Z","event_type":"price_change","market_id":"3823659","outcome_index":1,"market_type":"match","local_side":"away","local_uid":"2026-08-24_victoria_jimenez_kasintseva_francisca_jorge","bid":0.66,"ask":0.68,"mid":0.67,"spread":0.02,"price":0.66,"size":194.31,"side":"BUY"}
{"ts":"2026-08-24T20:48:16.325Z","event_type":"price_change","market_id":"3823659","outcome_index":0,"market_type":"match","local_side":"home","local_uid":"2026-08-24_victoria_jimenez_kasintseva_francisca_jorge","bid":0.32,"ask":0.34,"mid":0.33,"spread":0.02,"price":0.34,"size":194.31,"side":"SELL"}
{"ts":"2026-08-24T20:48:16.395Z","event_type":"best_bid_ask","market_id":"3824761","outcome_index":0,"market_type":"set1","local_side":"home","local_uid":"2026-08-24_jazmin_ortenzi_himeno_sakatsume","bid":0.14,"ask":0.28,"mid":0.21,"spread":0.14,"bid_size":null,"ask_size":null}
{"ts":"2026-08-24T20:48:16.396Z","event_type":"best_bid_ask","market_id":"3824761","outcome_index":1,"market_type":"set1","local_side":"away","local_uid":"2026-08-24_jazmin_ortenzi_himeno_sakatsume","bid":0.72,"ask":0.86,"mid":0.79,"spread":0.14,"bid_size":null,"ask_size":null}
{"ts":"2026-08-24T20:48:16.396Z","event_type":"price_change","market_id":"3824761","outcome_index":1,"market_type":"set1","local_side":"away","local_uid":"2026-08-24_jazmin_ortenzi_himeno_sakatsume","bid":0.72,"ask":0.86,"mid":0.79,"spread":0.14,"price":0.75,"size":0.0,"side":"BUY"}
{"ts":"2026-08-24T20:48:16.397Z","event_type":"price_change","market_id":"3824761","outcome_index":0,"market_type":"set1","local_side":"home","local_uid":"2026-08-24_jazmin_ortenzi_himeno_sakatsume","bid":0.14,"ask":0.28,"mid":0.21,"spread":0.14,"price":0.25,"size":0.0,"side":"SELL"}
{"ts":"2026-08-24T20:48:16.436Z","event_type":"best_bid_ask","market_id":"3825604","outcome_index":0,"market_type":"match","local_side":"home","local_uid":"2026-08-24_dalibor_svrcina_felipe_meligeni_alves","bid":0.78,"ask":0.83,"mid":0.805,"spread":0.05,"bid_size":null,"ask_size":null}
{"ts":"2026-08-24T20:48:16.437Z","event_type":"best_bid_ask","market_id":"3825604","outcome_index":1,"market_type":"match","local_side":"away","local_uid":"2026-08-24_dalibor_svrcina_felipe_meligeni_alves","bid":0.17,"ask":0.22,"mid":0.195,"spread":0.05,"bid_size":null,"ask_size":null}
{"ts":"2026-08-24T20:48:16.437Z","event_type":"price_change","market_id":"3825604","outcome_index":1,"market_type":"match","local_side":"away","local_uid":"2026-08-24_dalibor_svrcina_felipe_meligeni_alves","bid":0.17,"ask":0.22,"mid":0.195,"spread":0.05,"price":0.17,"size":116.0,"side":"BUY"}
{"ts":"2026-08-24T20:48:16.437Z","event_type":"price_change","market_id":"3825604","outcome_index":0,"market_type":"match","local_side":"home","local_uid":"2026-08-24_dalibor_svrcina_felipe_meligeni_alves","bid":0.78,"ask":0.83,"mid":0.805,"spread":0.05,"price":0.83,"size":116.0,"side":"SELL"}
{"ts":"2026-08-24T20:48:16.486Z","event_type":"best_bid_ask","market_id":"3823659","outcome_index":0,"market_type":"match","local_side":"home","local_uid":"2026-08-24_victoria_jimenez_kasintseva_francisca_jorge","bid":0.32,"ask":0.33,"mid":0.325,"spread":0.01,"bid_size":null,"ask_size":null}
{"ts":"2026-08-24T20:48:16.486Z","event_type":"best_bid_ask","market_id":"3823659","outcome_index":1,"market_type":"match","local_side":"away","local_uid":"2026-08-24_victoria_jimenez_kasintseva_francisca_jorge","bid":0.67,"ask":0.68,"mid":0.675,"spread":0.01,"bid_size":null,"ask_size":null}
{"ts":"2026-08-24T20:48:16.486Z","event_type":"price_change","market_id":"3823659","outcome_index":1,"market_type":"match","local_side":"away","local_uid":"2026-08-24_victoria_jimenez_kasintseva_francisca_jorge","bid":0.67,"ask":0.68,"mid":0.675,"spread":0.01,"price":0.67,"size":3217.91,"side":"BUY"}
{"ts":"2026-08-24T20:48:16.487Z","event_type":"price_change","market_id":"3823659","outcome_index":0,"market_type":"match","local_side":"home","local_uid":"2026-08-24_victoria_jimenez_kasintseva_francisca_jorge","bid":0.32,"ask":0.33,"mid":0.325,"spread":0.01,"price":0.33,"size":3217.91,"side":"SELL"}
{"ts":"2026-08-24T20:48:16.556Z","event_type":"best_bid_ask","market_id":"3824761","outcome_index":0,"market_type":"set1","local_side":"home","local_uid":"2026-08-24_jazmin_ortenzi_himeno_sakatsume","bid":0.14,"ask":0.31,"mid":0.225,"spread":0.17,"bid_size":null,"ask_size":null}
{"ts":"2026-08-24T20:48:16.556Z","event_type":"best_bid_ask","market_id":"3824761","outcome_index":1,"market_type":"set1","local_side":"away","local_uid":"2026-08-24_jazmin_ortenzi_himeno_sakatsume","bid":0.69,"ask":0.86,"mid":0.775,"spread":0.17,"bid_size":null,"ask_size":null}
{"ts":"2026-08-24T20:48:16.557Z","event_type":"price_change","market_id":"3824761","outcome_index":1,"market_type":"set1","local_side":"away","local_uid":"2026-08-24_jazmin_ortenzi_himeno_sakatsume","bid":0.69,"ask":0.86,"mid":0.775,"spread":0.17,"price":0.72,"size":0.0,"side":"BUY"}
{"ts":"2026-08-24T20:48:16.557Z","event_type":"price_change","market_id":"3824761","outcome_index":0,"market_type":"set1","local_side":"home","local_uid":"2026-08-24_jazmin_ortenzi_himeno_sakatsume","bid":0.14,"ask":0.31,"mid":0.225,"spread":0.17,"price":0.28,"size":0.0,"side":"SELL"}
{"ts":"2026-08-24T20:48:16.571Z","event_type":"best_bid_ask","market_id":"3826919","outcome_index":0,"market_type":"set2","local_side":"home","local_uid":"2026-08-24_dalibor_svrcina_felipe_meligeni_alves","bid":0.44,"ask":0.54,"mid":0.49,"spread":0.1,"bid_size":null,"ask_size":null}
{"ts":"2026-08-24T20:48:16.571Z","event_type":"best_bid_ask","market_id":"3826919","outcome_index":1,"market_type":"set2","local_side":"away","local_uid":"2026-08-24_dalibor_svrcina_felipe_meligeni_alves","bid":0.46,"ask":0.56,"mid":0.51,"spread":0.1,"bid_size":null,"ask_size":null}
{"ts":"2026-08-24T20:48:16.572Z","event_type":"price_change","market_id":"3826919","outcome_index":1,"market_type":"set2","local_side":"away","local_uid":"2026-08-24_dalibor_svrcina_felipe_meligeni_alves","bid":0.46,"ask":0.56,"mid":0.51,"spread":0.1,"price":0.46,"size":150.0,"side":"BUY"}
{"ts":"2026-08-24T20:48:16.572Z","event_type":"price_change","market_id":"3826919","outcome_index":0,"market_type":"set2","local_side":"home","local_uid":"2026-08-24_dalibor_svrcina_felipe_meligeni_alves","bid":0.44,"ask":0.54,"mid":0.49,"spread":0.1,"price":0.54,"size":150.0,"side":"SELL"}
{"ts":"2026-08-24T20:48:16.575Z","event_type":"best_bid_ask","market_id":"3825604","outcome_index":0,"market_type":"match","local_side":"home","local_uid":"2026-08-24_dalibor_svrcina_felipe_meligeni_alves","bid":0.78,"ask":0.82,"mid":0.8,"spread":0.04,"bid_size":null,"ask_size":null}
{"ts":"2026-08-24T20:48:16.575Z","event_type":"best_bid_ask","market_id":"3825604","outcome_index":1,"market_type":"match","local_side":"away","local_uid":"2026-08-24_dalibor_svrcina_felipe_meligeni_alves","bid":0.18,"ask":0.22,"mid":0.2,"spread":0.04,"bid_size":null,"ask_size":null}
{"ts":"2026-08-24T20:48:16.575Z","event_type":"price_change","market_id":"3825604","outcome_index":1,"market_type":"match","local_side":"away","local_uid":"2026-08-24_dalibor_svrcina_felipe_meligeni_alves","bid":0.18,"ask":0.22,"mid":0.2,"spread":0.04,"price":0.18,"size":150.0,"side":"BUY"}
{"ts":"2026-08-24T20:48:16.576Z","event_type":"price_change","market_id":"3825604","outcome_index":0,"market_type":"match","local_side":"home","local_uid":"2026-08-24_dalibor_svrcina_felipe_meligeni_alves","bid":0.78,"ask":0.82,"mid":0.8,"spread":0.04,"price":0.82,"size":150.0,"side":"SELL"}
{"ts":"2026-08-24T20:48:16.579Z","event_type":"best_bid_ask","market_id":"3825077","outcome_index":0,"market_type":"set1","local_side":"home","local_uid":"2026-08-24_polina_kudermetova_linda_fruhvirtova","bid":0.45,"ask":0.5,"mid":0.475,"spread":0.05,"bid_size":null,"ask_size":null}
{"ts":"2026-08-24T20:48:16.580Z","event_type":"best_bid_ask","market_id":"3825077","outcome_index":1,"market_type":"set1","local_side":"away","local_uid":"2026-08-24_polina_kudermetova_linda_fruhvirtova","bid":0.5,"ask":0.55,"mid":0.525,"spread":0.05,"bid_size":null,"ask_size":null}
{"ts":"2026-08-24T20:48:16.580Z","event_type":"price_change","market_id":"3825077","outcome_index":1,"market_type":"set1","local_side":"away","local_uid":"2026-08-24_polina_kudermetova_linda_fruhvirtova","bid":0.5,"ask":0.55,"mid":0.525,"spread":0.05,"price":0.5,"size":15.0,"side":"BUY"}
{"ts":"2026-08-24T20:48:16.580Z","event_type":"price_change","market_id":"3825077","outcome_index":0,"market_type":"set1","local_side":"home","local_uid":"2026-08-24_polina_kudermetova_linda_fruhvirtova","bid":0.45,"ask":0.5,"mid":0.475,"spread":0.05,"price":0.5,"size":15.0,"side":"SELL"}
{"ts":"2026-08-24T20:48:16.593Z","event_type":"best_bid_ask","market_id":"3825604","outcome_index":0,"market_type":"match","local_side":"home","local_uid":"2026-08-24_dalibor_svrcina_felipe_meligeni_alves","bid":0.78,"ask":0.81,"mid":0.795,"spread":0.03,"bid_size":null,"ask_size":null}
{"ts":"2026-08-24T20:48:16.593Z","event_type":"best_bid_ask","market_id":"3825604","outcome_index":1,"market_type":"match","local_side":"away","local_uid":"2026-08-24_dalibor_svrcina_felipe_meligeni_alves","bid":0.19,"ask":0.22,"mid":0.205,"spread":0.03,"bid_size":null,"ask_size":null}
{"ts":"2026-08-24T20:48:16.593Z","event_type":"price_change","market_id":"3825604","outcome_index":1,"market_type":"match","local_side":"away","local_uid":"2026-08-24_dalibor_svrcina_felipe_meligeni_alves","bid":0.19,"ask":0.22,"mid":0.205,"spread":0.03,"price":0.19,"size":100.0,"side":"BUY"}
{"ts":"2026-08-24T20:48:16.594Z","event_type":"price_change","market_id":"3825604","outcome_index":0,"market_type":"match","local_side":"home","local_uid":"2026-08-24_dalibor_svrcina_felipe_meligeni_alves","bid":0.78,"ask":0.81,"mid":0.795,"spread":0.03,"price":0.81,"size":100.0,"side":"SELL"}
{"ts":"2026-08-24T20:48:16.667Z","event_type":"best_bid_ask","market_id":"3824761","outcome_index":0,"market_type":"set1","local_side":"home","local_uid":"2026-08-24_jazmin_ortenzi_himeno_sakatsume","bid":0.14,"ask":0.3,"mid":0.22,"spread":0.16,"bid_size":null,"ask_size":null}
{"ts":"2026-08-24T20:48:16.668Z","event_type":"best_bid_ask","market_id":"3824761","outcome_index":1,"market_type":"set1","local_side":"away","local_uid":"2026-08-24_jazmin_ortenzi_himeno_sakatsume","bid":0.7,"ask":0.86,"mid":0.78,"spread":0.16,"bid_size":null,"ask_size":null}
{"ts":"2026-08-24T20:48:16.668Z","event_type":"price_change","market_id":"3824761","outcome_index":1,"market_type":"set1","local_side":"away","local_uid":"2026-08-24_jazmin_ortenzi_himeno_sakatsume","bid":0.7,"ask":0.86,"mid":0.78,"spread":0.16,"price":0.7,"size":250.0,"side":"BUY"}
{"ts":"2026-08-24T20:48:16.668Z","event_type":"price_change","market_id":"3824761","outcome_index":0,"market_type":"set1","local_side":"home","local_uid":"2026-08-24_jazmin_ortenzi_himeno_sakatsume","bid":0.14,"ask":0.3,"mid":0.22,"spread":0.16,"price":0.3,"size":250.0,"side":"SELL"}
{"ts":"2026-08-24T20:48:16.686Z","event_type":"best_bid_ask","market_id":"3825604","outcome_index":0,"market_type":"match","local_side":"home","local_uid":"2026-08-24_dalibor_svrcina_felipe_meligeni_alves","bid":0.78,"ask":0.8,"mid":0.79,"spread":0.02,"bid_size":null,"ask_size":null}
{"ts":"2026-08-24T20:48:16.691Z","event_type":"best_bid_ask","market_id":"3825604","outcome_index":1,"market_type":"match","local_side":"away","local_uid":"2026-08-24_dalibor_svrcina_felipe_meligeni_alves","bid":0.2,"ask":0.22,"mid":0.21,"spread":0.02,"bid_size":null,"ask_size":null}
{"ts":"2026-08-24T20:48:16.692Z","event_type":"price_change","market_id":"3825604","outcome_index":1,"market_type":"match","local_side":"away","local_uid":"2026-08-24_dalibor_svrcina_felipe_meligeni_alves","bid":0.2,"ask":0.22,"mid":0.21,"spread":0.02,"price":0.2,"size":50.0,"side":"BUY"}
{"ts":"2026-08-24T20:48:16.692Z","event_type":"price_change","market_id":"3825604","outcome_index":0,"market_type":"match","local_side":"home","local_uid":"2026-08-24_dalibor_svrcina_felipe_meligeni_alves","bid":0.78,"ask":0.8,"mid":0.79,"spread":0.02,"price":0.8,"size":50.0,"side":"SELL"}
{"ts":"2026-08-24T20:48:16.803Z","event_type":"best_bid_ask","market_id":"3825604","outcome_index":0,"market_type":"match","local_side":"home","local_uid":"2026-08-24_dalibor_svrcina_felipe_meligeni_alves","bid":0.78,"ask":0.79,"mid":0.785,"spread":0.01,"bid_size":null,"ask_size":null}
{"ts":"2026-08-24T20:48:16.804Z","event_type":"best_bid_ask","market_id":"3825604","outcome_index":1,"market_type":"match","local_side":"away","local_uid":"2026-08-24_dalibor_svrcina_felipe_meligeni_alves","bid":0.21,"ask":0.22,"mid":0.215,"spread":0.01,"bid_size":null,"ask_size":null}
{"ts":"2026-08-24T20:48:16.804Z","event_type":"price_change","market_id":"3825604","outcome_index":1,"market_type":"match","local_side":"away","local_uid":"2026-08-24_dalibor_svrcina_felipe_meligeni_alves","bid":0.21,"ask":0.22,"mid":0.215,"spread":0.01,"price":0.21,"size":121.0,"side":"BUY"}
{"ts":"2026-08-24T20:48:16.804Z","event_type":"price_change","market_id":"3825604","outcome_index":0,"market_type":"match","local_side":"home","local_uid":"2026-08-24_dalibor_svrcina_felipe_meligeni_alves","bid":0.78,"ask":0.79,"mid":0.785,"spread":0.01,"price":0.79,"size":121.0,"side":"SELL"}
{"ts":"2026-08-24T20:48:16.827Z","event_type":"best_bid_ask","market_id":"3826919","outcome_index":0,"market_type":"set2","local_side":"home","local_uid":"2026-08-24_dalibor_svrcina_felipe_meligeni_alves","bid":0.44,"ask":0.53,"mid":0.485,"spread":0.09,"bid_size":null,"ask_size":null}
{"ts":"2026-08-24T20:48:16.828Z","event_type":"best_bid_ask","market_id":"3826919","outcome_index":1,"market_type":"set2","local_side":"away","local_uid":"2026-08-24_dalibor_svrcina_felipe_meligeni_alves","bid":0.47,"ask":0.56,"mid":0.515,"spread":0.09,"bid_size":null,"ask_size":null}
{"ts":"2026-08-24T20:48:16.830Z","event_type":"price_change","market_id":"3826919","outcome_index":1,"market_type":"set2","local_side":"away","local_uid":"2026-08-24_dalibor_svrcina_felipe_meligeni_alves","bid":0.47,"ask":0.56,"mid":0.515,"spread":0.09,"price":0.47,"size":150.0,"side":"BUY"}
{"ts":"2026-08-24T20:48:16.830Z","event_type":"price_change","market_id":"3826919","outcome_index":0,"market_type":"set2","local_side":"home","local_uid":"2026-08-24_dalibor_svrcina_felipe_meligeni_alves","bid":0.44,"ask":0.53,"mid":0.485,"spread":0.09,"price":0.53,"size":150.0,"side":"SELL"}
{"ts":"2026-08-24T20:48:16.891Z","event_type":"best_bid_ask","market_id":"3824796","outcome_index":0,"market_type":"set2","local_side":"home","local_uid":"2026-08-24_victoria_jimenez_kasintseva_francisca_jorge","bid":0.46,"ask":0.57,"mid":0.515,"spread":0.11,"bid_size":null,"ask_size":null}
{"ts":"2026-08-24T20:48:16.892Z","event_type":"best_bid_ask","market_id":"3824796","outcome_index":1,"market_type":"set2","local_side":"away","local_uid":"2026-08-24_victoria_jimenez_kasintseva_francisca_jorge","bid":0.43,"ask":0.54,"mid":0.485,"spread":0.11,"bid_size":null,"ask_size":null}
{"ts":"2026-08-24T20:48:16.892Z","event_type":"price_change","market_id":"3824796","outcome_index":1,"market_type":"set2","local_side":"away","local_uid":"2026-08-24_victoria_jimenez_kasintseva_francisca_jorge","bid":0.43,"ask":0.54,"mid":0.485,"spread":0.11,"price":0.43,"size":5.0,"side":"BUY"}
{"ts":"2026-08-24T20:48:16.892Z","event_type":"price_change","market_id":"3824796","outcome_index":0,"market_type":"set2","local_side":"home","local_uid":"2026-08-24_victoria_jimenez_kasintseva_francisca_jorge","bid":0.46,"ask":0.57,"mid":0.515,"spread":0.11,"price":0.57,"size":5.0,"side":"SELL"}
{"ts":"2026-08-24T20:48:16.986Z","event_type":"best_bid_ask","market_id":"3823619","outcome_index":0,"market_type":"match","local_side":"home","local_uid":"2026-08-24_polina_kudermetova_linda_fruhvirtova","bid":0.53,"ask":0.54,"mid":0.535,"spread":0.01,"bid_size":null,"ask_size":null}
{"ts":"2026-08-24T20:48:16.986Z","event_type":"best_bid_ask","market_id":"3823619","outcome_index":1,"market_type":"match","local_side":"away","local_uid":"2026-08-24_polina_kudermetova_linda_fruhvirtova","bid":0.46,"ask":0.47,"mid":0.465,"spread":0.01,"bid_size":null,"ask_size":null}
{"ts":"2026-08-24T20:48:16.987Z","event_type":"price_change","market_id":"3823619","outcome_index":1,"market_type":"match","local_side":"away","local_uid":"2026-08-24_polina_kudermetova_linda_fruhvirtova","bid":0.46,"ask":0.47,"mid":0.465,"spread":0.01,"price":0.46,"size":50.0,"side":"BUY"}
{"ts":"2026-08-24T20:48:16.987Z","event_type":"price_change","market_id":"3823619","outcome_index":0,"market_type":"match","local_side":"home","local_uid":"2026-08-24_polina_kudermetova_linda_fruhvirtova","bid":0.53,"ask":0.54,"mid":0.535,"spread":0.01,"price":0.54,"size":50.0,"side":"SELL"}
{"ts":"2026-08-24T20:48:16.987Z","event_type":"best_bid_ask","market_id":"3826738","outcome_index":0,"market_type":"set2","local_side":"home","local_uid":"2026-08-24_harry_wendelken_stefano_travaglia","bid":0.49,"ask":0.6,"mid":0.545,"spread":0.11,"bid_size":null,"ask_size":null}
{"ts":"2026-08-24T20:48:16.987Z","event_type":"best_bid_ask","market_id":"3826738","outcome_index":1,"market_type":"set2","local_side":"away","local_uid":"2026-08-24_harry_wendelken_stefano_travaglia","bid":0.4,"ask":0.51,"mid":0.455,"spread":0.11,"bid_size":null,"ask_size":null}
{"ts":"2026-08-24T20:48:16.992Z","event_type":"price_change","market_id":"3826738","outcome_index":0,"market_type":"set2","local_side":"home","local_uid":"2026-08-24_harry_wendelken_stefano_travaglia","bid":0.49,"ask":0.6,"mid":0.545,"spread":0.11,"price":0.49,"size":42.8,"side":"BUY"}
{"ts":"2026-08-24T20:48:16.993Z","event_type":"price_change","market_id":"3826738","outcome_index":1,"market_type":"set2","local_side":"away","local_uid":"2026-08-24_harry_wendelken_stefano_travaglia","bid":0.4,"ask":0.51,"mid":0.455,"spread":0.11,"price":0.51,"size":42.8,"side":"SELL"}
{"ts":"2026-08-24T20:48:17.050Z","event_type":"best_bid_ask","market_id":"3826919","outcome_index":0,"market_type":"set2","local_side":"home","local_uid":"2026-08-24_dalibor_svrcina_felipe_meligeni_alves","bid":0.44,"ask":0.52,"mid":0.48,"spread":0.08,"bid_size":null,"ask_size":null}
{"ts":"2026-08-24T20:48:17.051Z","event_type":"best_bid_ask","market_id":"3826919","outcome_index":1,"market_type":"set2","local_side":"away","local_uid":"2026-08-24_dalibor_svrcina_felipe_meligeni_alves","bid":0.48,"ask":0.56,"mid":0.52,"spread":0.08,"bid_size":null,"ask_size":null}
{"ts":"2026-08-24T20:48:17.051Z","event_type":"price_change","market_id":"3826919","outcome_index":1,"market_type":"set2","local_side":"away","local_uid":"2026-08-24_dalibor_svrcina_felipe_meligeni_alves","bid":0.48,"ask":0.56,"mid":0.52,"spread":0.08,"price":0.48,"size":37.88,"side":"BUY"}
{"ts":"2026-08-24T20:48:17.051Z","event_type":"price_change","market_id":"3826919","outcome_index":0,"market_type":"set2","local_side":"home","local_uid":"2026-08-24_dalibor_svrcina_felipe_meligeni_alves","bid":0.44,"ask":0.52,"mid":0.48,"spread":0.08,"price":0.52,"size":37.88,"side":"SELL"}
{"ts":"2026-08-24T20:48:17.070Z","event_type":"best_bid_ask","market_id":"3826738","outcome_index":0,"market_type":"set2","local_side":"home","local_uid":"2026-08-24_harry_wendelken_stefano_travaglia","bid":0.48,"ask":0.6,"mid":0.54,"spread":0.12,"bid_size":null,"ask_size":null}
{"ts":"2026-08-24T20:48:17.070Z","event_type":"best_bid_ask","market_id":"3826738","outcome_index":1,"market_type":"set2","local_side":"away","local_uid":"2026-08-24_harry_wendelken_stefano_travaglia","bid":0.4,"ask":0.52,"mid":0.46,"spread":0.12,"bid_size":null,"ask_size":null}
{"ts":"2026-08-24T20:48:17.073Z","event_type":"price_change","market_id":"3826738","outcome_index":0,"market_type":"set2","local_side":"home","local_uid":"2026-08-24_harry_wendelken_stefano_travaglia","bid":0.48,"ask":0.6,"mid":0.54,"spread":0.12,"price":0.49,"size":0.0,"side":"BUY"}
{"ts":"2026-08-24T20:48:17.073Z","event_type":"price_change","market_id":"3826738","outcome_index":1,"market_type":"set2","local_side":"away","local_uid":"2026-08-24_harry_wendelken_stefano_travaglia","bid":0.4,"ask":0.52,"mid":0.46,"spread":0.12,"price":0.51,"size":0.0,"side":"SELL"}
{"ts":"2026-08-24T20:48:17.104Z","event_type":"best_bid_ask","market_id":"3826919","outcome_index":0,"market_type":"set2","local_side":"home","local_uid":"2026-08-24_dalibor_svrcina_felipe_meligeni_alves","bid":0.43,"ask":0.52,"mid":0.475,"spread":0.09,"bid_size":null,"ask_size":null}
{"ts":"2026-08-24T20:48:17.104Z","event_type":"best_bid_ask","market_id":"3826919","outcome_index":1,"market_type":"set2","local_side":"away","local_uid":"2026-08-24_dalibor_svrcina_felipe_meligeni_alves","bid":0.48,"ask":0.57,"mid":0.525,"spread":0.09,"bid_size":null,"ask_size":null}
{"ts":"2026-08-24T20:48:17.105Z","event_type":"price_change","market_id":"3826919","outcome_index":0,"market_type":"set2","local_side":"home","local_uid":"2026-08-24_dalibor_svrcina_felipe_meligeni_alves","bid":0.43,"ask":0.52,"mid":0.475,"spread":0.09,"price":0.44,"size":0.0,"side":"BUY"}
{"ts":"2026-08-24T20:48:17.105Z","event_type":"price_change","market_id":"3826919","outcome_index":1,"market_type":"set2","local_side":"away","local_uid":"2026-08-24_dalibor_svrcina_felipe_meligeni_alves","bid":0.48,"ask":0.57,"mid":0.525,"spread":0.09,"price":0.56,"size":0.0,"side":"SELL"}
{"ts":"2026-08-24T20:48:17.106Z","event_type":"best_bid_ask","market_id":"3825053","outcome_index":0,"market_type":"set1","local_side":"home","local_uid":"2026-08-24_robin_montgomery_kayla_cross","bid":0.88,"ask":0.94,"mid":0.91,"spread":0.06,"bid_size":null,"ask_size":null}
{"ts":"2026-08-24T20:48:17.106Z","event_type":"best_bid_ask","market_id":"3825053","outcome_index":1,"market_type":"set1","local_side":"away","local_uid":"2026-08-24_robin_montgomery_kayla_cross","bid":0.06,"ask":0.12,"mid":0.09,"spread":0.06,"bid_size":null,"ask_size":null}
{"ts":"2026-08-24T20:48:17.106Z","event_type":"price_change","market_id":"3825053","outcome_index":0,"market_type":"set1","local_side":"home","local_uid":"2026-08-24_robin_montgomery_kayla_cross","bid":0.88,"ask":0.94,"mid":0.91,"spread":0.06,"price":0.89,"size":0.0,"side":"BUY"}
{"ts":"2026-08-24T20:48:17.107Z","event_type":"price_change","market_id":"3825053","outcome_index":1,"market_type":"set1","local_side":"away","local_uid":"2026-08-24_robin_montgomery_kayla_cross","bid":0.06,"ask":0.12,"mid":0.09,"spread":0.06,"price":0.11,"size":0.0,"side":"SELL"}
{"ts":"2026-08-24T20:48:17.114Z","event_type":"best_bid_ask","market_id":"3826919","outcome_index":0,"market_type":"set2","local_side":"home","local_uid":"2026-08-24_dalibor_svrcina_felipe_meligeni_alves","bid":0.43,"ask":0.51,"mid":0.47,"spread":0.08,"bid_size":null,"ask_size":null}
{"ts":"2026-08-24T20:48:17.114Z","event_type":"best_bid_ask","market_id":"3826919","outcome_index":1,"market_type":"set2","local_side":"away","local_uid":"2026-08-24_dalibor_svrcina_felipe_meligeni_alves","bid":0.49,"ask":0.57,"mid":0.53,"spread":0.08,"bid_size":null,"ask_size":null}
{"ts":"2026-08-24T20:48:17.115Z","event_type":"price_change","market_id":"3826919","outcome_index":1,"market_type":"set2","local_side":"away","local_uid":"2026-08-24_dalibor_svrcina_felipe_meligeni_alves","bid":0.49,"ask":0.57,"mid":0.53,"spread":0.08,"price":0.49,"size":18.0,"side":"BUY"}
{"ts":"2026-08-24T20:48:17.115Z","event_type":"price_change","market_id":"3826919","outcome_index":0,"market_type":"set2","local_side":"home","local_uid":"2026-08-24_dalibor_svrcina_felipe_meligeni_alves","bid":0.43,"ask":0.51,"mid":0.47,"spread":0.08,"price":0.51,"size":18.0,"side":"SELL"}
{"ts":"2026-08-24T20:48:17.115Z","event_type":"best_bid_ask","market_id":"3826919","outcome_index":0,"market_type":"set2","local_side":"home","local_uid":"2026-08-24_dalibor_svrcina_felipe_meligeni_alves","bid":0.42,"ask":0.51,"mid":0.465,"spread":0.09,"bid_size":null,"ask_size":null}
{"ts":"2026-08-24T20:48:17.116Z","event_type":"best_bid_ask","market_id":"3826919","outcome_index":1,"market_type":"set2","local_side":"away","local_uid":"2026-08-24_dalibor_svrcina_felipe_meligeni_alves","bid":0.49,"ask":0.58,"mid":0.535,"spread":0.09,"bid_size":null,"ask_size":null}
{"ts":"2026-08-24T20:48:17.116Z","event_type":"price_change","market_id":"3826919","outcome_index":0,"market_type":"set2","local_side":"home","local_uid":"2026-08-24_dalibor_svrcina_felipe_meligeni_alves","bid":0.42,"ask":0.51,"mid":0.465,"spread":0.09,"price":0.43,"size":0.0,"side":"BUY"}
{"ts":"2026-08-24T20:48:17.116Z","event_type":"price_change","market_id":"3826919","outcome_index":1,"market_type":"set2","local_side":"away","local_uid":"2026-08-24_dalibor_svrcina_felipe_meligeni_alves","bid":0.49,"ask":0.58,"mid":0.535,"spread":0.09,"price":0.57,"size":0.0,"side":"SELL"}
{"ts":"2026-08-24T20:48:17.118Z","event_type":"best_bid_ask","market_id":"3826919","outcome_index":0,"market_type":"set2","local_side":"home","local_uid":"2026-08-24_dalibor_svrcina_felipe_meligeni_alves","bid":0.43,"ask":0.51,"mid":0.47,"spread":0.08,"bid_size":null,"ask_size":null}
{"ts":"2026-08-24T20:48:17.118Z","event_type":"best_bid_ask","market_id":"3826919","outcome_index":1,"market_type":"set2","local_side":"away","local_uid":"2026-08-24_dalibor_svrcina_felipe_meligeni_alves","bid":0.49,"ask":0.57,"mid":0.53,"spread":0.08,"bid_size":null,"ask_size":null}
{"ts":"2026-08-24T20:48:17.119Z","event_type":"price_change","market_id":"3826919","outcome_index":0,"market_type":"set2","local_side":"home","local_uid":"2026-08-24_dalibor_svrcina_felipe_meligeni_alves","bid":0.43,"ask":0.51,"mid":0.47,"spread":0.08,"price":0.43,"size":78.72,"side":"BUY"}
{"ts":"2026-08-24T20:48:17.119Z","event_type":"price_change","market_id":"3826919","outcome_index":1,"market_type":"set2","local_side":"away","local_uid":"2026-08-24_dalibor_svrcina_felipe_meligeni_alves","bid":0.49,"ask":0.57,"mid":0.53,"spread":0.08,"price":0.57,"size":78.72,"side":"SELL"}
{"ts":"2026-08-24T20:48:17.128Z","event_type":"best_bid_ask","market_id":"3826919","outcome_index":0,"market_type":"set2","local_side":"home","local_uid":"2026-08-24_dalibor_svrcina_felipe_meligeni_alves","bid":0.43,"ask":0.52,"mid":0.475,"spread":0.09,"bid_size":null,"ask_size":null}
{"ts":"2026-08-24T20:48:17.129Z","event_type":"best_bid_ask","market_id":"3826919","outcome_index":1,"market_type":"set2","local_side":"away","local_uid":"2026-08-24_dalibor_svrcina_felipe_meligeni_alves","bid":0.48,"ask":0.57,"mid":0.525,"spread":0.09,"bid_size":null,"ask_size":null}
{"ts":"2026-08-24T20:48:17.129Z","event_type":"price_change","market_id":"3826919","outcome_index":1,"market_type":"set2","local_side":"away","local_uid":"2026-08-24_dalibor_svrcina_felipe_meligeni_alves","bid":0.48,"ask":0.57,"mid":0.525,"spread":0.09,"price":0.49,"size":0.0,"side":"BUY"}
{"ts":"2026-08-24T20:48:17.129Z","event_type":"price_change","market_id":"3826919","outcome_index":0,"market_type":"set2","local_side":"home","local_uid":"2026-08-24_dalibor_svrcina_felipe_meligeni_alves","bid":0.43,"ask":0.52,"mid":0.475,"spread":0.09,"price":0.51,"size":0.0,"side":"SELL"}
{"ts":"2026-08-24T20:48:17.185Z","event_type":"best_bid_ask","market_id":"3825641","outcome_index":0,"market_type":"match","local_side":"home","local_uid":"2026-08-24_sebastian_gorzny_cruz_hewitt","bid":0.61,"ask":0.64,"mid":0.625,"spread":0.03,"bid_size":null,"ask_size":null}
{"ts":"2026-08-24T20:48:17.199Z","event_type":"best_bid_ask","market_id":"3825641","outcome_index":1,"market_type":"match","local_side":"away","local_uid":"2026-08-24_sebastian_gorzny_cruz_hewitt","bid":0.36,"ask":0.39,"mid":0.375,"spread":0.03,"bid_size":null,"ask_size":null}
{"ts":"2026-08-24T20:48:17.199Z","event_type":"price_change","market_id":"3825641","outcome_index":0,"market_type":"match","local_side":"home","local_uid":"2026-08-24_sebastian_gorzny_cruz_hewitt","bid":0.61,"ask":0.64,"mid":0.625,"spread":0.03,"price":0.61,"size":10.0,"side":"BUY"}
{"ts":"2026-08-24T20:48:17.199Z","event_type":"price_change","market_id":"3825641","outcome_index":1,"market_type":"match","local_side":"away","local_uid":"2026-08-24_sebastian_gorzny_cruz_hewitt","bid":0.36,"ask":0.39,"mid":0.375,"spread":0.03,"price":0.39,"size":10.0,"side":"SELL"}
{"ts":"2026-08-24T20:48:17.244Z","event_type":"best_bid_ask","market_id":"3824994","outcome_index":0,"market_type":"set2","local_side":"home","local_uid":"2026-08-24_angela_fita_boluda_lin_zhu","bid":0.33,"ask":0.43,"mid":0.38,"spread":0.1,"bid_size":null,"ask_size":null}
{"ts":"2026-08-24T20:48:17.244Z","event_type":"best_bid_ask","market_id":"3824994","outcome_index":1,"market_type":"set2","local_side":"away","local_uid":"2026-08-24_angela_fita_boluda_lin_zhu","bid":0.57,"ask":0.67,"mid":0.62,"spread":0.1,"bid_size":null,"ask_size":null}
{"ts":"2026-08-24T20:48:17.244Z","event_type":"price_change","market_id":"3824994","outcome_index":1,"market_type":"set2","local_side":"away","local_uid":"2026-08-24_angela_fita_boluda_lin_zhu","bid":0.57,"ask":0.67,"mid":0.62,"spread":0.1,"price":0.58,"size":0.0,"side":"BUY"}
{"ts":"2026-08-24T20:48:17.244Z","event_type":"price_change","market_id":"3824994","outcome_index":0,"market_type":"set2","local_side":"home","local_uid":"2026-08-24_angela_fita_boluda_lin_zhu","bid":0.33,"ask":0.43,"mid":0.38,"spread":0.1,"price":0.42,"size":0.0,"side":"SELL"}
{"ts":"2026-08-24T20:48:17.252Z","event_type":"best_bid_ask","market_id":"3826733","outcome_index":0,"market_type":"set1","local_side":"home","local_uid":"2026-08-24_harry_wendelken_stefano_travaglia","bid":0.85,"ask":0.92,"mid":0.885,"spread":0.07,"bid_size":null,"ask_size":null}
{"ts":"2026-08-24T20:48:17.252Z","event_type":"best_bid_ask","market_id":"3826733","outcome_index":1,"market_type":"set1","local_side":"away","local_uid":"2026-08-24_harry_wendelken_stefano_travaglia","bid":0.08,"ask":0.15,"mid":0.115,"spread":0.07,"bid_size":null,"ask_size":null}
{"ts":"2026-08-24T20:48:17.253Z","event_type":"price_change","market_id":"3826733","outcome_index":1,"market_type":"set1","local_side":"away","local_uid":"2026-08-24_harry_wendelken_stefano_travaglia","bid":0.08,"ask":0.15,"mid":0.115,"spread":0.07,"price":0.08,"size":22.44,"side":"BUY"}
{"ts":"2026-08-24T20:48:17.253Z","event_type":"price_change","market_id":"3826733","outcome_index":0,"market_type":"set1","local_side":"home","local_uid":"2026-08-24_harry_wendelken_stefano_travaglia","bid":0.85,"ask":0.92,"mid":0.885,"spread":0.07,"price":0.92,"size":22.44,"side":"SELL"}
{"ts":"2026-08-24T20:48:17.258Z","event_type":"best_bid_ask","market_id":"3824994","outcome_index":0,"market_type":"set2","local_side":"home","local_uid":"2026-08-24_angela_fita_boluda_lin_zhu","bid":0.33,"ask":0.45,"mid":0.39,"spread":0.12,"bid_size":null,"ask_size":null}
{"ts":"2026-08-24T20:48:17.258Z","event_type":"best_bid_ask","market_id":"3824994","outcome_index":1,"market_type":"set2","local_side":"away","local_uid":"2026-08-24_angela_fita_boluda_lin_zhu","bid":0.55,"ask":0.67,"mid":0.61,"spread":0.12,"bid_size":null,"ask_size":null}
{"ts":"2026-08-24T20:48:17.258Z","event_type":"price_change","market_id":"3824994","outcome_index":1,"market_type":"set2","local_side":"away","local_uid":"2026-08-24_angela_fita_boluda_lin_zhu","bid":0.55,"ask":0.67,"mid":0.61,"spread":0.12,"price":0.57,"size":0.0,"side":"BUY"}
{"ts":"2026-08-24T20:48:17.258Z","event_type":"price_change","market_id":"3824994","outcome_index":0,"market_type":"set2","local_side":"home","local_uid":"2026-08-24_angela_fita_boluda_lin_zhu","bid":0.33,"ask":0.45,"mid":0.39,"spread":0.12,"price":0.43,"size":0.0,"side":"SELL"}
{"ts":"2026-08-24T20:48:17.299Z","event_type":"best_bid_ask","market_id":"3824994","outcome_index":0,"market_type":"set2","local_side":"home","local_uid":"2026-08-24_angela_fita_boluda_lin_zhu","bid":0.33,"ask":0.42,"mid":0.375,"spread":0.09,"bid_size":null,"ask_size":null}
{"ts":"2026-08-24T20:48:17.299Z","event_type":"best_bid_ask","market_id":"3824994","outcome_index":1,"market_type":"set2","local_side":"away","local_uid":"2026-08-24_angela_fita_boluda_lin_zhu","bid":0.58,"ask":0.67,"mid":0.625,"spread":0.09,"bid_size":null,"ask_size":null}
{"ts":"2026-08-24T20:48:17.300Z","event_type":"price_change","market_id":"3824994","outcome_index":1,"market_type":"set2","local_side":"away","local_uid":"2026-08-24_angela_fita_boluda_lin_zhu","bid":0.58,"ask":0.67,"mid":0.625,"spread":0.09,"price":0.58,"size":7.0,"side":"BUY"}
{"ts":"2026-08-24T20:48:17.300Z","event_type":"price_change","market_id":"3824994","outcome_index":0,"market_type":"set2","local_side":"home","local_uid":"2026-08-24_angela_fita_boluda_lin_zhu","bid":0.33,"ask":0.42,"mid":0.375,"spread":0.09,"price":0.42,"size":7.0,"side":"SELL"}
{"ts":"2026-08-24T20:48:17.346Z","event_type":"best_bid_ask","market_id":"3823629","outcome_index":0,"market_type":"match","local_side":"home","local_uid":"2026-08-24_angela_fita_boluda_lin_zhu","bid":0.5,"ask":0.52,"mid":0.51,"spread":0.02,"bid_size":null,"ask_size":null}
{"ts":"2026-08-24T20:48:17.347Z","event_type":"best_bid_ask","market_id":"3823629","outcome_index":1,"market_type":"match","local_side":"away","local_uid":"2026-08-24_angela_fita_boluda_lin_zhu","bid":0.48,"ask":0.5,"mid":0.49,"spread":0.02,"bid_size":null,"ask_size":null}
{"ts":"2026-08-24T20:48:17.347Z","event_type":"price_change","market_id":"3823629","outcome_index":0,"market_type":"match","local_side":"home","local_uid":"2026-08-24_angela_fita_boluda_lin_zhu","bid":0.5,"ask":0.52,"mid":0.51,"spread":0.02,"price":0.5,"size":5342.5,"side":"BUY"}
{"ts":"2026-08-24T20:48:17.347Z","event_type":"price_change","market_id":"3823629","outcome_index":1,"market_type":"match","local_side":"away","local_uid":"2026-08-24_angela_fita_boluda_lin_zhu","bid":0.48,"ask":0.5,"mid":0.49,"spread":0.02,"price":0.5,"size":5342.5,"side":"SELL"}
{"ts":"2026-08-24T20:48:17.363Z","event_type":"best_bid_ask","market_id":"3824994","outcome_index":0,"market_type":"set2","local_side":"home","local_uid":"2026-08-24_angela_fita_boluda_lin_zhu","bid":0.31,"ask":0.42,"mid":0.365,"spread":0.11,"bid_size":null,"ask_size":null}
{"ts":"2026-08-24T20:48:17.364Z","event_type":"best_bid_ask","market_id":"3824994","outcome_index":1,"market_type":"set2","local_side":"away","local_uid":"2026-08-24_angela_fita_boluda_lin_zhu","bid":0.58,"ask":0.69,"mid":0.635,"spread":0.11,"bid_size":null,"ask_size":null}
{"ts":"2026-08-24T20:48:17.364Z","event_type":"price_change","market_id":"3824994","outcome_index":0,"market_type":"set2","local_side":"home","local_uid":"2026-08-24_angela_fita_boluda_lin_zhu","bid":0.31,"ask":0.42,"mid":0.365,"spread":0.11,"price":0.33,"size":0.0,"side":"BUY"}
{"ts":"2026-08-24T20:48:17.364Z","event_type":"price_change","market_id":"3824994","outcome_index":1,"market_type":"set2","local_side":"away","local_uid":"2026-08-24_angela_fita_boluda_lin_zhu","bid":0.58,"ask":0.69,"mid":0.635,"spread":0.11,"price":0.67,"size":0.0,"side":"SELL"}
{"ts":"2026-08-24T20:48:17.376Z","event_type":"best_bid_ask","market_id":"3823629","outcome_index":0,"market_type":"match","local_side":"home","local_uid":"2026-08-24_angela_fita_boluda_lin_zhu","bid":0.5,"ask":0.51,"mid":0.505,"spread":0.01,"bid_size":null,"ask_size":null}
{"ts":"2026-08-24T20:48:17.377Z","event_type":"best_bid_ask","market_id":"3823629","outcome_index":1,"market_type":"match","local_side":"away","local_uid":"2026-08-24_angela_fita_boluda_lin_zhu","bid":0.49,"ask":0.5,"mid":0.495,"spread":0.01,"bid_size":null,"ask_size":null}
{"ts":"2026-08-24T20:48:17.378Z","event_type":"price_change","market_id":"3823629","outcome_index":1,"market_type":"match","local_side":"away","local_uid":"2026-08-24_angela_fita_boluda_lin_zhu","bid":0.49,"ask":0.5,"mid":0.495,"spread":0.01,"price":0.49,"size":605.02,"side":"BUY"}
{"ts":"2026-08-24T20:48:17.378Z","event_type":"price_change","market_id":"3823629","outcome_index":0,"market_type":"match","local_side":"home","local_uid":"2026-08-24_angela_fita_boluda_lin_zhu","bid":0.5,"ask":0.51,"mid":0.505,"spread":0.01,"price":0.51,"size":605.02,"side":"SELL"}
{"ts":"2026-08-24T20:48:17.386Z","event_type":"book","market_id":"3826654","outcome_index":0,"market_type":"set2","local_side":"home","local_uid":"2026-08-24_sebastian_gorzny_cruz_hewitt","bid":0.06,"ask":0.13,"mid":0.095,"spread":0.07,"bid_size":88.0,"ask_size":0.3}
{"ts":"2026-08-24T20:48:17.387Z","event_type":"book","market_id":"3826654","outcome_index":1,"market_type":"set2","local_side":"away","local_uid":"2026-08-24_sebastian_gorzny_cruz_hewitt","bid":0.87,"ask":0.94,"mid":0.905,"spread":0.07,"bid_size":0.3,"ask_size":88.0}
{"ts":"2026-08-24T20:48:17.388Z","event_type":"book","market_id":"3825604","outcome_index":0,"market_type":"match","local_side":"home","local_uid":"2026-08-24_dalibor_svrcina_felipe_meligeni_alves","bid":0.78,"ask":0.79,"mid":0.785,"spread":0.01,"bid_size":8.17,"ask_size":1814.8}
{"ts":"2026-08-24T20:48:17.393Z","event_type":"book","market_id":"3825604","outcome_index":1,"market_type":"match","local_side":"away","local_uid":"2026-08-24_dalibor_svrcina_felipe_meligeni_alves","bid":0.21,"ask":0.22,"mid":0.215,"spread":0.01,"bid_size":1814.8,"ask_size":8.17}
{"ts":"2026-08-24T20:48:17.402Z","event_type":"best_bid_ask","market_id":"3826894","outcome_index":0,"market_type":"set1","local_side":"home","local_uid":"2026-08-24_raul_brancaccio_thiago_seyboth_wild","bid":0.0,"ask":0.15,"mid":0.075,"spread":0.15,"bid_size":null,"ask_size":null}
{"ts":"2026-08-24T20:48:17.402Z","event_type":"best_bid_ask","market_id":"3826894","outcome_index":1,"market_type":"set1","local_side":"away","local_uid":"2026-08-24_raul_brancaccio_thiago_seyboth_wild","bid":0.85,"ask":1.0,"mid":0.925,"spread":0.15,"bid_size":null,"ask_size":null}
{"ts":"2026-08-24T20:48:17.406Z","event_type":"price_change","market_id":"3826894","outcome_index":0,"market_type":"set1","local_side":"home","local_uid":"2026-08-24_raul_brancaccio_thiago_seyboth_wild","bid":0.0,"ask":0.15,"mid":0.075,"spread":0.15,"price":0.05,"size":0.0,"side":"BUY"}
{"ts":"2026-08-24T20:48:17.406Z","event_type":"price_change","market_id":"3826894","outcome_index":1,"market_type":"set1","local_side":"away","local_uid":"2026-08-24_raul_brancaccio_thiago_seyboth_wild","bid":0.85,"ask":1.0,"mid":0.925,"spread":0.15,"price":0.95,"size":0.0,"side":"SELL"}
{"ts":"2026-08-24T20:48:17.480Z","event_type":"best_bid_ask","market_id":"3826738","outcome_index":0,"market_type":"set2","local_side":"home","local_uid":"2026-08-24_harry_wendelken_stefano_travaglia","bid":0.49,"ask":0.6,"mid":0.545,"spread":0.11,"bid_size":null,"ask_size":null}
{"ts":"2026-08-24T20:48:17.481Z","event_type":"best_bid_ask","market_id":"3826738","outcome_index":1,"market_type":"set2","local_side":"away","local_uid":"2026-08-24_harry_wendelken_stefano_travaglia","bid":0.4,"ask":0.51,"mid":0.455,"spread":0.11,"bid_size":null,"ask_size":null}
{"ts":"2026-08-24T20:48:17.481Z","event_type":"price_change","market_id":"3826738","outcome_index":0,"market_type":"set2","local_side":"home","local_uid":"2026-08-24_harry_wendelken_stefano_travaglia","bid":0.49,"ask":0.6,"mid":0.545,"spread":0.11,"price":0.49,"size":42.8,"side":"BUY"}
{"ts":"2026-08-24T20:48:17.481Z","event_type":"price_change","market_id":"3826738","outcome_index":1,"market_type":"set2","local_side":"away","local_uid":"2026-08-24_harry_wendelken_stefano_travaglia","bid":0.4,"ask":0.51,"mid":0.455,"spread":0.11,"price":0.51,"size":42.8,"side":"SELL"}
{"ts":"2026-08-24T20:48:17.510Z","event_type":"best_bid_ask","market_id":"3826654","outcome_index":0,"market_type":"set2","local_side":"home","local_uid":"2026-08-24_sebastian_gorzny_cruz_hewitt","bid":0.04,"ask":0.13,"mid":0.085,"spread":0.09,"bid_size":null,"ask_size":null}
{"ts":"2026-08-24T20:48:17.510Z","event_type":"best_bid_ask","market_id":"3826654","outcome_index":1,"market_type":"set2","local_side":"away","local_uid":"2026-08-24_sebastian_gorzny_cruz_hewitt","bid":0.87,"ask":0.96,"mid":0.915,"spread":0.09,"bid_size":null,"ask_size":null}
{"ts":"2026-08-24T20:48:17.511Z","event_type":"price_change","market_id":"3826654","outcome_index":0,"market_type":"set2","local_side":"home","local_uid":"2026-08-24_sebastian_gorzny_cruz_hewitt","bid":0.04,"ask":0.13,"mid":0.085,"spread":0.09,"price":0.06,"size":0.0,"side":"BUY"}
{"ts":"2026-08-24T20:48:17.511Z","event_type":"price_change","market_id":"3826654","outcome_index":1,"market_type":"set2","local_side":"away","local_uid":"2026-08-24_sebastian_gorzny_cruz_hewitt","bid":0.87,"ask":0.96,"mid":0.915,"spread":0.09,"price":0.94,"size":0.0,"side":"SELL"}
{"ts":"2026-08-24T20:48:17.513Z","event_type":"last_trade_price","market_id":"3825604","outcome_index":1,"market_type":"match","local_side":"away","local_uid":"2026-08-24_dalibor_svrcina_felipe_meligeni_alves","last_trade":0.22,"trade_size":16.7273,"trade_side":"BUY","trade_notional":3.68}
{"ts":"2026-08-24T20:48:17.537Z","event_type":"best_bid_ask","market_id":"3825053","outcome_index":0,"market_type":"set1","local_side":"home","local_uid":"2026-08-24_robin_montgomery_kayla_cross","bid":0.88,"ask":0.95,"mid":0.915,"spread":0.07,"bid_size":null,"ask_size":null}
{"ts":"2026-08-24T20:48:17.537Z","event_type":"best_bid_ask","market_id":"3825053","outcome_index":1,"market_type":"set1","local_side":"away","local_uid":"2026-08-24_robin_montgomery_kayla_cross","bid":0.05,"ask":0.12,"mid":0.085,"spread":0.07,"bid_size":null,"ask_size":null}
{"ts":"2026-08-24T20:48:17.538Z","event_type":"price_change","market_id":"3825053","outcome_index":0,"market_type":"set1","local_side":"home","local_uid":"2026-08-24_robin_montgomery_kayla_cross","bid":0.88,"ask":0.95,"mid":0.915,"spread":0.07,"price":0.84,"size":0.0,"side":"BUY"}
{"ts":"2026-08-24T20:48:17.538Z","event_type":"price_change","market_id":"3825053","outcome_index":1,"market_type":"set1","local_side":"away","local_uid":"2026-08-24_robin_montgomery_kayla_cross","bid":0.05,"ask":0.12,"mid":0.085,"spread":0.07,"price":0.16,"size":0.0,"side":"SELL"}
{"ts":"2026-08-24T20:48:17.556Z","event_type":"last_trade_price","market_id":"3826654","outcome_index":0,"market_type":"set2","local_side":"home","local_uid":"2026-08-24_sebastian_gorzny_cruz_hewitt","last_trade":0.13,"trade_size":87.6923,"trade_side":"BUY","trade_notional":11.4}
{"ts":"2026-08-24T20:48:17.556Z","event_type":"best_bid_ask","market_id":"3826738","outcome_index":0,"market_type":"set2","local_side":"home","local_uid":"2026-08-24_harry_wendelken_stefano_travaglia","bid":0.48,"ask":0.6,"mid":0.54,"spread":0.12,"bid_size":null,"ask_size":null}
{"ts":"2026-08-24T20:48:17.556Z","event_type":"best_bid_ask","market_id":"3826738","outcome_index":1,"market_type":"set2","local_side":"away","local_uid":"2026-08-24_harry_wendelken_stefano_travaglia","bid":0.4,"ask":0.52,"mid":0.46,"spread":0.12,"bid_size":null,"ask_size":null}
{"ts":"2026-08-24T20:48:17.570Z","event_type":"price_change","market_id":"3826738","outcome_index":0,"market_type":"set2","local_side":"home","local_uid":"2026-08-24_harry_wendelken_stefano_travaglia","bid":0.48,"ask":0.6,"mid":0.54,"spread":0.12,"price":0.49,"size":0.0,"side":"BUY"}
{"ts":"2026-08-24T20:48:17.570Z","event_type":"price_change","market_id":"3826738","outcome_index":1,"market_type":"set2","local_side":"away","local_uid":"2026-08-24_harry_wendelken_stefano_travaglia","bid":0.4,"ask":0.52,"mid":0.46,"spread":0.12,"price":0.51,"size":0.0,"side":"SELL"}
{"ts":"2026-08-24T20:48:17.593Z","event_type":"price_change","market_id":"3826895","outcome_index":0,"market_type":"set2","local_side":"home","local_uid":"2026-08-24_raul_brancaccio_thiago_seyboth_wild","bid":0.28,"ask":0.4,"mid":0.34,"spread":0.12,"price":0.28,"size":150.0,"side":"BUY"}
{"ts":"2026-08-24T20:48:17.593Z","event_type":"price_change","market_id":"3826895","outcome_index":1,"market_type":"set2","local_side":"away","local_uid":"2026-08-24_raul_brancaccio_thiago_seyboth_wild","bid":0.6,"ask":0.72,"mid":0.66,"spread":0.12,"price":0.72,"size":150.0,"side":"SELL"}
{"ts":"2026-08-24T20:48:17.635Z","event_type":"best_bid_ask","market_id":"3826895","outcome_index":0,"market_type":"set2","local_side":"home","local_uid":"2026-08-24_raul_brancaccio_thiago_seyboth_wild","bid":0.25,"ask":0.4,"mid":0.325,"spread":0.15,"bid_size":null,"ask_size":null}
{"ts":"2026-08-24T20:48:17.635Z","event_type":"best_bid_ask","market_id":"3826895","outcome_index":1,"market_type":"set2","local_side":"away","local_uid":"2026-08-24_raul_brancaccio_thiago_seyboth_wild","bid":0.6,"ask":0.75,"mid":0.675,"spread":0.15,"bid_size":null,"ask_size":null}
{"ts":"2026-08-24T20:48:17.635Z","event_type":"price_change","market_id":"3826895","outcome_index":0,"market_type":"set2","local_side":"home","local_uid":"2026-08-24_raul_brancaccio_thiago_seyboth_wild","bid":0.25,"ask":0.4,"mid":0.325,"spread":0.15,"price":0.28,"size":0.0,"side":"BUY"}
{"ts":"2026-08-24T20:48:17.636Z","event_type":"price_change","market_id":"3826895","outcome_index":1,"market_type":"set2","local_side":"away","local_uid":"2026-08-24_raul_brancaccio_thiago_seyboth_wild","bid":0.6,"ask":0.75,"mid":0.675,"spread":0.15,"price":0.72,"size":0.0,"side":"SELL"}
{"ts":"2026-08-24T20:48:17.636Z","event_type":"best_bid_ask","market_id":"3823629","outcome_index":0,"market_type":"match","local_side":"home","local_uid":"2026-08-24_angela_fita_boluda_lin_zhu","bid":0.49,"ask":0.51,"mid":0.5,"spread":0.02,"bid_size":null,"ask_size":null}
{"ts":"2026-08-24T20:48:17.637Z","event_type":"best_bid_ask","market_id":"3823629","outcome_index":1,"market_type":"match","local_side":"away","local_uid":"2026-08-24_angela_fita_boluda_lin_zhu","bid":0.49,"ask":0.51,"mid":0.5,"spread":0.02,"bid_size":null,"ask_size":null}
{"ts":"2026-08-24T20:48:17.637Z","event_type":"price_change","market_id":"3823629","outcome_index":0,"market_type":"match","local_side":"home","local_uid":"2026-08-24_angela_fita_boluda_lin_zhu","bid":0.49,"ask":0.51,"mid":0.5,"spread":0.02,"price":0.5,"size":0.0,"side":"BUY"}
{"ts":"2026-08-24T20:48:17.637Z","event_type":"price_change","market_id":"3823629","outcome_index":1,"market_type":"match","local_side":"away","local_uid":"2026-08-24_angela_fita_boluda_lin_zhu","bid":0.49,"ask":0.51,"mid":0.5,"spread":0.02,"price":0.5,"size":0.0,"side":"SELL"}
{"ts":"2026-08-24T20:48:17.651Z","event_type":"best_bid_ask","market_id":"3826895","outcome_index":0,"market_type":"set2","local_side":"home","local_uid":"2026-08-24_raul_brancaccio_thiago_seyboth_wild","bid":0.23,"ask":0.4,"mid":0.315,"spread":0.17,"bid_size":null,"ask_size":null}
{"ts":"2026-08-24T20:48:17.651Z","event_type":"best_bid_ask","market_id":"3826895","outcome_index":1,"market_type":"set2","local_side":"away","local_uid":"2026-08-24_raul_brancaccio_thiago_seyboth_wild","bid":0.6,"ask":0.77,"mid":0.685,"spread":0.17,"bid_size":null,"ask_size":null}
{"ts":"2026-08-24T20:48:17.652Z","event_type":"price_change","market_id":"3826895","outcome_index":0,"market_type":"set2","local_side":"home","local_uid":"2026-08-24_raul_brancaccio_thiago_seyboth_wild","bid":0.23,"ask":0.4,"mid":0.315,"spread":0.17,"price":0.25,"size":0.0,"side":"BUY"}
{"ts":"2026-08-24T20:48:17.653Z","event_type":"price_change","market_id":"3826895","outcome_index":1,"market_type":"set2","local_side":"away","local_uid":"2026-08-24_raul_brancaccio_thiago_seyboth_wild","bid":0.6,"ask":0.77,"mid":0.685,"spread":0.17,"price":0.75,"size":0.0,"side":"SELL"}
{"ts":"2026-08-24T20:48:17.678Z","event_type":"best_bid_ask","market_id":"3823629","outcome_index":0,"market_type":"match","local_side":"home","local_uid":"2026-08-24_angela_fita_boluda_lin_zhu","bid":0.5,"ask":0.51,"mid":0.505,"spread":0.01,"bid_size":null,"ask_size":null}
{"ts":"2026-08-24T20:48:17.678Z","event_type":"best_bid_ask","market_id":"3823629","outcome_index":1,"market_type":"match","local_side":"away","local_uid":"2026-08-24_angela_fita_boluda_lin_zhu","bid":0.49,"ask":0.5,"mid":0.495,"spread":0.01,"bid_size":null,"ask_size":null}
{"ts":"2026-08-24T20:48:17.678Z","event_type":"price_change","market_id":"3823629","outcome_index":0,"market_type":"match","local_side":"home","local_uid":"2026-08-24_angela_fita_boluda_lin_zhu","bid":0.5,"ask":0.51,"mid":0.505,"spread":0.01,"price":0.5,"size":85.0,"side":"BUY"}
{"ts":"2026-08-24T20:48:17.679Z","event_type":"price_change","market_id":"3823629","outcome_index":1,"market_type":"match","local_side":"away","local_uid":"2026-08-24_angela_fita_boluda_lin_zhu","bid":0.49,"ask":0.5,"mid":0.495,"spread":0.01,"price":0.5,"size":85.0,"side":"SELL"}
{"ts":"2026-08-24T20:48:17.681Z","event_type":"best_bid_ask","market_id":"3826895","outcome_index":0,"market_type":"set2","local_side":"home","local_uid":"2026-08-24_raul_brancaccio_thiago_seyboth_wild","bid":0.24,"ask":0.4,"mid":0.32,"spread":0.16,"bid_size":null,"ask_size":null}
{"ts":"2026-08-24T20:48:17.682Z","event_type":"best_bid_ask","market_id":"3826895","outcome_index":1,"market_type":"set2","local_side":"away","local_uid":"2026-08-24_raul_brancaccio_thiago_seyboth_wild","bid":0.6,"ask":0.76,"mid":0.68,"spread":0.16,"bid_size":null,"ask_size":null}
{"ts":"2026-08-24T20:48:17.682Z","event_type":"price_change","market_id":"3826895","outcome_index":0,"market_type":"set2","local_side":"home","local_uid":"2026-08-24_raul_brancaccio_thiago_seyboth_wild","bid":0.24,"ask":0.4,"mid":0.32,"spread":0.16,"price":0.24,"size":562.0,"side":"BUY"}
{"ts":"2026-08-24T20:48:17.682Z","event_type":"price_change","market_id":"3826895","outcome_index":1,"market_type":"set2","local_side":"away","local_uid":"2026-08-24_raul_brancaccio_thiago_seyboth_wild","bid":0.6,"ask":0.76,"mid":0.68,"spread":0.16,"price":0.76,"size":562.0,"side":"SELL"}
{"ts":"2026-08-24T20:48:17.708Z","event_type":"best_bid_ask","market_id":"3824994","outcome_index":0,"market_type":"set2","local_side":"home","local_uid":"2026-08-24_angela_fita_boluda_lin_zhu","bid":0.29,"ask":0.42,"mid":0.355,"spread":0.13,"bid_size":null,"ask_size":null}
{"ts":"2026-08-24T20:48:17.708Z","event_type":"best_bid_ask","market_id":"3824994","outcome_index":1,"market_type":"set2","local_side":"away","local_uid":"2026-08-24_angela_fita_boluda_lin_zhu","bid":0.58,"ask":0.71,"mid":0.645,"spread":0.13,"bid_size":null,"ask_size":null}
{"ts":"2026-08-24T20:48:17.708Z","event_type":"price_change","market_id":"3824994","outcome_index":0,"market_type":"set2","local_side":"home","local_uid":"2026-08-24_angela_fita_boluda_lin_zhu","bid":0.29,"ask":0.42,"mid":0.355,"spread":0.13,"price":0.31,"size":0.0,"side":"BUY"}
{"ts":"2026-08-24T20:48:17.709Z","event_type":"price_change","market_id":"3824994","outcome_index":1,"market_type":"set2","local_side":"away","local_uid":"2026-08-24_angela_fita_boluda_lin_zhu","bid":0.58,"ask":0.71,"mid":0.645,"spread":0.13,"price":0.69,"size":0.0,"side":"SELL"}
{"ts":"2026-08-24T20:48:17.742Z","event_type":"best_bid_ask","market_id":"3826895","outcome_index":0,"market_type":"set2","local_side":"home","local_uid":"2026-08-24_raul_brancaccio_thiago_seyboth_wild","bid":0.25,"ask":0.4,"mid":0.325,"spread":0.15,"bid_size":null,"ask_size":null}
{"ts":"2026-08-24T20:48:17.742Z","event_type":"best_bid_ask","market_id":"3826895","outcome_index":1,"market_type":"set2","local_side":"away","local_uid":"2026-08-24_raul_brancaccio_thiago_seyboth_wild","bid":0.6,"ask":0.75,"mid":0.675,"spread":0.15,"bid_size":null,"ask_size":null}
{"ts":"2026-08-24T20:48:17.742Z","event_type":"price_change","market_id":"3826895","outcome_index":0,"market_type":"set2","local_side":"home","local_uid":"2026-08-24_raul_brancaccio_thiago_seyboth_wild","bid":0.25,"ask":0.4,"mid":0.325,"spread":0.15,"price":0.25,"size":25.0,"side":"BUY"}
{"ts":"2026-08-24T20:48:17.743Z","event_type":"price_change","market_id":"3826895","outcome_index":1,"market_type":"set2","local_side":"away","local_uid":"2026-08-24_raul_brancaccio_thiago_seyboth_wild","bid":0.6,"ask":0.75,"mid":0.675,"spread":0.15,"price":0.75,"size":25.0,"side":"SELL"}
{"ts":"2026-08-24T20:48:17.753Z","event_type":"best_bid_ask","market_id":"3826738","outcome_index":0,"market_type":"set2","local_side":"home","local_uid":"2026-08-24_harry_wendelken_stefano_travaglia","bid":0.49,"ask":0.6,"mid":0.545,"spread":0.11,"bid_size":null,"ask_size":null}
{"ts":"2026-08-24T20:48:17.754Z","event_type":"best_bid_ask","market_id":"3826738","outcome_index":1,"market_type":"set2","local_side":"away","local_uid":"2026-08-24_harry_wendelken_stefano_travaglia","bid":0.4,"ask":0.51,"mid":0.455,"spread":0.11,"bid_size":null,"ask_size":null}
{"ts":"2026-08-24T20:48:17.754Z","event_type":"price_change","market_id":"3826738","outcome_index":0,"market_type":"set2","local_side":"home","local_uid":"2026-08-24_harry_wendelken_stefano_travaglia","bid":0.49,"ask":0.6,"mid":0.545,"spread":0.11,"price":0.49,"size":44.0,"side":"BUY"}
{"ts":"2026-08-24T20:48:17.754Z","event_type":"price_change","market_id":"3826738","outcome_index":1,"market_type":"set2","local_side":"away","local_uid":"2026-08-24_harry_wendelken_stefano_travaglia","bid":0.4,"ask":0.51,"mid":0.455,"spread":0.11,"price":0.51,"size":44.0,"side":"SELL"}
{"ts":"2026-08-24T20:48:17.782Z","event_type":"best_bid_ask","market_id":"3823629","outcome_index":0,"market_type":"match","local_side":"home","local_uid":"2026-08-24_angela_fita_boluda_lin_zhu","bid":0.49,"ask":0.51,"mid":0.5,"spread":0.02,"bid_size":null,"ask_size":null}
{"ts":"2026-08-24T20:48:17.782Z","event_type":"best_bid_ask","market_id":"3823629","outcome_index":1,"market_type":"match","local_side":"away","local_uid":"2026-08-24_angela_fita_boluda_lin_zhu","bid":0.49,"ask":0.51,"mid":0.5,"spread":0.02,"bid_size":null,"ask_size":null}
{"ts":"2026-08-24T20:48:17.783Z","event_type":"price_change","market_id":"3823629","outcome_index":0,"market_type":"match","local_side":"home","local_uid":"2026-08-24_angela_fita_boluda_lin_zhu","bid":0.49,"ask":0.51,"mid":0.5,"spread":0.02,"price":0.5,"size":0.0,"side":"BUY"}
{"ts":"2026-08-24T20:48:17.783Z","event_type":"price_change","market_id":"3823629","outcome_index":1,"market_type":"match","local_side":"away","local_uid":"2026-08-24_angela_fita_boluda_lin_zhu","bid":0.49,"ask":0.51,"mid":0.5,"spread":0.02,"price":0.5,"size":0.0,"side":"SELL"}
{"ts":"2026-08-24T20:48:17.784Z","event_type":"best_bid_ask","market_id":"3824994","outcome_index":0,"market_type":"set2","local_side":"home","local_uid":"2026-08-24_angela_fita_boluda_lin_zhu","bid":0.3,"ask":0.42,"mid":0.36,"spread":0.12,"bid_size":null,"ask_size":null}
{"ts":"2026-08-24T20:48:17.785Z","event_type":"best_bid_ask","market_id":"3824994","outcome_index":1,"market_type":"set2","local_side":"away","local_uid":"2026-08-24_angela_fita_boluda_lin_zhu","bid":0.58,"ask":0.7,"mid":0.64,"spread":0.12,"bid_size":null,"ask_size":null}
{"ts":"2026-08-24T20:48:17.785Z","event_type":"price_change","market_id":"3824994","outcome_index":0,"market_type":"set2","local_side":"home","local_uid":"2026-08-24_angela_fita_boluda_lin_zhu","bid":0.3,"ask":0.42,"mid":0.36,"spread":0.12,"price":0.3,"size":150.0,"side":"BUY"}
{"ts":"2026-08-24T20:48:17.785Z","event_type":"price_change","market_id":"3824994","outcome_index":1,"market_type":"set2","local_side":"away","local_uid":"2026-08-24_angela_fita_boluda_lin_zhu","bid":0.58,"ask":0.7,"mid":0.64,"spread":0.12,"price":0.7,"size":150.0,"side":"SELL"}
{"ts":"2026-08-24T20:48:17.788Z","event_type":"best_bid_ask","market_id":"3826738","outcome_index":0,"market_type":"set2","local_side":"home","local_uid":"2026-08-24_harry_wendelken_stefano_travaglia","bid":0.48,"ask":0.6,"mid":0.54,"spread":0.12,"bid_size":null,"ask_size":null}
{"ts":"2026-08-24T20:48:17.788Z","event_type":"best_bid_ask","market_id":"3826738","outcome_index":1,"market_type":"set2","local_side":"away","local_uid":"2026-08-24_harry_wendelken_stefano_travaglia","bid":0.4,"ask":0.52,"mid":0.46,"spread":0.12,"bid_size":null,"ask_size":null}
{"ts":"2026-08-24T20:48:17.789Z","event_type":"price_change","market_id":"3826738","outcome_index":0,"market_type":"set2","local_side":"home","local_uid":"2026-08-24_harry_wendelken_stefano_travaglia","bid":0.48,"ask":0.6,"mid":0.54,"spread":0.12,"price":0.49,"size":0.0,"side":"BUY"}
{"ts":"2026-08-24T20:48:17.789Z","event_type":"price_change","market_id":"3826738","outcome_index":1,"market_type":"set2","local_side":"away","local_uid":"2026-08-24_harry_wendelken_stefano_travaglia","bid":0.4,"ask":0.52,"mid":0.46,"spread":0.12,"price":0.51,"size":0.0,"side":"SELL"}
{"ts":"2026-08-24T20:48:17.806Z","event_type":"best_bid_ask","market_id":"3823629","outcome_index":0,"market_type":"match","local_side":"home","local_uid":"2026-08-24_angela_fita_boluda_lin_zhu","bid":0.5,"ask":0.51,"mid":0.505,"spread":0.01,"bid_size":null,"ask_size":null}
{"ts":"2026-08-24T20:48:17.807Z","event_type":"best_bid_ask","market_id":"3823629","outcome_index":1,"market_type":"match","local_side":"away","local_uid":"2026-08-24_angela_fita_boluda_lin_zhu","bid":0.49,"ask":0.5,"mid":0.495,"spread":0.01,"bid_size":null,"ask_size":null}
{"ts":"2026-08-24T20:48:17.807Z","event_type":"price_change","market_id":"3823629","outcome_index":0,"market_type":"match","local_side":"home","local_uid":"2026-08-24_angela_fita_boluda_lin_zhu","bid":0.5,"ask":0.51,"mid":0.505,"spread":0.01,"price":0.5,"size":85.0,"side":"BUY"}
{"ts":"2026-08-24T20:48:17.807Z","event_type":"price_change","market_id":"3823629","outcome_index":1,"market_type":"match","local_side":"away","local_uid":"2026-08-24_angela_fita_boluda_lin_zhu","bid":0.49,"ask":0.5,"mid":0.495,"spread":0.01,"price":0.5,"size":85.0,"side":"SELL"}
{"ts":"2026-08-24T20:48:17.809Z","event_type":"best_bid_ask","market_id":"3824994","outcome_index":0,"market_type":"set2","local_side":"home","local_uid":"2026-08-24_angela_fita_boluda_lin_zhu","bid":0.3,"ask":0.46,"mid":0.38,"spread":0.16,"bid_size":null,"ask_size":null}
{"ts":"2026-08-24T20:48:17.809Z","event_type":"best_bid_ask","market_id":"3824994","outcome_index":1,"market_type":"set2","local_side":"away","local_uid":"2026-08-24_angela_fita_boluda_lin_zhu","bid":0.54,"ask":0.7,"mid":0.62,"spread":0.16,"bid_size":null,"ask_size":null}
{"ts":"2026-08-24T20:48:17.809Z","event_type":"price_change","market_id":"3824994","outcome_index":1,"market_type":"set2","local_side":"away","local_uid":"2026-08-24_angela_fita_boluda_lin_zhu","bid":0.54,"ask":0.7,"mid":0.62,"spread":0.16,"price":0.58,"size":0.0,"side":"BUY"}
{"ts":"2026-08-24T20:48:17.810Z","event_type":"price_change","market_id":"3824994","outcome_index":0,"market_type":"set2","local_side":"home","local_uid":"2026-08-24_angela_fita_boluda_lin_zhu","bid":0.3,"ask":0.46,"mid":0.38,"spread":0.16,"price":0.42,"size":0.0,"side":"SELL"}
{"ts":"2026-08-24T20:48:17.878Z","event_type":"best_bid_ask","market_id":"3823629","outcome_index":0,"market_type":"match","local_side":"home","local_uid":"2026-08-24_angela_fita_boluda_lin_zhu","bid":0.49,"ask":0.51,"mid":0.5,"spread":0.02,"bid_size":null,"ask_size":null}
{"ts":"2026-08-24T20:48:17.878Z","event_type":"best_bid_ask","market_id":"3823629","outcome_index":1,"market_type":"match","local_side":"away","local_uid":"2026-08-24_angela_fita_boluda_lin_zhu","bid":0.49,"ask":0.51,"mid":0.5,"spread":0.02,"bid_size":null,"ask_size":null}
{"ts":"2026-08-24T20:48:17.884Z","event_type":"price_change","market_id":"3823629","outcome_index":0,"market_type":"match","local_side":"home","local_uid":"2026-08-24_angela_fita_boluda_lin_zhu","bid":0.49,"ask":0.51,"mid":0.5,"spread":0.02,"price":0.5,"size":0.0,"side":"BUY"}
{"ts":"2026-08-24T20:48:17.884Z","event_type":"price_change","market_id":"3823629","outcome_index":1,"market_type":"match","local_side":"away","local_uid":"2026-08-24_angela_fita_boluda_lin_zhu","bid":0.49,"ask":0.51,"mid":0.5,"spread":0.02,"price":0.5,"size":0.0,"side":"SELL"}
{"ts":"2026-08-24T20:48:17.944Z","event_type":"best_bid_ask","market_id":"3826738","outcome_index":0,"market_type":"set2","local_side":"home","local_uid":"2026-08-24_harry_wendelken_stefano_travaglia","bid":0.49,"ask":0.6,"mid":0.545,"spread":0.11,"bid_size":null,"ask_size":null}
{"ts":"2026-08-24T20:48:17.944Z","event_type":"best_bid_ask","market_id":"3826738","outcome_index":1,"market_type":"set2","local_side":"away","local_uid":"2026-08-24_harry_wendelken_stefano_travaglia","bid":0.4,"ask":0.51,"mid":0.455,"spread":0.11,"bid_size":null,"ask_size":null}
{"ts":"2026-08-24T20:48:17.945Z","event_type":"price_change","market_id":"3826738","outcome_index":0,"market_type":"set2","local_side":"home","local_uid":"2026-08-24_harry_wendelken_stefano_travaglia","bid":0.49,"ask":0.6,"mid":0.545,"spread":0.11,"price":0.49,"size":42.8,"side":"BUY"}
{"ts":"2026-08-24T20:48:17.945Z","event_type":"price_change","market_id":"3826738","outcome_index":1,"market_type":"set2","local_side":"away","local_uid":"2026-08-24_harry_wendelken_stefano_travaglia","bid":0.4,"ask":0.51,"mid":0.455,"spread":0.11,"price":0.51,"size":42.8,"side":"SELL"}
{"ts":"2026-08-24T20:48:18.042Z","event_type":"best_bid_ask","market_id":"3826738","outcome_index":0,"market_type":"set2","local_side":"home","local_uid":"2026-08-24_harry_wendelken_stefano_travaglia","bid":0.48,"ask":0.6,"mid":0.54,"spread":0.12,"bid_size":null,"ask_size":null}
{"ts":"2026-08-24T20:48:18.043Z","event_type":"best_bid_ask","market_id":"3826738","outcome_index":1,"market_type":"set2","local_side":"away","local_uid":"2026-08-24_harry_wendelken_stefano_travaglia","bid":0.4,"ask":0.52,"mid":0.46,"spread":0.12,"bid_size":null,"ask_size":null}
{"ts":"2026-08-24T20:48:18.043Z","event_type":"price_change","market_id":"3826738","outcome_index":0,"market_type":"set2","local_side":"home","local_uid":"2026-08-24_harry_wendelken_stefano_travaglia","bid":0.48,"ask":0.6,"mid":0.54,"spread":0.12,"price":0.49,"size":0.0,"side":"BUY"}
{"ts":"2026-08-24T20:48:18.043Z","event_type":"price_change","market_id":"3826738","outcome_index":1,"market_type":"set2","local_side":"away","local_uid":"2026-08-24_harry_wendelken_stefano_travaglia","bid":0.4,"ask":0.52,"mid":0.46,"spread":0.12,"price":0.51,"size":0.0,"side":"SELL"}
{"ts":"2026-08-24T20:48:18.190Z","event_type":"best_bid_ask","market_id":"3825053","outcome_index":0,"market_type":"set1","local_side":"home","local_uid":"2026-08-24_robin_montgomery_kayla_cross","bid":0.87,"ask":0.95,"mid":0.91,"spread":0.08,"bid_size":null,"ask_size":null}
{"ts":"2026-08-24T20:48:18.190Z","event_type":"best_bid_ask","market_id":"3825053","outcome_index":1,"market_type":"set1","local_side":"away","local_uid":"2026-08-24_robin_montgomery_kayla_cross","bid":0.05,"ask":0.13,"mid":0.09,"spread":0.08,"bid_size":null,"ask_size":null}
{"ts":"2026-08-24T20:48:18.191Z","event_type":"price_change","market_id":"3825053","outcome_index":0,"market_type":"set1","local_side":"home","local_uid":"2026-08-24_robin_montgomery_kayla_cross","bid":0.87,"ask":0.95,"mid":0.91,"spread":0.08,"price":0.88,"size":0.0,"side":"BUY"}
{"ts":"2026-08-24T20:48:18.191Z","event_type":"price_change","market_id":"3825053","outcome_index":1,"market_type":"set1","local_side":"away","local_uid":"2026-08-24_robin_montgomery_kayla_cross","bid":0.05,"ask":0.13,"mid":0.09,"spread":0.08,"price":0.12,"size":0.0,"side":"SELL"}
{"ts":"2026-08-24T20:48:18.298Z","event_type":"best_bid_ask","market_id":"3826738","outcome_index":0,"market_type":"set2","local_side":"home","local_uid":"2026-08-24_harry_wendelken_stefano_travaglia","bid":0.5,"ask":0.6,"mid":0.55,"spread":0.1,"bid_size":null,"ask_size":null}
{"ts":"2026-08-24T20:48:18.298Z","event_type":"best_bid_ask","market_id":"3826738","outcome_index":1,"market_type":"set2","local_side":"away","local_uid":"2026-08-24_harry_wendelken_stefano_travaglia","bid":0.4,"ask":0.5,"mid":0.45,"spread":0.1,"bid_size":null,"ask_size":null}
{"ts":"2026-08-24T20:48:18.299Z","event_type":"price_change","market_id":"3826738","outcome_index":0,"market_type":"set2","local_side":"home","local_uid":"2026-08-24_harry_wendelken_stefano_travaglia","bid":0.5,"ask":0.6,"mid":0.55,"spread":0.1,"price":0.5,"size":18.0,"side":"BUY"}
{"ts":"2026-08-24T20:48:18.299Z","event_type":"price_change","market_id":"3826738","outcome_index":1,"market_type":"set2","local_side":"away","local_uid":"2026-08-24_harry_wendelken_stefano_travaglia","bid":0.4,"ask":0.5,"mid":0.45,"spread":0.1,"price":0.5,"size":18.0,"side":"SELL"}
{"ts":"2026-08-24T20:48:18.331Z","event_type":"best_bid_ask","market_id":"3826738","outcome_index":0,"market_type":"set2","local_side":"home","local_uid":"2026-08-24_harry_wendelken_stefano_travaglia","bid":0.48,"ask":0.6,"mid":0.54,"spread":0.12,"bid_size":null,"ask_size":null}
{"ts":"2026-08-24T20:48:18.332Z","event_type":"best_bid_ask","market_id":"3826738","outcome_index":1,"market_type":"set2","local_side":"away","local_uid":"2026-08-24_harry_wendelken_stefano_travaglia","bid":0.4,"ask":0.52,"mid":0.46,"spread":0.12,"bid_size":null,"ask_size":null}
{"ts":"2026-08-24T20:48:18.332Z","event_type":"price_change","market_id":"3826738","outcome_index":0,"market_type":"set2","local_side":"home","local_uid":"2026-08-24_harry_wendelken_stefano_travaglia","bid":0.48,"ask":0.6,"mid":0.54,"spread":0.12,"price":0.5,"size":0.0,"side":"BUY"}
{"ts":"2026-08-24T20:48:18.332Z","event_type":"price_change","market_id":"3826738","outcome_index":1,"market_type":"set2","local_side":"away","local_uid":"2026-08-24_harry_wendelken_stefano_travaglia","bid":0.4,"ask":0.52,"mid":0.46,"spread":0.12,"price":0.5,"size":0.0,"side":"SELL"}
{"ts":"2026-08-24T20:48:18.334Z","event_type":"best_bid_ask","market_id":"3825053","outcome_index":0,"market_type":"set1","local_side":"home","local_uid":"2026-08-24_robin_montgomery_kayla_cross","bid":0.85,"ask":0.95,"mid":0.9,"spread":0.1,"bid_size":null,"ask_size":null}
{"ts":"2026-08-24T20:48:18.334Z","event_type":"best_bid_ask","market_id":"3825053","outcome_index":1,"market_type":"set1","local_side":"away","local_uid":"2026-08-24_robin_montgomery_kayla_cross","bid":0.05,"ask":0.15,"mid":0.1,"spread":0.1,"bid_size":null,"ask_size":null}
{"ts":"2026-08-24T20:48:18.334Z","event_type":"price_change","market_id":"3825053","outcome_index":0,"market_type":"set1","local_side":"home","local_uid":"2026-08-24_robin_montgomery_kayla_cross","bid":0.85,"ask":0.95,"mid":0.9,"spread":0.1,"price":0.87,"size":0.0,"side":"BUY"}
{"ts":"2026-08-24T20:48:18.334Z","event_type":"price_change","market_id":"3825053","outcome_index":1,"market_type":"set1","local_side":"away","local_uid":"2026-08-24_robin_montgomery_kayla_cross","bid":0.05,"ask":0.15,"mid":0.1,"spread":0.1,"price":0.13,"size":0.0,"side":"SELL"}
{"ts":"2026-08-24T20:48:18.427Z","event_type":"best_bid_ask","market_id":"3825053","outcome_index":0,"market_type":"set1","local_side":"home","local_uid":"2026-08-24_robin_montgomery_kayla_cross","bid":0.86,"ask":0.95,"mid":0.905,"spread":0.09,"bid_size":null,"ask_size":null}
{"ts":"2026-08-24T20:48:18.428Z","event_type":"best_bid_ask","market_id":"3825053","outcome_index":1,"market_type":"set1","local_side":"away","local_uid":"2026-08-24_robin_montgomery_kayla_cross","bid":0.05,"ask":0.14,"mid":0.095,"spread":0.09,"bid_size":null,"ask_size":null}
{"ts":"2026-08-24T20:48:18.428Z","event_type":"price_change","market_id":"3825053","outcome_index":0,"market_type":"set1","local_side":"home","local_uid":"2026-08-24_robin_montgomery_kayla_cross","bid":0.86,"ask":0.95,"mid":0.905,"spread":0.09,"price":0.86,"size":150.0,"side":"BUY"}
{"ts":"2026-08-24T20:48:18.428Z","event_type":"price_change","market_id":"3825053","outcome_index":1,"market_type":"set1","local_side":"away","local_uid":"2026-08-24_robin_montgomery_kayla_cross","bid":0.05,"ask":0.14,"mid":0.095,"spread":0.09,"price":0.14,"size":150.0,"side":"SELL"}
{"ts":"2026-08-24T20:48:18.432Z","event_type":"best_bid_ask","market_id":"3826733","outcome_index":0,"market_type":"set1","local_side":"home","local_uid":"2026-08-24_harry_wendelken_stefano_travaglia","bid":0.85,"ask":0.91,"mid":0.88,"spread":0.06,"bid_size":null,"ask_size":null}
{"ts":"2026-08-24T20:48:18.433Z","event_type":"best_bid_ask","market_id":"3826733","outcome_index":1,"market_type":"set1","local_side":"away","local_uid":"2026-08-24_harry_wendelken_stefano_travaglia","bid":0.09,"ask":0.15,"mid":0.12,"spread":0.06,"bid_size":null,"ask_size":null}
{"ts":"2026-08-24T20:48:18.433Z","event_type":"price_change","market_id":"3826733","outcome_index":1,"market_type":"set1","local_side":"away","local_uid":"2026-08-24_harry_wendelken_stefano_travaglia","bid":0.09,"ask":0.15,"mid":0.12,"spread":0.06,"price":0.09,"size":88.0,"side":"BUY"}
{"ts":"2026-08-24T20:48:18.433Z","event_type":"price_change","market_id":"3826733","outcome_index":0,"market_type":"set1","local_side":"home","local_uid":"2026-08-24_harry_wendelken_stefano_travaglia","bid":0.85,"ask":0.91,"mid":0.88,"spread":0.06,"price":0.91,"size":88.0,"side":"SELL"}
{"ts":"2026-08-24T20:48:18.448Z","event_type":"best_bid_ask","market_id":"3825053","outcome_index":0,"market_type":"set1","local_side":"home","local_uid":"2026-08-24_robin_montgomery_kayla_cross","bid":0.87,"ask":0.95,"mid":0.91,"spread":0.08,"bid_size":null,"ask_size":null}
{"ts":"2026-08-24T20:48:18.449Z","event_type":"best_bid_ask","market_id":"3825053","outcome_index":1,"market_type":"set1","local_side":"away","local_uid":"2026-08-24_robin_montgomery_kayla_cross","bid":0.05,"ask":0.13,"mid":0.09,"spread":0.08,"bid_size":null,"ask_size":null}
{"ts":"2026-08-24T20:48:18.449Z","event_type":"price_change","market_id":"3825053","outcome_index":0,"market_type":"set1","local_side":"home","local_uid":"2026-08-24_robin_montgomery_kayla_cross","bid":0.87,"ask":0.95,"mid":0.91,"spread":0.08,"price":0.87,"size":25.0,"side":"BUY"}
{"ts":"2026-08-24T20:48:18.449Z","event_type":"price_change","market_id":"3825053","outcome_index":1,"market_type":"set1","local_side":"away","local_uid":"2026-08-24_robin_montgomery_kayla_cross","bid":0.05,"ask":0.13,"mid":0.09,"spread":0.08,"price":0.13,"size":25.0,"side":"SELL"}
{"ts":"2026-08-24T20:48:18.456Z","event_type":"best_bid_ask","market_id":"3826733","outcome_index":0,"market_type":"set1","local_side":"home","local_uid":"2026-08-24_harry_wendelken_stefano_travaglia","bid":0.85,"ask":0.9,"mid":0.875,"spread":0.05,"bid_size":null,"ask_size":null}
{"ts":"2026-08-24T20:48:18.458Z","event_type":"best_bid_ask","market_id":"3826733","outcome_index":1,"market_type":"set1","local_side":"away","local_uid":"2026-08-24_harry_wendelken_stefano_travaglia","bid":0.1,"ask":0.15,"mid":0.125,"spread":0.05,"bid_size":null,"ask_size":null}
{"ts":"2026-08-24T20:48:18.458Z","event_type":"price_change","market_id":"3826733","outcome_index":1,"market_type":"set1","local_side":"away","local_uid":"2026-08-24_harry_wendelken_stefano_travaglia","bid":0.1,"ask":0.15,"mid":0.125,"spread":0.05,"price":0.1,"size":1166.0,"side":"BUY"}
{"ts":"2026-08-24T20:48:18.459Z","event_type":"price_change","market_id":"3826733","outcome_index":0,"market_type":"set1","local_side":"home","local_uid":"2026-08-24_harry_wendelken_stefano_travaglia","bid":0.85,"ask":0.9,"mid":0.875,"spread":0.05,"price":0.9,"size":1166.0,"side":"SELL"}
{"ts":"2026-08-24T20:48:18.483Z","event_type":"best_bid_ask","market_id":"3826895","outcome_index":0,"market_type":"set2","local_side":"home","local_uid":"2026-08-24_raul_brancaccio_thiago_seyboth_wild","bid":0.24,"ask":0.4,"mid":0.32,"spread":0.16,"bid_size":null,"ask_size":null}
{"ts":"2026-08-24T20:48:18.483Z","event_type":"best_bid_ask","market_id":"3826895","outcome_index":1,"market_type":"set2","local_side":"away","local_uid":"2026-08-24_raul_brancaccio_thiago_seyboth_wild","bid":0.6,"ask":0.76,"mid":0.68,"spread":0.16,"bid_size":null,"ask_size":null}
{"ts":"2026-08-24T20:48:18.484Z","event_type":"price_change","market_id":"3826895","outcome_index":0,"market_type":"set2","local_side":"home","local_uid":"2026-08-24_raul_brancaccio_thiago_seyboth_wild","bid":0.24,"ask":0.4,"mid":0.32,"spread":0.16,"price":0.25,"size":0.0,"side":"BUY"}
{"ts":"2026-08-24T20:48:18.484Z","event_type":"price_change","market_id":"3826895","outcome_index":1,"market_type":"set2","local_side":"away","local_uid":"2026-08-24_raul_brancaccio_thiago_seyboth_wild","bid":0.6,"ask":0.76,"mid":0.68,"spread":0.16,"price":0.75,"size":0.0,"side":"SELL"}
{"ts":"2026-08-24T20:48:18.677Z","event_type":"best_bid_ask","market_id":"3825596","outcome_index":0,"market_type":"match","local_side":"home","local_uid":"2026-08-24_toby_samuel_francesco_maestrelli","bid":0.991,"ask":0.999,"mid":0.995,"spread":0.008,"bid_size":null,"ask_size":null}
{"ts":"2026-08-24T20:48:18.678Z","event_type":"best_bid_ask","market_id":"3825596","outcome_index":1,"market_type":"match","local_side":"away","local_uid":"2026-08-24_toby_samuel_francesco_maestrelli","bid":0.001,"ask":0.009,"mid":0.005,"spread":0.008,"bid_size":null,"ask_size":null}
{"ts":"2026-08-24T20:48:18.698Z","event_type":"book","market_id":"3825596","outcome_index":0,"market_type":"match","local_side":"home","local_uid":"2026-08-24_toby_samuel_francesco_maestrelli","bid":0.991,"ask":0.999,"mid":0.995,"spread":0.008,"bid_size":540.82,"ask_size":9.08}
{"ts":"2026-08-24T20:48:18.702Z","event_type":"book","market_id":"3825596","outcome_index":1,"market_type":"match","local_side":"away","local_uid":"2026-08-24_toby_samuel_francesco_maestrelli","bid":0.001,"ask":0.009,"mid":0.005,"spread":0.008,"bid_size":9.08,"ask_size":540.82}
{"ts":"2026-08-24T20:48:18.731Z","event_type":"best_bid_ask","market_id":"3826738","outcome_index":0,"market_type":"set2","local_side":"home","local_uid":"2026-08-24_harry_wendelken_stefano_travaglia","bid":0.49,"ask":0.6,"mid":0.545,"spread":0.11,"bid_size":null,"ask_size":null}
{"ts":"2026-08-24T20:48:18.732Z","event_type":"best_bid_ask","market_id":"3826738","outcome_index":1,"market_type":"set2","local_side":"away","local_uid":"2026-08-24_harry_wendelken_stefano_travaglia","bid":0.4,"ask":0.51,"mid":0.455,"spread":0.11,"bid_size":null,"ask_size":null}
{"ts":"2026-08-24T20:48:18.732Z","event_type":"price_change","market_id":"3826738","outcome_index":0,"market_type":"set2","local_side":"home","local_uid":"2026-08-24_harry_wendelken_stefano_travaglia","bid":0.49,"ask":0.6,"mid":0.545,"spread":0.11,"price":0.49,"size":406.0,"side":"BUY"}
{"ts":"2026-08-24T20:48:18.732Z","event_type":"price_change","market_id":"3826738","outcome_index":1,"market_type":"set2","local_side":"away","local_uid":"2026-08-24_harry_wendelken_stefano_travaglia","bid":0.4,"ask":0.51,"mid":0.455,"spread":0.11,"price":0.51,"size":406.0,"side":"SELL"}
{"ts":"2026-08-24T20:48:18.748Z","event_type":"last_trade_price","market_id":"3825604","outcome_index":1,"market_type":"match","local_side":"away","local_uid":"2026-08-24_dalibor_svrcina_felipe_meligeni_alves","last_trade":0.22,"trade_size":5.0,"trade_side":"BUY","trade_notional":1.1}
{"ts":"2026-08-24T20:48:18.839Z","event_type":"price_change","market_id":"3825598","outcome_index":1,"market_type":"match","local_side":"away","local_uid":"2026-08-24_gonzalo_bueno_billy_harris","bid":0.999,"ask":1.0,"mid":0.9995,"spread":0.001,"price":0.013,"size":44000.0,"side":"BUY"}
{"ts":"2026-08-24T20:48:18.839Z","event_type":"price_change","market_id":"3825598","outcome_index":0,"market_type":"match","local_side":"home","local_uid":"2026-08-24_gonzalo_bueno_billy_harris","bid":0.0,"ask":0.001,"mid":0.0005,"spread":0.001,"price":0.987,"size":44000.0,"side":"SELL"}
{"ts":"2026-08-24T20:48:18.861Z","event_type":"last_trade_price","market_id":"3825596","outcome_index":1,"market_type":"match","local_side":"away","local_uid":"2026-08-24_toby_samuel_francesco_maestrelli","last_trade":0.009,"trade_size":300.0,"trade_side":"BUY","trade_notional":2.7}
{"ts":"2026-08-24T20:48:18.869Z","event_type":"best_bid_ask","market_id":"3824796","outcome_index":0,"market_type":"set2","local_side":"home","local_uid":"2026-08-24_victoria_jimenez_kasintseva_francisca_jorge","bid":0.47,"ask":0.57,"mid":0.52,"spread":0.1,"bid_size":null,"ask_size":null}
{"ts":"2026-08-24T20:48:18.869Z","event_type":"best_bid_ask","market_id":"3824796","outcome_index":1,"market_type":"set2","local_side":"away","local_uid":"2026-08-24_victoria_jimenez_kasintseva_francisca_jorge","bid":0.43,"ask":0.53,"mid":0.48,"spread":0.1,"bid_size":null,"ask_size":null}
{"ts":"2026-08-24T20:48:18.869Z","event_type":"price_change","market_id":"3824796","outcome_index":0,"market_type":"set2","local_side":"home","local_uid":"2026-08-24_victoria_jimenez_kasintseva_francisca_jorge","bid":0.47,"ask":0.57,"mid":0.52,"spread":0.1,"price":0.47,"size":1095.0,"side":"BUY"}
{"ts":"2026-08-24T20:48:18.869Z","event_type":"price_change","market_id":"3824796","outcome_index":1,"market_type":"set2","local_side":"away","local_uid":"2026-08-24_victoria_jimenez_kasintseva_francisca_jorge","bid":0.43,"ask":0.53,"mid":0.48,"spread":0.1,"price":0.53,"size":1095.0,"side":"SELL"}
{"ts":"2026-08-24T20:48:18.870Z","event_type":"best_bid_ask","market_id":"3824761","outcome_index":0,"market_type":"set1","local_side":"home","local_uid":"2026-08-24_jazmin_ortenzi_himeno_sakatsume","bid":0.14,"ask":0.29,"mid":0.215,"spread":0.15,"bid_size":null,"ask_size":null}
{"ts":"2026-08-24T20:48:18.870Z","event_type":"best_bid_ask","market_id":"3824761","outcome_index":1,"market_type":"set1","local_side":"away","local_uid":"2026-08-24_jazmin_ortenzi_himeno_sakatsume","bid":0.71,"ask":0.86,"mid":0.785,"spread":0.15,"bid_size":null,"ask_size":null}
{"ts":"2026-08-24T20:48:18.870Z","event_type":"price_change","market_id":"3824761","outcome_index":1,"market_type":"set1","local_side":"away","local_uid":"2026-08-24_jazmin_ortenzi_himeno_sakatsume","bid":0.71,"ask":0.86,"mid":0.785,"spread":0.15,"price":0.71,"size":250.0,"side":"BUY"}
{"ts":"2026-08-24T20:48:18.871Z","event_type":"price_change","market_id":"3824761","outcome_index":0,"market_type":"set1","local_side":"home","local_uid":"2026-08-24_jazmin_ortenzi_himeno_sakatsume","bid":0.14,"ask":0.29,"mid":0.215,"spread":0.15,"price":0.29,"size":250.0,"side":"SELL"}
{"ts":"2026-08-24T20:48:18.972Z","event_type":"best_bid_ask","market_id":"3825077","outcome_index":0,"market_type":"set1","local_side":"home","local_uid":"2026-08-24_polina_kudermetova_linda_fruhvirtova","bid":0.45,"ask":0.51,"mid":0.48,"spread":0.06,"bid_size":null,"ask_size":null}
{"ts":"2026-08-24T20:48:18.973Z","event_type":"best_bid_ask","market_id":"3825077","outcome_index":1,"market_type":"set1","local_side":"away","local_uid":"2026-08-24_polina_kudermetova_linda_fruhvirtova","bid":0.49,"ask":0.55,"mid":0.52,"spread":0.06,"bid_size":null,"ask_size":null}
{"ts":"2026-08-24T20:48:18.973Z","event_type":"price_change","market_id":"3825077","outcome_index":1,"market_type":"set1","local_side":"away","local_uid":"2026-08-24_polina_kudermetova_linda_fruhvirtova","bid":0.49,"ask":0.55,"mid":0.52,"spread":0.06,"price":0.5,"size":0.0,"side":"BUY"}
{"ts":"2026-08-24T20:48:18.973Z","event_type":"price_change","market_id":"3825077","outcome_index":0,"market_type":"set1","local_side":"home","local_uid":"2026-08-24_polina_kudermetova_linda_fruhvirtova","bid":0.45,"ask":0.51,"mid":0.48,"spread":0.06,"price":0.5,"size":0.0,"side":"SELL"}
{"ts":"2026-08-24T20:48:18.977Z","event_type":"price_change","market_id":"3823663","outcome_index":1,"market_type":"match","local_side":"away","local_uid":"2026-08-24_savannah_broadus_tyra_caterina_grant","bid":0.65,"ask":0.66,"mid":0.655,"spread":0.01,"price":0.47,"size":50.0,"side":"BUY"}
{"ts":"2026-08-24T20:48:18.978Z","event_type":"price_change","market_id":"3823663","outcome_index":0,"market_type":"match","local_side":"home","local_uid":"2026-08-24_savannah_broadus_tyra_caterina_grant","bid":0.34,"ask":0.35,"mid":0.345,"spread":0.01,"price":0.53,"size":50.0,"side":"SELL"}
{"ts":"2026-08-24T20:48:18.978Z","event_type":"best_bid_ask","market_id":"3826738","outcome_index":0,"market_type":"set2","local_side":"home","local_uid":"2026-08-24_harry_wendelken_stefano_travaglia","bid":0.5,"ask":0.6,"mid":0.55,"spread":0.1,"bid_size":null,"ask_size":null}
{"ts":"2026-08-24T20:48:18.984Z","event_type":"best_bid_ask","market_id":"3826738","outcome_index":1,"market_type":"set2","local_side":"away","local_uid":"2026-08-24_harry_wendelken_stefano_travaglia","bid":0.4,"ask":0.5,"mid":0.45,"spread":0.1,"bid_size":null,"ask_size":null}
{"ts":"2026-08-24T20:48:18.985Z","event_type":"price_change","market_id":"3826738","outcome_index":0,"market_type":"set2","local_side":"home","local_uid":"2026-08-24_harry_wendelken_stefano_travaglia","bid":0.5,"ask":0.6,"mid":0.55,"spread":0.1,"price":0.5,"size":24.6,"side":"BUY"}
{"ts":"2026-08-24T20:48:18.985Z","event_type":"price_change","market_id":"3826738","outcome_index":1,"market_type":"set2","local_side":"away","local_uid":"2026-08-24_harry_wendelken_stefano_travaglia","bid":0.4,"ask":0.5,"mid":0.45,"spread":0.1,"price":0.5,"size":24.6,"side":"SELL"}
{"ts":"2026-08-24T20:48:19.008Z","event_type":"best_bid_ask","market_id":"3825070","outcome_index":0,"market_type":"set2","local_side":"home","local_uid":"2026-08-24_polina_kudermetova_linda_fruhvirtova","bid":0.5,"ask":0.61,"mid":0.555,"spread":0.11,"bid_size":null,"ask_size":null}
{"ts":"2026-08-24T20:48:19.008Z","event_type":"best_bid_ask","market_id":"3825070","outcome_index":1,"market_type":"set2","local_side":"away","local_uid":"2026-08-24_polina_kudermetova_linda_fruhvirtova","bid":0.39,"ask":0.5,"mid":0.445,"spread":0.11,"bid_size":null,"ask_size":null}
{"ts":"2026-08-24T20:48:19.009Z","event_type":"price_change","market_id":"3825070","outcome_index":0,"market_type":"set2","local_side":"home","local_uid":"2026-08-24_polina_kudermetova_linda_fruhvirtova","bid":0.5,"ask":0.61,"mid":0.555,"spread":0.11,"price":0.5,"size":150.0,"side":"BUY"}
{"ts":"2026-08-24T20:48:19.009Z","event_type":"price_change","market_id":"3825070","outcome_index":1,"market_type":"set2","local_side":"away","local_uid":"2026-08-24_polina_kudermetova_linda_fruhvirtova","bid":0.39,"ask":0.5,"mid":0.445,"spread":0.11,"price":0.5,"size":150.0,"side":"SELL"}
{"ts":"2026-08-24T20:48:19.127Z","event_type":"best_bid_ask","market_id":"3826919","outcome_index":0,"market_type":"set2","local_side":"home","local_uid":"2026-08-24_dalibor_svrcina_felipe_meligeni_alves","bid":0.44,"ask":0.52,"mid":0.48,"spread":0.08,"bid_size":null,"ask_size":null}
{"ts":"2026-08-24T20:48:19.133Z","event_type":"best_bid_ask","market_id":"3826919","outcome_index":1,"market_type":"set2","local_side":"away","local_uid":"2026-08-24_dalibor_svrcina_felipe_meligeni_alves","bid":0.48,"ask":0.56,"mid":0.52,"spread":0.08,"bid_size":null,"ask_size":null}
{"ts":"2026-08-24T20:48:19.133Z","event_type":"price_change","market_id":"3826919","outcome_index":0,"market_type":"set2","local_side":"home","local_uid":"2026-08-24_dalibor_svrcina_felipe_meligeni_alves","bid":0.44,"ask":0.52,"mid":0.48,"spread":0.08,"price":0.44,"size":123.98,"side":"BUY"}
{"ts":"2026-08-24T20:48:19.134Z","event_type":"price_change","market_id":"3826919","outcome_index":1,"market_type":"set2","local_side":"away","local_uid":"2026-08-24_dalibor_svrcina_felipe_meligeni_alves","bid":0.48,"ask":0.56,"mid":0.52,"spread":0.08,"price":0.56,"size":123.98,"side":"SELL"}
{"ts":"2026-08-24T20:48:19.139Z","event_type":"best_bid_ask","market_id":"3826733","outcome_index":0,"market_type":"set1","local_side":"home","local_uid":"2026-08-24_harry_wendelken_stefano_travaglia","bid":0.85,"ask":0.89,"mid":0.87,"spread":0.04,"bid_size":null,"ask_size":null}
{"ts":"2026-08-24T20:48:19.140Z","event_type":"best_bid_ask","market_id":"3826733","outcome_index":1,"market_type":"set1","local_side":"away","local_uid":"2026-08-24_harry_wendelken_stefano_travaglia","bid":0.11,"ask":0.15,"mid":0.13,"spread":0.04,"bid_size":null,"ask_size":null}
{"ts":"2026-08-24T20:48:19.140Z","event_type":"price_change","market_id":"3826733","outcome_index":1,"market_type":"set1","local_side":"away","local_uid":"2026-08-24_harry_wendelken_stefano_travaglia","bid":0.11,"ask":0.15,"mid":0.13,"spread":0.04,"price":0.11,"size":250.0,"side":"BUY"}
{"ts":"2026-08-24T20:48:19.140Z","event_type":"price_change","market_id":"3826733","outcome_index":0,"market_type":"set1","local_side":"home","local_uid":"2026-08-24_harry_wendelken_stefano_travaglia","bid":0.85,"ask":0.89,"mid":0.87,"spread":0.04,"price":0.89,"size":250.0,"side":"SELL"}
{"ts":"2026-08-24T20:48:19.144Z","event_type":"best_bid_ask","market_id":"3826733","outcome_index":0,"market_type":"set1","local_side":"home","local_uid":"2026-08-24_harry_wendelken_stefano_travaglia","bid":0.85,"ask":0.86,"mid":0.855,"spread":0.01,"bid_size":null,"ask_size":null}
{"ts":"2026-08-24T20:48:19.144Z","event_type":"best_bid_ask","market_id":"3826733","outcome_index":1,"market_type":"set1","local_side":"away","local_uid":"2026-08-24_harry_wendelken_stefano_travaglia","bid":0.14,"ask":0.15,"mid":0.145,"spread":0.01,"bid_size":null,"ask_size":null}
{"ts":"2026-08-24T20:48:19.145Z","event_type":"price_change","market_id":"3826733","outcome_index":1,"market_type":"set1","local_side":"away","local_uid":"2026-08-24_harry_wendelken_stefano_travaglia","bid":0.14,"ask":0.15,"mid":0.145,"spread":0.01,"price":0.14,"size":200.0,"side":"BUY"}
{"ts":"2026-08-24T20:48:19.145Z","event_type":"price_change","market_id":"3826733","outcome_index":0,"market_type":"set1","local_side":"home","local_uid":"2026-08-24_harry_wendelken_stefano_travaglia","bid":0.85,"ask":0.86,"mid":0.855,"spread":0.01,"price":0.86,"size":200.0,"side":"SELL"}
{"ts":"2026-08-24T20:48:19.164Z","event_type":"best_bid_ask","market_id":"3823619","outcome_index":0,"market_type":"match","local_side":"home","local_uid":"2026-08-24_polina_kudermetova_linda_fruhvirtova","bid":0.53,"ask":0.55,"mid":0.54,"spread":0.02,"bid_size":null,"ask_size":null}
{"ts":"2026-08-24T20:48:19.165Z","event_type":"best_bid_ask","market_id":"3823619","outcome_index":1,"market_type":"match","local_side":"away","local_uid":"2026-08-24_polina_kudermetova_linda_fruhvirtova","bid":0.45,"ask":0.47,"mid":0.46,"spread":0.02,"bid_size":null,"ask_size":null}
{"ts":"2026-08-24T20:48:19.165Z","event_type":"price_change","market_id":"3823619","outcome_index":1,"market_type":"match","local_side":"away","local_uid":"2026-08-24_polina_kudermetova_linda_fruhvirtova","bid":0.45,"ask":0.47,"mid":0.46,"spread":0.02,"price":0.46,"size":0.0,"side":"BUY"}
{"ts":"2026-08-24T20:48:19.165Z","event_type":"price_change","market_id":"3823619","outcome_index":0,"market_type":"match","local_side":"home","local_uid":"2026-08-24_polina_kudermetova_linda_fruhvirtova","bid":0.53,"ask":0.55,"mid":0.54,"spread":0.02,"price":0.54,"size":0.0,"side":"SELL"}
{"ts":"2026-08-24T20:48:19.183Z","event_type":"best_bid_ask","market_id":"3823619","outcome_index":0,"market_type":"match","local_side":"home","local_uid":"2026-08-24_polina_kudermetova_linda_fruhvirtova","bid":0.53,"ask":0.56,"mid":0.545,"spread":0.03,"bid_size":null,"ask_size":null}
{"ts":"2026-08-24T20:48:19.183Z","event_type":"best_bid_ask","market_id":"3823619","outcome_index":1,"market_type":"match","local_side":"away","local_uid":"2026-08-24_polina_kudermetova_linda_fruhvirtova","bid":0.44,"ask":0.47,"mid":0.455,"spread":0.03,"bid_size":null,"ask_size":null}
{"ts":"2026-08-24T20:48:19.184Z","event_type":"price_change","market_id":"3823619","outcome_index":1,"market_type":"match","local_side":"away","local_uid":"2026-08-24_polina_kudermetova_linda_fruhvirtova","bid":0.44,"ask":0.47,"mid":0.455,"spread":0.03,"price":0.45,"size":0.0,"side":"BUY"}
{"ts":"2026-08-24T20:48:19.184Z","event_type":"price_change","market_id":"3823619","outcome_index":0,"market_type":"match","local_side":"home","local_uid":"2026-08-24_polina_kudermetova_linda_fruhvirtova","bid":0.53,"ask":0.56,"mid":0.545,"spread":0.03,"price":0.55,"size":0.0,"side":"SELL"}
{"ts":"2026-08-24T20:48:19.198Z","event_type":"book","market_id":"3823619","outcome_index":0,"market_type":"match","local_side":"home","local_uid":"2026-08-24_polina_kudermetova_linda_fruhvirtova","bid":0.53,"ask":0.56,"mid":0.545,"spread":0.03,"bid_size":11525.0,"ask_size":2920.0}
{"ts":"2026-08-24T20:48:19.198Z","event_type":"book","market_id":"3823619","outcome_index":1,"market_type":"match","local_side":"away","local_uid":"2026-08-24_polina_kudermetova_linda_fruhvirtova","bid":0.44,"ask":0.47,"mid":0.455,"spread":0.03,"bid_size":2920.0,"ask_size":11525.0}
{"ts":"2026-08-24T20:48:19.247Z","event_type":"best_bid_ask","market_id":"3823619","outcome_index":0,"market_type":"match","local_side":"home","local_uid":"2026-08-24_polina_kudermetova_linda_fruhvirtova","bid":0.53,"ask":0.55,"mid":0.54,"spread":0.02,"bid_size":null,"ask_size":null}
{"ts":"2026-08-24T20:48:19.247Z","event_type":"best_bid_ask","market_id":"3823619","outcome_index":1,"market_type":"match","local_side":"away","local_uid":"2026-08-24_polina_kudermetova_linda_fruhvirtova","bid":0.45,"ask":0.47,"mid":0.46,"spread":0.02,"bid_size":null,"ask_size":null}
{"ts":"2026-08-24T20:48:19.248Z","event_type":"price_change","market_id":"3823619","outcome_index":1,"market_type":"match","local_side":"away","local_uid":"2026-08-24_polina_kudermetova_linda_fruhvirtova","bid":0.45,"ask":0.47,"mid":0.46,"spread":0.02,"price":0.45,"size":50.0,"side":"BUY"}
{"ts":"2026-08-24T20:48:19.248Z","event_type":"price_change","market_id":"3823619","outcome_index":0,"market_type":"match","local_side":"home","local_uid":"2026-08-24_polina_kudermetova_linda_fruhvirtova","bid":0.53,"ask":0.55,"mid":0.54,"spread":0.02,"price":0.55,"size":50.0,"side":"SELL"}
{"ts":"2026-08-24T20:48:19.249Z","event_type":"best_bid_ask","market_id":"3826919","outcome_index":0,"market_type":"set2","local_side":"home","local_uid":"2026-08-24_dalibor_svrcina_felipe_meligeni_alves","bid":0.43,"ask":0.52,"mid":0.475,"spread":0.09,"bid_size":null,"ask_size":null}
{"ts":"2026-08-24T20:48:19.249Z","event_type":"best_bid_ask","market_id":"3826919","outcome_index":1,"market_type":"set2","local_side":"away","local_uid":"2026-08-24_dalibor_svrcina_felipe_meligeni_alves","bid":0.48,"ask":0.57,"mid":0.525,"spread":0.09,"bid_size":null,"ask_size":null}
{"ts":"2026-08-24T20:48:19.249Z","event_type":"price_change","market_id":"3826919","outcome_index":0,"market_type":"set2","local_side":"home","local_uid":"2026-08-24_dalibor_svrcina_felipe_meligeni_alves","bid":0.43,"ask":0.52,"mid":0.475,"spread":0.09,"price":0.44,"size":0.0,"side":"BUY"}
{"ts":"2026-08-24T20:48:19.249Z","event_type":"price_change","market_id":"3826919","outcome_index":1,"market_type":"set2","local_side":"away","local_uid":"2026-08-24_dalibor_svrcina_felipe_meligeni_alves","bid":0.48,"ask":0.57,"mid":0.525,"spread":0.09,"price":0.56,"size":0.0,"side":"SELL"}
{"ts":"2026-08-24T20:48:19.262Z","event_type":"best_bid_ask","market_id":"3823619","outcome_index":0,"market_type":"match","local_side":"home","local_uid":"2026-08-24_polina_kudermetova_linda_fruhvirtova","bid":0.55,"ask":0.56,"mid":0.555,"spread":0.01,"bid_size":null,"ask_size":null}
{"ts":"2026-08-24T20:48:19.262Z","event_type":"best_bid_ask","market_id":"3823619","outcome_index":1,"market_type":"match","local_side":"away","local_uid":"2026-08-24_polina_kudermetova_linda_fruhvirtova","bid":0.44,"ask":0.45,"mid":0.445,"spread":0.01,"bid_size":null,"ask_size":null}
{"ts":"2026-08-24T20:48:19.262Z","event_type":"price_change","market_id":"3823619","outcome_index":0,"market_type":"match","local_side":"home","local_uid":"2026-08-24_polina_kudermetova_linda_fruhvirtova","bid":0.55,"ask":0.56,"mid":0.555,"spread":0.01,"price":0.55,"size":288.0,"side":"BUY"}
{"ts":"2026-08-24T20:48:19.262Z","event_type":"price_change","market_id":"3823619","outcome_index":1,"market_type":"match","local_side":"away","local_uid":"2026-08-24_polina_kudermetova_linda_fruhvirtova","bid":0.44,"ask":0.45,"mid":0.445,"spread":0.01,"price":0.45,"size":288.0,"side":"SELL"}
{"ts":"2026-08-24T20:48:19.264Z","event_type":"book","market_id":"3823619","outcome_index":0,"market_type":"match","local_side":"home","local_uid":"2026-08-24_polina_kudermetova_linda_fruhvirtova","bid":0.55,"ask":0.56,"mid":0.555,"spread":0.01,"bid_size":288.0,"ask_size":2920.0}
{"ts":"2026-08-24T20:48:19.272Z","event_type":"book","market_id":"3823619","outcome_index":1,"market_type":"match","local_side":"away","local_uid":"2026-08-24_polina_kudermetova_linda_fruhvirtova","bid":0.44,"ask":0.45,"mid":0.445,"spread":0.01,"bid_size":2920.0,"ask_size":288.0}
{"ts":"2026-08-24T20:48:19.276Z","event_type":"best_bid_ask","market_id":"3826919","outcome_index":0,"market_type":"set2","local_side":"home","local_uid":"2026-08-24_dalibor_svrcina_felipe_meligeni_alves","bid":0.44,"ask":0.52,"mid":0.48,"spread":0.08,"bid_size":null,"ask_size":null}
{"ts":"2026-08-24T20:48:19.276Z","event_type":"best_bid_ask","market_id":"3826919","outcome_index":1,"market_type":"set2","local_side":"away","local_uid":"2026-08-24_dalibor_svrcina_felipe_meligeni_alves","bid":0.48,"ask":0.56,"mid":0.52,"spread":0.08,"bid_size":null,"ask_size":null}
{"ts":"2026-08-24T20:48:19.276Z","event_type":"price_change","market_id":"3826919","outcome_index":0,"market_type":"set2","local_side":"home","local_uid":"2026-08-24_dalibor_svrcina_felipe_meligeni_alves","bid":0.44,"ask":0.52,"mid":0.48,"spread":0.08,"price":0.44,"size":79.2,"side":"BUY"}
{"ts":"2026-08-24T20:48:19.276Z","event_type":"price_change","market_id":"3826919","outcome_index":1,"market_type":"set2","local_side":"away","local_uid":"2026-08-24_dalibor_svrcina_felipe_meligeni_alves","bid":0.48,"ask":0.56,"mid":0.52,"spread":0.08,"price":0.56,"size":79.2,"side":"SELL"}
{"ts":"2026-08-24T20:48:19.285Z","event_type":"best_bid_ask","market_id":"3823619","outcome_index":0,"market_type":"match","local_side":"home","local_uid":"2026-08-24_polina_kudermetova_linda_fruhvirtova","bid":0.53,"ask":0.56,"mid":0.545,"spread":0.03,"bid_size":null,"ask_size":null}
{"ts":"2026-08-24T20:48:19.286Z","event_type":"best_bid_ask","market_id":"3823619","outcome_index":1,"market_type":"match","local_side":"away","local_uid":"2026-08-24_polina_kudermetova_linda_fruhvirtova","bid":0.44,"ask":0.47,"mid":0.455,"spread":0.03,"bid_size":null,"ask_size":null}
{"ts":"2026-08-24T20:48:19.286Z","event_type":"price_change","market_id":"3823619","outcome_index":0,"market_type":"match","local_side":"home","local_uid":"2026-08-24_polina_kudermetova_linda_fruhvirtova","bid":0.53,"ask":0.56,"mid":0.545,"spread":0.03,"price":0.55,"size":0.0,"side":"BUY"}
{"ts":"2026-08-24T20:48:19.286Z","event_type":"price_change","market_id":"3823619","outcome_index":1,"market_type":"match","local_side":"away","local_uid":"2026-08-24_polina_kudermetova_linda_fruhvirtova","bid":0.44,"ask":0.47,"mid":0.455,"spread":0.03,"price":0.45,"size":0.0,"side":"SELL"}
{"ts":"2026-08-24T20:48:19.305Z","event_type":"best_bid_ask","market_id":"3823619","outcome_index":0,"market_type":"match","local_side":"home","local_uid":"2026-08-24_polina_kudermetova_linda_fruhvirtova","bid":0.54,"ask":0.56,"mid":0.55,"spread":0.02,"bid_size":null,"ask_size":null}
{"ts":"2026-08-24T20:48:19.309Z","event_type":"best_bid_ask","market_id":"3823619","outcome_index":1,"market_type":"match","local_side":"away","local_uid":"2026-08-24_polina_kudermetova_linda_fruhvirtova","bid":0.44,"ask":0.46,"mid":0.45,"spread":0.02,"bid_size":null,"ask_size":null}
{"ts":"2026-08-24T20:48:19.310Z","event_type":"price_change","market_id":"3823619","outcome_index":0,"market_type":"match","local_side":"home","local_uid":"2026-08-24_polina_kudermetova_linda_fruhvirtova","bid":0.54,"ask":0.56,"mid":0.55,"spread":0.02,"price":0.54,"size":7.0,"side":"BUY"}
{"ts":"2026-08-24T20:48:19.310Z","event_type":"price_change","market_id":"3823619","outcome_index":1,"market_type":"match","local_side":"away","local_uid":"2026-08-24_polina_kudermetova_linda_fruhvirtova","bid":0.44,"ask":0.46,"mid":0.45,"spread":0.02,"price":0.46,"size":7.0,"side":"SELL"}
{"ts":"2026-08-24T20:48:19.380Z","event_type":"best_bid_ask","market_id":"3826654","outcome_index":0,"market_type":"set2","local_side":"home","local_uid":"2026-08-24_sebastian_gorzny_cruz_hewitt","bid":0.05,"ask":0.13,"mid":0.09,"spread":0.08,"bid_size":null,"ask_size":null}
{"ts":"2026-08-24T20:48:19.380Z","event_type":"best_bid_ask","market_id":"3826654","outcome_index":1,"market_type":"set2","local_side":"away","local_uid":"2026-08-24_sebastian_gorzny_cruz_hewitt","bid":0.87,"ask":0.95,"mid":0.91,"spread":0.08,"bid_size":null,"ask_size":null}
{"ts":"2026-08-24T20:48:19.381Z","event_type":"price_change","market_id":"3826654","outcome_index":0,"market_type":"set2","local_side":"home","local_uid":"2026-08-24_sebastian_gorzny_cruz_hewitt","bid":0.05,"ask":0.13,"mid":0.09,"spread":0.08,"price":0.05,"size":13.0,"side":"BUY"}
{"ts":"2026-08-24T20:48:19.381Z","event_type":"price_change","market_id":"3826654","outcome_index":1,"market_type":"set2","local_side":"away","local_uid":"2026-08-24_sebastian_gorzny_cruz_hewitt","bid":0.87,"ask":0.95,"mid":0.91,"spread":0.08,"price":0.95,"size":13.0,"side":"SELL"}
{"ts":"2026-08-24T20:48:19.381Z","event_type":"best_bid_ask","market_id":"3826654","outcome_index":0,"market_type":"set2","local_side":"home","local_uid":"2026-08-24_sebastian_gorzny_cruz_hewitt","bid":0.06,"ask":0.13,"mid":0.095,"spread":0.07,"bid_size":null,"ask_size":null}
{"ts":"2026-08-24T20:48:19.381Z","event_type":"best_bid_ask","market_id":"3826654","outcome_index":1,"market_type":"set2","local_side":"away","local_uid":"2026-08-24_sebastian_gorzny_cruz_hewitt","bid":0.87,"ask":0.94,"mid":0.905,"spread":0.07,"bid_size":null,"ask_size":null}
{"ts":"2026-08-24T20:48:19.382Z","event_type":"price_change","market_id":"3826654","outcome_index":0,"market_type":"set2","local_side":"home","local_uid":"2026-08-24_sebastian_gorzny_cruz_hewitt","bid":0.06,"ask":0.13,"mid":0.095,"spread":0.07,"price":0.06,"size":22.0,"side":"BUY"}
{"ts":"2026-08-24T20:48:19.382Z","event_type":"price_change","market_id":"3826654","outcome_index":1,"market_type":"set2","local_side":"away","local_uid":"2026-08-24_sebastian_gorzny_cruz_hewitt","bid":0.87,"ask":0.94,"mid":0.905,"spread":0.07,"price":0.94,"size":22.0,"side":"SELL"}
{"ts":"2026-08-24T20:48:19.411Z","event_type":"last_trade_price","market_id":"3823619","outcome_index":0,"market_type":"match","local_side":"home","local_uid":"2026-08-24_polina_kudermetova_linda_fruhvirtova","last_trade":0.55,"trade_size":50.0,"trade_side":"BUY","trade_notional":27.5}
{"ts":"2026-08-24T20:48:19.415Z","event_type":"last_trade_price","market_id":"3823619","outcome_index":1,"market_type":"match","local_side":"away","local_uid":"2026-08-24_polina_kudermetova_linda_fruhvirtova","last_trade":0.45,"trade_size":20.0,"trade_side":"SELL","trade_notional":9.0}
{"ts":"2026-08-24T20:48:19.520Z","event_type":"price_change","market_id":"3825038","outcome_index":1,"market_type":"set1","local_side":"away","local_uid":"2026-08-24_greet_minnen_jeline_vandromme","bid":0.967,"ask":0.999,"mid":0.983,"spread":0.032,"price":0.96,"size":0.0,"side":"BUY"}
{"ts":"2026-08-24T20:48:19.520Z","event_type":"price_change","market_id":"3825038","outcome_index":0,"market_type":"set1","local_side":"home","local_uid":"2026-08-24_greet_minnen_jeline_vandromme","bid":0.001,"ask":0.033,"mid":0.017,"spread":0.032,"price":0.04,"size":0.0,"side":"SELL"}
{"ts":"2026-08-24T20:48:19.534Z","event_type":"best_bid_ask","market_id":"3823625","outcome_index":0,"market_type":"match","local_side":"home","local_uid":"2026-08-24_greet_minnen_jeline_vandromme","bid":0.16,"ask":0.18,"mid":0.17,"spread":0.02,"bid_size":null,"ask_size":null}
{"ts":"2026-08-24T20:48:19.534Z","event_type":"best_bid_ask","market_id":"3823625","outcome_index":1,"market_type":"match","local_side":"away","local_uid":"2026-08-24_greet_minnen_jeline_vandromme","bid":0.82,"ask":0.84,"mid":0.83,"spread":0.02,"bid_size":null,"ask_size":null}
{"ts":"2026-08-24T20:48:19.534Z","event_type":"price_change","market_id":"3823625","outcome_index":0,"market_type":"match","local_side":"home","local_uid":"2026-08-24_greet_minnen_jeline_vandromme","bid":0.16,"ask":0.18,"mid":0.17,"spread":0.02,"price":0.17,"size":0.0,"side":"BUY"}
{"ts":"2026-08-24T20:48:19.534Z","event_type":"price_change","market_id":"3823625","outcome_index":1,"market_type":"match","local_side":"away","local_uid":"2026-08-24_greet_minnen_jeline_vandromme","bid":0.82,"ask":0.84,"mid":0.83,"spread":0.02,"price":0.83,"size":0.0,"side":"SELL"}
{"ts":"2026-08-24T20:48:19.555Z","event_type":"best_bid_ask","market_id":"3825077","outcome_index":0,"market_type":"set1","local_side":"home","local_uid":"2026-08-24_polina_kudermetova_linda_fruhvirtova","bid":0.45,"ask":0.5,"mid":0.475,"spread":0.05,"bid_size":null,"ask_size":null}
{"ts":"2026-08-24T20:48:19.555Z","event_type":"best_bid_ask","market_id":"3825077","outcome_index":1,"market_type":"set1","local_side":"away","local_uid":"2026-08-24_polina_kudermetova_linda_fruhvirtova","bid":0.5,"ask":0.55,"mid":0.525,"spread":0.05,"bid_size":null,"ask_size":null}
{"ts":"2026-08-24T20:48:19.556Z","event_type":"price_change","market_id":"3825077","outcome_index":1,"market_type":"set1","local_side":"away","local_uid":"2026-08-24_polina_kudermetova_linda_fruhvirtova","bid":0.5,"ask":0.55,"mid":0.525,"spread":0.05,"price":0.5,"size":15.0,"side":"BUY"}
{"ts":"2026-08-24T20:48:19.556Z","event_type":"price_change","market_id":"3825077","outcome_index":0,"market_type":"set1","local_side":"home","local_uid":"2026-08-24_polina_kudermetova_linda_fruhvirtova","bid":0.45,"ask":0.5,"mid":0.475,"spread":0.05,"price":0.5,"size":15.0,"side":"SELL"}
{"ts":"2026-08-24T20:48:19.569Z","event_type":"best_bid_ask","market_id":"3823625","outcome_index":0,"market_type":"match","local_side":"home","local_uid":"2026-08-24_greet_minnen_jeline_vandromme","bid":0.17,"ask":0.18,"mid":0.175,"spread":0.01,"bid_size":null,"ask_size":null}
{"ts":"2026-08-24T20:48:19.569Z","event_type":"best_bid_ask","market_id":"3823625","outcome_index":1,"market_type":"match","local_side":"away","local_uid":"2026-08-24_greet_minnen_jeline_vandromme","bid":0.82,"ask":0.83,"mid":0.825,"spread":0.01,"bid_size":null,"ask_size":null}
{"ts":"2026-08-24T20:48:19.570Z","event_type":"price_change","market_id":"3823625","outcome_index":0,"market_type":"match","local_side":"home","local_uid":"2026-08-24_greet_minnen_jeline_vandromme","bid":0.17,"ask":0.18,"mid":0.175,"spread":0.01,"price":0.17,"size":20.0,"side":"BUY"}
{"ts":"2026-08-24T20:48:19.570Z","event_type":"price_change","market_id":"3823625","outcome_index":1,"market_type":"match","local_side":"away","local_uid":"2026-08-24_greet_minnen_jeline_vandromme","bid":0.82,"ask":0.83,"mid":0.825,"spread":0.01,"price":0.83,"size":20.0,"side":"SELL"}
{"ts":"2026-08-24T20:48:19.570Z","event_type":"best_bid_ask","market_id":"3823619","outcome_index":0,"market_type":"match","local_side":"home","local_uid":"2026-08-24_polina_kudermetova_linda_fruhvirtova","bid":0.55,"ask":0.56,"mid":0.555,"spread":0.01,"bid_size":null,"ask_size":null}
{"ts":"2026-08-24T20:48:19.570Z","event_type":"best_bid_ask","market_id":"3823619","outcome_index":1,"market_type":"match","local_side":"away","local_uid":"2026-08-24_polina_kudermetova_linda_fruhvirtova","bid":0.44,"ask":0.45,"mid":0.445,"spread":0.01,"bid_size":null,"ask_size":null}
{"ts":"2026-08-24T20:48:19.571Z","event_type":"price_change","market_id":"3823619","outcome_index":0,"market_type":"match","local_side":"home","local_uid":"2026-08-24_polina_kudermetova_linda_fruhvirtova","bid":0.55,"ask":0.56,"mid":0.555,"spread":0.01,"price":0.55,"size":10.0,"side":"BUY"}
{"ts":"2026-08-24T20:48:19.571Z","event_type":"price_change","market_id":"3823619","outcome_index":1,"market_type":"match","local_side":"away","local_uid":"2026-08-24_polina_kudermetova_linda_fruhvirtova","bid":0.44,"ask":0.45,"mid":0.445,"spread":0.01,"price":0.45,"size":10.0,"side":"SELL"}
{"ts":"2026-08-24T20:48:19.651Z","event_type":"best_bid_ask","market_id":"3825070","outcome_index":0,"market_type":"set2","local_side":"home","local_uid":"2026-08-24_polina_kudermetova_linda_fruhvirtova","bid":0.51,"ask":0.61,"mid":0.56,"spread":0.1,"bid_size":null,"ask_size":null}
{"ts":"2026-08-24T20:48:19.651Z","event_type":"best_bid_ask","market_id":"3825070","outcome_index":1,"market_type":"set2","local_side":"away","local_uid":"2026-08-24_polina_kudermetova_linda_fruhvirtova","bid":0.39,"ask":0.49,"mid":0.44,"spread":0.1,"bid_size":null,"ask_size":null}
{"ts":"2026-08-24T20:48:19.652Z","event_type":"price_change","market_id":"3825070","outcome_index":0,"market_type":"set2","local_side":"home","local_uid":"2026-08-24_polina_kudermetova_linda_fruhvirtova","bid":0.51,"ask":0.61,"mid":0.56,"spread":0.1,"price":0.51,"size":150.0,"side":"BUY"}
{"ts":"2026-08-24T20:48:19.652Z","event_type":"price_change","market_id":"3825070","outcome_index":1,"market_type":"set2","local_side":"away","local_uid":"2026-08-24_polina_kudermetova_linda_fruhvirtova","bid":0.39,"ask":0.49,"mid":0.44,"spread":0.1,"price":0.49,"size":150.0,"side":"SELL"}
{"ts":"2026-08-24T20:48:19.692Z","event_type":"price_change","market_id":"3825614","outcome_index":0,"market_type":"match","local_side":"home","local_uid":"2026-08-24_jack_pinnington_jones_trevor_svajda","bid":0.42,"ask":0.43,"mid":0.425,"spread":0.01,"price":0.39,"size":12094.81,"side":"BUY"}
{"ts":"2026-08-24T20:48:19.692Z","event_type":"price_change","market_id":"3825614","outcome_index":1,"market_type":"match","local_side":"away","local_uid":"2026-08-24_jack_pinnington_jones_trevor_svajda","bid":0.57,"ask":0.58,"mid":0.575,"spread":0.01,"price":0.61,"size":12094.81,"side":"SELL"}
{"ts":"2026-08-24T20:48:19.739Z","event_type":"best_bid_ask","market_id":"3825038","outcome_index":0,"market_type":"set1","local_side":"home","local_uid":"2026-08-24_greet_minnen_jeline_vandromme","bid":0.001,"ask":0.041,"mid":0.021,"spread":0.04,"bid_size":null,"ask_size":null}
{"ts":"2026-08-24T20:48:19.740Z","event_type":"best_bid_ask","market_id":"3825038","outcome_index":1,"market_type":"set1","local_side":"away","local_uid":"2026-08-24_greet_minnen_jeline_vandromme","bid":0.959,"ask":0.999,"mid":0.979,"spread":0.04,"bid_size":null,"ask_size":null}
{"ts":"2026-08-24T20:48:19.740Z","event_type":"price_change","market_id":"3825038","outcome_index":1,"market_type":"set1","local_side":"away","local_uid":"2026-08-24_greet_minnen_jeline_vandromme","bid":0.959,"ask":0.999,"mid":0.979,"spread":0.04,"price":0.967,"size":0.0,"side":"BUY"}
{"ts":"2026-08-24T20:48:19.740Z","event_type":"price_change","market_id":"3825038","outcome_index":0,"market_type":"set1","local_side":"home","local_uid":"2026-08-24_greet_minnen_jeline_vandromme","bid":0.001,"ask":0.041,"mid":0.021,"spread":0.04,"price":0.033,"size":0.0,"side":"SELL"}
{"ts":"2026-08-24T20:48:19.788Z","event_type":"best_bid_ask","market_id":"3823629","outcome_index":0,"market_type":"match","local_side":"home","local_uid":"2026-08-24_angela_fita_boluda_lin_zhu","bid":0.49,"ask":0.52,"mid":0.505,"spread":0.03,"bid_size":null,"ask_size":null}
{"ts":"2026-08-24T20:48:19.788Z","event_type":"best_bid_ask","market_id":"3823629","outcome_index":1,"market_type":"match","local_side":"away","local_uid":"2026-08-24_angela_fita_boluda_lin_zhu","bid":0.48,"ask":0.51,"mid":0.495,"spread":0.03,"bid_size":null,"ask_size":null}
{"ts":"2026-08-24T20:48:19.789Z","event_type":"price_change","market_id":"3823629","outcome_index":1,"market_type":"match","local_side":"away","local_uid":"2026-08-24_angela_fita_boluda_lin_zhu","bid":0.48,"ask":0.51,"mid":0.495,"spread":0.03,"price":0.49,"size":0.0,"side":"BUY"}
{"ts":"2026-08-24T20:48:19.789Z","event_type":"price_change","market_id":"3823629","outcome_index":0,"market_type":"match","local_side":"home","local_uid":"2026-08-24_angela_fita_boluda_lin_zhu","bid":0.49,"ask":0.52,"mid":0.505,"spread":0.03,"price":0.51,"size":0.0,"side":"SELL"}
{"ts":"2026-08-24T20:48:19.805Z","event_type":"price_change","market_id":"3826875","outcome_index":0,"market_type":"set1","local_side":"home","local_uid":"2026-08-24_otto_virtanen_ugo_blanchet","bid":0.61,"ask":0.63,"mid":0.62,"spread":0.02,"price":0.49,"size":540.0,"side":"BUY"}
{"ts":"2026-08-24T20:48:19.805Z","event_type":"price_change","market_id":"3826875","outcome_index":1,"market_type":"set1","local_side":"away","local_uid":"2026-08-24_otto_virtanen_ugo_blanchet","bid":0.37,"ask":0.39,"mid":0.38,"spread":0.02,"price":0.51,"size":540.0,"side":"SELL"}
{"ts":"2026-08-24T20:48:19.817Z","event_type":"best_bid_ask","market_id":"3823625","outcome_index":0,"market_type":"match","local_side":"home","local_uid":"2026-08-24_greet_minnen_jeline_vandromme","bid":0.16,"ask":0.18,"mid":0.17,"spread":0.02,"bid_size":null,"ask_size":null}
{"ts":"2026-08-24T20:48:19.817Z","event_type":"best_bid_ask","market_id":"3823625","outcome_index":1,"market_type":"match","local_side":"away","local_uid":"2026-08-24_greet_minnen_jeline_vandromme","bid":0.82,"ask":0.84,"mid":0.83,"spread":0.02,"bid_size":null,"ask_size":null}
{"ts":"2026-08-24T20:48:19.817Z","event_type":"price_change","market_id":"3823625","outcome_index":0,"market_type":"match","local_side":"home","local_uid":"2026-08-24_greet_minnen_jeline_vandromme","bid":0.16,"ask":0.18,"mid":0.17,"spread":0.02,"price":0.17,"size":0.0,"side":"BUY"}
{"ts":"2026-08-24T20:48:19.817Z","event_type":"price_change","market_id":"3823625","outcome_index":1,"market_type":"match","local_side":"away","local_uid":"2026-08-24_greet_minnen_jeline_vandromme","bid":0.82,"ask":0.84,"mid":0.83,"spread":0.02,"price":0.83,"size":0.0,"side":"SELL"}
{"ts":"2026-08-24T20:48:19.842Z","event_type":"best_bid_ask","market_id":"3825038","outcome_index":0,"market_type":"set1","local_side":"home","local_uid":"2026-08-24_greet_minnen_jeline_vandromme","bid":0.001,"ask":0.05,"mid":0.0255,"spread":0.049,"bid_size":null,"ask_size":null}
{"ts":"2026-08-24T20:48:19.842Z","event_type":"best_bid_ask","market_id":"3825038","outcome_index":1,"market_type":"set1","local_side":"away","local_uid":"2026-08-24_greet_minnen_jeline_vandromme","bid":0.95,"ask":0.999,"mid":0.9745,"spread":0.049,"bid_size":null,"ask_size":null}
{"ts":"2026-08-24T20:48:19.843Z","event_type":"price_change","market_id":"3825038","outcome_index":1,"market_type":"set1","local_side":"away","local_uid":"2026-08-24_greet_minnen_jeline_vandromme","bid":0.95,"ask":0.999,"mid":0.9745,"spread":0.049,"price":0.959,"size":0.0,"side":"BUY"}
{"ts":"2026-08-24T20:48:19.843Z","event_type":"price_change","market_id":"3825038","outcome_index":0,"market_type":"set1","local_side":"home","local_uid":"2026-08-24_greet_minnen_jeline_vandromme","bid":0.001,"ask":0.05,"mid":0.0255,"spread":0.049,"price":0.041,"size":0.0,"side":"SELL"}
{"ts":"2026-08-24T20:48:19.939Z","event_type":"best_bid_ask","market_id":"3825038","outcome_index":0,"market_type":"set1","local_side":"home","local_uid":"2026-08-24_greet_minnen_jeline_vandromme","bid":0.001,"ask":0.08,"mid":0.0405,"spread":0.079,"bid_size":null,"ask_size":null}
{"ts":"2026-08-24T20:48:19.940Z","event_type":"best_bid_ask","market_id":"3825038","outcome_index":1,"market_type":"set1","local_side":"away","local_uid":"2026-08-24_greet_minnen_jeline_vandromme","bid":0.92,"ask":0.999,"mid":0.9595,"spread":0.079,"bid_size":null,"ask_size":null}
{"ts":"2026-08-24T20:48:19.940Z","event_type":"price_change","market_id":"3825038","outcome_index":1,"market_type":"set1","local_side":"away","local_uid":"2026-08-24_greet_minnen_jeline_vandromme","bid":0.92,"ask":0.999,"mid":0.9595,"spread":0.079,"price":0.95,"size":0.0,"side":"BUY"}
{"ts":"2026-08-24T20:48:19.940Z","event_type":"price_change","market_id":"3825038","outcome_index":0,"market_type":"set1","local_side":"home","local_uid":"2026-08-24_greet_minnen_jeline_vandromme","bid":0.001,"ask":0.08,"mid":0.0405,"spread":0.079,"price":0.05,"size":0.0,"side":"SELL"}
{"ts":"2026-08-24T20:48:19.950Z","event_type":"best_bid_ask","market_id":"3825038","outcome_index":0,"market_type":"set1","local_side":"home","local_uid":"2026-08-24_greet_minnen_jeline_vandromme","bid":0.001,"ask":0.075,"mid":0.038,"spread":0.074,"bid_size":null,"ask_size":null}
{"ts":"2026-08-24T20:48:19.950Z","event_type":"best_bid_ask","market_id":"3825038","outcome_index":1,"market_type":"set1","local_side":"away","local_uid":"2026-08-24_greet_minnen_jeline_vandromme","bid":0.925,"ask":0.999,"mid":0.962,"spread":0.074,"bid_size":null,"ask_size":null}
{"ts":"2026-08-24T20:48:19.950Z","event_type":"price_change","market_id":"3825038","outcome_index":1,"market_type":"set1","local_side":"away","local_uid":"2026-08-24_greet_minnen_jeline_vandromme","bid":0.925,"ask":0.999,"mid":0.962,"spread":0.074,"price":0.925,"size":42.31,"side":"BUY"}
{"ts":"2026-08-24T20:48:19.950Z","event_type":"price_change","market_id":"3825038","outcome_index":0,"market_type":"set1","local_side":"home","local_uid":"2026-08-24_greet_minnen_jeline_vandromme","bid":0.001,"ask":0.075,"mid":0.038,"spread":0.074,"price":0.075,"size":42.31,"side":"SELL"}
{"ts":"2026-08-24T20:48:19.977Z","event_type":"best_bid_ask","market_id":"3825038","outcome_index":0,"market_type":"set1","local_side":"home","local_uid":"2026-08-24_greet_minnen_jeline_vandromme","bid":0.001,"ask":0.059,"mid":0.03,"spread":0.058,"bid_size":null,"ask_size":null}
{"ts":"2026-08-24T20:48:19.978Z","event_type":"best_bid_ask","market_id":"3825038","outcome_index":1,"market_type":"set1","local_side":"away","local_uid":"2026-08-24_greet_minnen_jeline_vandromme","bid":0.941,"ask":0.999,"mid":0.97,"spread":0.058,"bid_size":null,"ask_size":null}
{"ts":"2026-08-24T20:48:19.978Z","event_type":"price_change","market_id":"3825038","outcome_index":1,"market_type":"set1","local_side":"away","local_uid":"2026-08-24_greet_minnen_jeline_vandromme","bid":0.941,"ask":0.999,"mid":0.97,"spread":0.058,"price":0.941,"size":250.0,"side":"BUY"}
{"ts":"2026-08-24T20:48:19.978Z","event_type":"price_change","market_id":"3825038","outcome_index":0,"market_type":"set1","local_side":"home","local_uid":"2026-08-24_greet_minnen_jeline_vandromme","bid":0.001,"ask":0.059,"mid":0.03,"spread":0.058,"price":0.059,"size":250.0,"side":"SELL"}
{"ts":"2026-08-24T20:48:20.020Z","event_type":"best_bid_ask","market_id":"3823625","outcome_index":0,"market_type":"match","local_side":"home","local_uid":"2026-08-24_greet_minnen_jeline_vandromme","bid":0.15,"ask":0.18,"mid":0.165,"spread":0.03,"bid_size":null,"ask_size":null}
{"ts":"2026-08-24T20:48:20.020Z","event_type":"best_bid_ask","market_id":"3823625","outcome_index":1,"market_type":"match","local_side":"away","local_uid":"2026-08-24_greet_minnen_jeline_vandromme","bid":0.82,"ask":0.85,"mid":0.835,"spread":0.03,"bid_size":null,"ask_size":null}
{"ts":"2026-08-24T20:48:20.020Z","event_type":"price_change","market_id":"3823625","outcome_index":1,"market_type":"match","local_side":"away","local_uid":"2026-08-24_greet_minnen_jeline_vandromme","bid":0.82,"ask":0.85,"mid":0.835,"spread":0.03,"price":0.82,"size":403.59,"side":"BUY"}
{"ts":"2026-08-24T20:48:20.021Z","event_type":"price_change","market_id":"3823625","outcome_index":0,"market_type":"match","local_side":"home","local_uid":"2026-08-24_greet_minnen_jeline_vandromme","bid":0.15,"ask":0.18,"mid":0.165,"spread":0.03,"price":0.18,"size":403.59,"side":"SELL"}
{"ts":"2026-08-24T20:48:20.114Z","event_type":"best_bid_ask","market_id":"3825608","outcome_index":0,"market_type":"match","local_side":"home","local_uid":"2026-08-24_raul_brancaccio_thiago_seyboth_wild","bid":0.22,"ask":0.25,"mid":0.235,"spread":0.03,"bid_size":null,"ask_size":null}
{"ts":"2026-08-24T20:48:20.115Z","event_type":"best_bid_ask","market_id":"3825608","outcome_index":1,"market_type":"match","local_side":"away","local_uid":"2026-08-24_raul_brancaccio_thiago_seyboth_wild","bid":0.75,"ask":0.78,"mid":0.765,"spread":0.03,"bid_size":null,"ask_size":null}
{"ts":"2026-08-24T20:48:20.115Z","event_type":"price_change","market_id":"3825608","outcome_index":1,"market_type":"match","local_side":"away","local_uid":"2026-08-24_raul_brancaccio_thiago_seyboth_wild","bid":0.75,"ask":0.78,"mid":0.765,"spread":0.03,"price":0.76,"size":0.0,"side":"BUY"}
{"ts":"2026-08-24T20:48:20.115Z","event_type":"price_change","market_id":"3825608","outcome_index":0,"market_type":"match","local_side":"home","local_uid":"2026-08-24_raul_brancaccio_thiago_seyboth_wild","bid":0.22,"ask":0.25,"mid":0.235,"spread":0.03,"price":0.24,"size":0.0,"side":"SELL"}
{"ts":"2026-08-24T20:48:20.123Z","event_type":"best_bid_ask","market_id":"3825070","outcome_index":0,"market_type":"set2","local_side":"home","local_uid":"2026-08-24_polina_kudermetova_linda_fruhvirtova","bid":0.52,"ask":0.61,"mid":0.565,"spread":0.09,"bid_size":null,"ask_size":null}
{"ts":"2026-08-24T20:48:20.124Z","event_type":"best_bid_ask","market_id":"3825070","outcome_index":1,"market_type":"set2","local_side":"away","local_uid":"2026-08-24_polina_kudermetova_linda_fruhvirtova","bid":0.39,"ask":0.48,"mid":0.435,"spread":0.09,"bid_size":null,"ask_size":null}
{"ts":"2026-08-24T20:48:20.132Z","event_type":"price_change","market_id":"3825070","outcome_index":0,"market_type":"set2","local_side":"home","local_uid":"2026-08-24_polina_kudermetova_linda_fruhvirtova","bid":0.52,"ask":0.61,"mid":0.565,"spread":0.09,"price":0.52,"size":150.0,"side":"BUY"}
{"ts":"2026-08-24T20:48:20.132Z","event_type":"price_change","market_id":"3825070","outcome_index":1,"market_type":"set2","local_side":"away","local_uid":"2026-08-24_polina_kudermetova_linda_fruhvirtova","bid":0.39,"ask":0.48,"mid":0.435,"spread":0.09,"price":0.48,"size":150.0,"side":"SELL"}
{"ts":"2026-08-24T20:48:20.227Z","event_type":"best_bid_ask","market_id":"3825038","outcome_index":0,"market_type":"set1","local_side":"home","local_uid":"2026-08-24_greet_minnen_jeline_vandromme","bid":0.001,"ask":0.054,"mid":0.0275,"spread":0.053,"bid_size":null,"ask_size":null}
{"ts":"2026-08-24T20:48:20.227Z","event_type":"best_bid_ask","market_id":"3825038","outcome_index":1,"market_type":"set1","local_side":"away","local_uid":"2026-08-24_greet_minnen_jeline_vandromme","bid":0.946,"ask":0.999,"mid":0.9725,"spread":0.053,"bid_size":null,"ask_size":null}
{"ts":"2026-08-24T20:48:20.227Z","event_type":"price_change","market_id":"3825038","outcome_index":1,"market_type":"set1","local_side":"away","local_uid":"2026-08-24_greet_minnen_jeline_vandromme","bid":0.946,"ask":0.999,"mid":0.9725,"spread":0.053,"price":0.946,"size":17.5,"side":"BUY"}
{"ts":"2026-08-24T20:48:20.228Z","event_type":"price_change","market_id":"3825038","outcome_index":0,"market_type":"set1","local_side":"home","local_uid":"2026-08-24_greet_minnen_jeline_vandromme","bid":0.001,"ask":0.054,"mid":0.0275,"spread":0.053,"price":0.054,"size":17.5,"side":"SELL"}
{"ts":"2026-08-24T20:48:20.247Z","event_type":"best_bid_ask","market_id":"3825038","outcome_index":0,"market_type":"set1","local_side":"home","local_uid":"2026-08-24_greet_minnen_jeline_vandromme","bid":0.001,"ask":0.059,"mid":0.03,"spread":0.058,"bid_size":null,"ask_size":null}
{"ts":"2026-08-24T20:48:20.248Z","event_type":"best_bid_ask","market_id":"3825038","outcome_index":1,"market_type":"set1","local_side":"away","local_uid":"2026-08-24_greet_minnen_jeline_vandromme","bid":0.941,"ask":0.999,"mid":0.97,"spread":0.058,"bid_size":null,"ask_size":null}
{"ts":"2026-08-24T20:48:20.248Z","event_type":"price_change","market_id":"3825038","outcome_index":1,"market_type":"set1","local_side":"away","local_uid":"2026-08-24_greet_minnen_jeline_vandromme","bid":0.941,"ask":0.999,"mid":0.97,"spread":0.058,"price":0.946,"size":0.0,"side":"BUY"}
{"ts":"2026-08-24T20:48:20.248Z","event_type":"price_change","market_id":"3825038","outcome_index":0,"market_type":"set1","local_side":"home","local_uid":"2026-08-24_greet_minnen_jeline_vandromme","bid":0.001,"ask":0.059,"mid":0.03,"spread":0.058,"price":0.054,"size":0.0,"side":"SELL"}
{"ts":"2026-08-24T20:48:20.329Z","event_type":"best_bid_ask","market_id":"3825038","outcome_index":0,"market_type":"set1","local_side":"home","local_uid":"2026-08-24_greet_minnen_jeline_vandromme","bid":0.001,"ask":0.054,"mid":0.0275,"spread":0.053,"bid_size":null,"ask_size":null}
{"ts":"2026-08-24T20:48:20.329Z","event_type":"best_bid_ask","market_id":"3825038","outcome_index":1,"market_type":"set1","local_side":"away","local_uid":"2026-08-24_greet_minnen_jeline_vandromme","bid":0.946,"ask":0.999,"mid":0.9725,"spread":0.053,"bid_size":null,"ask_size":null}
{"ts":"2026-08-24T20:48:20.329Z","event_type":"price_change","market_id":"3825038","outcome_index":1,"market_type":"set1","local_side":"away","local_uid":"2026-08-24_greet_minnen_jeline_vandromme","bid":0.946,"ask":0.999,"mid":0.9725,"spread":0.053,"price":0.946,"size":16.92,"side":"BUY"}
{"ts":"2026-08-24T20:48:20.330Z","event_type":"price_change","market_id":"3825038","outcome_index":0,"market_type":"set1","local_side":"home","local_uid":"2026-08-24_greet_minnen_jeline_vandromme","bid":0.001,"ask":0.054,"mid":0.0275,"spread":0.053,"price":0.054,"size":16.92,"side":"SELL"}
{"ts":"2026-08-24T20:48:20.331Z","event_type":"best_bid_ask","market_id":"3825608","outcome_index":0,"market_type":"match","local_side":"home","local_uid":"2026-08-24_raul_brancaccio_thiago_seyboth_wild","bid":0.23,"ask":0.25,"mid":0.24,"spread":0.02,"bid_size":null,"ask_size":null}
{"ts":"2026-08-24T20:48:20.331Z","event_type":"best_bid_ask","market_id":"3825608","outcome_index":1,"market_type":"match","local_side":"away","local_uid":"2026-08-24_raul_brancaccio_thiago_seyboth_wild","bid":0.75,"ask":0.77,"mid":0.76,"spread":0.02,"bid_size":null,"ask_size":null}
{"ts":"2026-08-24T20:48:20.331Z","event_type":"price_change","market_id":"3825608","outcome_index":0,"market_type":"match","local_side":"home","local_uid":"2026-08-24_raul_brancaccio_thiago_seyboth_wild","bid":0.23,"ask":0.25,"mid":0.24,"spread":0.02,"price":0.23,"size":10.0,"side":"BUY"}
{"ts":"2026-08-24T20:48:20.331Z","event_type":"price_change","market_id":"3825608","outcome_index":1,"market_type":"match","local_side":"away","local_uid":"2026-08-24_raul_brancaccio_thiago_seyboth_wild","bid":0.75,"ask":0.77,"mid":0.76,"spread":0.02,"price":0.77,"size":10.0,"side":"SELL"}
{"ts":"2026-08-24T20:48:20.369Z","event_type":"best_bid_ask","market_id":"3823623","outcome_index":0,"market_type":"match","local_side":"home","local_uid":"2026-08-24_robin_montgomery_kayla_cross","bid":0.89,"ask":0.9,"mid":0.895,"spread":0.01,"bid_size":null,"ask_size":null}
{"ts":"2026-08-24T20:48:20.370Z","event_type":"best_bid_ask","market_id":"3823623","outcome_index":1,"market_type":"match","local_side":"away","local_uid":"2026-08-24_robin_montgomery_kayla_cross","bid":0.1,"ask":0.11,"mid":0.105,"spread":0.01,"bid_size":null,"ask_size":null}
{"ts":"2026-08-24T20:48:20.370Z","event_type":"price_change","market_id":"3823623","outcome_index":0,"market_type":"match","local_side":"home","local_uid":"2026-08-24_robin_montgomery_kayla_cross","bid":0.89,"ask":0.9,"mid":0.895,"spread":0.01,"price":0.89,"size":14025.27,"side":"BUY"}
{"ts":"2026-08-24T20:48:20.370Z","event_type":"price_change","market_id":"3823623","outcome_index":1,"market_type":"match","local_side":"away","local_uid":"2026-08-24_robin_montgomery_kayla_cross","bid":0.1,"ask":0.11,"mid":0.105,"spread":0.01,"price":0.11,"size":14025.27,"side":"SELL"}
{"ts":"2026-08-24T20:48:20.464Z","event_type":"best_bid_ask","market_id":"3826654","outcome_index":0,"market_type":"set2","local_side":"home","local_uid":"2026-08-24_sebastian_gorzny_cruz_hewitt","bid":0.04,"ask":0.13,"mid":0.085,"spread":0.09,"bid_size":null,"ask_size":null}
{"ts":"2026-08-24T20:48:20.464Z","event_type":"best_bid_ask","market_id":"3826654","outcome_index":1,"market_type":"set2","local_side":"away","local_uid":"2026-08-24_sebastian_gorzny_cruz_hewitt","bid":0.87,"ask":0.96,"mid":0.915,"spread":0.09,"bid_size":null,"ask_size":null}
{"ts":"2026-08-24T20:48:20.465Z","event_type":"price_change","market_id":"3826654","outcome_index":0,"market_type":"set2","local_side":"home","local_uid":"2026-08-24_sebastian_gorzny_cruz_hewitt","bid":0.04,"ask":0.13,"mid":0.085,"spread":0.09,"price":0.06,"size":0.0,"side":"BUY"}
{"ts":"2026-08-24T20:48:20.465Z","event_type":"price_change","market_id":"3826654","outcome_index":1,"market_type":"set2","local_side":"away","local_uid":"2026-08-24_sebastian_gorzny_cruz_hewitt","bid":0.87,"ask":0.96,"mid":0.915,"spread":0.09,"price":0.94,"size":0.0,"side":"SELL"}
{"ts":"2026-08-24T20:48:20.505Z","event_type":"best_bid_ask","market_id":"3823623","outcome_index":0,"market_type":"match","local_side":"home","local_uid":"2026-08-24_robin_montgomery_kayla_cross","bid":0.89,"ask":0.91,"mid":0.9,"spread":0.02,"bid_size":null,"ask_size":null}
{"ts":"2026-08-24T20:48:20.506Z","event_type":"best_bid_ask","market_id":"3823623","outcome_index":1,"market_type":"match","local_side":"away","local_uid":"2026-08-24_robin_montgomery_kayla_cross","bid":0.09,"ask":0.11,"mid":0.1,"spread":0.02,"bid_size":null,"ask_size":null}
{"ts":"2026-08-24T20:48:20.506Z","event_type":"price_change","market_id":"3823623","outcome_index":1,"market_type":"match","local_side":"away","local_uid":"2026-08-24_robin_montgomery_kayla_cross","bid":0.09,"ask":0.11,"mid":0.1,"spread":0.02,"price":0.1,"size":0.0,"side":"BUY"}
{"ts":"2026-08-24T20:48:20.506Z","event_type":"price_change","market_id":"3823623","outcome_index":0,"market_type":"match","local_side":"home","local_uid":"2026-08-24_robin_montgomery_kayla_cross","bid":0.89,"ask":0.91,"mid":0.9,"spread":0.02,"price":0.9,"size":0.0,"side":"SELL"}
{"ts":"2026-08-24T20:48:20.600Z","event_type":"best_bid_ask","market_id":"3825053","outcome_index":0,"market_type":"set1","local_side":"home","local_uid":"2026-08-24_robin_montgomery_kayla_cross","bid":0.89,"ask":0.95,"mid":0.92,"spread":0.06,"bid_size":null,"ask_size":null}
{"ts":"2026-08-24T20:48:20.600Z","event_type":"best_bid_ask","market_id":"3825053","outcome_index":1,"market_type":"set1","local_side":"away","local_uid":"2026-08-24_robin_montgomery_kayla_cross","bid":0.05,"ask":0.11,"mid":0.08,"spread":0.06,"bid_size":null,"ask_size":null}
{"ts":"2026-08-24T20:48:20.601Z","event_type":"price_change","market_id":"3825053","outcome_index":0,"market_type":"set1","local_side":"home","local_uid":"2026-08-24_robin_montgomery_kayla_cross","bid":0.89,"ask":0.95,"mid":0.92,"spread":0.06,"price":0.89,"size":423.0,"side":"BUY"}
{"ts":"2026-08-24T20:48:20.601Z","event_type":"price_change","market_id":"3825053","outcome_index":1,"market_type":"set1","local_side":"away","local_uid":"2026-08-24_robin_montgomery_kayla_cross","bid":0.05,"ask":0.11,"mid":0.08,"spread":0.06,"price":0.11,"size":423.0,"side":"SELL"}
{"ts":"2026-08-24T20:48:20.610Z","event_type":"best_bid_ask","market_id":"3825053","outcome_index":0,"market_type":"set1","local_side":"home","local_uid":"2026-08-24_robin_montgomery_kayla_cross","bid":0.9,"ask":0.95,"mid":0.925,"spread":0.05,"bid_size":null,"ask_size":null}
{"ts":"2026-08-24T20:48:20.611Z","event_type":"best_bid_ask","market_id":"3825053","outcome_index":1,"market_type":"set1","local_side":"away","local_uid":"2026-08-24_robin_montgomery_kayla_cross","bid":0.05,"ask":0.1,"mid":0.075,"spread":0.05,"bid_size":null,"ask_size":null}
{"ts":"2026-08-24T20:48:20.617Z","event_type":"price_change","market_id":"3825053","outcome_index":0,"market_type":"set1","local_side":"home","local_uid":"2026-08-24_robin_montgomery_kayla_cross","bid":0.9,"ask":0.95,"mid":0.925,"spread":0.05,"price":0.9,"size":88.0,"side":"BUY"}
{"ts":"2026-08-24T20:48:20.617Z","event_type":"price_change","market_id":"3825053","outcome_index":1,"market_type":"set1","local_side":"away","local_uid":"2026-08-24_robin_montgomery_kayla_cross","bid":0.05,"ask":0.1,"mid":0.075,"spread":0.05,"price":0.1,"size":88.0,"side":"SELL"}
{"ts":"2026-08-24T20:48:20.618Z","event_type":"best_bid_ask","market_id":"3825051","outcome_index":0,"market_type":"set2","local_side":"home","local_uid":"2026-08-24_robin_montgomery_kayla_cross","bid":0.7,"ask":0.78,"mid":0.74,"spread":0.08,"bid_size":null,"ask_size":null}
{"ts":"2026-08-24T20:48:20.618Z","event_type":"best_bid_ask","market_id":"3825051","outcome_index":1,"market_type":"set2","local_side":"away","local_uid":"2026-08-24_robin_montgomery_kayla_cross","bid":0.22,"ask":0.3,"mid":0.26,"spread":0.08,"bid_size":null,"ask_size":null}
{"ts":"2026-08-24T20:48:20.619Z","event_type":"price_change","market_id":"3825051","outcome_index":0,"market_type":"set2","local_side":"home","local_uid":"2026-08-24_robin_montgomery_kayla_cross","bid":0.7,"ask":0.78,"mid":0.74,"spread":0.08,"price":0.7,"size":166.0,"side":"BUY"}
{"ts":"2026-08-24T20:48:20.619Z","event_type":"price_change","market_id":"3825051","outcome_index":1,"market_type":"set2","local_side":"away","local_uid":"2026-08-24_robin_montgomery_kayla_cross","bid":0.22,"ask":0.3,"mid":0.26,"spread":0.08,"price":0.3,"size":166.0,"side":"SELL"}
{"ts":"2026-08-24T20:48:20.655Z","event_type":"best_bid_ask","market_id":"3825053","outcome_index":0,"market_type":"set1","local_side":"home","local_uid":"2026-08-24_robin_montgomery_kayla_cross","bid":0.9,"ask":0.96,"mid":0.93,"spread":0.06,"bid_size":null,"ask_size":null}
{"ts":"2026-08-24T20:48:20.656Z","event_type":"best_bid_ask","market_id":"3825053","outcome_index":1,"market_type":"set1","local_side":"away","local_uid":"2026-08-24_robin_montgomery_kayla_cross","bid":0.04,"ask":0.1,"mid":0.07,"spread":0.06,"bid_size":null,"ask_size":null}
{"ts":"2026-08-24T20:48:20.656Z","event_type":"price_change","market_id":"3825053","outcome_index":1,"market_type":"set1","local_side":"away","local_uid":"2026-08-24_robin_montgomery_kayla_cross","bid":0.04,"ask":0.1,"mid":0.07,"spread":0.06,"price":0.05,"size":0.0,"side":"BUY"}
{"ts":"2026-08-24T20:48:20.656Z","event_type":"price_change","market_id":"3825053","outcome_index":0,"market_type":"set1","local_side":"home","local_uid":"2026-08-24_robin_montgomery_kayla_cross","bid":0.9,"ask":0.96,"mid":0.93,"spread":0.06,"price":0.95,"size":0.0,"side":"SELL"}
{"ts":"2026-08-24T20:48:20.657Z","event_type":"best_bid_ask","market_id":"3825053","outcome_index":0,"market_type":"set1","local_side":"home","local_uid":"2026-08-24_robin_montgomery_kayla_cross","bid":0.91,"ask":0.96,"mid":0.935,"spread":0.05,"bid_size":null,"ask_size":null}
{"ts":"2026-08-24T20:48:20.657Z","event_type":"best_bid_ask","market_id":"3825053","outcome_index":1,"market_type":"set1","local_side":"away","local_uid":"2026-08-24_robin_montgomery_kayla_cross","bid":0.04,"ask":0.09,"mid":0.065,"spread":0.05,"bid_size":null,"ask_size":null}
{"ts":"2026-08-24T20:48:20.657Z","event_type":"price_change","market_id":"3825053","outcome_index":0,"market_type":"set1","local_side":"home","local_uid":"2026-08-24_robin_montgomery_kayla_cross","bid":0.91,"ask":0.96,"mid":0.935,"spread":0.05,"price":0.91,"size":96.64,"side":"BUY"}
{"ts":"2026-08-24T20:48:20.657Z","event_type":"price_change","market_id":"3825053","outcome_index":1,"market_type":"set1","local_side":"away","local_uid":"2026-08-24_robin_montgomery_kayla_cross","bid":0.04,"ask":0.09,"mid":0.065,"spread":0.05,"price":0.09,"size":96.64,"side":"SELL"}
{"ts":"2026-08-24T20:48:20.690Z","event_type":"best_bid_ask","market_id":"3825040","outcome_index":0,"market_type":"set2","local_side":"home","local_uid":"2026-08-24_greet_minnen_jeline_vandromme","bid":0.27,"ask":0.4,"mid":0.335,"spread":0.13,"bid_size":null,"ask_size":null}
{"ts":"2026-08-24T20:48:20.697Z","event_type":"best_bid_ask","market_id":"3825040","outcome_index":1,"market_type":"set2","local_side":"away","local_uid":"2026-08-24_greet_minnen_jeline_vandromme","bid":0.6,"ask":0.73,"mid":0.665,"spread":0.13,"bid_size":null,"ask_size":null}
{"ts":"2026-08-24T20:48:20.698Z","event_type":"price_change","market_id":"3825040","outcome_index":0,"market_type":"set2","local_side":"home","local_uid":"2026-08-24_greet_minnen_jeline_vandromme","bid":0.27,"ask":0.4,"mid":0.335,"spread":0.13,"price":0.29,"size":0.0,"side":"BUY"}
{"ts":"2026-08-24T20:48:20.698Z","event_type":"price_change","market_id":"3825040","outcome_index":1,"market_type":"set2","local_side":"away","local_uid":"2026-08-24_greet_minnen_jeline_vandromme","bid":0.6,"ask":0.73,"mid":0.665,"spread":0.13,"price":0.71,"size":0.0,"side":"SELL"}
{"ts":"2026-08-24T20:48:20.847Z","event_type":"best_bid_ask","market_id":"3826654","outcome_index":0,"market_type":"set2","local_side":"home","local_uid":"2026-08-24_sebastian_gorzny_cruz_hewitt","bid":0.05,"ask":0.13,"mid":0.09,"spread":0.08,"bid_size":null,"ask_size":null}
{"ts":"2026-08-24T20:48:20.859Z","event_type":"best_bid_ask","market_id":"3826654","outcome_index":1,"market_type":"set2","local_side":"away","local_uid":"2026-08-24_sebastian_gorzny_cruz_hewitt","bid":0.87,"ask":0.95,"mid":0.91,"spread":0.08,"bid_size":null,"ask_size":null}
{"ts":"2026-08-24T20:48:20.860Z","event_type":"price_change","market_id":"3826654","outcome_index":0,"market_type":"set2","local_side":"home","local_uid":"2026-08-24_sebastian_gorzny_cruz_hewitt","bid":0.05,"ask":0.13,"mid":0.09,"spread":0.08,"price":0.05,"size":13.0,"side":"BUY"}
{"ts":"2026-08-24T20:48:20.860Z","event_type":"price_change","market_id":"3826654","outcome_index":1,"market_type":"set2","local_side":"away","local_uid":"2026-08-24_sebastian_gorzny_cruz_hewitt","bid":0.87,"ask":0.95,"mid":0.91,"spread":0.08,"price":0.95,"size":13.0,"side":"SELL"}
{"ts":"2026-08-24T20:48:20.871Z","event_type":"best_bid_ask","market_id":"3826654","outcome_index":0,"market_type":"set2","local_side":"home","local_uid":"2026-08-24_sebastian_gorzny_cruz_hewitt","bid":0.06,"ask":0.13,"mid":0.095,"spread":0.07,"bid_size":null,"ask_size":null}
{"ts":"2026-08-24T20:48:20.871Z","event_type":"best_bid_ask","market_id":"3826654","outcome_index":1,"market_type":"set2","local_side":"away","local_uid":"2026-08-24_sebastian_gorzny_cruz_hewitt","bid":0.87,"ask":0.94,"mid":0.905,"spread":0.07,"bid_size":null,"ask_size":null}
{"ts":"2026-08-24T20:48:20.872Z","event_type":"price_change","market_id":"3826654","outcome_index":0,"market_type":"set2","local_side":"home","local_uid":"2026-08-24_sebastian_gorzny_cruz_hewitt","bid":0.06,"ask":0.13,"mid":0.095,"spread":0.07,"price":0.06,"size":22.0,"side":"BUY"}
{"ts":"2026-08-24T20:48:20.872Z","event_type":"price_change","market_id":"3826654","outcome_index":1,"market_type":"set2","local_side":"away","local_uid":"2026-08-24_sebastian_gorzny_cruz_hewitt","bid":0.87,"ask":0.94,"mid":0.905,"spread":0.07,"price":0.94,"size":22.0,"side":"SELL"}
{"ts":"2026-08-24T20:48:20.908Z","event_type":"best_bid_ask","market_id":"3823625","outcome_index":0,"market_type":"match","local_side":"home","local_uid":"2026-08-24_greet_minnen_jeline_vandromme","bid":0.15,"ask":0.19,"mid":0.17,"spread":0.04,"bid_size":null,"ask_size":null}
{"ts":"2026-08-24T20:48:20.909Z","event_type":"best_bid_ask","market_id":"3823625","outcome_index":1,"market_type":"match","local_side":"away","local_uid":"2026-08-24_greet_minnen_jeline_vandromme","bid":0.81,"ask":0.85,"mid":0.83,"spread":0.04,"bid_size":null,"ask_size":null}
{"ts":"2026-08-24T20:48:20.909Z","event_type":"price_change","market_id":"3823625","outcome_index":1,"market_type":"match","local_side":"away","local_uid":"2026-08-24_greet_minnen_jeline_vandromme","bid":0.81,"ask":0.85,"mid":0.83,"spread":0.04,"price":0.82,"size":0.0,"side":"BUY"}
{"ts":"2026-08-24T20:48:20.909Z","event_type":"price_change","market_id":"3823625","outcome_index":0,"market_type":"match","local_side":"home","local_uid":"2026-08-24_greet_minnen_jeline_vandromme","bid":0.15,"ask":0.19,"mid":0.17,"spread":0.04,"price":0.18,"size":0.0,"side":"SELL"}
{"ts":"2026-08-24T20:48:20.928Z","event_type":"best_bid_ask","market_id":"3825053","outcome_index":0,"market_type":"set1","local_side":"home","local_uid":"2026-08-24_robin_montgomery_kayla_cross","bid":0.91,"ask":0.97,"mid":0.94,"spread":0.06,"bid_size":null,"ask_size":null}
{"ts":"2026-08-24T20:48:20.929Z","event_type":"best_bid_ask","market_id":"3825053","outcome_index":1,"market_type":"set1","local_side":"away","local_uid":"2026-08-24_robin_montgomery_kayla_cross","bid":0.03,"ask":0.09,"mid":0.06,"spread":0.06,"bid_size":null,"ask_size":null}
{"ts":"2026-08-24T20:48:20.929Z","event_type":"price_change","market_id":"3825053","outcome_index":0,"market_type":"set1","local_side":"home","local_uid":"2026-08-24_robin_montgomery_kayla_cross","bid":0.91,"ask":0.97,"mid":0.94,"spread":0.06,"price":0.84,"size":0.0,"side":"BUY"}
{"ts":"2026-08-24T20:48:20.929Z","event_type":"price_change","market_id":"3825053","outcome_index":1,"market_type":"set1","local_side":"away","local_uid":"2026-08-24_robin_montgomery_kayla_cross","bid":0.03,"ask":0.09,"mid":0.06,"spread":0.06,"price":0.16,"size":0.0,"side":"SELL"}
{"ts":"2026-08-24T20:48:20.947Z","event_type":"best_bid_ask","market_id":"3825053","outcome_index":0,"market_type":"set1","local_side":"home","local_uid":"2026-08-24_robin_montgomery_kayla_cross","bid":0.92,"ask":0.97,"mid":0.945,"spread":0.05,"bid_size":null,"ask_size":null}
{"ts":"2026-08-24T20:48:20.959Z","event_type":"best_bid_ask","market_id":"3825053","outcome_index":1,"market_type":"set1","local_side":"away","local_uid":"2026-08-24_robin_montgomery_kayla_cross","bid":0.03,"ask":0.08,"mid":0.055,"spread":0.05,"bid_size":null,"ask_size":null}
{"ts":"2026-08-24T20:48:20.960Z","event_type":"price_change","market_id":"3825053","outcome_index":0,"market_type":"set1","local_side":"home","local_uid":"2026-08-24_robin_montgomery_kayla_cross","bid":0.92,"ask":0.97,"mid":0.945,"spread":0.05,"price":0.92,"size":48.71,"side":"BUY"}
{"ts":"2026-08-24T20:48:20.960Z","event_type":"price_change","market_id":"3825053","outcome_index":1,"market_type":"set1","local_side":"away","local_uid":"2026-08-24_robin_montgomery_kayla_cross","bid":0.03,"ask":0.08,"mid":0.055,"spread":0.05,"price":0.08,"size":48.71,"side":"SELL"}
{"ts":"2026-08-24T20:48:21.004Z","event_type":"best_bid_ask","market_id":"3825053","outcome_index":0,"market_type":"set1","local_side":"home","local_uid":"2026-08-24_robin_montgomery_kayla_cross","bid":0.92,"ask":0.96,"mid":0.94,"spread":0.04,"bid_size":null,"ask_size":null}
{"ts":"2026-08-24T20:48:21.004Z","event_type":"best_bid_ask","market_id":"3825053","outcome_index":1,"market_type":"set1","local_side":"away","local_uid":"2026-08-24_robin_montgomery_kayla_cross","bid":0.04,"ask":0.08,"mid":0.06,"spread":0.04,"bid_size":null,"ask_size":null}
{"ts":"2026-08-24T20:48:21.004Z","event_type":"price_change","market_id":"3825053","outcome_index":1,"market_type":"set1","local_side":"away","local_uid":"2026-08-24_robin_montgomery_kayla_cross","bid":0.04,"ask":0.08,"mid":0.06,"spread":0.04,"price":0.04,"size":250.0,"side":"BUY"}
{"ts":"2026-08-24T20:48:21.005Z","event_type":"price_change","market_id":"3825053","outcome_index":0,"market_type":"set1","local_side":"home","local_uid":"2026-08-24_robin_montgomery_kayla_cross","bid":0.92,"ask":0.96,"mid":0.94,"spread":0.04,"price":0.96,"size":250.0,"side":"SELL"}
{"ts":"2026-08-24T20:48:21.009Z","event_type":"best_bid_ask","market_id":"3823623","outcome_index":0,"market_type":"match","local_side":"home","local_uid":"2026-08-24_robin_montgomery_kayla_cross","bid":0.89,"ask":0.9,"mid":0.895,"spread":0.01,"bid_size":null,"ask_size":null}
{"ts":"2026-08-24T20:48:21.009Z","event_type":"best_bid_ask","market_id":"3823623","outcome_index":1,"market_type":"match","local_side":"away","local_uid":"2026-08-24_robin_montgomery_kayla_cross","bid":0.1,"ask":0.11,"mid":0.105,"spread":0.01,"bid_size":null,"ask_size":null}
{"ts":"2026-08-24T20:48:21.009Z","event_type":"price_change","market_id":"3823623","outcome_index":1,"market_type":"match","local_side":"away","local_uid":"2026-08-24_robin_montgomery_kayla_cross","bid":0.1,"ask":0.11,"mid":0.105,"spread":0.01,"price":0.1,"size":2020.0,"side":"BUY"}
{"ts":"2026-08-24T20:48:21.010Z","event_type":"price_change","market_id":"3823623","outcome_index":0,"market_type":"match","local_side":"home","local_uid":"2026-08-24_robin_montgomery_kayla_cross","bid":0.89,"ask":0.9,"mid":0.895,"spread":0.01,"price":0.9,"size":2020.0,"side":"SELL"}
{"ts":"2026-08-24T20:48:21.042Z","event_type":"best_bid_ask","market_id":"3823619","outcome_index":0,"market_type":"match","local_side":"home","local_uid":"2026-08-24_polina_kudermetova_linda_fruhvirtova","bid":0.55,"ask":0.57,"mid":0.56,"spread":0.02,"bid_size":null,"ask_size":null}
{"ts":"2026-08-24T20:48:21.043Z","event_type":"best_bid_ask","market_id":"3823619","outcome_index":1,"market_type":"match","local_side":"away","local_uid":"2026-08-24_polina_kudermetova_linda_fruhvirtova","bid":0.43,"ask":0.45,"mid":0.44,"spread":0.02,"bid_size":null,"ask_size":null}
{"ts":"2026-08-24T20:48:21.043Z","event_type":"price_change","market_id":"3823619","outcome_index":1,"market_type":"match","local_side":"away","local_uid":"2026-08-24_polina_kudermetova_linda_fruhvirtova","bid":0.43,"ask":0.45,"mid":0.44,"spread":0.02,"price":0.44,"size":0.0,"side":"BUY"}
{"ts":"2026-08-24T20:48:21.043Z","event_type":"price_change","market_id":"3823619","outcome_index":0,"market_type":"match","local_side":"home","local_uid":"2026-08-24_polina_kudermetova_linda_fruhvirtova","bid":0.55,"ask":0.57,"mid":0.56,"spread":0.02,"price":0.56,"size":0.0,"side":"SELL"}
{"ts":"2026-08-24T20:48:21.065Z","event_type":"best_bid_ask","market_id":"3825053","outcome_index":0,"market_type":"set1","local_side":"home","local_uid":"2026-08-24_robin_montgomery_kayla_cross","bid":0.92,"ask":0.95,"mid":0.935,"spread":0.03,"bid_size":null,"ask_size":null}
{"ts":"2026-08-24T20:48:21.066Z","event_type":"best_bid_ask","market_id":"3825053","outcome_index":1,"market_type":"set1","local_side":"away","local_uid":"2026-08-24_robin_montgomery_kayla_cross","bid":0.05,"ask":0.08,"mid":0.065,"spread":0.03,"bid_size":null,"ask_size":null}
{"ts":"2026-08-24T20:48:21.067Z","event_type":"price_change","market_id":"3825053","outcome_index":1,"market_type":"set1","local_side":"away","local_uid":"2026-08-24_robin_montgomery_kayla_cross","bid":0.05,"ask":0.08,"mid":0.065,"spread":0.03,"price":0.05,"size":200.0,"side":"BUY"}
{"ts":"2026-08-24T20:48:21.067Z","event_type":"price_change","market_id":"3825053","outcome_index":0,"market_type":"set1","local_side":"home","local_uid":"2026-08-24_robin_montgomery_kayla_cross","bid":0.92,"ask":0.95,"mid":0.935,"spread":0.03,"price":0.95,"size":200.0,"side":"SELL"}
{"ts":"2026-08-24T20:48:21.067Z","event_type":"best_bid_ask","market_id":"3825051","outcome_index":0,"market_type":"set2","local_side":"home","local_uid":"2026-08-24_robin_montgomery_kayla_cross","bid":0.71,"ask":0.78,"mid":0.745,"spread":0.07,"bid_size":null,"ask_size":null}
{"ts":"2026-08-24T20:48:21.068Z","event_type":"best_bid_ask","market_id":"3825051","outcome_index":1,"market_type":"set2","local_side":"away","local_uid":"2026-08-24_robin_montgomery_kayla_cross","bid":0.22,"ask":0.29,"mid":0.255,"spread":0.07,"bid_size":null,"ask_size":null}
{"ts":"2026-08-24T20:48:21.068Z","event_type":"price_change","market_id":"3825051","outcome_index":0,"market_type":"set2","local_side":"home","local_uid":"2026-08-24_robin_montgomery_kayla_cross","bid":0.71,"ask":0.78,"mid":0.745,"spread":0.07,"price":0.71,"size":50.0,"side":"BUY"}
{"ts":"2026-08-24T20:48:21.068Z","event_type":"price_change","market_id":"3825051","outcome_index":1,"market_type":"set2","local_side":"away","local_uid":"2026-08-24_robin_montgomery_kayla_cross","bid":0.22,"ask":0.29,"mid":0.255,"spread":0.07,"price":0.29,"size":50.0,"side":"SELL"}
{"ts":"2026-08-24T20:48:21.171Z","event_type":"best_bid_ask","market_id":"3823619","outcome_index":0,"market_type":"match","local_side":"home","local_uid":"2026-08-24_polina_kudermetova_linda_fruhvirtova","bid":0.56,"ask":0.57,"mid":0.565,"spread":0.01,"bid_size":null,"ask_size":null}
{"ts":"2026-08-24T20:48:21.172Z","event_type":"best_bid_ask","market_id":"3823619","outcome_index":1,"market_type":"match","local_side":"away","local_uid":"2026-08-24_polina_kudermetova_linda_fruhvirtova","bid":0.43,"ask":0.44,"mid":0.435,"spread":0.01,"bid_size":null,"ask_size":null}
{"ts":"2026-08-24T20:48:21.172Z","event_type":"price_change","market_id":"3823619","outcome_index":0,"market_type":"match","local_side":"home","local_uid":"2026-08-24_polina_kudermetova_linda_fruhvirtova","bid":0.56,"ask":0.57,"mid":0.565,"spread":0.01,"price":0.56,"size":50.0,"side":"BUY"}
{"ts":"2026-08-24T20:48:21.172Z","event_type":"price_change","market_id":"3823619","outcome_index":1,"market_type":"match","local_side":"away","local_uid":"2026-08-24_polina_kudermetova_linda_fruhvirtova","bid":0.43,"ask":0.44,"mid":0.435,"spread":0.01,"price":0.44,"size":50.0,"side":"SELL"}
{"ts":"2026-08-24T20:48:21.178Z","event_type":"best_bid_ask","market_id":"3825038","outcome_index":0,"market_type":"set1","local_side":"home","local_uid":"2026-08-24_greet_minnen_jeline_vandromme","bid":0.001,"ask":0.059,"mid":0.03,"spread":0.058,"bid_size":null,"ask_size":null}
{"ts":"2026-08-24T20:48:21.179Z","event_type":"best_bid_ask","market_id":"3825038","outcome_index":1,"market_type":"set1","local_side":"away","local_uid":"2026-08-24_greet_minnen_jeline_vandromme","bid":0.941,"ask":0.999,"mid":0.97,"spread":0.058,"bid_size":null,"ask_size":null}
{"ts":"2026-08-24T20:48:21.179Z","event_type":"price_change","market_id":"3825038","outcome_index":1,"market_type":"set1","local_side":"away","local_uid":"2026-08-24_greet_minnen_jeline_vandromme","bid":0.941,"ask":0.999,"mid":0.97,"spread":0.058,"price":0.946,"size":0.0,"side":"BUY"}
{"ts":"2026-08-24T20:48:21.179Z","event_type":"price_change","market_id":"3825038","outcome_index":0,"market_type":"set1","local_side":"home","local_uid":"2026-08-24_greet_minnen_jeline_vandromme","bid":0.001,"ask":0.059,"mid":0.03,"spread":0.058,"price":0.054,"size":0.0,"side":"SELL"}
{"ts":"2026-08-24T20:48:21.308Z","event_type":"best_bid_ask","market_id":"3825038","outcome_index":0,"market_type":"set1","local_side":"home","local_uid":"2026-08-24_greet_minnen_jeline_vandromme","bid":0.001,"ask":0.05,"mid":0.0255,"spread":0.049,"bid_size":null,"ask_size":null}
{"ts":"2026-08-24T20:48:21.308Z","event_type":"best_bid_ask","market_id":"3825038","outcome_index":1,"market_type":"set1","local_side":"away","local_uid":"2026-08-24_greet_minnen_jeline_vandromme","bid":0.95,"ask":0.999,"mid":0.9745,"spread":0.049,"bid_size":null,"ask_size":null}
{"ts":"2026-08-24T20:48:21.308Z","event_type":"price_change","market_id":"3825038","outcome_index":1,"market_type":"set1","local_side":"away","local_uid":"2026-08-24_greet_minnen_jeline_vandromme","bid":0.95,"ask":0.999,"mid":0.9745,"spread":0.049,"price":0.95,"size":44.0,"side":"BUY"}
{"ts":"2026-08-24T20:48:21.309Z","event_type":"price_change","market_id":"3825038","outcome_index":0,"market_type":"set1","local_side":"home","local_uid":"2026-08-24_greet_minnen_jeline_vandromme","bid":0.001,"ask":0.05,"mid":0.0255,"spread":0.049,"price":0.05,"size":44.0,"side":"SELL"}
{"ts":"2026-08-24T20:48:21.315Z","event_type":"best_bid_ask","market_id":"3825038","outcome_index":0,"market_type":"set1","local_side":"home","local_uid":"2026-08-24_greet_minnen_jeline_vandromme","bid":0.001,"ask":0.059,"mid":0.03,"spread":0.058,"bid_size":null,"ask_size":null}
