{"ts":"2026-08-24T20:48:21.315Z","event_type":"best_bid_ask","market_id":"3825038","outcome_index":1,"market_type":"set1","local_side":"away","local_uid":"2026-08-24_greet_minnen_jeline_vandromme","bid":0.941,"ask":0.999,"mid":0.97,"spread":0.058,"bid_size":null,"ask_size":null}
{"ts":"2026-08-24T20:48:21.315Z","event_type":"price_change","market_id":"3825038","outcome_index":1,"market_type":"set1","local_side":"away","local_uid":"2026-08-24_greet_minnen_jeline_vandromme","bid":0.941,"ask":0.999,"mid":0.97,"spread":0.058,"price":0.95,"size":0.0,"side":"BUY"}
{"ts":"2026-08-24T20:48:21.315Z","event_type":"price_change","market_id":"3825038","outcome_index":0,"market_type":"set1","local_side":"home","local_uid":"2026-08-24_greet_minnen_jeline_vandromme","bid":0.001,"ask":0.059,"mid":0.03,"spread":0.058,"price":0.05,"size":0.0,"side":"SELL"}
{"ts":"2026-08-24T20:48:21.316Z","event_type":"best_bid_ask","market_id":"3825038","outcome_index":0,"market_type":"set1","local_side":"home","local_uid":"2026-08-24_greet_minnen_jeline_vandromme","bid":0.001,"ask":0.05,"mid":0.0255,"spread":0.049,"bid_size":null,"ask_size":null}
{"ts":"2026-08-24T20:48:21.316Z","event_type":"best_bid_ask","market_id":"3825038","outcome_index":1,"market_type":"set1","local_side":"away","local_uid":"2026-08-24_greet_minnen_jeline_vandromme","bid":0.95,"ask":0.999,"mid":0.9745,"spread":0.049,"bid_size":null,"ask_size":null}
{"ts":"2026-08-24T20:48:21.316Z","event_type":"price_change","market_id":"3825038","outcome_index":1,"market_type":"set1","local_side":"away","local_uid":"2026-08-24_greet_minnen_jeline_vandromme","bid":0.95,"ask":0.999,"mid":0.9745,"spread":0.049,"price":0.95,"size":22.0,"side":"BUY"}
{"ts":"2026-08-24T20:48:21.316Z","event_type":"price_change","market_id":"3825038","outcome_index":0,"market_type":"set1","local_side":"home","local_uid":"2026-08-24_greet_minnen_jeline_vandromme","bid":0.001,"ask":0.05,"mid":0.0255,"spread":0.049,"price":0.05,"size":22.0,"side":"SELL"}
{"ts":"2026-08-24T20:48:21.318Z","event_type":"best_bid_ask","market_id":"3825038","outcome_index":0,"market_type":"set1","local_side":"home","local_uid":"2026-08-24_greet_minnen_jeline_vandromme","bid":0.001,"ask":0.033,"mid":0.017,"spread":0.032,"bid_size":null,"ask_size":null}
{"ts":"2026-08-24T20:48:21.318Z","event_type":"best_bid_ask","market_id":"3825038","outcome_index":1,"market_type":"set1","local_side":"away","local_uid":"2026-08-24_greet_minnen_jeline_vandromme","bid":0.967,"ask":0.999,"mid":0.983,"spread":0.032,"bid_size":null,"ask_size":null}
{"ts":"2026-08-24T20:48:21.319Z","event_type":"price_change","market_id":"3825038","outcome_index":1,"market_type":"set1","local_side":"away","local_uid":"2026-08-24_greet_minnen_jeline_vandromme","bid":0.967,"ask":0.999,"mid":0.983,"spread":0.032,"price":0.967,"size":16.13,"side":"BUY"}
{"ts":"2026-08-24T20:48:21.319Z","event_type":"price_change","market_id":"3825038","outcome_index":0,"market_type":"set1","local_side":"home","local_uid":"2026-08-24_greet_minnen_jeline_vandromme","bid":0.001,"ask":0.033,"mid":0.017,"spread":0.032,"price":0.033,"size":16.13,"side":"SELL"}
{"ts":"2026-08-24T20:48:21.334Z","event_type":"best_bid_ask","market_id":"3825038","outcome_index":0,"market_type":"set1","local_side":"home","local_uid":"2026-08-24_greet_minnen_jeline_vandromme","bid":0.001,"ask":0.059,"mid":0.03,"spread":0.058,"bid_size":null,"ask_size":null}
{"ts":"2026-08-24T20:48:21.335Z","event_type":"best_bid_ask","market_id":"3825038","outcome_index":1,"market_type":"set1","local_side":"away","local_uid":"2026-08-24_greet_minnen_jeline_vandromme","bid":0.941,"ask":0.999,"mid":0.97,"spread":0.058,"bid_size":null,"ask_size":null}
{"ts":"2026-08-24T20:48:21.335Z","event_type":"price_change","market_id":"3825038","outcome_index":1,"market_type":"set1","local_side":"away","local_uid":"2026-08-24_greet_minnen_jeline_vandromme","bid":0.941,"ask":0.999,"mid":0.97,"spread":0.058,"price":0.967,"size":0.0,"side":"BUY"}
{"ts":"2026-08-24T20:48:21.335Z","event_type":"price_change","market_id":"3825038","outcome_index":0,"market_type":"set1","local_side":"home","local_uid":"2026-08-24_greet_minnen_jeline_vandromme","bid":0.001,"ask":0.059,"mid":0.03,"spread":0.058,"price":0.033,"size":0.0,"side":"SELL"}
{"ts":"2026-08-24T20:48:21.414Z","event_type":"best_bid_ask","market_id":"3825038","outcome_index":0,"market_type":"set1","local_side":"home","local_uid":"2026-08-24_greet_minnen_jeline_vandromme","bid":0.001,"ask":0.05,"mid":0.0255,"spread":0.049,"bid_size":null,"ask_size":null}
{"ts":"2026-08-24T20:48:21.414Z","event_type":"best_bid_ask","market_id":"3825038","outcome_index":1,"market_type":"set1","local_side":"away","local_uid":"2026-08-24_greet_minnen_jeline_vandromme","bid":0.95,"ask":0.999,"mid":0.9745,"spread":0.049,"bid_size":null,"ask_size":null}
{"ts":"2026-08-24T20:48:21.415Z","event_type":"price_change","market_id":"3825038","outcome_index":1,"market_type":"set1","local_side":"away","local_uid":"2026-08-24_greet_minnen_jeline_vandromme","bid":0.95,"ask":0.999,"mid":0.9745,"spread":0.049,"price":0.95,"size":22.0,"side":"BUY"}
{"ts":"2026-08-24T20:48:21.415Z","event_type":"price_change","market_id":"3825038","outcome_index":0,"market_type":"set1","local_side":"home","local_uid":"2026-08-24_greet_minnen_jeline_vandromme","bid":0.001,"ask":0.05,"mid":0.0255,"spread":0.049,"price":0.05,"size":22.0,"side":"SELL"}
{"ts":"2026-08-24T20:48:21.442Z","event_type":"best_bid_ask","market_id":"3826654","outcome_index":0,"market_type":"set2","local_side":"home","local_uid":"2026-08-24_sebastian_gorzny_cruz_hewitt","bid":0.04,"ask":0.13,"mid":0.085,"spread":0.09,"bid_size":null,"ask_size":null}
{"ts":"2026-08-24T20:48:21.442Z","event_type":"best_bid_ask","market_id":"3826654","outcome_index":1,"market_type":"set2","local_side":"away","local_uid":"2026-08-24_sebastian_gorzny_cruz_hewitt","bid":0.87,"ask":0.96,"mid":0.915,"spread":0.09,"bid_size":null,"ask_size":null}
{"ts":"2026-08-24T20:48:21.443Z","event_type":"price_change","market_id":"3826654","outcome_index":0,"market_type":"set2","local_side":"home","local_uid":"2026-08-24_sebastian_gorzny_cruz_hewitt","bid":0.04,"ask":0.13,"mid":0.085,"spread":0.09,"price":0.06,"size":0.0,"side":"BUY"}
{"ts":"2026-08-24T20:48:21.443Z","event_type":"price_change","market_id":"3826654","outcome_index":1,"market_type":"set2","local_side":"away","local_uid":"2026-08-24_sebastian_gorzny_cruz_hewitt","bid":0.87,"ask":0.96,"mid":0.915,"spread":0.09,"price":0.94,"size":0.0,"side":"SELL"}
{"ts":"2026-08-24T20:48:21.451Z","event_type":"best_bid_ask","market_id":"3825038","outcome_index":0,"market_type":"set1","local_side":"home","local_uid":"2026-08-24_greet_minnen_jeline_vandromme","bid":0.001,"ask":0.059,"mid":0.03,"spread":0.058,"bid_size":null,"ask_size":null}
{"ts":"2026-08-24T20:48:21.452Z","event_type":"best_bid_ask","market_id":"3825038","outcome_index":1,"market_type":"set1","local_side":"away","local_uid":"2026-08-24_greet_minnen_jeline_vandromme","bid":0.941,"ask":0.999,"mid":0.97,"spread":0.058,"bid_size":null,"ask_size":null}
{"ts":"2026-08-24T20:48:21.452Z","event_type":"price_change","market_id":"3825038","outcome_index":1,"market_type":"set1","local_side":"away","local_uid":"2026-08-24_greet_minnen_jeline_vandromme","bid":0.941,"ask":0.999,"mid":0.97,"spread":0.058,"price":0.95,"size":0.0,"side":"BUY"}
{"ts":"2026-08-24T20:48:21.452Z","event_type":"price_change","market_id":"3825038","outcome_index":0,"market_type":"set1","local_side":"home","local_uid":"2026-08-24_greet_minnen_jeline_vandromme","bid":0.001,"ask":0.059,"mid":0.03,"spread":0.058,"price":0.05,"size":0.0,"side":"SELL"}
{"ts":"2026-08-24T20:48:21.456Z","event_type":"best_bid_ask","market_id":"3825038","outcome_index":0,"market_type":"set1","local_side":"home","local_uid":"2026-08-24_greet_minnen_jeline_vandromme","bid":0.001,"ask":0.05,"mid":0.0255,"spread":0.049,"bid_size":null,"ask_size":null}
{"ts":"2026-08-24T20:48:21.456Z","event_type":"best_bid_ask","market_id":"3825038","outcome_index":1,"market_type":"set1","local_side":"away","local_uid":"2026-08-24_greet_minnen_jeline_vandromme","bid":0.95,"ask":0.999,"mid":0.9745,"spread":0.049,"bid_size":null,"ask_size":null}
{"ts":"2026-08-24T20:48:21.457Z","event_type":"price_change","market_id":"3825038","outcome_index":1,"market_type":"set1","local_side":"away","local_uid":"2026-08-24_greet_minnen_jeline_vandromme","bid":0.95,"ask":0.999,"mid":0.9745,"spread":0.049,"price":0.95,"size":50.0,"side":"BUY"}
{"ts":"2026-08-24T20:48:21.457Z","event_type":"price_change","market_id":"3825038","outcome_index":0,"market_type":"set1","local_side":"home","local_uid":"2026-08-24_greet_minnen_jeline_vandromme","bid":0.001,"ask":0.05,"mid":0.0255,"spread":0.049,"price":0.05,"size":50.0,"side":"SELL"}
{"ts":"2026-08-24T20:48:21.473Z","event_type":"book","market_id":"3825641","outcome_index":0,"market_type":"match","local_side":"home","local_uid":"2026-08-24_sebastian_gorzny_cruz_hewitt","bid":0.61,"ask":0.64,"mid":0.625,"spread":0.03,"bid_size":7.43,"ask_size":110.0}
{"ts":"2026-08-24T20:48:21.481Z","event_type":"book","market_id":"3825641","outcome_index":1,"market_type":"match","local_side":"away","local_uid":"2026-08-24_sebastian_gorzny_cruz_hewitt","bid":0.36,"ask":0.39,"mid":0.375,"spread":0.03,"bid_size":110.0,"ask_size":7.43}
{"ts":"2026-08-24T20:48:21.505Z","event_type":"best_bid_ask","market_id":"3825038","outcome_index":0,"market_type":"set1","local_side":"home","local_uid":"2026-08-24_greet_minnen_jeline_vandromme","bid":0.001,"ask":0.059,"mid":0.03,"spread":0.058,"bid_size":null,"ask_size":null}
{"ts":"2026-08-24T20:48:21.505Z","event_type":"best_bid_ask","market_id":"3825038","outcome_index":1,"market_type":"set1","local_side":"away","local_uid":"2026-08-24_greet_minnen_jeline_vandromme","bid":0.941,"ask":0.999,"mid":0.97,"spread":0.058,"bid_size":null,"ask_size":null}
{"ts":"2026-08-24T20:48:21.505Z","event_type":"price_change","market_id":"3825038","outcome_index":1,"market_type":"set1","local_side":"away","local_uid":"2026-08-24_greet_minnen_jeline_vandromme","bid":0.941,"ask":0.999,"mid":0.97,"spread":0.058,"price":0.95,"size":0.0,"side":"BUY"}
{"ts":"2026-08-24T20:48:21.505Z","event_type":"price_change","market_id":"3825038","outcome_index":0,"market_type":"set1","local_side":"home","local_uid":"2026-08-24_greet_minnen_jeline_vandromme","bid":0.001,"ask":0.059,"mid":0.03,"spread":0.058,"price":0.05,"size":0.0,"side":"SELL"}
{"ts":"2026-08-24T20:48:21.506Z","event_type":"best_bid_ask","market_id":"3825038","outcome_index":0,"market_type":"set1","local_side":"home","local_uid":"2026-08-24_greet_minnen_jeline_vandromme","bid":0.001,"ask":0.05,"mid":0.0255,"spread":0.049,"bid_size":null,"ask_size":null}
{"ts":"2026-08-24T20:48:21.506Z","event_type":"best_bid_ask","market_id":"3825038","outcome_index":1,"market_type":"set1","local_side":"away","local_uid":"2026-08-24_greet_minnen_jeline_vandromme","bid":0.95,"ask":0.999,"mid":0.9745,"spread":0.049,"bid_size":null,"ask_size":null}
{"ts":"2026-08-24T20:48:21.506Z","event_type":"price_change","market_id":"3825038","outcome_index":1,"market_type":"set1","local_side":"away","local_uid":"2026-08-24_greet_minnen_jeline_vandromme","bid":0.95,"ask":0.999,"mid":0.9745,"spread":0.049,"price":0.95,"size":22.0,"side":"BUY"}
{"ts":"2026-08-24T20:48:21.507Z","event_type":"price_change","market_id":"3825038","outcome_index":0,"market_type":"set1","local_side":"home","local_uid":"2026-08-24_greet_minnen_jeline_vandromme","bid":0.001,"ask":0.05,"mid":0.0255,"spread":0.049,"price":0.05,"size":22.0,"side":"SELL"}
{"ts":"2026-08-24T20:48:21.549Z","event_type":"best_bid_ask","market_id":"3825641","outcome_index":0,"market_type":"match","local_side":"home","local_uid":"2026-08-24_sebastian_gorzny_cruz_hewitt","bid":0.6,"ask":0.64,"mid":0.62,"spread":0.04,"bid_size":null,"ask_size":null}
{"ts":"2026-08-24T20:48:21.549Z","event_type":"best_bid_ask","market_id":"3825641","outcome_index":1,"market_type":"match","local_side":"away","local_uid":"2026-08-24_sebastian_gorzny_cruz_hewitt","bid":0.36,"ask":0.4,"mid":0.38,"spread":0.04,"bid_size":null,"ask_size":null}
{"ts":"2026-08-24T20:48:21.549Z","event_type":"price_change","market_id":"3825641","outcome_index":0,"market_type":"match","local_side":"home","local_uid":"2026-08-24_sebastian_gorzny_cruz_hewitt","bid":0.6,"ask":0.64,"mid":0.62,"spread":0.04,"price":0.61,"size":0.0,"side":"BUY"}
{"ts":"2026-08-24T20:48:21.550Z","event_type":"price_change","market_id":"3825641","outcome_index":1,"market_type":"match","local_side":"away","local_uid":"2026-08-24_sebastian_gorzny_cruz_hewitt","bid":0.36,"ask":0.4,"mid":0.38,"spread":0.04,"price":0.39,"size":0.0,"side":"SELL"}
{"ts":"2026-08-24T20:48:21.550Z","event_type":"book","market_id":"3825641","outcome_index":0,"market_type":"match","local_side":"home","local_uid":"2026-08-24_sebastian_gorzny_cruz_hewitt","bid":0.6,"ask":0.64,"mid":0.62,"spread":0.04,"bid_size":34.0,"ask_size":110.0}
{"ts":"2026-08-24T20:48:21.551Z","event_type":"book","market_id":"3825641","outcome_index":1,"market_type":"match","local_side":"away","local_uid":"2026-08-24_sebastian_gorzny_cruz_hewitt","bid":0.36,"ask":0.4,"mid":0.38,"spread":0.04,"bid_size":110.0,"ask_size":34.0}
{"ts":"2026-08-24T20:48:21.552Z","event_type":"last_trade_price","market_id":"3825641","outcome_index":1,"market_type":"match","local_side":"away","local_uid":"2026-08-24_sebastian_gorzny_cruz_hewitt","last_trade":0.39,"trade_size":2.5641,"trade_side":"BUY","trade_notional":1.0}
{"ts":"2026-08-24T20:48:21.553Z","event_type":"best_bid_ask","market_id":"3825038","outcome_index":0,"market_type":"set1","local_side":"home","local_uid":"2026-08-24_greet_minnen_jeline_vandromme","bid":0.001,"ask":0.059,"mid":0.03,"spread":0.058,"bid_size":null,"ask_size":null}
{"ts":"2026-08-24T20:48:21.553Z","event_type":"best_bid_ask","market_id":"3825038","outcome_index":1,"market_type":"set1","local_side":"away","local_uid":"2026-08-24_greet_minnen_jeline_vandromme","bid":0.941,"ask":0.999,"mid":0.97,"spread":0.058,"bid_size":null,"ask_size":null}
{"ts":"2026-08-24T20:48:21.553Z","event_type":"price_change","market_id":"3825038","outcome_index":1,"market_type":"set1","local_side":"away","local_uid":"2026-08-24_greet_minnen_jeline_vandromme","bid":0.941,"ask":0.999,"mid":0.97,"spread":0.058,"price":0.95,"size":0.0,"side":"BUY"}
{"ts":"2026-08-24T20:48:21.554Z","event_type":"price_change","market_id":"3825038","outcome_index":0,"market_type":"set1","local_side":"home","local_uid":"2026-08-24_greet_minnen_jeline_vandromme","bid":0.001,"ask":0.059,"mid":0.03,"spread":0.058,"price":0.05,"size":0.0,"side":"SELL"}
{"ts":"2026-08-24T20:48:21.574Z","event_type":"best_bid_ask","market_id":"3825038","outcome_index":0,"market_type":"set1","local_side":"home","local_uid":"2026-08-24_greet_minnen_jeline_vandromme","bid":0.001,"ask":0.09,"mid":0.0455,"spread":0.089,"bid_size":null,"ask_size":null}
{"ts":"2026-08-24T20:48:21.575Z","event_type":"best_bid_ask","market_id":"3825038","outcome_index":1,"market_type":"set1","local_side":"away","local_uid":"2026-08-24_greet_minnen_jeline_vandromme","bid":0.91,"ask":0.999,"mid":0.9545,"spread":0.089,"bid_size":null,"ask_size":null}
{"ts":"2026-08-24T20:48:21.575Z","event_type":"price_change","market_id":"3825038","outcome_index":1,"market_type":"set1","local_side":"away","local_uid":"2026-08-24_greet_minnen_jeline_vandromme","bid":0.91,"ask":0.999,"mid":0.9545,"spread":0.089,"price":0.941,"size":0.0,"side":"BUY"}
{"ts":"2026-08-24T20:48:21.575Z","event_type":"price_change","market_id":"3825038","outcome_index":0,"market_type":"set1","local_side":"home","local_uid":"2026-08-24_greet_minnen_jeline_vandromme","bid":0.001,"ask":0.09,"mid":0.0455,"spread":0.089,"price":0.059,"size":0.0,"side":"SELL"}
{"ts":"2026-08-24T20:48:21.584Z","event_type":"best_bid_ask","market_id":"3825038","outcome_index":0,"market_type":"set1","local_side":"home","local_uid":"2026-08-24_greet_minnen_jeline_vandromme","bid":0.001,"ask":0.14,"mid":0.0705,"spread":0.139,"bid_size":null,"ask_size":null}
{"ts":"2026-08-24T20:48:21.584Z","event_type":"best_bid_ask","market_id":"3825038","outcome_index":1,"market_type":"set1","local_side":"away","local_uid":"2026-08-24_greet_minnen_jeline_vandromme","bid":0.86,"ask":0.999,"mid":0.9295,"spread":0.139,"bid_size":null,"ask_size":null}
{"ts":"2026-08-24T20:48:21.584Z","event_type":"price_change","market_id":"3825038","outcome_index":1,"market_type":"set1","local_side":"away","local_uid":"2026-08-24_greet_minnen_jeline_vandromme","bid":0.86,"ask":0.999,"mid":0.9295,"spread":0.139,"price":0.91,"size":0.0,"side":"BUY"}
{"ts":"2026-08-24T20:48:21.584Z","event_type":"price_change","market_id":"3825038","outcome_index":0,"market_type":"set1","local_side":"home","local_uid":"2026-08-24_greet_minnen_jeline_vandromme","bid":0.001,"ask":0.14,"mid":0.0705,"spread":0.139,"price":0.09,"size":0.0,"side":"SELL"}
{"ts":"2026-08-24T20:48:21.585Z","event_type":"best_bid_ask","market_id":"3825038","outcome_index":0,"market_type":"set1","local_side":"home","local_uid":"2026-08-24_greet_minnen_jeline_vandromme","bid":0.001,"ask":0.05,"mid":0.0255,"spread":0.049,"bid_size":null,"ask_size":null}
{"ts":"2026-08-24T20:48:21.586Z","event_type":"best_bid_ask","market_id":"3825038","outcome_index":1,"market_type":"set1","local_side":"away","local_uid":"2026-08-24_greet_minnen_jeline_vandromme","bid":0.95,"ask":0.999,"mid":0.9745,"spread":0.049,"bid_size":null,"ask_size":null}
{"ts":"2026-08-24T20:48:21.586Z","event_type":"price_change","market_id":"3825038","outcome_index":1,"market_type":"set1","local_side":"away","local_uid":"2026-08-24_greet_minnen_jeline_vandromme","bid":0.95,"ask":0.999,"mid":0.9745,"spread":0.049,"price":0.95,"size":22.0,"side":"BUY"}
{"ts":"2026-08-24T20:48:21.586Z","event_type":"price_change","market_id":"3825038","outcome_index":0,"market_type":"set1","local_side":"home","local_uid":"2026-08-24_greet_minnen_jeline_vandromme","bid":0.001,"ask":0.05,"mid":0.0255,"spread":0.049,"price":0.05,"size":22.0,"side":"SELL"}
{"ts":"2026-08-24T20:48:21.587Z","event_type":"best_bid_ask","market_id":"3826733","outcome_index":0,"market_type":"set1","local_side":"home","local_uid":"2026-08-24_harry_wendelken_stefano_travaglia","bid":0.85,"ask":0.89,"mid":0.87,"spread":0.04,"bid_size":null,"ask_size":null}
{"ts":"2026-08-24T20:48:21.587Z","event_type":"best_bid_ask","market_id":"3826733","outcome_index":1,"market_type":"set1","local_side":"away","local_uid":"2026-08-24_harry_wendelken_stefano_travaglia","bid":0.11,"ask":0.15,"mid":0.13,"spread":0.04,"bid_size":null,"ask_size":null}
{"ts":"2026-08-24T20:48:21.588Z","event_type":"price_change","market_id":"3826733","outcome_index":1,"market_type":"set1","local_side":"away","local_uid":"2026-08-24_harry_wendelken_stefano_travaglia","bid":0.11,"ask":0.15,"mid":0.13,"spread":0.04,"price":0.14,"size":0.0,"side":"BUY"}
{"ts":"2026-08-24T20:48:21.588Z","event_type":"price_change","market_id":"3826733","outcome_index":0,"market_type":"set1","local_side":"home","local_uid":"2026-08-24_harry_wendelken_stefano_travaglia","bid":0.85,"ask":0.89,"mid":0.87,"spread":0.04,"price":0.86,"size":0.0,"side":"SELL"}
{"ts":"2026-08-24T20:48:21.589Z","event_type":"best_bid_ask","market_id":"3826654","outcome_index":0,"market_type":"set2","local_side":"home","local_uid":"2026-08-24_sebastian_gorzny_cruz_hewitt","bid":0.05,"ask":0.13,"mid":0.09,"spread":0.08,"bid_size":null,"ask_size":null}
{"ts":"2026-08-24T20:48:21.589Z","event_type":"best_bid_ask","market_id":"3826654","outcome_index":1,"market_type":"set2","local_side":"away","local_uid":"2026-08-24_sebastian_gorzny_cruz_hewitt","bid":0.87,"ask":0.95,"mid":0.91,"spread":0.08,"bid_size":null,"ask_size":null}
{"ts":"2026-08-24T20:48:21.589Z","event_type":"price_change","market_id":"3826654","outcome_index":0,"market_type":"set2","local_side":"home","local_uid":"2026-08-24_sebastian_gorzny_cruz_hewitt","bid":0.05,"ask":0.13,"mid":0.09,"spread":0.08,"price":0.05,"size":13.0,"side":"BUY"}
{"ts":"2026-08-24T20:48:21.590Z","event_type":"price_change","market_id":"3826654","outcome_index":1,"market_type":"set2","local_side":"away","local_uid":"2026-08-24_sebastian_gorzny_cruz_hewitt","bid":0.87,"ask":0.95,"mid":0.91,"spread":0.08,"price":0.95,"size":13.0,"side":"SELL"}
{"ts":"2026-08-24T20:48:21.591Z","event_type":"best_bid_ask","market_id":"3826654","outcome_index":0,"market_type":"set2","local_side":"home","local_uid":"2026-08-24_sebastian_gorzny_cruz_hewitt","bid":0.06,"ask":0.13,"mid":0.095,"spread":0.07,"bid_size":null,"ask_size":null}
{"ts":"2026-08-24T20:48:21.591Z","event_type":"best_bid_ask","market_id":"3826654","outcome_index":1,"market_type":"set2","local_side":"away","local_uid":"2026-08-24_sebastian_gorzny_cruz_hewitt","bid":0.87,"ask":0.94,"mid":0.905,"spread":0.07,"bid_size":null,"ask_size":null}
{"ts":"2026-08-24T20:48:21.591Z","event_type":"price_change","market_id":"3826654","outcome_index":0,"market_type":"set2","local_side":"home","local_uid":"2026-08-24_sebastian_gorzny_cruz_hewitt","bid":0.06,"ask":0.13,"mid":0.095,"spread":0.07,"price":0.06,"size":22.0,"side":"BUY"}
{"ts":"2026-08-24T20:48:21.591Z","event_type":"price_change","market_id":"3826654","outcome_index":1,"market_type":"set2","local_side":"away","local_uid":"2026-08-24_sebastian_gorzny_cruz_hewitt","bid":0.87,"ask":0.94,"mid":0.905,"spread":0.07,"price":0.94,"size":22.0,"side":"SELL"}
{"ts":"2026-08-24T20:48:21.593Z","event_type":"last_trade_price","market_id":"3825641","outcome_index":1,"market_type":"match","local_side":"away","local_uid":"2026-08-24_sebastian_gorzny_cruz_hewitt","last_trade":0.39,"trade_size":4.86,"trade_side":"BUY","trade_notional":1.8954}
{"ts":"2026-08-24T20:48:21.604Z","event_type":"best_bid_ask","market_id":"3823623","outcome_index":0,"market_type":"match","local_side":"home","local_uid":"2026-08-24_robin_montgomery_kayla_cross","bid":0.89,"ask":0.91,"mid":0.9,"spread":0.02,"bid_size":null,"ask_size":null}
{"ts":"2026-08-24T20:48:21.605Z","event_type":"best_bid_ask","market_id":"3823623","outcome_index":1,"market_type":"match","local_side":"away","local_uid":"2026-08-24_robin_montgomery_kayla_cross","bid":0.09,"ask":0.11,"mid":0.1,"spread":0.02,"bid_size":null,"ask_size":null}
{"ts":"2026-08-24T20:48:21.605Z","event_type":"price_change","market_id":"3823623","outcome_index":0,"market_type":"match","local_side":"home","local_uid":"2026-08-24_robin_montgomery_kayla_cross","bid":0.89,"ask":0.91,"mid":0.9,"spread":0.02,"price":0.88,"size":2882.5,"side":"BUY"}
{"ts":"2026-08-24T20:48:21.605Z","event_type":"price_change","market_id":"3823623","outcome_index":1,"market_type":"match","local_side":"away","local_uid":"2026-08-24_robin_montgomery_kayla_cross","bid":0.09,"ask":0.11,"mid":0.1,"spread":0.02,"price":0.12,"size":2882.5,"side":"SELL"}
{"ts":"2026-08-24T20:48:21.614Z","event_type":"best_bid_ask","market_id":"3825070","outcome_index":0,"market_type":"set2","local_side":"home","local_uid":"2026-08-24_polina_kudermetova_linda_fruhvirtova","bid":0.53,"ask":0.61,"mid":0.57,"spread":0.08,"bid_size":null,"ask_size":null}
{"ts":"2026-08-24T20:48:21.615Z","event_type":"best_bid_ask","market_id":"3825070","outcome_index":1,"market_type":"set2","local_side":"away","local_uid":"2026-08-24_polina_kudermetova_linda_fruhvirtova","bid":0.39,"ask":0.47,"mid":0.43,"spread":0.08,"bid_size":null,"ask_size":null}
{"ts":"2026-08-24T20:48:21.615Z","event_type":"price_change","market_id":"3825070","outcome_index":0,"market_type":"set2","local_side":"home","local_uid":"2026-08-24_polina_kudermetova_linda_fruhvirtova","bid":0.53,"ask":0.61,"mid":0.57,"spread":0.08,"price":0.53,"size":150.0,"side":"BUY"}
{"ts":"2026-08-24T20:48:21.615Z","event_type":"price_change","market_id":"3825070","outcome_index":1,"market_type":"set2","local_side":"away","local_uid":"2026-08-24_polina_kudermetova_linda_fruhvirtova","bid":0.39,"ask":0.47,"mid":0.43,"spread":0.08,"price":0.47,"size":150.0,"side":"SELL"}
{"ts":"2026-08-24T20:48:21.616Z","event_type":"best_bid_ask","market_id":"3825053","outcome_index":0,"market_type":"set1","local_side":"home","local_uid":"2026-08-24_robin_montgomery_kayla_cross","bid":0.92,"ask":0.96,"mid":0.94,"spread":0.04,"bid_size":null,"ask_size":null}
{"ts":"2026-08-24T20:48:21.623Z","event_type":"best_bid_ask","market_id":"3825053","outcome_index":1,"market_type":"set1","local_side":"away","local_uid":"2026-08-24_robin_montgomery_kayla_cross","bid":0.04,"ask":0.08,"mid":0.06,"spread":0.04,"bid_size":null,"ask_size":null}
{"ts":"2026-08-24T20:48:21.623Z","event_type":"price_change","market_id":"3825053","outcome_index":1,"market_type":"set1","local_side":"away","local_uid":"2026-08-24_robin_montgomery_kayla_cross","bid":0.04,"ask":0.08,"mid":0.06,"spread":0.04,"price":0.05,"size":0.0,"side":"BUY"}
{"ts":"2026-08-24T20:48:21.624Z","event_type":"price_change","market_id":"3825053","outcome_index":0,"market_type":"set1","local_side":"home","local_uid":"2026-08-24_robin_montgomery_kayla_cross","bid":0.92,"ask":0.96,"mid":0.94,"spread":0.04,"price":0.95,"size":0.0,"side":"SELL"}
{"ts":"2026-08-24T20:48:21.640Z","event_type":"best_bid_ask","market_id":"3823625","outcome_index":0,"market_type":"match","local_side":"home","local_uid":"2026-08-24_greet_minnen_jeline_vandromme","bid":0.15,"ask":0.18,"mid":0.165,"spread":0.03,"bid_size":null,"ask_size":null}
{"ts":"2026-08-24T20:48:21.640Z","event_type":"best_bid_ask","market_id":"3823625","outcome_index":1,"market_type":"match","local_side":"away","local_uid":"2026-08-24_greet_minnen_jeline_vandromme","bid":0.82,"ask":0.85,"mid":0.835,"spread":0.03,"bid_size":null,"ask_size":null}
{"ts":"2026-08-24T20:48:21.640Z","event_type":"price_change","market_id":"3823625","outcome_index":1,"market_type":"match","local_side":"away","local_uid":"2026-08-24_greet_minnen_jeline_vandromme","bid":0.82,"ask":0.85,"mid":0.835,"spread":0.03,"price":0.82,"size":403.59,"side":"BUY"}
{"ts":"2026-08-24T20:48:21.641Z","event_type":"price_change","market_id":"3823625","outcome_index":0,"market_type":"match","local_side":"home","local_uid":"2026-08-24_greet_minnen_jeline_vandromme","bid":0.15,"ask":0.18,"mid":0.165,"spread":0.03,"price":0.18,"size":403.59,"side":"SELL"}
{"ts":"2026-08-24T20:48:21.642Z","event_type":"price_change","market_id":"3823651","outcome_index":0,"market_type":"match","local_side":"home","local_uid":"2026-08-24_dominika_salkova_akasha_urhobo","bid":0.62,"ask":0.63,"mid":0.625,"spread":0.01,"price":0.46,"size":0.0,"side":"BUY"}
{"ts":"2026-08-24T20:48:21.642Z","event_type":"price_change","market_id":"3823651","outcome_index":1,"market_type":"match","local_side":"away","local_uid":"2026-08-24_dominika_salkova_akasha_urhobo","bid":0.37,"ask":0.38,"mid":0.375,"spread":0.01,"price":0.54,"size":0.0,"side":"SELL"}
{"ts":"2026-08-24T20:48:21.682Z","event_type":"best_bid_ask","market_id":"3825038","outcome_index":0,"market_type":"set1","local_side":"home","local_uid":"2026-08-24_greet_minnen_jeline_vandromme","bid":0.001,"ask":0.06,"mid":0.0305,"spread":0.059,"bid_size":null,"ask_size":null}
{"ts":"2026-08-24T20:48:21.682Z","event_type":"best_bid_ask","market_id":"3825038","outcome_index":1,"market_type":"set1","local_side":"away","local_uid":"2026-08-24_greet_minnen_jeline_vandromme","bid":0.94,"ask":0.999,"mid":0.9695,"spread":0.059,"bid_size":null,"ask_size":null}
{"ts":"2026-08-24T20:48:21.682Z","event_type":"price_change","market_id":"3825038","outcome_index":1,"market_type":"set1","local_side":"away","local_uid":"2026-08-24_greet_minnen_jeline_vandromme","bid":0.94,"ask":0.999,"mid":0.9695,"spread":0.059,"price":0.95,"size":0.0,"side":"BUY"}
{"ts":"2026-08-24T20:48:21.683Z","event_type":"price_change","market_id":"3825038","outcome_index":0,"market_type":"set1","local_side":"home","local_uid":"2026-08-24_greet_minnen_jeline_vandromme","bid":0.001,"ask":0.06,"mid":0.0305,"spread":0.059,"price":0.05,"size":0.0,"side":"SELL"}
{"ts":"2026-08-24T20:48:21.689Z","event_type":"best_bid_ask","market_id":"3825038","outcome_index":0,"market_type":"set1","local_side":"home","local_uid":"2026-08-24_greet_minnen_jeline_vandromme","bid":0.001,"ask":0.09,"mid":0.0455,"spread":0.089,"bid_size":null,"ask_size":null}
{"ts":"2026-08-24T20:48:21.689Z","event_type":"best_bid_ask","market_id":"3825038","outcome_index":1,"market_type":"set1","local_side":"away","local_uid":"2026-08-24_greet_minnen_jeline_vandromme","bid":0.91,"ask":0.999,"mid":0.9545,"spread":0.089,"bid_size":null,"ask_size":null}
{"ts":"2026-08-24T20:48:21.689Z","event_type":"price_change","market_id":"3825038","outcome_index":1,"market_type":"set1","local_side":"away","local_uid":"2026-08-24_greet_minnen_jeline_vandromme","bid":0.91,"ask":0.999,"mid":0.9545,"spread":0.089,"price":0.94,"size":0.0,"side":"BUY"}
{"ts":"2026-08-24T20:48:21.689Z","event_type":"price_change","market_id":"3825038","outcome_index":0,"market_type":"set1","local_side":"home","local_uid":"2026-08-24_greet_minnen_jeline_vandromme","bid":0.001,"ask":0.09,"mid":0.0455,"spread":0.089,"price":0.06,"size":0.0,"side":"SELL"}
{"ts":"2026-08-24T20:48:21.695Z","event_type":"best_bid_ask","market_id":"3825038","outcome_index":0,"market_type":"set1","local_side":"home","local_uid":"2026-08-24_greet_minnen_jeline_vandromme","bid":0.001,"ask":0.14,"mid":0.0705,"spread":0.139,"bid_size":null,"ask_size":null}
{"ts":"2026-08-24T20:48:21.695Z","event_type":"best_bid_ask","market_id":"3825038","outcome_index":1,"market_type":"set1","local_side":"away","local_uid":"2026-08-24_greet_minnen_jeline_vandromme","bid":0.86,"ask":0.999,"mid":0.9295,"spread":0.139,"bid_size":null,"ask_size":null}
{"ts":"2026-08-24T20:48:21.696Z","event_type":"price_change","market_id":"3825038","outcome_index":1,"market_type":"set1","local_side":"away","local_uid":"2026-08-24_greet_minnen_jeline_vandromme","bid":0.86,"ask":0.999,"mid":0.9295,"spread":0.139,"price":0.91,"size":0.0,"side":"BUY"}
{"ts":"2026-08-24T20:48:21.696Z","event_type":"price_change","market_id":"3825038","outcome_index":0,"market_type":"set1","local_side":"home","local_uid":"2026-08-24_greet_minnen_jeline_vandromme","bid":0.001,"ask":0.14,"mid":0.0705,"spread":0.139,"price":0.09,"size":0.0,"side":"SELL"}
{"ts":"2026-08-24T20:48:21.701Z","event_type":"best_bid_ask","market_id":"3825038","outcome_index":0,"market_type":"set1","local_side":"home","local_uid":"2026-08-24_greet_minnen_jeline_vandromme","bid":0.001,"ask":0.08,"mid":0.0405,"spread":0.079,"bid_size":null,"ask_size":null}
{"ts":"2026-08-24T20:48:21.702Z","event_type":"best_bid_ask","market_id":"3825038","outcome_index":1,"market_type":"set1","local_side":"away","local_uid":"2026-08-24_greet_minnen_jeline_vandromme","bid":0.92,"ask":0.999,"mid":0.9595,"spread":0.079,"bid_size":null,"ask_size":null}
{"ts":"2026-08-24T20:48:21.702Z","event_type":"price_change","market_id":"3825038","outcome_index":1,"market_type":"set1","local_side":"away","local_uid":"2026-08-24_greet_minnen_jeline_vandromme","bid":0.92,"ask":0.999,"mid":0.9595,"spread":0.079,"price":0.92,"size":44.0,"side":"BUY"}
{"ts":"2026-08-24T20:48:21.702Z","event_type":"price_change","market_id":"3825038","outcome_index":0,"market_type":"set1","local_side":"home","local_uid":"2026-08-24_greet_minnen_jeline_vandromme","bid":0.001,"ask":0.08,"mid":0.0405,"spread":0.079,"price":0.08,"size":44.0,"side":"SELL"}
{"ts":"2026-08-24T20:48:21.744Z","event_type":"best_bid_ask","market_id":"3823625","outcome_index":0,"market_type":"match","local_side":"home","local_uid":"2026-08-24_greet_minnen_jeline_vandromme","bid":0.15,"ask":0.19,"mid":0.17,"spread":0.04,"bid_size":null,"ask_size":null}
{"ts":"2026-08-24T20:48:21.745Z","event_type":"best_bid_ask","market_id":"3823625","outcome_index":1,"market_type":"match","local_side":"away","local_uid":"2026-08-24_greet_minnen_jeline_vandromme","bid":0.81,"ask":0.85,"mid":0.83,"spread":0.04,"bid_size":null,"ask_size":null}
{"ts":"2026-08-24T20:48:21.745Z","event_type":"price_change","market_id":"3823625","outcome_index":1,"market_type":"match","local_side":"away","local_uid":"2026-08-24_greet_minnen_jeline_vandromme","bid":0.81,"ask":0.85,"mid":0.83,"spread":0.04,"price":0.82,"size":0.0,"side":"BUY"}
{"ts":"2026-08-24T20:48:21.746Z","event_type":"price_change","market_id":"3823625","outcome_index":0,"market_type":"match","local_side":"home","local_uid":"2026-08-24_greet_minnen_jeline_vandromme","bid":0.15,"ask":0.19,"mid":0.17,"spread":0.04,"price":0.18,"size":0.0,"side":"SELL"}
{"ts":"2026-08-24T20:48:21.822Z","event_type":"best_bid_ask","market_id":"3825038","outcome_index":0,"market_type":"set1","local_side":"home","local_uid":"2026-08-24_greet_minnen_jeline_vandromme","bid":0.001,"ask":0.09,"mid":0.0455,"spread":0.089,"bid_size":null,"ask_size":null}
{"ts":"2026-08-24T20:48:21.822Z","event_type":"best_bid_ask","market_id":"3825038","outcome_index":1,"market_type":"set1","local_side":"away","local_uid":"2026-08-24_greet_minnen_jeline_vandromme","bid":0.91,"ask":0.999,"mid":0.9545,"spread":0.089,"bid_size":null,"ask_size":null}
{"ts":"2026-08-24T20:48:21.822Z","event_type":"price_change","market_id":"3825038","outcome_index":1,"market_type":"set1","local_side":"away","local_uid":"2026-08-24_greet_minnen_jeline_vandromme","bid":0.91,"ask":0.999,"mid":0.9545,"spread":0.089,"price":0.92,"size":0.0,"side":"BUY"}
{"ts":"2026-08-24T20:48:21.823Z","event_type":"price_change","market_id":"3825038","outcome_index":0,"market_type":"set1","local_side":"home","local_uid":"2026-08-24_greet_minnen_jeline_vandromme","bid":0.001,"ask":0.09,"mid":0.0455,"spread":0.089,"price":0.08,"size":0.0,"side":"SELL"}
{"ts":"2026-08-24T20:48:21.823Z","event_type":"best_bid_ask","market_id":"3825038","outcome_index":0,"market_type":"set1","local_side":"home","local_uid":"2026-08-24_greet_minnen_jeline_vandromme","bid":0.001,"ask":0.08,"mid":0.0405,"spread":0.079,"bid_size":null,"ask_size":null}
{"ts":"2026-08-24T20:48:21.823Z","event_type":"best_bid_ask","market_id":"3825038","outcome_index":1,"market_type":"set1","local_side":"away","local_uid":"2026-08-24_greet_minnen_jeline_vandromme","bid":0.92,"ask":0.999,"mid":0.9595,"spread":0.079,"bid_size":null,"ask_size":null}
{"ts":"2026-08-24T20:48:21.824Z","event_type":"price_change","market_id":"3825038","outcome_index":1,"market_type":"set1","local_side":"away","local_uid":"2026-08-24_greet_minnen_jeline_vandromme","bid":0.92,"ask":0.999,"mid":0.9595,"spread":0.079,"price":0.92,"size":22.0,"side":"BUY"}
{"ts":"2026-08-24T20:48:21.824Z","event_type":"price_change","market_id":"3825038","outcome_index":0,"market_type":"set1","local_side":"home","local_uid":"2026-08-24_greet_minnen_jeline_vandromme","bid":0.001,"ask":0.08,"mid":0.0405,"spread":0.079,"price":0.08,"size":22.0,"side":"SELL"}
{"ts":"2026-08-24T20:48:21.850Z","event_type":"best_bid_ask","market_id":"3825038","outcome_index":0,"market_type":"set1","local_side":"home","local_uid":"2026-08-24_greet_minnen_jeline_vandromme","bid":0.001,"ask":0.09,"mid":0.0455,"spread":0.089,"bid_size":null,"ask_size":null}
{"ts":"2026-08-24T20:48:21.850Z","event_type":"best_bid_ask","market_id":"3825038","outcome_index":1,"market_type":"set1","local_side":"away","local_uid":"2026-08-24_greet_minnen_jeline_vandromme","bid":0.91,"ask":0.999,"mid":0.9545,"spread":0.089,"bid_size":null,"ask_size":null}
{"ts":"2026-08-24T20:48:21.850Z","event_type":"price_change","market_id":"3825038","outcome_index":1,"market_type":"set1","local_side":"away","local_uid":"2026-08-24_greet_minnen_jeline_vandromme","bid":0.91,"ask":0.999,"mid":0.9545,"spread":0.089,"price":0.92,"size":0.0,"side":"BUY"}
{"ts":"2026-08-24T20:48:21.851Z","event_type":"price_change","market_id":"3825038","outcome_index":0,"market_type":"set1","local_side":"home","local_uid":"2026-08-24_greet_minnen_jeline_vandromme","bid":0.001,"ask":0.09,"mid":0.0455,"spread":0.089,"price":0.08,"size":0.0,"side":"SELL"}
{"ts":"2026-08-24T20:48:21.853Z","event_type":"best_bid_ask","market_id":"3825038","outcome_index":0,"market_type":"set1","local_side":"home","local_uid":"2026-08-24_greet_minnen_jeline_vandromme","bid":0.001,"ask":0.07,"mid":0.0355,"spread":0.069,"bid_size":null,"ask_size":null}
{"ts":"2026-08-24T20:48:21.853Z","event_type":"best_bid_ask","market_id":"3825038","outcome_index":1,"market_type":"set1","local_side":"away","local_uid":"2026-08-24_greet_minnen_jeline_vandromme","bid":0.93,"ask":0.999,"mid":0.9645,"spread":0.069,"bid_size":null,"ask_size":null}
{"ts":"2026-08-24T20:48:21.853Z","event_type":"price_change","market_id":"3825038","outcome_index":1,"market_type":"set1","local_side":"away","local_uid":"2026-08-24_greet_minnen_jeline_vandromme","bid":0.93,"ask":0.999,"mid":0.9645,"spread":0.069,"price":0.93,"size":26.0,"side":"BUY"}
{"ts":"2026-08-24T20:48:21.854Z","event_type":"price_change","market_id":"3825038","outcome_index":0,"market_type":"set1","local_side":"home","local_uid":"2026-08-24_greet_minnen_jeline_vandromme","bid":0.001,"ask":0.07,"mid":0.0355,"spread":0.069,"price":0.07,"size":26.0,"side":"SELL"}
{"ts":"2026-08-24T20:48:21.855Z","event_type":"best_bid_ask","market_id":"3825038","outcome_index":0,"market_type":"set1","local_side":"home","local_uid":"2026-08-24_greet_minnen_jeline_vandromme","bid":0.001,"ask":0.06,"mid":0.0305,"spread":0.059,"bid_size":null,"ask_size":null}
{"ts":"2026-08-24T20:48:21.856Z","event_type":"best_bid_ask","market_id":"3825038","outcome_index":1,"market_type":"set1","local_side":"away","local_uid":"2026-08-24_greet_minnen_jeline_vandromme","bid":0.94,"ask":0.999,"mid":0.9695,"spread":0.059,"bid_size":null,"ask_size":null}
{"ts":"2026-08-24T20:48:21.856Z","event_type":"price_change","market_id":"3825038","outcome_index":1,"market_type":"set1","local_side":"away","local_uid":"2026-08-24_greet_minnen_jeline_vandromme","bid":0.94,"ask":0.999,"mid":0.9695,"spread":0.059,"price":0.94,"size":44.0,"side":"BUY"}
{"ts":"2026-08-24T20:48:21.856Z","event_type":"price_change","market_id":"3825038","outcome_index":0,"market_type":"set1","local_side":"home","local_uid":"2026-08-24_greet_minnen_jeline_vandromme","bid":0.001,"ask":0.06,"mid":0.0305,"spread":0.059,"price":0.06,"size":44.0,"side":"SELL"}
{"ts":"2026-08-24T20:48:21.862Z","event_type":"best_bid_ask","market_id":"3825038","outcome_index":0,"market_type":"set1","local_side":"home","local_uid":"2026-08-24_greet_minnen_jeline_vandromme","bid":0.001,"ask":0.09,"mid":0.0455,"spread":0.089,"bid_size":null,"ask_size":null}
{"ts":"2026-08-24T20:48:21.862Z","event_type":"best_bid_ask","market_id":"3825038","outcome_index":1,"market_type":"set1","local_side":"away","local_uid":"2026-08-24_greet_minnen_jeline_vandromme","bid":0.91,"ask":0.999,"mid":0.9545,"spread":0.089,"bid_size":null,"ask_size":null}
{"ts":"2026-08-24T20:48:21.862Z","event_type":"price_change","market_id":"3825038","outcome_index":1,"market_type":"set1","local_side":"away","local_uid":"2026-08-24_greet_minnen_jeline_vandromme","bid":0.91,"ask":0.999,"mid":0.9545,"spread":0.089,"price":0.94,"size":0.0,"side":"BUY"}
{"ts":"2026-08-24T20:48:21.862Z","event_type":"price_change","market_id":"3825038","outcome_index":0,"market_type":"set1","local_side":"home","local_uid":"2026-08-24_greet_minnen_jeline_vandromme","bid":0.001,"ask":0.09,"mid":0.0455,"spread":0.089,"price":0.06,"size":0.0,"side":"SELL"}
{"ts":"2026-08-24T20:48:21.878Z","event_type":"best_bid_ask","market_id":"3825038","outcome_index":0,"market_type":"set1","local_side":"home","local_uid":"2026-08-24_greet_minnen_jeline_vandromme","bid":0.001,"ask":0.14,"mid":0.0705,"spread":0.139,"bid_size":null,"ask_size":null}
{"ts":"2026-08-24T20:48:21.878Z","event_type":"best_bid_ask","market_id":"3825038","outcome_index":1,"market_type":"set1","local_side":"away","local_uid":"2026-08-24_greet_minnen_jeline_vandromme","bid":0.86,"ask":0.999,"mid":0.9295,"spread":0.139,"bid_size":null,"ask_size":null}
{"ts":"2026-08-24T20:48:21.878Z","event_type":"price_change","market_id":"3825038","outcome_index":1,"market_type":"set1","local_side":"away","local_uid":"2026-08-24_greet_minnen_jeline_vandromme","bid":0.86,"ask":0.999,"mid":0.9295,"spread":0.139,"price":0.91,"size":0.0,"side":"BUY"}
{"ts":"2026-08-24T20:48:21.879Z","event_type":"price_change","market_id":"3825038","outcome_index":0,"market_type":"set1","local_side":"home","local_uid":"2026-08-24_greet_minnen_jeline_vandromme","bid":0.001,"ask":0.14,"mid":0.0705,"spread":0.139,"price":0.09,"size":0.0,"side":"SELL"}
{"ts":"2026-08-24T20:48:21.879Z","event_type":"best_bid_ask","market_id":"3825038","outcome_index":0,"market_type":"set1","local_side":"home","local_uid":"2026-08-24_greet_minnen_jeline_vandromme","bid":0.001,"ask":0.06,"mid":0.0305,"spread":0.059,"bid_size":null,"ask_size":null}
{"ts":"2026-08-24T20:48:21.879Z","event_type":"best_bid_ask","market_id":"3825038","outcome_index":1,"market_type":"set1","local_side":"away","local_uid":"2026-08-24_greet_minnen_jeline_vandromme","bid":0.94,"ask":0.999,"mid":0.9695,"spread":0.059,"bid_size":null,"ask_size":null}
{"ts":"2026-08-24T20:48:21.879Z","event_type":"price_change","market_id":"3825038","outcome_index":1,"market_type":"set1","local_side":"away","local_uid":"2026-08-24_greet_minnen_jeline_vandromme","bid":0.94,"ask":0.999,"mid":0.9695,"spread":0.059,"price":0.94,"size":26.0,"side":"BUY"}
{"ts":"2026-08-24T20:48:21.880Z","event_type":"price_change","market_id":"3825038","outcome_index":0,"market_type":"set1","local_side":"home","local_uid":"2026-08-24_greet_minnen_jeline_vandromme","bid":0.001,"ask":0.06,"mid":0.0305,"spread":0.059,"price":0.06,"size":26.0,"side":"SELL"}
{"ts":"2026-08-24T20:48:21.880Z","event_type":"best_bid_ask","market_id":"3825038","outcome_index":0,"market_type":"set1","local_side":"home","local_uid":"2026-08-24_greet_minnen_jeline_vandromme","bid":0.001,"ask":0.05,"mid":0.0255,"spread":0.049,"bid_size":null,"ask_size":null}
{"ts":"2026-08-24T20:48:21.880Z","event_type":"best_bid_ask","market_id":"3825038","outcome_index":1,"market_type":"set1","local_side":"away","local_uid":"2026-08-24_greet_minnen_jeline_vandromme","bid":0.95,"ask":0.999,"mid":0.9745,"spread":0.049,"bid_size":null,"ask_size":null}
{"ts":"2026-08-24T20:48:21.880Z","event_type":"price_change","market_id":"3825038","outcome_index":1,"market_type":"set1","local_side":"away","local_uid":"2026-08-24_greet_minnen_jeline_vandromme","bid":0.95,"ask":0.999,"mid":0.9745,"spread":0.049,"price":0.95,"size":44.0,"side":"BUY"}
{"ts":"2026-08-24T20:48:21.881Z","event_type":"price_change","market_id":"3825038","outcome_index":0,"market_type":"set1","local_side":"home","local_uid":"2026-08-24_greet_minnen_jeline_vandromme","bid":0.001,"ask":0.05,"mid":0.0255,"spread":0.049,"price":0.05,"size":44.0,"side":"SELL"}
{"ts":"2026-08-24T20:48:21.923Z","event_type":"best_bid_ask","market_id":"3825038","outcome_index":0,"market_type":"set1","local_side":"home","local_uid":"2026-08-24_greet_minnen_jeline_vandromme","bid":0.001,"ask":0.06,"mid":0.0305,"spread":0.059,"bid_size":null,"ask_size":null}
{"ts":"2026-08-24T20:48:21.924Z","event_type":"best_bid_ask","market_id":"3825038","outcome_index":1,"market_type":"set1","local_side":"away","local_uid":"2026-08-24_greet_minnen_jeline_vandromme","bid":0.94,"ask":0.999,"mid":0.9695,"spread":0.059,"bid_size":null,"ask_size":null}
{"ts":"2026-08-24T20:48:21.924Z","event_type":"price_change","market_id":"3825038","outcome_index":1,"market_type":"set1","local_side":"away","local_uid":"2026-08-24_greet_minnen_jeline_vandromme","bid":0.94,"ask":0.999,"mid":0.9695,"spread":0.059,"price":0.95,"size":0.0,"side":"BUY"}
{"ts":"2026-08-24T20:48:21.924Z","event_type":"price_change","market_id":"3825038","outcome_index":0,"market_type":"set1","local_side":"home","local_uid":"2026-08-24_greet_minnen_jeline_vandromme","bid":0.001,"ask":0.06,"mid":0.0305,"spread":0.059,"price":0.05,"size":0.0,"side":"SELL"}
{"ts":"2026-08-24T20:48:21.925Z","event_type":"best_bid_ask","market_id":"3825038","outcome_index":0,"market_type":"set1","local_side":"home","local_uid":"2026-08-24_greet_minnen_jeline_vandromme","bid":0.001,"ask":0.14,"mid":0.0705,"spread":0.139,"bid_size":null,"ask_size":null}
{"ts":"2026-08-24T20:48:21.925Z","event_type":"best_bid_ask","market_id":"3825038","outcome_index":1,"market_type":"set1","local_side":"away","local_uid":"2026-08-24_greet_minnen_jeline_vandromme","bid":0.86,"ask":0.999,"mid":0.9295,"spread":0.139,"bid_size":null,"ask_size":null}
{"ts":"2026-08-24T20:48:21.926Z","event_type":"price_change","market_id":"3825038","outcome_index":1,"market_type":"set1","local_side":"away","local_uid":"2026-08-24_greet_minnen_jeline_vandromme","bid":0.86,"ask":0.999,"mid":0.9295,"spread":0.139,"price":0.94,"size":0.0,"side":"BUY"}
{"ts":"2026-08-24T20:48:21.926Z","event_type":"price_change","market_id":"3825038","outcome_index":0,"market_type":"set1","local_side":"home","local_uid":"2026-08-24_greet_minnen_jeline_vandromme","bid":0.001,"ask":0.14,"mid":0.0705,"spread":0.139,"price":0.06,"size":0.0,"side":"SELL"}
{"ts":"2026-08-24T20:48:21.926Z","event_type":"best_bid_ask","market_id":"3825038","outcome_index":0,"market_type":"set1","local_side":"home","local_uid":"2026-08-24_greet_minnen_jeline_vandromme","bid":0.001,"ask":0.1,"mid":0.0505,"spread":0.099,"bid_size":null,"ask_size":null}
{"ts":"2026-08-24T20:48:21.931Z","event_type":"best_bid_ask","market_id":"3825038","outcome_index":1,"market_type":"set1","local_side":"away","local_uid":"2026-08-24_greet_minnen_jeline_vandromme","bid":0.9,"ask":0.999,"mid":0.9495,"spread":0.099,"bid_size":null,"ask_size":null}
{"ts":"2026-08-24T20:48:21.932Z","event_type":"price_change","market_id":"3825038","outcome_index":1,"market_type":"set1","local_side":"away","local_uid":"2026-08-24_greet_minnen_jeline_vandromme","bid":0.9,"ask":0.999,"mid":0.9495,"spread":0.099,"price":0.9,"size":423.0,"side":"BUY"}
{"ts":"2026-08-24T20:48:21.932Z","event_type":"price_change","market_id":"3825038","outcome_index":0,"market_type":"set1","local_side":"home","local_uid":"2026-08-24_greet_minnen_jeline_vandromme","bid":0.001,"ask":0.1,"mid":0.0505,"spread":0.099,"price":0.1,"size":423.0,"side":"SELL"}
{"ts":"2026-08-24T20:48:21.952Z","event_type":"best_bid_ask","market_id":"3825038","outcome_index":0,"market_type":"set1","local_side":"home","local_uid":"2026-08-24_greet_minnen_jeline_vandromme","bid":0.001,"ask":0.09,"mid":0.0455,"spread":0.089,"bid_size":null,"ask_size":null}
{"ts":"2026-08-24T20:48:21.952Z","event_type":"best_bid_ask","market_id":"3825038","outcome_index":1,"market_type":"set1","local_side":"away","local_uid":"2026-08-24_greet_minnen_jeline_vandromme","bid":0.91,"ask":0.999,"mid":0.9545,"spread":0.089,"bid_size":null,"ask_size":null}
{"ts":"2026-08-24T20:48:21.953Z","event_type":"price_change","market_id":"3825038","outcome_index":1,"market_type":"set1","local_side":"away","local_uid":"2026-08-24_greet_minnen_jeline_vandromme","bid":0.91,"ask":0.999,"mid":0.9545,"spread":0.089,"price":0.91,"size":88.0,"side":"BUY"}
{"ts":"2026-08-24T20:48:21.953Z","event_type":"price_change","market_id":"3825038","outcome_index":0,"market_type":"set1","local_side":"home","local_uid":"2026-08-24_greet_minnen_jeline_vandromme","bid":0.001,"ask":0.09,"mid":0.0455,"spread":0.089,"price":0.09,"size":88.0,"side":"SELL"}
{"ts":"2026-08-24T20:48:21.966Z","event_type":"best_bid_ask","market_id":"3825038","outcome_index":0,"market_type":"set1","local_side":"home","local_uid":"2026-08-24_greet_minnen_jeline_vandromme","bid":0.001,"ask":0.06,"mid":0.0305,"spread":0.059,"bid_size":null,"ask_size":null}
{"ts":"2026-08-24T20:48:21.966Z","event_type":"best_bid_ask","market_id":"3825038","outcome_index":1,"market_type":"set1","local_side":"away","local_uid":"2026-08-24_greet_minnen_jeline_vandromme","bid":0.94,"ask":0.999,"mid":0.9695,"spread":0.059,"bid_size":null,"ask_size":null}
{"ts":"2026-08-24T20:48:21.972Z","event_type":"price_change","market_id":"3825038","outcome_index":1,"market_type":"set1","local_side":"away","local_uid":"2026-08-24_greet_minnen_jeline_vandromme","bid":0.94,"ask":0.999,"mid":0.9695,"spread":0.059,"price":0.94,"size":50.0,"side":"BUY"}
{"ts":"2026-08-24T20:48:21.972Z","event_type":"price_change","market_id":"3825038","outcome_index":0,"market_type":"set1","local_side":"home","local_uid":"2026-08-24_greet_minnen_jeline_vandromme","bid":0.001,"ask":0.06,"mid":0.0305,"spread":0.059,"price":0.06,"size":50.0,"side":"SELL"}
{"ts":"2026-08-24T20:48:22.045Z","event_type":"best_bid_ask","market_id":"3825038","outcome_index":0,"market_type":"set1","local_side":"home","local_uid":"2026-08-24_greet_minnen_jeline_vandromme","bid":0.001,"ask":0.08,"mid":0.0405,"spread":0.079,"bid_size":null,"ask_size":null}
{"ts":"2026-08-24T20:48:22.045Z","event_type":"best_bid_ask","market_id":"3825038","outcome_index":1,"market_type":"set1","local_side":"away","local_uid":"2026-08-24_greet_minnen_jeline_vandromme","bid":0.92,"ask":0.999,"mid":0.9595,"spread":0.079,"bid_size":null,"ask_size":null}
{"ts":"2026-08-24T20:48:22.046Z","event_type":"price_change","market_id":"3825038","outcome_index":1,"market_type":"set1","local_side":"away","local_uid":"2026-08-24_greet_minnen_jeline_vandromme","bid":0.92,"ask":0.999,"mid":0.9595,"spread":0.079,"price":0.94,"size":0.0,"side":"BUY"}
{"ts":"2026-08-24T20:48:22.046Z","event_type":"price_change","market_id":"3825038","outcome_index":0,"market_type":"set1","local_side":"home","local_uid":"2026-08-24_greet_minnen_jeline_vandromme","bid":0.001,"ask":0.08,"mid":0.0405,"spread":0.079,"price":0.06,"size":0.0,"side":"SELL"}
{"ts":"2026-08-24T20:48:22.182Z","event_type":"best_bid_ask","market_id":"3826654","outcome_index":0,"market_type":"set2","local_side":"home","local_uid":"2026-08-24_sebastian_gorzny_cruz_hewitt","bid":0.05,"ask":0.13,"mid":0.09,"spread":0.08,"bid_size":null,"ask_size":null}
{"ts":"2026-08-24T20:48:22.182Z","event_type":"best_bid_ask","market_id":"3826654","outcome_index":1,"market_type":"set2","local_side":"away","local_uid":"2026-08-24_sebastian_gorzny_cruz_hewitt","bid":0.87,"ask":0.95,"mid":0.91,"spread":0.08,"bid_size":null,"ask_size":null}
{"ts":"2026-08-24T20:48:22.183Z","event_type":"price_change","market_id":"3826654","outcome_index":0,"market_type":"set2","local_side":"home","local_uid":"2026-08-24_sebastian_gorzny_cruz_hewitt","bid":0.05,"ask":0.13,"mid":0.09,"spread":0.08,"price":0.06,"size":0.0,"side":"BUY"}
{"ts":"2026-08-24T20:48:22.183Z","event_type":"price_change","market_id":"3826654","outcome_index":1,"market_type":"set2","local_side":"away","local_uid":"2026-08-24_sebastian_gorzny_cruz_hewitt","bid":0.87,"ask":0.95,"mid":0.91,"spread":0.08,"price":0.94,"size":0.0,"side":"SELL"}
{"ts":"2026-08-24T20:48:22.183Z","event_type":"best_bid_ask","market_id":"3826654","outcome_index":0,"market_type":"set2","local_side":"home","local_uid":"2026-08-24_sebastian_gorzny_cruz_hewitt","bid":0.04,"ask":0.13,"mid":0.085,"spread":0.09,"bid_size":null,"ask_size":null}
{"ts":"2026-08-24T20:48:22.183Z","event_type":"best_bid_ask","market_id":"3826654","outcome_index":1,"market_type":"set2","local_side":"away","local_uid":"2026-08-24_sebastian_gorzny_cruz_hewitt","bid":0.87,"ask":0.96,"mid":0.915,"spread":0.09,"bid_size":null,"ask_size":null}
{"ts":"2026-08-24T20:48:22.184Z","event_type":"price_change","market_id":"3826654","outcome_index":0,"market_type":"set2","local_side":"home","local_uid":"2026-08-24_sebastian_gorzny_cruz_hewitt","bid":0.04,"ask":0.13,"mid":0.085,"spread":0.09,"price":0.05,"size":0.0,"side":"BUY"}
{"ts":"2026-08-24T20:48:22.184Z","event_type":"price_change","market_id":"3826654","outcome_index":1,"market_type":"set2","local_side":"away","local_uid":"2026-08-24_sebastian_gorzny_cruz_hewitt","bid":0.87,"ask":0.96,"mid":0.915,"spread":0.09,"price":0.95,"size":0.0,"side":"SELL"}
{"ts":"2026-08-24T20:48:22.420Z","event_type":"best_bid_ask","market_id":"3825038","outcome_index":0,"market_type":"set1","local_side":"home","local_uid":"2026-08-24_greet_minnen_jeline_vandromme","bid":0.001,"ask":0.09,"mid":0.0455,"spread":0.089,"bid_size":null,"ask_size":null}
{"ts":"2026-08-24T20:48:22.420Z","event_type":"best_bid_ask","market_id":"3825038","outcome_index":1,"market_type":"set1","local_side":"away","local_uid":"2026-08-24_greet_minnen_jeline_vandromme","bid":0.91,"ask":0.999,"mid":0.9545,"spread":0.089,"bid_size":null,"ask_size":null}
{"ts":"2026-08-24T20:48:22.421Z","event_type":"price_change","market_id":"3825038","outcome_index":1,"market_type":"set1","local_side":"away","local_uid":"2026-08-24_greet_minnen_jeline_vandromme","bid":0.91,"ask":0.999,"mid":0.9545,"spread":0.089,"price":0.92,"size":0.0,"side":"BUY"}
{"ts":"2026-08-24T20:48:22.421Z","event_type":"price_change","market_id":"3825038","outcome_index":0,"market_type":"set1","local_side":"home","local_uid":"2026-08-24_greet_minnen_jeline_vandromme","bid":0.001,"ask":0.09,"mid":0.0455,"spread":0.089,"price":0.08,"size":0.0,"side":"SELL"}
{"ts":"2026-08-24T20:48:22.421Z","event_type":"best_bid_ask","market_id":"3825038","outcome_index":0,"market_type":"set1","local_side":"home","local_uid":"2026-08-24_greet_minnen_jeline_vandromme","bid":0.001,"ask":0.1,"mid":0.0505,"spread":0.099,"bid_size":null,"ask_size":null}
{"ts":"2026-08-24T20:48:22.422Z","event_type":"best_bid_ask","market_id":"3825038","outcome_index":1,"market_type":"set1","local_side":"away","local_uid":"2026-08-24_greet_minnen_jeline_vandromme","bid":0.9,"ask":0.999,"mid":0.9495,"spread":0.099,"bid_size":null,"ask_size":null}
{"ts":"2026-08-24T20:48:22.422Z","event_type":"price_change","market_id":"3825038","outcome_index":1,"market_type":"set1","local_side":"away","local_uid":"2026-08-24_greet_minnen_jeline_vandromme","bid":0.9,"ask":0.999,"mid":0.9495,"spread":0.099,"price":0.91,"size":0.0,"side":"BUY"}
{"ts":"2026-08-24T20:48:22.422Z","event_type":"price_change","market_id":"3825038","outcome_index":0,"market_type":"set1","local_side":"home","local_uid":"2026-08-24_greet_minnen_jeline_vandromme","bid":0.001,"ask":0.1,"mid":0.0505,"spread":0.099,"price":0.09,"size":0.0,"side":"SELL"}
{"ts":"2026-08-24T20:48:22.439Z","event_type":"best_bid_ask","market_id":"3825038","outcome_index":0,"market_type":"set1","local_side":"home","local_uid":"2026-08-24_greet_minnen_jeline_vandromme","bid":0.001,"ask":0.14,"mid":0.0705,"spread":0.139,"bid_size":null,"ask_size":null}
{"ts":"2026-08-24T20:48:22.439Z","event_type":"best_bid_ask","market_id":"3825038","outcome_index":1,"market_type":"set1","local_side":"away","local_uid":"2026-08-24_greet_minnen_jeline_vandromme","bid":0.86,"ask":0.999,"mid":0.9295,"spread":0.139,"bid_size":null,"ask_size":null}
{"ts":"2026-08-24T20:48:22.439Z","event_type":"price_change","market_id":"3825038","outcome_index":1,"market_type":"set1","local_side":"away","local_uid":"2026-08-24_greet_minnen_jeline_vandromme","bid":0.86,"ask":0.999,"mid":0.9295,"spread":0.139,"price":0.9,"size":0.0,"side":"BUY"}
{"ts":"2026-08-24T20:48:22.440Z","event_type":"price_change","market_id":"3825038","outcome_index":0,"market_type":"set1","local_side":"home","local_uid":"2026-08-24_greet_minnen_jeline_vandromme","bid":0.001,"ask":0.14,"mid":0.0705,"spread":0.139,"price":0.1,"size":0.0,"side":"SELL"}
{"ts":"2026-08-24T20:48:22.440Z","event_type":"best_bid_ask","market_id":"3825038","outcome_index":0,"market_type":"set1","local_side":"home","local_uid":"2026-08-24_greet_minnen_jeline_vandromme","bid":0.001,"ask":0.08,"mid":0.0405,"spread":0.079,"bid_size":null,"ask_size":null}
{"ts":"2026-08-24T20:48:22.440Z","event_type":"best_bid_ask","market_id":"3825038","outcome_index":1,"market_type":"set1","local_side":"away","local_uid":"2026-08-24_greet_minnen_jeline_vandromme","bid":0.92,"ask":0.999,"mid":0.9595,"spread":0.079,"bid_size":null,"ask_size":null}
{"ts":"2026-08-24T20:48:22.440Z","event_type":"price_change","market_id":"3825038","outcome_index":1,"market_type":"set1","local_side":"away","local_uid":"2026-08-24_greet_minnen_jeline_vandromme","bid":0.92,"ask":0.999,"mid":0.9595,"spread":0.079,"price":0.92,"size":52.0,"side":"BUY"}
{"ts":"2026-08-24T20:48:22.441Z","event_type":"price_change","market_id":"3825038","outcome_index":0,"market_type":"set1","local_side":"home","local_uid":"2026-08-24_greet_minnen_jeline_vandromme","bid":0.001,"ask":0.08,"mid":0.0405,"spread":0.079,"price":0.08,"size":52.0,"side":"SELL"}
{"ts":"2026-08-24T20:48:22.485Z","event_type":"best_bid_ask","market_id":"3825038","outcome_index":0,"market_type":"set1","local_side":"home","local_uid":"2026-08-24_greet_minnen_jeline_vandromme","bid":0.001,"ask":0.09,"mid":0.0455,"spread":0.089,"bid_size":null,"ask_size":null}
{"ts":"2026-08-24T20:48:22.485Z","event_type":"best_bid_ask","market_id":"3825038","outcome_index":1,"market_type":"set1","local_side":"away","local_uid":"2026-08-24_greet_minnen_jeline_vandromme","bid":0.91,"ask":0.999,"mid":0.9545,"spread":0.089,"bid_size":null,"ask_size":null}
{"ts":"2026-08-24T20:48:22.485Z","event_type":"price_change","market_id":"3825038","outcome_index":1,"market_type":"set1","local_side":"away","local_uid":"2026-08-24_greet_minnen_jeline_vandromme","bid":0.91,"ask":0.999,"mid":0.9545,"spread":0.089,"price":0.92,"size":0.0,"side":"BUY"}
{"ts":"2026-08-24T20:48:22.485Z","event_type":"price_change","market_id":"3825038","outcome_index":0,"market_type":"set1","local_side":"home","local_uid":"2026-08-24_greet_minnen_jeline_vandromme","bid":0.001,"ask":0.09,"mid":0.0455,"spread":0.089,"price":0.08,"size":0.0,"side":"SELL"}
{"ts":"2026-08-24T20:48:22.486Z","event_type":"best_bid_ask","market_id":"3826654","outcome_index":0,"market_type":"set2","local_side":"home","local_uid":"2026-08-24_sebastian_gorzny_cruz_hewitt","bid":0.05,"ask":0.13,"mid":0.09,"spread":0.08,"bid_size":null,"ask_size":null}
{"ts":"2026-08-24T20:48:22.487Z","event_type":"best_bid_ask","market_id":"3826654","outcome_index":1,"market_type":"set2","local_side":"away","local_uid":"2026-08-24_sebastian_gorzny_cruz_hewitt","bid":0.87,"ask":0.95,"mid":0.91,"spread":0.08,"bid_size":null,"ask_size":null}
{"ts":"2026-08-24T20:48:22.489Z","event_type":"price_change","market_id":"3826654","outcome_index":0,"market_type":"set2","local_side":"home","local_uid":"2026-08-24_sebastian_gorzny_cruz_hewitt","bid":0.05,"ask":0.13,"mid":0.09,"spread":0.08,"price":0.05,"size":13.0,"side":"BUY"}
{"ts":"2026-08-24T20:48:22.489Z","event_type":"price_change","market_id":"3826654","outcome_index":1,"market_type":"set2","local_side":"away","local_uid":"2026-08-24_sebastian_gorzny_cruz_hewitt","bid":0.87,"ask":0.95,"mid":0.91,"spread":0.08,"price":0.95,"size":13.0,"side":"SELL"}
{"ts":"2026-08-24T20:48:22.494Z","event_type":"best_bid_ask","market_id":"3826654","outcome_index":0,"market_type":"set2","local_side":"home","local_uid":"2026-08-24_sebastian_gorzny_cruz_hewitt","bid":0.06,"ask":0.13,"mid":0.095,"spread":0.07,"bid_size":null,"ask_size":null}
{"ts":"2026-08-24T20:48:22.494Z","event_type":"best_bid_ask","market_id":"3826654","outcome_index":1,"market_type":"set2","local_side":"away","local_uid":"2026-08-24_sebastian_gorzny_cruz_hewitt","bid":0.87,"ask":0.94,"mid":0.905,"spread":0.07,"bid_size":null,"ask_size":null}
{"ts":"2026-08-24T20:48:22.495Z","event_type":"price_change","market_id":"3826654","outcome_index":0,"market_type":"set2","local_side":"home","local_uid":"2026-08-24_sebastian_gorzny_cruz_hewitt","bid":0.06,"ask":0.13,"mid":0.095,"spread":0.07,"price":0.06,"size":22.0,"side":"BUY"}
{"ts":"2026-08-24T20:48:22.495Z","event_type":"price_change","market_id":"3826654","outcome_index":1,"market_type":"set2","local_side":"away","local_uid":"2026-08-24_sebastian_gorzny_cruz_hewitt","bid":0.87,"ask":0.94,"mid":0.905,"spread":0.07,"price":0.94,"size":22.0,"side":"SELL"}
{"ts":"2026-08-24T20:48:22.514Z","event_type":"best_bid_ask","market_id":"3825038","outcome_index":0,"market_type":"set1","local_side":"home","local_uid":"2026-08-24_greet_minnen_jeline_vandromme","bid":0.001,"ask":0.11,"mid":0.0555,"spread":0.109,"bid_size":null,"ask_size":null}
{"ts":"2026-08-24T20:48:22.515Z","event_type":"best_bid_ask","market_id":"3825038","outcome_index":1,"market_type":"set1","local_side":"away","local_uid":"2026-08-24_greet_minnen_jeline_vandromme","bid":0.89,"ask":0.999,"mid":0.9445,"spread":0.109,"bid_size":null,"ask_size":null}
{"ts":"2026-08-24T20:48:22.520Z","event_type":"price_change","market_id":"3825038","outcome_index":1,"market_type":"set1","local_side":"away","local_uid":"2026-08-24_greet_minnen_jeline_vandromme","bid":0.89,"ask":0.999,"mid":0.9445,"spread":0.109,"price":0.91,"size":0.0,"side":"BUY"}
{"ts":"2026-08-24T20:48:22.521Z","event_type":"price_change","market_id":"3825038","outcome_index":0,"market_type":"set1","local_side":"home","local_uid":"2026-08-24_greet_minnen_jeline_vandromme","bid":0.001,"ask":0.11,"mid":0.0555,"spread":0.109,"price":0.09,"size":0.0,"side":"SELL"}
{"ts":"2026-08-24T20:48:22.542Z","event_type":"best_bid_ask","market_id":"3825038","outcome_index":0,"market_type":"set1","local_side":"home","local_uid":"2026-08-24_greet_minnen_jeline_vandromme","bid":0.001,"ask":0.09,"mid":0.0455,"spread":0.089,"bid_size":null,"ask_size":null}
{"ts":"2026-08-24T20:48:22.542Z","event_type":"best_bid_ask","market_id":"3825038","outcome_index":1,"market_type":"set1","local_side":"away","local_uid":"2026-08-24_greet_minnen_jeline_vandromme","bid":0.91,"ask":0.999,"mid":0.9545,"spread":0.089,"bid_size":null,"ask_size":null}
{"ts":"2026-08-24T20:48:22.542Z","event_type":"price_change","market_id":"3825038","outcome_index":1,"market_type":"set1","local_side":"away","local_uid":"2026-08-24_greet_minnen_jeline_vandromme","bid":0.91,"ask":0.999,"mid":0.9545,"spread":0.089,"price":0.91,"size":88.0,"side":"BUY"}
{"ts":"2026-08-24T20:48:22.543Z","event_type":"price_change","market_id":"3825038","outcome_index":0,"market_type":"set1","local_side":"home","local_uid":"2026-08-24_greet_minnen_jeline_vandromme","bid":0.001,"ask":0.09,"mid":0.0455,"spread":0.089,"price":0.09,"size":88.0,"side":"SELL"}
{"ts":"2026-08-24T20:48:22.581Z","event_type":"best_bid_ask","market_id":"3825038","outcome_index":0,"market_type":"set1","local_side":"home","local_uid":"2026-08-24_greet_minnen_jeline_vandromme","bid":0.001,"ask":0.1,"mid":0.0505,"spread":0.099,"bid_size":null,"ask_size":null}
{"ts":"2026-08-24T20:48:22.581Z","event_type":"best_bid_ask","market_id":"3825038","outcome_index":1,"market_type":"set1","local_side":"away","local_uid":"2026-08-24_greet_minnen_jeline_vandromme","bid":0.9,"ask":0.999,"mid":0.9495,"spread":0.099,"bid_size":null,"ask_size":null}
{"ts":"2026-08-24T20:48:22.582Z","event_type":"price_change","market_id":"3825038","outcome_index":1,"market_type":"set1","local_side":"away","local_uid":"2026-08-24_greet_minnen_jeline_vandromme","bid":0.9,"ask":0.999,"mid":0.9495,"spread":0.099,"price":0.91,"size":0.0,"side":"BUY"}
{"ts":"2026-08-24T20:48:22.582Z","event_type":"price_change","market_id":"3825038","outcome_index":0,"market_type":"set1","local_side":"home","local_uid":"2026-08-24_greet_minnen_jeline_vandromme","bid":0.001,"ask":0.1,"mid":0.0505,"spread":0.099,"price":0.09,"size":0.0,"side":"SELL"}
{"ts":"2026-08-24T20:48:22.583Z","event_type":"best_bid_ask","market_id":"3825038","outcome_index":0,"market_type":"set1","local_side":"home","local_uid":"2026-08-24_greet_minnen_jeline_vandromme","bid":0.001,"ask":0.06,"mid":0.0305,"spread":0.059,"bid_size":null,"ask_size":null}
{"ts":"2026-08-24T20:48:22.583Z","event_type":"best_bid_ask","market_id":"3825038","outcome_index":1,"market_type":"set1","local_side":"away","local_uid":"2026-08-24_greet_minnen_jeline_vandromme","bid":0.94,"ask":0.999,"mid":0.9695,"spread":0.059,"bid_size":null,"ask_size":null}
{"ts":"2026-08-24T20:48:22.583Z","event_type":"price_change","market_id":"3825038","outcome_index":1,"market_type":"set1","local_side":"away","local_uid":"2026-08-24_greet_minnen_jeline_vandromme","bid":0.94,"ask":0.999,"mid":0.9695,"spread":0.059,"price":0.94,"size":44.0,"side":"BUY"}
{"ts":"2026-08-24T20:48:22.584Z","event_type":"price_change","market_id":"3825038","outcome_index":0,"market_type":"set1","local_side":"home","local_uid":"2026-08-24_greet_minnen_jeline_vandromme","bid":0.001,"ask":0.06,"mid":0.0305,"spread":0.059,"price":0.06,"size":44.0,"side":"SELL"}
{"ts":"2026-08-24T20:48:22.696Z","event_type":"best_bid_ask","market_id":"3825038","outcome_index":0,"market_type":"set1","local_side":"home","local_uid":"2026-08-24_greet_minnen_jeline_vandromme","bid":0.001,"ask":0.09,"mid":0.0455,"spread":0.089,"bid_size":null,"ask_size":null}
{"ts":"2026-08-24T20:48:22.696Z","event_type":"best_bid_ask","market_id":"3825038","outcome_index":1,"market_type":"set1","local_side":"away","local_uid":"2026-08-24_greet_minnen_jeline_vandromme","bid":0.91,"ask":0.999,"mid":0.9545,"spread":0.089,"bid_size":null,"ask_size":null}
{"ts":"2026-08-24T20:48:22.697Z","event_type":"price_change","market_id":"3825038","outcome_index":1,"market_type":"set1","local_side":"away","local_uid":"2026-08-24_greet_minnen_jeline_vandromme","bid":0.91,"ask":0.999,"mid":0.9545,"spread":0.089,"price":0.94,"size":0.0,"side":"BUY"}
{"ts":"2026-08-24T20:48:22.697Z","event_type":"price_change","market_id":"3825038","outcome_index":0,"market_type":"set1","local_side":"home","local_uid":"2026-08-24_greet_minnen_jeline_vandromme","bid":0.001,"ask":0.09,"mid":0.0455,"spread":0.089,"price":0.06,"size":0.0,"side":"SELL"}
{"ts":"2026-08-24T20:48:22.764Z","event_type":"price_change","market_id":"3825592","outcome_index":0,"market_type":"match","local_side":"home","local_uid":"2026-08-24_francesco_passaro_felix_gill","bid":0.54,"ask":0.55,"mid":0.545,"spread":0.01,"price":0.44,"size":6831.81,"side":"BUY"}
{"ts":"2026-08-24T20:48:22.764Z","event_type":"price_change","market_id":"3825592","outcome_index":1,"market_type":"match","local_side":"away","local_uid":"2026-08-24_francesco_passaro_felix_gill","bid":0.45,"ask":0.46,"mid":0.455,"spread":0.01,"price":0.56,"size":6831.81,"side":"SELL"}
{"ts":"2026-08-24T20:48:22.781Z","event_type":"best_bid_ask","market_id":"3825038","outcome_index":0,"market_type":"set1","local_side":"home","local_uid":"2026-08-24_greet_minnen_jeline_vandromme","bid":0.001,"ask":0.08,"mid":0.0405,"spread":0.079,"bid_size":null,"ask_size":null}
{"ts":"2026-08-24T20:48:22.781Z","event_type":"best_bid_ask","market_id":"3825038","outcome_index":1,"market_type":"set1","local_side":"away","local_uid":"2026-08-24_greet_minnen_jeline_vandromme","bid":0.92,"ask":0.999,"mid":0.9595,"spread":0.079,"bid_size":null,"ask_size":null}
{"ts":"2026-08-24T20:48:22.781Z","event_type":"price_change","market_id":"3825038","outcome_index":1,"market_type":"set1","local_side":"away","local_uid":"2026-08-24_greet_minnen_jeline_vandromme","bid":0.92,"ask":0.999,"mid":0.9595,"spread":0.079,"price":0.92,"size":44.0,"side":"BUY"}
{"ts":"2026-08-24T20:48:22.781Z","event_type":"price_change","market_id":"3825038","outcome_index":0,"market_type":"set1","local_side":"home","local_uid":"2026-08-24_greet_minnen_jeline_vandromme","bid":0.001,"ask":0.08,"mid":0.0405,"spread":0.079,"price":0.08,"size":44.0,"side":"SELL"}
{"ts":"2026-08-24T20:48:22.819Z","event_type":"book","market_id":"3823619","outcome_index":0,"market_type":"match","local_side":"home","local_uid":"2026-08-24_polina_kudermetova_linda_fruhvirtova","bid":0.56,"ask":0.57,"mid":0.565,"spread":0.01,"bid_size":50.0,"ask_size":24383.14}
{"ts":"2026-08-24T20:48:22.820Z","event_type":"book","market_id":"3823619","outcome_index":1,"market_type":"match","local_side":"away","local_uid":"2026-08-24_polina_kudermetova_linda_fruhvirtova","bid":0.43,"ask":0.44,"mid":0.435,"spread":0.01,"bid_size":24383.14,"ask_size":50.0}
{"ts":"2026-08-24T20:48:22.845Z","event_type":"best_bid_ask","market_id":"3825038","outcome_index":0,"market_type":"set1","local_side":"home","local_uid":"2026-08-24_greet_minnen_jeline_vandromme","bid":0.001,"ask":0.1,"mid":0.0505,"spread":0.099,"bid_size":null,"ask_size":null}
{"ts":"2026-08-24T20:48:22.846Z","event_type":"best_bid_ask","market_id":"3825038","outcome_index":1,"market_type":"set1","local_side":"away","local_uid":"2026-08-24_greet_minnen_jeline_vandromme","bid":0.9,"ask":0.999,"mid":0.9495,"spread":0.099,"bid_size":null,"ask_size":null}
{"ts":"2026-08-24T20:48:22.846Z","event_type":"price_change","market_id":"3825038","outcome_index":1,"market_type":"set1","local_side":"away","local_uid":"2026-08-24_greet_minnen_jeline_vandromme","bid":0.9,"ask":0.999,"mid":0.9495,"spread":0.099,"price":0.92,"size":0.0,"side":"BUY"}
{"ts":"2026-08-24T20:48:22.846Z","event_type":"price_change","market_id":"3825038","outcome_index":0,"market_type":"set1","local_side":"home","local_uid":"2026-08-24_greet_minnen_jeline_vandromme","bid":0.001,"ask":0.1,"mid":0.0505,"spread":0.099,"price":0.08,"size":0.0,"side":"SELL"}
{"ts":"2026-08-24T20:48:22.848Z","event_type":"best_bid_ask","market_id":"3825038","outcome_index":0,"market_type":"set1","local_side":"home","local_uid":"2026-08-24_greet_minnen_jeline_vandromme","bid":0.001,"ask":0.09,"mid":0.0455,"spread":0.089,"bid_size":null,"ask_size":null}
{"ts":"2026-08-24T20:48:22.848Z","event_type":"best_bid_ask","market_id":"3825038","outcome_index":1,"market_type":"set1","local_side":"away","local_uid":"2026-08-24_greet_minnen_jeline_vandromme","bid":0.91,"ask":0.999,"mid":0.9545,"spread":0.089,"bid_size":null,"ask_size":null}
{"ts":"2026-08-24T20:48:22.849Z","event_type":"price_change","market_id":"3825038","outcome_index":1,"market_type":"set1","local_side":"away","local_uid":"2026-08-24_greet_minnen_jeline_vandromme","bid":0.91,"ask":0.999,"mid":0.9545,"spread":0.089,"price":0.91,"size":88.0,"side":"BUY"}
{"ts":"2026-08-24T20:48:22.849Z","event_type":"price_change","market_id":"3825038","outcome_index":0,"market_type":"set1","local_side":"home","local_uid":"2026-08-24_greet_minnen_jeline_vandromme","bid":0.001,"ask":0.09,"mid":0.0455,"spread":0.089,"price":0.09,"size":88.0,"side":"SELL"}
{"ts":"2026-08-24T20:48:22.871Z","event_type":"best_bid_ask","market_id":"3825038","outcome_index":0,"market_type":"set1","local_side":"home","local_uid":"2026-08-24_greet_minnen_jeline_vandromme","bid":0.001,"ask":0.06,"mid":0.0305,"spread":0.059,"bid_size":null,"ask_size":null}
{"ts":"2026-08-24T20:48:22.871Z","event_type":"best_bid_ask","market_id":"3825038","outcome_index":1,"market_type":"set1","local_side":"away","local_uid":"2026-08-24_greet_minnen_jeline_vandromme","bid":0.94,"ask":0.999,"mid":0.9695,"spread":0.059,"bid_size":null,"ask_size":null}
{"ts":"2026-08-24T20:48:22.872Z","event_type":"price_change","market_id":"3825038","outcome_index":1,"market_type":"set1","local_side":"away","local_uid":"2026-08-24_greet_minnen_jeline_vandromme","bid":0.94,"ask":0.999,"mid":0.9695,"spread":0.059,"price":0.94,"size":50.0,"side":"BUY"}
{"ts":"2026-08-24T20:48:22.872Z","event_type":"price_change","market_id":"3825038","outcome_index":0,"market_type":"set1","local_side":"home","local_uid":"2026-08-24_greet_minnen_jeline_vandromme","bid":0.001,"ask":0.06,"mid":0.0305,"spread":0.059,"price":0.06,"size":50.0,"side":"SELL"}
{"ts":"2026-08-24T20:48:22.895Z","event_type":"best_bid_ask","market_id":"3825051","outcome_index":0,"market_type":"set2","local_side":"home","local_uid":"2026-08-24_robin_montgomery_kayla_cross","bid":0.71,"ask":0.79,"mid":0.75,"spread":0.08,"bid_size":null,"ask_size":null}
{"ts":"2026-08-24T20:48:22.895Z","event_type":"best_bid_ask","market_id":"3825051","outcome_index":1,"market_type":"set2","local_side":"away","local_uid":"2026-08-24_robin_montgomery_kayla_cross","bid":0.21,"ask":0.29,"mid":0.25,"spread":0.08,"bid_size":null,"ask_size":null}
{"ts":"2026-08-24T20:48:22.896Z","event_type":"price_change","market_id":"3825051","outcome_index":1,"market_type":"set2","local_side":"away","local_uid":"2026-08-24_robin_montgomery_kayla_cross","bid":0.21,"ask":0.29,"mid":0.25,"spread":0.08,"price":0.22,"size":0.0,"side":"BUY"}
{"ts":"2026-08-24T20:48:22.896Z","event_type":"price_change","market_id":"3825051","outcome_index":0,"market_type":"set2","local_side":"home","local_uid":"2026-08-24_robin_montgomery_kayla_cross","bid":0.71,"ask":0.79,"mid":0.75,"spread":0.08,"price":0.78,"size":0.0,"side":"SELL"}
{"ts":"2026-08-24T20:48:22.942Z","event_type":"last_trade_price","market_id":"3823619","outcome_index":0,"market_type":"match","local_side":"home","local_uid":"2026-08-24_polina_kudermetova_linda_fruhvirtova","last_trade":0.57,"trade_size":2.5614,"trade_side":"BUY","trade_notional":1.46}
{"ts":"2026-08-24T20:48:22.942Z","event_type":"best_bid_ask","market_id":"3825051","outcome_index":0,"market_type":"set2","local_side":"home","local_uid":"2026-08-24_robin_montgomery_kayla_cross","bid":0.71,"ask":0.78,"mid":0.745,"spread":0.07,"bid_size":null,"ask_size":null}
{"ts":"2026-08-24T20:48:22.942Z","event_type":"best_bid_ask","market_id":"3825051","outcome_index":1,"market_type":"set2","local_side":"away","local_uid":"2026-08-24_robin_montgomery_kayla_cross","bid":0.22,"ask":0.29,"mid":0.255,"spread":0.07,"bid_size":null,"ask_size":null}
{"ts":"2026-08-24T20:48:22.943Z","event_type":"price_change","market_id":"3825051","outcome_index":1,"market_type":"set2","local_side":"away","local_uid":"2026-08-24_robin_montgomery_kayla_cross","bid":0.22,"ask":0.29,"mid":0.255,"spread":0.07,"price":0.22,"size":406.0,"side":"BUY"}
{"ts":"2026-08-24T20:48:22.943Z","event_type":"price_change","market_id":"3825051","outcome_index":0,"market_type":"set2","local_side":"home","local_uid":"2026-08-24_robin_montgomery_kayla_cross","bid":0.71,"ask":0.78,"mid":0.745,"spread":0.07,"price":0.78,"size":406.0,"side":"SELL"}
{"ts":"2026-08-24T20:48:22.967Z","event_type":"best_bid_ask","market_id":"3825038","outcome_index":0,"market_type":"set1","local_side":"home","local_uid":"2026-08-24_greet_minnen_jeline_vandromme","bid":0.001,"ask":0.09,"mid":0.0455,"spread":0.089,"bid_size":null,"ask_size":null}
{"ts":"2026-08-24T20:48:22.971Z","event_type":"best_bid_ask","market_id":"3825038","outcome_index":1,"market_type":"set1","local_side":"away","local_uid":"2026-08-24_greet_minnen_jeline_vandromme","bid":0.91,"ask":0.999,"mid":0.9545,"spread":0.089,"bid_size":null,"ask_size":null}
{"ts":"2026-08-24T20:48:22.972Z","event_type":"price_change","market_id":"3825038","outcome_index":1,"market_type":"set1","local_side":"away","local_uid":"2026-08-24_greet_minnen_jeline_vandromme","bid":0.91,"ask":0.999,"mid":0.9545,"spread":0.089,"price":0.94,"size":0.0,"side":"BUY"}
{"ts":"2026-08-24T20:48:22.972Z","event_type":"price_change","market_id":"3825038","outcome_index":0,"market_type":"set1","local_side":"home","local_uid":"2026-08-24_greet_minnen_jeline_vandromme","bid":0.001,"ask":0.09,"mid":0.0455,"spread":0.089,"price":0.06,"size":0.0,"side":"SELL"}
{"ts":"2026-08-24T20:48:23.043Z","event_type":"best_bid_ask","market_id":"3825038","outcome_index":0,"market_type":"set1","local_side":"home","local_uid":"2026-08-24_greet_minnen_jeline_vandromme","bid":0.001,"ask":0.08,"mid":0.0405,"spread":0.079,"bid_size":null,"ask_size":null}
{"ts":"2026-08-24T20:48:23.043Z","event_type":"best_bid_ask","market_id":"3825038","outcome_index":1,"market_type":"set1","local_side":"away","local_uid":"2026-08-24_greet_minnen_jeline_vandromme","bid":0.92,"ask":0.999,"mid":0.9595,"spread":0.079,"bid_size":null,"ask_size":null}
{"ts":"2026-08-24T20:48:23.044Z","event_type":"price_change","market_id":"3825038","outcome_index":1,"market_type":"set1","local_side":"away","local_uid":"2026-08-24_greet_minnen_jeline_vandromme","bid":0.92,"ask":0.999,"mid":0.9595,"spread":0.079,"price":0.92,"size":44.0,"side":"BUY"}
{"ts":"2026-08-24T20:48:23.044Z","event_type":"price_change","market_id":"3825038","outcome_index":0,"market_type":"set1","local_side":"home","local_uid":"2026-08-24_greet_minnen_jeline_vandromme","bid":0.001,"ask":0.08,"mid":0.0405,"spread":0.079,"price":0.08,"size":44.0,"side":"SELL"}
{"ts":"2026-08-24T20:48:23.064Z","event_type":"price_change","market_id":"3823655","outcome_index":0,"market_type":"match","local_side":"home","local_uid":"2026-08-24_laura_pigossi_despina_papamichail","bid":0.77,"ask":0.78,"mid":0.775,"spread":0.01,"price":0.47,"size":0.0,"side":"BUY"}
{"ts":"2026-08-24T20:48:23.064Z","event_type":"price_change","market_id":"3823655","outcome_index":1,"market_type":"match","local_side":"away","local_uid":"2026-08-24_laura_pigossi_despina_papamichail","bid":0.22,"ask":0.23,"mid":0.225,"spread":0.01,"price":0.53,"size":0.0,"side":"SELL"}
{"ts":"2026-08-24T20:48:23.095Z","event_type":"best_bid_ask","market_id":"3825038","outcome_index":0,"market_type":"set1","local_side":"home","local_uid":"2026-08-24_greet_minnen_jeline_vandromme","bid":0.001,"ask":0.09,"mid":0.0455,"spread":0.089,"bid_size":null,"ask_size":null}
{"ts":"2026-08-24T20:48:23.095Z","event_type":"best_bid_ask","market_id":"3825038","outcome_index":1,"market_type":"set1","local_side":"away","local_uid":"2026-08-24_greet_minnen_jeline_vandromme","bid":0.91,"ask":0.999,"mid":0.9545,"spread":0.089,"bid_size":null,"ask_size":null}
{"ts":"2026-08-24T20:48:23.096Z","event_type":"price_change","market_id":"3825038","outcome_index":1,"market_type":"set1","local_side":"away","local_uid":"2026-08-24_greet_minnen_jeline_vandromme","bid":0.91,"ask":0.999,"mid":0.9545,"spread":0.089,"price":0.92,"size":0.0,"side":"BUY"}
{"ts":"2026-08-24T20:48:23.096Z","event_type":"price_change","market_id":"3825038","outcome_index":0,"market_type":"set1","local_side":"home","local_uid":"2026-08-24_greet_minnen_jeline_vandromme","bid":0.001,"ask":0.09,"mid":0.0455,"spread":0.089,"price":0.08,"size":0.0,"side":"SELL"}
{"ts":"2026-08-24T20:48:23.146Z","event_type":"price_change","market_id":"3825631","outcome_index":0,"market_type":"match","local_side":"home","local_uid":"2026-08-24_harry_wendelken_stefano_travaglia","bid":0.64,"ask":0.65,"mid":0.645,"spread":0.01,"price":0.62,"size":7965.1,"side":"BUY"}
{"ts":"2026-08-24T20:48:23.146Z","event_type":"price_change","market_id":"3825631","outcome_index":1,"market_type":"match","local_side":"away","local_uid":"2026-08-24_harry_wendelken_stefano_travaglia","bid":0.35,"ask":0.36,"mid":0.355,"spread":0.01,"price":0.38,"size":7965.1,"side":"SELL"}
{"ts":"2026-08-24T20:48:23.147Z","event_type":"best_bid_ask","market_id":"3826654","outcome_index":0,"market_type":"set2","local_side":"home","local_uid":"2026-08-24_sebastian_gorzny_cruz_hewitt","bid":0.04,"ask":0.13,"mid":0.085,"spread":0.09,"bid_size":null,"ask_size":null}
{"ts":"2026-08-24T20:48:23.147Z","event_type":"best_bid_ask","market_id":"3826654","outcome_index":1,"market_type":"set2","local_side":"away","local_uid":"2026-08-24_sebastian_gorzny_cruz_hewitt","bid":0.87,"ask":0.96,"mid":0.915,"spread":0.09,"bid_size":null,"ask_size":null}
{"ts":"2026-08-24T20:48:23.148Z","event_type":"price_change","market_id":"3826654","outcome_index":0,"market_type":"set2","local_side":"home","local_uid":"2026-08-24_sebastian_gorzny_cruz_hewitt","bid":0.04,"ask":0.13,"mid":0.085,"spread":0.09,"price":0.06,"size":0.0,"side":"BUY"}
{"ts":"2026-08-24T20:48:23.148Z","event_type":"price_change","market_id":"3826654","outcome_index":1,"market_type":"set2","local_side":"away","local_uid":"2026-08-24_sebastian_gorzny_cruz_hewitt","bid":0.87,"ask":0.96,"mid":0.915,"spread":0.09,"price":0.94,"size":0.0,"side":"SELL"}
{"ts":"2026-08-24T20:48:23.224Z","event_type":"best_bid_ask","market_id":"3823625","outcome_index":0,"market_type":"match","local_side":"home","local_uid":"2026-08-24_greet_minnen_jeline_vandromme","bid":0.15,"ask":0.18,"mid":0.165,"spread":0.03,"bid_size":null,"ask_size":null}
{"ts":"2026-08-24T20:48:23.224Z","event_type":"best_bid_ask","market_id":"3823625","outcome_index":1,"market_type":"match","local_side":"away","local_uid":"2026-08-24_greet_minnen_jeline_vandromme","bid":0.82,"ask":0.85,"mid":0.835,"spread":0.03,"bid_size":null,"ask_size":null}
{"ts":"2026-08-24T20:48:23.224Z","event_type":"price_change","market_id":"3823625","outcome_index":1,"market_type":"match","local_side":"away","local_uid":"2026-08-24_greet_minnen_jeline_vandromme","bid":0.82,"ask":0.85,"mid":0.835,"spread":0.03,"price":0.82,"size":22.0,"side":"BUY"}
{"ts":"2026-08-24T20:48:23.225Z","event_type":"price_change","market_id":"3823625","outcome_index":0,"market_type":"match","local_side":"home","local_uid":"2026-08-24_greet_minnen_jeline_vandromme","bid":0.15,"ask":0.18,"mid":0.165,"spread":0.03,"price":0.18,"size":22.0,"side":"SELL"}
{"ts":"2026-08-24T20:48:23.229Z","event_type":"best_bid_ask","market_id":"3825038","outcome_index":0,"market_type":"set1","local_side":"home","local_uid":"2026-08-24_greet_minnen_jeline_vandromme","bid":0.001,"ask":0.08,"mid":0.0405,"spread":0.079,"bid_size":null,"ask_size":null}
{"ts":"2026-08-24T20:48:23.230Z","event_type":"best_bid_ask","market_id":"3825038","outcome_index":1,"market_type":"set1","local_side":"away","local_uid":"2026-08-24_greet_minnen_jeline_vandromme","bid":0.92,"ask":0.999,"mid":0.9595,"spread":0.079,"bid_size":null,"ask_size":null}
{"ts":"2026-08-24T20:48:23.230Z","event_type":"price_change","market_id":"3825038","outcome_index":1,"market_type":"set1","local_side":"away","local_uid":"2026-08-24_greet_minnen_jeline_vandromme","bid":0.92,"ask":0.999,"mid":0.9595,"spread":0.079,"price":0.92,"size":44.0,"side":"BUY"}
{"ts":"2026-08-24T20:48:23.230Z","event_type":"price_change","market_id":"3825038","outcome_index":0,"market_type":"set1","local_side":"home","local_uid":"2026-08-24_greet_minnen_jeline_vandromme","bid":0.001,"ask":0.08,"mid":0.0405,"spread":0.079,"price":0.08,"size":44.0,"side":"SELL"}
{"ts":"2026-08-24T20:48:23.295Z","event_type":"best_bid_ask","market_id":"3825038","outcome_index":0,"market_type":"set1","local_side":"home","local_uid":"2026-08-24_greet_minnen_jeline_vandromme","bid":0.001,"ask":0.09,"mid":0.0455,"spread":0.089,"bid_size":null,"ask_size":null}
{"ts":"2026-08-24T20:48:23.295Z","event_type":"best_bid_ask","market_id":"3825038","outcome_index":1,"market_type":"set1","local_side":"away","local_uid":"2026-08-24_greet_minnen_jeline_vandromme","bid":0.91,"ask":0.999,"mid":0.9545,"spread":0.089,"bid_size":null,"ask_size":null}
{"ts":"2026-08-24T20:48:23.296Z","event_type":"price_change","market_id":"3825038","outcome_index":1,"market_type":"set1","local_side":"away","local_uid":"2026-08-24_greet_minnen_jeline_vandromme","bid":0.91,"ask":0.999,"mid":0.9545,"spread":0.089,"price":0.92,"size":0.0,"side":"BUY"}
{"ts":"2026-08-24T20:48:23.296Z","event_type":"price_change","market_id":"3825038","outcome_index":0,"market_type":"set1","local_side":"home","local_uid":"2026-08-24_greet_minnen_jeline_vandromme","bid":0.001,"ask":0.09,"mid":0.0455,"spread":0.089,"price":0.08,"size":0.0,"side":"SELL"}
{"ts":"2026-08-24T20:48:23.348Z","event_type":"best_bid_ask","market_id":"3823625","outcome_index":0,"market_type":"match","local_side":"home","local_uid":"2026-08-24_greet_minnen_jeline_vandromme","bid":0.15,"ask":0.17,"mid":0.16,"spread":0.02,"bid_size":null,"ask_size":null}
{"ts":"2026-08-24T20:48:23.348Z","event_type":"best_bid_ask","market_id":"3823625","outcome_index":1,"market_type":"match","local_side":"away","local_uid":"2026-08-24_greet_minnen_jeline_vandromme","bid":0.83,"ask":0.85,"mid":0.84,"spread":0.02,"bid_size":null,"ask_size":null}
{"ts":"2026-08-24T20:48:23.349Z","event_type":"price_change","market_id":"3823625","outcome_index":1,"market_type":"match","local_side":"away","local_uid":"2026-08-24_greet_minnen_jeline_vandromme","bid":0.83,"ask":0.85,"mid":0.84,"spread":0.02,"price":0.83,"size":25.0,"side":"BUY"}
{"ts":"2026-08-24T20:48:23.349Z","event_type":"price_change","market_id":"3823625","outcome_index":0,"market_type":"match","local_side":"home","local_uid":"2026-08-24_greet_minnen_jeline_vandromme","bid":0.15,"ask":0.17,"mid":0.16,"spread":0.02,"price":0.17,"size":25.0,"side":"SELL"}
{"ts":"2026-08-24T20:48:23.443Z","event_type":"price_change","market_id":"3827165","outcome_index":0,"market_type":"set2","local_side":"home","local_uid":"2026-08-24_jenson_brooksby_stefanos_tsitsipas","bid":0.39,"ask":0.48,"mid":0.435,"spread":0.09,"price":0.39,"size":2423.0,"side":"BUY"}
{"ts":"2026-08-24T20:48:23.443Z","event_type":"price_change","market_id":"3827165","outcome_index":1,"market_type":"set2","local_side":"away","local_uid":"2026-08-24_jenson_brooksby_stefanos_tsitsipas","bid":0.52,"ask":0.61,"mid":0.565,"spread":0.09,"price":0.61,"size":2423.0,"side":"SELL"}
{"ts":"2026-08-24T20:48:23.503Z","event_type":"best_bid_ask","market_id":"3825038","outcome_index":0,"market_type":"set1","local_side":"home","local_uid":"2026-08-24_greet_minnen_jeline_vandromme","bid":0.001,"ask":0.08,"mid":0.0405,"spread":0.079,"bid_size":null,"ask_size":null}
{"ts":"2026-08-24T20:48:23.503Z","event_type":"best_bid_ask","market_id":"3825038","outcome_index":1,"market_type":"set1","local_side":"away","local_uid":"2026-08-24_greet_minnen_jeline_vandromme","bid":0.92,"ask":0.999,"mid":0.9595,"spread":0.079,"bid_size":null,"ask_size":null}
{"ts":"2026-08-24T20:48:23.504Z","event_type":"price_change","market_id":"3825038","outcome_index":1,"market_type":"set1","local_side":"away","local_uid":"2026-08-24_greet_minnen_jeline_vandromme","bid":0.92,"ask":0.999,"mid":0.9595,"spread":0.079,"price":0.92,"size":44.0,"side":"BUY"}
{"ts":"2026-08-24T20:48:23.504Z","event_type":"price_change","market_id":"3825038","outcome_index":0,"market_type":"set1","local_side":"home","local_uid":"2026-08-24_greet_minnen_jeline_vandromme","bid":0.001,"ask":0.08,"mid":0.0405,"spread":0.079,"price":0.08,"size":44.0,"side":"SELL"}
{"ts":"2026-08-24T20:48:23.542Z","event_type":"best_bid_ask","market_id":"3825038","outcome_index":0,"market_type":"set1","local_side":"home","local_uid":"2026-08-24_greet_minnen_jeline_vandromme","bid":0.001,"ask":0.09,"mid":0.0455,"spread":0.089,"bid_size":null,"ask_size":null}
{"ts":"2026-08-24T20:48:23.542Z","event_type":"best_bid_ask","market_id":"3825038","outcome_index":1,"market_type":"set1","local_side":"away","local_uid":"2026-08-24_greet_minnen_jeline_vandromme","bid":0.91,"ask":0.999,"mid":0.9545,"spread":0.089,"bid_size":null,"ask_size":null}
{"ts":"2026-08-24T20:48:23.542Z","event_type":"price_change","market_id":"3825038","outcome_index":1,"market_type":"set1","local_side":"away","local_uid":"2026-08-24_greet_minnen_jeline_vandromme","bid":0.91,"ask":0.999,"mid":0.9545,"spread":0.089,"price":0.92,"size":0.0,"side":"BUY"}
{"ts":"2026-08-24T20:48:23.543Z","event_type":"price_change","market_id":"3825038","outcome_index":0,"market_type":"set1","local_side":"home","local_uid":"2026-08-24_greet_minnen_jeline_vandromme","bid":0.001,"ask":0.09,"mid":0.0455,"spread":0.089,"price":0.08,"size":0.0,"side":"SELL"}
{"ts":"2026-08-24T20:48:23.552Z","event_type":"price_change","market_id":"3826975","outcome_index":1,"market_type":"set2","local_side":"away","local_uid":"2026-08-24_gonzalo_bueno_billy_harris","bid":0.999,"ask":1.0,"mid":0.9995,"spread":0.001,"price":0.013,"size":10560.0,"side":"BUY"}
{"ts":"2026-08-24T20:48:23.552Z","event_type":"price_change","market_id":"3826975","outcome_index":0,"market_type":"set2","local_side":"home","local_uid":"2026-08-24_gonzalo_bueno_billy_harris","bid":0.0,"ask":0.001,"mid":0.0005,"spread":0.001,"price":0.987,"size":10560.0,"side":"SELL"}
{"ts":"2026-08-24T20:48:23.593Z","event_type":"price_change","market_id":"3824767","outcome_index":0,"market_type":"set1","local_side":"home","local_uid":"2026-08-24_savannah_broadus_tyra_caterina_grant","bid":0.37,"ask":0.41,"mid":0.39,"spread":0.04,"price":0.35,"size":9274.13,"side":"BUY"}
{"ts":"2026-08-24T20:48:23.593Z","event_type":"price_change","market_id":"3824767","outcome_index":1,"market_type":"set1","local_side":"away","local_uid":"2026-08-24_savannah_broadus_tyra_caterina_grant","bid":0.59,"ask":0.63,"mid":0.61,"spread":0.04,"price":0.65,"size":9274.13,"side":"SELL"}
{"ts":"2026-08-24T20:48:23.595Z","event_type":"best_bid_ask","market_id":"3826919","outcome_index":0,"market_type":"set2","local_side":"home","local_uid":"2026-08-24_dalibor_svrcina_felipe_meligeni_alves","bid":0.43,"ask":0.52,"mid":0.475,"spread":0.09,"bid_size":null,"ask_size":null}
{"ts":"2026-08-24T20:48:23.595Z","event_type":"best_bid_ask","market_id":"3826919","outcome_index":1,"market_type":"set2","local_side":"away","local_uid":"2026-08-24_dalibor_svrcina_felipe_meligeni_alves","bid":0.48,"ask":0.57,"mid":0.525,"spread":0.09,"bid_size":null,"ask_size":null}
{"ts":"2026-08-24T20:48:23.595Z","event_type":"price_change","market_id":"3826919","outcome_index":0,"market_type":"set2","local_side":"home","local_uid":"2026-08-24_dalibor_svrcina_felipe_meligeni_alves","bid":0.43,"ask":0.52,"mid":0.475,"spread":0.09,"price":0.44,"size":0.0,"side":"BUY"}
{"ts":"2026-08-24T20:48:23.596Z","event_type":"price_change","market_id":"3826919","outcome_index":1,"market_type":"set2","local_side":"away","local_uid":"2026-08-24_dalibor_svrcina_felipe_meligeni_alves","bid":0.48,"ask":0.57,"mid":0.525,"spread":0.09,"price":0.56,"size":0.0,"side":"SELL"}
{"ts":"2026-08-24T20:48:23.610Z","event_type":"best_bid_ask","market_id":"3826919","outcome_index":0,"market_type":"set2","local_side":"home","local_uid":"2026-08-24_dalibor_svrcina_felipe_meligeni_alves","bid":0.42,"ask":0.52,"mid":0.47,"spread":0.1,"bid_size":null,"ask_size":null}
{"ts":"2026-08-24T20:48:23.610Z","event_type":"best_bid_ask","market_id":"3826919","outcome_index":1,"market_type":"set2","local_side":"away","local_uid":"2026-08-24_dalibor_svrcina_felipe_meligeni_alves","bid":0.48,"ask":0.58,"mid":0.53,"spread":0.1,"bid_size":null,"ask_size":null}
{"ts":"2026-08-24T20:48:23.611Z","event_type":"price_change","market_id":"3826919","outcome_index":0,"market_type":"set2","local_side":"home","local_uid":"2026-08-24_dalibor_svrcina_felipe_meligeni_alves","bid":0.42,"ask":0.52,"mid":0.47,"spread":0.1,"price":0.43,"size":0.0,"side":"BUY"}
{"ts":"2026-08-24T20:48:23.611Z","event_type":"price_change","market_id":"3826919","outcome_index":1,"market_type":"set2","local_side":"away","local_uid":"2026-08-24_dalibor_svrcina_felipe_meligeni_alves","bid":0.48,"ask":0.58,"mid":0.53,"spread":0.1,"price":0.57,"size":0.0,"side":"SELL"}
{"ts":"2026-08-24T20:48:23.617Z","event_type":"best_bid_ask","market_id":"3826919","outcome_index":0,"market_type":"set2","local_side":"home","local_uid":"2026-08-24_dalibor_svrcina_felipe_meligeni_alves","bid":0.43,"ask":0.52,"mid":0.475,"spread":0.09,"bid_size":null,"ask_size":null}
{"ts":"2026-08-24T20:48:23.617Z","event_type":"best_bid_ask","market_id":"3826919","outcome_index":1,"market_type":"set2","local_side":"away","local_uid":"2026-08-24_dalibor_svrcina_felipe_meligeni_alves","bid":0.48,"ask":0.57,"mid":0.525,"spread":0.09,"bid_size":null,"ask_size":null}
{"ts":"2026-08-24T20:48:23.617Z","event_type":"price_change","market_id":"3826919","outcome_index":0,"market_type":"set2","local_side":"home","local_uid":"2026-08-24_dalibor_svrcina_felipe_meligeni_alves","bid":0.43,"ask":0.52,"mid":0.475,"spread":0.09,"price":0.43,"size":1126.0,"side":"BUY"}
{"ts":"2026-08-24T20:48:23.618Z","event_type":"price_change","market_id":"3826919","outcome_index":1,"market_type":"set2","local_side":"away","local_uid":"2026-08-24_dalibor_svrcina_felipe_meligeni_alves","bid":0.48,"ask":0.57,"mid":0.525,"spread":0.09,"price":0.57,"size":1126.0,"side":"SELL"}
{"ts":"2026-08-24T20:48:23.657Z","event_type":"best_bid_ask","market_id":"3825051","outcome_index":0,"market_type":"set2","local_side":"home","local_uid":"2026-08-24_robin_montgomery_kayla_cross","bid":0.71,"ask":0.79,"mid":0.75,"spread":0.08,"bid_size":null,"ask_size":null}
{"ts":"2026-08-24T20:48:23.659Z","event_type":"best_bid_ask","market_id":"3825051","outcome_index":1,"market_type":"set2","local_side":"away","local_uid":"2026-08-24_robin_montgomery_kayla_cross","bid":0.21,"ask":0.29,"mid":0.25,"spread":0.08,"bid_size":null,"ask_size":null}
{"ts":"2026-08-24T20:48:23.659Z","event_type":"price_change","market_id":"3825051","outcome_index":1,"market_type":"set2","local_side":"away","local_uid":"2026-08-24_robin_montgomery_kayla_cross","bid":0.21,"ask":0.29,"mid":0.25,"spread":0.08,"price":0.22,"size":0.0,"side":"BUY"}
{"ts":"2026-08-24T20:48:23.659Z","event_type":"price_change","market_id":"3825051","outcome_index":0,"market_type":"set2","local_side":"home","local_uid":"2026-08-24_robin_montgomery_kayla_cross","bid":0.71,"ask":0.79,"mid":0.75,"spread":0.08,"price":0.78,"size":0.0,"side":"SELL"}
{"ts":"2026-08-24T20:48:23.693Z","event_type":"price_change","market_id":"3826161","outcome_index":1,"market_type":"set2","local_side":"away","local_uid":"2026-08-24_daniel_altmaier_francisco_comesana","bid":0.49,"ask":0.52,"mid":0.505,"spread":0.03,"price":0.46,"size":3402.24,"side":"BUY"}
{"ts":"2026-08-24T20:48:23.693Z","event_type":"price_change","market_id":"3826161","outcome_index":0,"market_type":"set2","local_side":"home","local_uid":"2026-08-24_daniel_altmaier_francisco_comesana","bid":0.48,"ask":0.51,"mid":0.495,"spread":0.03,"price":0.54,"size":3402.24,"side":"SELL"}
{"ts":"2026-08-24T20:48:23.801Z","event_type":"best_bid_ask","market_id":"3826654","outcome_index":0,"market_type":"set2","local_side":"home","local_uid":"2026-08-24_sebastian_gorzny_cruz_hewitt","bid":0.06,"ask":0.13,"mid":0.095,"spread":0.07,"bid_size":null,"ask_size":null}
{"ts":"2026-08-24T20:48:23.802Z","event_type":"best_bid_ask","market_id":"3826654","outcome_index":1,"market_type":"set2","local_side":"away","local_uid":"2026-08-24_sebastian_gorzny_cruz_hewitt","bid":0.87,"ask":0.94,"mid":0.905,"spread":0.07,"bid_size":null,"ask_size":null}
{"ts":"2026-08-24T20:48:23.802Z","event_type":"price_change","market_id":"3826654","outcome_index":0,"market_type":"set2","local_side":"home","local_uid":"2026-08-24_sebastian_gorzny_cruz_hewitt","bid":0.06,"ask":0.13,"mid":0.095,"spread":0.07,"price":0.06,"size":22.0,"side":"BUY"}
{"ts":"2026-08-24T20:48:23.802Z","event_type":"price_change","market_id":"3826654","outcome_index":1,"market_type":"set2","local_side":"away","local_uid":"2026-08-24_sebastian_gorzny_cruz_hewitt","bid":0.87,"ask":0.94,"mid":0.905,"spread":0.07,"price":0.94,"size":22.0,"side":"SELL"}
{"ts":"2026-08-24T20:48:23.906Z","event_type":"best_bid_ask","market_id":"3825038","outcome_index":0,"market_type":"set1","local_side":"home","local_uid":"2026-08-24_greet_minnen_jeline_vandromme","bid":0.001,"ask":0.1,"mid":0.0505,"spread":0.099,"bid_size":null,"ask_size":null}
{"ts":"2026-08-24T20:48:23.907Z","event_type":"best_bid_ask","market_id":"3825038","outcome_index":1,"market_type":"set1","local_side":"away","local_uid":"2026-08-24_greet_minnen_jeline_vandromme","bid":0.9,"ask":0.999,"mid":0.9495,"spread":0.099,"bid_size":null,"ask_size":null}
{"ts":"2026-08-24T20:48:23.907Z","event_type":"price_change","market_id":"3825038","outcome_index":1,"market_type":"set1","local_side":"away","local_uid":"2026-08-24_greet_minnen_jeline_vandromme","bid":0.9,"ask":0.999,"mid":0.9495,"spread":0.099,"price":0.91,"size":0.0,"side":"BUY"}
{"ts":"2026-08-24T20:48:23.908Z","event_type":"price_change","market_id":"3825038","outcome_index":0,"market_type":"set1","local_side":"home","local_uid":"2026-08-24_greet_minnen_jeline_vandromme","bid":0.001,"ask":0.1,"mid":0.0505,"spread":0.099,"price":0.09,"size":0.0,"side":"SELL"}
{"ts":"2026-08-24T20:48:23.908Z","event_type":"best_bid_ask","market_id":"3825038","outcome_index":0,"market_type":"set1","local_side":"home","local_uid":"2026-08-24_greet_minnen_jeline_vandromme","bid":0.001,"ask":0.08,"mid":0.0405,"spread":0.079,"bid_size":null,"ask_size":null}
{"ts":"2026-08-24T20:48:23.908Z","event_type":"best_bid_ask","market_id":"3825038","outcome_index":1,"market_type":"set1","local_side":"away","local_uid":"2026-08-24_greet_minnen_jeline_vandromme","bid":0.92,"ask":0.999,"mid":0.9595,"spread":0.079,"bid_size":null,"ask_size":null}
{"ts":"2026-08-24T20:48:23.909Z","event_type":"price_change","market_id":"3825038","outcome_index":1,"market_type":"set1","local_side":"away","local_uid":"2026-08-24_greet_minnen_jeline_vandromme","bid":0.92,"ask":0.999,"mid":0.9595,"spread":0.079,"price":0.92,"size":44.0,"side":"BUY"}
{"ts":"2026-08-24T20:48:23.909Z","event_type":"price_change","market_id":"3825038","outcome_index":0,"market_type":"set1","local_side":"home","local_uid":"2026-08-24_greet_minnen_jeline_vandromme","bid":0.001,"ask":0.08,"mid":0.0405,"spread":0.079,"price":0.08,"size":44.0,"side":"SELL"}
{"ts":"2026-08-24T20:48:23.948Z","event_type":"best_bid_ask","market_id":"3825038","outcome_index":0,"market_type":"set1","local_side":"home","local_uid":"2026-08-24_greet_minnen_jeline_vandromme","bid":0.001,"ask":0.09,"mid":0.0455,"spread":0.089,"bid_size":null,"ask_size":null}
{"ts":"2026-08-24T20:48:23.949Z","event_type":"best_bid_ask","market_id":"3825038","outcome_index":1,"market_type":"set1","local_side":"away","local_uid":"2026-08-24_greet_minnen_jeline_vandromme","bid":0.91,"ask":0.999,"mid":0.9545,"spread":0.089,"bid_size":null,"ask_size":null}
{"ts":"2026-08-24T20:48:23.949Z","event_type":"price_change","market_id":"3825038","outcome_index":1,"market_type":"set1","local_side":"away","local_uid":"2026-08-24_greet_minnen_jeline_vandromme","bid":0.91,"ask":0.999,"mid":0.9545,"spread":0.089,"price":0.92,"size":0.0,"side":"BUY"}
{"ts":"2026-08-24T20:48:23.949Z","event_type":"price_change","market_id":"3825038","outcome_index":0,"market_type":"set1","local_side":"home","local_uid":"2026-08-24_greet_minnen_jeline_vandromme","bid":0.001,"ask":0.09,"mid":0.0455,"spread":0.089,"price":0.08,"size":0.0,"side":"SELL"}
{"ts":"2026-08-24T20:48:24.036Z","event_type":"best_bid_ask","market_id":"3825038","outcome_index":0,"market_type":"set1","local_side":"home","local_uid":"2026-08-24_greet_minnen_jeline_vandromme","bid":0.001,"ask":0.1,"mid":0.0505,"spread":0.099,"bid_size":null,"ask_size":null}
{"ts":"2026-08-24T20:48:24.036Z","event_type":"best_bid_ask","market_id":"3825038","outcome_index":1,"market_type":"set1","local_side":"away","local_uid":"2026-08-24_greet_minnen_jeline_vandromme","bid":0.9,"ask":0.999,"mid":0.9495,"spread":0.099,"bid_size":null,"ask_size":null}
{"ts":"2026-08-24T20:48:24.037Z","event_type":"price_change","market_id":"3825038","outcome_index":1,"market_type":"set1","local_side":"away","local_uid":"2026-08-24_greet_minnen_jeline_vandromme","bid":0.9,"ask":0.999,"mid":0.9495,"spread":0.099,"price":0.91,"size":0.0,"side":"BUY"}
{"ts":"2026-08-24T20:48:24.037Z","event_type":"price_change","market_id":"3825038","outcome_index":0,"market_type":"set1","local_side":"home","local_uid":"2026-08-24_greet_minnen_jeline_vandromme","bid":0.001,"ask":0.1,"mid":0.0505,"spread":0.099,"price":0.09,"size":0.0,"side":"SELL"}
{"ts":"2026-08-24T20:48:24.037Z","event_type":"best_bid_ask","market_id":"3825038","outcome_index":0,"market_type":"set1","local_side":"home","local_uid":"2026-08-24_greet_minnen_jeline_vandromme","bid":0.001,"ask":0.08,"mid":0.0405,"spread":0.079,"bid_size":null,"ask_size":null}
{"ts":"2026-08-24T20:48:24.037Z","event_type":"best_bid_ask","market_id":"3825038","outcome_index":1,"market_type":"set1","local_side":"away","local_uid":"2026-08-24_greet_minnen_jeline_vandromme","bid":0.92,"ask":0.999,"mid":0.9595,"spread":0.079,"bid_size":null,"ask_size":null}
{"ts":"2026-08-24T20:48:24.038Z","event_type":"price_change","market_id":"3825038","outcome_index":1,"market_type":"set1","local_side":"away","local_uid":"2026-08-24_greet_minnen_jeline_vandromme","bid":0.92,"ask":0.999,"mid":0.9595,"spread":0.079,"price":0.92,"size":44.0,"side":"BUY"}
{"ts":"2026-08-24T20:48:24.038Z","event_type":"price_change","market_id":"3825038","outcome_index":0,"market_type":"set1","local_side":"home","local_uid":"2026-08-24_greet_minnen_jeline_vandromme","bid":0.001,"ask":0.08,"mid":0.0405,"spread":0.079,"price":0.08,"size":44.0,"side":"SELL"}
{"ts":"2026-08-24T20:48:24.069Z","event_type":"best_bid_ask","market_id":"3825038","outcome_index":0,"market_type":"set1","local_side":"home","local_uid":"2026-08-24_greet_minnen_jeline_vandromme","bid":0.001,"ask":0.09,"mid":0.0455,"spread":0.089,"bid_size":null,"ask_size":null}
{"ts":"2026-08-24T20:48:24.069Z","event_type":"best_bid_ask","market_id":"3825038","outcome_index":1,"market_type":"set1","local_side":"away","local_uid":"2026-08-24_greet_minnen_jeline_vandromme","bid":0.91,"ask":0.999,"mid":0.9545,"spread":0.089,"bid_size":null,"ask_size":null}
{"ts":"2026-08-24T20:48:24.070Z","event_type":"price_change","market_id":"3825038","outcome_index":1,"market_type":"set1","local_side":"away","local_uid":"2026-08-24_greet_minnen_jeline_vandromme","bid":0.91,"ask":0.999,"mid":0.9545,"spread":0.089,"price":0.92,"size":0.0,"side":"BUY"}
{"ts":"2026-08-24T20:48:24.070Z","event_type":"price_change","market_id":"3825038","outcome_index":0,"market_type":"set1","local_side":"home","local_uid":"2026-08-24_greet_minnen_jeline_vandromme","bid":0.001,"ask":0.09,"mid":0.0455,"spread":0.089,"price":0.08,"size":0.0,"side":"SELL"}
{"ts":"2026-08-24T20:48:24.075Z","event_type":"best_bid_ask","market_id":"3825620","outcome_index":0,"market_type":"match","local_side":"home","local_uid":"2026-08-24_andrea_guerrieri_august_holmgren","bid":0.94,"ask":0.95,"mid":0.945,"spread":0.01,"bid_size":null,"ask_size":null}
{"ts":"2026-08-24T20:48:24.075Z","event_type":"best_bid_ask","market_id":"3825620","outcome_index":1,"market_type":"match","local_side":"away","local_uid":"2026-08-24_andrea_guerrieri_august_holmgren","bid":0.05,"ask":0.06,"mid":0.055,"spread":0.01,"bid_size":null,"ask_size":null}
{"ts":"2026-08-24T20:48:24.076Z","event_type":"book","market_id":"3825620","outcome_index":0,"market_type":"match","local_side":"home","local_uid":"2026-08-24_andrea_guerrieri_august_holmgren","bid":0.94,"ask":0.95,"mid":0.945,"spread":0.01,"bid_size":8146.63,"ask_size":30485.14}
{"ts":"2026-08-24T20:48:24.077Z","event_type":"book","market_id":"3825620","outcome_index":1,"market_type":"match","local_side":"away","local_uid":"2026-08-24_andrea_guerrieri_august_holmgren","bid":0.05,"ask":0.06,"mid":0.055,"spread":0.01,"bid_size":30485.14,"ask_size":8146.63}
{"ts":"2026-08-24T20:48:24.105Z","event_type":"last_trade_price","market_id":"3825620","outcome_index":1,"market_type":"match","local_side":"away","local_uid":"2026-08-24_andrea_guerrieri_august_holmgren","last_trade":0.06,"trade_size":16.6667,"trade_side":"BUY","trade_notional":1.0}
{"ts":"2026-08-24T20:48:24.174Z","event_type":"best_bid_ask","market_id":"3825038","outcome_index":0,"market_type":"set1","local_side":"home","local_uid":"2026-08-24_greet_minnen_jeline_vandromme","bid":0.001,"ask":0.1,"mid":0.0505,"spread":0.099,"bid_size":null,"ask_size":null}
{"ts":"2026-08-24T20:48:24.175Z","event_type":"best_bid_ask","market_id":"3825038","outcome_index":1,"market_type":"set1","local_side":"away","local_uid":"2026-08-24_greet_minnen_jeline_vandromme","bid":0.9,"ask":0.999,"mid":0.9495,"spread":0.099,"bid_size":null,"ask_size":null}
{"ts":"2026-08-24T20:48:24.175Z","event_type":"price_change","market_id":"3825038","outcome_index":1,"market_type":"set1","local_side":"away","local_uid":"2026-08-24_greet_minnen_jeline_vandromme","bid":0.9,"ask":0.999,"mid":0.9495,"spread":0.099,"price":0.91,"size":0.0,"side":"BUY"}
{"ts":"2026-08-24T20:48:24.175Z","event_type":"price_change","market_id":"3825038","outcome_index":0,"market_type":"set1","local_side":"home","local_uid":"2026-08-24_greet_minnen_jeline_vandromme","bid":0.001,"ask":0.1,"mid":0.0505,"spread":0.099,"price":0.09,"size":0.0,"side":"SELL"}
{"ts":"2026-08-24T20:48:24.176Z","event_type":"best_bid_ask","market_id":"3825038","outcome_index":0,"market_type":"set1","local_side":"home","local_uid":"2026-08-24_greet_minnen_jeline_vandromme","bid":0.001,"ask":0.08,"mid":0.0405,"spread":0.079,"bid_size":null,"ask_size":null}
{"ts":"2026-08-24T20:48:24.176Z","event_type":"best_bid_ask","market_id":"3825038","outcome_index":1,"market_type":"set1","local_side":"away","local_uid":"2026-08-24_greet_minnen_jeline_vandromme","bid":0.92,"ask":0.999,"mid":0.9595,"spread":0.079,"bid_size":null,"ask_size":null}
{"ts":"2026-08-24T20:48:24.176Z","event_type":"price_change","market_id":"3825038","outcome_index":1,"market_type":"set1","local_side":"away","local_uid":"2026-08-24_greet_minnen_jeline_vandromme","bid":0.92,"ask":0.999,"mid":0.9595,"spread":0.079,"price":0.92,"size":44.0,"side":"BUY"}
{"ts":"2026-08-24T20:48:24.176Z","event_type":"price_change","market_id":"3825038","outcome_index":0,"market_type":"set1","local_side":"home","local_uid":"2026-08-24_greet_minnen_jeline_vandromme","bid":0.001,"ask":0.08,"mid":0.0405,"spread":0.079,"price":0.08,"size":44.0,"side":"SELL"}
{"ts":"2026-08-24T20:48:24.207Z","event_type":"best_bid_ask","market_id":"3825038","outcome_index":0,"market_type":"set1","local_side":"home","local_uid":"2026-08-24_greet_minnen_jeline_vandromme","bid":0.001,"ask":0.09,"mid":0.0455,"spread":0.089,"bid_size":null,"ask_size":null}
{"ts":"2026-08-24T20:48:24.207Z","event_type":"best_bid_ask","market_id":"3825038","outcome_index":1,"market_type":"set1","local_side":"away","local_uid":"2026-08-24_greet_minnen_jeline_vandromme","bid":0.91,"ask":0.999,"mid":0.9545,"spread":0.089,"bid_size":null,"ask_size":null}
{"ts":"2026-08-24T20:48:24.207Z","event_type":"price_change","market_id":"3825038","outcome_index":1,"market_type":"set1","local_side":"away","local_uid":"2026-08-24_greet_minnen_jeline_vandromme","bid":0.91,"ask":0.999,"mid":0.9545,"spread":0.089,"price":0.92,"size":0.0,"side":"BUY"}
{"ts":"2026-08-24T20:48:24.208Z","event_type":"price_change","market_id":"3825038","outcome_index":0,"market_type":"set1","local_side":"home","local_uid":"2026-08-24_greet_minnen_jeline_vandromme","bid":0.001,"ask":0.09,"mid":0.0455,"spread":0.089,"price":0.08,"size":0.0,"side":"SELL"}
{"ts":"2026-08-24T20:48:24.251Z","event_type":"best_bid_ask","market_id":"3825038","outcome_index":0,"market_type":"set1","local_side":"home","local_uid":"2026-08-24_greet_minnen_jeline_vandromme","bid":0.001,"ask":0.1,"mid":0.0505,"spread":0.099,"bid_size":null,"ask_size":null}
{"ts":"2026-08-24T20:48:24.252Z","event_type":"best_bid_ask","market_id":"3825038","outcome_index":1,"market_type":"set1","local_side":"away","local_uid":"2026-08-24_greet_minnen_jeline_vandromme","bid":0.9,"ask":0.999,"mid":0.9495,"spread":0.099,"bid_size":null,"ask_size":null}
{"ts":"2026-08-24T20:48:24.252Z","event_type":"price_change","market_id":"3825038","outcome_index":1,"market_type":"set1","local_side":"away","local_uid":"2026-08-24_greet_minnen_jeline_vandromme","bid":0.9,"ask":0.999,"mid":0.9495,"spread":0.099,"price":0.91,"size":0.0,"side":"BUY"}
{"ts":"2026-08-24T20:48:24.252Z","event_type":"price_change","market_id":"3825038","outcome_index":0,"market_type":"set1","local_side":"home","local_uid":"2026-08-24_greet_minnen_jeline_vandromme","bid":0.001,"ask":0.1,"mid":0.0505,"spread":0.099,"price":0.09,"size":0.0,"side":"SELL"}
{"ts":"2026-08-24T20:48:24.253Z","event_type":"best_bid_ask","market_id":"3825038","outcome_index":0,"market_type":"set1","local_side":"home","local_uid":"2026-08-24_greet_minnen_jeline_vandromme","bid":0.001,"ask":0.08,"mid":0.0405,"spread":0.079,"bid_size":null,"ask_size":null}
{"ts":"2026-08-24T20:48:24.253Z","event_type":"best_bid_ask","market_id":"3825038","outcome_index":1,"market_type":"set1","local_side":"away","local_uid":"2026-08-24_greet_minnen_jeline_vandromme","bid":0.92,"ask":0.999,"mid":0.9595,"spread":0.079,"bid_size":null,"ask_size":null}
{"ts":"2026-08-24T20:48:24.253Z","event_type":"price_change","market_id":"3825038","outcome_index":1,"market_type":"set1","local_side":"away","local_uid":"2026-08-24_greet_minnen_jeline_vandromme","bid":0.92,"ask":0.999,"mid":0.9595,"spread":0.079,"price":0.92,"size":44.0,"side":"BUY"}
{"ts":"2026-08-24T20:48:24.254Z","event_type":"price_change","market_id":"3825038","outcome_index":0,"market_type":"set1","local_side":"home","local_uid":"2026-08-24_greet_minnen_jeline_vandromme","bid":0.001,"ask":0.08,"mid":0.0405,"spread":0.079,"price":0.08,"size":44.0,"side":"SELL"}
{"ts":"2026-08-24T20:48:24.313Z","event_type":"best_bid_ask","market_id":"3825038","outcome_index":0,"market_type":"set1","local_side":"home","local_uid":"2026-08-24_greet_minnen_jeline_vandromme","bid":0.001,"ask":0.1,"mid":0.0505,"spread":0.099,"bid_size":null,"ask_size":null}
{"ts":"2026-08-24T20:48:24.314Z","event_type":"best_bid_ask","market_id":"3825038","outcome_index":1,"market_type":"set1","local_side":"away","local_uid":"2026-08-24_greet_minnen_jeline_vandromme","bid":0.9,"ask":0.999,"mid":0.9495,"spread":0.099,"bid_size":null,"ask_size":null}
{"ts":"2026-08-24T20:48:24.314Z","event_type":"price_change","market_id":"3825038","outcome_index":1,"market_type":"set1","local_side":"away","local_uid":"2026-08-24_greet_minnen_jeline_vandromme","bid":0.9,"ask":0.999,"mid":0.9495,"spread":0.099,"price":0.92,"size":0.0,"side":"BUY"}
{"ts":"2026-08-24T20:48:24.314Z","event_type":"price_change","market_id":"3825038","outcome_index":0,"market_type":"set1","local_side":"home","local_uid":"2026-08-24_greet_minnen_jeline_vandromme","bid":0.001,"ask":0.1,"mid":0.0505,"spread":0.099,"price":0.08,"size":0.0,"side":"SELL"}
{"ts":"2026-08-24T20:48:24.315Z","event_type":"best_bid_ask","market_id":"3825038","outcome_index":0,"market_type":"set1","local_side":"home","local_uid":"2026-08-24_greet_minnen_jeline_vandromme","bid":0.001,"ask":0.09,"mid":0.0455,"spread":0.089,"bid_size":null,"ask_size":null}
{"ts":"2026-08-24T20:48:24.315Z","event_type":"best_bid_ask","market_id":"3825038","outcome_index":1,"market_type":"set1","local_side":"away","local_uid":"2026-08-24_greet_minnen_jeline_vandromme","bid":0.91,"ask":0.999,"mid":0.9545,"spread":0.089,"bid_size":null,"ask_size":null}
{"ts":"2026-08-24T20:48:24.315Z","event_type":"price_change","market_id":"3825038","outcome_index":1,"market_type":"set1","local_side":"away","local_uid":"2026-08-24_greet_minnen_jeline_vandromme","bid":0.91,"ask":0.999,"mid":0.9545,"spread":0.089,"price":0.91,"size":88.0,"side":"BUY"}
{"ts":"2026-08-24T20:48:24.315Z","event_type":"price_change","market_id":"3825038","outcome_index":0,"market_type":"set1","local_side":"home","local_uid":"2026-08-24_greet_minnen_jeline_vandromme","bid":0.001,"ask":0.09,"mid":0.0455,"spread":0.089,"price":0.09,"size":88.0,"side":"SELL"}
{"ts":"2026-08-24T20:48:24.478Z","event_type":"best_bid_ask","market_id":"3826738","outcome_index":0,"market_type":"set2","local_side":"home","local_uid":"2026-08-24_harry_wendelken_stefano_travaglia","bid":0.49,"ask":0.6,"mid":0.545,"spread":0.11,"bid_size":null,"ask_size":null}
{"ts":"2026-08-24T20:48:24.479Z","event_type":"best_bid_ask","market_id":"3826738","outcome_index":1,"market_type":"set2","local_side":"away","local_uid":"2026-08-24_harry_wendelken_stefano_travaglia","bid":0.4,"ask":0.51,"mid":0.455,"spread":0.11,"bid_size":null,"ask_size":null}
{"ts":"2026-08-24T20:48:24.479Z","event_type":"price_change","market_id":"3826738","outcome_index":0,"market_type":"set2","local_side":"home","local_uid":"2026-08-24_harry_wendelken_stefano_travaglia","bid":0.49,"ask":0.6,"mid":0.545,"spread":0.11,"price":0.5,"size":0.0,"side":"BUY"}
{"ts":"2026-08-24T20:48:24.479Z","event_type":"price_change","market_id":"3826738","outcome_index":1,"market_type":"set2","local_side":"away","local_uid":"2026-08-24_harry_wendelken_stefano_travaglia","bid":0.4,"ask":0.51,"mid":0.455,"spread":0.11,"price":0.5,"size":0.0,"side":"SELL"}
{"ts":"2026-08-24T20:48:24.514Z","event_type":"best_bid_ask","market_id":"3825038","outcome_index":0,"market_type":"set1","local_side":"home","local_uid":"2026-08-24_greet_minnen_jeline_vandromme","bid":0.001,"ask":0.075,"mid":0.038,"spread":0.074,"bid_size":null,"ask_size":null}
{"ts":"2026-08-24T20:48:24.514Z","event_type":"best_bid_ask","market_id":"3825038","outcome_index":1,"market_type":"set1","local_side":"away","local_uid":"2026-08-24_greet_minnen_jeline_vandromme","bid":0.925,"ask":0.999,"mid":0.962,"spread":0.074,"bid_size":null,"ask_size":null}
{"ts":"2026-08-24T20:48:24.515Z","event_type":"price_change","market_id":"3825038","outcome_index":1,"market_type":"set1","local_side":"away","local_uid":"2026-08-24_greet_minnen_jeline_vandromme","bid":0.925,"ask":0.999,"mid":0.962,"spread":0.074,"price":0.925,"size":150.0,"side":"BUY"}
{"ts":"2026-08-24T20:48:24.515Z","event_type":"price_change","market_id":"3825038","outcome_index":0,"market_type":"set1","local_side":"home","local_uid":"2026-08-24_greet_minnen_jeline_vandromme","bid":0.001,"ask":0.075,"mid":0.038,"spread":0.074,"price":0.075,"size":150.0,"side":"SELL"}
{"ts":"2026-08-24T20:48:24.516Z","event_type":"best_bid_ask","market_id":"3826738","outcome_index":0,"market_type":"set2","local_side":"home","local_uid":"2026-08-24_harry_wendelken_stefano_travaglia","bid":0.5,"ask":0.6,"mid":0.55,"spread":0.1,"bid_size":null,"ask_size":null}
{"ts":"2026-08-24T20:48:24.516Z","event_type":"best_bid_ask","market_id":"3826738","outcome_index":1,"market_type":"set2","local_side":"away","local_uid":"2026-08-24_harry_wendelken_stefano_travaglia","bid":0.4,"ask":0.5,"mid":0.45,"spread":0.1,"bid_size":null,"ask_size":null}
{"ts":"2026-08-24T20:48:24.517Z","event_type":"price_change","market_id":"3826738","outcome_index":0,"market_type":"set2","local_side":"home","local_uid":"2026-08-24_harry_wendelken_stefano_travaglia","bid":0.5,"ask":0.6,"mid":0.55,"spread":0.1,"price":0.5,"size":18.0,"side":"BUY"}
{"ts":"2026-08-24T20:48:24.517Z","event_type":"price_change","market_id":"3826738","outcome_index":1,"market_type":"set2","local_side":"away","local_uid":"2026-08-24_harry_wendelken_stefano_travaglia","bid":0.4,"ask":0.5,"mid":0.45,"spread":0.1,"price":0.5,"size":18.0,"side":"SELL"}
{"ts":"2026-08-24T20:48:24.553Z","event_type":"best_bid_ask","market_id":"3826738","outcome_index":0,"market_type":"set2","local_side":"home","local_uid":"2026-08-24_harry_wendelken_stefano_travaglia","bid":0.48,"ask":0.6,"mid":0.54,"spread":0.12,"bid_size":null,"ask_size":null}
{"ts":"2026-08-24T20:48:24.554Z","event_type":"best_bid_ask","market_id":"3826738","outcome_index":1,"market_type":"set2","local_side":"away","local_uid":"2026-08-24_harry_wendelken_stefano_travaglia","bid":0.4,"ask":0.52,"mid":0.46,"spread":0.12,"bid_size":null,"ask_size":null}
{"ts":"2026-08-24T20:48:24.555Z","event_type":"price_change","market_id":"3826738","outcome_index":0,"market_type":"set2","local_side":"home","local_uid":"2026-08-24_harry_wendelken_stefano_travaglia","bid":0.48,"ask":0.6,"mid":0.54,"spread":0.12,"price":0.5,"size":0.0,"side":"BUY"}
{"ts":"2026-08-24T20:48:24.555Z","event_type":"price_change","market_id":"3826738","outcome_index":1,"market_type":"set2","local_side":"away","local_uid":"2026-08-24_harry_wendelken_stefano_travaglia","bid":0.4,"ask":0.52,"mid":0.46,"spread":0.12,"price":0.5,"size":0.0,"side":"SELL"}
{"ts":"2026-08-24T20:48:24.658Z","event_type":"best_bid_ask","market_id":"3826654","outcome_index":0,"market_type":"set2","local_side":"home","local_uid":"2026-08-24_sebastian_gorzny_cruz_hewitt","bid":0.05,"ask":0.13,"mid":0.09,"spread":0.08,"bid_size":null,"ask_size":null}
{"ts":"2026-08-24T20:48:24.658Z","event_type":"best_bid_ask","market_id":"3826654","outcome_index":1,"market_type":"set2","local_side":"away","local_uid":"2026-08-24_sebastian_gorzny_cruz_hewitt","bid":0.87,"ask":0.95,"mid":0.91,"spread":0.08,"bid_size":null,"ask_size":null}
{"ts":"2026-08-24T20:48:24.659Z","event_type":"price_change","market_id":"3826654","outcome_index":0,"market_type":"set2","local_side":"home","local_uid":"2026-08-24_sebastian_gorzny_cruz_hewitt","bid":0.05,"ask":0.13,"mid":0.09,"spread":0.08,"price":0.06,"size":0.0,"side":"BUY"}
{"ts":"2026-08-24T20:48:24.659Z","event_type":"price_change","market_id":"3826654","outcome_index":1,"market_type":"set2","local_side":"away","local_uid":"2026-08-24_sebastian_gorzny_cruz_hewitt","bid":0.87,"ask":0.95,"mid":0.91,"spread":0.08,"price":0.94,"size":0.0,"side":"SELL"}
{"ts":"2026-08-24T20:48:24.672Z","event_type":"best_bid_ask","market_id":"3826654","outcome_index":0,"market_type":"set2","local_side":"home","local_uid":"2026-08-24_sebastian_gorzny_cruz_hewitt","bid":0.04,"ask":0.13,"mid":0.085,"spread":0.09,"bid_size":null,"ask_size":null}
{"ts":"2026-08-24T20:48:24.673Z","event_type":"best_bid_ask","market_id":"3826654","outcome_index":1,"market_type":"set2","local_side":"away","local_uid":"2026-08-24_sebastian_gorzny_cruz_hewitt","bid":0.87,"ask":0.96,"mid":0.915,"spread":0.09,"bid_size":null,"ask_size":null}
{"ts":"2026-08-24T20:48:24.673Z","event_type":"price_change","market_id":"3826654","outcome_index":0,"market_type":"set2","local_side":"home","local_uid":"2026-08-24_sebastian_gorzny_cruz_hewitt","bid":0.04,"ask":0.13,"mid":0.085,"spread":0.09,"price":0.05,"size":0.0,"side":"BUY"}
{"ts":"2026-08-24T20:48:24.673Z","event_type":"price_change","market_id":"3826654","outcome_index":1,"market_type":"set2","local_side":"away","local_uid":"2026-08-24_sebastian_gorzny_cruz_hewitt","bid":0.87,"ask":0.96,"mid":0.915,"spread":0.09,"price":0.95,"size":0.0,"side":"SELL"}
{"ts":"2026-08-24T20:48:24.688Z","event_type":"best_bid_ask","market_id":"3826738","outcome_index":0,"market_type":"set2","local_side":"home","local_uid":"2026-08-24_harry_wendelken_stefano_travaglia","bid":0.49,"ask":0.6,"mid":0.545,"spread":0.11,"bid_size":null,"ask_size":null}
{"ts":"2026-08-24T20:48:24.688Z","event_type":"best_bid_ask","market_id":"3826738","outcome_index":1,"market_type":"set2","local_side":"away","local_uid":"2026-08-24_harry_wendelken_stefano_travaglia","bid":0.4,"ask":0.51,"mid":0.455,"spread":0.11,"bid_size":null,"ask_size":null}
{"ts":"2026-08-24T20:48:24.689Z","event_type":"price_change","market_id":"3826738","outcome_index":0,"market_type":"set2","local_side":"home","local_uid":"2026-08-24_harry_wendelken_stefano_travaglia","bid":0.49,"ask":0.6,"mid":0.545,"spread":0.11,"price":0.49,"size":24.6,"side":"BUY"}
{"ts":"2026-08-24T20:48:24.689Z","event_type":"price_change","market_id":"3826738","outcome_index":1,"market_type":"set2","local_side":"away","local_uid":"2026-08-24_harry_wendelken_stefano_travaglia","bid":0.4,"ask":0.51,"mid":0.455,"spread":0.11,"price":0.51,"size":24.6,"side":"SELL"}
{"ts":"2026-08-24T20:48:24.735Z","event_type":"best_bid_ask","market_id":"3825038","outcome_index":0,"market_type":"set1","local_side":"home","local_uid":"2026-08-24_greet_minnen_jeline_vandromme","bid":0.001,"ask":0.09,"mid":0.0455,"spread":0.089,"bid_size":null,"ask_size":null}
{"ts":"2026-08-24T20:48:24.735Z","event_type":"best_bid_ask","market_id":"3825038","outcome_index":1,"market_type":"set1","local_side":"away","local_uid":"2026-08-24_greet_minnen_jeline_vandromme","bid":0.91,"ask":0.999,"mid":0.9545,"spread":0.089,"bid_size":null,"ask_size":null}
{"ts":"2026-08-24T20:48:24.735Z","event_type":"price_change","market_id":"3825038","outcome_index":1,"market_type":"set1","local_side":"away","local_uid":"2026-08-24_greet_minnen_jeline_vandromme","bid":0.91,"ask":0.999,"mid":0.9545,"spread":0.089,"price":0.925,"size":0.0,"side":"BUY"}
{"ts":"2026-08-24T20:48:24.736Z","event_type":"price_change","market_id":"3825038","outcome_index":0,"market_type":"set1","local_side":"home","local_uid":"2026-08-24_greet_minnen_jeline_vandromme","bid":0.001,"ask":0.09,"mid":0.0455,"spread":0.089,"price":0.075,"size":0.0,"side":"SELL"}
{"ts":"2026-08-24T20:48:24.748Z","event_type":"best_bid_ask","market_id":"3825038","outcome_index":0,"market_type":"set1","local_side":"home","local_uid":"2026-08-24_greet_minnen_jeline_vandromme","bid":0.001,"ask":0.075,"mid":0.038,"spread":0.074,"bid_size":null,"ask_size":null}
{"ts":"2026-08-24T20:48:24.748Z","event_type":"best_bid_ask","market_id":"3825038","outcome_index":1,"market_type":"set1","local_side":"away","local_uid":"2026-08-24_greet_minnen_jeline_vandromme","bid":0.925,"ask":0.999,"mid":0.962,"spread":0.074,"bid_size":null,"ask_size":null}
{"ts":"2026-08-24T20:48:24.748Z","event_type":"price_change","market_id":"3825038","outcome_index":1,"market_type":"set1","local_side":"away","local_uid":"2026-08-24_greet_minnen_jeline_vandromme","bid":0.925,"ask":0.999,"mid":0.962,"spread":0.074,"price":0.925,"size":150.0,"side":"BUY"}
{"ts":"2026-08-24T20:48:24.749Z","event_type":"price_change","market_id":"3825038","outcome_index":0,"market_type":"set1","local_side":"home","local_uid":"2026-08-24_greet_minnen_jeline_vandromme","bid":0.001,"ask":0.075,"mid":0.038,"spread":0.074,"price":0.075,"size":150.0,"side":"SELL"}
{"ts":"2026-08-24T20:48:24.773Z","event_type":"best_bid_ask","market_id":"3802836","outcome_index":0,"market_type":"set1","local_side":"home","local_uid":"2026-08-24_edward_winter_andres_andrade","bid":0.0,"ask":1.0,"mid":0.5,"spread":1.0,"bid_size":null,"ask_size":null}
{"ts":"2026-08-24T20:48:24.774Z","event_type":"best_bid_ask","market_id":"3802836","outcome_index":1,"market_type":"set1","local_side":"away","local_uid":"2026-08-24_edward_winter_andres_andrade","bid":0.0,"ask":1.0,"mid":0.5,"spread":1.0,"bid_size":null,"ask_size":null}
{"ts":"2026-08-24T20:48:24.774Z","event_type":"price_change","market_id":"3802836","outcome_index":1,"market_type":"set1","local_side":"away","local_uid":"2026-08-24_edward_winter_andres_andrade","bid":0.0,"ask":1.0,"mid":0.5,"spread":1.0,"price":0.002,"size":0.0,"side":"BUY"}
{"ts":"2026-08-24T20:48:24.774Z","event_type":"price_change","market_id":"3802836","outcome_index":0,"market_type":"set1","local_side":"home","local_uid":"2026-08-24_edward_winter_andres_andrade","bid":0.0,"ask":1.0,"mid":0.5,"spread":1.0,"price":0.998,"size":0.0,"side":"SELL"}
{"ts":"2026-08-24T20:48:24.777Z","event_type":"best_bid_ask","market_id":"3825038","outcome_index":0,"market_type":"set1","local_side":"home","local_uid":"2026-08-24_greet_minnen_jeline_vandromme","bid":0.001,"ask":0.065,"mid":0.033,"spread":0.064,"bid_size":null,"ask_size":null}
{"ts":"2026-08-24T20:48:24.777Z","event_type":"best_bid_ask","market_id":"3825038","outcome_index":1,"market_type":"set1","local_side":"away","local_uid":"2026-08-24_greet_minnen_jeline_vandromme","bid":0.935,"ask":0.999,"mid":0.967,"spread":0.064,"bid_size":null,"ask_size":null}
{"ts":"2026-08-24T20:48:24.777Z","event_type":"price_change","market_id":"3825038","outcome_index":1,"market_type":"set1","local_side":"away","local_uid":"2026-08-24_greet_minnen_jeline_vandromme","bid":0.935,"ask":0.999,"mid":0.967,"spread":0.064,"price":0.935,"size":24.6,"side":"BUY"}
{"ts":"2026-08-24T20:48:24.778Z","event_type":"price_change","market_id":"3825038","outcome_index":0,"market_type":"set1","local_side":"home","local_uid":"2026-08-24_greet_minnen_jeline_vandromme","bid":0.001,"ask":0.065,"mid":0.033,"spread":0.064,"price":0.065,"size":24.6,"side":"SELL"}
{"ts":"2026-08-24T20:48:24.832Z","event_type":"best_bid_ask","market_id":"3825038","outcome_index":0,"market_type":"set1","local_side":"home","local_uid":"2026-08-24_greet_minnen_jeline_vandromme","bid":0.001,"ask":0.09,"mid":0.0455,"spread":0.089,"bid_size":null,"ask_size":null}
{"ts":"2026-08-24T20:48:24.832Z","event_type":"best_bid_ask","market_id":"3825038","outcome_index":1,"market_type":"set1","local_side":"away","local_uid":"2026-08-24_greet_minnen_jeline_vandromme","bid":0.91,"ask":0.999,"mid":0.9545,"spread":0.089,"bid_size":null,"ask_size":null}
{"ts":"2026-08-24T20:48:24.832Z","event_type":"price_change","market_id":"3825038","outcome_index":1,"market_type":"set1","local_side":"away","local_uid":"2026-08-24_greet_minnen_jeline_vandromme","bid":0.91,"ask":0.999,"mid":0.9545,"spread":0.089,"price":0.935,"size":0.0,"side":"BUY"}
{"ts":"2026-08-24T20:48:24.833Z","event_type":"price_change","market_id":"3825038","outcome_index":0,"market_type":"set1","local_side":"home","local_uid":"2026-08-24_greet_minnen_jeline_vandromme","bid":0.001,"ask":0.09,"mid":0.0455,"spread":0.089,"price":0.065,"size":0.0,"side":"SELL"}
{"ts":"2026-08-24T20:48:24.871Z","event_type":"best_bid_ask","market_id":"3823629","outcome_index":0,"market_type":"match","local_side":"home","local_uid":"2026-08-24_angela_fita_boluda_lin_zhu","bid":0.5,"ask":0.52,"mid":0.51,"spread":0.02,"bid_size":null,"ask_size":null}
{"ts":"2026-08-24T20:48:24.871Z","event_type":"best_bid_ask","market_id":"3823629","outcome_index":1,"market_type":"match","local_side":"away","local_uid":"2026-08-24_angela_fita_boluda_lin_zhu","bid":0.48,"ask":0.5,"mid":0.49,"spread":0.02,"bid_size":null,"ask_size":null}
{"ts":"2026-08-24T20:48:24.872Z","event_type":"price_change","market_id":"3823629","outcome_index":0,"market_type":"match","local_side":"home","local_uid":"2026-08-24_angela_fita_boluda_lin_zhu","bid":0.5,"ask":0.52,"mid":0.51,"spread":0.02,"price":0.5,"size":5000.0,"side":"BUY"}
{"ts":"2026-08-24T20:48:24.872Z","event_type":"price_change","market_id":"3823629","outcome_index":1,"market_type":"match","local_side":"away","local_uid":"2026-08-24_angela_fita_boluda_lin_zhu","bid":0.48,"ask":0.5,"mid":0.49,"spread":0.02,"price":0.5,"size":5000.0,"side":"SELL"}
{"ts":"2026-08-24T20:48:24.876Z","event_type":"price_change","market_id":"3826719","outcome_index":1,"market_type":"set2","local_side":"away","local_uid":"2026-08-24_laslo_djere_alexandre_muller","bid":0.39,"ask":0.47,"mid":0.43,"spread":0.08,"price":0.39,"size":3163.0,"side":"BUY"}
{"ts":"2026-08-24T20:48:24.876Z","event_type":"price_change","market_id":"3826719","outcome_index":0,"market_type":"set2","local_side":"home","local_uid":"2026-08-24_laslo_djere_alexandre_muller","bid":0.53,"ask":0.61,"mid":0.57,"spread":0.08,"price":0.61,"size":3163.0,"side":"SELL"}
{"ts":"2026-08-24T20:48:24.877Z","event_type":"best_bid_ask","market_id":"3825038","outcome_index":0,"market_type":"set1","local_side":"home","local_uid":"2026-08-24_greet_minnen_jeline_vandromme","bid":0.001,"ask":0.075,"mid":0.038,"spread":0.074,"bid_size":null,"ask_size":null}
{"ts":"2026-08-24T20:48:24.877Z","event_type":"best_bid_ask","market_id":"3825038","outcome_index":1,"market_type":"set1","local_side":"away","local_uid":"2026-08-24_greet_minnen_jeline_vandromme","bid":0.925,"ask":0.999,"mid":0.962,"spread":0.074,"bid_size":null,"ask_size":null}
{"ts":"2026-08-24T20:48:24.877Z","event_type":"price_change","market_id":"3825038","outcome_index":1,"market_type":"set1","local_side":"away","local_uid":"2026-08-24_greet_minnen_jeline_vandromme","bid":0.925,"ask":0.999,"mid":0.962,"spread":0.074,"price":0.925,"size":150.0,"side":"BUY"}
{"ts":"2026-08-24T20:48:24.877Z","event_type":"price_change","market_id":"3825038","outcome_index":0,"market_type":"set1","local_side":"home","local_uid":"2026-08-24_greet_minnen_jeline_vandromme","bid":0.001,"ask":0.075,"mid":0.038,"spread":0.074,"price":0.075,"size":150.0,"side":"SELL"}
{"ts":"2026-08-24T20:48:24.896Z","event_type":"best_bid_ask","market_id":"3823629","outcome_index":0,"market_type":"match","local_side":"home","local_uid":"2026-08-24_angela_fita_boluda_lin_zhu","bid":0.49,"ask":0.52,"mid":0.505,"spread":0.03,"bid_size":null,"ask_size":null}
{"ts":"2026-08-24T20:48:24.897Z","event_type":"best_bid_ask","market_id":"3823629","outcome_index":1,"market_type":"match","local_side":"away","local_uid":"2026-08-24_angela_fita_boluda_lin_zhu","bid":0.48,"ask":0.51,"mid":0.495,"spread":0.03,"bid_size":null,"ask_size":null}
{"ts":"2026-08-24T20:48:24.897Z","event_type":"price_change","market_id":"3823629","outcome_index":0,"market_type":"match","local_side":"home","local_uid":"2026-08-24_angela_fita_boluda_lin_zhu","bid":0.49,"ask":0.52,"mid":0.505,"spread":0.03,"price":0.5,"size":0.0,"side":"BUY"}
{"ts":"2026-08-24T20:48:24.897Z","event_type":"price_change","market_id":"3823629","outcome_index":1,"market_type":"match","local_side":"away","local_uid":"2026-08-24_angela_fita_boluda_lin_zhu","bid":0.48,"ask":0.51,"mid":0.495,"spread":0.03,"price":0.5,"size":0.0,"side":"SELL"}
{"ts":"2026-08-24T20:48:24.899Z","event_type":"best_bid_ask","market_id":"3823623","outcome_index":0,"market_type":"match","local_side":"home","local_uid":"2026-08-24_robin_montgomery_kayla_cross","bid":0.9,"ask":0.91,"mid":0.905,"spread":0.01,"bid_size":null,"ask_size":null}
{"ts":"2026-08-24T20:48:24.899Z","event_type":"best_bid_ask","market_id":"3823623","outcome_index":1,"market_type":"match","local_side":"away","local_uid":"2026-08-24_robin_montgomery_kayla_cross","bid":0.09,"ask":0.1,"mid":0.095,"spread":0.01,"bid_size":null,"ask_size":null}
{"ts":"2026-08-24T20:48:24.899Z","event_type":"price_change","market_id":"3823623","outcome_index":0,"market_type":"match","local_side":"home","local_uid":"2026-08-24_robin_montgomery_kayla_cross","bid":0.9,"ask":0.91,"mid":0.905,"spread":0.01,"price":0.9,"size":4777.0,"side":"BUY"}
{"ts":"2026-08-24T20:48:24.899Z","event_type":"price_change","market_id":"3823623","outcome_index":1,"market_type":"match","local_side":"away","local_uid":"2026-08-24_robin_montgomery_kayla_cross","bid":0.09,"ask":0.1,"mid":0.095,"spread":0.01,"price":0.1,"size":4777.0,"side":"SELL"}
{"ts":"2026-08-24T20:48:24.951Z","event_type":"best_bid_ask","market_id":"3826654","outcome_index":0,"market_type":"set2","local_side":"home","local_uid":"2026-08-24_sebastian_gorzny_cruz_hewitt","bid":0.05,"ask":0.13,"mid":0.09,"spread":0.08,"bid_size":null,"ask_size":null}
{"ts":"2026-08-24T20:48:24.951Z","event_type":"best_bid_ask","market_id":"3826654","outcome_index":1,"market_type":"set2","local_side":"away","local_uid":"2026-08-24_sebastian_gorzny_cruz_hewitt","bid":0.87,"ask":0.95,"mid":0.91,"spread":0.08,"bid_size":null,"ask_size":null}
{"ts":"2026-08-24T20:48:24.952Z","event_type":"price_change","market_id":"3826654","outcome_index":0,"market_type":"set2","local_side":"home","local_uid":"2026-08-24_sebastian_gorzny_cruz_hewitt","bid":0.05,"ask":0.13,"mid":0.09,"spread":0.08,"price":0.05,"size":13.0,"side":"BUY"}
{"ts":"2026-08-24T20:48:24.952Z","event_type":"price_change","market_id":"3826654","outcome_index":1,"market_type":"set2","local_side":"away","local_uid":"2026-08-24_sebastian_gorzny_cruz_hewitt","bid":0.87,"ask":0.95,"mid":0.91,"spread":0.08,"price":0.95,"size":13.0,"side":"SELL"}
{"ts":"2026-08-24T20:48:24.954Z","event_type":"best_bid_ask","market_id":"3826654","outcome_index":0,"market_type":"set2","local_side":"home","local_uid":"2026-08-24_sebastian_gorzny_cruz_hewitt","bid":0.06,"ask":0.13,"mid":0.095,"spread":0.07,"bid_size":null,"ask_size":null}
{"ts":"2026-08-24T20:48:24.954Z","event_type":"best_bid_ask","market_id":"3826654","outcome_index":1,"market_type":"set2","local_side":"away","local_uid":"2026-08-24_sebastian_gorzny_cruz_hewitt","bid":0.87,"ask":0.94,"mid":0.905,"spread":0.07,"bid_size":null,"ask_size":null}
{"ts":"2026-08-24T20:48:24.955Z","event_type":"price_change","market_id":"3826654","outcome_index":0,"market_type":"set2","local_side":"home","local_uid":"2026-08-24_sebastian_gorzny_cruz_hewitt","bid":0.06,"ask":0.13,"mid":0.095,"spread":0.07,"price":0.06,"size":22.0,"side":"BUY"}
{"ts":"2026-08-24T20:48:24.955Z","event_type":"price_change","market_id":"3826654","outcome_index":1,"market_type":"set2","local_side":"away","local_uid":"2026-08-24_sebastian_gorzny_cruz_hewitt","bid":0.87,"ask":0.94,"mid":0.905,"spread":0.07,"price":0.94,"size":22.0,"side":"SELL"}
{"ts":"2026-08-24T20:48:24.958Z","event_type":"best_bid_ask","market_id":"3823629","outcome_index":0,"market_type":"match","local_side":"home","local_uid":"2026-08-24_angela_fita_boluda_lin_zhu","bid":0.5,"ask":0.52,"mid":0.51,"spread":0.02,"bid_size":null,"ask_size":null}
{"ts":"2026-08-24T20:48:24.958Z","event_type":"best_bid_ask","market_id":"3823629","outcome_index":1,"market_type":"match","local_side":"away","local_uid":"2026-08-24_angela_fita_boluda_lin_zhu","bid":0.48,"ask":0.5,"mid":0.49,"spread":0.02,"bid_size":null,"ask_size":null}
{"ts":"2026-08-24T20:48:24.958Z","event_type":"price_change","market_id":"3823629","outcome_index":0,"market_type":"match","local_side":"home","local_uid":"2026-08-24_angela_fita_boluda_lin_zhu","bid":0.5,"ask":0.52,"mid":0.51,"spread":0.02,"price":0.5,"size":85.0,"side":"BUY"}
{"ts":"2026-08-24T20:48:24.958Z","event_type":"price_change","market_id":"3823629","outcome_index":1,"market_type":"match","local_side":"away","local_uid":"2026-08-24_angela_fita_boluda_lin_zhu","bid":0.48,"ask":0.5,"mid":0.49,"spread":0.02,"price":0.5,"size":85.0,"side":"SELL"}
{"ts":"2026-08-24T20:48:24.990Z","event_type":"best_bid_ask","market_id":"3823629","outcome_index":0,"market_type":"match","local_side":"home","local_uid":"2026-08-24_angela_fita_boluda_lin_zhu","bid":0.49,"ask":0.52,"mid":0.505,"spread":0.03,"bid_size":null,"ask_size":null}
{"ts":"2026-08-24T20:48:24.991Z","event_type":"best_bid_ask","market_id":"3823629","outcome_index":1,"market_type":"match","local_side":"away","local_uid":"2026-08-24_angela_fita_boluda_lin_zhu","bid":0.48,"ask":0.51,"mid":0.495,"spread":0.03,"bid_size":null,"ask_size":null}
{"ts":"2026-08-24T20:48:24.991Z","event_type":"price_change","market_id":"3823629","outcome_index":0,"market_type":"match","local_side":"home","local_uid":"2026-08-24_angela_fita_boluda_lin_zhu","bid":0.49,"ask":0.52,"mid":0.505,"spread":0.03,"price":0.5,"size":0.0,"side":"BUY"}
{"ts":"2026-08-24T20:48:24.991Z","event_type":"price_change","market_id":"3823629","outcome_index":1,"market_type":"match","local_side":"away","local_uid":"2026-08-24_angela_fita_boluda_lin_zhu","bid":0.48,"ask":0.51,"mid":0.495,"spread":0.03,"price":0.5,"size":0.0,"side":"SELL"}
{"ts":"2026-08-24T20:48:25.007Z","event_type":"best_bid_ask","market_id":"3823629","outcome_index":0,"market_type":"match","local_side":"home","local_uid":"2026-08-24_angela_fita_boluda_lin_zhu","bid":0.49,"ask":0.53,"mid":0.51,"spread":0.04,"bid_size":null,"ask_size":null}
{"ts":"2026-08-24T20:48:25.007Z","event_type":"best_bid_ask","market_id":"3823629","outcome_index":1,"market_type":"match","local_side":"away","local_uid":"2026-08-24_angela_fita_boluda_lin_zhu","bid":0.47,"ask":0.51,"mid":0.49,"spread":0.04,"bid_size":null,"ask_size":null}
{"ts":"2026-08-24T20:48:25.008Z","event_type":"price_change","market_id":"3823629","outcome_index":1,"market_type":"match","local_side":"away","local_uid":"2026-08-24_angela_fita_boluda_lin_zhu","bid":0.47,"ask":0.51,"mid":0.49,"spread":0.04,"price":0.48,"size":0.0,"side":"BUY"}
{"ts":"2026-08-24T20:48:25.008Z","event_type":"price_change","market_id":"3823629","outcome_index":0,"market_type":"match","local_side":"home","local_uid":"2026-08-24_angela_fita_boluda_lin_zhu","bid":0.49,"ask":0.53,"mid":0.51,"spread":0.04,"price":0.52,"size":0.0,"side":"SELL"}
{"ts":"2026-08-24T20:48:25.018Z","event_type":"best_bid_ask","market_id":"3823629","outcome_index":0,"market_type":"match","local_side":"home","local_uid":"2026-08-24_angela_fita_boluda_lin_zhu","bid":0.5,"ask":0.53,"mid":0.515,"spread":0.03,"bid_size":null,"ask_size":null}
{"ts":"2026-08-24T20:48:25.018Z","event_type":"best_bid_ask","market_id":"3823629","outcome_index":1,"market_type":"match","local_side":"away","local_uid":"2026-08-24_angela_fita_boluda_lin_zhu","bid":0.47,"ask":0.5,"mid":0.485,"spread":0.03,"bid_size":null,"ask_size":null}
{"ts":"2026-08-24T20:48:25.019Z","event_type":"price_change","market_id":"3823629","outcome_index":0,"market_type":"match","local_side":"home","local_uid":"2026-08-24_angela_fita_boluda_lin_zhu","bid":0.5,"ask":0.53,"mid":0.515,"spread":0.03,"price":0.5,"size":85.0,"side":"BUY"}
{"ts":"2026-08-24T20:48:25.019Z","event_type":"price_change","market_id":"3823629","outcome_index":1,"market_type":"match","local_side":"away","local_uid":"2026-08-24_angela_fita_boluda_lin_zhu","bid":0.47,"ask":0.5,"mid":0.485,"spread":0.03,"price":0.5,"size":85.0,"side":"SELL"}
{"ts":"2026-08-24T20:48:25.038Z","event_type":"best_bid_ask","market_id":"3823629","outcome_index":0,"market_type":"match","local_side":"home","local_uid":"2026-08-24_angela_fita_boluda_lin_zhu","bid":0.5,"ask":0.52,"mid":0.51,"spread":0.02,"bid_size":null,"ask_size":null}
{"ts":"2026-08-24T20:48:25.038Z","event_type":"best_bid_ask","market_id":"3823629","outcome_index":1,"market_type":"match","local_side":"away","local_uid":"2026-08-24_angela_fita_boluda_lin_zhu","bid":0.48,"ask":0.5,"mid":0.49,"spread":0.02,"bid_size":null,"ask_size":null}
{"ts":"2026-08-24T20:48:25.038Z","event_type":"price_change","market_id":"3823629","outcome_index":1,"market_type":"match","local_side":"away","local_uid":"2026-08-24_angela_fita_boluda_lin_zhu","bid":0.48,"ask":0.5,"mid":0.49,"spread":0.02,"price":0.48,"size":10.0,"side":"BUY"}
{"ts":"2026-08-24T20:48:25.038Z","event_type":"price_change","market_id":"3823629","outcome_index":0,"market_type":"match","local_side":"home","local_uid":"2026-08-24_angela_fita_boluda_lin_zhu","bid":0.5,"ask":0.52,"mid":0.51,"spread":0.02,"price":0.52,"size":10.0,"side":"SELL"}
{"ts":"2026-08-24T20:48:25.067Z","event_type":"best_bid_ask","market_id":"3824994","outcome_index":0,"market_type":"set2","local_side":"home","local_uid":"2026-08-24_angela_fita_boluda_lin_zhu","bid":0.33,"ask":0.46,"mid":0.395,"spread":0.13,"bid_size":null,"ask_size":null}
{"ts":"2026-08-24T20:48:25.067Z","event_type":"best_bid_ask","market_id":"3824994","outcome_index":1,"market_type":"set2","local_side":"away","local_uid":"2026-08-24_angela_fita_boluda_lin_zhu","bid":0.54,"ask":0.67,"mid":0.605,"spread":0.13,"bid_size":null,"ask_size":null}
{"ts":"2026-08-24T20:48:25.067Z","event_type":"price_change","market_id":"3824994","outcome_index":0,"market_type":"set2","local_side":"home","local_uid":"2026-08-24_angela_fita_boluda_lin_zhu","bid":0.33,"ask":0.46,"mid":0.395,"spread":0.13,"price":0.33,"size":423.0,"side":"BUY"}
{"ts":"2026-08-24T20:48:25.067Z","event_type":"price_change","market_id":"3824994","outcome_index":1,"market_type":"set2","local_side":"away","local_uid":"2026-08-24_angela_fita_boluda_lin_zhu","bid":0.54,"ask":0.67,"mid":0.605,"spread":0.13,"price":0.67,"size":423.0,"side":"SELL"}
{"ts":"2026-08-24T20:48:25.068Z","event_type":"best_bid_ask","market_id":"3824994","outcome_index":0,"market_type":"set2","local_side":"home","local_uid":"2026-08-24_angela_fita_boluda_lin_zhu","bid":0.34,"ask":0.46,"mid":0.4,"spread":0.12,"bid_size":null,"ask_size":null}
{"ts":"2026-08-24T20:48:25.069Z","event_type":"best_bid_ask","market_id":"3824994","outcome_index":1,"market_type":"set2","local_side":"away","local_uid":"2026-08-24_angela_fita_boluda_lin_zhu","bid":0.54,"ask":0.66,"mid":0.6,"spread":0.12,"bid_size":null,"ask_size":null}
{"ts":"2026-08-24T20:48:25.069Z","event_type":"price_change","market_id":"3824994","outcome_index":0,"market_type":"set2","local_side":"home","local_uid":"2026-08-24_angela_fita_boluda_lin_zhu","bid":0.34,"ask":0.46,"mid":0.4,"spread":0.12,"price":0.34,"size":88.0,"side":"BUY"}
{"ts":"2026-08-24T20:48:25.069Z","event_type":"price_change","market_id":"3824994","outcome_index":1,"market_type":"set2","local_side":"away","local_uid":"2026-08-24_angela_fita_boluda_lin_zhu","bid":0.54,"ask":0.66,"mid":0.6,"spread":0.12,"price":0.66,"size":88.0,"side":"SELL"}
{"ts":"2026-08-24T20:48:25.091Z","event_type":"best_bid_ask","market_id":"3823629","outcome_index":0,"market_type":"match","local_side":"home","local_uid":"2026-08-24_angela_fita_boluda_lin_zhu","bid":0.51,"ask":0.52,"mid":0.515,"spread":0.01,"bid_size":null,"ask_size":null}
{"ts":"2026-08-24T20:48:25.091Z","event_type":"best_bid_ask","market_id":"3823629","outcome_index":1,"market_type":"match","local_side":"away","local_uid":"2026-08-24_angela_fita_boluda_lin_zhu","bid":0.48,"ask":0.49,"mid":0.485,"spread":0.01,"bid_size":null,"ask_size":null}
{"ts":"2026-08-24T20:48:25.091Z","event_type":"price_change","market_id":"3823629","outcome_index":0,"market_type":"match","local_side":"home","local_uid":"2026-08-24_angela_fita_boluda_lin_zhu","bid":0.51,"ask":0.52,"mid":0.515,"spread":0.01,"price":0.51,"size":910.61,"side":"BUY"}
{"ts":"2026-08-24T20:48:25.092Z","event_type":"price_change","market_id":"3823629","outcome_index":1,"market_type":"match","local_side":"away","local_uid":"2026-08-24_angela_fita_boluda_lin_zhu","bid":0.48,"ask":0.49,"mid":0.485,"spread":0.01,"price":0.49,"size":910.61,"side":"SELL"}
{"ts":"2026-08-24T20:48:25.097Z","event_type":"best_bid_ask","market_id":"3825038","outcome_index":0,"market_type":"set1","local_side":"home","local_uid":"2026-08-24_greet_minnen_jeline_vandromme","bid":0.001,"ask":0.086,"mid":0.0435,"spread":0.085,"bid_size":null,"ask_size":null}
{"ts":"2026-08-24T20:48:25.097Z","event_type":"best_bid_ask","market_id":"3825038","outcome_index":1,"market_type":"set1","local_side":"away","local_uid":"2026-08-24_greet_minnen_jeline_vandromme","bid":0.914,"ask":0.999,"mid":0.9565,"spread":0.085,"bid_size":null,"ask_size":null}
{"ts":"2026-08-24T20:48:25.098Z","event_type":"price_change","market_id":"3825038","outcome_index":1,"market_type":"set1","local_side":"away","local_uid":"2026-08-24_greet_minnen_jeline_vandromme","bid":0.914,"ask":0.999,"mid":0.9565,"spread":0.085,"price":0.925,"size":0.0,"side":"BUY"}
{"ts":"2026-08-24T20:48:25.098Z","event_type":"price_change","market_id":"3825038","outcome_index":0,"market_type":"set1","local_side":"home","local_uid":"2026-08-24_greet_minnen_jeline_vandromme","bid":0.001,"ask":0.086,"mid":0.0435,"spread":0.085,"price":0.075,"size":0.0,"side":"SELL"}
{"ts":"2026-08-24T20:48:25.110Z","event_type":"best_bid_ask","market_id":"3823629","outcome_index":0,"market_type":"match","local_side":"home","local_uid":"2026-08-24_angela_fita_boluda_lin_zhu","bid":0.51,"ask":0.53,"mid":0.52,"spread":0.02,"bid_size":null,"ask_size":null}
{"ts":"2026-08-24T20:48:25.110Z","event_type":"best_bid_ask","market_id":"3823629","outcome_index":1,"market_type":"match","local_side":"away","local_uid":"2026-08-24_angela_fita_boluda_lin_zhu","bid":0.47,"ask":0.49,"mid":0.48,"spread":0.02,"bid_size":null,"ask_size":null}
{"ts":"2026-08-24T20:48:25.111Z","event_type":"price_change","market_id":"3823629","outcome_index":1,"market_type":"match","local_side":"away","local_uid":"2026-08-24_angela_fita_boluda_lin_zhu","bid":0.47,"ask":0.49,"mid":0.48,"spread":0.02,"price":0.48,"size":0.0,"side":"BUY"}
{"ts":"2026-08-24T20:48:25.111Z","event_type":"price_change","market_id":"3823629","outcome_index":0,"market_type":"match","local_side":"home","local_uid":"2026-08-24_angela_fita_boluda_lin_zhu","bid":0.51,"ask":0.53,"mid":0.52,"spread":0.02,"price":0.52,"size":0.0,"side":"SELL"}
{"ts":"2026-08-24T20:48:25.114Z","event_type":"best_bid_ask","market_id":"3824994","outcome_index":0,"market_type":"set2","local_side":"home","local_uid":"2026-08-24_angela_fita_boluda_lin_zhu","bid":0.35,"ask":0.46,"mid":0.405,"spread":0.11,"bid_size":null,"ask_size":null}
{"ts":"2026-08-24T20:48:25.118Z","event_type":"best_bid_ask","market_id":"3824994","outcome_index":1,"market_type":"set2","local_side":"away","local_uid":"2026-08-24_angela_fita_boluda_lin_zhu","bid":0.54,"ask":0.65,"mid":0.595,"spread":0.11,"bid_size":null,"ask_size":null}
{"ts":"2026-08-24T20:48:25.118Z","event_type":"price_change","market_id":"3824994","outcome_index":0,"market_type":"set2","local_side":"home","local_uid":"2026-08-24_angela_fita_boluda_lin_zhu","bid":0.35,"ask":0.46,"mid":0.405,"spread":0.11,"price":0.35,"size":150.0,"side":"BUY"}
{"ts":"2026-08-24T20:48:25.119Z","event_type":"price_change","market_id":"3824994","outcome_index":1,"market_type":"set2","local_side":"away","local_uid":"2026-08-24_angela_fita_boluda_lin_zhu","bid":0.54,"ask":0.65,"mid":0.595,"spread":0.11,"price":0.65,"size":150.0,"side":"SELL"}
{"ts":"2026-08-24T20:48:25.119Z","event_type":"best_bid_ask","market_id":"3824994","outcome_index":0,"market_type":"set2","local_side":"home","local_uid":"2026-08-24_angela_fita_boluda_lin_zhu","bid":0.35,"ask":0.47,"mid":0.41,"spread":0.12,"bid_size":null,"ask_size":null}
{"ts":"2026-08-24T20:48:25.119Z","event_type":"best_bid_ask","market_id":"3824994","outcome_index":1,"market_type":"set2","local_side":"away","local_uid":"2026-08-24_angela_fita_boluda_lin_zhu","bid":0.53,"ask":0.65,"mid":0.59,"spread":0.12,"bid_size":null,"ask_size":null}
{"ts":"2026-08-24T20:48:25.120Z","event_type":"price_change","market_id":"3824994","outcome_index":1,"market_type":"set2","local_side":"away","local_uid":"2026-08-24_angela_fita_boluda_lin_zhu","bid":0.53,"ask":0.65,"mid":0.59,"spread":0.12,"price":0.54,"size":0.0,"side":"BUY"}
{"ts":"2026-08-24T20:48:25.120Z","event_type":"price_change","market_id":"3824994","outcome_index":0,"market_type":"set2","local_side":"home","local_uid":"2026-08-24_angela_fita_boluda_lin_zhu","bid":0.35,"ask":0.47,"mid":0.41,"spread":0.12,"price":0.46,"size":0.0,"side":"SELL"}
{"ts":"2026-08-24T20:48:25.122Z","event_type":"best_bid_ask","market_id":"3825038","outcome_index":0,"market_type":"set1","local_side":"home","local_uid":"2026-08-24_greet_minnen_jeline_vandromme","bid":0.001,"ask":0.09,"mid":0.0455,"spread":0.089,"bid_size":null,"ask_size":null}
{"ts":"2026-08-24T20:48:25.122Z","event_type":"best_bid_ask","market_id":"3825038","outcome_index":1,"market_type":"set1","local_side":"away","local_uid":"2026-08-24_greet_minnen_jeline_vandromme","bid":0.91,"ask":0.999,"mid":0.9545,"spread":0.089,"bid_size":null,"ask_size":null}
{"ts":"2026-08-24T20:48:25.122Z","event_type":"price_change","market_id":"3825038","outcome_index":1,"market_type":"set1","local_side":"away","local_uid":"2026-08-24_greet_minnen_jeline_vandromme","bid":0.91,"ask":0.999,"mid":0.9545,"spread":0.089,"price":0.914,"size":0.0,"side":"BUY"}
{"ts":"2026-08-24T20:48:25.122Z","event_type":"price_change","market_id":"3825038","outcome_index":0,"market_type":"set1","local_side":"home","local_uid":"2026-08-24_greet_minnen_jeline_vandromme","bid":0.001,"ask":0.09,"mid":0.0455,"spread":0.089,"price":0.086,"size":0.0,"side":"SELL"}
{"ts":"2026-08-24T20:48:25.135Z","event_type":"best_bid_ask","market_id":"3824994","outcome_index":0,"market_type":"set2","local_side":"home","local_uid":"2026-08-24_angela_fita_boluda_lin_zhu","bid":0.35,"ask":0.46,"mid":0.405,"spread":0.11,"bid_size":null,"ask_size":null}
{"ts":"2026-08-24T20:48:25.135Z","event_type":"best_bid_ask","market_id":"3824994","outcome_index":1,"market_type":"set2","local_side":"away","local_uid":"2026-08-24_angela_fita_boluda_lin_zhu","bid":0.54,"ask":0.65,"mid":0.595,"spread":0.11,"bid_size":null,"ask_size":null}
{"ts":"2026-08-24T20:48:25.136Z","event_type":"price_change","market_id":"3824994","outcome_index":1,"market_type":"set2","local_side":"away","local_uid":"2026-08-24_angela_fita_boluda_lin_zhu","bid":0.54,"ask":0.65,"mid":0.595,"spread":0.11,"price":0.54,"size":28.04,"side":"BUY"}
{"ts":"2026-08-24T20:48:25.136Z","event_type":"price_change","market_id":"3824994","outcome_index":0,"market_type":"set2","local_side":"home","local_uid":"2026-08-24_angela_fita_boluda_lin_zhu","bid":0.35,"ask":0.46,"mid":0.405,"spread":0.11,"price":0.46,"size":28.04,"side":"SELL"}
{"ts":"2026-08-24T20:48:25.141Z","event_type":"best_bid_ask","market_id":"3825038","outcome_index":0,"market_type":"set1","local_side":"home","local_uid":"2026-08-24_greet_minnen_jeline_vandromme","bid":0.001,"ask":0.075,"mid":0.038,"spread":0.074,"bid_size":null,"ask_size":null}
{"ts":"2026-08-24T20:48:25.141Z","event_type":"best_bid_ask","market_id":"3825038","outcome_index":1,"market_type":"set1","local_side":"away","local_uid":"2026-08-24_greet_minnen_jeline_vandromme","bid":0.925,"ask":0.999,"mid":0.962,"spread":0.074,"bid_size":null,"ask_size":null}
{"ts":"2026-08-24T20:48:25.142Z","event_type":"price_change","market_id":"3825038","outcome_index":1,"market_type":"set1","local_side":"away","local_uid":"2026-08-24_greet_minnen_jeline_vandromme","bid":0.925,"ask":0.999,"mid":0.962,"spread":0.074,"price":0.925,"size":150.0,"side":"BUY"}
{"ts":"2026-08-24T20:48:25.142Z","event_type":"price_change","market_id":"3825038","outcome_index":0,"market_type":"set1","local_side":"home","local_uid":"2026-08-24_greet_minnen_jeline_vandromme","bid":0.001,"ask":0.075,"mid":0.038,"spread":0.074,"price":0.075,"size":150.0,"side":"SELL"}
{"ts":"2026-08-24T20:48:25.145Z","event_type":"price_change","market_id":"3825594","outcome_index":1,"market_type":"match","local_side":"away","local_uid":"2026-08-24_pol_martin_tiffon_tom_gentzsch","bid":0.68,"ask":0.69,"mid":0.685,"spread":0.01,"price":0.51,"size":19.0,"side":"BUY"}
{"ts":"2026-08-24T20:48:25.145Z","event_type":"price_change","market_id":"3825594","outcome_index":0,"market_type":"match","local_side":"home","local_uid":"2026-08-24_pol_martin_tiffon_tom_gentzsch","bid":0.31,"ask":0.32,"mid":0.315,"spread":0.01,"price":0.49,"size":19.0,"side":"SELL"}
{"ts":"2026-08-24T20:48:25.186Z","event_type":"best_bid_ask","market_id":"3825038","outcome_index":0,"market_type":"set1","local_side":"home","local_uid":"2026-08-24_greet_minnen_jeline_vandromme","bid":0.001,"ask":0.09,"mid":0.0455,"spread":0.089,"bid_size":null,"ask_size":null}
{"ts":"2026-08-24T20:48:25.188Z","event_type":"best_bid_ask","market_id":"3825038","outcome_index":1,"market_type":"set1","local_side":"away","local_uid":"2026-08-24_greet_minnen_jeline_vandromme","bid":0.91,"ask":0.999,"mid":0.9545,"spread":0.089,"bid_size":null,"ask_size":null}
{"ts":"2026-08-24T20:48:25.189Z","event_type":"price_change","market_id":"3825038","outcome_index":1,"market_type":"set1","local_side":"away","local_uid":"2026-08-24_greet_minnen_jeline_vandromme","bid":0.91,"ask":0.999,"mid":0.9545,"spread":0.089,"price":0.925,"size":0.0,"side":"BUY"}
{"ts":"2026-08-24T20:48:25.189Z","event_type":"price_change","market_id":"3825038","outcome_index":0,"market_type":"set1","local_side":"home","local_uid":"2026-08-24_greet_minnen_jeline_vandromme","bid":0.001,"ask":0.09,"mid":0.0455,"spread":0.089,"price":0.075,"size":0.0,"side":"SELL"}
{"ts":"2026-08-24T20:48:25.189Z","event_type":"best_bid_ask","market_id":"3823629","outcome_index":0,"market_type":"match","local_side":"home","local_uid":"2026-08-24_angela_fita_boluda_lin_zhu","bid":0.52,"ask":0.53,"mid":0.525,"spread":0.01,"bid_size":null,"ask_size":null}
{"ts":"2026-08-24T20:48:25.190Z","event_type":"best_bid_ask","market_id":"3823629","outcome_index":1,"market_type":"match","local_side":"away","local_uid":"2026-08-24_angela_fita_boluda_lin_zhu","bid":0.47,"ask":0.48,"mid":0.475,"spread":0.01,"bid_size":null,"ask_size":null}
{"ts":"2026-08-24T20:48:25.190Z","event_type":"price_change","market_id":"3823629","outcome_index":0,"market_type":"match","local_side":"home","local_uid":"2026-08-24_angela_fita_boluda_lin_zhu","bid":0.52,"ask":0.53,"mid":0.525,"spread":0.01,"price":0.52,"size":14025.25,"side":"BUY"}
{"ts":"2026-08-24T20:48:25.190Z","event_type":"price_change","market_id":"3823629","outcome_index":1,"market_type":"match","local_side":"away","local_uid":"2026-08-24_angela_fita_boluda_lin_zhu","bid":0.47,"ask":0.48,"mid":0.475,"spread":0.01,"price":0.48,"size":14025.25,"side":"SELL"}
{"ts":"2026-08-24T20:48:25.203Z","event_type":"best_bid_ask","market_id":"3824994","outcome_index":0,"market_type":"set2","local_side":"home","local_uid":"2026-08-24_angela_fita_boluda_lin_zhu","bid":0.35,"ask":0.47,"mid":0.41,"spread":0.12,"bid_size":null,"ask_size":null}
{"ts":"2026-08-24T20:48:25.203Z","event_type":"best_bid_ask","market_id":"3824994","outcome_index":1,"market_type":"set2","local_side":"away","local_uid":"2026-08-24_angela_fita_boluda_lin_zhu","bid":0.53,"ask":0.65,"mid":0.59,"spread":0.12,"bid_size":null,"ask_size":null}
{"ts":"2026-08-24T20:48:25.204Z","event_type":"price_change","market_id":"3824994","outcome_index":1,"market_type":"set2","local_side":"away","local_uid":"2026-08-24_angela_fita_boluda_lin_zhu","bid":0.53,"ask":0.65,"mid":0.59,"spread":0.12,"price":0.54,"size":0.0,"side":"BUY"}
{"ts":"2026-08-24T20:48:25.204Z","event_type":"price_change","market_id":"3824994","outcome_index":0,"market_type":"set2","local_side":"home","local_uid":"2026-08-24_angela_fita_boluda_lin_zhu","bid":0.35,"ask":0.47,"mid":0.41,"spread":0.12,"price":0.46,"size":0.0,"side":"SELL"}
{"ts":"2026-08-24T20:48:25.227Z","event_type":"best_bid_ask","market_id":"3825038","outcome_index":0,"market_type":"set1","local_side":"home","local_uid":"2026-08-24_greet_minnen_jeline_vandromme","bid":0.001,"ask":0.075,"mid":0.038,"spread":0.074,"bid_size":null,"ask_size":null}
{"ts":"2026-08-24T20:48:25.228Z","event_type":"best_bid_ask","market_id":"3825038","outcome_index":1,"market_type":"set1","local_side":"away","local_uid":"2026-08-24_greet_minnen_jeline_vandromme","bid":0.925,"ask":0.999,"mid":0.962,"spread":0.074,"bid_size":null,"ask_size":null}
{"ts":"2026-08-24T20:48:25.228Z","event_type":"price_change","market_id":"3825038","outcome_index":1,"market_type":"set1","local_side":"away","local_uid":"2026-08-24_greet_minnen_jeline_vandromme","bid":0.925,"ask":0.999,"mid":0.962,"spread":0.074,"price":0.925,"size":150.0,"side":"BUY"}
{"ts":"2026-08-24T20:48:25.228Z","event_type":"price_change","market_id":"3825038","outcome_index":0,"market_type":"set1","local_side":"home","local_uid":"2026-08-24_greet_minnen_jeline_vandromme","bid":0.001,"ask":0.075,"mid":0.038,"spread":0.074,"price":0.075,"size":150.0,"side":"SELL"}
{"ts":"2026-08-24T20:48:25.286Z","event_type":"best_bid_ask","market_id":"3823625","outcome_index":0,"market_type":"match","local_side":"home","local_uid":"2026-08-24_greet_minnen_jeline_vandromme","bid":0.15,"ask":0.16,"mid":0.155,"spread":0.01,"bid_size":null,"ask_size":null}
{"ts":"2026-08-24T20:48:25.286Z","event_type":"best_bid_ask","market_id":"3823625","outcome_index":1,"market_type":"match","local_side":"away","local_uid":"2026-08-24_greet_minnen_jeline_vandromme","bid":0.84,"ask":0.85,"mid":0.845,"spread":0.01,"bid_size":null,"ask_size":null}
{"ts":"2026-08-24T20:48:25.286Z","event_type":"price_change","market_id":"3823625","outcome_index":1,"market_type":"match","local_side":"away","local_uid":"2026-08-24_greet_minnen_jeline_vandromme","bid":0.84,"ask":0.85,"mid":0.845,"spread":0.01,"price":0.84,"size":870.0,"side":"BUY"}
{"ts":"2026-08-24T20:48:25.287Z","event_type":"price_change","market_id":"3823625","outcome_index":0,"market_type":"match","local_side":"home","local_uid":"2026-08-24_greet_minnen_jeline_vandromme","bid":0.15,"ask":0.16,"mid":0.155,"spread":0.01,"price":0.16,"size":870.0,"side":"SELL"}
{"ts":"2026-08-24T20:48:25.287Z","event_type":"best_bid_ask","market_id":"3825038","outcome_index":0,"market_type":"set1","local_side":"home","local_uid":"2026-08-24_greet_minnen_jeline_vandromme","bid":0.001,"ask":0.09,"mid":0.0455,"spread":0.089,"bid_size":null,"ask_size":null}
{"ts":"2026-08-24T20:48:25.287Z","event_type":"best_bid_ask","market_id":"3825038","outcome_index":1,"market_type":"set1","local_side":"away","local_uid":"2026-08-24_greet_minnen_jeline_vandromme","bid":0.91,"ask":0.999,"mid":0.9545,"spread":0.089,"bid_size":null,"ask_size":null}
{"ts":"2026-08-24T20:48:25.287Z","event_type":"price_change","market_id":"3825038","outcome_index":1,"market_type":"set1","local_side":"away","local_uid":"2026-08-24_greet_minnen_jeline_vandromme","bid":0.91,"ask":0.999,"mid":0.9545,"spread":0.089,"price":0.925,"size":0.0,"side":"BUY"}
{"ts":"2026-08-24T20:48:25.288Z","event_type":"price_change","market_id":"3825038","outcome_index":0,"market_type":"set1","local_side":"home","local_uid":"2026-08-24_greet_minnen_jeline_vandromme","bid":0.001,"ask":0.09,"mid":0.0455,"spread":0.089,"price":0.075,"size":0.0,"side":"SELL"}
{"ts":"2026-08-24T20:48:25.334Z","event_type":"best_bid_ask","market_id":"3825038","outcome_index":0,"market_type":"set1","local_side":"home","local_uid":"2026-08-24_greet_minnen_jeline_vandromme","bid":0.001,"ask":0.086,"mid":0.0435,"spread":0.085,"bid_size":null,"ask_size":null}
{"ts":"2026-08-24T20:48:25.335Z","event_type":"best_bid_ask","market_id":"3825038","outcome_index":1,"market_type":"set1","local_side":"away","local_uid":"2026-08-24_greet_minnen_jeline_vandromme","bid":0.914,"ask":0.999,"mid":0.9565,"spread":0.085,"bid_size":null,"ask_size":null}
{"ts":"2026-08-24T20:48:25.335Z","event_type":"price_change","market_id":"3825038","outcome_index":1,"market_type":"set1","local_side":"away","local_uid":"2026-08-24_greet_minnen_jeline_vandromme","bid":0.914,"ask":0.999,"mid":0.9565,"spread":0.085,"price":0.914,"size":100.0,"side":"BUY"}
{"ts":"2026-08-24T20:48:25.335Z","event_type":"price_change","market_id":"3825038","outcome_index":0,"market_type":"set1","local_side":"home","local_uid":"2026-08-24_greet_minnen_jeline_vandromme","bid":0.001,"ask":0.086,"mid":0.0435,"spread":0.085,"price":0.086,"size":100.0,"side":"SELL"}
{"ts":"2026-08-24T20:48:25.336Z","event_type":"best_bid_ask","market_id":"3825038","outcome_index":0,"market_type":"set1","local_side":"home","local_uid":"2026-08-24_greet_minnen_jeline_vandromme","bid":0.001,"ask":0.065,"mid":0.033,"spread":0.064,"bid_size":null,"ask_size":null}
{"ts":"2026-08-24T20:48:25.337Z","event_type":"best_bid_ask","market_id":"3825038","outcome_index":1,"market_type":"set1","local_side":"away","local_uid":"2026-08-24_greet_minnen_jeline_vandromme","bid":0.935,"ask":0.999,"mid":0.967,"spread":0.064,"bid_size":null,"ask_size":null}
{"ts":"2026-08-24T20:48:25.337Z","event_type":"price_change","market_id":"3825038","outcome_index":1,"market_type":"set1","local_side":"away","local_uid":"2026-08-24_greet_minnen_jeline_vandromme","bid":0.935,"ask":0.999,"mid":0.967,"spread":0.064,"price":0.935,"size":24.6,"side":"BUY"}
{"ts":"2026-08-24T20:48:25.337Z","event_type":"price_change","market_id":"3825038","outcome_index":0,"market_type":"set1","local_side":"home","local_uid":"2026-08-24_greet_minnen_jeline_vandromme","bid":0.001,"ask":0.065,"mid":0.033,"spread":0.064,"price":0.065,"size":24.6,"side":"SELL"}
{"ts":"2026-08-24T20:48:25.375Z","event_type":"best_bid_ask","market_id":"3825038","outcome_index":0,"market_type":"set1","local_side":"home","local_uid":"2026-08-24_greet_minnen_jeline_vandromme","bid":0.001,"ask":0.086,"mid":0.0435,"spread":0.085,"bid_size":null,"ask_size":null}
{"ts":"2026-08-24T20:48:25.375Z","event_type":"best_bid_ask","market_id":"3825038","outcome_index":1,"market_type":"set1","local_side":"away","local_uid":"2026-08-24_greet_minnen_jeline_vandromme","bid":0.914,"ask":0.999,"mid":0.9565,"spread":0.085,"bid_size":null,"ask_size":null}
{"ts":"2026-08-24T20:48:25.376Z","event_type":"price_change","market_id":"3825038","outcome_index":1,"market_type":"set1","local_side":"away","local_uid":"2026-08-24_greet_minnen_jeline_vandromme","bid":0.914,"ask":0.999,"mid":0.9565,"spread":0.085,"price":0.935,"size":0.0,"side":"BUY"}
{"ts":"2026-08-24T20:48:25.376Z","event_type":"price_change","market_id":"3825038","outcome_index":0,"market_type":"set1","local_side":"home","local_uid":"2026-08-24_greet_minnen_jeline_vandromme","bid":0.001,"ask":0.086,"mid":0.0435,"spread":0.085,"price":0.065,"size":0.0,"side":"SELL"}
{"ts":"2026-08-24T20:48:25.377Z","event_type":"best_bid_ask","market_id":"3825038","outcome_index":0,"market_type":"set1","local_side":"home","local_uid":"2026-08-24_greet_minnen_jeline_vandromme","bid":0.001,"ask":0.09,"mid":0.0455,"spread":0.089,"bid_size":null,"ask_size":null}
{"ts":"2026-08-24T20:48:25.377Z","event_type":"best_bid_ask","market_id":"3825038","outcome_index":1,"market_type":"set1","local_side":"away","local_uid":"2026-08-24_greet_minnen_jeline_vandromme","bid":0.91,"ask":0.999,"mid":0.9545,"spread":0.089,"bid_size":null,"ask_size":null}
{"ts":"2026-08-24T20:48:25.378Z","event_type":"price_change","market_id":"3825038","outcome_index":1,"market_type":"set1","local_side":"away","local_uid":"2026-08-24_greet_minnen_jeline_vandromme","bid":0.91,"ask":0.999,"mid":0.9545,"spread":0.089,"price":0.914,"size":0.0,"side":"BUY"}
{"ts":"2026-08-24T20:48:25.378Z","event_type":"price_change","market_id":"3825038","outcome_index":0,"market_type":"set1","local_side":"home","local_uid":"2026-08-24_greet_minnen_jeline_vandromme","bid":0.001,"ask":0.09,"mid":0.0455,"spread":0.089,"price":0.086,"size":0.0,"side":"SELL"}
{"ts":"2026-08-24T20:48:25.379Z","event_type":"price_change","market_id":"3824782","outcome_index":1,"market_type":"set1","local_side":"away","local_uid":"2026-08-24_victoria_jimenez_kasintseva_francisca_jorge","bid":0.999,"ask":1.0,"mid":0.9995,"spread":0.001,"price":0.01,"size":14111.0,"side":"BUY"}
{"ts":"2026-08-24T20:48:25.379Z","event_type":"price_change","market_id":"3824782","outcome_index":0,"market_type":"set1","local_side":"home","local_uid":"2026-08-24_victoria_jimenez_kasintseva_francisca_jorge","bid":0.0,"ask":0.001,"mid":0.0005,"spread":0.001,"price":0.99,"size":14111.0,"side":"SELL"}
{"ts":"2026-08-24T20:48:25.420Z","event_type":"best_bid_ask","market_id":"3825038","outcome_index":0,"market_type":"set1","local_side":"home","local_uid":"2026-08-24_greet_minnen_jeline_vandromme","bid":0.001,"ask":0.075,"mid":0.038,"spread":0.074,"bid_size":null,"ask_size":null}
{"ts":"2026-08-24T20:48:25.420Z","event_type":"best_bid_ask","market_id":"3825038","outcome_index":1,"market_type":"set1","local_side":"away","local_uid":"2026-08-24_greet_minnen_jeline_vandromme","bid":0.925,"ask":0.999,"mid":0.962,"spread":0.074,"bid_size":null,"ask_size":null}
{"ts":"2026-08-24T20:48:25.421Z","event_type":"price_change","market_id":"3825038","outcome_index":1,"market_type":"set1","local_side":"away","local_uid":"2026-08-24_greet_minnen_jeline_vandromme","bid":0.925,"ask":0.999,"mid":0.962,"spread":0.074,"price":0.925,"size":150.0,"side":"BUY"}
{"ts":"2026-08-24T20:48:25.421Z","event_type":"price_change","market_id":"3825038","outcome_index":0,"market_type":"set1","local_side":"home","local_uid":"2026-08-24_greet_minnen_jeline_vandromme","bid":0.001,"ask":0.075,"mid":0.038,"spread":0.074,"price":0.075,"size":150.0,"side":"SELL"}
{"ts":"2026-08-24T20:48:25.515Z","event_type":"best_bid_ask","market_id":"3826733","outcome_index":0,"market_type":"set1","local_side":"home","local_uid":"2026-08-24_harry_wendelken_stefano_travaglia","bid":0.85,"ask":0.95,"mid":0.9,"spread":0.1,"bid_size":null,"ask_size":null}
{"ts":"2026-08-24T20:48:25.516Z","event_type":"best_bid_ask","market_id":"3826733","outcome_index":1,"market_type":"set1","local_side":"away","local_uid":"2026-08-24_harry_wendelken_stefano_travaglia","bid":0.05,"ask":0.15,"mid":0.1,"spread":0.1,"bid_size":null,"ask_size":null}
{"ts":"2026-08-24T20:48:25.516Z","event_type":"price_change","market_id":"3826733","outcome_index":1,"market_type":"set1","local_side":"away","local_uid":"2026-08-24_harry_wendelken_stefano_travaglia","bid":0.05,"ask":0.15,"mid":0.1,"spread":0.1,"price":0.11,"size":0.0,"side":"BUY"}
{"ts":"2026-08-24T20:48:25.516Z","event_type":"price_change","market_id":"3826733","outcome_index":0,"market_type":"set1","local_side":"home","local_uid":"2026-08-24_harry_wendelken_stefano_travaglia","bid":0.85,"ask":0.95,"mid":0.9,"spread":0.1,"price":0.89,"size":0.0,"side":"SELL"}
{"ts":"2026-08-24T20:48:25.543Z","event_type":"best_bid_ask","market_id":"3825038","outcome_index":0,"market_type":"set1","local_side":"home","local_uid":"2026-08-24_greet_minnen_jeline_vandromme","bid":0.001,"ask":0.09,"mid":0.0455,"spread":0.089,"bid_size":null,"ask_size":null}
{"ts":"2026-08-24T20:48:25.543Z","event_type":"best_bid_ask","market_id":"3825038","outcome_index":1,"market_type":"set1","local_side":"away","local_uid":"2026-08-24_greet_minnen_jeline_vandromme","bid":0.91,"ask":0.999,"mid":0.9545,"spread":0.089,"bid_size":null,"ask_size":null}
{"ts":"2026-08-24T20:48:25.543Z","event_type":"price_change","market_id":"3825038","outcome_index":1,"market_type":"set1","local_side":"away","local_uid":"2026-08-24_greet_minnen_jeline_vandromme","bid":0.91,"ask":0.999,"mid":0.9545,"spread":0.089,"price":0.925,"size":0.0,"side":"BUY"}
{"ts":"2026-08-24T20:48:25.544Z","event_type":"price_change","market_id":"3825038","outcome_index":0,"market_type":"set1","local_side":"home","local_uid":"2026-08-24_greet_minnen_jeline_vandromme","bid":0.001,"ask":0.09,"mid":0.0455,"spread":0.089,"price":0.075,"size":0.0,"side":"SELL"}
{"ts":"2026-08-24T20:48:25.554Z","event_type":"best_bid_ask","market_id":"3825038","outcome_index":0,"market_type":"set1","local_side":"home","local_uid":"2026-08-24_greet_minnen_jeline_vandromme","bid":0.001,"ask":0.065,"mid":0.033,"spread":0.064,"bid_size":null,"ask_size":null}
{"ts":"2026-08-24T20:48:25.554Z","event_type":"best_bid_ask","market_id":"3825038","outcome_index":1,"market_type":"set1","local_side":"away","local_uid":"2026-08-24_greet_minnen_jeline_vandromme","bid":0.935,"ask":0.999,"mid":0.967,"spread":0.064,"bid_size":null,"ask_size":null}
{"ts":"2026-08-24T20:48:25.555Z","event_type":"price_change","market_id":"3825038","outcome_index":1,"market_type":"set1","local_side":"away","local_uid":"2026-08-24_greet_minnen_jeline_vandromme","bid":0.935,"ask":0.999,"mid":0.967,"spread":0.064,"price":0.935,"size":24.6,"side":"BUY"}
{"ts":"2026-08-24T20:48:25.555Z","event_type":"price_change","market_id":"3825038","outcome_index":0,"market_type":"set1","local_side":"home","local_uid":"2026-08-24_greet_minnen_jeline_vandromme","bid":0.001,"ask":0.065,"mid":0.033,"spread":0.064,"price":0.065,"size":24.6,"side":"SELL"}
{"ts":"2026-08-24T20:48:25.601Z","event_type":"best_bid_ask","market_id":"3823625","outcome_index":0,"market_type":"match","local_side":"home","local_uid":"2026-08-24_greet_minnen_jeline_vandromme","bid":0.15,"ask":0.17,"mid":0.16,"spread":0.02,"bid_size":null,"ask_size":null}
{"ts":"2026-08-24T20:48:25.602Z","event_type":"best_bid_ask","market_id":"3823625","outcome_index":1,"market_type":"match","local_side":"away","local_uid":"2026-08-24_greet_minnen_jeline_vandromme","bid":0.83,"ask":0.85,"mid":0.84,"spread":0.02,"bid_size":null,"ask_size":null}
{"ts":"2026-08-24T20:48:25.602Z","event_type":"price_change","market_id":"3823625","outcome_index":1,"market_type":"match","local_side":"away","local_uid":"2026-08-24_greet_minnen_jeline_vandromme","bid":0.83,"ask":0.85,"mid":0.84,"spread":0.02,"price":0.84,"size":0.0,"side":"BUY"}
{"ts":"2026-08-24T20:48:25.602Z","event_type":"price_change","market_id":"3823625","outcome_index":0,"market_type":"match","local_side":"home","local_uid":"2026-08-24_greet_minnen_jeline_vandromme","bid":0.15,"ask":0.17,"mid":0.16,"spread":0.02,"price":0.16,"size":0.0,"side":"SELL"}
{"ts":"2026-08-24T20:48:25.653Z","event_type":"best_bid_ask","market_id":"3825038","outcome_index":0,"market_type":"set1","local_side":"home","local_uid":"2026-08-24_greet_minnen_jeline_vandromme","bid":0.001,"ask":0.08,"mid":0.0405,"spread":0.079,"bid_size":null,"ask_size":null}
{"ts":"2026-08-24T20:48:25.653Z","event_type":"best_bid_ask","market_id":"3825038","outcome_index":1,"market_type":"set1","local_side":"away","local_uid":"2026-08-24_greet_minnen_jeline_vandromme","bid":0.92,"ask":0.999,"mid":0.9595,"spread":0.079,"bid_size":null,"ask_size":null}
{"ts":"2026-08-24T20:48:25.653Z","event_type":"price_change","market_id":"3825038","outcome_index":1,"market_type":"set1","local_side":"away","local_uid":"2026-08-24_greet_minnen_jeline_vandromme","bid":0.92,"ask":0.999,"mid":0.9595,"spread":0.079,"price":0.935,"size":0.0,"side":"BUY"}
{"ts":"2026-08-24T20:48:25.653Z","event_type":"price_change","market_id":"3825038","outcome_index":0,"market_type":"set1","local_side":"home","local_uid":"2026-08-24_greet_minnen_jeline_vandromme","bid":0.001,"ask":0.08,"mid":0.0405,"spread":0.079,"price":0.065,"size":0.0,"side":"SELL"}
{"ts":"2026-08-24T20:48:25.685Z","event_type":"best_bid_ask","market_id":"3825038","outcome_index":0,"market_type":"set1","local_side":"home","local_uid":"2026-08-24_greet_minnen_jeline_vandromme","bid":0.001,"ask":0.096,"mid":0.0485,"spread":0.095,"bid_size":null,"ask_size":null}
{"ts":"2026-08-24T20:48:25.685Z","event_type":"best_bid_ask","market_id":"3825038","outcome_index":1,"market_type":"set1","local_side":"away","local_uid":"2026-08-24_greet_minnen_jeline_vandromme","bid":0.904,"ask":0.999,"mid":0.9515,"spread":0.095,"bid_size":null,"ask_size":null}
{"ts":"2026-08-24T20:48:25.686Z","event_type":"price_change","market_id":"3825038","outcome_index":1,"market_type":"set1","local_side":"away","local_uid":"2026-08-24_greet_minnen_jeline_vandromme","bid":0.904,"ask":0.999,"mid":0.9515,"spread":0.095,"price":0.92,"size":0.0,"side":"BUY"}
{"ts":"2026-08-24T20:48:25.686Z","event_type":"price_change","market_id":"3825038","outcome_index":0,"market_type":"set1","local_side":"home","local_uid":"2026-08-24_greet_minnen_jeline_vandromme","bid":0.001,"ask":0.096,"mid":0.0485,"spread":0.095,"price":0.08,"size":0.0,"side":"SELL"}
{"ts":"2026-08-24T20:48:25.697Z","event_type":"best_bid_ask","market_id":"3825038","outcome_index":0,"market_type":"set1","local_side":"home","local_uid":"2026-08-24_greet_minnen_jeline_vandromme","bid":0.001,"ask":0.1,"mid":0.0505,"spread":0.099,"bid_size":null,"ask_size":null}
{"ts":"2026-08-24T20:48:25.697Z","event_type":"best_bid_ask","market_id":"3825038","outcome_index":1,"market_type":"set1","local_side":"away","local_uid":"2026-08-24_greet_minnen_jeline_vandromme","bid":0.9,"ask":0.999,"mid":0.9495,"spread":0.099,"bid_size":null,"ask_size":null}
{"ts":"2026-08-24T20:48:25.698Z","event_type":"price_change","market_id":"3825038","outcome_index":1,"market_type":"set1","local_side":"away","local_uid":"2026-08-24_greet_minnen_jeline_vandromme","bid":0.9,"ask":0.999,"mid":0.9495,"spread":0.099,"price":0.904,"size":0.0,"side":"BUY"}
{"ts":"2026-08-24T20:48:25.698Z","event_type":"price_change","market_id":"3825038","outcome_index":0,"market_type":"set1","local_side":"home","local_uid":"2026-08-24_greet_minnen_jeline_vandromme","bid":0.001,"ask":0.1,"mid":0.0505,"spread":0.099,"price":0.096,"size":0.0,"side":"SELL"}
{"ts":"2026-08-24T20:48:25.705Z","event_type":"best_bid_ask","market_id":"3825038","outcome_index":0,"market_type":"set1","local_side":"home","local_uid":"2026-08-24_greet_minnen_jeline_vandromme","bid":0.001,"ask":0.075,"mid":0.038,"spread":0.074,"bid_size":null,"ask_size":null}
{"ts":"2026-08-24T20:48:25.705Z","event_type":"best_bid_ask","market_id":"3825038","outcome_index":1,"market_type":"set1","local_side":"away","local_uid":"2026-08-24_greet_minnen_jeline_vandromme","bid":0.925,"ask":0.999,"mid":0.962,"spread":0.074,"bid_size":null,"ask_size":null}
{"ts":"2026-08-24T20:48:25.706Z","event_type":"price_change","market_id":"3825038","outcome_index":1,"market_type":"set1","local_side":"away","local_uid":"2026-08-24_greet_minnen_jeline_vandromme","bid":0.925,"ask":0.999,"mid":0.962,"spread":0.074,"price":0.925,"size":150.0,"side":"BUY"}
{"ts":"2026-08-24T20:48:25.706Z","event_type":"price_change","market_id":"3825038","outcome_index":0,"market_type":"set1","local_side":"home","local_uid":"2026-08-24_greet_minnen_jeline_vandromme","bid":0.001,"ask":0.075,"mid":0.038,"spread":0.074,"price":0.075,"size":150.0,"side":"SELL"}
{"ts":"2026-08-24T20:48:25.804Z","event_type":"best_bid_ask","market_id":"3823629","outcome_index":0,"market_type":"match","local_side":"home","local_uid":"2026-08-24_angela_fita_boluda_lin_zhu","bid":0.52,"ask":0.54,"mid":0.53,"spread":0.02,"bid_size":null,"ask_size":null}
{"ts":"2026-08-24T20:48:25.804Z","event_type":"best_bid_ask","market_id":"3823629","outcome_index":1,"market_type":"match","local_side":"away","local_uid":"2026-08-24_angela_fita_boluda_lin_zhu","bid":0.46,"ask":0.48,"mid":0.47,"spread":0.02,"bid_size":null,"ask_size":null}
{"ts":"2026-08-24T20:48:25.804Z","event_type":"price_change","market_id":"3823629","outcome_index":1,"market_type":"match","local_side":"away","local_uid":"2026-08-24_angela_fita_boluda_lin_zhu","bid":0.46,"ask":0.48,"mid":0.47,"spread":0.02,"price":0.47,"size":0.0,"side":"BUY"}
{"ts":"2026-08-24T20:48:25.805Z","event_type":"price_change","market_id":"3823629","outcome_index":0,"market_type":"match","local_side":"home","local_uid":"2026-08-24_angela_fita_boluda_lin_zhu","bid":0.52,"ask":0.54,"mid":0.53,"spread":0.02,"price":0.53,"size":0.0,"side":"SELL"}
{"ts":"2026-08-24T20:48:25.845Z","event_type":"best_bid_ask","market_id":"3825038","outcome_index":0,"market_type":"set1","local_side":"home","local_uid":"2026-08-24_greet_minnen_jeline_vandromme","bid":0.001,"ask":0.07,"mid":0.0355,"spread":0.069,"bid_size":null,"ask_size":null}
{"ts":"2026-08-24T20:48:25.845Z","event_type":"best_bid_ask","market_id":"3825038","outcome_index":1,"market_type":"set1","local_side":"away","local_uid":"2026-08-24_greet_minnen_jeline_vandromme","bid":0.93,"ask":0.999,"mid":0.9645,"spread":0.069,"bid_size":null,"ask_size":null}
{"ts":"2026-08-24T20:48:25.846Z","event_type":"price_change","market_id":"3825038","outcome_index":1,"market_type":"set1","local_side":"away","local_uid":"2026-08-24_greet_minnen_jeline_vandromme","bid":0.93,"ask":0.999,"mid":0.9645,"spread":0.069,"price":0.93,"size":50.0,"side":"BUY"}
{"ts":"2026-08-24T20:48:25.846Z","event_type":"price_change","market_id":"3825038","outcome_index":0,"market_type":"set1","local_side":"home","local_uid":"2026-08-24_greet_minnen_jeline_vandromme","bid":0.001,"ask":0.07,"mid":0.0355,"spread":0.069,"price":0.07,"size":50.0,"side":"SELL"}
{"ts":"2026-08-24T20:48:25.861Z","event_type":"best_bid_ask","market_id":"3823629","outcome_index":0,"market_type":"match","local_side":"home","local_uid":"2026-08-24_angela_fita_boluda_lin_zhu","bid":0.53,"ask":0.54,"mid":0.535,"spread":0.01,"bid_size":null,"ask_size":null}
{"ts":"2026-08-24T20:48:25.862Z","event_type":"best_bid_ask","market_id":"3823629","outcome_index":1,"market_type":"match","local_side":"away","local_uid":"2026-08-24_angela_fita_boluda_lin_zhu","bid":0.46,"ask":0.47,"mid":0.465,"spread":0.01,"bid_size":null,"ask_size":null}
{"ts":"2026-08-24T20:48:25.862Z","event_type":"price_change","market_id":"3823629","outcome_index":0,"market_type":"match","local_side":"home","local_uid":"2026-08-24_angela_fita_boluda_lin_zhu","bid":0.53,"ask":0.54,"mid":0.535,"spread":0.01,"price":0.53,"size":837.58,"side":"BUY"}
{"ts":"2026-08-24T20:48:25.862Z","event_type":"price_change","market_id":"3823629","outcome_index":1,"market_type":"match","local_side":"away","local_uid":"2026-08-24_angela_fita_boluda_lin_zhu","bid":0.46,"ask":0.47,"mid":0.465,"spread":0.01,"price":0.47,"size":837.58,"side":"SELL"}
{"ts":"2026-08-24T20:48:25.887Z","event_type":"best_bid_ask","market_id":"3826654","outcome_index":0,"market_type":"set2","local_side":"home","local_uid":"2026-08-24_sebastian_gorzny_cruz_hewitt","bid":0.04,"ask":0.13,"mid":0.085,"spread":0.09,"bid_size":null,"ask_size":null}
{"ts":"2026-08-24T20:48:25.887Z","event_type":"best_bid_ask","market_id":"3826654","outcome_index":1,"market_type":"set2","local_side":"away","local_uid":"2026-08-24_sebastian_gorzny_cruz_hewitt","bid":0.87,"ask":0.96,"mid":0.915,"spread":0.09,"bid_size":null,"ask_size":null}
{"ts":"2026-08-24T20:48:25.887Z","event_type":"price_change","market_id":"3826654","outcome_index":0,"market_type":"set2","local_side":"home","local_uid":"2026-08-24_sebastian_gorzny_cruz_hewitt","bid":0.04,"ask":0.13,"mid":0.085,"spread":0.09,"price":0.06,"size":0.0,"side":"BUY"}
{"ts":"2026-08-24T20:48:25.887Z","event_type":"price_change","market_id":"3826654","outcome_index":1,"market_type":"set2","local_side":"away","local_uid":"2026-08-24_sebastian_gorzny_cruz_hewitt","bid":0.87,"ask":0.96,"mid":0.915,"spread":0.09,"price":0.94,"size":0.0,"side":"SELL"}
{"ts":"2026-08-24T20:48:25.942Z","event_type":"best_bid_ask","market_id":"3825038","outcome_index":0,"market_type":"set1","local_side":"home","local_uid":"2026-08-24_greet_minnen_jeline_vandromme","bid":0.001,"ask":0.075,"mid":0.038,"spread":0.074,"bid_size":null,"ask_size":null}
{"ts":"2026-08-24T20:48:25.943Z","event_type":"best_bid_ask","market_id":"3825038","outcome_index":1,"market_type":"set1","local_side":"away","local_uid":"2026-08-24_greet_minnen_jeline_vandromme","bid":0.925,"ask":0.999,"mid":0.962,"spread":0.074,"bid_size":null,"ask_size":null}
{"ts":"2026-08-24T20:48:25.943Z","event_type":"price_change","market_id":"3825038","outcome_index":1,"market_type":"set1","local_side":"away","local_uid":"2026-08-24_greet_minnen_jeline_vandromme","bid":0.925,"ask":0.999,"mid":0.962,"spread":0.074,"price":0.93,"size":0.0,"side":"BUY"}
{"ts":"2026-08-24T20:48:25.943Z","event_type":"price_change","market_id":"3825038","outcome_index":0,"market_type":"set1","local_side":"home","local_uid":"2026-08-24_greet_minnen_jeline_vandromme","bid":0.001,"ask":0.075,"mid":0.038,"spread":0.074,"price":0.07,"size":0.0,"side":"SELL"}
{"ts":"2026-08-24T20:48:26.256Z","event_type":"price_change","market_id":"3826156","outcome_index":0,"market_type":"set1","local_side":"home","local_uid":"2026-08-24_daniel_altmaier_francisco_comesana","bid":0.48,"ask":0.51,"mid":0.495,"spread":0.03,"price":0.46,"size":4311.98,"side":"BUY"}
{"ts":"2026-08-24T20:48:26.256Z","event_type":"price_change","market_id":"3826156","outcome_index":1,"market_type":"set1","local_side":"away","local_uid":"2026-08-24_daniel_altmaier_francisco_comesana","bid":0.49,"ask":0.52,"mid":0.505,"spread":0.03,"price":0.54,"size":4311.98,"side":"SELL"}
{"ts":"2026-08-24T20:48:26.369Z","event_type":"best_bid_ask","market_id":"3825038","outcome_index":0,"market_type":"set1","local_side":"home","local_uid":"2026-08-24_greet_minnen_jeline_vandromme","bid":0.001,"ask":0.08,"mid":0.0405,"spread":0.079,"bid_size":null,"ask_size":null}
{"ts":"2026-08-24T20:48:26.369Z","event_type":"best_bid_ask","market_id":"3825038","outcome_index":1,"market_type":"set1","local_side":"away","local_uid":"2026-08-24_greet_minnen_jeline_vandromme","bid":0.92,"ask":0.999,"mid":0.9595,"spread":0.079,"bid_size":null,"ask_size":null}
{"ts":"2026-08-24T20:48:26.370Z","event_type":"price_change","market_id":"3825038","outcome_index":1,"market_type":"set1","local_side":"away","local_uid":"2026-08-24_greet_minnen_jeline_vandromme","bid":0.92,"ask":0.999,"mid":0.9595,"spread":0.079,"price":0.925,"size":0.0,"side":"BUY"}
{"ts":"2026-08-24T20:48:26.370Z","event_type":"price_change","market_id":"3825038","outcome_index":0,"market_type":"set1","local_side":"home","local_uid":"2026-08-24_greet_minnen_jeline_vandromme","bid":0.001,"ask":0.08,"mid":0.0405,"spread":0.079,"price":0.075,"size":0.0,"side":"SELL"}
{"ts":"2026-08-24T20:48:26.372Z","event_type":"best_bid_ask","market_id":"3825038","outcome_index":0,"market_type":"set1","local_side":"home","local_uid":"2026-08-24_greet_minnen_jeline_vandromme","bid":0.001,"ask":0.09,"mid":0.0455,"spread":0.089,"bid_size":null,"ask_size":null}
{"ts":"2026-08-24T20:48:26.372Z","event_type":"best_bid_ask","market_id":"3825038","outcome_index":1,"market_type":"set1","local_side":"away","local_uid":"2026-08-24_greet_minnen_jeline_vandromme","bid":0.91,"ask":0.999,"mid":0.9545,"spread":0.089,"bid_size":null,"ask_size":null}
{"ts":"2026-08-24T20:48:26.372Z","event_type":"price_change","market_id":"3825038","outcome_index":1,"market_type":"set1","local_side":"away","local_uid":"2026-08-24_greet_minnen_jeline_vandromme","bid":0.91,"ask":0.999,"mid":0.9545,"spread":0.089,"price":0.92,"size":0.0,"side":"BUY"}
{"ts":"2026-08-24T20:48:26.372Z","event_type":"price_change","market_id":"3825038","outcome_index":0,"market_type":"set1","local_side":"home","local_uid":"2026-08-24_greet_minnen_jeline_vandromme","bid":0.001,"ask":0.09,"mid":0.0455,"spread":0.089,"price":0.08,"size":0.0,"side":"SELL"}
{"ts":"2026-08-24T20:48:26.379Z","event_type":"best_bid_ask","market_id":"3826654","outcome_index":0,"market_type":"set2","local_side":"home","local_uid":"2026-08-24_sebastian_gorzny_cruz_hewitt","bid":0.06,"ask":0.13,"mid":0.095,"spread":0.07,"bid_size":null,"ask_size":null}
{"ts":"2026-08-24T20:48:26.380Z","event_type":"best_bid_ask","market_id":"3826654","outcome_index":1,"market_type":"set2","local_side":"away","local_uid":"2026-08-24_sebastian_gorzny_cruz_hewitt","bid":0.87,"ask":0.94,"mid":0.905,"spread":0.07,"bid_size":null,"ask_size":null}
{"ts":"2026-08-24T20:48:26.380Z","event_type":"price_change","market_id":"3826654","outcome_index":0,"market_type":"set2","local_side":"home","local_uid":"2026-08-24_sebastian_gorzny_cruz_hewitt","bid":0.06,"ask":0.13,"mid":0.095,"spread":0.07,"price":0.06,"size":22.0,"side":"BUY"}
{"ts":"2026-08-24T20:48:26.380Z","event_type":"price_change","market_id":"3826654","outcome_index":1,"market_type":"set2","local_side":"away","local_uid":"2026-08-24_sebastian_gorzny_cruz_hewitt","bid":0.87,"ask":0.94,"mid":0.905,"spread":0.07,"price":0.94,"size":22.0,"side":"SELL"}
{"ts":"2026-08-24T20:48:26.395Z","event_type":"best_bid_ask","market_id":"3823625","outcome_index":0,"market_type":"match","local_side":"home","local_uid":"2026-08-24_greet_minnen_jeline_vandromme","bid":0.13,"ask":0.17,"mid":0.15,"spread":0.04,"bid_size":null,"ask_size":null}
{"ts":"2026-08-24T20:48:26.395Z","event_type":"best_bid_ask","market_id":"3823625","outcome_index":1,"market_type":"match","local_side":"away","local_uid":"2026-08-24_greet_minnen_jeline_vandromme","bid":0.83,"ask":0.87,"mid":0.85,"spread":0.04,"bid_size":null,"ask_size":null}
{"ts":"2026-08-24T20:48:26.396Z","event_type":"price_change","market_id":"3823625","outcome_index":0,"market_type":"match","local_side":"home","local_uid":"2026-08-24_greet_minnen_jeline_vandromme","bid":0.13,"ask":0.17,"mid":0.15,"spread":0.04,"price":0.15,"size":0.0,"side":"BUY"}
{"ts":"2026-08-24T20:48:26.396Z","event_type":"price_change","market_id":"3823625","outcome_index":1,"market_type":"match","local_side":"away","local_uid":"2026-08-24_greet_minnen_jeline_vandromme","bid":0.83,"ask":0.87,"mid":0.85,"spread":0.04,"price":0.85,"size":0.0,"side":"SELL"}
{"ts":"2026-08-24T20:48:26.398Z","event_type":"best_bid_ask","market_id":"3825038","outcome_index":0,"market_type":"set1","local_side":"home","local_uid":"2026-08-24_greet_minnen_jeline_vandromme","bid":0.001,"ask":0.075,"mid":0.038,"spread":0.074,"bid_size":null,"ask_size":null}
{"ts":"2026-08-24T20:48:26.398Z","event_type":"best_bid_ask","market_id":"3825038","outcome_index":1,"market_type":"set1","local_side":"away","local_uid":"2026-08-24_greet_minnen_jeline_vandromme","bid":0.925,"ask":0.999,"mid":0.962,"spread":0.074,"bid_size":null,"ask_size":null}
{"ts":"2026-08-24T20:48:26.398Z","event_type":"price_change","market_id":"3825038","outcome_index":1,"market_type":"set1","local_side":"away","local_uid":"2026-08-24_greet_minnen_jeline_vandromme","bid":0.925,"ask":0.999,"mid":0.962,"spread":0.074,"price":0.925,"size":150.0,"side":"BUY"}
{"ts":"2026-08-24T20:48:26.398Z","event_type":"price_change","market_id":"3825038","outcome_index":0,"market_type":"set1","local_side":"home","local_uid":"2026-08-24_greet_minnen_jeline_vandromme","bid":0.001,"ask":0.075,"mid":0.038,"spread":0.074,"price":0.075,"size":150.0,"side":"SELL"}
{"ts":"2026-08-24T20:48:26.492Z","event_type":"best_bid_ask","market_id":"3825038","outcome_index":0,"market_type":"set1","local_side":"home","local_uid":"2026-08-24_greet_minnen_jeline_vandromme","bid":0.001,"ask":0.08,"mid":0.0405,"spread":0.079,"bid_size":null,"ask_size":null}
{"ts":"2026-08-24T20:48:26.492Z","event_type":"best_bid_ask","market_id":"3825038","outcome_index":1,"market_type":"set1","local_side":"away","local_uid":"2026-08-24_greet_minnen_jeline_vandromme","bid":0.92,"ask":0.999,"mid":0.9595,"spread":0.079,"bid_size":null,"ask_size":null}
{"ts":"2026-08-24T20:48:26.493Z","event_type":"price_change","market_id":"3825038","outcome_index":1,"market_type":"set1","local_side":"away","local_uid":"2026-08-24_greet_minnen_jeline_vandromme","bid":0.92,"ask":0.999,"mid":0.9595,"spread":0.079,"price":0.925,"size":0.0,"side":"BUY"}
{"ts":"2026-08-24T20:48:26.493Z","event_type":"price_change","market_id":"3825038","outcome_index":0,"market_type":"set1","local_side":"home","local_uid":"2026-08-24_greet_minnen_jeline_vandromme","bid":0.001,"ask":0.08,"mid":0.0405,"spread":0.079,"price":0.075,"size":0.0,"side":"SELL"}
{"ts":"2026-08-24T20:48:26.494Z","event_type":"best_bid_ask","market_id":"3823625","outcome_index":0,"market_type":"match","local_side":"home","local_uid":"2026-08-24_greet_minnen_jeline_vandromme","bid":0.14,"ask":0.17,"mid":0.155,"spread":0.03,"bid_size":null,"ask_size":null}
{"ts":"2026-08-24T20:48:26.495Z","event_type":"best_bid_ask","market_id":"3823625","outcome_index":1,"market_type":"match","local_side":"away","local_uid":"2026-08-24_greet_minnen_jeline_vandromme","bid":0.83,"ask":0.86,"mid":0.845,"spread":0.03,"bid_size":null,"ask_size":null}
{"ts":"2026-08-24T20:48:26.495Z","event_type":"price_change","market_id":"3823625","outcome_index":0,"market_type":"match","local_side":"home","local_uid":"2026-08-24_greet_minnen_jeline_vandromme","bid":0.14,"ask":0.17,"mid":0.155,"spread":0.03,"price":0.14,"size":23.0,"side":"BUY"}
{"ts":"2026-08-24T20:48:26.495Z","event_type":"price_change","market_id":"3823625","outcome_index":1,"market_type":"match","local_side":"away","local_uid":"2026-08-24_greet_minnen_jeline_vandromme","bid":0.83,"ask":0.86,"mid":0.845,"spread":0.03,"price":0.86,"size":23.0,"side":"SELL"}
{"ts":"2026-08-24T20:48:26.497Z","event_type":"best_bid_ask","market_id":"3823625","outcome_index":0,"market_type":"match","local_side":"home","local_uid":"2026-08-24_greet_minnen_jeline_vandromme","bid":0.16,"ask":0.17,"mid":0.165,"spread":0.01,"bid_size":null,"ask_size":null}
{"ts":"2026-08-24T20:48:26.497Z","event_type":"best_bid_ask","market_id":"3823625","outcome_index":1,"market_type":"match","local_side":"away","local_uid":"2026-08-24_greet_minnen_jeline_vandromme","bid":0.83,"ask":0.84,"mid":0.835,"spread":0.01,"bid_size":null,"ask_size":null}
{"ts":"2026-08-24T20:48:26.497Z","event_type":"price_change","market_id":"3823625","outcome_index":0,"market_type":"match","local_side":"home","local_uid":"2026-08-24_greet_minnen_jeline_vandromme","bid":0.16,"ask":0.17,"mid":0.165,"spread":0.01,"price":0.16,"size":2750.0,"side":"BUY"}
{"ts":"2026-08-24T20:48:26.498Z","event_type":"price_change","market_id":"3823625","outcome_index":1,"market_type":"match","local_side":"away","local_uid":"2026-08-24_greet_minnen_jeline_vandromme","bid":0.83,"ask":0.84,"mid":0.835,"spread":0.01,"price":0.84,"size":2750.0,"side":"SELL"}
{"ts":"2026-08-24T20:48:26.498Z","event_type":"best_bid_ask","market_id":"3825038","outcome_index":0,"market_type":"set1","local_side":"home","local_uid":"2026-08-24_greet_minnen_jeline_vandromme","bid":0.001,"ask":0.09,"mid":0.0455,"spread":0.089,"bid_size":null,"ask_size":null}
{"ts":"2026-08-24T20:48:26.498Z","event_type":"best_bid_ask","market_id":"3825038","outcome_index":1,"market_type":"set1","local_side":"away","local_uid":"2026-08-24_greet_minnen_jeline_vandromme","bid":0.91,"ask":0.999,"mid":0.9545,"spread":0.089,"bid_size":null,"ask_size":null}
{"ts":"2026-08-24T20:48:26.499Z","event_type":"price_change","market_id":"3825038","outcome_index":1,"market_type":"set1","local_side":"away","local_uid":"2026-08-24_greet_minnen_jeline_vandromme","bid":0.91,"ask":0.999,"mid":0.9545,"spread":0.089,"price":0.92,"size":0.0,"side":"BUY"}
{"ts":"2026-08-24T20:48:26.499Z","event_type":"price_change","market_id":"3825038","outcome_index":0,"market_type":"set1","local_side":"home","local_uid":"2026-08-24_greet_minnen_jeline_vandromme","bid":0.001,"ask":0.09,"mid":0.0455,"spread":0.089,"price":0.08,"size":0.0,"side":"SELL"}
{"ts":"2026-08-24T20:48:26.507Z","event_type":"best_bid_ask","market_id":"3825038","outcome_index":0,"market_type":"set1","local_side":"home","local_uid":"2026-08-24_greet_minnen_jeline_vandromme","bid":0.001,"ask":0.075,"mid":0.038,"spread":0.074,"bid_size":null,"ask_size":null}
{"ts":"2026-08-24T20:48:26.507Z","event_type":"best_bid_ask","market_id":"3825038","outcome_index":1,"market_type":"set1","local_side":"away","local_uid":"2026-08-24_greet_minnen_jeline_vandromme","bid":0.925,"ask":0.999,"mid":0.962,"spread":0.074,"bid_size":null,"ask_size":null}
{"ts":"2026-08-24T20:48:26.508Z","event_type":"price_change","market_id":"3825038","outcome_index":1,"market_type":"set1","local_side":"away","local_uid":"2026-08-24_greet_minnen_jeline_vandromme","bid":0.925,"ask":0.999,"mid":0.962,"spread":0.074,"price":0.925,"size":150.0,"side":"BUY"}
{"ts":"2026-08-24T20:48:26.508Z","event_type":"price_change","market_id":"3825038","outcome_index":0,"market_type":"set1","local_side":"home","local_uid":"2026-08-24_greet_minnen_jeline_vandromme","bid":0.001,"ask":0.075,"mid":0.038,"spread":0.074,"price":0.075,"size":150.0,"side":"SELL"}
{"ts":"2026-08-24T20:48:26.520Z","event_type":"best_bid_ask","market_id":"3825620","outcome_index":0,"market_type":"match","local_side":"home","local_uid":"2026-08-24_andrea_guerrieri_august_holmgren","bid":0.94,"ask":0.96,"mid":0.95,"spread":0.02,"bid_size":null,"ask_size":null}
{"ts":"2026-08-24T20:48:26.520Z","event_type":"best_bid_ask","market_id":"3825620","outcome_index":1,"market_type":"match","local_side":"away","local_uid":"2026-08-24_andrea_guerrieri_august_holmgren","bid":0.04,"ask":0.06,"mid":0.05,"spread":0.02,"bid_size":null,"ask_size":null}
{"ts":"2026-08-24T20:48:26.521Z","event_type":"price_change","market_id":"3825620","outcome_index":1,"market_type":"match","local_side":"away","local_uid":"2026-08-24_andrea_guerrieri_august_holmgren","bid":0.04,"ask":0.06,"mid":0.05,"spread":0.02,"price":0.05,"size":0.0,"side":"BUY"}
{"ts":"2026-08-24T20:48:26.521Z","event_type":"price_change","market_id":"3825620","outcome_index":0,"market_type":"match","local_side":"home","local_uid":"2026-08-24_andrea_guerrieri_august_holmgren","bid":0.94,"ask":0.96,"mid":0.95,"spread":0.02,"price":0.95,"size":0.0,"side":"SELL"}
{"ts":"2026-08-24T20:48:26.527Z","event_type":"best_bid_ask","market_id":"3825038","outcome_index":0,"market_type":"set1","local_side":"home","local_uid":"2026-08-24_greet_minnen_jeline_vandromme","bid":0.001,"ask":0.08,"mid":0.0405,"spread":0.079,"bid_size":null,"ask_size":null}
{"ts":"2026-08-24T20:48:26.527Z","event_type":"best_bid_ask","market_id":"3825038","outcome_index":1,"market_type":"set1","local_side":"away","local_uid":"2026-08-24_greet_minnen_jeline_vandromme","bid":0.92,"ask":0.999,"mid":0.9595,"spread":0.079,"bid_size":null,"ask_size":null}
{"ts":"2026-08-24T20:48:26.527Z","event_type":"price_change","market_id":"3825038","outcome_index":1,"market_type":"set1","local_side":"away","local_uid":"2026-08-24_greet_minnen_jeline_vandromme","bid":0.92,"ask":0.999,"mid":0.9595,"spread":0.079,"price":0.925,"size":0.0,"side":"BUY"}
{"ts":"2026-08-24T20:48:26.527Z","event_type":"price_change","market_id":"3825038","outcome_index":0,"market_type":"set1","local_side":"home","local_uid":"2026-08-24_greet_minnen_jeline_vandromme","bid":0.001,"ask":0.08,"mid":0.0405,"spread":0.079,"price":0.075,"size":0.0,"side":"SELL"}
{"ts":"2026-08-24T20:48:26.542Z","event_type":"best_bid_ask","market_id":"3826919","outcome_index":0,"market_type":"set2","local_side":"home","local_uid":"2026-08-24_dalibor_svrcina_felipe_meligeni_alves","bid":0.43,"ask":0.51,"mid":0.47,"spread":0.08,"bid_size":null,"ask_size":null}
{"ts":"2026-08-24T20:48:26.542Z","event_type":"best_bid_ask","market_id":"3826919","outcome_index":1,"market_type":"set2","local_side":"away","local_uid":"2026-08-24_dalibor_svrcina_felipe_meligeni_alves","bid":0.49,"ask":0.57,"mid":0.53,"spread":0.08,"bid_size":null,"ask_size":null}
{"ts":"2026-08-24T20:48:26.542Z","event_type":"price_change","market_id":"3826919","outcome_index":1,"market_type":"set2","local_side":"away","local_uid":"2026-08-24_dalibor_svrcina_felipe_meligeni_alves","bid":0.49,"ask":0.57,"mid":0.53,"spread":0.08,"price":0.49,"size":24.6,"side":"BUY"}
{"ts":"2026-08-24T20:48:26.543Z","event_type":"price_change","market_id":"3826919","outcome_index":0,"market_type":"set2","local_side":"home","local_uid":"2026-08-24_dalibor_svrcina_felipe_meligeni_alves","bid":0.43,"ask":0.51,"mid":0.47,"spread":0.08,"price":0.51,"size":24.6,"side":"SELL"}
{"ts":"2026-08-24T20:48:26.545Z","event_type":"best_bid_ask","market_id":"3825038","outcome_index":0,"market_type":"set1","local_side":"home","local_uid":"2026-08-24_greet_minnen_jeline_vandromme","bid":0.001,"ask":0.065,"mid":0.033,"spread":0.064,"bid_size":null,"ask_size":null}
{"ts":"2026-08-24T20:48:26.545Z","event_type":"best_bid_ask","market_id":"3825038","outcome_index":1,"market_type":"set1","local_side":"away","local_uid":"2026-08-24_greet_minnen_jeline_vandromme","bid":0.935,"ask":0.999,"mid":0.967,"spread":0.064,"bid_size":null,"ask_size":null}
{"ts":"2026-08-24T20:48:26.545Z","event_type":"price_change","market_id":"3825038","outcome_index":1,"market_type":"set1","local_side":"away","local_uid":"2026-08-24_greet_minnen_jeline_vandromme","bid":0.935,"ask":0.999,"mid":0.967,"spread":0.064,"price":0.935,"size":24.6,"side":"BUY"}
{"ts":"2026-08-24T20:48:26.545Z","event_type":"price_change","market_id":"3825038","outcome_index":0,"market_type":"set1","local_side":"home","local_uid":"2026-08-24_greet_minnen_jeline_vandromme","bid":0.001,"ask":0.065,"mid":0.033,"spread":0.064,"price":0.065,"size":24.6,"side":"SELL"}
{"ts":"2026-08-24T20:48:26.554Z","event_type":"best_bid_ask","market_id":"3826919","outcome_index":0,"market_type":"set2","local_side":"home","local_uid":"2026-08-24_dalibor_svrcina_felipe_meligeni_alves","bid":0.43,"ask":0.52,"mid":0.475,"spread":0.09,"bid_size":null,"ask_size":null}
{"ts":"2026-08-24T20:48:26.554Z","event_type":"best_bid_ask","market_id":"3826919","outcome_index":1,"market_type":"set2","local_side":"away","local_uid":"2026-08-24_dalibor_svrcina_felipe_meligeni_alves","bid":0.48,"ask":0.57,"mid":0.525,"spread":0.09,"bid_size":null,"ask_size":null}
{"ts":"2026-08-24T20:48:26.554Z","event_type":"price_change","market_id":"3826919","outcome_index":1,"market_type":"set2","local_side":"away","local_uid":"2026-08-24_dalibor_svrcina_felipe_meligeni_alves","bid":0.48,"ask":0.57,"mid":0.525,"spread":0.09,"price":0.49,"size":0.0,"side":"BUY"}
{"ts":"2026-08-24T20:48:26.554Z","event_type":"price_change","market_id":"3826919","outcome_index":0,"market_type":"set2","local_side":"home","local_uid":"2026-08-24_dalibor_svrcina_felipe_meligeni_alves","bid":0.43,"ask":0.52,"mid":0.475,"spread":0.09,"price":0.51,"size":0.0,"side":"SELL"}
{"ts":"2026-08-24T20:48:26.628Z","event_type":"best_bid_ask","market_id":"3826919","outcome_index":0,"market_type":"set2","local_side":"home","local_uid":"2026-08-24_dalibor_svrcina_felipe_meligeni_alves","bid":0.43,"ask":0.51,"mid":0.47,"spread":0.08,"bid_size":null,"ask_size":null}
{"ts":"2026-08-24T20:48:26.629Z","event_type":"best_bid_ask","market_id":"3826919","outcome_index":1,"market_type":"set2","local_side":"away","local_uid":"2026-08-24_dalibor_svrcina_felipe_meligeni_alves","bid":0.49,"ask":0.57,"mid":0.53,"spread":0.08,"bid_size":null,"ask_size":null}
{"ts":"2026-08-24T20:48:26.629Z","event_type":"price_change","market_id":"3826919","outcome_index":1,"market_type":"set2","local_side":"away","local_uid":"2026-08-24_dalibor_svrcina_felipe_meligeni_alves","bid":0.49,"ask":0.57,"mid":0.53,"spread":0.08,"price":0.49,"size":24.6,"side":"BUY"}
{"ts":"2026-08-24T20:48:26.629Z","event_type":"price_change","market_id":"3826919","outcome_index":0,"market_type":"set2","local_side":"home","local_uid":"2026-08-24_dalibor_svrcina_felipe_meligeni_alves","bid":0.43,"ask":0.51,"mid":0.47,"spread":0.08,"price":0.51,"size":24.6,"side":"SELL"}
{"ts":"2026-08-24T20:48:26.633Z","event_type":"best_bid_ask","market_id":"3825038","outcome_index":0,"market_type":"set1","local_side":"home","local_uid":"2026-08-24_greet_minnen_jeline_vandromme","bid":0.001,"ask":0.09,"mid":0.0455,"spread":0.089,"bid_size":null,"ask_size":null}
{"ts":"2026-08-24T20:48:26.634Z","event_type":"best_bid_ask","market_id":"3825038","outcome_index":1,"market_type":"set1","local_side":"away","local_uid":"2026-08-24_greet_minnen_jeline_vandromme","bid":0.91,"ask":0.999,"mid":0.9545,"spread":0.089,"bid_size":null,"ask_size":null}
{"ts":"2026-08-24T20:48:26.634Z","event_type":"price_change","market_id":"3825038","outcome_index":1,"market_type":"set1","local_side":"away","local_uid":"2026-08-24_greet_minnen_jeline_vandromme","bid":0.91,"ask":0.999,"mid":0.9545,"spread":0.089,"price":0.935,"size":0.0,"side":"BUY"}
{"ts":"2026-08-24T20:48:26.634Z","event_type":"price_change","market_id":"3825038","outcome_index":0,"market_type":"set1","local_side":"home","local_uid":"2026-08-24_greet_minnen_jeline_vandromme","bid":0.001,"ask":0.09,"mid":0.0455,"spread":0.089,"price":0.065,"size":0.0,"side":"SELL"}
{"ts":"2026-08-24T20:48:26.643Z","event_type":"best_bid_ask","market_id":"3826919","outcome_index":0,"market_type":"set2","local_side":"home","local_uid":"2026-08-24_dalibor_svrcina_felipe_meligeni_alves","bid":0.43,"ask":0.52,"mid":0.475,"spread":0.09,"bid_size":null,"ask_size":null}
{"ts":"2026-08-24T20:48:26.644Z","event_type":"best_bid_ask","market_id":"3826919","outcome_index":1,"market_type":"set2","local_side":"away","local_uid":"2026-08-24_dalibor_svrcina_felipe_meligeni_alves","bid":0.48,"ask":0.57,"mid":0.525,"spread":0.09,"bid_size":null,"ask_size":null}
{"ts":"2026-08-24T20:48:26.644Z","event_type":"price_change","market_id":"3826919","outcome_index":1,"market_type":"set2","local_side":"away","local_uid":"2026-08-24_dalibor_svrcina_felipe_meligeni_alves","bid":0.48,"ask":0.57,"mid":0.525,"spread":0.09,"price":0.49,"size":0.0,"side":"BUY"}
{"ts":"2026-08-24T20:48:26.644Z","event_type":"price_change","market_id":"3826919","outcome_index":0,"market_type":"set2","local_side":"home","local_uid":"2026-08-24_dalibor_svrcina_felipe_meligeni_alves","bid":0.43,"ask":0.52,"mid":0.475,"spread":0.09,"price":0.51,"size":0.0,"side":"SELL"}
{"ts":"2026-08-24T20:48:26.650Z","event_type":"best_bid_ask","market_id":"3825038","outcome_index":0,"market_type":"set1","local_side":"home","local_uid":"2026-08-24_greet_minnen_jeline_vandromme","bid":0.001,"ask":0.075,"mid":0.038,"spread":0.074,"bid_size":null,"ask_size":null}
{"ts":"2026-08-24T20:48:26.651Z","event_type":"best_bid_ask","market_id":"3825038","outcome_index":1,"market_type":"set1","local_side":"away","local_uid":"2026-08-24_greet_minnen_jeline_vandromme","bid":0.925,"ask":0.999,"mid":0.962,"spread":0.074,"bid_size":null,"ask_size":null}
{"ts":"2026-08-24T20:48:26.651Z","event_type":"price_change","market_id":"3825038","outcome_index":1,"market_type":"set1","local_side":"away","local_uid":"2026-08-24_greet_minnen_jeline_vandromme","bid":0.925,"ask":0.999,"mid":0.962,"spread":0.074,"price":0.925,"size":150.0,"side":"BUY"}
{"ts":"2026-08-24T20:48:26.651Z","event_type":"price_change","market_id":"3825038","outcome_index":0,"market_type":"set1","local_side":"home","local_uid":"2026-08-24_greet_minnen_jeline_vandromme","bid":0.001,"ask":0.075,"mid":0.038,"spread":0.074,"price":0.075,"size":150.0,"side":"SELL"}
{"ts":"2026-08-24T20:48:26.819Z","event_type":"best_bid_ask","market_id":"3826919","outcome_index":0,"market_type":"set2","local_side":"home","local_uid":"2026-08-24_dalibor_svrcina_felipe_meligeni_alves","bid":0.43,"ask":0.51,"mid":0.47,"spread":0.08,"bid_size":null,"ask_size":null}
{"ts":"2026-08-24T20:48:26.823Z","event_type":"best_bid_ask","market_id":"3826919","outcome_index":1,"market_type":"set2","local_side":"away","local_uid":"2026-08-24_dalibor_svrcina_felipe_meligeni_alves","bid":0.49,"ask":0.57,"mid":0.53,"spread":0.08,"bid_size":null,"ask_size":null}
{"ts":"2026-08-24T20:48:26.824Z","event_type":"price_change","market_id":"3826919","outcome_index":1,"market_type":"set2","local_side":"away","local_uid":"2026-08-24_dalibor_svrcina_felipe_meligeni_alves","bid":0.49,"ask":0.57,"mid":0.53,"spread":0.08,"price":0.49,"size":24.6,"side":"BUY"}
{"ts":"2026-08-24T20:48:26.824Z","event_type":"price_change","market_id":"3826919","outcome_index":0,"market_type":"set2","local_side":"home","local_uid":"2026-08-24_dalibor_svrcina_felipe_meligeni_alves","bid":0.43,"ask":0.51,"mid":0.47,"spread":0.08,"price":0.51,"size":24.6,"side":"SELL"}
{"ts":"2026-08-24T20:48:26.872Z","event_type":"best_bid_ask","market_id":"3826919","outcome_index":0,"market_type":"set2","local_side":"home","local_uid":"2026-08-24_dalibor_svrcina_felipe_meligeni_alves","bid":0.43,"ask":0.52,"mid":0.475,"spread":0.09,"bid_size":null,"ask_size":null}
